Workbook

Sheet 处理量
A1: 常州市深水江边污水处理有限公司污水处理运行月报表
A2: 44835
A3: 日 期 | B3: 水温 | C3: 天气 | D3: 日处理 水量 （m3） | E3: 污泥量（T） | H3: 药剂量 | I3: MLSS | J3: 电耗 | K3: 混凝剂 | L3: 絮凝剂 阴离子 （kg） | M3: 盐酸 | N3: 氯酸钠 | O3: 乙酸（吨） | Q3: 回用水 （m3） | R3: 实际水量（m3） | T3: 费用统计 | U3: 成本分析用 | W3: 单价 | X3: 单耗 | Z3: 最新时间 | AD3: PAC | AE3: PAM阳 | AF3: PAM阴 | AG3: HCL | AH3: NACLO3 | AI3: 合计 | AK3: 干泥量 | AL3: 单耗
B4: 度 | C4: 状况 | E4: 国电 | F4: 英科环境 | G4: 其他 | H4: （Kg） | I4: （mg/l） | J4: ( 度 ) | K4: （Kg） | M4: （Kg） | N4: （Kg） | O4: 缺氧段 | P4: 提标段 | T4: 电量 | U4: =ROUND(J37*W4,2) -> 1049992 | W4: 0.68119373 | X4: =J36/R36 -> 0.27687103 | Z4: 44656 | AB4: 污泥量合计
A5: 1 | B5: 27.9 | C5: 晴 | D5: 205468 | E5: 0 | F5: 105.36 | G5: 0 | H5: 100 | I5: 3654 | J5: 53300 | K5: 0 | L5: 0 | M5: 4856 | N5: 1564 | O5: 0 | P5: 0 | Q5: 5496 | R5: =D5-Q5 -> 199972 | T5: 聚丙烯酰阳离子 | U5: =H37*W5/1000 -> 118300 | W5: 28000 | X5: =H36/R36*1000 -> 0.75890755 | Z5: 44287 | AB5: =E5+F5+G5 -> 105.36 | AD5: =$W$9*K5/1000/R5 -> 0 | AE5: =$W$5*H5/1000/R5 -> 0.01400196 | AF5: =$W$6*L5/1000/R5 -> 0 | AG5: =$W$7*M5/1000/R5 -> 0.010806113 | AH5: =$W$8*N5/1000/R5 -> 0.050798012 | AI5: =AD5+AE5+AF5+AG5+AH5 -> 0.075606085 | AK5: =AB5*(100-进出水!T7)/100 -> 22.86312 | AL5: =H5/AK5 -> 4.3738562
A6: 2 | B6: 27.6 | C6: 晴 | D6: 171839 | E6: 0 | F6: 102.14 | G6: 0 | H6: 125 | I6: 3618 | J6: 48500 | K6: 0 | L6: 0.2 | M6: 4714 | N6: 1540 | O6: 0 | P6: 0 | Q6: 5488 | R6: =D6-Q6 -> 166351 | T6: 聚丙烯酰阴离子 | U6: =L37*W6/1000 -> 27.04 | V6: =U5+U6 -> 118327.04 | W6: 10400 | X6: =L36/R36*1000 -> 0.00046702003 | Z6: 44256 | AB6: =E6+F6+G6 -> 102.14 | AD6: =$W$9*K6/1000/R6 -> 0 | AE6: =$W$5*H6/1000/R6 -> 0.021039849 | AF6: =$W$6*L6/1000/R6 -> 1.2503682e-05 | AG6: =$W$7*M6/1000/R6 -> 0.012610264 | AH6: =$W$8*N6/1000/R6 -> 0.060127682 | AI6: =AD6+AE6+AF6+AG6+AH6 -> 0.093790299 | AK6: =AB6*(100-进出水!T8)/100 -> 22.36866 | AL6: =H6/AK6 -> 5.5881756
A7: 3 | B7: 29.5 | C7: 晴 | D7: 161241 | E7: 0 | F7: 105.58 | G7: 0 | H7: 125 | I7: 4760 | J7: 48200 | K7: 0 | L7: 0 | M7: 4288 | N7: 1396 | O7: 1.62 | P7: 0 | Q7: 5488 | R7: =D7-Q7 -> 155753 | T7: 工业盐酸 | U7: =M37*W7/1000 -> 54224.14 | W7: 445 | X7: =M36/R36*1000 -> 21.887433 | Z7: 44228 | AB7: =E7+F7+G7 -> 105.58 | AD7: =$W$9*K7/1000/R7 -> 0 | AE7: =$W$5*H7/1000/R7 -> 0.022471477 | AF7: =$W$6*L7/1000/R7 -> 0 | AG7: =$W$7*M7/1000/R7 -> 0.012251193 | AH7: =$W$8*N7/1000/R7 -> 0.058214095 | AI7: =AD7+AE7+AF7+AG7+AH7 -> 0.092936765 | AK7: =AB7*(100-进出水!T9)/100 -> 23.33318 | AL7: =H7/AK7 -> 5.3571781
A8: 4 | B8: 28.3 | C8: 阴 | D8: 161797 | E8: 104.84 | F8: 0 | G8: 0 | H8: 125 | I8: 4386 | J8: 46600 | K8: 0 | L8: 0.2 | M8: 2087 | N8: 652 | O8: 0 | P8: 0 | Q8: 5518 | R8: =D8-Q8 -> 156279 | T8: 工业氯酸钠 | U8: =N37*W8/1000 -> 252083.94 | V8: =U7+U8 -> 306308.08 | W8: 6495 | X8: =N36/R36*1000 -> 6.9715314 | Z8: 44806 | AB8: =E8+F8+G8 -> 104.84 | AD8: =$W$9*K8/1000/R8 -> 0 | AE8: =$W$5*H8/1000/R8 -> 0.022395843 | AF8: =$W$6*L8/1000/R8 -> 1.330953e-05 | AG8: =$W$7*M8/1000/R8 -> 0.005942673 | AH8: =$W$8*N8/1000/R8 -> 0.027097307 | AI8: =AD8+AE8+AF8+AG8+AH8 -> 0.055449133 | AK8: =AB8*(100-进出水!T10)/100 -> 23.48416 | AL8: =H8/AK8 -> 5.3227367
A9: 5 | B9: 27 | C9: 雨 | D9: 173778 | E9: 53.28 | F9: 51.9 | G9: 0 | H9: 125 | I9: 4800 | J9: 49400 | K9: 0 | L9: 0 | M9: 1661 | N9: 508 | O9: 0 | P9: 0 | Q9: 5512 | R9: =D9-Q9 -> 168266 | T9: 混凝药剂 | U9: =K37*W9/1000 -> 34526.64 | W9: 526 | X9: =K36/R36*1000 -> 11.79046 | Z9: 44228 | AB9: =E9+F9+G9 -> 105.18 | AD9: =$W$9*K9/1000/R9 -> 0 | AE9: =$W$5*H9/1000/R9 -> 0.020800399 | AF9: =$W$6*L9/1000/R9 -> 0 | AG9: =$W$7*M9/1000/R9 -> 0.0043927175 | AH9: =$W$8*N9/1000/R9 -> 0.019608596 | AI9: =AD9+AE9+AF9+AG9+AH9 -> 0.044801713 | AK9: =AB9*(100-进出水!T11)/100 -> 23.34996 | AL9: =H9/AK9 -> 5.3533282
A10: 6 | B10: 26.5 | C10: 雨 | D10: 191585 | E10: 71.18 | F10: 35.28 | G10: 0 | H10: 125 | I10: 3420 | J10: 50100 | K10: 0 | L10: 0.2 | M10: 1945 | N10: 604 | O10: 1.62 | P10: 0 | Q10: 5496 | R10: =D10-Q10 -> 186089 | T10: 污泥外运 | U10: =T18 -> 67856.44 | V10: 计算见下表 | AB10: =E10+F10+G10 -> 106.46 | AD10: =$W$9*K10/1000/R10 -> 0 | AE10: =$W$5*H10/1000/R10 -> 0.018808205 | AF10: =$W$6*L10/1000/R10 -> 1.1177447e-05 | AG10: =$W$7*M10/1000/R10 -> 0.0046511347 | AH10: =$W$8*N10/1000/R10 -> 0.021081203 | AI10: =AD10+AE10+AF10+AG10+AH10 -> 0.04455172 | AK10: =AB10*(100-进出水!T12)/100 -> 23.4212 | AL10: =H10/AK10 -> 5.3370451
A11: 7 | B11: 26 | C11: 阴 | D11: 213641 | E11: 66.48 | F11: 16.12 | G11: 0 | H11: 125 | I11: 3252 | J11: 52000 | K11: 0 | L11: 0 | M11: 4359 | N11: 1396 | O11: 1.56 | P11: 0 | Q11: 5487 | R11: =D11-Q11 -> 208154 | T11: 自来水 | U11: =汇总!J5*W11 -> 14254.8 | W11: 4.2 | AB11: =E11+F11+G11 -> 82.6 | AD11: =$W$9*K11/1000/R11 -> 0 | AE11: =$W$5*H11/1000/R11 -> 0.016814474 | AF11: =$W$6*L11/1000/R11 -> 0 | AG11: =$W$7*M11/1000/R11 -> 0.0093188457 | AH11: =$W$8*N11/1000/R11 -> 0.043559192 | AI11: =AD11+AE11+AF11+AG11+AH11 -> 0.069692511 | AK11: =AB11*(100-进出水!T13)/100 -> 17.9242 | AL11: =H11/AK11 -> 6.9738119
A12: 8 | B12: 26.4 | C12: 阴 | D12: 211741 | E12: 0 | F12: 63.8 | G12: 0 | H12: 125 | I12: 3958 | J12: 51400 | K12: 0 | L12: 0.2 | M12: 5140 | N12: 1612 | O12: 0 | P12: 0 | Q12: 5496 | R12: =D12-Q12 -> 206245 | AB12: =E12+F12+G12 -> 63.8 | AD12: =$W$9*K12/1000/R12 -> 0 | AE12: =$W$5*H12/1000/R12 -> 0.016970108 | AF12: =$W$6*L12/1000/R12 -> 1.0085093e-05 | AG12: =$W$7*M12/1000/R12 -> 0.011090208 | AH12: =$W$8*N12/1000/R12 -> 0.050764576 | AI12: =AD12+AE12+AF12+AG12+AH12 -> 0.078834978 | AK12: =AB12*(100-进出水!T14)/100 -> 13.9722 | AL12: =H12/AK12 -> 8.9463363
A13: 9 | B13: 27 | C13: 晴 | D13: 211578 | E13: 0 | F13: 64 | G13: 0 | H13: 125 | I13: 3864 | J13: 50500 | K13: 0 | L13: 0 | M13: 5566 | N13: 1756 | O13: 0 | P13: 0 | Q13: 5497 | R13: =D13-Q13 -> 206081 | U13: =U14/R37 -> 0.082476054 | AB13: =E13+F13+G13 -> 64 | AD13: =$W$9*K13/1000/R13 -> 0 | AE13: =$W$5*H13/1000/R13 -> 0.016983613 | AF13: =$W$6*L13/1000/R13 -> 0 | AG13: =$W$7*M13/1000/R13 -> 0.012018915 | AH13: =$W$8*N13/1000/R13 -> 0.055343384 | AI13: =AD13+AE13+AF13+AG13+AH13 -> 0.084345913 | AK13: =AB13*(100-进出水!T15)/100 -> 13.824 | AL13: =H13/AK13 -> 9.0422454
A14: 10 | B14: 25.2 | C14: 晴 | D14: 212007 | E14: 0 | F14: 69.5 | G14: 0 | H14: 125 | I14: 3692 | J14: 50200 | K14: 0 | L14: 0 | M14: 4785 | N14: 1564 | O14: 0 | P14: 0 | Q14: 5504 | R14: =D14-Q14 -> 206503 | T14: 总药剂 | U14: =U5+U6+U7+U8+U9 -> 459161.76 | V14: 除磷药剂 | W14: =U6+U9 -> 34553.68 | AB14: =E14+F14+G14 -> 69.5 | AD14: =$W$9*K14/1000/R14 -> 0 | AE14: =$W$5*H14/1000/R14 -> 0.016948906 | AF14: =$W$6*L14/1000/R14 -> 0 | AG14: =$W$7*M14/1000/R14 -> 0.010311351 | AH14: =$W$8*N14/1000/R14 -> 0.04919144 | AI14: =AD14+AE14+AF14+AG14+AH14 -> 0.076451698 | AK14: =AB14*(100-进出水!T16)/100 -> 14.8035 | AL14: =H14/AK14 -> 8.4439491
A15: 11 | B15: 25.8 | C15: 晴 | D15: 212686 | E15: 0 | F15: 86.6 | G15: 0 | H15: 125 | I15: 3810 | J15: 50700 | K15: 0 | L15: 0.2 | M15: 5921 | N15: 1852 | O15: 0 | P15: 0 | Q15: 5515 | R15: =D15-Q15 -> 207171 | T15: 总泥量 | U15: 英科（吨） | V15: 国电（吨） | W15: 外运（吨） | AB15: =E15+F15+G15 -> 86.6 | AD15: =$W$9*K15/1000/R15 -> 0 | AE15: =$W$5*H15/1000/R15 -> 0.016894256 | AF15: =$W$6*L15/1000/R15 -> 1.0040015e-05 | AG15: =$W$7*M15/1000/R15 -> 0.012718213 | AH15: =$W$8*N15/1000/R15 -> 0.058061891 | AI15: =AD15+AE15+AF15+AG15+AH15 -> 0.087684401 | AK15: =AB15*(100-进出水!T17)/100 -> 18.619 | AL15: =H15/AK15 -> 6.7135722
A16: 12 | B16: 25.6 | C16: 晴 | D16: 212536 | E16: 68.32 | F16: 0 | G16: 16.5 | H16: 125 | I16: 3618 | J16: 51800 | K16: 0 | L16: 0 | M16: 3933 | N16: 1276 | O16: 0 | P16: 0 | Q16: 5507 | R16: =D16-Q16 -> 207029 | T16: =U16+V16+W16 -> 3117.16 | U16: =F37 -> 991.48 | V16: =E37 -> 1984.68 | W16: =G37 -> 141 | AB16: =E16+F16+G16 -> 84.82 | AD16: =$W$9*K16/1000/R16 -> 0 | AE16: =$W$5*H16/1000/R16 -> 0.016905844 | AF16: =$W$6*L16/1000/R16 -> 0 | AG16: =$W$7*M16/1000/R16 -> 0.0084538156 | AH16: =$W$8*N16/1000/R16 -> 0.040031203 | AI16: =AD16+AE16+AF16+AG16+AH16 -> 0.065390863 | AK16: =AB16*(100-进出水!T18)/100 -> 18.49076 | AL16: =H16/AK16 -> 6.7601332
A17: 13 | B17: 25 | C17: 晴 | D17: 207604 | E17: 50.82 | F17: 0 | G17: 30 | H17: 125 | I17: 4142 | J17: 51800 | K17: 0 | L17: 0 | M17: 2371 | N17: 748 | O17: 0 | P17: 0 | Q17: 5500 | R17: =D17-Q17 -> 202104 | T17: 江边费用 | U17: 22.8 | V17: 22.8 | AB17: =E17+F17+G17 -> 80.82 | AD17: =$W$9*K17/1000/R17 -> 0 | AE17: =$W$5*H17/1000/R17 -> 0.017317817 | AF17: =$W$6*L17/1000/R17 -> 0 | AG17: =$W$7*M17/1000/R17 -> 0.0052205548 | AH17: =$W$8*N17/1000/R17 -> 0.024038416 | AI17: =AD17+AE17+AF17+AG17+AH17 -> 0.046576787 | AK17: =AB17*(100-进出水!T19)/100 -> 17.86122 | AL17: =H17/AK17 -> 6.9984021
A18: 14 | B18: 25.5 | C18: 晴 | D18: 210179 | E18: 52.5 | F18: 0 | G18: 16.5 | H18: 125 | I18: 4138 | J18: 51400 | K18: 0 | L18: 0.2 | M18: 2513 | N18: 772 | O18: 0 | P18: 0 | Q18: 5502 | R18: =D18-Q18 -> 204677 | T18: =U18+V18 -> 67856.44 | U18: =ROUND(U16*U17,2) -> 22605.74 | V18: =ROUND(V16*V17,2) -> 45250.7 | AB18: =E18+F18+G18 -> 69 | AD18: =$W$9*K18/1000/R18 -> 0 | AE18: =$W$5*H18/1000/R18 -> 0.017100114 | AF18: =$W$6*L18/1000/R18 -> 1.0162353e-05 | AG18: =$W$7*M18/1000/R18 -> 0.0054636574 | AH18: =$W$8*N18/1000/R18 -> 0.024497819 | AI18: =AD18+AE18+AF18+AG18+AH18 -> 0.047071752 | AK18: =AB18*(100-进出水!T20)/100 -> 15.111 | AL18: =H18/AK18 -> 8.2721196
A19: 15 | B19: 25.6 | C19: 晴 | D19: 195881 | E19: 86.68 | F19: 0 | G19: 0 | H19: 100 | I19: 4562 | J19: 51100 | K19: 0 | L19: 0 | M19: 1945 | N19: 604 | O19: 0 | P19: 0 | Q19: 5537 | R19: =D19-Q19 -> 190344 | T19: 排水承担 | V19: 0 | AB19: =E19+F19+G19 -> 86.68 | AD19: =$W$9*K19/1000/R19 -> 0 | AE19: =$W$5*H19/1000/R19 -> 0.014710209 | AF19: =$W$6*L19/1000/R19 -> 0 | AG19: =$W$7*M19/1000/R19 -> 0.004547162 | AH19: =$W$8*N19/1000/R19 -> 0.020609948 | AI19: =AD19+AE19+AF19+AG19+AH19 -> 0.039867319 | AK19: =AB19*(100-进出水!T21)/100 -> 18.80956 | AL19: =H19/AK19 -> 5.3164455
A20: 16 | B20: 25.4 | C20: 晴 | D20: 159608 | E20: 68.2 | F20: 0 | G20: 16.5 | H20: 150 | I20: 3690 | J20: 48600 | K20: 0 | L20: 0.2 | M20: 4856 | N20: 1516 | O20: 0 | P20: 0 | Q20: 5502 | R20: =D20-Q20 -> 154106 | T20: =U20+V20 -> 0 | V20: =ROUND(V16*V19,2) -> 0 | AB20: =E20+F20+G20 -> 84.7 | AD20: =$W$9*K20/1000/R20 -> 0 | AE20: =$W$5*H20/1000/R20 -> 0.027253968 | AF20: =$W$6*L20/1000/R20 -> 1.3497203e-05 | AG20: =$W$7*M20/1000/R20 -> 0.014022296 | AH20: =$W$8*N20/1000/R20 -> 0.063893813 | AI20: =AD20+AE20+AF20+AG20+AH20 -> 0.10518357 | AK20: =AB20*(100-进出水!T22)/100 -> 18.2952 | AL20: =H20/AK20 -> 8.1988718
A21: 17 | B21: 25.3 | C21: 晴 | D21: 149401 | E21: 0 | F21: 83.18 | G21: 0 | H21: 100 | I21: 3284 | J21: 44800 | K21: 10320 | L21: 0 | M21: 5211 | N21: 1612 | O21: 0 | P21: 0 | Q21: 5495 | R21: =D21-Q21 -> 143906 | T21: 总运费 | U21: 总单价 | V21: =V17+V19 -> 22.8 | W21: 核对 | AB21: =E21+F21+G21 -> 83.18 | AD21: =$W$9*K21/1000/R21 -> 0.03772129 | AE21: =$W$5*H21/1000/R21 -> 0.019457146 | AF21: =$W$6*L21/1000/R21 -> 0 | AG21: =$W$7*M21/1000/R21 -> 0.016113956 | AH21: =$W$8*N21/1000/R21 -> 0.07275541 | AI21: =AD21+AE21+AF21+AG21+AH21 -> 0.1460478 | AK21: =AB21*(100-进出水!T23)/100 -> 17.80052 | AL21: =H21/AK21 -> 5.6178134
A22: 18 | B22: 25.4 | C22: 晴 | D22: 153184 | E22: 67.72 | F22: 0 | G22: 16.5 | H22: 150 | I22: 4110 | J22: 43800 | K22: 0 | L22: 0.2 | M22: 5211 | N22: 1708 | O22: 0 | P22: 0 | Q22: 5516 | R22: =D22-Q22 -> 147668 | T22: =T18+T20 -> 67856.44 | W22: =T16-E37-F37-G37 -> -2.2737368e-13 | AB22: =E22+F22+G22 -> 84.22 | AD22: =$W$9*K22/1000/R22 -> 0 | AE22: =$W$5*H22/1000/R22 -> 0.028442181 | AF22: =$W$6*L22/1000/R22 -> 1.4085652e-05 | AG22: =$W$7*M22/1000/R22 -> 0.015703436 | AH22: =$W$8*N22/1000/R22 -> 0.075124333 | AI22: =AD22+AE22+AF22+AG22+AH22 -> 0.11928404 | AK22: =AB22*(100-进出水!T24)/100 -> 18.19152 | AL22: =H22/AK22 -> 8.2456001
A23: 19 | B23: 25.5 | C23: 晴 | D23: 158973 | E23: 101.58 | F23: 0 | G23: 0 | H23: 125 | I23: 3584 | J23: 45300 | K23: 9120 | L23: 0 | M23: 4856 | N23: 1588 | O23: 0 | P23: 0 | Q23: 5488 | R23: =D23-Q23 -> 153485 | AB23: =E23+F23+G23 -> 101.58 | AD23: =$W$9*K23/1000/R23 -> 0.03125465 | AE23: =$W$5*H23/1000/R23 -> 0.022803531 | AF23: =$W$6*L23/1000/R23 -> 0 | AG23: =$W$7*M23/1000/R23 -> 0.014079031 | AH23: =$W$8*N23/1000/R23 -> 0.06719914 | AI23: =AD23+AE23+AF23+AG23+AH23 -> 0.13533635 | AK23: =AB23*(100-进出水!T25)/100 -> 21.8397 | AL23: =H23/AK23 -> 5.7235218
A24: 20 | B24: 25.6 | C24: 晴 | D24: 160898 | E24: 99.8 | F24: 0 | G24: 0 | H24: 125 | I24: 4458 | J24: 46300 | K24: 22320 | L24: 0.2 | M24: 4359 | N24: 1420 | O24: 0 | P24: 0 | Q24: 5504 | R24: =D24-Q24 -> 155394 | T24: 絮凝剂 | U24: 用量（kg） | V24: =H37 -> 4225 | W24: =L37 -> 2.6 | AB24: =E24+F24+G24 -> 99.8 | AD24: =$W$9*K24/1000/R24 -> 0.075551952 | AE24: =$W$5*H24/1000/R24 -> 0.022523392 | AF24: =$W$6*L24/1000/R24 -> 1.338533e-05 | AG24: =$W$7*M24/1000/R24 -> 0.012482818 | AH24: =$W$8*N24/1000/R24 -> 0.059351712 | AI24: =AD24+AE24+AF24+AG24+AH24 -> 0.16992326 | AK24: =AB24*(100-进出水!T26)/100 -> 21.3572 | AL24: =H24/AK24 -> 5.8528271
A25: 21 | B25: 25.3 | C25: 晴 | D25: 162672 | E25: 102.74 | F25: 0 | G25: 0 | H25: 100 | I25: 4708 | J25: 45800 | K25: 3840 | L25: 0 | M25: 2016 | N25: 628 | O25: 0 | P25: 0 | Q25: 5488 | R25: =D25-Q25 -> 157184 | U25: 单耗（kg/T） | V25: =汇总!F6 -> 6.2317261 | W25: =W24/R37*1000 -> 0.00046702003 | AB25: =E25+F25+G25 -> 102.74 | AD25: =$W$9*K25/1000/R25 -> 0.012850163 | AE25: =$W$5*H25/1000/R25 -> 0.017813518 | AF25: =$W$6*L25/1000/R25 -> 0 | AG25: =$W$7*M25/1000/R25 -> 0.0057074511 | AH25: =$W$8*N25/1000/R25 -> 0.025949588 | AI25: =AD25+AE25+AF25+AG25+AH25 -> 0.06232072 | AK25: =AB25*(100-进出水!T27)/100 -> 22.0891 | AL25: =H25/AK25 -> 4.5271197
A26: 22 | B26: 25.8 | C26: 晴 | D26: 166592 | E26: 103.9 | F26: 0 | G26: 0 | H26: 125 | I26: 5272 | J26: 46100 | K26: 15960 | L26: 0 | M26: 2087 | N26: 652 | O26: 0 | P26: 0 | Q26: 5488 | R26: =D26-Q26 -> 161104 | T26: 混凝剂 | U26: 用量（kg） | V26: =K37 -> 65640 | AB26: =E26+F26+G26 -> 103.9 | AD26: =$W$9*K26/1000/R26 -> 0.052108948 | AE26: =$W$5*H26/1000/R26 -> 0.021725097 | AF26: =$W$6*L26/1000/R26 -> 0 | AG26: =$W$7*M26/1000/R26 -> 0.0057646924 | AH26: =$W$8*N26/1000/R26 -> 0.026285753 | AI26: =AD26+AE26+AF26+AG26+AH26 -> 0.10588449 | AK26: =AB26*(100-进出水!T28)/100 -> 22.6502 | AL26: =H26/AK26 -> 5.5187151
A27: 23 | B27: 25.6 | C27: 晴 | D27: 151813 | E27: 72.26 | F27: 0 | G27: 30 | H27: 125 | I27: 4456 | J27: 47900 | K27: 4080 | L27: 0.2 | M27: 3436 | N27: 1108 | O27: 3.06 | P27: 0 | Q27: 5480 | R27: =D27-Q27 -> 146333 | U27: 单耗（g/m3） | V27: =ROUND(K37/R37*1000,1) -> 11.8 | AB27: =E27+F27+G27 -> 102.26 | AD27: =$W$9*K27/1000/R27 -> 0.014665728 | AE27: =$W$5*H27/1000/R27 -> 0.02391805 | AF27: =$W$6*L27/1000/R27 -> 1.4214155e-05 | AG27: =$W$7*M27/1000/R27 -> 0.010448908 | AH27: =$W$8*N27/1000/R27 -> 0.049178654 | AI27: =AD27+AE27+AF27+AG27+AH27 -> 0.098225554 | AK27: =AB27*(100-进出水!T29)/100 -> 22.39494 | AL27: =H27/AK27 -> 5.581618
A28: 24 | B28: 25.9 | C28: 晴 | D28: 163431 | E28: 83.68 | F28: 0 | G28: 15 | H28: 125 | I28: 3220 | J28: 49100 | K28: 0 | L28: 0 | M28: 4146 | N28: 1324 | O28: 3.06 | P28: 0 | Q28: 5488 | R28: =D28-Q28 -> 157943 | T28: 盐酸 | U28: 用量（kg） | V28: =M37 -> 121852 | AB28: =E28+F28+G28 -> 98.68 | AD28: =$W$9*K28/1000/R28 -> 0 | AE28: =$W$5*H28/1000/R28 -> 0.022159893 | AF28: =$W$6*L28/1000/R28 -> 0 | AG28: =$W$7*M28/1000/R28 -> 0.011681239 | AH28: =$W$8*N28/1000/R28 -> 0.054446098 | AI28: =AD28+AE28+AF28+AG28+AH28 -> 0.08828723 | AK28: =AB28*(100-进出水!T30)/100 -> 21.41356 | AL28: =H28/AK28 -> 5.8374226
A29: 25 | B29: 25.6 | C29: 晴 | D29: 171692 | E29: 103 | F29: 0 | G29: 0 | H29: 125 | I29: 4738 | J29: 49600 | K29: 0 | L29: 0.2 | M29: 5424 | N29: 1780 | O29: 2.04 | P29: 0 | Q29: 5488 | R29: =D29-Q29 -> 166204 | U29: 单耗（g/m3） | V29: =ROUND(M37/R37*1000,1) -> 21.9 | AB29: =E29+F29+G29 -> 103 | AD29: =$W$9*K29/1000/R29 -> 0 | AE29: =$W$5*H29/1000/R29 -> 0.021058458 | AF29: =$W$6*L29/1000/R29 -> 1.2514741e-05 | AG29: =$W$7*M29/1000/R29 -> 0.014522394 | AH29: =$W$8*N29/1000/R29 -> 0.069559698 | AI29: =AD29+AE29+AF29+AG29+AH29 -> 0.10515306 | AK29: =AB29*(100-进出水!T31)/100 -> 22.454 | AL29: =H29/AK29 -> 5.5669368
A30: 26 | B30: 25.2 | C30: 阴 | D30: 193798 | E30: 103.3 | F30: 0 | G30: 0 | H30: 125 | I30: 4776 | J30: 51900 | K30: 0 | L30: 0 | M30: 5211 | N30: 1684 | O30: 1.62 | P30: 0 | Q30: 5482 | R30: =D30-Q30 -> 188316 | T30: 氯酸钠 | U30: 用量（kg） | V30: =处理量!N37 -> 38812 | AB30: =E30+F30+G30 -> 103.3 | AD30: =$W$9*K30/1000/R30 -> 0 | AE30: =$W$5*H30/1000/R30 -> 0.018585781 | AF30: =$W$6*L30/1000/R30 -> 0 | AG30: =$W$7*M30/1000/R30 -> 0.01231385 | AH30: =$W$8*N30/1000/R30 -> 0.058080992 | AI30: =AD30+AE30+AF30+AG30+AH30 -> 0.088980623 | AK30: =AB30*(100-进出水!T32)/100 -> 22.4161 | AL30: =H30/AK30 -> 5.5763491
A31: 27 | B31: 24.9 | C31: 阴 | D31: 208804 | E31: 104.22 | F31: 0 | G31: 0 | H31: 125 | I31: 5164 | J31: 52000 | K31: 0 | L31: 0.2 | M31: 5069 | N31: 1588 | O31: 1.56 | P31: 0 | Q31: 5486 | R31: =D31-Q31 -> 203318 | U31: 单耗（g/m3） | V31: =ROUND(N37/R37*1000,2) -> 6.97 | AB31: =E31+F31+G31 -> 104.22 | AD31: =$W$9*K31/1000/R31 -> 0 | AE31: =$W$5*H31/1000/R31 -> 0.017214413 | AF31: =$W$6*L31/1000/R31 -> 1.023028e-05 | AG31: =$W$7*M31/1000/R31 -> 0.011094468 | AH31: =$W$8*N31/1000/R31 -> 0.050728711 | AI31: =AD31+AE31+AF31+AG31+AH31 -> 0.079047822 | AK31: =AB31*(100-进出水!T33)/100 -> 22.82418 | AL31: =H31/AK31 -> 5.476648
A32: 28 | B32: 25.8 | C32: 晴 | D32: 207834 | E32: 104.54 | F32: 0 | G32: 0 | H32: 175 | I32: 4476 | J32: 55800 | K32: 0 | L32: 0 | M32: 3010 | N32: 940 | O32: 1.2 | P32: 0 | Q32: 5480 | R32: =D32-Q32 -> 202354 | T32: 乙酸 | U32: 用量（T） | V32: =O37 -> 18.84 | AB32: =E32+F32+G32 -> 104.54 | AD32: =$W$9*K32/1000/R32 -> 0 | AE32: =$W$5*H32/1000/R32 -> 0.02421499 | AF32: =$W$6*L32/1000/R32 -> 0 | AG32: =$W$7*M32/1000/R32 -> 0.0066193404 | AH32: =$W$8*N32/1000/R32 -> 0.030171383 | AI32: =AD32+AE32+AF32+AG32+AH32 -> 0.061005713 | AK32: =AB32*(100-进出水!T34)/100 -> 22.68518 | AL32: =H32/AK32 -> 7.7142875
A33: 29 | B33: 25 | C33: 晴 | D33: 211061 | E33: 105.48 | F33: 68.54 | G33: 0 | H33: 250 | I33: 4524 | J33: 54500 | K33: 0 | L33: 0.2 | M33: 1874 | N33: 580 | O33: 0 | P33: 0 | Q33: 5480 | R33: =D33-Q33 -> 205581 | U33: 单耗（g/m3） | V33: =ROUND(V32/R37*1000000,2) -> 3.38 | AB33: =E33+F33+G33 -> 174.02 | AD33: =$W$9*K33/1000/R33 -> 0 | AE33: =$W$5*H33/1000/R33 -> 0.034049839 | AF33: =$W$6*L33/1000/R33 -> 1.0117667e-05 | AG33: =$W$7*M33/1000/R33 -> 0.0040564546 | AH33: =$W$8*N33/1000/R33 -> 0.018324164 | AI33: =AD33+AE33+AF33+AG33+AH33 -> 0.056440576 | AK33: =AB33*(100-进出水!T35)/100 -> 37.4143 | AL33: =H33/AK33 -> 6.6819371
A34: 30 | B34: 25.2 | C34: 晴 | D34: 191949 | E34: 86.36 | F34: 86.44 | G34: 0 | H34: 200 | I34: 3812 | J34: 52900 | K34: 0 | L34: 0 | M34: 3081 | N34: 988 | O34: 0 | P34: 0 | Q34: 5472 | R34: =D34-Q34 -> 186477 | AB34: =E34+F34+G34 -> 172.8 | AD34: =$W$9*K34/1000/R34 -> 0 | AE34: =$W$5*H34/1000/R34 -> 0.030030513 | AF34: =$W$6*L34/1000/R34 -> 0 | AG34: =$W$7*M34/1000/R34 -> 0.0073523544 | AH34: =$W$8*N34/1000/R34 -> 0.034412072 | AI34: =AD34+AE34+AF34+AG34+AH34 -> 0.07179494 | AK34: =AB34*(100-进出水!T36)/100 -> 37.3248 | AL34: =H34/AK34 -> 5.3583676
A35: 31 | B35: 24.2 | C35: 晴 | D35: 172310 | E35: 123.8 | F35: 53.04 | G35: 0 | H35: 275 | I35: 4646 | J35: 50000 | K35: 0 | L35: 0 | M35: 5921 | N35: 1852 | O35: 1.5 | P35: 0 | Q35: 5488 | R35: =D35-Q35 -> 166822 | AB35: =E35+F35+G35 -> 176.84 | AD35: =$W$9*K35/1000/R35 -> 0 | AE35: =$W$5*H35/1000/R35 -> 0.046156982 | AF35: =$W$6*L35/1000/R35 -> 0 | AG35: =$W$7*M35/1000/R35 -> 0.01579435 | AH35: =$W$8*N35/1000/R35 -> 0.072105238 | AI35: =AD35+AE35+AF35+AG35+AH35 -> 0.13405657 | AK35: =AB35*(100-进出水!T37)/100 -> 38.55112 | AL35: =H35/AK35 -> 7.1333855
A36: 平均 | B36: =AVERAGE(B5:B35) -> 25.954839 | C36: / | D36: =AVERAGE(D5:D35) -> 185083.26 | E36: =AVERAGE(E5:E35) -> 64.021935 | F36: =AVERAGE(F5:F35) -> 31.983226 | G36: =AVERAGE(G5:G35) -> 4.5483871 | H36: =AVERAGE(H5:H35) -> 136.29032 | I36: =AVERAGE(I5:I35) -> 4148.129 | J36: =AVERAGE(J5:J35) -> 49722.581 | K36: =AVERAGE(K5:K35) -> 2117.4194 | ... Q36: =AVERAGE(Q5:Q35) -> 5495.7419 | R36: =D36-Q36 -> 179587.52
A37: 合计 | B37: / | C37: / | D37: =SUM(D5:D35) -> 5737581 | E37: =SUM(E5:E35) -> 1984.68 | F37: =SUM(F5:F35) -> 991.48 | G37: =SUM(G5:G35) -> 141 | H37: =SUM(H5:H35) -> 4225 | I37: / | J37: =SUM(J5:J35) -> 1541400 | K37: =SUM(K5:K35) -> 65640 | L37: =SUM(L5:L35) -> 2.6 | M37: =SUM(M5:M35) -> 121852 | N37: =SUM(N5:N35) -> 38812 | O37: =SUM(O5:O35) -> 18.84 | P37: =SUM(P5:P35) -> 0 | Q37: =SUM(Q5:Q35) -> 170368 | R37: =SUM(R5:R35) -> 5567213 | AB37: =SUM(AB5:AB36) -> 3117.16
A38: 审核： | I38: 制表： | Q38: 制表时间: | R38: 44867
M39: =M37*0.31 -> 37774.12
Q40: 最大 | R40: =MAX(R5:R35) -> 208154 | AB40: =(100-进出水!T38)*AB37/100 -> 677.9823
...

Sheet 汇总
A1: 常州市深水江边污水处理有限公司污水运行月报表
A2: 44835
A3: 污 水 处 理 | B3: 污水处理量（m3） | C3: =处理量!R37 -> 5567213 | D3: 污 泥 处 理 | E3: 脱水污泥量（T） | F3: =处理量!E37+处理量!F37+处理量!G37 -> 3117.16 | G3: 水 电 用 量 | H3: 用电量（度） | J3: =处理量!J37 -> 1541400 | K3: 污 水 电 单 耗 | L3: 污水（度/m3） | M3: =J3/C3 -> 0.27687103 | P3: 除臭用水量 | Q3: 1773.2 | R3: =J5-Q3 -> 1620.8 | V3: 188314
B4: 日均处理量（m3） | C4: =处理量!R36 -> 179587.52 | E4: 絮凝剂用量（kg） | F4: =处理量!H37 -> 4225 | H4: 日均用电量（度） | J4: =J3/M15 -> 49722.581 | L4: CODcr（度/kg） | M4: =J3/I12 -> 1.4556837 | P4: 除臭用电量 | Q4: 50536 | V4: 193894
E5: 含水率（%） | F5: =进出水!T38 -> 78.25 | H5: 用水量（T） | J5: 3394 | V5: =V4-V3 -> 5580
B6: 最高日处理量 | C6: =处理量!R40 -> 208154 | E6: 絮凝剂单耗（kg/T） | F6: =F4/(F3*(100-F5)/100) -> 6.2317261 | G6: 消 毒 剂 | H6: 工业合成盐酸（T） | J6: =处理量!M37/1000 -> 121.852 | L6: BOD5（度/kg） | M6: =J3/I13 -> 2.927374
B7: 最低日处理量 | C7: =处理量!R41 -> 143906 | E7: 产泥率(g/m３) | F7: =F3*(100-F5)/100*1000/(C3/1000) -> 121.78128 | H7: 药单耗(g/m3) | J7: =J6*1000/(C3/1000) -> 21.887433 | L7: SS（度/kg） | M7: =J3/I14 -> 2.5468773
B8: 负荷率（%） | C8: =C4/200000*100 -> 89.793758 | D8: 混 凝 剂 | E8: 混凝剂用量（T） | F8: =处理量!K37/1000 -> 65.64 | H8: 氯酸钠（T） | J8: =处理量!N37/1000 -> 38.812 | K8: 乙酸-厌缺氧段 | L8: 投加量（吨） | M8: =处理量!O37 -> 18.84
B9: 进水水温(℃) | C9: =处理量!B36 -> 25.954839 | E9: 药单耗(g/m3) | F9: =F8*1000/(C3/1000) -> 11.79046 | H9: 药单耗(g/m3) | J9: =J8*1000/(C3/1000) -> 6.9715314 | L9: 药单耗(g/m3) | M9: =M8*1000000/C3 -> 3.384099
A10: 处 理 质 量 | B10: 项目 | C10: 进水 | E10: 出水 | G10: 去除率（%） | I10: 去除总量（kg) | K10: 乙酸-提标段 | L10: 投加量（吨） | M10: 0
L11: 药单耗(g/m3) | M11: 0
B12: CODcr | C12: =进出水!B38 -> 212 | E12: =进出水!N38 -> 21.8 | G12: =(C12-E12)/C12*100 -> 89.716981 | I12: =$C$3*(C12-E12)/1000 -> 1058883.9 | K12: 污 泥 去 向 | L12: 国电 | M12: =处理量!V16 -> 1984.68 | P12: =ROUND(E12,2) -> 21.8 | Q12: =C3 -> 5567213 | R12: =P12*Q12/1000000 -> 121.36524 | S12: CODcr
B13: BOD5 | C13: =进出水!C38 -> 97 | E13: =进出水!O38 -> 2.42 | G13: =(C13-E13)/C13*100 -> 97.505155 | I13: =$C$3*(C13-E13)/1000 -> 526547.01 | L13: 英科环境 | M13: =处理量!U16 -> 991.48 | P13: =ROUND(E13,2) -> 2.42 | Q13: =Q12 -> 5567213 | R13: =P13*Q13/1000000 -> 13.472655 | S13: BOD5
B14: SS | C14: =进出水!D38 -> 114 | E14: =进出水!P38 -> 5.29 | G14: =(C14-E14)/C14*100 -> 95.359649 | I14: =$C$3*(C14-E14)/1000 -> 605211.73 | L14: 其它 | M14: =处理量!W16 -> 141 | P14: =ROUND(E14,2) -> 5.29 | Q14: =Q13 -> 5567213 | R14: =P14*Q14/1000000 -> 29.450557 | S14: SS
B15: TP | C15: =进出水!E38 -> 2.63 | E15: =进出水!Q38 -> 0.17 | G15: =(C15-E15)/C15*100 -> 93.536122 | I15: =$C$3*(C15-E15)/1000 -> 13695.344 | K15: 运 行 情 况 | L15: 应运行天数 | M15: 31 | P15: =ROUND(E15,2) -> 0.17 | Q15: =Q14 -> 5567213 | R15: =P15*Q15/1000000 -> 0.94642621 | S15: TP
B16: TN | C16: =进出水!G38 -> 30.3 | E16: =进出水!S38 -> 7.07 | G16: =(C16-E16)/C16*100 -> 76.666667 | I16: =$C$3*(C16-E16)/1000 -> 129326.36 | L16: 实际运行天数 | M16: 31 | P16: =ROUND(E16,2) -> 7.07 | Q16: =Q15 -> 5567213 | R16: =P16*Q16/1000000 -> 39.360196 | S16: TN
B17: NH3-N | C17: =进出水!F38 -> 23.7 | E17: =进出水!R38 -> 0.33 | G17: =(C17-E17)/C17*100 -> 98.607595 | I17: =$C$3*(C17-E17)/1000 -> 130105.77 | L17: 达标排放天数 | M17: 31 | P17: =ROUND(E17,2) -> 0.33 | Q17: =Q16 -> 5567213 | R17: =P17*Q17/1000000 -> 1.8371803 | S17: NH3-N
B18: 粪大肠菌群数 (个/L) | E18: <20 | L18: 运转率 | M18: 100
A19: 备注 | B19: 本月产生泥饼3117.16吨，其中运往常州市英科环境科技有限公司991.48吨，国电常州发电有限公司1984.68吨，外运接种141.00吨：常州千红生化制药股份有限公司66.00吨；常州市新区江边污水处理厂30.00吨；江苏盈天化学有限公司45.00吨。 | P19: =F3*(100-F5)/100 -> 677.9823
A21: 审核： 制表： 制表日期：2022/11/2

Sheet 进出水
A1: 常州市深水江边污水处理有限公司进出水水质、污泥含水率月报表
J3: 44835
A4: 日期 | B4: 进水 | H4: 二沉池出水 | N4: 总出水 | T4: 污泥含水率 | U4: 粪大肠菌群
B5: CODCr | C5: BOD5 | D5: SS | E5: TP | F5: NH3-N | G5: TN | H5: CODCr | I5: BOD5 | J5: SS | K5: TP | L5: NH3-N | M5: TN | N5: CODCr | O5: BOD5 | P5: SS | Q5: TP | R5: NH3-N | S5: TN
B6: （mg/L） | C6: （mg/L） | D6: （mg/L） | E6: （mg/L） | F6: （mg/L） | G6: （mg/L） | H6: （mg/L） | I6: （mg/L） | J6: （mg/L） | K6: （mg/L） | L6: （mg/L） | M6: （mg/L） | N6: （mg/L） | O6: （mg/L） | P6: （mg/L） | Q6: （mg/L） | R6: （mg/L） | S6: （mg/L） | T6: （%） | U6: (个/L)
A7: 1 | B7: 198 | C7: 90.4 | D7: 110 | E7: 3.62 | F7: 27.7 | G7: 32.9 | H7: 29 | I7: 3.1 | J7: 18 | K7: 0.52 | L7: 0.44 | M7: 9.57 | N7: 19 | O7: 2.55 | P7: 5 | Q7: 0.15 | R7: 0.43 | S7: 8.76 | T7: 78.3 | U7: <20 | W7: =1-S7/G7 -> 0.7337386
A8: 2 | B8: 242 | C8: 110 | D8: 162 | E8: 2.9 | F8: 30.5 | G8: 35.8 | H8: 26 | I8: 2.87 | J8: 14 | K8: 0.5 | L8: 0.35 | M8: 8.57 | N8: 25 | O8: 2.31 | P8: 6 | Q8: 0.16 | R8: 0.34 | S8: 8.02 | T8: 78.1 | U8: <20 | W8: =1-S8/G8 -> 0.77597765
A9: 3 | B9: 154 | C9: 71.6 | D9: 98 | E9: 2.68 | F9: 28.2 | G9: 35.1 | H9: 19 | I9: 2.25 | J9: 14 | K9: 0.55 | L9: 0.24 | M9: 6.83 | N9: <16 | O9: 2.2 | P9: 6 | Q9: 0.16 | R9: 0.21 | S9: 6.06 | T9: 77.9 | U9: <20 | W9: =1-S9/G9 -> 0.82735043
A10: 4 | B10: 190 | C10: 86.4 | D10: 144 | E10: 3.39 | F10: 30.7 | G10: 37.6 | H10: 25 | I10: 3.1 | J10: 13 | K10: 0.53 | L10: 0.32 | M10: 8.09 | N10: 17 | O10: 2.5 | P10: 6 | Q10: 0.14 | R10: 0.31 | S10: 7.76 | T10: 77.6 | U10: <20 | W10: =1-S10/G10 -> 0.79361702
A11: 5 | B11: 224 | C11: 102 | D11: 136 | E11: 2.69 | F11: 27.3 | G11: 38.6 | H11: 20 | I11: 2.46 | J11: 12 | K11: 0.5 | L11: 0.61 | M11: 10.7 | N11: 18 | O11: 2.21 | P11: 5 | Q11: 0.16 | R11: 0.53 | S11: 10.5 | T11: 77.8 | U11: 70 | W11: =1-S11/G11 -> 0.72797927
A12: 6 | B12: 144 | C12: 65.2 | D12: 92 | E12: 2.07 | F12: 24.1 | G12: 34.2 | H12: 23 | I12: 2.6 | J12: 14 | K12: 0.55 | L12: 0.53 | M12: 7.99 | N12: 22 | O12: 2.47 | P12: 5 | Q12: 0.15 | R12: 0.5 | S12: 7.86 | T12: 78 | U12: <20 | W12: =1-S12/G12 -> 0.77017544
A13: 7 | B13: 216 | C13: 99.4 | D13: 148 | E13: 3.89 | F13: 25.5 | G13: 32.3 | H13: 23 | I13: 2.77 | J13: 12 | K13: 0.52 | L13: 0.5 | M13: 8.99 | N13: 16 | O13: 2.1 | P13: 5 | Q13: 0.15 | R13: 0.41 | S13: 8.8 | T13: 78.3 | U13: <20 | W13: =1-S13/G13 -> 0.72755418
A14: 8 | B14: 172 | C14: 76.2 | D14: 132 | E14: 2.33 | F14: 20.6 | G14: 27.5 | H14: 38 | I14: 3.33 | J14: 17 | K14: 0.55 | L14: 0.18 | M14: 8.94 | N14: 20 | O14: 2.46 | P14: 5 | Q14: 0.14 | R14: 0.17 | S14: 7.22 | T14: 78.1 | U14: <20 | W14: =1-S14/G14 -> 0.73745455
A15: 9 | B15: 178 | C15: 78.4 | D15: 82 | E15: 2.5 | F15: 15.7 | G15: 19.7 | H15: 27 | I15: 2.81 | J15: 15 | K15: 0.51 | L15: 0.25 | M15: 8.62 | N15: 19 | O15: 2.3 | P15: 5 | Q15: 0.16 | R15: 0.14 | S15: 7.18 | T15: 78.4 | U15: <20 | W15: =1-S15/G15 -> 0.63553299
A16: 10 | B16: 110 | C16: 50.2 | D16: 58 | E16: 1.59 | F16: 15.5 | G16: 20.9 | H16: 25 | I16: 2.25 | J16: 10 | K16: 0.56 | L16: 0.36 | M16: 7.94 | N16: 18 | O16: 2.2 | P16: 5 | Q16: 0.18 | R16: 0.21 | S16: 6.12 | T16: 78.7 | U16: 100 | W16: =1-S16/G16 -> 0.70717703
A17: 11 | B17: 166 | C17: 73.4 | D17: 86 | E17: 2.5 | F17: 23.5 | G17: 29.1 | H17: 27 | I17: 2.41 | J17: 14 | K17: 0.51 | L17: 0.42 | M17: 6.15 | N17: 18 | O17: 2.19 | P17: 5 | Q17: 0.27 | R17: 0.32 | S17: 5.02 | T17: 78.5 | U17: <20 | W17: =1-S17/G17 -> 0.82749141
A18: 12 | B18: 166 | C18: 75.6 | D18: 108 | E18: 2.18 | F18: 20.1 | G18: 25.1 | H18: 29 | I18: 2.78 | J18: 18 | K18: 0.52 | L18: 0.49 | M18: 8.04 | N18: 18 | O18: 2.31 | P18: 5 | Q18: 0.19 | R18: 0.35 | S18: 6.02 | T18: 78.2 | U18: <20 | W18: =1-S18/G18 -> 0.76015936
A19: 13 | B19: 202 | C19: 91.6 | D19: 76 | E19: 2.85 | F19: 20.7 | G19: 26.8 | H19: 37 | I19: 3.4 | J19: 15 | K19: 0.56 | L19: 0.52 | M19: 6.83 | N19: 21 | O19: 2.57 | P19: 5 | Q19: 0.13 | R19: 0.39 | S19: 5.96 | T19: 77.9 | U19: <20 | W19: =1-S19/G19 -> 0.77761194
A20: 14 | B20: 183 | C20: 85.3 | D20: 104 | E20: 1.82 | F20: 25.9 | G20: 31.9 | H20: 32 | I20: 3.07 | J20: 17 | K20: 0.49 | L20: 0.45 | M20: 8.44 | N20: 22 | O20: 2.24 | P20: 6 | Q20: 0.13 | R20: 0.34 | S20: 7.73 | T20: 78.1 | U20: <20 | W20: =1-S20/G20 -> 0.75768025
A21: 15 | B21: 254 | C21: 116 | D21: 152 | E21: 2.33 | F21: 20.9 | G21: 27.7 | H21: 41 | I21: 3.88 | J21: 18 | K21: 0.55 | L21: 0.62 | M21: 6.94 | N21: 23 | O21: 2.61 | P21: 6 | Q21: 0.15 | R21: 0.35 | S21: 5.62 | T21: 78.3 | U21: <20 | W21: =1-S21/G21 -> 0.79711191
A22: 16 | B22: 230 | C22: 105 | D22: 136 | E22: 3.47 | F22: 20.6 | G22: 29.3 | H22: 43 | I22: 3.95 | J22: 16 | K22: 0.55 | L22: 0.54 | M22: 10.8 | N22: 23 | O22: 2.59 | P22: 5 | Q22: 0.18 | R22: 0.49 | S22: 7.16 | T22: 78.4 | U22: 60 | W22: =1-S22/G22 -> 0.7556314
A23: 17 | B23: 348 | C23: 155 | D23: 148 | E23: 3.59 | F23: 18 | G23: 24.8 | H23: 42 | I23: 3.58 | J23: 18 | K23: 0.5 | L23: 0.28 | M23: 6.94 | N23: 21 | O23: 2.54 | P23: 5 | Q23: 0.21 | R23: 0.21 | S23: 5.96 | T23: 78.6 | U23: <20 | W23: =1-S23/G23 -> 0.75967742
A24: 18 | B24: 159 | C24: 72.3 | D24: 80 | E24: 2.22 | F24: 22.4 | G24: 28.6 | H24: 28 | I24: 2.44 | J24: 12 | K24: 0.55 | L24: 0.32 | M24: 6.58 | N24: 23 | O24: 2.2 | P24: 5 | Q24: 0.2 | R24: 0.26 | S24: 6.06 | T24: 78.4 | U24: <20 | W24: =1-S24/G24 -> 0.78811189
A25: 19 | B25: 182 | C25: 82.1 | D25: 96 | E25: 1.92 | F25: 17.9 | G25: 23.9 | H25: 27 | I25: 2.99 | J25: 11 | K25: 0.53 | L25: 0.45 | M25: 6.78 | N25: 16 | O25: 2.34 | P25: 5 | Q25: 0.18 | R25: 0.39 | S25: 5.36 | T25: 78.5 | U25: <20 | W25: =1-S25/G25 -> 0.77573222
A26: 20 | B26: 278 | C26: 128 | D26: 102 | E26: 2.81 | F26: 19.1 | G26: 26.9 | H26: 34 | I26: 3.14 | J26: 13 | K26: 0.5 | L26: 0.28 | M26: 7.54 | N26: 24 | O26: 2.62 | P26: 5 | Q26: 0.2 | R26: 0.22 | S26: 7.06 | T26: 78.6 | U26: <20 | W26: =1-S26/G26 -> 0.73754647
A27: 21 | B27: 224 | C27: 101 | D27: 122 | E27: 3.05 | F27: 25.5 | G27: 30.4 | H27: 37 | I27: 3.47 | J27: 16 | K27: 0.56 | L27: 0.41 | M27: 6.11 | N27: 24 | O27: 2.5 | P27: 6 | Q27: 0.2 | R27: 0.33 | S27: 5.74 | T27: 78.5 | U27: <20 | W27: =1-S27/G27 -> 0.81118421
A28: 22 | B28: 226 | C28: 104 | D28: 148 | E28: 2.09 | F28: 15.2 | G28: 21.2 | H28: 37 | I28: 3.6 | J28: 17 | K28: 0.54 | L28: 0.25 | M28: 6.81 | N28: 25 | O28: 2.54 | P28: 6 | Q28: 0.26 | R28: 0.22 | S28: 6.04 | T28: 78.2 | U28: <20 | W28: =1-S28/G28 -> 0.71509434
A29: 23 | B29: 164 | C29: 74.4 | D29: 86 | E29: 1.95 | F29: 22 | G29: 28.1 | H29: 37 | I29: 3.44 | J29: 15 | K29: 0.54 | L29: 0.41 | M29: 5.96 | N29: 26 | O29: 2.25 | P29: 6 | Q29: 0.21 | R29: 0.28 | S29: 5.84 | T29: 78.1 | U29: <20 | W29: =1-S29/G29 -> 0.79217082
A30: 24 | B30: 228 | C30: 103 | D30: 130 | E30: 3.48 | F30: 31.3 | G30: 38.5 | H30: 38 | I30: 3.58 | J30: 16 | K30: 0.56 | L30: 0.62 | M30: 7.81 | N30: 25 | O30: 2.71 | P30: 5 | Q30: 0.14 | R30: 0.5 | S30: 6.94 | T30: 78.3 | U30: 80 | W30: =1-S30/G30 -> 0.81974026
A31: 25 | B31: 236 | C31: 109 | D31: 110 | E31: 2.93 | F31: 33 | G31: 37.4 | H31: 35 | I31: 3.41 | J31: 15 | K31: 0.51 | L31: 0.42 | M31: 7.66 | N31: 25 | O31: 2.2 | P31: 5 | Q31: 0.15 | R31: 0.36 | S31: 6.71 | T31: 78.2 | U31: <20 | W31: =1-S31/G31 -> 0.82058824
A32: 26 | B32: 220 | C32: 102 | D32: 82 | E32: 2.19 | F32: 18.1 | G32: 29.2 | H32: 30 | I32: 3.07 | J32: 13 | K32: 0.51 | L32: 0.31 | M32: 9 | N32: 27 | O32: 2.61 | P32: 5 | Q32: 0.17 | R32: 0.29 | S32: 8.68 | T32: 78.3 | U32: <20 | W32: =1-S32/G32 -> 0.70273973
A33: 27 | B33: 254 | C33: 116 | D33: 88 | E33: 1.88 | F33: 22.9 | G33: 29.1 | H33: 31 | I33: 3.11 | J33: 14 | K33: 0.52 | L33: 0.44 | M33: 8.06 | N33: 26 | O33: 2.45 | P33: 5 | Q33: 0.15 | R33: 0.43 | S33: 7.94 | T33: 78.1 | U33: <20 | W33: =1-S33/G33 -> 0.72714777
A34: 28 | B34: 204 | C34: 93.1 | D34: 132 | E34: 2.74 | F34: 27 | G34: 32.3 | H34: 42 | I34: 4.01 | J34: 18 | K34: 0.51 | L34: 0.39 | M34: 10.7 | N34: 22 | O34: 2.58 | P34: 6 | Q34: 0.13 | R34: 0.29 | S34: 8.78 | T34: 78.3 | U34: <20 | W34: =1-S34/G34 -> 0.72817337
A35: 29 | B35: 258 | C35: 118 | D35: 152 | E35: 3.28 | F35: 29 | G35: 36.2 | H35: 38 | I35: 3.37 | J35: 16 | K35: 0.55 | L35: 0.25 | M35: 8.06 | N35: 26 | O35: 2.58 | P35: 5 | Q35: 0.15 | R35: 0.24 | S35: 7.88 | T35: 78.5 | U35: <20 | W35: =1-S35/G35 -> 0.78232044
A36: 30 | B36: 178 | C36: 82.2 | D36: 104 | E36: 2.1 | F36: 25.4 | G36: 31.3 | H36: 37 | I36: 3.33 | J36: 16 | K36: 0.51 | L36: 0.42 | M36: 8.01 | N36: 23 | O36: 2.76 | P36: 5 | Q36: 0.14 | R36: 0.37 | S36: 6.88 | T36: 78.4 | U36: <20 | W36: =1-S36/G36 -> 0.78019169
A37: 31 | B37: 394 | C37: 180 | D37: 134 | E37: 2.61 | F37: 31.7 | G37: 37.2 | H37: 30 | I37: 2.96 | J37: 12 | K37: 0.5 | L37: 0.44 | M37: 7.76 | N37: 23 | O37: 2.47 | P37: 5 | Q37: 0.13 | R37: 0.29 | S37: 7.54 | T37: 78.2 | U37: <20 | W37: =1-S37/G37 -> 0.79731183
A38: 平均 | B38: =ROUND(AVERAGE(B7:B37),0) -> 212 | C38: =ROUND(AVERAGE(C7:C37),0) -> 97 | D38: =ROUND(AVERAGE(D7:D37),0) -> 114 | E38: =ROUND(AVERAGE(E7:E37),2) -> 2.63 | F38: =ROUND(AVERAGE(F7:F37),1) -> 23.7 | G38: =ROUND(AVERAGE(G7:G37),1) -> 30.3 | H38: =ROUND(AVERAGE(H7:H37),1) -> 31.8 | I38: =ROUND(AVERAGE(I7:I37),2) -> 3.11 | J38: =ROUND(AVERAGE(J7:J37),2) -> 14.81 | K38: =ROUND(AVERAGE(K7:K37),2) -> 0.53 | L38: =ROUND(AVERAGE(L7:L37),2) -> 0.4 | M38: =ROUND(AVERAGE(M7:M37),1) -> 8 | N38: =ROUND(AVERAGE(N7:N37),1) -> 21.8 | O38: =ROUND(AVERAGE(O7:O37),2) -> 2.42 | P38: =ROUND(AVERAGE(P7:P37),2) -> 5.29 | Q38: =ROUND(AVERAGE(Q7:Q37),2) -> 0.17 | R38: =ROUND(AVERAGE(R7:R37),2) -> 0.33 | S38: =ROUND(AVERAGE(S7:S37),2) -> 7.07 | T38: =ROUND(AVERAGE(T7:T37),2) -> 78.25 | U38: <20
A39: 审核： | J39: 制表： | Q39: 制表时间：2022/11/2
B41: 项目 | C41: 进水（mg/L) | D41: 最大值 | E41: 最小值（mg/L) | F41: 出水（mg/L) | G41: 最大值 | H41: 最小值（mg/L) | I41: 去除率
D42: （mg/L) | G42: （mg/L) | I42: （%）
...

Sheet 设备
A1: 常州市深水江边污水处理有限公司设备运行月报表
A2: 44835
A3: 运行 工段 | B3: 设备名称 | C3: 编号 | D3: 运行 天数 | E3: 定时 | F3: 额定运行时间 | G3: 实际运行时间 | H3: 利用率 | I3: 完好率 | J3: 维修、保养情况
D5: （d） | E5: （h/d） | F5: （h） | G5: （h） | H5: % | I5: %
A6: 预 处 理 | B6: 粗格栅机 | C6: 1# | D6: 31 | E6: 2 | F6: 62 | G6: 31 | H6: 0.5 | I6: 1
C7: 2# | D7: 31 | E7: 2 | F7: 62 | G7: 31 | H7: 0.5 | I7: 1
B8: 螺旋输送机 | C8: / | D8: 31 | E8: 2 | F8: 62 | G8: 31 | H8: 0.5 | I8: 1
B9: 螺旋压榨机 | C9: / | D9: 31 | E9: 2 | F9: 62 | G9: 31 | H9: 0.5 | I9: 1
B10: 进水泵 | C10: 1# | D10: 31 | E10: 24 | F10: 744 | G10: 55 | H10: 0.073924731 | I10: 1 | J10: 27日更换保护板
C11: 2# | D11: 31 | E11: 24 | F11: 744 | G11: 414 | H11: 0.55645161 | I11: 0.94 | J11: 18日-19日修理
C12: 3# | D12: 31 | E12: 24 | F12: 744 | G12: 544 | H12: 0.7311828 | I12: 1
C13: 4# | D13: 31 | E13: 24 | F13: 744 | G13: 248 | H13: 0.33333333 | I13: 1
C14: 5# | D14: 31 | E14: 24 | F14: 744 | G14: 738 | H14: 0.99193548 | I14: 1
B15: 细格栅机 | C15: 1# | D15: 31 | E15: 2.4 | F15: 74.4 | G15: 74.4 | H15: 1 | I15: 1
C16: 2# | D16: 31 | E16: 2.4 | F16: 74.4 | G16: 74.4 | H16: 1 | I16: 1
C17: 3# | D17: 31 | E17: 2.4 | F17: 74.4 | G17: 74.4 | H17: 1 | I17: 1
C18: 4# | D18: 31 | E18: 2.4 | F18: 74.4 | G18: 74.4 | H18: 1 | I18: 1
C19: 5# | D19: 31 | E19: 2.4 | F19: 74.4 | G19: 21.6 | H19: 0.29 | I19: 0.29 | J19: 10日坏发外修理
C20: 6# | D20: 31 | E20: 2.4 | F20: 74.4 | G20: 74.4 | H20: 1 | I20: 1
B21: 螺旋输送机 | C21: 1# | D21: 31 | E21: 2 | F21: 62 | G21: 15.5 | H21: 0.25 | I21: 1
C22: 2# | D22: 31 | E22: 2 | F22: 62 | G22: 15.5 | H22: 0.25 | I22: 1
B23: 螺旋压榨机 | C23: 1# | D23: 31 | E23: 2 | F23: 62 | G23: 15.5 | H23: 0.25 | I23: 1
C24: 2# | D24: 31 | E24: 2 | F24: 62 | G24: 15.5 | H24: 0.25 | I24: 1
B25: 搅拌机 | C25: 1# | D25: 31 | E25: 24 | F25: 744 | G25: 15.5 | H25: 0.020833333 | I25: 1
B26: 砂水分离机 | C26: 1# | D26: 31 | E26: 0.5 | F26: 15.5 | G26: 15.5 | H26: 1 | I26: 1
B27: 搅拌机 | C27: 2# | D27: 31 | E27: 24 | F27: 744 | G27: 0 | H27: 0 | I27: 1
B28: 砂水分离机 | C28: 2# | D28: 31 | E28: 0.5 | F28: 15.5 | G28: 15.5 | H28: 1 | I28: 1
B29: 搅拌机 | C29: 3# | D29: 31 | E29: 24 | F29: 744 | G29: 744 | H29: 1 | I29: 1
B30: 砂水分离机 | C30: 3# | D30: 31 | E30: 0.5 | F30: 15.5 | G30: 15.5 | H30: 1 | I30: 1
B31: 搅拌机 | C31: 4# | D31: 31 | E31: 24 | F31: 744 | G31: 0 | H31: 0 | I31: 1
B32: 砂水分离机 | C32: 4# | D32: 31 | E32: 0.5 | F32: 15.5 | G32: 15.5 | H32: 1 | I32: 1
B33: 高压鼓风机 | C33: 1# | D33: 31 | E33: 24 | F33: 744 | G33: 0 | H33: 0 | I33: 1
C34: 2# | D34: 31 | E34: 24 | F34: 744 | G34: 324 | H34: 0.43548387 | I34: 1
C35: 3# | D35: 31 | E35: 24 | F35: 744 | G35: 466 | H35: 0.62634409 | I35: 1 | J35: 26日更换滤网
C36: 4# | D36: 31 | E36: 24 | F36: 744 | G36: 164 | H36: 0.22043011 | I36: 0.99 | J36: 2日更换模块
C37: 5# | D37: 31 | E37: 24 | F37: 744 | G37: 534 | H37: 0.71774194 | I37: 1
A38: 审核： | E38: 制表： | H38: 制表时间：2022/11/4
A46: 常州市深水江边污水处理有限公司设备运行月报表
A47: =A2 -> 44835
A48: 运行 工段 | B48: 设备名称 | C48: 编号 | D48: 运行 天数 | E48: 定时 | F48: 额定运行时间 | G48: 实际运行时间 | H48: 利用率 | I48: 完好率 | J48: 维修、保养情况
...

Sheet 仪表
A1: 常州市深水江边污水处理有限公司污水运行月报表
D2: 44835
A3: 仪表名称 | B3: 编号 | C3: 规格型号 | D3: 安装位置 | E3: 运行情况 | F3: 标定、校准情况 | G3: 备注
A4: 一期溶氧仪 | B4: 1#（南） | C4: 美商生化T-10 | D4: 一期生反池 | E4: 正常 | F4: 校准 | G4: 2022-10-07 2022-10-14 2022-10-21 2022-10-28
B5: 2#（南） | C5: 美商生化T-10 | D5: 一期生反池 | E5: 正常 | F5: 校准 | G5: =G4 -> 2022-10-07 2022-10-14 2022-10-21 2022-10-28
B6: 1#（北） | C6: 美商生化T-10 | D6: 一期生反池 | E6: 正常 | F6: 校准 | G6: =G5 -> 2022-10-07 2022-10-14 2022-10-21 2022-10-28
B7: 2#（北） | C7: 美商生化T-10 | D7: 一期生反池 | E7: 正常 | F7: 校准 | G7: =G6 -> 2022-10-07 2022-10-14 2022-10-21 2022-10-28
A8: 一期污泥浓度计 | B8: 1#（南） | C8: E+H | D8: 一期生反池 | E8: 正常 | F8: 校准 | G8: =G7 -> 2022-10-07 2022-10-14 2022-10-21 2022-10-28
B9: 2#（南） | C9: E+H | D9: 一期生反池 | E9: 正常 | F9: 校准 | G9: =G8 -> 2022-10-07 2022-10-14 2022-10-21 2022-10-28
B10: 1#（北） | C10: E+H | D10: 一期生反池 | E10: 正常 | F10: 校准 | G10: =G9 -> 2022-10-07 2022-10-14 2022-10-21 2022-10-28
B11: 2#（北） | C11: E+H | D11: 一期生反池 | E11: 正常 | F11: 校准 | G11: =G10 -> 2022-10-07 2022-10-14 2022-10-21 2022-10-28
A12: 进水PH计 | B12: 1# | C12: 哈希 | D12: 一期旋流沉砂池 | E12: 正常 | F12: 标定 | G12: =G11 -> 2022-10-07 2022-10-14 2022-10-21 2022-10-28
A13: 二期溶氧仪 | B13: 1#（南） | C13: 哈希LDO | D13: 二期生反池 | E13: 正常 | F13: 校准 | G13: =G12 -> 2022-10-07 2022-10-14 2022-10-21 2022-10-28
B14: 2#（南） | C14: 哈希LDO | D14: 二期生反池 | E14: 正常 | F14: 校准 | G14: =G13 -> 2022-10-07 2022-10-14 2022-10-21 2022-10-28
B15: 1#（北） | C15: 哈希LDO | D15: 二期生反池 | E15: 正常 | F15: 校准 | G15: =G14 -> 2022-10-07 2022-10-14 2022-10-21 2022-10-28
B16: 2#（北） | C16: 哈希LDO | D16: 二期生反池 | E16: 正常 | F16: 校准 | G16: =G15 -> 2022-10-07 2022-10-14 2022-10-21 2022-10-28
A17: 二期污泥浓度计 | B17: 1#（南） | C17: 哈希TXPRO-2 | D17: 二期生反池 | E17: 正常 | F17: 校准 | G17: =G16 -> 2022-10-07 2022-10-14 2022-10-21 2022-10-28
B18: 2#（南） | C18: E+H | D18: 二期生反池 | E18: 正常 | F18: 校准 | G18: =G17 -> 2022-10-07 2022-10-14 2022-10-21 2022-10-28
B19: 1#（北） | C19: 哈希TXPRO-2 | D19: 二期生反池 | E19: 正常 | F19: 校准 | G19: =G18 -> 2022-10-07 2022-10-14 2022-10-21 2022-10-28
B20: 2#（北） | C20: E+H | D20: 二期生反池 | E20: 正常 | F20: 校准 | G20: =G19 -> 2022-10-07 2022-10-14 2022-10-21 2022-10-28
A21: 审核： | D21: 制表： | F21: 制表日期：2022/11/4
A25: 常州市深水江边污水处理有限公司污水运行月报表
D26: =D2 -> 44835
A27: 仪表名称 | B27: 编号 | C27: 规格型号 | D27: 安装位置 | E27: 运行情况 | F27: 标定、校准情况 | G27: 备注
A28: 一期ORP | B28: 1#（南） | C28: E+H | D28: 一期生反池 | E28: 正常 | F28: 标定 | G28: 44851
B29: 2#（北） | C29: E+H | D29: 一期生反池 | E29: 正常 | F29: 标定 | G29: =G28 -> 44851
A30: 二期ORP | B30: 1#（南） | C30: 哈希 | D30: 二期生反池 | E30: 正常 | F30: 标定 | G30: =G29 -> 44851
B31: 2#（北） | C31: 哈希 | D31: 二期生反池 | E31: 正常 | F31: 标定 | G31: =G30 -> 44851
A32: 审核： | D32: 制表： | F32: =F21 -> 制表日期：2022/11/4

Sheet 实验数据
A1: 常州市深水江边污水处理有限公司实验数据汇总表
A3: 采样地点：一期北 | E3: 采样时间：2022-10-22
A4: 硝化实验 | E4: 反硝化实验 | G4: 释磷实验
A5: 时间节点 | B5: NO3-N(mg/l) | C5: NH3-N(mg/l) | D5: PO43-(mg/l) | E5: 时间节点 | F5: NO3-N(mg/l) | G5: 时间节点 | H5: PO43-(mg/l)
A6: 0分钟 | B6: 1.23 | C6: 6.53 | D6: 2.03 | E6: 0分钟 | F6: 5.98 | G6: 0分钟 | H6: 2.13
A7: 15分钟 | B7: 2.38 | C7: 4.21 | D7: 1.25 | E7: 15分钟 | F7: 5.52 | G7: 30分钟 | H7: 2.58
A8: 30分钟 | B8: 4.26 | C8: 2.18 | D8: 0.62 | E8: 30分钟 | F8: 4.11 | G8: 60分钟 | H8: 3.84
A9: 60分钟 | B9: 6.33 | C9: 1.34 | D9: 0.33 | E9: 45分钟 | F9: 2.54 | G9: 90分钟 | H9: 4.98
A10: MLSS(mg/l) | B10: 4424 | E10: 60分钟 | F10: 1.83 | G10: MLSS(mg/l) | H10: 3822
E11: 90分钟 | F11: 1.12
E12: MLSS(mg/l) | F12: 5244
A13: 审核： | D13: 制表： | G13: 制表日期：2022/11/4
