Workbook

Sheet 处理量
A1: 常州市深水江边污水处理有限公司污水处理运行月报表 | V1: 1577700 | W1: 1012264.7
A2: 45231
A3: 日 期 | B3: 水温 | C3: 天气 | D3: 日处理水量 （m3） | E3: 污泥量（T） | H3: 药剂量 | I3: MLSS | J3: 电耗 | K3: 混凝剂 | L3: 絮凝剂 阴离子 （kg） | M3: 盐酸 | N3: 氯酸钠 | O3: 乙酸（吨） | Q3: 回用水 （m3） | R3: 实际水量（m3） | T3: 费用统计 | U3: 成本分析用 | W3: 单价 | X3: 单耗 | Y3: 之前价 | Z3: 最新时间 | AD3: PAC | AE3: PAM阳 | AF3: PAM阴 | AG3: HCL | AH3: NACLO3 | AI3: 合计 | AK3: 干泥量 | AL3: 单耗
B4: 度 | C4: 状况 | E4: 国电 | F4: 英科环境 | G4: 其他 | H4: （Kg） | I4: （mg/l） | J4: ( 度 ) | K4: （Kg） | M4: （Kg） | N4: （Kg） | O4: 缺氧段 | P4: 提标段 | T4: 电量 | U4: =ROUND(J36*W4,2) -> 1016755.9 | W4: =W1/V1 -> 0.64160783 | X4: =J35/R35 -> 0.28286612 | Y4: 0.67841211 | Z4: 44929 | AB4: 污泥量合计
A5: 1 | B5: 26.5 | C5: 晴 | D5: 185684 | E5: 0 | F5: 159.62 | G5: 0 | H5: 75 | I5: 3576 | J5: 48000 | K5: 12264 | L5: 0 | M5: 0 | N5: 0 | O5: 1.98 | P5: 0 | Q5: 0 | R5: =D5-Q5 -> 185684 | S5: =O5*1000 -> 1980 | T5: 聚丙烯酰阳离子 | U5: =H36*W5/1000 -> 87500 | W5: 28000 | X5: =H35/R35*1000 -> 0.55780691 | Y5: 28000 | Z5: 44656 | AA5: =J5*$W$4 -> 30797.176 | AB5: =E5+F5+G5 -> 159.62 | AD5: =$W$9*K5/1000/R5 -> 0.027475841 | AE5: =$W$5*H5/1000/R5 -> 0.011309537 | AF5: =$W$6*L5/1000/R5 -> 0 | AG5: =$W$7*M5/1000/R5 -> 0 | AH5: =$W$8*N5/1000/R5 -> 0 | AI5: =AD5+AE5+AF5+AG5+AH5 -> 0.038785377 | AJ5: =AI5*R5 -> 7201.824 | AK5: =AB5*(100-进出水!T7)/100 -> 34.3183 | AL5: =H5/AK5 -> 2.1854229
A6: 2 | B6: 26.1 | C6: 晴 | D6: 204615 | E6: 0 | F6: 91.06 | G6: 0 | H6: 100 | I6: 4368 | J6: 50000 | K6: 11304 | L6: 0 | M6: 0 | N6: 0 | O6: 1.32 | P6: 0 | Q6: 0 | R6: =D6-Q6 -> 204615 | S6: =O6*1000 -> 1320 | T6: 聚丙烯酰阴离子 | U6: =L36*W6/1000 -> 0 | V6: =U5+U6 -> 87500 | W6: 10400 | X6: =L35/R35*1000 -> 0 | Y6: 10400 | Z6: 44656 | AA6: =J6*$W$4 -> 32080.392 | AB6: =E6+F6+G6 -> 91.06 | AD6: =$W$9*K6/1000/R6 -> 0.02298201 | AE6: =$W$5*H6/1000/R6 -> 0.013684236 | AF6: =$W$6*L6/1000/R6 -> 0 | AG6: =$W$7*M6/1000/R6 -> 0 | AH6: =$W$8*N6/1000/R6 -> 0 | AI6: =AD6+AE6+AF6+AG6+AH6 -> 0.036666246 | AJ6: =AI6*R6 -> 7502.464 | AK6: =AB6*(100-进出水!T8)/100 -> 19.76002 | AL6: =H6/AK6 -> 5.0607236
A7: 3 | B7: 26.2 | C7: 晴 | D7: 202679 | E7: 0 | F7: 104.98 | G7: 0 | H7: 100 | I7: 3232 | J7: 50500 | K7: 11616 | L7: 0 | M7: 0 | N7: 0 | O7: 1.8 | P7: 0 | Q7: 0 | R7: =D7-Q7 -> 202679 | S7: =O7*1000 -> 1800 | T7: 工业盐酸 | U7: =M36*W7/1000 -> 12693.096 | W7: 468 | X7: =M35/R35*1000 -> 4.8412285 | Y7: 445 | Z7: 44656 | AA7: =J7*$W$4 -> 32401.196 | AB7: =E7+F7+G7 -> 104.98 | AD7: =$W$9*K7/1000/R7 -> 0.023841918 | AE7: =$W$5*H7/1000/R7 -> 0.013814949 | AF7: =$W$6*L7/1000/R7 -> 0 | AG7: =$W$7*M7/1000/R7 -> 0 | AH7: =$W$8*N7/1000/R7 -> 0 | AI7: =AD7+AE7+AF7+AG7+AH7 -> 0.037656866 | AJ7: =AI7*R7 -> 7632.256 | AK7: =AB7*(100-进出水!T9)/100 -> 22.67568 | AL7: =H7/AK7 -> 4.4100111
A8: 4 | B8: 25.8 | C8: 晴 | D8: 200081 | E8: 0 | F8: 106.04 | G8: 0 | H8: 75 | I8: 4106 | J8: 51400 | K8: 8304 | L8: 0 | M8: 0 | N8: 0 | O8: 2.16 | P8: 0 | Q8: 0 | R8: =D8-Q8 -> 200081 | S8: =O8*1000 -> 2160 | T8: 工业氯酸钠 | U8: =N36*W8/1000 -> 50017.272 | V8: =U7+U8 -> 62710.368 | W8: 5773 | X8: =N35/R35*1000 -> 1.5465085 | Y8: 6495 | Z8: 44900 | AA8: =J8*$W$4 -> 32978.643 | AB8: =E8+F8+G8 -> 106.04 | AD8: =$W$9*K8/1000/R8 -> 0.017265328 | AE8: =$W$5*H8/1000/R8 -> 0.010495749 | AF8: =$W$6*L8/1000/R8 -> 0 | AG8: =$W$7*M8/1000/R8 -> 0 | AH8: =$W$8*N8/1000/R8 -> 0 | AI8: =AD8+AE8+AF8+AG8+AH8 -> 0.027761077 | AJ8: =AI8*R8 -> 5554.464 | AK8: =AB8*(100-进出水!T10)/100 -> 23.01068 | AL8: =H8/AK8 -> 3.2593561
A9: 5 | B9: 26.3 | C9: 晴 | D9: 209249 | E9: 0 | F9: 119.98 | G9: 0 | H9: 100 | I9: 3706 | J9: 55200 | K9: 12276 | L9: 0 | M9: 0 | N9: 0 | O9: 2.34 | P9: 0 | Q9: 0 | R9: =D9-Q9 -> 209249 | S9: =O9*1000 -> 2340 | T9: 混凝药剂 | U9: =K36*W9/1000 -> 75209.472 | W9: 416 | X9: =K35/R35*1000 -> 32.271049 | Y9: 526 | Z9: 44656 | AA9: =J9*$W$4 -> 35416.752 | AB9: =E9+F9+G9 -> 119.98 | AD9: =$W$9*K9/1000/R9 -> 0.02440545 | AE9: =$W$5*H9/1000/R9 -> 0.013381187 | AF9: =$W$6*L9/1000/R9 -> 0 | AG9: =$W$7*M9/1000/R9 -> 0 | AH9: =$W$8*N9/1000/R9 -> 0 | AI9: =AD9+AE9+AF9+AG9+AH9 -> 0.037786637 | AJ9: =AI9*R9 -> 7906.816 | AK9: =AB9*(100-进出水!T11)/100 -> 25.67572 | AL9: =H9/AK9 -> 3.8947301
A10: 6 | B10: 25.6 | C10: 晴 | D10: 191662 | E10: 0 | F10: 32.28 | G10: 30 | H10: 75 | I10: 3256 | J10: 53200 | K10: 0 | L10: 0 | M10: 0 | N10: 0 | O10: 2.22 | P10: 0 | Q10: 0 | R10: =D10-Q10 -> 191662 | S10: =O10*1000 -> 2220 | T10: 污泥外运 | U10: =T18 -> 32897.86 | V10: 计算见下表 | AA10: =J10*$W$4 -> 34133.537 | AB10: =E10+F10+G10 -> 62.28 | AD10: =$W$9*K10/1000/R10 -> 0 | AE10: =$W$5*H10/1000/R10 -> 0.010956789 | AF10: =$W$6*L10/1000/R10 -> 0 | AG10: =$W$7*M10/1000/R10 -> 0 | AH10: =$W$8*N10/1000/R10 -> 0 | AI10: =AD10+AE10+AF10+AG10+AH10 -> 0.010956789 | AJ10: =AI10*R10 -> 2100 | AK10: =AB10*(100-进出水!T12)/100 -> 13.14108 | AL10: =H10/AK10 -> 5.7072935
A11: 7 | B11: 25.4 | C11: 晴 | D11: 162807 | E11: 121.2 | F11: 0 | G11: 0 | H11: 100 | I11: 3396 | J11: 46500 | K11: 936 | L11: 0 | M11: 0 | N11: 0 | O11: 2.22 | P11: 0 | Q11: 2 | R11: =D11-Q11 -> 162805 | S11: =O11*1000 -> 2220 | T11: 自来水 | U11: =汇总!J5*4.2 -> 18190.2 | W11: 4.2 | AA11: =J11*$W$4 -> 29834.764 | AB11: =E11+F11+G11 -> 121.2 | AD11: =$W$9*K11/1000/R11 -> 0.002391671 | AE11: =$W$5*H11/1000/R11 -> 0.017198489 | AF11: =$W$6*L11/1000/R11 -> 0 | AG11: =$W$7*M11/1000/R11 -> 0 | AH11: =$W$8*N11/1000/R11 -> 0 | AI11: =AD11+AE11+AF11+AG11+AH11 -> 0.01959016 | AJ11: =AI11*R11 -> 3189.376 | AK11: =AB11*(100-进出水!T13)/100 -> 25.6944 | AL11: =H11/AK11 -> 3.8918986
A12: 8 | B12: 25.1 | C12: 晴 | D12: 197085 | E12: 0 | F12: 104.98 | G12: 15 | H12: 75 | I12: 4342 | J12: 52300 | K12: 0 | L12: 0 | M12: 0 | N12: 0 | O12: 2.22 | P12: 0 | Q12: 0 | R12: =D12-Q12 -> 197085 | S12: =O12*1000 -> 2220 | AA12: =J12*$W$4 -> 33556.09 | AB12: =E12+F12+G12 -> 119.98 | AD12: =$W$9*K12/1000/R12 -> 0 | AE12: =$W$5*H12/1000/R12 -> 0.010655301 | AF12: =$W$6*L12/1000/R12 -> 0 | AG12: =$W$7*M12/1000/R12 -> 0 | AH12: =$W$8*N12/1000/R12 -> 0 | AI12: =AD12+AE12+AF12+AG12+AH12 -> 0.010655301 | AJ12: =AI12*R12 -> 2100 | AK12: =AB12*(100-进出水!T14)/100 -> 25.7957 | AL12: =H12/AK12 -> 2.9074613
A13: 9 | B13: 25 | C13: 阴 | D13: 190664 | E13: 17.34 | F13: 66.66 | G13: 0 | H13: 100 | I13: 4472 | J13: 53700 | K13: 0 | L13: 0 | M13: 0 | N13: 0 | O13: 2.28 | P13: 0 | Q13: 294 | R13: =D13-Q13 -> 190370 | S13: =O13*1000 -> 2280 | U13: =U14/R36 -> 0.040237038 | AA13: =J13*$W$4 -> 34454.341 | AB13: =E13+F13+G13 -> 84 | AD13: =$W$9*K13/1000/R13 -> 0 | AE13: =$W$5*H13/1000/R13 -> 0.0147082 | AF13: =$W$6*L13/1000/R13 -> 0 | AG13: =$W$7*M13/1000/R13 -> 0 | AH13: =$W$8*N13/1000/R13 -> 0 | AI13: =AD13+AE13+AF13+AG13+AH13 -> 0.0147082 | AJ13: =AI13*R13 -> 2800 | AK13: =AB13*(100-进出水!T15)/100 -> 17.976 | AL13: =H13/AK13 -> 5.5629729
A14: 10 | B14: 24.9 | C14: 雨 | D14: 194129 | E14: 35.14 | F14: 68.7 | G14: 0 | H14: 75 | I14: 4248 | J14: 53900 | K14: 0 | L14: 0 | M14: 0 | N14: 0 | O14: 2.16 | P14: 0 | Q14: 0 | R14: =D14-Q14 -> 194129 | S14: =O14*1000 -> 2160 | T14: 总药剂 | U14: =U5+U6+U7+U8+U9 -> 225419.84 | V14: 除磷药剂 | W14: =U6+U9 -> 75209.472 | AA14: =J14*$W$4 -> 34582.662 | AB14: =E14+F14+G14 -> 103.84 | AD14: =$W$9*K14/1000/R14 -> 0 | AE14: =$W$5*H14/1000/R14 -> 0.010817549 | AF14: =$W$6*L14/1000/R14 -> 0 | AG14: =$W$7*M14/1000/R14 -> 0 | AH14: =$W$8*N14/1000/R14 -> 0 | AI14: =AD14+AE14+AF14+AG14+AH14 -> 0.010817549 | AJ14: =AI14*R14 -> 2100 | AK14: =AB14*(100-进出水!T16)/100 -> 21.91024 | AL14: =H14/AK14 -> 3.423057
A15: 11 | B15: 24.7 | C15: 多云 | D15: 193419 | E15: 52.98 | F15: 53.66 | G15: 0 | H15: 75 | I15: 4836 | J15: 53200 | K15: 0 | L15: 0 | M15: 0 | N15: 0 | O15: 2.18 | P15: 0 | Q15: 0 | R15: =D15-Q15 -> 193419 | S15: =O15*1000 -> 2180 | T15: 总泥量 | U15: 英科（吨） | V15: 国电（吨） | W15: 外运（吨） | AA15: =J15*$W$4 -> 34133.537 | AB15: =E15+F15+G15 -> 106.64 | AD15: =$W$9*K15/1000/R15 -> 0 | AE15: =$W$5*H15/1000/R15 -> 0.010857258 | AF15: =$W$6*L15/1000/R15 -> 0 | AG15: =$W$7*M15/1000/R15 -> 0 | AH15: =$W$8*N15/1000/R15 -> 0 | AI15: =AD15+AE15+AF15+AG15+AH15 -> 0.010857258 | AJ15: =AI15*R15 -> 2100 | AK15: =AB15*(100-进出水!T17)/100 -> 22.82096 | AL15: =H15/AK15 -> 3.2864525
A16: 12 | B16: 24 | C16: 阴 | D16: 184541 | E16: 0 | F16: 104.2 | G16: 0 | H16: 100 | I16: 3932 | J16: 53700 | K16: 0 | L16: 0 | M16: 0 | N16: 0 | O16: 2.7 | P16: 0 | Q16: 151 | R16: =D16-Q16 -> 184390 | S16: =O16*1000 -> 2700 | T16: =U16+V16+W16 -> 3535.1 | U16: =F36 -> 3200.2 | V16: =E36 -> 226.66 | W16: =G36 -> 108.24 | AA16: =J16*$W$4 -> 34454.341 | AB16: =E16+F16+G16 -> 104.2 | AD16: =$W$9*K16/1000/R16 -> 0 | AE16: =$W$5*H16/1000/R16 -> 0.015185205 | AF16: =$W$6*L16/1000/R16 -> 0 | AG16: =$W$7*M16/1000/R16 -> 0 | AH16: =$W$8*N16/1000/R16 -> 0 | AI16: =AD16+AE16+AF16+AG16+AH16 -> 0.015185205 | AJ16: =AI16*R16 -> 2800 | AK16: =AB16*(100-进出水!T18)/100 -> 22.0904 | AL16: =H16/AK16 -> 4.5268533
A17: 13 | B17: 23.6 | C17: 晴 | D17: 188675 | E17: 0 | F17: 125.98 | G17: 0 | H17: 75 | I17: 3442 | J17: 52700 | K17: 0 | L17: 0 | M17: 0 | N17: 0 | O17: 2.22 | P17: 0 | Q17: 0 | R17: =D17-Q17 -> 188675 | S17: =O17*1000 -> 2220 | T17: 江边费用 | U17: 9.6 | V17: 9.6 | AA17: =J17*$W$4 -> 33812.733 | AB17: =E17+F17+G17 -> 125.98 | AD17: =$W$9*K17/1000/R17 -> 0 | AE17: =$W$5*H17/1000/R17 -> 0.01113025 | AF17: =$W$6*L17/1000/R17 -> 0 | AG17: =$W$7*M17/1000/R17 -> 0 | AH17: =$W$8*N17/1000/R17 -> 0 | AI17: =AD17+AE17+AF17+AG17+AH17 -> 0.01113025 | AJ17: =AI17*R17 -> 2100 | AK17: =AB17*(100-进出水!T19)/100 -> 27.46364 | AL17: =H17/AK17 -> 2.7308835
A18: 14 | B18: 23.1 | C18: 晴 | D18: 200801 | E18: 0 | F18: 110.04 | G18: 0 | H18: 100 | I18: 4010 | J18: 54200 | K18: 0 | L18: 0 | M18: 0 | N18: 0 | O18: 3.3 | P18: 0 | Q18: 0 | R18: =D18-Q18 -> 200801 | S18: =O18*1000 -> 3300 | T18: =U18+V18 -> 32897.86 | U18: =ROUND(U16*U17,2) -> 30721.92 | V18: =ROUND(V16*V17,2) -> 2175.94 | AA18: =J18*$W$4 -> 34775.145 | AB18: =E18+F18+G18 -> 110.04 | AD18: =$W$9*K18/1000/R18 -> 0 | AE18: =$W$5*H18/1000/R18 -> 0.013944154 | AF18: =$W$6*L18/1000/R18 -> 0 | AG18: =$W$7*M18/1000/R18 -> 0 | AH18: =$W$8*N18/1000/R18 -> 0 | AI18: =AD18+AE18+AF18+AG18+AH18 -> 0.013944154 | AJ18: =AI18*R18 -> 2800 | AK18: =AB18*(100-进出水!T20)/100 -> 23.76864 | AL18: =H18/AK18 -> 4.2072243
A19: 15 | B19: 23.4 | C19: 晴 | D19: 175404 | E19: 0 | F19: 108.74 | G19: 0 | H19: 75 | I19: 4232 | J19: 50500 | K19: 0 | L19: 0 | M19: 0 | N19: 0 | O19: 4.44 | P19: 0 | Q19: 0 | R19: =D19-Q19 -> 175404 | S19: =O19*1000 -> 4440 | T19: 排水承担 | V19: 0 | AA19: =J19*$W$4 -> 32401.196 | AB19: =E19+F19+G19 -> 108.74 | AD19: =$W$9*K19/1000/R19 -> 0 | AE19: =$W$5*H19/1000/R19 -> 0.011972361 | AF19: =$W$6*L19/1000/R19 -> 0 | AG19: =$W$7*M19/1000/R19 -> 0 | AH19: =$W$8*N19/1000/R19 -> 0 | AI19: =AD19+AE19+AF19+AG19+AH19 -> 0.011972361 | AJ19: =AI19*R19 -> 2100 | AK19: =AB19*(100-进出水!T21)/100 -> 23.3791 | AL19: =H19/AK19 -> 3.2079935
A20: 16 | B20: 23.1 | C20: 晴 | D20: 200014 | E20: 0 | F20: 100.46 | G20: 0 | H20: 100 | I20: 4474 | J20: 53100 | K20: 8160 | L20: 0 | M20: 0 | N20: 0 | O20: 4.2 | P20: 0 | Q20: 0 | R20: =D20-Q20 -> 200014 | S20: =O20*1000 -> 4200 | T20: =U20+V20 -> 0 | V20: =ROUND(V16*V19,2) -> 0 | AA20: =J20*$W$4 -> 34069.376 | AB20: =E20+F20+G20 -> 100.46 | AD20: =$W$9*K20/1000/R20 -> 0.016971612 | AE20: =$W$5*H20/1000/R20 -> 0.01399902 | AF20: =$W$6*L20/1000/R20 -> 0 | AG20: =$W$7*M20/1000/R20 -> 0 | AH20: =$W$8*N20/1000/R20 -> 0 | AI20: =AD20+AE20+AF20+AG20+AH20 -> 0.030970632 | AJ20: =AI20*R20 -> 6194.56 | AK20: =AB20*(100-进出水!T22)/100 -> 21.29752 | AL20: =H20/AK20 -> 4.6953824
A21: 17 | B21: 23.2 | C21: 晴 | D21: 194201 | E21: 0 | F21: 122 | G21: 0 | H21: 75 | I21: 4450 | J21: 53200 | K21: 13008 | L21: 0 | M21: 0 | N21: 0 | O21: 3.36 | P21: 0 | Q21: 0 | R21: =D21-Q21 -> 194201 | S21: =O21*1000 -> 3360 | T21: 总运费 | U21: 总单价 | V21: =V17+V19 -> 9.6 | W21: 核对 | AA21: =J21*$W$4 -> 34133.537 | AB21: =E21+F21+G21 -> 122 | AD21: =$W$9*K21/1000/R21 -> 0.027864573 | AE21: =$W$5*H21/1000/R21 -> 0.010813539 | AF21: =$W$6*L21/1000/R21 -> 0 | AG21: =$W$7*M21/1000/R21 -> 0 | AH21: =$W$8*N21/1000/R21 -> 0 | AI21: =AD21+AE21+AF21+AG21+AH21 -> 0.038678112 | AJ21: =AI21*R21 -> 7511.328 | AK21: =AB21*(100-进出水!T23)/100 -> 26.23 | AL21: =H21/AK21 -> 2.8593214
A22: 18 | B22: 23.1 | C22: 晴 | D22: 181019 | E22: 0 | F22: 105.14 | G22: 0 | H22: 75 | I22: 4210 | J22: 51400 | K22: 12696 | L22: 0 | M22: 0 | N22: 0 | O22: 2.1 | P22: 0 | Q22: 0 | R22: =D22-Q22 -> 181019 | S22: =O22*1000 -> 2100 | T22: =T18+T20 -> 32897.86 | W22: =T16-E36-F36-G36 -> -2.1316282e-13 | AA22: =J22*$W$4 -> 32978.643 | AB22: =E22+F22+G22 -> 105.14 | AD22: =$W$9*K22/1000/R22 -> 0.029176694 | AE22: =$W$5*H22/1000/R22 -> 0.011600992 | AF22: =$W$6*L22/1000/R22 -> 0 | AG22: =$W$7*M22/1000/R22 -> 0 | AH22: =$W$8*N22/1000/R22 -> 0 | AI22: =AD22+AE22+AF22+AG22+AH22 -> 0.040777686 | AJ22: =AI22*R22 -> 7381.536 | AK22: =AB22*(100-进出水!T24)/100 -> 22.81538 | AL22: =H22/AK22 -> 3.2872562
A23: 19 | B23: 23.6 | C23: 晴 | D23: 172907 | E23: 0 | F23: 105.28 | G23: 0 | H23: 100 | I23: 4374 | J23: 50600 | K23: 12672 | L23: 0 | M23: 0 | N23: 0 | O23: 2.38 | P23: 0 | Q23: 0 | R23: =D23-Q23 -> 172907 | S23: =O23*1000 -> 2380 | AA23: =J23*$W$4 -> 32465.356 | AB23: =E23+F23+G23 -> 105.28 | AD23: =$W$9*K23/1000/R23 -> 0.030487788 | AE23: =$W$5*H23/1000/R23 -> 0.016193676 | AF23: =$W$6*L23/1000/R23 -> 0 | AG23: =$W$7*M23/1000/R23 -> 0 | AH23: =$W$8*N23/1000/R23 -> 0 | AI23: =AD23+AE23+AF23+AG23+AH23 -> 0.046681465 | AJ23: =AI23*R23 -> 8071.552 | AK23: =AB23*(100-进出水!T25)/100 -> 22.95104 | AL23: =H23/AK23 -> 4.357101
A24: 20 | B24: 26.3 | C24: 晴 | D24: 161127 | E24: 0 | F24: 103.94 | G24: 0 | H24: 75 | I24: 4216 | J24: 48800 | K24: 12552 | L24: 0 | M24: 0 | N24: 0 | O24: 2.52 | P24: 0 | Q24: 0 | R24: =D24-Q24 -> 161127 | S24: =O24*1000 -> 2520 | T24: 絮凝剂 | U24: 用量（kg） | V24: =H36 -> 3125 | W24: =L36 -> 0 | AA24: =J24*$W$4 -> 31310.462 | AB24: =E24+F24+G24 -> 103.94 | AD24: =$W$9*K24/1000/R24 -> 0.032406934 | AE24: =$W$5*H24/1000/R24 -> 0.013033197 | AF24: =$W$6*L24/1000/R24 -> 0 | AG24: =$W$7*M24/1000/R24 -> 0 | AH24: =$W$8*N24/1000/R24 -> 0 | AI24: =AD24+AE24+AF24+AG24+AH24 -> 0.045440131 | AJ24: =AI24*R24 -> 7321.632 | AK24: =AB24*(100-进出水!T26)/100 -> 22.8668 | AL24: =H24/AK24 -> 3.2798643
A25: 21 | B25: 25.7 | C25: 晴 | D25: 180637 | E25: 0 | F25: 83.78 | G25: 0 | H25: 100 | I25: 5068 | J25: 53700 | K25: 12612 | L25: 0 | M25: 0 | N25: 0 | O25: 3.42 | P25: 0 | Q25: 0 | R25: =D25-Q25 -> 180637 | S25: =O25*1000 -> 3420 | U25: 单耗（kg/T） | V25: =汇总!F6 -> 4.1001483 | W25: =W24/R36*1000 -> 0 | AA25: =J25*$W$4 -> 34454.341 | AB25: =E25+F25+G25 -> 83.78 | AD25: =$W$9*K25/1000/R25 -> 0.029044946 | AE25: =$W$5*H25/1000/R25 -> 0.0155007 | AF25: =$W$6*L25/1000/R25 -> 0 | AG25: =$W$7*M25/1000/R25 -> 0 | AH25: =$W$8*N25/1000/R25 -> 0 | AI25: =AD25+AE25+AF25+AG25+AH25 -> 0.044545647 | AJ25: =AI25*R25 -> 8046.592 | AK25: =AB25*(100-进出水!T27)/100 -> 18.26404 | AL25: =H25/AK25 -> 5.4752399
A26: 22 | B26: 22.3 | C26: 晴 | D26: 200391 | E26: 0 | F26: 101.5 | G26: 0 | H26: 75 | I26: 4520 | J26: 53800 | K26: 4320 | L26: 0 | M26: 0 | N26: 0 | O26: 2.1 | P26: 0 | Q26: 0 | R26: =D26-Q26 -> 200391 | S26: =O26*1000 -> 2100 | T26: 混凝剂 | U26: 用量（kg） | V26: =K36 -> 180792 | AA26: =J26*$W$4 -> 34518.501 | AB26: =E26+F26+G26 -> 101.5 | AD26: =$W$9*K26/1000/R26 -> 0.0089680674 | AE26: =$W$5*H26/1000/R26 -> 0.010479513 | AF26: =$W$6*L26/1000/R26 -> 0 | AG26: =$W$7*M26/1000/R26 -> 0 | AH26: =$W$8*N26/1000/R26 -> 0 | AI26: =AD26+AE26+AF26+AG26+AH26 -> 0.01944758 | AJ26: =AI26*R26 -> 3897.12 | AK26: =AB26*(100-进出水!T28)/100 -> 22.0255 | AL26: =H26/AK26 -> 3.405144
A27: 23 | B27: 23 | C27: 晴 | D27: 203233 | E27: 0 | F27: 85.92 | G27: 0 | H27: 100 | I27: 4242 | J27: 56400 | K27: 0 | L27: 0 | M27: 0 | N27: 0 | O27: 2.16 | P27: 0 | Q27: 0 | R27: =D27-Q27 -> 203233 | S27: =O27*1000 -> 2160 | U27: 单耗（g/m3） | V27: =ROUND(K36/R36*1000,1) -> 32.3 | AA27: =J27*$W$4 -> 36186.682 | AB27: =E27+F27+G27 -> 85.92 | AD27: =$W$9*K27/1000/R27 -> 0 | AE27: =$W$5*H27/1000/R27 -> 0.01377729 | AF27: =$W$6*L27/1000/R27 -> 0 | AG27: =$W$7*M27/1000/R27 -> 0 | AH27: =$W$8*N27/1000/R27 -> 0 | AI27: =AD27+AE27+AF27+AG27+AH27 -> 0.01377729 | AJ27: =AI27*R27 -> 2800 | AK27: =AB27*(100-进出水!T29)/100 -> 18.73056 | AL27: =H27/AK27 -> 5.3388687
A28: 24 | B28: 23.6 | C28: 晴 | D28: 192956 | E28: 0 | F28: 102.34 | G28: 0 | H28: 150 | I28: 4894 | J28: 55400 | K28: 9372 | L28: 0 | M28: 2485 | N28: 720 | O28: 2.94 | P28: 0 | Q28: 4537 | R28: =D28-Q28 -> 188419 | S28: =O28*1000 -> 2940 | T28: 盐酸 | U28: 用量（kg） | V28: =M36 -> 27122 | AA28: =J28*$W$4 -> 35545.074 | AB28: =E28+F28+G28 -> 102.34 | AD28: =$W$9*K28/1000/R28 -> 0.020691926 | AE28: =$W$5*H28/1000/R28 -> 0.022290746 | AF28: =$W$6*L28/1000/R28 -> 0 | AG28: =$W$7*M28/1000/R28 -> 0.0061723075 | AH28: =$W$8*N28/1000/R28 -> 0.022060196 | AI28: =AD28+AE28+AF28+AG28+AH28 -> 0.071215175 | AJ28: =AI28*R28 -> 13418.292 | AK28: =AB28*(100-进出水!T30)/100 -> 22.5148 | AL28: =H28/AK28 -> 6.6622844
A29: 25 | B29: 22.2 | C29: 晴 | D29: 180746 | E29: 0 | F29: 158.16 | G29: 0 | H29: 150 | I29: 4502 | J29: 55800 | K29: 12756 | L29: 0 | M29: 3266 | N29: 1032 | O29: 2.28 | P29: 0 | Q29: 5483 | R29: =D29-Q29 -> 175263 | S29: =O29*1000 -> 2280 | U29: 单耗（g/m3） | V29: =ROUND(M36/R36*1000,1) -> 4.8 | AA29: =J29*$W$4 -> 35801.717 | AB29: =E29+F29+G29 -> 158.16 | AD29: =$W$9*K29/1000/R29 -> 0.030277332 | AE29: =$W$5*H29/1000/R29 -> 0.023963986 | AF29: =$W$6*L29/1000/R29 -> 0 | AG29: =$W$7*M29/1000/R29 -> 0.0087211106 | AH29: =$W$8*N29/1000/R29 -> 0.033993119 | AI29: =AD29+AE29+AF29+AG29+AH29 -> 0.096955547 | AJ29: =AI29*R29 -> 16992.72 | AK29: =AB29*(100-进出水!T31)/100 -> 34.63704 | AL29: =H29/AK29 -> 4.3306241
A30: 26 | B30: 22.3 | C30: 晴 | D30: 176831 | E30: 0 | F30: 126.38 | G30: 0 | H30: 175 | I30: 5130 | J30: 54000 | K30: 12804 | L30: 0 | M30: 4970 | N30: 1632 | O30: 2.32 | P30: 0 | Q30: 5528 | R30: =D30-Q30 -> 171303 | S30: =O30*1000 -> 2320 | T30: 氯酸钠 | U30: 用量（kg） | V30: =处理量!N36 -> 8664 | AA30: =J30*$W$4 -> 34646.823 | AB30: =E30+F30+G30 -> 126.38 | AD30: =$W$9*K30/1000/R30 -> 0.031093816 | AE30: =$W$5*H30/1000/R30 -> 0.028604286 | AF30: =$W$6*L30/1000/R30 -> 0 | AG30: =$W$7*M30/1000/R30 -> 0.013578046 | AH30: =$W$8*N30/1000/R30 -> 0.054999247 | AI30: =AD30+AE30+AF30+AG30+AH30 -> 0.1282754 | AJ30: =AI30*R30 -> 21973.96 | AK30: =AB30*(100-进出水!T32)/100 -> 27.29808 | AL30: =H30/AK30 -> 6.4107073
A31: 27 | B31: 22.8 | C31: 晴 | D31: 175173 | E31: 0 | F31: 224.32 | G31: 16.02 | H31: 175 | I31: 4156 | J31: 54600 | K31: 12300 | L31: 0 | M31: 4828 | N31: 1608 | O31: 2.22 | P31: 0 | Q31: 5555 | R31: =D31-Q31 -> 169618 | S31: =O31*1000 -> 2220 | U31: 单耗（g/m3） | V31: =ROUND(N36/R36*1000,2) -> 1.55 | AA31: =J31*$W$4 -> 35031.788 | AB31: =E31+F31+G31 -> 240.34 | AD31: =$W$9*K31/1000/R31 -> 0.03016661 | AE31: =$W$5*H31/1000/R31 -> 0.028888443 | AF31: =$W$6*L31/1000/R31 -> 0 | AG31: =$W$7*M31/1000/R31 -> 0.013321133 | AH31: =$W$8*N31/1000/R31 -> 0.054728767 | AI31: =AD31+AE31+AF31+AG31+AH31 -> 0.12710495 | AJ31: =AI31*R31 -> 21559.288 | AK31: =AB31*(100-进出水!T33)/100 -> 51.6731 | AL31: =H31/AK31 -> 3.3866751
A32: 28 | B32: 21.6 | C32: 晴 | D32: 180173 | E32: 0 | F32: 102.4 | G32: 47.22 | H32: 150 | I32: 4618 | J32: 55900 | K32: 840 | L32: 0 | M32: 4615 | N32: 1512 | O32: 3.12 | P32: 0 | Q32: 5520 | R32: =D32-Q32 -> 174653 | S32: =O32*1000 -> 3120 | T32: 乙酸 | U32: 用量（T） | V32: =O36 -> 79.54 | AA32: =J32*$W$4 -> 35865.878 | AB32: =E32+F32+G32 -> 149.62 | AD32: =$W$9*K32/1000/R32 -> 0.0020007672 | AE32: =$W$5*H32/1000/R32 -> 0.024047683 | AF32: =$W$6*L32/1000/R32 -> 0 | AG32: =$W$7*M32/1000/R32 -> 0.012366349 | AH32: =$W$8*N32/1000/R32 -> 0.049977819 | AI32: =AD32+AE32+AF32+AG32+AH32 -> 0.088392619 | AJ32: =AI32*R32 -> 15438.036 | AK32: =AB32*(100-进出水!T34)/100 -> 32.01868 | AL32: =H32/AK32 -> 4.6847653
A33: 29 | B33: 22.1 | C33: 晴 | D33: 168422 | E33: 0 | F33: 224 | G33: 0 | H33: 175 | I33: 4780 | J33: 53200 | K33: 0 | L33: 0 | M33: 3763 | N33: 1200 | O33: 4.44 | P33: 0 | Q33: 5534 | R33: =D33-Q33 -> 162888 | S33: =O33*1000 -> 4440 | U33: 单耗（g/m3） | V33: =ROUND(V32/R36*1000000,2) -> 14.2 | AA33: =J33*$W$4 -> 34133.537 | AB33: =E33+F33+G33 -> 224 | AD33: =$W$9*K33/1000/R33 -> 0 | AE33: =$W$5*H33/1000/R33 -> 0.03008202 | AF33: =$W$6*L33/1000/R33 -> 0 | AG33: =$W$7*M33/1000/R33 -> 0.010811625 | AH33: =$W$8*N33/1000/R33 -> 0.042529836 | AI33: =AD33+AE33+AF33+AG33+AH33 -> 0.083423481 | AJ33: =AI33*R33 -> 13588.684 | AK33: =AB33*(100-进出水!T35)/100 -> 48.832 | AL33: =H33/AK33 -> 3.5837156
A34: 30 | B34: 21.7 | C34: 晴 | D34: 191205 | E34: 0 | F34: 97.66 | G34: 0 | H34: 150 | I34: 3912 | J34: 55800 | K34: 0 | L34: 0 | M34: 3195 | N34: 960 | O34: 4.44 | P34: 0 | Q34: 5629 | R34: =D34-Q34 -> 185576 | S34: =O34*1000 -> 4440 | AA34: =J34*$W$4 -> 35801.717 | AB34: =E34+F34+G34 -> 97.66 | AD34: =$W$9*K34/1000/R34 -> 0 | AE34: =$W$5*H34/1000/R34 -> 0.022632237 | AF34: =$W$6*L34/1000/R34 -> 0 | AG34: =$W$7*M34/1000/R34 -> 0.0080573997 | AH34: =$W$8*N34/1000/R34 -> 0.029864207 | AI34: =AD34+AE34+AF34+AG34+AH34 -> 0.060553843 | AJ34: =AI34*R34 -> 11237.34 | AK34: =AB34*(100-进出水!T36)/100 -> 20.89924 | AL34: =H34/AK34 -> 7.1772945
A35: 平均 | B35: =AVERAGE(B5:B34) -> 24.076667 | C35: / | D35: =AVERAGE(D5:D34) -> 188017.67 | E35: =AVERAGE(E5:E34) -> 7.5553333 | F35: =AVERAGE(F5:F34) -> 106.67333 | G35: =AVERAGE(G5:G34) -> 3.608 | H35: =AVERAGE(H5:H34) -> 104.16667 | I35: =AVERAGE(I5:I34) -> 4223.3333 | J35: =AVERAGE(J5:J34) -> 52823.333 | K35: =AVERAGE(K5:K34) -> 6026.4 | ... O35: =AVERAGE(O5:O34) -> 2.6513333 | P35: 0 | Q35: =AVERAGE(Q5:Q34) -> 1274.4333 | R35: =D35-Q35 -> 186743.23
A36: 合计 | B36: / | C36: / | D36: =SUM(D5:D34) -> 5640530 | E36: =SUM(E5:E34) -> 226.66 | F36: =SUM(F5:F34) -> 3200.2 | G36: =SUM(G5:G34) -> 108.24 | H36: =SUM(H5:H34) -> 3125 | I36: / | J36: =SUM(J5:J34) -> 1584700 | K36: =SUM(K5:K34) -> 180792 | L36: =SUM(L5:L34) -> 0 | M36: =SUM(M5:M34) -> 27122 | N36: =SUM(N5:N34) -> 8664 | O36: =SUM(O5:O34) -> 79.54 | P36: =SUM(P5:P34) -> 0 | Q36: =SUM(Q5:Q34) -> 38233 | R36: =SUM(R5:R34) -> 5602297 | AB36: =SUM(AB5:AB35) -> 3535.1 | AI36: =AVERAGE(AI5:AI34) -> 0.041490433
A37: 审核： | I37: 制表： | Q37: 制表时间: | R37: 45264
M38: =M36*0.31 -> 8407.82 | T38: =L36/R36*1000 -> 0
J39: =J35*30 -> 1584700 | Q39: 最大 | R39: =MAX(R5:R34) -> 209249
J40: =J39*W4 -> 1016755.9 | O40: =O36*1000 -> 79540 | Q40: 最小 | R40: =MIN(R5:R34) -> 161127 | T40: =O36*1000 -> 79540

Sheet 汇总
A1: 常州市深水江边污水处理有限公司污水运行月报表
A2: 45231
A3: 污 水 处 理 | B3: 污水处理量 | C3: =处理量!R36 -> 5602297 | D3: 污 泥 处 理 | E3: 脱水污泥量（T） | F3: =处理量!E36+处理量!F36+处理量!G36 -> 3535.1 | G3: 水 电 用 量 | H3: 用电量（度） | J3: =处理量!J36 -> 1584700 | K3: 污 水 电 单 耗 | L3: 污水（度/m3） | M3: =J3/C3 -> 0.28286612 | P3: 除臭用水量
B4: 日均处理量 | C4: =处理量!R35 -> 186743.23 | E4: 絮凝剂用量（kg） | F4: =处理量!H36 -> 3125 | H4: 日均用电量（度） | J4: =J3/M15 -> 52823.333 | L4: CODcr（度/kg） | M4: =J3/I12 -> 1.5389887 | P4: 除臭用电量
E5: 含水率（%） | F5: =进出水!T37 -> 78.44 | H5: 用水量（T） | J5: 4331
B6: 最高日处理量 | C6: =处理量!R39 -> 209249 | E6: 絮凝剂单耗（kg/T） | F6: =F4/(F3*(100-F5)/100) -> 4.1001483 | G6: 消 毒 剂 | H6: 工业合成盐酸（T） | J6: =处理量!M36/1000 -> 27.122 | L6: BOD5（度/kg） | M6: =J3/I13 -> 2.8457356
B7: 最低日处理量 | C7: =处理量!R40 -> 161127 | E7: 产泥率(g/m３) | F7: =F3*(100-F5)/100*1000/(C3/1000) -> 136.04555 | H7: 药单耗(g/m3) | J7: =J6*1000/(C3/1000) -> 4.8412285 | L7: SS（度/kg） | M7: =J3/I14 -> 3.4664965
B8: 负荷率（%） | C8: =C4/200000*100 -> 93.371617 | D8: 混 凝 剂 | E8: 混凝剂用量（T） | F8: =处理量!K36/1000 -> 180.792 | H8: 氯酸钠（T） | J8: =处理量!N36/1000 -> 8.664 | K8: 乙酸-厌缺氧段 | L8: 投加量（吨） | M8: =处理量!O36 -> 79.54
B9: 进水水温(℃) | C9: =处理量!B35 -> 24.076667 | E9: 药单耗(g/m3) | F9: =F8*1000/(C3/1000) -> 32.271049 | H9: 药单耗(g/m3) | J9: =J8*1000/(C3/1000) -> 1.5465085 | L9: 药单耗(g/m3) | M9: =M8*1000000/C3 -> 14.197748
A10: 处 理 质 量 | B10: 项目 | C10: 进水 | E10: 出水 | G10: 去除率（%） | I10: 去除总量（kg) | K10: 乙酸-提标段 | L10: 投加量（吨） | M10: 0
L11: 药单耗(g/m3) | M11: 0
B12: CODcr | C12: =进出水!B37 -> 209 | E12: =进出水!N37 -> 25.2 | G12: =(C12-E12)/C12*100 -> 87.942584 | I12: =$C$3*(C12-E12)/1000 -> 1029702.2 | K12: 污 泥 去 向 | L12: 国电 | M12: =处理量!V16 -> 226.66 | P12: =ROUND(E12,2) -> 25.2 | Q12: =C3 -> 5602297 | R12: =P12*Q12/1000000 -> 141.17788 | S12: CODcr
B13: BOD5 | C13: =进出水!C37 -> 102 | E13: =进出水!O37 -> 2.6 | G13: =(C13-E13)/C13*100 -> 97.45098 | I13: =$C$3*(C13-E13)/1000 -> 556868.32 | L13: 英科环境 | M13: =处理量!U16 -> 3200.2 | P13: =ROUND(E13,2) -> 2.6 | Q13: =Q12 -> 5602297 | R13: =P13*Q13/1000000 -> 14.565972 | S13: BOD5
B14: SS | C14: =进出水!D37 -> 87 | E14: =进出水!P37 -> 5.4 | G14: =(C14-E14)/C14*100 -> 93.793103 | I14: =$C$3*(C14-E14)/1000 -> 457147.44 | L14: 其它 | M14: =处理量!W16 -> 108.24 | P14: =ROUND(E14,2) -> 5.4 | Q14: =Q13 -> 5602297 | R14: =P14*Q14/1000000 -> 30.252404 | S14: SS
B15: TP | C15: =进出水!E37 -> 2.92 | E15: =进出水!Q37 -> 0.17 | G15: =(C15-E15)/C15*100 -> 94.178082 | I15: =$C$3*(C15-E15)/1000 -> 15406.317 | K15: 运 行 情 况 | L15: 应运行天数 | M15: 30 | P15: =ROUND(E15,2) -> 0.17 | Q15: =Q14 -> 5602297 | R15: =P15*Q15/1000000 -> 0.95239049 | S15: TP
B16: TN | C16: =进出水!G37 -> 30.4 | E16: =进出水!S37 -> 7.96 | G16: =(C16-E16)/C16*100 -> 73.815789 | I16: =$C$3*(C16-E16)/1000 -> 125715.54 | L16: 实际运行天数 | M16: 30 | P16: =ROUND(E16,2) -> 7.96 | Q16: =Q15 -> 5602297 | R16: =P16*Q16/1000000 -> 44.594284 | S16: TN
B17: NH3-N | C17: =进出水!F37 -> 24.3 | E17: =进出水!R37 -> 0.34 | G17: =(C17-E17)/C17*100 -> 98.600823 | I17: =$C$3*(C17-E17)/1000 -> 134231.04 | L17: 达标排放天数 | M17: 30 | P17: =ROUND(E17,2) -> 0.34 | Q17: =Q16 -> 5602297 | R17: =P17*Q17/1000000 -> 1.904781 | S17: NH3-N
B18: 粪大肠菌群数 (个/L) | E18: <20 | L18: 运转率 | M18: 100
A19: 备注 | B19: 本月产生泥饼3535.10吨，其中运往常州市英科环境科技有限公司3200.20吨，国电常州发电有限公司226.66吨，本月外运接种108.24吨，其中常州吉庆纺织植绒材料有限公司30.00吨,常州市巨朋纺织印染有限公司15.00吨，江苏盈天化学有限公司63.24吨。
A21: 审核： 制表： 制表日期：2023/12/4

Sheet 进出水
A1: 常州市深水江边污水处理有限公司进出水水质、污泥含水率月报表
J3: 45231
A4: 日期 | B4: 进水 | H4: 二沉池出水 | N4: 总出水 | T4: 污泥含水率 | U4: 粪大肠菌群
B5: CODCr | C5: BOD5 | D5: SS | E5: TP | F5: NH3-N | G5: TN | H5: CODCr | I5: BOD5 | J5: SS | K5: TP | L5: NH3-N | M5: TN | N5: CODCr | O5: BOD5 | P5: SS | Q5: TP | R5: NH3-N | S5: TN
B6: （mg/L） | C6: （mg/L） | D6: （mg/L） | E6: （mg/L） | F6: （mg/L） | G6: （mg/L） | H6: （mg/L） | I6: （mg/L） | J6: （mg/L） | K6: （mg/L） | L6: （mg/L） | M6: （mg/L） | N6: （mg/L） | O6: （mg/L） | P6: （mg/L） | Q6: （mg/L） | R6: （mg/L） | S6: （mg/L） | T6: （%） | U6: (个/L)
A7: 1 | B7: 161 | C7: 74.1 | D7: 84 | E7: 1.99 | F7: 24.2 | G7: 30.6 | H7: 34 | I7: 3.42 | J7: 14 | K7: 0.54 | L7: 0.36 | M7: 6.44 | N7: 26 | O7: 2.61 | P7: 5 | Q7: 0.13 | R7: 0.25 | S7: 5.88 | T7: 78.5 | U7: <20 | W7: =1-S7/G7 -> 0.80784314
A8: 2 | B8: 158 | C8: 68 | D8: 90 | E8: 2.15 | F8: 21.6 | G8: 27.6 | H8: 32 | I8: 3.22 | J8: 16 | K8: 0.53 | L8: 0.4 | M8: 7.76 | N8: 25 | O8: 2.5 | P8: 5 | Q8: 0.16 | R8: 0.34 | S8: 7.44 | T8: 78.3 | U8: <20 | W8: =1-S8/G8 -> 0.73043478
A9: 3 | B9: 226 | C9: 106 | D9: 94 | E9: 2.15 | F9: 21.4 | G9: 29.2 | H9: 35 | I9: 3.5 | J9: 18 | K9: 0.51 | L9: 0.3 | M9: 6.73 | N9: 30 | O9: 2.94 | P9: 5 | Q9: 0.13 | R9: 0.14 | S9: 6.02 | T9: 78.4 | U9: 20 | W9: =1-S9/G9 -> 0.79383562
A10: 4 | B10: 239 | C10: 103 | D10: 100 | E10: 2.2 | F10: 20.6 | G10: 26.7 | H10: 40 | I10: 3.98 | J10: 17 | K10: 0.54 | L10: 0.37 | M10: 8.49 | N10: 24 | O10: 2.44 | P10: 6 | Q10: 0.26 | R10: 0.36 | S10: 7 | T10: 78.3 | U10: 40 | W10: =1-S10/G10 -> 0.73782772
A11: 5 | B11: 174 | C11: 78.3 | D11: 90 | E11: 2.44 | F11: 21.2 | G11: 30.7 | H11: 33 | I11: 3.31 | J11: 16 | K11: 0.5 | L11: 0.45 | M11: 7.96 | N11: 23 | O11: 2.53 | P11: 5 | Q11: 0.09 | R11: 0.41 | S11: 7.5 | T11: 78.6 | U11: 20 | W11: =1-S11/G11 -> 0.75570033
A12: 6 | B12: 170 | C12: 81.6 | D12: 78 | E12: 2.36 | F12: 21.7 | G12: 30.4 | H12: 37 | I12: 3.67 | J12: 16 | K12: 0.52 | L12: 0.75 | M12: 9.13 | N12: 26 | O12: 2.66 | P12: 6 | Q12: 0.11 | R12: 0.68 | S12: 8.08 | T12: 78.9 | U12: <20 | W12: =1-S12/G12 -> 0.73421053
A13: 7 | B13: 192 | C13: 82.4 | D13: 82 | E13: 3.52 | F13: 26.3 | G13: 32 | H13: 37 | I13: 3.7 | J13: 16 | K13: 0.52 | L13: 0.37 | M13: 10.8 | N13: 24 | O13: 2.48 | P13: 6 | Q13: 0.11 | R13: 0.28 | S13: 10.5 | T13: 78.8 | U13: <20 | W13: =1-S13/G13 -> 0.671875
A14: 8 | B14: 173 | C14: 96.8 | D14: 76 | E14: 4 | F14: 25.8 | G14: 31.1 | H14: 36 | I14: 3.36 | J14: 12 | K14: 0.51 | L14: 0.43 | M14: 7.81 | N14: 23 | O14: 2.65 | P14: 5 | Q14: 0.14 | R14: 0.33 | S14: 7.4 | T14: 78.5 | U14: <20 | W14: =1-S14/G14 -> 0.76205788
A15: 9 | B15: 156 | C15: 82.6 | D15: 70 | E15: 3.93 | F15: 24.9 | G15: 29.1 | H15: 29 | I15: 2.9 | J15: 11 | K15: 0.52 | L15: 0.56 | M15: 8.25 | N15: 23 | O15: 2.36 | P15: 5 | Q15: 0.28 | R15: 0.34 | S15: 7.5 | T15: 78.6 | U15: <20 | W15: =1-S15/G15 -> 0.74226804
A16: 10 | B16: 171 | C16: 97.4 | D16: 72 | E16: 3.33 | F16: 27.9 | G16: 31.2 | H16: 29 | I16: 2.96 | J16: 14 | K16: 0.5 | L16: 0.47 | M16: 8.05 | N16: 25 | O16: 2.55 | P16: 6 | Q16: 0.2 | R16: 0.24 | S16: 7.64 | T16: 78.9 | U16: 20 | W16: =1-S16/G16 -> 0.75512821
A17: 11 | B17: 236 | C17: 125 | D17: 66 | E17: 2.23 | F17: 22.2 | G17: 29.1 | H17: 33 | I17: 3.31 | J17: 16 | K17: 0.53 | L17: 0.32 | M17: 8.32 | N17: 27 | O17: 2.7 | P17: 6 | Q17: 0.16 | R17: 0.27 | S17: 8.1 | T17: 78.6 | U17: 20 | W17: =1-S17/G17 -> 0.72164948
A18: 12 | B18: 170 | C18: 91.7 | D18: 74 | E18: 2.6 | F18: 22.1 | G18: 28.9 | H18: 36 | I18: 3.36 | J18: 18 | K18: 0.52 | L18: 0.52 | M18: 8.42 | N18: 26 | O18: 2.62 | P18: 6 | Q18: 0.16 | R18: 0.43 | S18: 8.1 | T18: 78.8 | U18: 40 | W18: =1-S18/G18 -> 0.71972318
A19: 13 | B19: 265 | C19: 154 | D19: 104 | E19: 5.14 | F19: 26.8 | G19: 31 | H19: 35 | I19: 3.6 | J19: 16 | K19: 0.51 | L19: 0.38 | M19: 10.5 | N19: 26 | O19: 2.62 | P19: 5 | Q19: 0.28 | R19: 0.27 | S19: 9.52 | T19: 78.2 | U19: 50 | W19: =1-S19/G19 -> 0.69290323
A20: 14 | B20: 192 | C20: 106 | D20: 110 | E20: 4.07 | F20: 25.9 | G20: 32.2 | H20: 32 | I20: 3.22 | J20: 15 | K20: 0.52 | L20: 0.37 | M20: 9.98 | N20: 29 | O20: 2.8 | P20: 5 | Q20: 0.22 | R20: 0.31 | S20: 8.54 | T20: 78.4 | U20: <20 | W20: =1-S20/G20 -> 0.73478261
A21: 15 | B21: 195 | C21: 109 | D21: 78 | E21: 2.53 | F21: 28.5 | G21: 35.6 | H21: 35 | I21: 3.68 | J21: 14 | K21: 0.52 | L21: 0.33 | M21: 9.1 | N21: 29 | O21: 2.9 | P21: 5 | Q21: 0.16 | R21: 0.32 | S21: 7.81 | T21: 78.5 | U21: <20 | W21: =1-S21/G21 -> 0.78061798
A22: 16 | B22: 211 | C22: 112 | D22: 96 | E22: 4.25 | F22: 30.1 | G22: 35.6 | H22: 38 | I22: 3.68 | J22: 16 | K22: 0.54 | L22: 0.45 | M22: 8.83 | N22: 25 | O22: 2.58 | P22: 5 | Q22: 0.23 | R22: 0.38 | S22: 8.28 | T22: 78.8 | U22: 20 | W22: =1-S22/G22 -> 0.76741573
A23: 17 | B23: 210 | C23: 116 | D23: 92 | E23: 2.19 | F23: 22.5 | G23: 27.1 | H23: 38 | I23: 3.38 | J23: 17 | K23: 0.53 | L23: 0.39 | M23: 8.04 | N23: 26 | O23: 2.6 | P23: 5 | Q23: 0.21 | R23: 0.36 | S23: 7.01 | T23: 78.5 | U23: 40 | W23: =1-S23/G23 -> 0.74132841
A24: 18 | B24: 204 | C24: 114 | D24: 74 | E24: 2.22 | F24: 21.7 | G24: 27.8 | H24: 39 | I24: 3.64 | J24: 16 | K24: 0.52 | L24: 0.31 | M24: 8.88 | N24: 23 | O24: 2.74 | P24: 5 | Q24: 0.16 | R24: 0.22 | S24: 7.54 | T24: 78.3 | U24: 50 | W24: =1-S24/G24 -> 0.72877698
A25: 19 | B25: 297 | C25: 136 | D25: 86 | E25: 2.49 | F25: 22.8 | G25: 28.8 | H25: 41 | I25: 3.88 | J25: 17 | K25: 0.53 | L25: 0.39 | M25: 8.88 | N25: 24 | O25: 2.46 | P25: 6 | Q25: 0.13 | R25: 0.28 | S25: 7.06 | T25: 78.2 | U25: 40 | W25: =1-S25/G25 -> 0.75486111
A26: 20 | B26: 209 | C26: 96.1 | D26: 108 | E26: 2.5 | F26: 29.1 | G26: 34.9 | H26: 47 | I26: 3.74 | J26: 16 | K26: 0.54 | L26: 0.47 | M26: 8.94 | N26: 25 | O26: 2.52 | P26: 5 | Q26: 0.2 | R26: 0.34 | S26: 8.07 | T26: 78 | U26: <20 | W26: =1-S26/G26 -> 0.76876791
A27: 21 | B27: 225 | C27: 99 | D27: 100 | E27: 1.75 | F27: 20.7 | G27: 26.5 | H27: 36 | I27: 3.6 | J27: 16 | K27: 0.52 | L27: 0.35 | M27: 9.86 | N27: 23 | O27: 2.43 | P27: 6 | Q27: 0.2 | R27: 0.28 | S27: 9.36 | T27: 78.2 | U27: <20 | W27: =1-S27/G27 -> 0.64679245
A28: 22 | B28: 174 | C28: 81.6 | D28: 66 | E28: 2.78 | F28: 26.5 | G28: 31.5 | H28: 35 | I28: 3.5 | J28: 18 | K28: 0.54 | L28: 0.42 | M28: 8.86 | N28: 23 | O28: 2.38 | P28: 6 | Q28: 0.19 | R28: 0.3 | S28: 7.84 | T28: 78.3 | U28: 20 | W28: =1-S28/G28 -> 0.75111111
A29: 23 | B29: 234 | C29: 105 | D29: 96 | E29: 2.56 | F29: 27.6 | G29: 32.3 | H29: 31 | I29: 3.1 | J29: 15 | K29: 0.52 | L29: 0.42 | M29: 8.49 | N29: 24 | O29: 2.42 | P29: 5 | Q29: 0.15 | R29: 0.35 | S29: 8.2 | T29: 78.2 | U29: <20 | W29: =1-S29/G29 -> 0.74613003
A30: 24 | B30: 367 | C30: 158 | D30: 144 | E30: 2.54 | F30: 27.5 | G30: 36.9 | H30: 46 | I30: 3.94 | J30: 17 | K30: 0.53 | L30: 0.47 | M30: 9.02 | N30: 28 | O30: 2.78 | P30: 6 | Q30: 0.2 | R30: 0.32 | S30: 8.14 | T30: 78 | U30: 40 | W30: =1-S30/G30 -> 0.77940379
A31: 25 | B31: 124 | C31: 70.6 | D31: 48 | E31: 2.12 | F31: 16.1 | G31: 21.9 | H31: 51 | I31: 4.06 | J31: 16 | K31: 0.53 | L31: 0.37 | M31: 8.33 | N31: 26 | O31: 2.66 | P31: 5 | Q31: 0.15 | R31: 0.32 | S31: 7.56 | T31: 78.1 | U31: 70 | W31: =1-S31/G31 -> 0.65479452
A32: 26 | B32: 179 | C32: 85.9 | D32: 94 | E32: 2.56 | F32: 20.9 | G32: 26.4 | H32: 38 | I32: 3.68 | J32: 14 | K32: 0.54 | L32: 0.58 | M32: 8.17 | N32: 24 | O32: 2.47 | P32: 5 | Q32: 0.12 | R32: 0.55 | S32: 7.94 | T32: 78.4 | U32: 20 | W32: =1-S32/G32 -> 0.69924242
A33: 27 | B33: 262 | C33: 110 | D33: 98 | E33: 3.08 | F33: 24 | G33: 30.9 | H33: 51 | I33: 4.26 | J33: 18 | K33: 0.53 | L33: 0.52 | M33: 9.91 | N33: 25 | O33: 2.62 | P33: 6 | Q33: 0.11 | R33: 0.4 | S33: 8.88 | T33: 78.5 | U33: <20 | W33: =1-S33/G33 -> 0.71262136
A34: 28 | B34: 277 | C34: 130 | D34: 96 | E34: 3.45 | F34: 25.8 | G34: 31.3 | H34: 52 | I34: 4.84 | J34: 16 | K34: 0.54 | L34: 0.49 | M34: 8.86 | N34: 22 | O34: 2.32 | P34: 6 | Q34: 0.11 | R34: 0.32 | S34: 8.56 | T34: 78.6 | U34: <20 | W34: =1-S34/G34 -> 0.72651757
A35: 29 | B35: 246 | C35: 101 | D35: 88 | E35: 4.89 | F35: 25.7 | G35: 32.7 | H35: 37 | I35: 3.7 | J35: 14 | K35: 0.53 | L35: 0.38 | M35: 9.39 | N35: 24 | O35: 2.45 | P35: 5 | Q35: 0.14 | R35: 0.33 | S35: 8.83 | T35: 78.2 | U35: <20 | W35: =1-S35/G35 -> 0.72996942
A36: 30 | B36: 175 | C36: 83.6 | D36: 68 | E36: 3.5 | F36: 26.4 | G36: 31.1 | H36: 36 | I36: 3.62 | J36: 13 | K36: 0.54 | L36: 0.47 | M36: 8.65 | N36: 29 | O36: 2.69 | P36: 5 | Q36: 0.25 | R36: 0.34 | S36: 8.41 | T36: 78.6 | U36: 20 | W36: =1-S36/G36 -> 0.72958199
A37: 平均 | B37: =ROUND(AVERAGE(B7:B36),0) -> 209 | C37: =ROUND(AVERAGE(C7:C36),0) -> 102 | D37: =ROUND(AVERAGE(D7:D36),0) -> 87 | E37: =ROUND(AVERAGE(E7:E36),2) -> 2.92 | F37: =ROUND(AVERAGE(F7:F36),1) -> 24.3 | G37: =ROUND(AVERAGE(G7:G36),1) -> 30.4 | H37: =ROUND(AVERAGE(H7:H36),1) -> 37.6 | I37: =ROUND(AVERAGE(I7:I36),2) -> 3.59 | J37: =ROUND(AVERAGE(J7:J36),2) -> 15.6 | K37: =ROUND(AVERAGE(K7:K36),2) -> 0.53 | L37: =ROUND(AVERAGE(L7:L36),2) -> 0.43 | M37: =ROUND(AVERAGE(M7:M36),1) -> 8.7 | N37: =ROUND(AVERAGE(N7:N36),1) -> 25.2 | O37: =ROUND(AVERAGE(O7:O36),1) -> 2.6 | P37: =ROUND(AVERAGE(P7:P36),2) -> 5.4 | Q37: =ROUND(AVERAGE(Q7:Q36),2) -> 0.17 | R37: =ROUND(AVERAGE(R7:R36),2) -> 0.34 | S37: =ROUND(AVERAGE(S7:S36),2) -> 7.96 | T37: =ROUND(AVERAGE(T7:T36),2) -> 78.44 | U37: <20
A38: 审核： | J38: 制表： | Q38: 制表时间：2023/12/4
B40: 项目 | C40: 进水（mg/L) | D40: 最大值 | E40: 最小值（mg/L) | F40: 出水（mg/L) | G40: 最大值 | H40: 最小值（mg/L) | I40: 去除率
D41: （mg/L) | G41: （mg/L) | I41: （%）
B42: CODCr | C42: =B37 -> 209 | D42: =MAX(B7:B36) -> 367 | E42: =MIN(B7:B36) -> 124 | F42: =N37 -> 25.2 | G42: =MAX(N7:N36) -> 30 | H42: =MIN(N7:N36) -> 22 | I42: =1-F42/C42 -> 0.87942584 | K42: B/C | L42: =C43/C42 -> 0.48803828
...

Sheet 设备
A1: 常州市深水江边污水处理有限公司设备运行月报表
A2: 45231
A3: 运行 工段 | B3: 设备名称 | C3: 编号 | D3: 运行 天数 | E3: 定时 | F3: 额定运行时间 | G3: 实际运行时间 | H3: 利用率 | I3: 完好率 | J3: 维修、保养情况
D5: （d） | E5: (h/d) | F5: （h） | G5: （h） | H5: % | I5: %
A6: 预 处 理 | B6: 粗格栅机 | C6: 1# | D6: 30 | E6: 2 | F6: 60 | G6: 60 | H6: 1 | I6: 1
C7: 2# | D7: 30 | E7: 2 | F7: 60 | G7: 60 | H7: 1 | I7: 1
B8: 螺旋输送机 | C8: / | D8: 30 | E8: 2 | F8: 60 | G8: 60 | H8: 1 | I8: 1
B9: 螺旋压榨机 | C9: / | D9: 30 | E9: 2 | F9: 60 | G9: 60 | H9: 1 | I9: 1
B10: 进水泵 | C10: 1# | D10: 30 | E10: 24 | F10: 720 | G10: 718 | H10: 0.99 | I10: 1
C11: 2# | D11: 30 | E11: 24 | F11: 720 | G11: 297 | H11: 0.4125 | I11: 1
C12: 3# | D12: 30 | E12: 24 | F12: 720 | G12: 422 | H12: 0.58611111 | I12: 1
C13: 4# | D13: 30 | E13: 24 | F13: 720 | G13: 0 | H13: 0 | I13: 1
C14: 5# | D14: 30 | E14: 24 | F14: 720 | G14: 718 | H14: 0.99722222 | I14: 1
B15: 细格栅机 | C15: 1# | D15: 30 | E15: 2.4 | F15: 72 | G15: 72 | H15: 1 | I15: 1
C16: 2# | D16: 30 | E16: 2.4 | F16: 72 | G16: 72 | H16: 1 | I16: 1
C17: 3# | D17: 30 | E17: 2.4 | F17: 72 | G17: 72 | H17: 1 | I17: 1
C18: 4# | D18: 30 | E18: 2.4 | F18: 72 | G18: 72 | H18: 1 | I18: 1
C19: 5# | D19: 30 | E19: 2.4 | F19: 72 | G19: 38.4 | H19: 1 | I19: 0.53
C20: 6# | D20: 30 | E20: 2.4 | F20: 72 | G20: 72 | H20: 1 | I20: 1
B21: 螺旋输送机 | C21: 1# | D21: 30 | E21: 2 | F21: 60 | G21: 60 | H21: 1 | I21: 1
C22: 2# | D22: 30 | E22: 2 | F22: 60 | G22: 60 | H22: 1 | I22: 1
B23: 螺旋压榨机 | C23: 1# | D23: 30 | E23: 2 | F23: 60 | G23: 60 | H23: 1 | I23: 1
C24: 2# | D24: 30 | E24: 2 | F24: 60 | G24: 0 | H24: 0 | I24: 1
B25: 搅拌机 | C25: 1# | D25: 30 | E25: 24 | F25: 720 | G25: 720 | H25: 1 | I25: 1
B26: 砂水分离机 | C26: 1# | D26: 30 | E26: 0.5 | F26: 15 | G26: 15 | H26: 1 | I26: 1
B27: 搅拌机 | C27: 2# | D27: 30 | E27: 24 | F27: 720 | G27: 0 | H27: 0 | I27: 0
B28: 砂水分离机 | C28: 2# | D28: 30 | E28: 0.5 | F28: 15 | G28: 15 | H28: 1 | I28: 1
B29: 搅拌机 | C29: 3# | D29: 30 | E29: 24 | F29: 720 | G29: 720 | H29: 1 | I29: 1
B30: 砂水分离机 | C30: 3# | D30: 30 | E30: 0.5 | F30: 15 | G30: 15 | H30: 1 | I30: 1
B31: 搅拌机 | C31: 4# | D31: 30 | E31: 24 | F31: 720 | G31: 0 | H31: 0 | I31: 0
B32: 砂水分离机 | C32: 4# | D32: 30 | E32: 0.5 | F32: 15 | G32: 15 | H32: 1 | I32: 1
B33: 高压鼓风机 | C33: 1# | D33: 30 | E33: 24 | F33: 720 | G33: 48 | H33: 0.066666667 | I33: 1
C34: 2# | D34: 30 | E34: 24 | F34: 720 | G34: 160 | H34: 0.22222222 | I34: 1
C35: 3# | D35: 30 | E35: 24 | F35: 720 | G35: 338 | H35: 0.46944444 | I35: 1 | J35: 20日更换滤网
C36: 4# | D36: 30 | E36: 24 | F36: 720 | G36: 644 | H36: 0.89444444 | I36: 1
C37: 5# | D37: 30 | E37: 24 | F37: 720 | G37: 272 | H37: 0.37777778 | I37: 1 | J37: 3日更换滤网
A38: 审核： | E38: 制表： | H38: 制表时间：2023/12/4
A46: 常州市深水江边污水处理有限公司设备运行月报表
A47: =A2 -> 45231
A48: 运行 工段 | B48: 设备名称 | C48: 编号 | D48: 运行 天数 | E48: 定时 | F48: 额定运行时间 | G48: 实际运行时间 | H48: 利用率 | I48: 完好率 | J48: 维修、保养情况
...

Sheet 仪表
A1: 常州市深水江边污水处理有限公司污水运行月报表
D2: 45231
A3: 仪表名称 | B3: 编号 | C3: 规格型号 | D3: 安装位置 | E3: 运行情况 | F3: 标定、校准情况 | G3: 备注
A4: 一期溶氧仪 | B4: 1#（南） | C4: 哈希LDO2 | D4: 一期生反池 | E4: 正常 | F4: 校准 | G4: 2023-11-06 2023-11-13 2023-11-20 2023-11-27
B5: 2#（南） | C5: 哈希LDO2 | D5: 一期生反池 | E5: 正常 | F5: 校准 | G5: =G4 -> 2023-11-06 2023-11-13 2023-11-20 2023-11-27
B6: 1#（北） | C6: 哈希LDO2 | D6: 一期生反池 | E6: 正常 | F6: 校准 | G6: =G5 -> 2023-11-06 2023-11-13 2023-11-20 2023-11-27
B7: 2#（北） | C7: 哈希LDO2 | D7: 一期生反池 | E7: 正常 | F7: 校准 | G7: =G6 -> 2023-11-06 2023-11-13 2023-11-20 2023-11-27
A8: 一期污泥浓度计 | B8: 1#（南） | C8: E+H | D8: 一期生反池 | E8: 正常 | F8: 校准 | G8: =G7 -> 2023-11-06 2023-11-13 2023-11-20 2023-11-27
B9: 2#（南） | C9: E+H | D9: 一期生反池 | E9: 正常 | F9: 校准 | G9: =G8 -> 2023-11-06 2023-11-13 2023-11-20 2023-11-27
B10: 1#（北） | C10: E+H | D10: 一期生反池 | E10: 正常 | F10: 校准 | G10: =G9 -> 2023-11-06 2023-11-13 2023-11-20 2023-11-27
B11: 2#（北） | C11: E+H | D11: 一期生反池 | E11: 正常 | F11: 校准 | G11: =G10 -> 2023-11-06 2023-11-13 2023-11-20 2023-11-27
A12: 进水PH计 | B12: 1# | C12: 哈希 | D12: 一期旋流沉砂池 | E12: 正常 | F12: 标定 | G12: =G11 -> 2023-11-06 2023-11-13 2023-11-20 2023-11-27
A13: 二期溶氧仪 | B13: 1#（南） | C13: 哈希LDO | D13: 二期生反池 | E13: 正常 | F13: 校准 | G13: =G12 -> 2023-11-06 2023-11-13 2023-11-20 2023-11-27
B14: 2#（南） | C14: 哈希LDO | D14: 二期生反池 | E14: 正常 | F14: 校准 | G14: =G13 -> 2023-11-06 2023-11-13 2023-11-20 2023-11-27
B15: 1#（北） | C15: 哈希LDO | D15: 二期生反池 | E15: 正常 | F15: 校准 | G15: =G14 -> 2023-11-06 2023-11-13 2023-11-20 2023-11-27
B16: 2#（北） | C16: 哈希LDO | D16: 二期生反池 | E16: 正常 | F16: 校准 | G16: =G15 -> 2023-11-06 2023-11-13 2023-11-20 2023-11-27
A17: 二期污泥浓度计 | B17: 1#（南） | C17: E+H | D17: 二期生反池 | E17: 正常 | F17: 校准 | G17: =G16 -> 2023-11-06 2023-11-13 2023-11-20 2023-11-27
B18: 2#（南） | C18: E+H | D18: 二期生反池 | E18: 正常 | F18: 校准 | G18: =G17 -> 2023-11-06 2023-11-13 2023-11-20 2023-11-27
B19: 1#（北） | C19: E+H | D19: 二期生反池 | E19: 正常 | F19: 校准 | G19: =G18 -> 2023-11-06 2023-11-13 2023-11-20 2023-11-27
B20: 2#（北） | C20: E+H | D20: 二期生反池 | E20: 正常 | F20: 校准 | G20: =G19 -> 2023-11-06 2023-11-13 2023-11-20 2023-11-27
A21: 审核： | D21: 制表： | F21: 制表日期：2023/12/5
A25: 常州市深水江边污水处理有限公司污水运行月报表
D26: =D2 -> 45231
A27: 仪表名称 | B27: 编号 | C27: 规格型号 | D27: 安装位置 | E27: 运行情况 | F27: 标定、校准情况 | G27: 备注
A28: 一期ORP | B28: 1#（南） | C28: E+H | D28: 一期生反池 | E28: 正常 | F28: 标定 | G28: 45245
B29: 2#（北） | C29: E+H | D29: 一期生反池 | E29: 正常 | F29: 标定 | G29: =G28 -> 45245
A30: 二期ORP | B30: 1#（南） | C30: 哈希 | D30: 二期生反池 | E30: 正常 | F30: 标定 | G30: =G29 -> 45245
B31: 2#（北） | C31: 哈希 | D31: 二期生反池 | E31: 正常 | F31: 标定 | G31: =G30 -> 45245
A32: 审核： | D32: 制表： | F32: =F21 -> 制表日期：2023/12/5

Sheet 实验数据
A1: 常州市深水江边污水处理有限公司实验数据汇总表
A3: 采样地点：一期北 | E3: 采样时间：2023-11-22
A4: 硝化实验 | E4: 反硝化实验 | G4: 释磷实验
A5: 时间节点 | B5: NO3-N(mg/l) | C5: NH3-N(mg/l) | D5: PO43-(mg/l) | E5: 时间节点 | F5: NO3-N(mg/l) | G5: 时间节点 | H5: PO43-(mg/l)
A6: 0分钟 | B6: 1.01 | C6: 8.22 | D6: 3.35 | E6: 0分钟 | F6: 8.22 | G6: 0分钟 | H6: 2.13
A7: 15分钟 | B7: 2.75 | C7: 6.61 | D7: 2.13 | E7: 15分钟 | F7: 7.24 | G7: 30分钟 | H7: 2.45
A8: 30分钟 | B8: 5.12 | C8: 2.31 | D8: 1.38 | E8: 30分钟 | F8: 4.32 | G8: 60分钟 | H8: 3.53
A9: 60分钟 | B9: 7.68 | C9: 1.24 | D9: 0.71 | E9: 45分钟 | F9: 3.28 | G9: 90分钟 | H9: 4.82
A10: MLSS(mg/l) | B10: 4528 | E10: 60分钟 | F10: 2.42 | G10: MLSS(mg/l) | H10: 4842
E11: 90分钟 | F11: 1.88
E12: MLSS(mg/l) | F12: 4622
A13: 审核： | D13: 制表： | G13: 制表日期：2023/12/5
