Workbook

Sheet 处理量
A1: 常州市深水江边污水处理有限公司污水处理运行月报表
A2: 45139
A3: 日 期 | B3: 水温 | C3: 天气 | D3: 日处理 水量 （m3） | E3: 污泥量（T） | H3: 药剂量 | I3: MLSS | J3: 电耗 | K3: 混凝剂 | L3: 絮凝剂 阴离子 （kg） | M3: 盐酸 | N3: 氯酸钠 | O3: 乙酸（吨） | Q3: 回用水 （m3） | R3: 实际水量（m3） | T3: 费用统计 | U3: 成本分析用 | W3: 单价 | X3: 单耗 | Y3: 单位电耗 | Z3: 电费 | AA3: 电成本 | AB3: 最新时间 | AE3: 3742 | AF3: PAC | AG3: PAC费用 | AH3: PAM阳 | AI3: PAM阳费用 | AJ3: PAM阴 | AK3: PAM阴费用 | AL3: HCL | AM3: 盐酸费用 | AN3: NACLO3 | AO3: 氯酸钠费用 | AP3: 合计 | AS3: 干泥量 | AT3: 单耗
B4: 度 | C4: 状况 | E4: 国电 | F4: 英科环境 | G4: 其他 | H4: （Kg） | I4: （mg/l） | J4: ( 度 ) | K4: （Kg） | M4: （Kg） | N4: （Kg） | O4: 缺氧段 | P4: 提标段 | T4: 电量 | U4: =ROUND(J37*W4,2) -> 1051698 | W4: 0.66884888 | X4: =J36/R36 -> 0.26177762 | AB4: 45142 | AD4: 污泥量合计 | AE4: =AE3/31 -> 120.70968
A5: 1 | B5: 29.6 | C5: 晴 | D5: 208700 | E5: 0 | F5: 103.4 | G5: 0 | H5: 100 | I5: 3342 | J5: 50100 | K5: 31320 | L5: 0.2 | M5: 4686 | N5: 1560 | O5: 1.5 | P5: 0 | Q5: 5504 | R5: =D5-Q5 -> 203196 | T5: 聚丙烯酰阳离子 | U5: =H37*W5/1000 -> 86100 | W5: 28000 | X5: =H36/R36*1000 -> 0.51193474 | Y5: =J5/R5 -> 0.24655997 | Z5: =J5*$W$4 -> 33509.329 | AA5: =Z5/R5 -> 0.16491136 | AB5: 45142 | AC5: =AD5*(100-进出水!T7)/100 -> 21.9208 | AD5: =E5+F5+G5 -> 103.4 | AE5: 120 | AF5: =$W$9*K5/1000/R5 -> 0.064120947 | AG5: =AF5*R5 -> 13029.12 | AH5: =$W$5*H5/1000/R5 -> 0.013779799 | AI5: =AH5*R5 -> 2800 | AJ5: =$W$6*L5/1000/R5 -> 1.0236422e-05 | AK5: =AJ5*R5 -> 2.08 | AL5: =$W$7*M5/1000/R5 -> 0.010792772 | AM5: =AL5*R5 -> 2193.048 | AN5: =$W$8*N5/1000/R5 -> 0.038770448 | AO5: =AN5*R5 -> 7878 | AP5: =AF5+AH5+AJ5+AL5+AN5 -> 0.1274742 | AQ5: =AP5*R5 -> 25902.248 | AS5: =AD5*(100-进出水!T7)/100 -> 21.9208 | AT5: =H5/AS5 -> 4.5618773
A6: 2 | B6: 29.7 | C6: 晴 | D6: 212057 | E6: 0 | F6: 105.16 | G6: 15 | H6: 75 | I6: 4282 | J6: 51100 | K6: 18240 | L6: 0.2 | M6: 2840 | N6: 1008 | O6: 1.6 | P6: 0 | Q6: 5504 | R6: =D6-Q6 -> 206553 | T6: 聚丙烯酰阴离子 | U6: =L37*W6/1000 -> 49.92 | V6: =U5+U6 -> 86149.92 | W6: 10400 | X6: =L36/R36*1000 -> 0.00079911764 | Y6: =J6/R6 -> 0.24739413 | Z6: =J6*$W$4 -> 34178.178 | AA6: =Z6/R6 -> 0.16546929 | AB6: 45142 | AC6: =AD6*(100-进出水!T8)/100 -> 25.71424 | AD6: =E6+F6+G6 -> 120.16 | AE6: 120 | AF6: =$W$9*K6/1000/R6 -> 0.036735559 | AG6: =AF6*R6 -> 7587.84 | AH6: =$W$5*H6/1000/R6 -> 0.010166882 | AI6: =AH6*R6 -> 2100 | AJ6: =$W$6*L6/1000/R6 -> 1.0070055e-05 | AK6: =AJ6*R6 -> 2.08 | AL6: =$W$7*M6/1000/R6 -> 0.0064347649 | AM6: =AL6*R6 -> 1329.12 | AN6: =$W$8*N6/1000/R6 -> 0.024644522 | AO6: =AN6*R6 -> 5090.4 | AP6: =AF6+AH6+AJ6+AL6+AN6 -> 0.077991799 | AQ6: =AP6*R6 -> 16109.44 | AS6: =AD6*(100-进出水!T8)/100 -> 25.71424 | AT6: =H6/AS6 -> 2.9166719
A7: 3 | B7: 28.9 | C7: 晴 | D7: 211931 | E7: 0 | F7: 106.54 | G7: 0 | H7: 75 | I7: 3774 | J7: 51200 | K7: 14040 | L7: 0 | M7: 2130 | N7: 792 | O7: 1.7 | P7: 0 | Q7: 5496 | R7: =D7-Q7 -> 206435 | T7: 工业盐酸 | U7: =M37*W7/1000 -> 50008.14 | W7: 468 | X7: =M36/R36*1000 -> 17.789524 | Y7: =J7/R7 -> 0.24801996 | Z7: =J7*$W$4 -> 34245.063 | AA7: =Z7/R7 -> 0.16588787 | AB7: 45142 | AC7: =AD7*(100-进出水!T9)/100 -> 23.11918 | AD7: =E7+F7+G7 -> 106.54 | AE7: 120 | AF7: =$W$9*K7/1000/R7 -> 0.028292877 | AG7: =AF7*R7 -> 5840.64 | AH7: =$W$5*H7/1000/R7 -> 0.010172694 | AI7: =AH7*R7 -> 2100 | AJ7: =$W$6*L7/1000/R7 -> 0 | AK7: =AJ7*R7 -> 0 | AL7: =$W$7*M7/1000/R7 -> 0.0048288323 | AM7: =AL7*R7 -> 996.84 | AN7: =$W$8*N7/1000/R7 -> 0.019374622 | AO7: =AN7*R7 -> 3999.6 | AP7: =AF7+AH7+AJ7+AL7+AN7 -> 0.062669024 | AQ7: =AP7*R7 -> 12937.08 | AS7: =AD7*(100-进出水!T9)/100 -> 23.11918 | AT7: =H7/AS7 -> 3.2440597
A8: 4 | B8: 29.9 | C8: 晴 | D8: 211062 | E8: 0 | F8: 103.38 | G8: 0 | H8: 75 | I8: 4896 | J8: 54400 | K8: 7200 | L8: 0.2 | M8: 1988 | N8: 720 | O8: 1.6 | P8: 0 | Q8: 5488 | R8: =D8-Q8 -> 205574 | T8: 工业氯酸钠 | U8: =N37*W8/1000 -> 181800 | V8: =U7+U8 -> 231808.14 | W8: 5050 | X8: =N36/R36*1000 -> 5.9933823 | Y8: =J8/R8 -> 0.2646249 | Z8: =J8*$W$4 -> 36385.379 | AA8: =Z8/R8 -> 0.17699407 | AB8: 45142 | AC8: =AD8*(100-进出水!T10)/100 -> 21.81318 | AD8: =E8+F8+G8 -> 103.38 | AE8: 120 | AF8: =$W$9*K8/1000/R8 -> 0.014569936 | AG8: =AF8*R8 -> 2995.2 | AH8: =$W$5*H8/1000/R8 -> 0.0102153 | AI8: =AH8*R8 -> 2100 | AJ8: =$W$6*L8/1000/R8 -> 1.0118011e-05 | AK8: =AJ8*R8 -> 2.08 | AL8: =$W$7*M8/1000/R8 -> 0.0045257863 | AM8: =AL8*R8 -> 930.384 | AN8: =$W$8*N8/1000/R8 -> 0.017687062 | AO8: =AN8*R8 -> 3636 | AP8: =AF8+AH8+AJ8+AL8+AN8 -> 0.047008201 | AQ8: =AP8*R8 -> 9663.664 | AS8: =AD8*(100-进出水!T10)/100 -> 21.81318 | AT8: =H8/AS8 -> 3.4382882
A9: 5 | B9: 29 | C9: 晴 | D9: 209663 | E9: 0 | F9: 88.26 | G9: 0 | H9: 75 | I9: 4176 | J9: 55200 | K9: 5400 | L9: 0.2 | M9: 1278 | N9: 480 | O9: 1.4 | P9: 0 | Q9: 5480 | R9: =D9-Q9 -> 204183 | T9: 混凝药剂 | U9: =K37*W9/1000 -> 98841.6 | W9: 416 | X9: =K36/R36*1000 -> 39.556323 | Y9: =J9/R9 -> 0.27034572 | Z9: =J9*$W$4 -> 36920.458 | AA9: =Z9/R9 -> 0.18082043 | AB9: 45142 | AC9: =AD9*(100-进出水!T11)/100 -> 19.15242 | AD9: =E9+F9+G9 -> 88.26 | AE9: 120 | AF9: =$W$9*K9/1000/R9 -> 0.011001895 | AG9: =AF9*R9 -> 2246.4 | AH9: =$W$5*H9/1000/R9 -> 0.010284891 | AI9: =AH9*R9 -> 2100 | AJ9: =$W$6*L9/1000/R9 -> 1.018694e-05 | AK9: =AJ9*R9 -> 2.08 | AL9: =$W$7*M9/1000/R9 -> 0.0029292546 | AM9: =AL9*R9 -> 598.104 | AN9: =$W$8*N9/1000/R9 -> 0.011871703 | AO9: =AN9*R9 -> 2424 | AP9: =AF9+AH9+AJ9+AL9+AN9 -> 0.036097932 | AQ9: =AP9*R9 -> 7370.584 | AS9: =AD9*(100-进出水!T11)/100 -> 19.15242 | AT9: =H9/AS9 -> 3.9159542
A10: 6 | B10: 29.6 | C10: 晴 | D10: 213088 | E10: 0 | F10: 87.44 | G10: 0 | H10: 75 | I10: 4634 | J10: 53900 | K10: 5760 | L10: 0.2 | M10: 2485 | N10: 984 | O10: 1.4 | P10: 0 | Q10: 5488 | R10: =D10-Q10 -> 207600 | T10: 污泥外运 | U10: =T18 -> 32425.53 | V10: 计算见下表 | Y10: =J10/R10 -> 0.25963391 | Z10: =J10*$W$4 -> 36050.955 | AA10: =Z10/R10 -> 0.17365585 | AC10: =AD10*(100-进出水!T12)/100 -> 18.71216 | AD10: =E10+F10+G10 -> 87.44 | AE10: 120 | AF10: =$W$9*K10/1000/R10 -> 0.011542197 | AG10: =AF10*R10 -> 2396.16 | AH10: =$W$5*H10/1000/R10 -> 0.010115607 | AI10: =AH10*R10 -> 2100 | AJ10: =$W$6*L10/1000/R10 -> 1.0019268e-05 | AK10: =AJ10*R10 -> 2.08 | AL10: =$W$7*M10/1000/R10 -> 0.0056020231 | AM10: =AL10*R10 -> 1162.98 | AN10: =$W$8*N10/1000/R10 -> 0.023936416 | AO10: =AN10*R10 -> 4969.2 | AP10: =AF10+AH10+AJ10+AL10+AN10 -> 0.051206262 | AQ10: =AP10*R10 -> 10630.42 | AS10: =AD10*(100-进出水!T12)/100 -> 18.71216 | AT10: =H10/AS10 -> 4.0080889
A11: 7 | B11: 29.3 | C11: 晴 | D11: 198888 | E11: 0 | F11: 91.28 | G11: 0 | H11: 75 | I11: 4340 | J11: 52100 | K11: 5880 | L11: 0 | M11: 3550 | N11: 1248 | O11: 1.36 | P11: 0 | Q11: 5488 | R11: =D11-Q11 -> 193400 | T11: 自来水 | U11: =汇总!J5*W11 -> 17887.8 | W11: 4.2 | Y11: =J11/R11 -> 0.26938987 | Z11: =J11*$W$4 -> 34847.027 | AA11: =Z11/R11 -> 0.18018111 | AC11: =AD11*(100-进出水!T13)/100 -> 19.80776 | AD11: =E11+F11+G11 -> 91.28 | AE11: 120 | AF11: =$W$9*K11/1000/R11 -> 0.012647777 | AG11: =AF11*R11 -> 2446.08 | AH11: =$W$5*H11/1000/R11 -> 0.010858325 | AI11: =AH11*R11 -> 2100 | AJ11: =$W$6*L11/1000/R11 -> 0 | AK11: =AJ11*R11 -> 0 | AL11: =$W$7*M11/1000/R11 -> 0.008590486 | AM11: =AL11*R11 -> 1661.4 | AN11: =$W$8*N11/1000/R11 -> 0.032587384 | AO11: =AN11*R11 -> 6302.4 | AP11: =AF11+AH11+AJ11+AL11+AN11 -> 0.064683971 | AQ11: =AP11*R11 -> 12509.88 | AS11: =AD11*(100-进出水!T13)/100 -> 19.80776 | AT11: =H11/AS11 -> 3.7863948
A12: 8 | B12: 30.6 | C12: 晴 | D12: 201072 | E12: 0 | F12: 71.76 | G12: 0 | H12: 100 | I12: 4188 | J12: 52400 | K12: 6000 | L12: 0.2 | M12: 4260 | N12: 1488 | O12: 1.5 | P12: 0 | Q12: 5488 | R12: =D12-Q12 -> 195584 | Y12: =J12/R12 -> 0.26791558 | Z12: =J12*$W$4 -> 35047.681 | AA12: =Z12/R12 -> 0.17919503 | AC12: =AD12*(100-进出水!T14)/100 -> 15.21312 | AD12: =E12+F12+G12 -> 71.76 | AE12: 120 | AF12: =$W$9*K12/1000/R12 -> 0.01276178 | AG12: =AF12*R12 -> 2496 | AH12: =$W$5*H12/1000/R12 -> 0.014316099 | AI12: =AH12*R12 -> 2800 | AJ12: =$W$6*L12/1000/R12 -> 1.0634817e-05 | AK12: =AJ12*R12 -> 2.08 | AL12: =$W$7*M12/1000/R12 -> 0.010193472 | AM12: =AL12*R12 -> 1993.68 | AN12: =$W$8*N12/1000/R12 -> 0.038420321 | AO12: =AN12*R12 -> 7514.4 | AP12: =AF12+AH12+AJ12+AL12+AN12 -> 0.075702307 | AQ12: =AP12*R12 -> 14806.16 | AS12: =AD12*(100-进出水!T14)/100 -> 15.21312 | AT12: =H12/AS12 -> 6.5732736
A13: 9 | B13: 30.4 | C13: 晴 | D13: 196081 | E13: 0 | F13: 143.16 | G13: 0 | H13: 75 | I13: 4384 | J13: 52600 | K13: 5880 | L13: 0.2 | M13: 3195 | N13: 1056 | O13: 1.5 | P13: 0 | Q13: 5496 | R13: =D13-Q13 -> 190585 | U13: =U14/R37 -> 0.069389992 | Y13: =J13/R13 -> 0.27599234 | Z13: =J13*$W$4 -> 35181.451 | AA13: =Z13/R13 -> 0.18459717 | AC13: =AD13*(100-进出水!T15)/100 -> 30.49308 | AD13: =E13+F13+G13 -> 143.16 | AE13: 120 | AF13: =$W$9*K13/1000/R13 -> 0.012834588 | AG13: =AF13*R13 -> 2446.08 | AH13: =$W$5*H13/1000/R13 -> 0.011018706 | AI13: =AH13*R13 -> 2100 | AJ13: =$W$6*L13/1000/R13 -> 1.0913766e-05 | AK13: =AJ13*R13 -> 2.08 | AL13: =$W$7*M13/1000/R13 -> 0.0078456332 | AM13: =AL13*R13 -> 1495.26 | AN13: =$W$8*N13/1000/R13 -> 0.027981216 | AO13: =AN13*R13 -> 5332.8 | AP13: =AF13+AH13+AJ13+AL13+AN13 -> 0.059691056 | AQ13: =AP13*R13 -> 11376.22 | AS13: =AD13*(100-进出水!T15)/100 -> 30.49308 | AT13: =H13/AS13 -> 2.4595744
A14: 10 | B14: 30.6 | C14: 晴 | D14: 174580 | E14: 0 | F14: 126.78 | G14: 0 | H14: 125 | I14: 3912 | J14: 49000 | K14: 5760 | L14: 0.2 | M14: 4260 | N14: 1392 | O14: 1.5 | P14: 0 | Q14: 5488 | R14: =D14-Q14 -> 169092 | T14: 总药剂 | U14: =U5+U6+U7+U8+U9 -> 416799.66 | V14: 除磷药剂 | W14: =U6+U9 -> 98891.52 | Y14: =J14/R14 -> 0.28978308 | Z14: =J14*$W$4 -> 32773.595 | AA14: =Z14/R14 -> 0.19382109 | AC14: =AD14*(100-进出水!T16)/100 -> 26.87736 | AD14: =E14+F14+G14 -> 126.78 | AE14: 120 | AF14: =$W$9*K14/1000/R14 -> 0.014170747 | AG14: =AF14*R14 -> 2396.16 | AH14: =$W$5*H14/1000/R14 -> 0.020698791 | AI14: =AH14*R14 -> 3500 | AJ14: =$W$6*L14/1000/R14 -> 1.2300996e-05 | AK14: =AJ14*R14 -> 2.08 | AL14: =$W$7*M14/1000/R14 -> 0.011790505 | AM14: =AL14*R14 -> 1993.68 | AN14: =$W$8*N14/1000/R14 -> 0.041572635 | AO14: =AN14*R14 -> 7029.6 | AP14: =AF14+AH14+AJ14+AL14+AN14 -> 0.088244979 | AQ14: =AP14*R14 -> 14921.52 | AS14: =AD14*(100-进出水!T16)/100 -> 26.87736 | AT14: =H14/AS14 -> 4.6507544
A15: 11 | B15: 30.3 | C15: 晴 | D15: 179136 | E15: 0 | F15: 104.36 | G15: 0 | H15: 125 | I15: 5316 | J15: 49900 | K15: 9120 | L15: 0.2 | M15: 2343 | N15: 840 | O15: 1.5 | P15: 0 | Q15: 5488 | R15: =D15-Q15 -> 173648 | T15: 总泥量 | U15: 英科（吨） | V15: 国电（吨） | W15: 外运（吨） | Y15: =J15/R15 -> 0.28736294 | Z15: =J15*$W$4 -> 33375.559 | AA15: =Z15/R15 -> 0.19220238 | AC15: =AD15*(100-进出水!T17)/100 -> 22.01996 | AD15: =E15+F15+G15 -> 104.36 | AE15: 120 | AF15: =$W$9*K15/1000/R15 -> 0.021848337 | AG15: =AF15*R15 -> 3793.92 | AH15: =$W$5*H15/1000/R15 -> 0.020155717 | AI15: =AH15*R15 -> 3500 | AJ15: =$W$6*L15/1000/R15 -> 1.1978255e-05 | AK15: =AJ15*R15 -> 2.08 | AL15: =$W$7*M15/1000/R15 -> 0.0063146365 | AM15: =AL15*R15 -> 1096.524 | AN15: =$W$8*N15/1000/R15 -> 0.024428729 | AO15: =AN15*R15 -> 4242 | AP15: =AF15+AH15+AJ15+AL15+AN15 -> 0.072759398 | AQ15: =AP15*R15 -> 12634.524 | AS15: =AD15*(100-进出水!T17)/100 -> 22.01996 | AT15: =H15/AS15 -> 5.6766679
A16: 12 | B16: 31.2 | C16: 晴 | D16: 155260 | E16: 0 | F16: 70.18 | G16: 0 | H16: 75 | I16: 5046 | J16: 45700 | K16: 10800 | L16: 0 | M16: 1846 | N16: 648 | O16: 1.5 | P16: 0 | Q16: 5496 | R16: =D16-Q16 -> 149764 | T16: =U16+V16+W16 -> 3422.66 | U16: =F37 -> 2253.24 | V16: =E37 -> 1124.42 | W16: =G37 -> 45 | Y16: =J16/R16 -> 0.30514676 | Z16: =J16*$W$4 -> 30566.394 | AA16: =Z16/R16 -> 0.20409707 | AC16: =AD16*(100-进出水!T18)/100 -> 14.94834 | AD16: =E16+F16+G16 -> 70.18 | AE16: 120 | AF16: =$W$9*K16/1000/R16 -> 0.029999199 | AG16: =AF16*R16 -> 4492.8 | AH16: =$W$5*H16/1000/R16 -> 0.014022061 | AI16: =AH16*R16 -> 2100 | AJ16: =$W$6*L16/1000/R16 -> 0 | AK16: =AJ16*R16 -> 0 | AL16: =$W$7*M16/1000/R16 -> 0.0057685959 | AM16: =AL16*R16 -> 863.928 | AN16: =$W$8*N16/1000/R16 -> 0.021850378 | AO16: =AN16*R16 -> 3272.4 | AP16: =AF16+AH16+AJ16+AL16+AN16 -> 0.071640234 | AQ16: =AP16*R16 -> 10729.128 | AS16: =AD16*(100-进出水!T18)/100 -> 14.94834 | AT16: =H16/AS16 -> 5.0172795
A17: 13 | B17: 29.7 | C17: 晴 | D17: 156754 | E17: 0 | F17: 105.32 | G17: 0 | H17: 75 | I17: 3516 | J17: 46600 | K17: 11640 | L17: 0.2 | M17: 4970 | N17: 1632 | O17: 1.5 | P17: 0 | Q17: 5480 | R17: =D17-Q17 -> 151274 | T17: 江边费用 | U17: 9.6 | V17: 9.6 | Y17: =J17/R17 -> 0.30805029 | Z17: =J17*$W$4 -> 31168.358 | AA17: =Z17/R17 -> 0.20603909 | AC17: =AD17*(100-进出水!T19)/100 -> 22.53848 | AD17: =E17+F17+G17 -> 105.32 | AE17: 120 | AF17: =$W$9*K17/1000/R17 -> 0.032009731 | AG17: =AF17*R17 -> 4842.24 | AH17: =$W$5*H17/1000/R17 -> 0.013882095 | AI17: =AH17*R17 -> 2100 | AJ17: =$W$6*L17/1000/R17 -> 1.3749884e-05 | AK17: =AJ17*R17 -> 2.08 | AL17: =$W$7*M17/1000/R17 -> 0.015375808 | AM17: =AL17*R17 -> 2325.96 | AN17: =$W$8*N17/1000/R17 -> 0.054481272 | AO17: =AN17*R17 -> 8241.6 | AP17: =AF17+AH17+AJ17+AL17+AN17 -> 0.11576266 | AQ17: =AP17*R17 -> 17511.88 | AS17: =AD17*(100-进出水!T19)/100 -> 22.53848 | AT17: =H17/AS17 -> 3.3276423
A18: 14 | B18: 31.1 | C18: 阴 | D18: 153086 | E18: 0 | F18: 107.22 | G18: 0 | H18: 75 | I18: 4876 | J18: 49000 | K18: 11040 | L18: 0.2 | M18: 4260 | N18: 1392 | O18: 1.3 | P18: 0 | Q18: 4424 | R18: =D18-Q18 -> 148662 | T18: =U18+V18 -> 32425.53 | U18: =ROUND(U16*U17,2) -> 21631.1 | V18: =ROUND(V16*V17,2) -> 10794.43 | Y18: =J18/R18 -> 0.32960676 | Z18: =J18*$W$4 -> 32773.595 | AA18: =Z18/R18 -> 0.22045711 | AC18: =AD18*(100-进出水!T20)/100 -> 23.0523 | AD18: =E18+F18+G18 -> 107.22 | AE18: 120 | AF18: =$W$9*K18/1000/R18 -> 0.030893167 | AG18: =AF18*R18 -> 4592.64 | AH18: =$W$5*H18/1000/R18 -> 0.014126004 | AI18: =AH18*R18 -> 2100 | AJ18: =$W$6*L18/1000/R18 -> 1.3991471e-05 | AK18: =AJ18*R18 -> 2.08 | AL18: =$W$7*M18/1000/R18 -> 0.013410825 | AM18: =AL18*R18 -> 1993.68 | AN18: =$W$8*N18/1000/R18 -> 0.047285789 | AO18: =AN18*R18 -> 7029.6 | AP18: =AF18+AH18+AJ18+AL18+AN18 -> 0.10572978 | AQ18: =AP18*R18 -> 15718 | AS18: =AD18*(100-进出水!T20)/100 -> 23.0523 | AT18: =H18/AS18 -> 3.2534715
A19: 15 | B19: 30.2 | C19: 晴 | D19: 179776 | E19: 0 | F19: 104.6 | G19: 0 | H19: 75 | I19: 4006 | J19: 48500 | K19: 11040 | L19: 0.2 | M19: 4828 | N19: 1608 | O19: 1.8 | P19: 0 | Q19: 5264 | R19: =D19-Q19 -> 174512 | T19: 排水承担 | V19: 0 | Y19: =J19/R19 -> 0.27791785 | Z19: =J19*$W$4 -> 32439.171 | AA19: =Z19/R19 -> 0.18588504 | AC19: =AD19*(100-进出水!T21)/100 -> 22.1752 | AD19: =E19+F19+G19 -> 104.6 | AE19: 120 | AF19: =$W$9*K19/1000/R19 -> 0.026317044 | AG19: =AF19*R19 -> 4592.64 | AH19: =$W$5*H19/1000/R19 -> 0.012033556 | AI19: =AH19*R19 -> 2100 | AJ19: =$W$6*L19/1000/R19 -> 1.1918951e-05 | AK19: =AJ19*R19 -> 2.08 | AL19: =$W$7*M19/1000/R19 -> 0.012947557 | AM19: =AL19*R19 -> 2259.504 | AN19: =$W$8*N19/1000/R19 -> 0.046532044 | AO19: =AN19*R19 -> 8120.4 | AP19: =AF19+AH19+AJ19+AL19+AN19 -> 0.09784212 | AQ19: =AP19*R19 -> 17074.624 | AS19: =AD19*(100-进出水!T21)/100 -> 22.1752 | AT19: =H19/AS19 -> 3.3821566
A20: 16 | B20: 31.3 | C20: 晴 | D20: 202339 | E20: 17.92 | F20: 87.46 | G20: 0 | H20: 125 | I20: 4994 | J20: 53100 | K20: 11280 | L20: 0.2 | M20: 5325 | N20: 1680 | O20: 1.85 | P20: 0 | Q20: 5304 | R20: =D20-Q20 -> 197035 | T20: =U20+V20 -> 0 | V20: =ROUND(V16*V19,2) -> 0 | Y20: =J20/R20 -> 0.26949527 | Z20: =J20*$W$4 -> 35515.876 | AA20: =Z20/R20 -> 0.18025161 | AC20: =AD20*(100-进出水!T22)/100 -> 22.55132 | AD20: =E20+F20+G20 -> 105.38 | AE20: 120 | AF20: =$W$9*K20/1000/R20 -> 0.023815464 | AG20: =AF20*R20 -> 4692.48 | AH20: =$W$5*H20/1000/R20 -> 0.017763342 | AI20: =AH20*R20 -> 3500 | AJ20: =$W$6*L20/1000/R20 -> 1.05565e-05 | AK20: =AJ20*R20 -> 2.08 | AL20: =$W$7*M20/1000/R20 -> 0.012648007 | AM20: =AL20*R20 -> 2492.1 | AN20: =$W$8*N20/1000/R20 -> 0.04305834 | AO20: =AN20*R20 -> 8484 | AP20: =AF20+AH20+AJ20+AL20+AN20 -> 0.097295709 | AQ20: =AP20*R20 -> 19170.66 | AS20: =AD20*(100-进出水!T22)/100 -> 22.55132 | AT20: =H20/AS20 -> 5.5429128
A21: 17 | B21: 31.1 | C21: 晴 | D21: 208273 | E21: 82.96 | F21: 53.4 | G21: 0 | H21: 150 | I21: 4364 | J21: 52800 | K21: 10800 | L21: 0 | M21: 2556 | N21: 912 | O21: 1.75 | P21: 0 | Q21: 5312 | R21: =D21-Q21 -> 202961 | T21: 总运费 | U21: 总单价 | V21: =V17+V19 -> 9.6 | W21: 核对 | Y21: =J21/R21 -> 0.2601485 | Z21: =J21*$W$4 -> 35315.221 | AA21: =Z21/R21 -> 0.17400003 | AC21: =AD21*(100-进出水!T23)/100 -> 29.72648 | AD21: =E21+F21+G21 -> 136.36 | AE21: 120 | AF21: =$W$9*K21/1000/R21 -> 0.022136272 | AG21: =AF21*R21 -> 4492.8 | AH21: =$W$5*H21/1000/R21 -> 0.020693631 | AI21: =AH21*R21 -> 4200 | AJ21: =$W$6*L21/1000/R21 -> 0 | AK21: =AJ21*R21 -> 0 | AL21: =$W$7*M21/1000/R21 -> 0.0058937825 | AM21: =AL21*R21 -> 1196.208 | AN21: =$W$8*N21/1000/R21 -> 0.022692044 | AO21: =AN21*R21 -> 4605.6 | AP21: =AF21+AH21+AJ21+AL21+AN21 -> 0.07141573 | AQ21: =AP21*R21 -> 14494.608 | AS21: =AD21*(100-进出水!T23)/100 -> 29.72648 | AT21: =H21/AS21 -> 5.0460061
A22: 18 | B22: 31.1 | C22: 晴 | D22: 212838 | E22: 122.48 | F22: 34.76 | G22: 0 | H22: 150 | I22: 4136 | J22: 48200 | K22: 0 | L22: 0.2 | M22: 2485 | N22: 864 | O22: 1.8 | P22: 0 | Q22: 5304 | R22: =D22-Q22 -> 207534 | T22: =T18+T20 -> 32425.53 | W22: =T16-E37-F37-G37 -> 0 | Y22: =J22/R22 -> 0.2322511 | Z22: =J22*$W$4 -> 32238.516 | AA22: =Z22/R22 -> 0.15534089 | AC22: =AD22*(100-进出水!T24)/100 -> 33.64936 | AD22: =E22+F22+G22 -> 157.24 | AE22: 120 | AF22: =$W$9*K22/1000/R22 -> 0 | AG22: =AF22*R22 -> 0 | AH22: =$W$5*H22/1000/R22 -> 0.020237648 | AI22: =AH22*R22 -> 4200 | AJ22: =$W$6*L22/1000/R22 -> 1.0022454e-05 | AK22: =AJ22*R22 -> 2.08 | AL22: =$W$7*M22/1000/R22 -> 0.0056038047 | AM22: =AL22*R22 -> 1162.98 | AN22: =$W$8*N22/1000/R22 -> 0.021024025 | AO22: =AN22*R22 -> 4363.2 | AP22: =AF22+AH22+AJ22+AL22+AN22 -> 0.0468755 | AQ22: =AP22*R22 -> 9728.26 | AS22: =AD22*(100-进出水!T24)/100 -> 33.64936 | AT22: =H22/AS22 -> 4.4577371
A23: 19 | B23: 30.5 | C23: 晴 | D23: 215360 | E23: 79.22 | F23: 49.8 | G23: 0 | H23: 150 | I23: 3824 | J23: 51000 | K23: 0 | L23: 0.2 | M23: 1988 | N23: 720 | O23: 1.85 | P23: 0 | Q23: 5320 | R23: =D23-Q23 -> 210040 | Y23: =J23/R23 -> 0.24281089 | Z23: =J23*$W$4 -> 34111.293 | AA23: =Z23/R23 -> 0.16240379 | AC23: =AD23*(100-进出水!T25)/100 -> 27.86832 | AD23: =E23+F23+G23 -> 129.02 | AE23: 120 | AF23: =$W$9*K23/1000/R23 -> 0 | AG23: =AF23*R23 -> 0 | AH23: =$W$5*H23/1000/R23 -> 0.019996191 | AI23: =AH23*R23 -> 4200 | AJ23: =$W$6*L23/1000/R23 -> 9.9028756e-06 | AK23: =AJ23*R23 -> 2.08 | AL23: =$W$7*M23/1000/R23 -> 0.0044295563 | AM23: =AL23*R23 -> 930.384 | AN23: =$W$8*N23/1000/R23 -> 0.017310988 | AO23: =AN23*R23 -> 3636 | AP23: =AF23+AH23+AJ23+AL23+AN23 -> 0.041746639 | AQ23: =AP23*R23 -> 8768.464 | AS23: =AD23*(100-进出水!T25)/100 -> 27.86832 | AT23: =H23/AS23 -> 5.3824558
A24: 20 | B24: 30.9 | C24: 晴 | D24: 213868 | E24: 98.42 | F24: 32 | G24: 0 | H24: 150 | I24: 3986 | J24: 51500 | K24: 0 | L24: 0.2 | M24: 4118 | N24: 1440 | O24: 1.8 | P24: 0 | Q24: 5312 | R24: =D24-Q24 -> 208556 | T24: 絮凝剂 | U24: 用量（kg） | V24: =H37 -> 3075 | W24: =L37 -> 4.8 | Y24: =J24/R24 -> 0.24693607 | Z24: =J24*$W$4 -> 34445.717 | AA24: =Z24/R24 -> 0.16516292 | AC24: =AD24*(100-进出水!T26)/100 -> 27.64904 | AD24: =E24+F24+G24 -> 130.42 | AE24: 120 | AF24: =$W$9*K24/1000/R24 -> 0 | AG24: =AF24*R24 -> 0 | AH24: =$W$5*H24/1000/R24 -> 0.020138476 | AI24: =AH24*R24 -> 4200 | AJ24: =$W$6*L24/1000/R24 -> 9.9733405e-06 | AK24: =AJ24*R24 -> 2.08 | AL24: =$W$7*M24/1000/R24 -> 0.0092407986 | AM24: =AL24*R24 -> 1927.224 | AN24: =$W$8*N24/1000/R24 -> 0.034868333 | AO24: =AN24*R24 -> 7272 | AP24: =AF24+AH24+AJ24+AL24+AN24 -> 0.064257581 | AQ24: =AP24*R24 -> 13401.304 | AS24: =AD24*(100-进出水!T26)/100 -> 27.64904 | AT24: =H24/AS24 -> 5.4251432
A25: 21 | B25: 31.2 | C25: 晴 | D25: 209817 | E25: 112.16 | F25: 16.02 | G25: 0 | H25: 150 | I25: 4368 | J25: 50700 | K25: 0 | L25: 0 | M25: 4473 | N25: 1488 | O25: 1.8 | P25: 0 | Q25: 3648 | R25: =D25-Q25 -> 206169 | U25: 单耗（kg/T） | V25: =汇总!F6 -> 4.1982431 | W25: =W24/R37*1000 -> 0.00079911764 | Y25: =J25/R25 -> 0.24591476 | Z25: =J25*$W$4 -> 33910.638 | AA25: =Z25/R25 -> 0.16447981 | AC25: =AD25*(100-进出水!T27)/100 -> 27.30234 | AD25: =E25+F25+G25 -> 128.18 | AE25: 120 | AF25: =$W$9*K25/1000/R25 -> 0 | AG25: =AF25*R25 -> 0 | AH25: =$W$5*H25/1000/R25 -> 0.020371637 | AI25: =AH25*R25 -> 4200 | AJ25: =$W$6*L25/1000/R25 -> 0 | AK25: =AJ25*R25 -> 0 | AL25: =$W$7*M25/1000/R25 -> 0.010153631 | AM25: =AL25*R25 -> 2093.364 | AN25: =$W$8*N25/1000/R25 -> 0.036447769 | AO25: =AN25*R25 -> 7514.4 | AP25: =AF25+AH25+AJ25+AL25+AN25 -> 0.066973037 | AQ25: =AP25*R25 -> 13807.764 | AS25: =AD25*(100-进出水!T27)/100 -> 27.30234 | AT25: =H25/AS25 -> 5.4940346
A26: 22 | B26: 30.6 | C26: 阴 | D26: 208774 | E26: 99.98 | F26: 66.62 | G26: 0 | H26: 150 | I26: 3986 | J26: 50600 | K26: 0 | L26: 0.2 | M26: 2982 | N26: 960 | O26: 1.85 | P26: 0 | Q26: 1568 | R26: =D26-Q26 -> 207206 | T26: 混凝剂 | U26: 用量（kg） | V26: =K37 -> 237600 | Y26: =J26/R26 -> 0.24420142 | Z26: =J26*$W$4 -> 33843.753 | AA26: =Z26/R26 -> 0.16333385 | AC26: =AD26*(100-进出水!T28)/100 -> 35.819 | AD26: =E26+F26+G26 -> 166.6 | AE26: 120 | AF26: =$W$9*K26/1000/R26 -> 0 | AG26: =AF26*R26 -> 0 | AH26: =$W$5*H26/1000/R26 -> 0.020269683 | AI26: =AH26*R26 -> 4200 | AJ26: =$W$6*L26/1000/R26 -> 1.0038319e-05 | AK26: =AJ26*R26 -> 2.08 | AL26: =$W$7*M26/1000/R26 -> 0.0067352104 | AM26: =AL26*R26 -> 1395.576 | AN26: =$W$8*N26/1000/R26 -> 0.023397006 | AO26: =AN26*R26 -> 4848 | AP26: =AF26+AH26+AJ26+AL26+AN26 -> 0.050411938 | AQ26: =AP26*R26 -> 10445.656 | AS26: =AD26*(100-进出水!T28)/100 -> 35.819 | AT26: =H26/AS26 -> 4.1877216
A27: 23 | B27: 30.5 | C27: 晴 | D27: 212141 | E27: 66.26 | F27: 52.3 | G27: 30 | H27: 150 | I27: 3144 | J27: 50600 | K27: 0 | L27: 0.2 | M27: 3905 | N27: 1200 | O27: 1.8 | P27: 0 | Q27: 5376 | R27: =D27-Q27 -> 206765 | U27: 单耗（g/m3） | V27: =ROUND(K37/R37*1000,1) -> 39.6 | Y27: =J27/R27 -> 0.24472227 | Z27: =J27*$W$4 -> 33843.753 | AA27: =Z27/R27 -> 0.16368222 | AC27: =AD27*(100-进出水!T29)/100 -> 31.79184 | AD27: =E27+F27+G27 -> 148.56 | AE27: 120 | AF27: =$W$9*K27/1000/R27 -> 0 | AG27: =AF27*R27 -> 0 | AH27: =$W$5*H27/1000/R27 -> 0.020312916 | AI27: =AH27*R27 -> 4200 | AJ27: =$W$6*L27/1000/R27 -> 1.005973e-05 | AK27: =AJ27*R27 -> 2.08 | AL27: =$W$7*M27/1000/R27 -> 0.00883873 | AM27: =AL27*R27 -> 1827.54 | AN27: =$W$8*N27/1000/R27 -> 0.029308635 | AO27: =AN27*R27 -> 6060 | AP27: =AF27+AH27+AJ27+AL27+AN27 -> 0.058470341 | AQ27: =AP27*R27 -> 12089.62 | AS27: =AD27*(100-进出水!T29)/100 -> 31.79184 | AT27: =H27/AS27 -> 4.7181918
A28: 24 | B28: 30.3 | C28: 晴 | D28: 211128 | E28: 115.98 | F28: 51.52 | G28: 0 | H28: 100 | I28: 3674 | J28: 53500 | K28: 0 | L28: 0.2 | M28: 4260 | N28: 1392 | O28: 1.8 | P28: 0 | Q28: 5384 | R28: =D28-Q28 -> 205744 | T28: 盐酸 | U28: 用量（kg） | V28: =M37 -> 106855 | Y28: =J28/R28 -> 0.26003188 | Z28: =J28*$W$4 -> 35783.415 | AA28: =Z28/R28 -> 0.17392204 | AC28: =AD28*(100-进出水!T30)/100 -> 35.3425 | AD28: =E28+F28+G28 -> 167.5 | AE28: 120 | AF28: =$W$9*K28/1000/R28 -> 0 | AG28: =AF28*R28 -> 0 | AH28: =$W$5*H28/1000/R28 -> 0.013609145 | AI28: =AH28*R28 -> 2800 | AJ28: =$W$6*L28/1000/R28 -> 1.0109651e-05 | AK28: =AJ28*R28 -> 2.08 | AL28: =$W$7*M28/1000/R28 -> 0.0096901003 | AM28: =AL28*R28 -> 1993.68 | AN28: =$W$8*N28/1000/R28 -> 0.034166731 | AO28: =AN28*R28 -> 7029.6 | AP28: =AF28+AH28+AJ28+AL28+AN28 -> 0.057476087 | AQ28: =AP28*R28 -> 11825.36 | AS28: =AD28*(100-进出水!T30)/100 -> 35.3425 | AT28: =H28/AS28 -> 2.8294546
A29: 25 | B29: 30.5 | C29: 晴 | D29: 208112 | E29: 88.26 | F29: 52.78 | G29: 0 | H29: 75 | I29: 3448 | J29: 52800 | K29: 0 | L29: 0 | M29: 2130 | N29: 768 | O29: 1.85 | P29: 0 | Q29: 5384 | R29: =D29-Q29 -> 202728 | U29: 单耗（g/m3） | V29: =ROUND(M37/R37*1000,1) -> 17.8 | Y29: =J29/R29 -> 0.2604475 | Z29: =J29*$W$4 -> 35315.221 | AA29: =Z29/R29 -> 0.17420002 | AC29: =AD29*(100-进出水!T31)/100 -> 30.04152 | AD29: =E29+F29+G29 -> 141.04 | AE29: 120 | AF29: =$W$9*K29/1000/R29 -> 0 | AG29: =AF29*R29 -> 0 | AH29: =$W$5*H29/1000/R29 -> 0.010358707 | AI29: =AH29*R29 -> 2100 | AJ29: =$W$6*L29/1000/R29 -> 0 | AK29: =AJ29*R29 -> 0 | AL29: =$W$7*M29/1000/R29 -> 0.0049171303 | AM29: =AL29*R29 -> 996.84 | AN29: =$W$8*N29/1000/R29 -> 0.019131052 | AO29: =AN29*R29 -> 3878.4 | AP29: =AF29+AH29+AJ29+AL29+AN29 -> 0.03440689 | AQ29: =AP29*R29 -> 6975.24 | AS29: =AD29*(100-进出水!T31)/100 -> 30.04152 | AT29: =H29/AS29 -> 2.4965448
A30: 26 | B30: 31.1 | C30: 晴 | D30: 188448 | E30: 16.62 | F30: 54.48 | G30: 0 | H30: 75 | I30: 3642 | J30: 48500 | K30: 1320 | L30: 0.2 | M30: 1988 | N30: 648 | O30: 1.75 | P30: 0 | Q30: 5376 | R30: =D30-Q30 -> 183072 | T30: 氯酸钠 | U30: 用量（kg） | V30: =处理量!N37 -> 36000 | Y30: =J30/R30 -> 0.26492309 | Z30: =J30*$W$4 -> 32439.171 | AA30: =Z30/R30 -> 0.17719351 | AC30: =AD30*(100-进出水!T32)/100 -> 15.2865 | AD30: =E30+F30+G30 -> 71.1 | AE30: 120 | AF30: =$W$9*K30/1000/R30 -> 0.0029994756 | AG30: =AF30*R30 -> 549.12 | AH30: =$W$5*H30/1000/R30 -> 0.011470897 | AI30: =AH30*R30 -> 2100 | AJ30: =$W$6*L30/1000/R30 -> 1.136165e-05 | AK30: =AJ30*R30 -> 2.08 | AL30: =$W$7*M30/1000/R30 -> 0.0050820661 | AM30: =AL30*R30 -> 930.384 | AN30: =$W$8*N30/1000/R30 -> 0.017874934 | AO30: =AN30*R30 -> 3272.4 | AP30: =AF30+AH30+AJ30+AL30+AN30 -> 0.037438734 | AQ30: =AP30*R30 -> 6853.984 | AS30: =AD30*(100-进出水!T32)/100 -> 15.2865 | AT30: =H30/AS30 -> 4.9062899
A31: 27 | B31: 29.3 | C31: 阴 | D31: 178494 | E31: 52.86 | F31: 32.36 | G31: 0 | H31: 75 | I31: 4114 | J31: 50600 | K31: 16680 | L31: 0.2 | M31: 4828 | N31: 1560 | O31: 1.8 | P31: 0 | Q31: 5376 | R31: =D31-Q31 -> 173118 | U31: 单耗（g/m3） | V31: =ROUND(N37/R37*1000,2) -> 5.99 | Y31: =J31/R31 -> 0.29228619 | Z31: =J31*$W$4 -> 33843.753 | AA31: =Z31/R31 -> 0.19549529 | AC31: =AD31*(100-进出水!T33)/100 -> 18.49274 | AD31: =E31+F31+G31 -> 85.22 | AE31: 120 | AF31: =$W$9*K31/1000/R31 -> 0.040081794 | AG31: =AF31*R31 -> 6938.88 | AH31: =$W$5*H31/1000/R31 -> 0.012130454 | AI31: =AH31*R31 -> 2100 | AJ31: =$W$6*L31/1000/R31 -> 1.2014926e-05 | AK31: =AJ31*R31 -> 2.08 | AL31: =$W$7*M31/1000/R31 -> 0.013051814 | AM31: =AL31*R31 -> 2259.504 | AN31: =$W$8*N31/1000/R31 -> 0.045506533 | AO31: =AN31*R31 -> 7878 | AP31: =AF31+AH31+AJ31+AL31+AN31 -> 0.11078261 | AQ31: =AP31*R31 -> 19178.464 | AS31: =AD31*(100-进出水!T33)/100 -> 18.49274 | AT31: =H31/AS31 -> 4.0556456
A32: 28 | B32: 30.6 | C32: 阴 | D32: 204298 | E32: 53.14 | F32: 15.04 | G32: 0 | H32: 75 | I32: 4492 | J32: 49600 | K32: 11280 | L32: 0.2 | M32: 4118 | N32: 1416 | O32: 1.75 | P32: 0 | Q32: 5376 | R32: =D32-Q32 -> 198922 | T32: 乙酸 | U32: 用量（T） | V32: =O37 -> 51.41 | Y32: =J32/R32 -> 0.24934396 | Z32: =J32*$W$4 -> 33174.905 | AA32: =Z32/R32 -> 0.16677343 | AC32: =AD32*(100-进出水!T34)/100 -> 14.59052 | AD32: =E32+F32+G32 -> 68.18 | AE32: 120 | AF32: =$W$9*K32/1000/R32 -> 0.023589548 | AG32: =AF32*R32 -> 4692.48 | AH32: =$W$5*H32/1000/R32 -> 0.010556902 | AI32: =AH32*R32 -> 2100 | AJ32: =$W$6*L32/1000/R32 -> 1.045636e-05 | AK32: =AJ32*R32 -> 2.08 | AL32: =$W$7*M32/1000/R32 -> 0.0096883402 | AM32: =AL32*R32 -> 1927.224 | AN32: =$W$8*N32/1000/R32 -> 0.035947758 | AO32: =AN32*R32 -> 7150.8 | AP32: =AF32+AH32+AJ32+AL32+AN32 -> 0.079793004 | AQ32: =AP32*R32 -> 15872.584 | AS32: =AD32*(100-进出水!T34)/100 -> 14.59052 | AT32: =H32/AS32 -> 5.140324
A33: 29 | B33: 30.1 | C33: 阴 | D33: 210620 | E33: 34.16 | F33: 50.12 | G33: 0 | H33: 75 | I33: 4586 | J33: 51000 | K33: 9120 | L33: 0.2 | M33: 4970 | N33: 1560 | O33: 1.8 | P33: 0 | Q33: 5384 | R33: =D33-Q33 -> 205236 | U33: 单耗（g/m3） | V33: =ROUND(V32/R37*1000000,2) -> 8.56 | Y33: =J33/R33 -> 0.24849442 | Z33: =J33*$W$4 -> 34111.293 | AA33: =Z33/R33 -> 0.16620521 | AC33: =AD33*(100-进出水!T35)/100 -> 18.20448 | AD33: =E33+F33+G33 -> 84.28 | AE33: 120 | AF33: =$W$9*K33/1000/R33 -> 0.018485646 | AG33: =AF33*R33 -> 3793.92 | AH33: =$W$5*H33/1000/R33 -> 0.010232123 | AI33: =AH33*R33 -> 2100 | AJ33: =$W$6*L33/1000/R33 -> 1.0134674e-05 | AK33: =AJ33*R33 -> 2.08 | AL33: =$W$7*M33/1000/R33 -> 0.011333099 | AM33: =AL33*R33 -> 2325.96 | AN33: =$W$8*N33/1000/R33 -> 0.038385079 | AO33: =AN33*R33 -> 7878 | AP33: =AF33+AH33+AJ33+AL33+AN33 -> 0.078446082 | AQ33: =AP33*R33 -> 16099.96 | AS33: =AD33*(100-进出水!T35)/100 -> 18.20448 | AT33: =H33/AS33 -> 4.119865
A34: 30 | B34: 29.4 | C34: 雨 | D34: 212360 | E34: 34.62 | F34: 50.08 | G34: 0 | H34: 75 | I34: 3562 | J34: 49600 | K34: 9000 | L34: 0 | M34: 4260 | N34: 1392 | O34: 1.8 | P34: 0 | Q34: 5376 | R34: =D34-Q34 -> 206984 | Y34: =J34/R34 -> 0.23963205 | Z34: =J34*$W$4 -> 33174.905 | AA34: =Z34/R34 -> 0.16027763 | AC34: =AD34*(100-进出水!T36)/100 -> 18.0411 | AD34: =E34+F34+G34 -> 84.7 | AE34: 120 | AF34: =$W$9*K34/1000/R34 -> 0.018088355 | AG34: =AF34*R34 -> 3744 | AH34: =$W$5*H34/1000/R34 -> 0.010145712 | AI34: =AH34*R34 -> 2100 | AJ34: =$W$6*L34/1000/R34 -> 0 | AK34: =AJ34*R34 -> 0 | AL34: =$W$7*M34/1000/R34 -> 0.0096320489 | AM34: =AL34*R34 -> 1993.68 | AN34: =$W$8*N34/1000/R34 -> 0.033962045 | AO34: =AN34*R34 -> 7029.6 | AP34: =AF34+AH34+AJ34+AL34+AN34 -> 0.071828161 | AQ34: =AP34*R34 -> 14867.28 | AS34: =AD34*(100-进出水!T36)/100 -> 18.0411 | AT34: =H34/AS34 -> 4.1571745
A35: 31 | B35: 28.7 | C35: 晴 | D35: 209861 | E35: 49.38 | F35: 35.66 | G35: 0 | H35: 75 | I35: 3980 | J35: 46600 | K35: 9000 | L35: 0.2 | M35: 3550 | N35: 1152 | O35: 1.7 | P35: 0 | Q35: 5368 | R35: =D35-Q35 -> 204493 | Y35: =J35/R35 -> 0.22788066 | Z35: =J35*$W$4 -> 31168.358 | AA35: =Z35/R35 -> 0.15241773 | AC35: =AD35*(100-进出水!T37)/100 -> 18.19856 | AD35: =E35+F35+G35 -> 85.04 | AE35: 142 | AF35: =$W$9*K35/1000/R35 -> 0.018308695 | AG35: =AF35*R35 -> 3744 | AH35: =$W$5*H35/1000/R35 -> 0.0102693 | AI35: =AH35*R35 -> 2100 | AJ35: =$W$6*L35/1000/R35 -> 1.0171497e-05 | AK35: =AJ35*R35 -> 2.08 | AL35: =$W$7*M35/1000/R35 -> 0.0081244835 | AM35: =AL35*R35 -> 1661.4 | AN35: =$W$8*N35/1000/R35 -> 0.028448896 | AO35: =AN35*R35 -> 5817.6 | AP35: =AF35+AH35+AJ35+AL35+AN35 -> 0.065161546 | AQ35: =AP35*R35 -> 13325.08 | AS35: =AD35*(100-进出水!T37)/100 -> 18.19856 | AT35: =H35/AS35 -> 4.1212052
A36: 平均 | B36: =AVERAGE(B5:B35) -> 30.235484 | C36: / | D36: =AVERAGE(D5:D35) -> 198963.39 | E36: =AVERAGE(E5:E35) -> 36.271613 | F36: =AVERAGE(F5:F35) -> 72.685161 | G36: =AVERAGE(G5:G35) -> 1.4516129 | H36: =AVERAGE(H5:H35) -> 99.193548 | I36: =AVERAGE(I5:I35) -> 4160.9032 | J36: =AVERAGE(J5:J35) -> 50722.581 | K36: =AVERAGE(K5:K35) -> 7664.5161 | ... Q36: =AVERAGE(Q5:Q35) -> 5201.2903 | R36: =D36-Q36 -> 193762.1
A37: 合计 | B37: / | C37: / | D37: =SUM(D5:D35) -> 6167865 | E37: =SUM(E5:E35) -> 1124.42 | F37: =SUM(F5:F35) -> 2253.24 | G37: =SUM(G5:G35) -> 45 | H37: =SUM(H5:H35) -> 3075 | I37: / | J37: =SUM(J5:J35) -> 1572400 | K37: =SUM(K5:K35) -> 237600 | L37: =SUM(L5:L35) -> 4.8 | M37: =SUM(M5:M35) -> 106855 | N37: =SUM(N5:N35) -> 36000 | O37: =SUM(O5:O35) -> 51.41 | P37: =SUM(P5:P35) -> 0 | Q37: =SUM(Q5:Q35) -> 161240 | R37: =SUM(R5:R35) -> 6006625 | AD37: =SUM(AD5:AD36) -> 3422.66
A38: 审核： | I38: 制表： | Q38: 制表时间: | R38: 45173
M39: =M37*0.31 -> 33125.05
Q40: 最大 | R40: =MAX(R5:R35) -> 210040 | AD40: =(100-进出水!T38)*AD37/100 -> 732.44924
...

Sheet 汇总
A1: 常州市深水江边污水处理有限公司污水运行月报表
A2: =处理量!A2 -> 45139
A3: 污 水 处 理 | B3: 污水处理量（m3） | C3: =处理量!R37 -> 6006625 | D3: 污 泥 处 理 | E3: 脱水污泥量（T） | F3: =处理量!E37+处理量!F37+处理量!G37 -> 3422.66 | G3: 水 电 用 量 | H3: 用电量（度） | J3: =处理量!J37 -> 1572400 | K3: 污 水 电 单 耗 | L3: 污水（度/m3） | M3: =J3/C3 -> 0.26177762 | P3: 除臭用水量 | Q3: 1773.2 | R3: =J5-Q3 -> 2485.8 | V3: 188314
B4: 日均处理量（m3） | C4: =处理量!R36 -> 193762.1 | E4: 絮凝剂用量（kg） | F4: =处理量!H37 -> 3075 | H4: 日均用电量（度） | J4: =J3/M15 -> 50722.581 | L4: CODcr（度/kg） | M4: =J3/I12 -> 2.1077103 | P4: 除臭用电量 | Q4: 50536 | V4: 193894
E5: 含水率（%） | F5: =进出水!T38 -> 78.6 | H5: 用水量（T） | J5: 4259 | V5: =V4-V3 -> 5580
B6: 最高日处理量 | C6: =处理量!R40 -> 210040 | E6: 絮凝剂单耗（kg/T） | F6: =F4/(F3*(100-F5)/100) -> 4.1982431 | G6: 消 毒 剂 | H6: 工业合成盐酸（T） | J6: =处理量!M37/1000 -> 106.855 | L6: BOD5（度/kg） | M6: =J3/I13 -> 4.0529125
B7: 最低日处理量 | C7: =处理量!R41 -> 148662 | E7: 产泥率(g/m３) | F7: =F3*(100-F5)/100*1000/(C3/1000) -> 121.94023 | H7: 药单耗(g/m3) | J7: =J6*1000/(C3/1000) -> 17.789524 | L7: SS（度/kg） | M7: =J3/I14 -> 4.5282411
B8: 负荷率（%） | C8: =C4/200000*100 -> 96.881048 | D8: 混 凝 剂 | E8: 混凝剂用量（T） | F8: =处理量!K37/1000 -> 237.6 | H8: 氯酸钠（T） | J8: =处理量!N37/1000 -> 36 | K8: 乙酸-厌缺氧段 | L8: 投加量（吨） | M8: =处理量!O37 -> 51.41
B9: 进水水温(℃) | C9: =处理量!B36 -> 30.235484 | E9: 药单耗(g/m3) | F9: =F8*1000/(C3/1000) -> 39.556323 | H9: 药单耗(g/m3) | J9: =J8*1000/(C3/1000) -> 5.9933823 | L9: 药单耗(g/m3) | M9: =M8*1000000/C3 -> 8.5588829
A10: 处 理 质 量 | B10: 项目 | C10: 进水 | E10: 出水 | G10: 去除率（%） | I10: 去除总量（kg) | K10: 乙酸-提标段 | L10: 投加量（吨） | M10: 0
L11: 药单耗(g/m3) | M11: 0
B12: CODcr | C12: =进出水!B38 -> 146 | E12: =进出水!N38 -> 21.8 | G12: =(C12-E12)/C12*100 -> 85.068493 | I12: =$C$3*(C12-E12)/1000 -> 746022.82 | K12: 污 泥 去 向 | L12: 国电 | M12: =处理量!V16 -> 1124.42 | O12: =C12 -> 146 | P12: =ROUND(E12,2) -> 21.8 | Q12: =C3 -> 6006625 | R12: =P12*Q12/1000000 -> 130.94442 | S12: CODcr
B13: BOD5 | C13: =进出水!C38 -> 67 | E13: =进出水!O38 -> 2.41 | G13: =(C13-E13)/C13*100 -> 96.402985 | I13: =$C$3*(C13-E13)/1000 -> 387967.91 | L13: 英科环境 | M13: =处理量!U16 -> 2253.24 | O13: =C13 -> 67 | P13: =ROUND(E13,2) -> 2.41 | Q13: =Q12 -> 6006625 | R13: =P13*Q13/1000000 -> 14.475966 | S13: BOD5
B14: SS | C14: =进出水!D38 -> 63 | E14: =进出水!P38 -> 5.19 | G14: =(C14-E14)/C14*100 -> 91.761905 | I14: =$C$3*(C14-E14)/1000 -> 347242.99 | L14: 其它 | M14: =处理量!W16 -> 45 | O14: =C14 -> 63 | P14: =ROUND(E14,2) -> 5.19 | Q14: =Q13 -> 6006625 | R14: =P14*Q14/1000000 -> 31.174384 | S14: SS
B15: TP | C15: =进出水!E38 -> 2.15 | E15: =进出水!Q38 -> 0.2 | G15: =(C15-E15)/C15*100 -> 90.697674 | I15: =$C$3*(C15-E15)/1000 -> 11712.919 | K15: 运 行 情 况 | L15: 应运行天数 | M15: 31 | O15: =C15 -> 2.15 | P15: =ROUND(E15,2) -> 0.2 | Q15: =Q14 -> 6006625 | R15: =P15*Q15/1000000 -> 1.201325 | S15: TP
B16: TN | C16: =进出水!G38 -> 25.7 | E16: =进出水!S38 -> 7.09 | G16: =(C16-E16)/C16*100 -> 72.412451 | I16: =$C$3*(C16-E16)/1000 -> 111783.29 | L16: 实际运行天数 | M16: 31 | O16: =C16 -> 25.7 | P16: =ROUND(E16,2) -> 7.09 | Q16: =Q15 -> 6006625 | R16: =P16*Q16/1000000 -> 42.586971 | S16: TN
B17: NH3-N | C17: =进出水!F38 -> 19.2 | E17: =进出水!R38 -> 0.31 | G17: =(C17-E17)/C17*100 -> 98.385417 | I17: =$C$3*(C17-E17)/1000 -> 113465.15 | L17: 达标排放天数 | M17: 31 | O17: =C17 -> 19.2 | P17: =ROUND(E17,2) -> 0.31 | Q17: =Q16 -> 6006625 | R17: =P17*Q17/1000000 -> 1.8620538 | S17: NH3-N
B18: 粪大肠菌群数 (个/L) | E18: <20 | L18: 运转率 | M18: 100
A19: 备注 | B19: 本月产生泥饼3422.66吨，其中运往常州市英科环境科技有限公司2253.24吨，国电常州发电有限公司1124.42吨，外运接种45.00吨，常州市百丈污水处理有限公司30.00吨，江苏腾业新材料有限公司15.00吨。 | P19: =F3*(100-F5)/100 -> 732.44924
A21: 审核： 制表： 制表日期：2023/9/4

Sheet 进出水
A1: 常州市深水江边污水处理有限公司进出水水质、污泥含水率月报表
J3: =处理量!A2 -> 45139
A4: 日期 | B4: 进水 | H4: 二沉池出水 | N4: 总出水 | T4: 污泥含水率 | U4: 粪大肠菌群
B5: CODCr | C5: BOD5 | D5: SS | E5: TP | F5: NH3-N | G5: TN | H5: CODCr | I5: BOD5 | J5: SS | K5: TP | L5: NH3-N | M5: TN | N5: CODCr | O5: BOD5 | P5: SS | Q5: TP | R5: NH3-N | S5: TN | Y5: COD(mg/L) | AB5: BOD(mg/L) | AE5: SS(mg/L) | AH5: NH3-N | AK5: TN | AN5: TP
B6: （mg/L） | C6: （mg/L） | D6: （mg/L） | E6: （mg/L） | F6: （mg/L） | G6: （mg/L） | H6: （mg/L） | I6: （mg/L） | J6: （mg/L） | K6: （mg/L） | L6: （mg/L） | M6: （mg/L） | N6: （mg/L） | O6: （mg/L） | P6: （mg/L） | Q6: （mg/L） | R6: （mg/L） | S6: （mg/L） | T6: （%） | U6: (个/L) | Y6: 进水 | Z6: 二沉 | AA6: 出水 | AB6: 进水 | AC6: 二沉 | AD6: 出水 | AE6: 进水 | AF6: 二沉 | AG6: 出水 | AH6: 进水 | AI6: 二沉 | AJ6: 出水 | AK6: 进水 | AL6: 二沉 | AM6: 出水 | AN6: 进水 | AO6: 二沉 | AP6: 出水
A7: 1 | B7: =Y7 -> 140 | C7: 63 | D7: =AE7 -> 54 | E7: =AN7 -> 4.68 | F7: =AH7 -> 20.9 | G7: =AK7 -> 27.2 | H7: =Z7 -> 27 | I7: 2.89 | J7: =AF7 -> 12 | K7: =AO7 -> 0.55 | L7: =AI7 -> 0.4 | M7: =AL7 -> 6.64 | N7: =AA7 -> 22 | O7: 2.41 | P7: =AG7 -> 5 | Q7: =AP7 -> 0.31 | R7: =AJ7 -> 0.38 | S7: =AM7 -> 5.88 | T7: =AQ7 -> 78.8 | U7: =AR7 -> <20 | W7: =1-S7/G7 -> 0.78382353 | Y7: 140 | Z7: 27 | AA7: 22 | AB7: 59.4 | AC7: 2.44 | AD7: 2.26 | AE7: 54 | AF7: 12 | AG7: 5 | AH7: 20.9 | AI7: 0.4 | AJ7: 0.38 | AK7: 27.2 | AL7: 6.64 | AM7: 5.88 | AN7: 4.68 | AO7: 0.55 | AP7: 0.31 | AQ7: 78.8 | AR7: <20
A8: 2 | B8: =Y8 -> 170 | C8: 76.4 | D8: =AE8 -> 70 | E8: =AN8 -> 2.9 | F8: =AH8 -> 22 | G8: =AK8 -> 26.8 | H8: =Z8 -> 31 | I8: 3.02 | J8: =AF8 -> 13 | K8: =AO8 -> 0.54 | L8: =AI8 -> 0.34 | M8: =AL8 -> 7.96 | N8: =AA8 -> 22 | O8: 2.76 | P8: =AG8 -> 5 | Q8: =AP8 -> 0.31 | R8: =AJ8 -> 0.28 | S8: =AM8 -> 7.4 | T8: =AQ8 -> 78.6 | U8: =AR8 -> <20 | W8: =1-S8/G8 -> 0.7238806 | Y8: 170 | Z8: 31 | AA8: 22 | AB8: 57.1 | AC8: 3.24 | AD8: 2.66 | AE8: 70 | AF8: 13 | AG8: 5 | AH8: 22 | AI8: 0.34 | AJ8: 0.28 | AK8: 26.8 | AL8: 7.96 | AM8: 7.4 | AN8: 2.9 | AO8: 0.54 | AP8: 0.31 | AQ8: 78.6 | AR8: <20
A9: 3 | B9: =Y9 -> 130 | C9: 58 | D9: =AE9 -> 54 | E9: =AN9 -> 3.62 | F9: =AH9 -> 21.2 | G9: =AK9 -> 26.5 | H9: =Z9 -> 27 | I9: 2.74 | J9: =AF9 -> 11 | K9: =AO9 -> 0.53 | L9: =AI9 -> 0.4 | M9: =AL9 -> 8.59 | N9: =AA9 -> 20 | O9: 2.18 | P9: =AG9 -> 5 | Q9: =AP9 -> 0.23 | R9: =AJ9 -> 0.38 | S9: =AM9 -> 7.74 | T9: =AQ9 -> 78.3 | U9: =AR9 -> <20 | W9: =1-S9/G9 -> 0.70792453 | Y9: 130 | Z9: 27 | AA9: 20 | AB9: 40.6 | AC9: 2.46 | AD9: 2.11 | AE9: 54 | AF9: 11 | AG9: 5 | AH9: 21.2 | AI9: 0.4 | AJ9: 0.38 | AK9: 26.5 | AL9: 8.59 | AM9: 7.74 | AN9: 3.62 | AO9: 0.53 | AP9: 0.23 | AQ9: 78.3 | AR9: <20
A10: 4 | B10: =Y10 -> 154 | C10: 69.1 | D10: =AE10 -> 62 | E10: =AN10 -> 2.42 | F10: =AH10 -> 20.6 | G10: =AK10 -> 25.7 | H10: =Z10 -> 27 | I10: 2.88 | J10: =AF10 -> 10 | K10: =AO10 -> 0.55 | L10: =AI10 -> 0.27 | M10: =AL10 -> 8.69 | N10: =AA10 -> 19 | O10: 2.23 | P10: =AG10 -> 5 | Q10: =AP10 -> 0.16 | R10: =AJ10 -> 0.2 | S10: =AM10 -> 8.37 | T10: =AQ10 -> 78.9 | U10: =AR10 -> 130 | W10: =1-S10/G10 -> 0.67431907 | Y10: 154 | Z10: 27 | AA10: 19 | AB10: 56 | AC10: 3.08 | AD10: 2.62 | AE10: 62 | AF10: 10 | AG10: 5 | AH10: 20.6 | AI10: 0.27 | AJ10: 0.2 | AK10: 25.7 | AL10: 8.69 | AM10: 8.37 | AN10: 2.42 | AO10: 0.55 | AP10: 0.16 | AQ10: 78.9 | AR10: 130
A11: 5 | B11: =Y11 -> 127 | C11: 57.2 | D11: =AE11 -> 64 | E11: =AN11 -> 1.91 | F11: =AH11 -> 19.9 | G11: =AK11 -> 33.2 | H11: =Z11 -> 25 | I11: 2.67 | J11: =AF11 -> 11 | K11: =AO11 -> 0.52 | L11: =AI11 -> 0.19 | M11: =AL11 -> 8.1 | N11: =AA11 -> 18 | O11: 2.18 | P11: =AG11 -> 5 | Q11: =AP11 -> 0.15 | R11: =AJ11 -> 0.18 | S11: =AM11 -> 7.84 | T11: =AQ11 -> 78.3 | U11: =AR11 -> 20 | W11: =1-S11/G11 -> 0.76385542 | Y11: 127 | Z11: 25 | AA11: 18 | AB11: 63 | AC11: 3.43 | AD11: 2.2 | AE11: 64 | AF11: 11 | AG11: 5 | AH11: 19.9 | AI11: 0.19 | AJ11: 0.18 | AK11: 33.2 | AL11: 8.1 | AM11: 7.84 | AN11: 1.91 | AO11: 0.52 | AP11: 0.15 | AQ11: 78.3 | AR11: 20
A12: 6 | B12: =Y12 -> 136 | C12: 61.2 | D12: =AE12 -> 60 | E12: =AN12 -> 1.95 | F12: =AH12 -> 19.5 | G12: =AK12 -> 36.6 | H12: =Z12 -> 25 | I12: 2.89 | J12: =AF12 -> 12 | K12: =AO12 -> 0.54 | L12: =AI12 -> 0.44 | M12: =AL12 -> 8.66 | N12: =AA12 -> 18 | O12: 2.34 | P12: =AG12 -> 5 | Q12: =AP12 -> 0.17 | R12: =AJ12 -> 0.36 | S12: =AM12 -> 7.44 | T12: =AQ12 -> 78.6 | U12: =AR12 -> 20 | W12: =1-S12/G12 -> 0.79672131 | Y12: 136 | Z12: 25 | AA12: 18 | AB12: 63 | AC12: 2.89 | AD12: 2.41 | AE12: 60 | AF12: 12 | AG12: 5 | AH12: 19.5 | AI12: 0.44 | AJ12: 0.36 | AK12: 36.6 | AL12: 8.66 | AM12: 7.44 | AN12: 1.95 | AO12: 0.54 | AP12: 0.17 | AQ12: 78.6 | AR12: 20
A13: 7 | B13: =Y13 -> 126 | C13: 56.4 | D13: =AE13 -> 56 | E13: =AN13 -> 1.68 | F13: =AH13 -> 23.3 | G13: =AK13 -> 30.6 | H13: =Z13 -> 27 | I13: 2.96 | J13: =AF13 -> 11 | K13: =AO13 -> 0.51 | L13: =AI13 -> 0.25 | M13: =AL13 -> 7.47 | N13: =AA13 -> 20 | O13: 2.43 | P13: =AG13 -> 5 | Q13: =AP13 -> 0.2 | R13: =AJ13 -> 0.2 | S13: =AM13 -> 6.28 | T13: =AQ13 -> 78.3 | U13: =AR13 -> <20 | W13: =1-S13/G13 -> 0.79477124 | Y13: 126 | Z13: 27 | AA13: 20 | AB13: 76.4 | AC13: 3.02 | AD13: 2.76 | AE13: 56 | AF13: 11 | AG13: 5 | AH13: 23.3 | AI13: 0.25 | AJ13: 0.2 | AK13: 30.6 | AL13: 7.47 | AM13: 6.28 | AN13: 1.68 | AO13: 0.51 | AP13: 0.2 | AQ13: 78.3 | AR13: <20
A14: 8 | B14: =Y14 -> 148 | C14: 66.4 | D14: =AE14 -> 78 | E14: =AN14 -> 2.43 | F14: =AH14 -> 20 | G14: =AK14 -> 25.3 | H14: =Z14 -> 25 | I14: 2.86 | J14: =AF14 -> 11 | K14: =AO14 -> 0.51 | L14: =AI14 -> 0.4 | M14: =AL14 -> 7.03 | N14: =AA14 -> 18 | O14: 2.24 | P14: =AG14 -> 5 | Q14: =AP14 -> 0.18 | R14: =AJ14 -> 0.24 | S14: =AM14 -> 6.86 | T14: =AQ14 -> 78.8 | U14: =AR14 -> <20 | W14: =1-S14/G14 -> 0.72885375 | Y14: 148 | Z14: 25 | AA14: 18 | AB14: 58 | AC14: 2.74 | AD14: 2.18 | AE14: 78 | AF14: 11 | AG14: 5 | AH14: 20 | AI14: 0.4 | AJ14: 0.24 | AK14: 25.3 | AL14: 7.03 | AM14: 6.86 | AN14: 2.43 | AO14: 0.51 | AP14: 0.18 | AQ14: 78.8 | AR14: <20
A15: 9 | B15: =Y15 -> 130 | C15: 58.2 | D15: =AE15 -> 50 | E15: =AN15 -> 2.16 | F15: =AH15 -> 22.7 | G15: =AK15 -> 27.6 | H15: =Z15 -> 26 | I15: 2.84 | J15: =AF15 -> 14 | K15: =AO15 -> 0.53 | L15: =AI15 -> 0.35 | M15: =AL15 -> 7.42 | N15: =AA15 -> 18 | O15: 2.22 | P15: =AG15 -> 5 | Q15: =AP15 -> 0.23 | R15: =AJ15 -> 0.28 | S15: =AM15 -> 7.1 | T15: =AQ15 -> 78.7 | U15: =AR15 -> <20 | W15: =1-S15/G15 -> 0.74275362 | Y15: 130 | Z15: 26 | AA15: 18 | AB15: 69.1 | AC15: 2.88 | AD15: 2.23 | AE15: 50 | AF15: 14 | AG15: 5 | AH15: 22.7 | AI15: 0.35 | AJ15: 0.28 | AK15: 27.6 | AL15: 7.42 | AM15: 7.1 | AN15: 2.16 | AO15: 0.53 | AP15: 0.23 | AQ15: 78.7 | AR15: <20
A16: 10 | B16: =Y16 -> 136 | C16: 61 | D16: =AE16 -> 70 | E16: =AN16 -> 3.43 | F16: =AH16 -> 16.2 | G16: =AK16 -> 22.3 | H16: =Z16 -> 37 | I16: 3.26 | J16: =AF16 -> 14 | K16: =AO16 -> 0.53 | L16: =AI16 -> 0.41 | M16: =AL16 -> 7.76 | N16: =AA16 -> 23 | O16: 2.64 | P16: =AG16 -> 5 | Q16: =AP16 -> 0.21 | R16: =AJ16 -> 0.4 | S16: =AM16 -> 6.82 | T16: =AQ16 -> 78.8 | U16: =AR16 -> 40 | W16: =1-S16/G16 -> 0.6941704 | Y16: 136 | Z16: 37 | AA16: 23 | AB16: 57.2 | AC16: 2.67 | AD16: 2.18 | AE16: 70 | AF16: 14 | AG16: 5 | AH16: 16.2 | AI16: 0.41 | AJ16: 0.4 | AK16: 22.3 | AL16: 7.76 | AM16: 6.82 | AN16: 3.43 | AO16: 0.53 | AP16: 0.21 | AQ16: 78.8 | AR16: 40
A17: 11 | B17: =Y17 -> 146 | C17: 65.4 | D17: =AE17 -> 64 | E17: =AN17 -> 1.6 | F17: =AH17 -> 16.1 | G17: =AK17 -> 22 | H17: =Z17 -> 29 | I17: 2.98 | J17: =AF17 -> 12 | K17: =AO17 -> 0.52 | L17: =AI17 -> 0.31 | M17: =AL17 -> 6.82 | N17: =AA17 -> 22 | O17: 2.4 | P17: =AG17 -> 5 | Q17: =AP17 -> 0.2 | R17: =AJ17 -> 0.29 | S17: =AM17 -> 6.15 | T17: =AQ17 -> 78.9 | U17: =AR17 -> 300 | W17: =1-S17/G17 -> 0.72045455 | Y17: 146 | Z17: 29 | AA17: 22 | AB17: 61.2 | AC17: 2.89 | AD17: 2.34 | AE17: 64 | AF17: 12 | AG17: 5 | AH17: 16.1 | AI17: 0.31 | AJ17: 0.29 | AK17: 22 | AL17: 6.82 | AM17: 6.15 | AN17: 1.6 | AO17: 0.52 | AP17: 0.2 | AQ17: 78.9 | AR17: 300
A18: 12 | B18: =Y18 -> 169 | C18: 75.8 | D18: =AE18 -> 90 | E18: =AN18 -> 1.67 | F18: =AH18 -> 20 | G18: =AK18 -> 26.4 | H18: =Z18 -> 32 | I18: 3.2 | J18: =AF18 -> 16 | K18: =AO18 -> 0.5 | L18: =AI18 -> 0.32 | M18: =AL18 -> 7.4 | N18: =AA18 -> 23 | O18: 2.34 | P18: =AG18 -> 6 | Q18: =AP18 -> 0.27 | R18: =AJ18 -> 0.27 | S18: =AM18 -> 7.16 | T18: =AQ18 -> 78.7 | U18: =AR18 -> 130 | W18: =1-S18/G18 -> 0.72878788 | Y18: 169 | Z18: 32 | AA18: 23 | AB18: 56.4 | AC18: 2.96 | AD18: 2.43 | AE18: 90 | AF18: 16 | AG18: 6 | AH18: 20 | AI18: 0.32 | AJ18: 0.27 | AK18: 26.4 | AL18: 7.4 | AM18: 7.16 | AN18: 1.67 | AO18: 0.5 | AP18: 0.27 | AQ18: 78.7 | AR18: 130
A19: 13 | B19: =Y19 -> 172 | C19: 77.2 | D19: =AE19 -> 56 | E19: =AN19 -> 3.01 | F19: =AH19 -> 18 | G19: =AK19 -> 24.2 | H19: =Z19 -> 35 | I19: 3.36 | J19: =AF19 -> 18 | K19: =AO19 -> 0.54 | L19: =AI19 -> 0.4 | M19: =AL19 -> 8.02 | N19: =AA19 -> 24 | O19: 2.54 | P19: =AG19 -> 5 | Q19: =AP19 -> 0.26 | R19: =AJ19 -> 0.25 | S19: =AM19 -> 7.03 | T19: =AQ19 -> 78.6 | U19: =AR19 -> 90 | W19: =1-S19/G19 -> 0.70950413 | Y19: 172 | Z19: 35 | AA19: 24 | AB19: 66.4 | AC19: 2.86 | AD19: 2.24 | AE19: 56 | AF19: 18 | AG19: 5 | AH19: 18 | AI19: 0.4 | AJ19: 0.25 | AK19: 24.2 | AL19: 8.02 | AM19: 7.03 | AN19: 3.01 | AO19: 0.54 | AP19: 0.26 | AQ19: 78.6 | AR19: 90
A20: 14 | B20: =Y20 -> 166 | C20: 74.3 | D20: =AE20 -> 72 | E20: =AN20 -> 1.99 | F20: =AH20 -> 17.7 | G20: =AK20 -> 25.1 | H20: =Z20 -> 35 | I20: 3.61 | J20: =AF20 -> 17 | K20: =AO20 -> 0.55 | L20: =AI20 -> 0.46 | M20: =AL20 -> 7.94 | N20: =AA20 -> 29 | O20: 2.82 | P20: =AG20 -> 5 | Q20: =AP20 -> 0.24 | R20: =AJ20 -> 0.41 | S20: =AM20 -> 7.03 | T20: =AQ20 -> 78.5 | U20: =AR20 -> <20 | W20: =1-S20/G20 -> 0.71992032 | Y20: 166 | Z20: 35 | AA20: 29 | AB20: 58.2 | AC20: 2.84 | AD20: 2.22 | AE20: 72 | AF20: 17 | AG20: 5 | AH20: 17.7 | AI20: 0.46 | AJ20: 0.41 | AK20: 25.1 | AL20: 7.94 | AM20: 7.03 | AN20: 1.99 | AO20: 0.55 | AP20: 0.24 | AQ20: 78.5 | AR20: <20
A21: 15 | B21: =Y21 -> 156 | C21: 70.2 | D21: =AE21 -> 78 | E21: =AN21 -> 1.42 | F21: =AH21 -> 19.3 | G21: =AK21 -> 25.6 | H21: =Z21 -> 44 | I21: 4.1 | J21: =AF21 -> 18 | K21: =AO21 -> 0.52 | L21: =AI21 -> 1.38 | M21: =AL21 -> 7.84 | N21: =AA21 -> 32 | O21: 3.06 | P21: =AG21 -> 6 | Q21: =AP21 -> 0.19 | R21: =AJ21 -> 0.67 | S21: =AM21 -> 7.84 | T21: =AQ21 -> 78.8 | U21: =AR21 -> 20 | W21: =1-S21/G21 -> 0.69375 | Y21: 156 | Z21: 44 | AA21: 32 | AB21: 61 | AC21: 3.26 | AD21: 2.64 | AE21: 78 | AF21: 18 | AG21: 6 | AH21: 19.3 | AI21: 1.38 | AJ21: 0.67 | AK21: 25.6 | AL21: 7.84 | AM21: 7.84 | AN21: 1.42 | AO21: 0.52 | AP21: 0.19 | AQ21: 78.8 | AR21: 20
A22: 16 | B22: =Y22 -> 173 | C22: 77.4 | D22: =AE22 -> 94 | E22: =AN22 -> 2.02 | F22: =AH22 -> 21.2 | G22: =AK22 -> 26.7 | H22: =Z22 -> 35 | I22: 3.12 | J22: =AF22 -> 16 | K22: =AO22 -> 0.51 | L22: =AI22 -> 0.44 | M22: =AL22 -> 7.8 | N22: =AA22 -> 25 | O22: 2.6 | P22: =AG22 -> 5 | Q22: =AP22 -> 0.16 | R22: =AJ22 -> 0.42 | S22: =AM22 -> 6.89 | T22: =AQ22 -> 78.6 | U22: =AR22 -> 20 | W22: =1-S22/G22 -> 0.74194757 | Y22: 173 | Z22: 35 | AA22: 25 | AB22: 65.4 | AC22: 2.98 | AD22: 2.4 | AE22: 94 | AF22: 16 | AG22: 5 | AH22: 21.2 | AI22: 0.44 | AJ22: 0.42 | AK22: 26.7 | AL22: 7.8 | AM22: 6.89 | AN22: 2.02 | AO22: 0.51 | AP22: 0.16 | AQ22: 78.6 | AR22: 20
A23: 17 | B23: =Y23 -> 186 | C23: 83.5 | D23: =AE23 -> 68 | E23: =AN23 -> 1.99 | F23: =AH23 -> 20.5 | G23: =AK23 -> 25.8 | H23: =Z23 -> 37 | I23: 3.32 | J23: =AF23 -> 17 | K23: =AO23 -> 0.55 | L23: =AI23 -> 0.61 | M23: =AL23 -> 8.47 | N23: =AA23 -> 25 | O23: 2.5 | P23: =AG23 -> 6 | Q23: =AP23 -> 0.15 | R23: =AJ23 -> 0.59 | S23: =AM23 -> 7.61 | T23: =AQ23 -> 78.2 | U23: =AR23 -> <20 | W23: =1-S23/G23 -> 0.70503876 | Y23: 186 | Z23: 37 | AA23: 25 | AB23: 75.8 | AC23: 3.2 | AD23: 2.34 | AE23: 68 | AF23: 17 | AG23: 6 | AH23: 20.5 | AI23: 0.61 | AJ23: 0.59 | AK23: 25.8 | AL23: 8.47 | AM23: 7.61 | AN23: 1.99 | AO23: 0.55 | AP23: 0.15 | AQ23: 78.2 | AR23: <20
A24: 18 | B24: =Y24 -> 128 | C24: 57.6 | D24: =AE24 -> 46 | E24: =AN24 -> 1.48 | F24: =AH24 -> 15.7 | G24: =AK24 -> 21.6 | H24: =Z24 -> 33 | I24: 3.2 | J24: =AF24 -> 13 | K24: =AO24 -> 0.55 | L24: =AI24 -> 0.32 | M24: =AL24 -> 7.32 | N24: =AA24 -> 23 | O24: 2.24 | P24: =AG24 -> 5 | Q24: =AP24 -> 0.13 | R24: =AJ24 -> 0.22 | S24: =AM24 -> 7.2 | T24: =AQ24 -> 78.6 | U24: =AR24 -> 50 | W24: =1-S24/G24 -> 0.66666667 | Y24: 128 | Z24: 33 | AA24: 23 | AB24: 77.2 | AC24: 3.36 | AD24: 2.54 | AE24: 46 | AF24: 13 | AG24: 5 | AH24: 15.7 | AI24: 0.32 | AJ24: 0.22 | AK24: 21.6 | AL24: 7.32 | AM24: 7.2 | AN24: 1.48 | AO24: 0.55 | AP24: 0.13 | AQ24: 78.6 | AR24: 50
A25: 19 | B25: =Y25 -> 212 | C25: 85.5 | D25: =AE25 -> 66 | E25: =AN25 -> 1.74 | F25: =AH25 -> 17 | G25: =AK25 -> 22.7 | H25: =Z25 -> 29 | I25: 2.98 | J25: =AF25 -> 14 | K25: =AO25 -> 0.52 | L25: =AI25 -> 0.26 | M25: =AL25 -> 7.32 | N25: =AA25 -> 22 | O25: 2.25 | P25: =AG25 -> 5 | Q25: =AP25 -> 0.15 | R25: =AJ25 -> 0.21 | S25: =AM25 -> 7.15 | T25: =AQ25 -> 78.4 | U25: =AR25 -> 60 | W25: =1-S25/G25 -> 0.68502203 | Y25: 212 | Z25: 29 | AA25: 22 | AB25: 74.3 | AC25: 3.61 | AD25: 2.82 | AE25: 66 | AF25: 14 | AG25: 5 | AH25: 17 | AI25: 0.26 | AJ25: 0.21 | AK25: 22.7 | AL25: 7.32 | AM25: 7.15 | AN25: 1.74 | AO25: 0.52 | AP25: 0.15 | AQ25: 78.4 | AR25: 60
A26: 20 | B26: =Y26 -> 134 | C26: 60.4 | D26: =AE26 -> 44 | E26: =AN26 -> 1.88 | F26: =AH26 -> 17 | G26: =AK26 -> 23.4 | H26: =Z26 -> 30 | I26: 3.04 | J26: =AF26 -> 14 | K26: =AO26 -> 0.54 | L26: =AI26 -> 0.4 | M26: =AL26 -> 7.28 | N26: =AA26 -> 21 | O26: 2.18 | P26: =AG26 -> 5 | Q26: =AP26 -> 0.15 | R26: =AJ26 -> 0.28 | S26: =AM26 -> 6.68 | T26: =AQ26 -> 78.8 | U26: =AR26 -> 40 | W26: =1-S26/G26 -> 0.71452991 | Y26: 134 | Z26: 30 | AA26: 21 | AB26: 70.2 | AC26: 4.1 | AD26: 3.06 | AE26: 44 | AF26: 14 | AG26: 5 | AH26: 17 | AI26: 0.4 | AJ26: 0.28 | AK26: 23.4 | AL26: 7.28 | AM26: 6.68 | AN26: 1.88 | AO26: 0.54 | AP26: 0.15 | AQ26: 78.8 | AR26: 40
A27: 21 | B27: =Y27 -> 210 | C27: 94.5 | D27: =AE27 -> 72 | E27: =AN27 -> 1.74 | F27: =AH27 -> 17.7 | G27: =AK27 -> 23.8 | H27: =Z27 -> 28 | I27: 2.89 | J27: =AF27 -> 17 | K27: =AO27 -> 0.51 | L27: =AI27 -> 0.32 | M27: =AL27 -> 7.15 | N27: =AA27 -> 24 | O27: 2.36 | P27: =AG27 -> 6 | Q27: =AP27 -> 0.15 | R27: =AJ27 -> 0.29 | S27: =AM27 -> 6.54 | T27: =AQ27 -> 78.7 | U27: =AR27 -> <20 | W27: =1-S27/G27 -> 0.72521008 | Y27: 210 | Z27: 28 | AA27: 24 | AB27: 77.4 | AC27: 3.12 | AD27: 2.6 | AE27: 72 | AF27: 17 | AG27: 6 | AH27: 17.7 | AI27: 0.32 | AJ27: 0.29 | AK27: 23.8 | AL27: 7.15 | AM27: 6.54 | AN27: 1.74 | AO27: 0.51 | AP27: 0.15 | AQ27: 78.7 | AR27: <20
A28: 22 | B28: =Y28 -> 121 | C28: 66.3 | D28: =AE28 -> 66 | E28: =AN28 -> 1.94 | F28: =AH28 -> 18.9 | G28: =AK28 -> 24.7 | H28: =Z28 -> 25 | I28: 3.36 | J28: =AF28 -> 12 | K28: =AO28 -> 0.54 | L28: =AI28 -> 0.45 | M28: =AL28 -> 7.3 | N28: =AA28 -> 19 | O28: 2.54 | P28: =AG28 -> 5 | Q28: =AP28 -> 0.2 | R28: =AJ28 -> 0.32 | S28: =AM28 -> 7.02 | T28: =AQ28 -> 78.5 | U28: =AR28 -> <20 | W28: =1-S28/G28 -> 0.71578947 | Y28: 121 | Z28: 25 | AA28: 19 | AB28: 83.5 | AC28: 3.32 | AD28: 2.5 | AE28: 66 | AF28: 12 | AG28: 5 | AH28: 18.9 | AI28: 0.45 | AJ28: 0.32 | AK28: 24.7 | AL28: 7.3 | AM28: 7.02 | AN28: 1.94 | AO28: 0.54 | AP28: 0.2 | AQ28: 78.5 | AR28: <20
A29: 23 | B29: =Y29 -> 130 | C29: 71.2 | D29: =AE29 -> 70 | E29: =AN29 -> 2.04 | F29: =AH29 -> 23.1 | G29: =AK29 -> 28.8 | H29: =Z29 -> 29 | I29: 3.28 | J29: =AF29 -> 12 | K29: =AO29 -> 0.52 | L29: =AI29 -> 0.37 | M29: =AL29 -> 7.93 | N29: =AA29 -> 22 | O29: 2.34 | P29: =AG29 -> 5 | Q29: =AP29 -> 0.23 | R29: =AJ29 -> 0.18 | S29: =AM29 -> 7.48 | T29: =AQ29 -> 78.6 | U29: =AR29 -> <20 | W29: =1-S29/G29 -> 0.74027778 | Y29: 130 | Z29: 29 | AA29: 22 | AB29: 57.6 | AC29: 3.2 | AD29: 2.24 | AE29: 70 | AF29: 12 | AG29: 5 | AH29: 23.1 | AI29: 0.37 | AJ29: 0.18 | AK29: 28.8 | AL29: 7.93 | AM29: 7.48 | AN29: 2.04 | AO29: 0.52 | AP29: 0.23 | AQ29: 78.6 | AR29: <20
A30: 24 | B30: =Y30 -> 121 | C30: 66.2 | D30: =AE30 -> 50 | E30: =AN30 -> 1.64 | F30: =AH30 -> 18.5 | G30: =AK30 -> 24.3 | H30: =Z30 -> 24 | I30: 2.97 | J30: =AF30 -> 11 | K30: =AO30 -> 0.5 | L30: =AI30 -> 0.44 | M30: =AL30 -> 7.15 | N30: =AA30 -> 19 | O30: 2.28 | P30: =AG30 -> 5 | Q30: =AP30 -> 0.16 | R30: =AJ30 -> 0.33 | S30: =AM30 -> 6.65 | T30: =AQ30 -> 78.9 | U30: =AR30 -> 40 | W30: =1-S30/G30 -> 0.72633745 | Y30: 121 | Z30: 24 | AA30: 19 | AB30: 95.5 | AC30: 2.98 | AD30: 2.25 | AE30: 50 | AF30: 11 | AG30: 5 | AH30: 18.5 | AI30: 0.44 | AJ30: 0.33 | AK30: 24.3 | AL30: 7.15 | AM30: 6.65 | AN30: 1.64 | AO30: 0.5 | AP30: 0.16 | AQ30: 78.9 | AR30: 40
A31: 25 | B31: =Y31 -> 148 | C31: 81.2 | D31: =AE31 -> 64 | E31: =AN31 -> 2.25 | F31: =AH31 -> 19.8 | G31: =AK31 -> 24.4 | H31: =Z31 -> 34 | I31: 4.06 | J31: =AF31 -> 15 | K31: =AO31 -> 0.53 | L31: =AI31 -> 0.64 | M31: =AL31 -> 7.41 | N31: =AA31 -> 19 | O31: 2.28 | P31: =AG31 -> 6 | Q31: =AP31 -> 0.17 | R31: =AJ31 -> 0.22 | S31: =AM31 -> 7.18 | T31: =AQ31 -> 78.7 | U31: =AR31 -> 20 | W31: =1-S31/G31 -> 0.7057377 | Y31: 148 | Z31: 34 | AA31: 19 | AB31: 60.4 | AC31: 3.04 | AD31: 2.18 | AE31: 64 | AF31: 15 | AG31: 6 | AH31: 19.8 | AI31: 0.64 | AJ31: 0.22 | AK31: 24.4 | AL31: 7.41 | AM31: 7.18 | AN31: 2.25 | AO31: 0.53 | AP31: 0.17 | AQ31: 78.7 | AR31: 20
A32: 26 | B32: =Y32 -> 118 | C32: 64.4 | D32: =AE32 -> 48 | E32: =AN32 -> 1.85 | F32: =AH32 -> 15 | G32: =AK32 -> 21.2 | H32: =Z32 -> 30 | I32: 3.28 | J32: =AF32 -> 12 | K32: =AO32 -> 0.51 | L32: =AI32 -> 0.22 | M32: =AL32 -> 7.56 | N32: =AA32 -> 21 | O32: 2.6 | P32: =AG32 -> 6 | Q32: =AP32 -> 0.22 | R32: =AJ32 -> 0.22 | S32: =AM32 -> 7.44 | T32: =AQ32 -> 78.5 | U32: =AR32 -> 50 | W32: =1-S32/G32 -> 0.6490566 | Y32: 118 | Z32: 30 | AA32: 21 | AB32: 94.5 | AC32: 2.89 | AD32: 2.36 | AE32: 48 | AF32: 12 | AG32: 6 | AH32: 15 | AI32: 0.22 | AJ32: 0.22 | AK32: 21.2 | AL32: 7.56 | AM32: 7.44 | AN32: 1.85 | AO32: 0.51 | AP32: 0.22 | AQ32: 78.5 | AR32: 50
A33: 27 | B33: =Y33 -> 124 | C33: 58 | D33: =AE33 -> 54 | E33: =AN33 -> 2.09 | F33: =AH33 -> 20.5 | G33: =AK33 -> 26.8 | H33: =Z33 -> 29 | I33: 3.02 | J33: =AF33 -> 13 | K33: =AO33 -> 0.52 | L33: =AI33 -> 0.32 | M33: =AL33 -> 7.72 | N33: =AA33 -> 23 | O33: 2.36 | P33: =AG33 -> 5 | Q33: =AP33 -> 0.22 | R33: =AJ33 -> 0.23 | S33: =AM33 -> 6.7 | T33: =AQ33 -> 78.3 | U33: =AR33 -> 20 | W33: =1-S33/G33 -> 0.75 | Y33: 124 | Z33: 29 | AA33: 23 | AB33: 66.3 | AC33: 3.36 | AD33: 2.54 | AE33: 54 | AF33: 13 | AG33: 5 | AH33: 20.5 | AI33: 0.32 | AJ33: 0.23 | AK33: 26.8 | AL33: 7.72 | AM33: 6.7 | AN33: 2.09 | AO33: 0.52 | AP33: 0.22 | AQ33: 78.3 | AR33: 20
A34: 28 | B34: =Y34 -> 115 | C34: 51.8 | D34: =AE34 -> 64 | E34: =AN34 -> 2.15 | F34: =AH34 -> 23.1 | G34: =AK34 -> 29.3 | H34: =Z34 -> 35 | I34: 3.52 | J34: =AF34 -> 16 | K34: =AO34 -> 0.53 | L34: =AI34 -> 0.41 | M34: =AL34 -> 6.78 | N34: =AA34 -> 24 | O34: 2.52 | P34: =AG34 -> 5 | Q34: =AP34 -> 0.19 | R34: =AJ34 -> 0.34 | S34: =AM34 -> 6.66 | T34: =AQ34 -> 78.6 | U34: =AR34 -> <20 | W34: =1-S34/G34 -> 0.77269625 | Y34: 115 | Z34: 35 | AA34: 24 | AB34: 71.2 | AC34: 3.28 | AD34: 2.34 | AE34: 64 | AF34: 16 | AG34: 5 | AH34: 23.1 | AI34: 0.41 | AJ34: 0.34 | AK34: 29.3 | AL34: 6.78 | AM34: 6.66 | AN34: 2.15 | AO34: 0.53 | AP34: 0.19 | AQ34: 78.6 | AR34: <20
A35: 29 | B35: =Y35 -> 145 | C35: 64.6 | D35: =AE35 -> 60 | E35: =AN35 -> 2.13 | F35: =AH35 -> 17.6 | G35: =AK35 -> 23.1 | H35: =Z35 -> 36 | I35: 2.97 | J35: =AF35 -> 12 | K35: =AO35 -> 0.51 | L35: =AI35 -> 0.31 | M35: =AL35 -> 8.91 | N35: =AA35 -> 22 | O35: 2.31 | P35: =AG35 -> 5 | Q35: =AP35 -> 0.18 | R35: =AJ35 -> 0.2 | S35: =AM35 -> 7.8 | T35: =AQ35 -> 78.4 | U35: =AR35 -> <20 | W35: =1-S35/G35 -> 0.66233766 | Y35: 145 | Z35: 36 | AA35: 22 | AB35: 66.2 | AC35: 2.97 | AD35: 2.28 | AE35: 60 | AF35: 12 | AG35: 5 | AH35: 17.6 | AI35: 0.31 | AJ35: 0.2 | AK35: 23.1 | AL35: 8.91 | AM35: 7.8 | AN35: 2.13 | AO35: 0.51 | AP35: 0.18 | AQ35: 78.4 | AR35: <20
A36: 30 | B36: =Y36 -> 111 | C36: 50.4 | D36: =AE36 -> 54 | E36: =AN36 -> 1.5 | F36: =AH36 -> 18.7 | G36: =AK36 -> 25.3 | H36: =Z36 -> 25 | I36: 2.79 | J36: =AF36 -> 11 | K36: =AO36 -> 0.52 | L36: =AI36 -> 0.48 | M36: =AL36 -> 7.04 | N36: =AA36 -> 21 | O36: 2.28 | P36: =AG36 -> 5 | Q36: =AP36 -> 0.19 | R36: =AJ36 -> 0.39 | S36: =AM36 -> 6.8 | T36: =AQ36 -> 78.7 | U36: =AR36 -> <20 | W36: =1-S36/G36 -> 0.7312253 | Y36: 111 | Z36: 25 | AA36: 21 | AB36: 81.2 | AC36: 4.06 | AD36: 2.28 | AE36: 54 | AF36: 11 | AG36: 5 | AH36: 18.7 | AI36: 0.48 | AJ36: 0.39 | AK36: 25.3 | AL36: 7.04 | AM36: 6.8 | AN36: 1.5 | AO36: 0.52 | AP36: 0.19 | AQ36: 78.7 | AR36: <20
A37: 31 | B37: =Y37 -> 152 | C37: 67.6 | D37: =AE37 -> 44 | E37: =AN37 -> 1.34 | F37: =AH37 -> 13.8 | G37: =AK37 -> 19.7 | H37: =Z37 -> 30 | I37: 3.19 | J37: =AF37 -> 13 | K37: =AO37 -> 0.53 | L37: =AI37 -> 0.28 | M37: =AL37 -> 8.03 | N37: =AA37 -> 19 | O37: 2.33 | P37: =AG37 -> 5 | Q37: =AP37 -> 0.12 | R37: =AJ37 -> 0.27 | S37: =AM37 -> 7.12 | T37: =AQ37 -> 78.6 | U37: =AR37 -> 20 | W37: =1-S37/G37 -> 0.63857868 | Y37: 152 | Z37: 30 | AA37: 19 | AB37: 64.4 | AC37: 3.28 | AD37: 2.6 | AE37: 44 | AF37: 13 | AG37: 5 | AH37: 13.8 | AI37: 0.28 | AJ37: 0.27 | AK37: 19.7 | AL37: 8.03 | AM37: 7.12 | AN37: 1.34 | AO37: 0.53 | AP37: 0.12 | AQ37: 78.6 | AR37: 20
A38: 平均 | B38: =ROUND(AVERAGE(B7:B37),0) -> 146 | C38: =ROUND(AVERAGE(C7:C37),0) -> 67 | D38: =ROUND(AVERAGE(D7:D37),0) -> 63 | E38: =ROUND(AVERAGE(E7:E37),2) -> 2.15 | F38: =ROUND(AVERAGE(F7:F37),1) -> 19.2 | G38: =ROUND(AVERAGE(G7:G37),1) -> 25.7 | H38: =ROUND(AVERAGE(H7:H37),1) -> 30.4 | I38: =ROUND(AVERAGE(I7:I37),2) -> 3.14 | J38: =ROUND(AVERAGE(J7:J37),2) -> 13.48 | K38: =ROUND(AVERAGE(K7:K37),2) -> 0.53 | L38: =ROUND(AVERAGE(L7:L37),2) -> 0.41 | M38: =ROUND(AVERAGE(M7:M37),1) -> 7.7 | N38: =ROUND(AVERAGE(N7:N37),1) -> 21.8 | O38: =ROUND(AVERAGE(O7:O37),2) -> 2.41 | P38: =ROUND(AVERAGE(P7:P37),2) -> 5.19 | Q38: =ROUND(AVERAGE(Q7:Q37),2) -> 0.2 | R38: =ROUND(AVERAGE(R7:R37),2) -> 0.31 | S38: =ROUND(AVERAGE(S7:S37),2) -> 7.09 | T38: =ROUND(AVERAGE(T7:T37),2) -> 78.6 | U38: <20
A39: 审核： | J39: 制表： | Q39: 制表时间：2023/9/4
B41: 项目 | C41: 进水（mg/L) | D41: 最大值 | E41: 最小值（mg/L) | F41: 出水（mg/L) | G41: 最大值 | H41: 最小值（mg/L) | I41: 去除率
D42: （mg/L) | G42: （mg/L) | I42: （%）
...

Sheet 设备
A1: 常州市深水江边污水处理有限公司设备运行月报表
A2: 45139
A3: 运行 工段 | B3: 设备名称 | C3: 编号 | D3: 运行 天数 | E3: 定时 | F3: 额定运行时间 | G3: 实际运行时间 | H3: 利用率 | I3: 完好率 | J3: 维修、保养情况
D5: （d） | E5: （h/d） | F5: （h） | G5: （h） | H5: % | I5: %
A6: 预 处 理 | B6: 粗格栅机 | C6: 1# | D6: 31 | E6: 2 | F6: 62 | G6: 62 | H6: 1 | I6: 1 | J6: 25日保养
C7: 2# | D7: 31 | E7: 2 | F7: 62 | G7: 62 | H7: 1 | I7: 1 | J7: 25日保养
B8: 螺旋输送机 | C8: / | D8: 31 | E8: 2 | F8: 62 | G8: 62 | H8: 1 | I8: 1 | J8: 25日保养
B9: 螺旋压榨机 | C9: / | D9: 31 | E9: 2 | F9: 62 | G9: 62 | H9: 1 | I9: 1 | J9: 25日保养
B10: 进水泵 | C10: 1# | D10: 31 | E10: 24 | F10: 744 | G10: 628 | H10: 0.84408602 | I10: 1
C11: 2# | D11: 31 | E11: 24 | F11: 744 | G11: 50 | H11: 0.067204301 | I11: 1
C12: 3# | D12: 31 | E12: 24 | F12: 744 | G12: 718 | H12: 0.99 | I12: 1
C13: 4# | D13: 31 | E13: 24 | F13: 744 | G13: 162 | H13: 0.8 | I13: 1
C14: 5# | D14: 31 | E14: 24 | F14: 744 | G14: 744 | H14: 1 | I14: 1
B15: 细格栅机 | C15: 1# | D15: 31 | E15: 2.4 | F15: 74.4 | G15: 74.4 | H15: 1 | I15: 1
C16: 2# | D16: 31 | E16: 2.4 | F16: 74.4 | G16: 74.4 | H16: 1 | I16: 1
C17: 3# | D17: 31 | E17: 2.4 | F17: 74.4 | G17: 74.4 | H17: 1 | I17: 1
C18: 4# | D18: 31 | E18: 2.4 | F18: 74.4 | G18: 74.4 | H18: 1 | I18: 1
C19: 5# | D19: 31 | E19: 2.4 | F19: 74.4 | G19: 74.4 | H19: 1 | I19: 1 | J19: 29日链条更换调整
C20: 6# | D20: 31 | E20: 2.4 | F20: 74.4 | G20: 74.4 | H20: 1 | I20: 1
B21: 螺旋输送机 | C21: 1# | D21: 31 | E21: 2 | F21: 62 | G21: 62 | H21: 1 | I21: 1
C22: 2# | D22: 31 | E22: 2 | F22: 62 | G22: 62 | H22: 1 | I22: 1
B23: 螺旋压榨机 | C23: 1# | D23: 31 | E23: 2 | F23: 62 | G23: 62 | H23: 1 | I23: 1
C24: 2# | D24: 31 | E24: 2 | F24: 62 | G24: 0 | H24: 0 | I24: 1
B25: 搅拌机 | C25: 1# | D25: 31 | E25: 24 | F25: 744 | G25: 0 | H25: 0 | I25: 0
B26: 砂水分离机 | C26: 1# | D26: 31 | E26: 0.5 | F26: 15.5 | G26: 15.5 | H26: 1 | I26: 1
B27: 搅拌机 | C27: 2# | D27: 31 | E27: 24 | F27: 744 | G27: 0 | H27: 0 | I27: 0
B28: 砂水分离机 | C28: 2# | D28: 31 | E28: 0.5 | F28: 15.5 | G28: 15.5 | H28: 1 | I28: 1
B29: 搅拌机 | C29: 3# | D29: 31 | E29: 24 | F29: 744 | G29: 744 | H29: 1 | I29: 1
B30: 砂水分离机 | C30: 3# | D30: 31 | E30: 0.5 | F30: 15.5 | G30: 15.5 | H30: 1 | I30: 1
B31: 搅拌机 | C31: 4# | D31: 31 | E31: 24 | F31: 744 | G31: 0 | H31: 0 | I31: 0
B32: 砂水分离机 | C32: 4# | D32: 31 | E32: 0.5 | F32: 15.5 | G32: 15.5 | H32: 1 | I32: 1
B33: 高压鼓风机 | C33: 1# | D33: 31 | E33: 24 | F33: 744 | G33: 744 | H33: 1 | I33: 1
C34: 2# | D34: 31 | E34: 24 | F34: 744 | G34: 362 | H34: 0.48655914 | I34: 1
C35: 3# | D35: 31 | E35: 24 | F35: 744 | G35: 384 | H35: 0.51612903 | I35: 1
C36: 4# | D36: 31 | E36: 24 | F36: 744 | G36: 0 | H36: 0 | I36: 1
C37: 5# | D37: 31 | E37: 24 | F37: 744 | G37: 0 | H37: 0 | I37: 1
A38: 审核： | E38: 制表： | H38: 制表时间：2023/9/5
A46: 常州市深水江边污水处理有限公司设备运行月报表
A47: =A2 -> 45139
A48: 运行 工段 | B48: 设备名称 | C48: 编号 | D48: 运行 天数 | E48: 定时 | F48: 额定运行时间 | G48: 实际运行时间 | H48: 利用率 | I48: 完好率 | J48: 维修、保养情况
...

Sheet 仪表
A1: 常州市深水江边污水处理有限公司污水运行月报表
D2: =处理量!A2 -> 45139
A3: 仪表名称 | B3: 编号 | C3: 规格型号 | D3: 安装位置 | E3: 运行情况 | F3: 标定、校准情况 | G3: 备注
A4: 一期溶氧仪 | B4: 1#（南） | C4: 美商生化T-10 | D4: 一期生反池 | E4: 正常 | F4: 校准 | G4: 2023-08-04 2023-08-11 2023-08-18 2023-08-25
B5: 2#（南） | C5: 美商生化T-10 | D5: 一期生反池 | E5: 正常 | F5: 校准 | G5: =G4 -> 2023-08-04 2023-08-11 2023-08-18 2023-08-25
B6: 1#（北） | C6: 美商生化T-10 | D6: 一期生反池 | E6: 正常 | F6: 校准 | G6: =G5 -> 2023-08-04 2023-08-11 2023-08-18 2023-08-25
B7: 2#（北） | C7: 美商生化T-10 | D7: 一期生反池 | E7: 正常 | F7: 校准 | G7: =G6 -> 2023-08-04 2023-08-11 2023-08-18 2023-08-25
A8: 一期污泥浓度计 | B8: 1#（南） | C8: E+H | D8: 一期生反池 | E8: 正常 | F8: 校准 | G8: =G7 -> 2023-08-04 2023-08-11 2023-08-18 2023-08-25
B9: 2#（南） | C9: E+H | D9: 一期生反池 | E9: 正常 | F9: 校准 | G9: =G8 -> 2023-08-04 2023-08-11 2023-08-18 2023-08-25
