Workbook

Sheet 处理量
A1: 常州市深水江边污水处理有限公司污水处理运行月报表
A2: 2023年 2月
A3: 日 期 | B3: 水温 | C3: 天气 | D3: 日处理 水量 （m3） | E3: 污泥量（T） | H3: 药剂量 | I3: MLSS | J3: 电耗 | K3: 混凝剂 | L3: 絮凝剂 阴离子 （kg） | M3: 盐酸 | N3: 氯酸钠 | O3: 乙酸（吨） | Q3: 回用水 （m3） | R3: 实际水量（m3） | T3: 费用统计 | U3: 成本分析用 | W3: 单价 | X3: 单耗 | Y3: 之前价 | Z3: 最新时间 | AD3: PAC | AE3: PAM阳 | AF3: PAM阴 | AG3: HCL | AH3: NACLO3 | AI3: 合计 | AK3: 干泥量 | AL3: 单耗
B4: 度 | C4: 状况 | E4: 国电 | F4: 英科环境 | G4: 其他 | H4: （Kg） | I4: （mg/l） | J4: ( 度 ) | K4: （Kg） | M4: （Kg） | N4: （Kg） | O4: 缺氧段 | P4: 提标段 | T4: 电量 | U4: =ROUND(J34*W4,2) -> 968456.46 | W4: 0.68019136 | X4: =J33/R33 -> 0.30725394 | Z4: 44960 | AB4: 污泥量合计
A5: 1 | B5: 14.4 | C5: 晴 | D5: 144613 | E5: 0 | F5: 0 | G5: 0 | H5: 125 | I5: 5008 | J5: 49700 | K5: 0 | L5: 0.2 | M5: 1491 | N5: 576 | O5: 3.5 | P5: 0 | Q5: 5432 | R5: =D5-Q5 -> 139181 | S5: 190000 | T5: 聚丙烯酰阳离子 | U5: =H34*W5/1000 -> 123900 | W5: 28000 | X5: =H33/R33*1000 -> 0.95490847 | Z5: 44652 | AB5: =E5+F5+G5 -> 0 | AD5: =$W$9*K5/1000/R5 -> 0 | AE5: =$W$5*H5/1000/R5 -> 0.025147111 | AF5: =$W$6*L5/1000/R5 -> 1.4944569e-05 | AG5: =$W$7*M5/1000/R5 -> 0.0050135291 | AH5: =$W$8*N5/1000/R5 -> 0.025013069 | AI5: =AD5+AE5+AF5+AG5+AH5 -> 0.055188654 | AK5: =AB5*(100-进出水!T7)/100 -> 0 | AL5: =H5/AK5 -> #DIV/0!
A6: 2 | B6: 13 | C6: 阴 | D6: 147687 | E6: 35.72 | F6: 34.1 | G6: 0 | H6: 100 | I6: 4742 | J6: 46000 | K6: 0 | L6: 0 | M6: 2627 | N6: 840 | O6: 3.35 | P6: 0 | Q6: 5438 | R6: =D6-Q6 -> 142249 | S6: 190000 | T6: 聚丙烯酰阴离子 | U6: =L34*W6/1000 -> 22.88 | V6: =U5+U6 -> 123922.88 | W6: 10400 | X6: =L33/R33*1000 -> 0.00047475675 | Z6: 44256 | AB6: =E6+F6+G6 -> 69.82 | AD6: =$W$9*K6/1000/R6 -> 0 | AE6: =$W$5*H6/1000/R6 -> 0.019683794 | AF6: =$W$6*L6/1000/R6 -> 0 | AG6: =$W$7*M6/1000/R6 -> 0.0086428446 | AH6: =$W$8*N6/1000/R6 -> 0.035690655 | AI6: =AD6+AE6+AF6+AG6+AH6 -> 0.064017294 | AK6: =AB6*(100-进出水!T8)/100 -> 15.0113 | AL6: =H6/AK6 -> 6.6616482
A7: 3 | B7: 14.4 | C7: 晴 | D7: 143268 | E7: 35.5 | F7: 34.24 | G7: 0 | H7: 100 | I7: 5432 | J7: 45400 | K7: 0 | L7: 0 | M7: 1775 | N7: 648 | O7: 3.2 | P7: 0 | Q7: 5435 | R7: =D7-Q7 -> 137833 | S7: 190000 | T7: 工业盐酸 | U7: =M34*W7/1000 -> 38677.392 | W7: 468 | X7: =M33/R33*1000 -> 17.834453 | Z7: 44927 | AB7: =E7+F7+G7 -> 69.74 | AD7: =$W$9*K7/1000/R7 -> 0 | AE7: =$W$5*H7/1000/R7 -> 0.020314438 | AF7: =$W$6*L7/1000/R7 -> 0 | AG7: =$W$7*M7/1000/R7 -> 0.0060268586 | AH7: =$W$8*N7/1000/R7 -> 0.028414908 | AI7: =AD7+AE7+AF7+AG7+AH7 -> 0.054756205 | AK7: =AB7*(100-进出水!T9)/100 -> 14.78488 | AL7: =H7/AK7 -> 6.7636667
A8: 4 | B8: 14.3 | C8: 晴 | D8: 144783 | E8: 36.14 | F8: 52.36 | G8: 30 | H8: 100 | I8: 5126 | J8: 46600 | K8: 0 | L8: 0.2 | M8: 1420 | N8: 600 | O8: 3.5 | P8: 0 | Q8: 5433 | R8: =D8-Q8 -> 139350 | S8: 190000 | T8: 工业氯酸钠 | U8: =N34*W8/1000 -> 174647.42 | V8: =U7+U8 -> 213324.82 | W8: 6044 | X8: =N33/R33*1000 -> 6.2357141 | Z8: 44929 | AB8: =E8+F8+G8 -> 118.5 | AD8: =$W$9*K8/1000/R8 -> 0 | AE8: =$W$5*H8/1000/R8 -> 0.02009329 | AF8: =$W$6*L8/1000/R8 -> 1.4926444e-05 | AG8: =$W$7*M8/1000/R8 -> 0.0047689989 | AH8: =$W$8*N8/1000/R8 -> 0.026023681 | AI8: =AD8+AE8+AF8+AG8+AH8 -> 0.050900897 | AK8: =AB8*(100-进出水!T10)/100 -> 25.7145 | AL8: =H8/AK8 -> 3.8888565
A9: 5 | B9: 14.5 | C9: 阴 | D9: 142460 | E9: 54.04 | F9: 51.66 | G9: 15 | H9: 125 | I9: 5006 | J9: 48500 | K9: 0 | L9: 0 | M9: 2485 | N9: 912 | O9: 3.45 | P9: 0 | Q9: 5525 | R9: =D9-Q9 -> 136935 | S9: 190000 | T9: 混凝药剂 | U9: =K34*W9/1000 -> 14027.52 | W9: 416 | X9: =K33/R33*1000 -> 7.2767262 | Z9: 44927 | AB9: =E9+F9+G9 -> 120.7 | AD9: =$W$9*K9/1000/R9 -> 0 | AE9: =$W$5*H9/1000/R9 -> 0.025559572 | AF9: =$W$6*L9/1000/R9 -> 0 | AG9: =$W$7*M9/1000/R9 -> 0.0084929346 | AH9: =$W$8*N9/1000/R9 -> 0.040253609 | AI9: =AD9+AE9+AF9+AG9+AH9 -> 0.074306116 | AK9: =AB9*(100-进出水!T11)/100 -> 25.5884 | AL9: =H9/AK9 -> 4.885026
A10: 6 | B10: 14.2 | C10: 雨 | D10: 152134 | E10: 87.22 | F10: 16.52 | G10: 0 | H10: 75 | I10: 4758 | J10: 48500 | K10: 0 | L10: 0.2 | M10: 3266 | N10: 1128 | O10: 3.35 | P10: 0 | Q10: 5446 | R10: =D10-Q10 -> 146688 | S10: 190000 | T10: 污泥外运 | U10: =T18 -> 24358.69 | V10: 计算见下表 | AB10: =E10+F10+G10 -> 103.74 | AD10: =$W$9*K10/1000/R10 -> 0 | AE10: =$W$5*H10/1000/R10 -> 0.014316099 | AF10: =$W$6*L10/1000/R10 -> 1.4179756e-05 | AG10: =$W$7*M10/1000/R10 -> 0.010419993 | AH10: =$W$8*N10/1000/R10 -> 0.046477094 | AI10: =AD10+AE10+AF10+AG10+AH10 -> 0.071227367 | AK10: =AB10*(100-进出水!T12)/100 -> 21.88914 | AL10: =H10/AK10 -> 3.4263566
A11: 7 | B11: 15.2 | C11: 阴 | D11: 147959 | E11: 88.2 | F11: 0 | G11: 0 | H11: 200 | I11: 5394 | J11: 47500 | K11: 0 | L11: 0 | M11: 5325 | N11: 1752 | O11: 2.15 | P11: 0 | Q11: 5446 | R11: =D11-Q11 -> 142513 | S11: 190000 | T11: 自来水 | U11: =汇总!J5*4.21 -> 14928.66 | W11: 4.2 | AB11: =E11+F11+G11 -> 88.2 | AD11: =$W$9*K11/1000/R11 -> 0 | AE11: =$W$5*H11/1000/R11 -> 0.039294661 | AF11: =$W$6*L11/1000/R11 -> 0 | AG11: =$W$7*M11/1000/R11 -> 0.017486826 | AH11: =$W$8*N11/1000/R11 -> 0.074302611 | AI11: =AD11+AE11+AF11+AG11+AH11 -> 0.1310841 | AK11: =AB11*(100-进出水!T13)/100 -> 19.1394 | AL11: =H11/AK11 -> 10.449648
A12: 8 | B12: 15.6 | C12: 阴 | D12: 150832 | E12: 50.22 | F12: 0 | G12: 0 | H12: 150 | I12: 5728 | J12: 48800 | K12: 0 | L12: 0 | M12: 3266 | N12: 1152 | O12: 1.8 | P12: 0 | Q12: 5348 | R12: =D12-Q12 -> 145484 | S12: 190000 | AB12: =E12+F12+G12 -> 50.22 | AD12: =$W$9*K12/1000/R12 -> 0 | AE12: =$W$5*H12/1000/R12 -> 0.028869154 | AF12: =$W$6*L12/1000/R12 -> 0 | AG12: =$W$7*M12/1000/R12 -> 0.010506227 | AH12: =$W$8*N12/1000/R12 -> 0.047858789 | AI12: =AD12+AE12+AF12+AG12+AH12 -> 0.08723417 | AK12: =AB12*(100-进出水!T14)/100 -> 10.89774 | AL12: =H12/AK12 -> 13.764322
A13: 9 | B13: 15.5 | C13: 雨 | D13: 157832 | E13: 70.7 | F13: 0 | G13: 0 | H13: 100 | I13: 5322 | J13: 49200 | K13: 0 | L13: 0.2 | M13: 2840 | N13: 1008 | O13: 1.75 | P13: 0 | Q13: 5906 | R13: =D13-Q13 -> 151926 | S13: 190000 | U13: =U14/R34 -> 0.075804673 | AB13: =E13+F13+G13 -> 70.7 | AD13: =$W$9*K13/1000/R13 -> 0 | AE13: =$W$5*H13/1000/R13 -> 0.018430025 | AF13: =$W$6*L13/1000/R13 -> 1.3690876e-05 | AG13: =$W$7*M13/1000/R13 -> 0.0087484696 | AH13: =$W$8*N13/1000/R13 -> 0.040100786 | AI13: =AD13+AE13+AF13+AG13+AH13 -> 0.067292972 | AK13: =AB13*(100-进出水!T15)/100 -> 15.0591 | AL13: =H13/AK13 -> 6.6405031
A14: 10 | B14: 14 | C14: 阴 | D14: 178453 | E14: 91.28 | F14: 0 | G14: 60 | H14: 125 | I14: 5188 | J14: 49500 | K14: 0 | L14: 0 | M14: 2698 | N14: 864 | O14: 0.55 | P14: 0 | Q14: 5197 | R14: =D14-Q14 -> 173256 | S14: 190000 | T14: 总药剂 | U14: =U5+U6+U7+U8+U9 -> 351275.22 | V14: 除磷药剂 | W14: =U6+U9 -> 14050.4 | AB14: =E14+F14+G14 -> 151.28 | AD14: =$W$9*K14/1000/R14 -> 0 | AE14: =$W$5*H14/1000/R14 -> 0.020201321 | AF14: =$W$6*L14/1000/R14 -> 0 | AG14: =$W$7*M14/1000/R14 -> 0.0072878515 | AH14: =$W$8*N14/1000/R14 -> 0.030140463 | AI14: =AD14+AE14+AF14+AG14+AH14 -> 0.057629635 | AK14: =AB14*(100-进出水!T16)/100 -> 32.22264 | AL14: =H14/AK14 -> 3.87926
A15: 11 | B15: 15.2 | C15: 雨 | D15: 192947 | E15: 37.16 | F15: 0 | G15: 0 | H15: 125 | I15: 4710 | J15: 52400 | K15: 0 | L15: 0 | M15: 1491 | N15: 552 | O15: 0 | P15: 0 | Q15: 5463 | R15: =D15-Q15 -> 187484 | S15: 190000 | T15: 总泥量 | U15: 英科（吨） | V15: 国电（吨） | W15: 外运（吨） | AB15: =E15+F15+G15 -> 37.16 | AD15: =$W$9*K15/1000/R15 -> 0 | AE15: =$W$5*H15/1000/R15 -> 0.01866826 | AF15: =$W$6*L15/1000/R15 -> 0 | AG15: =$W$7*M15/1000/R15 -> 0.0037218536 | AH15: =$W$8*N15/1000/R15 -> 0.017795055 | AI15: =AD15+AE15+AF15+AG15+AH15 -> 0.040185168 | AK15: =AB15*(100-进出水!T17)/100 -> 7.87792 | AL15: =H15/AK15 -> 15.867132
A16: 12 | B16: 15.4 | C16: 雨 | D16: 187286 | E16: 72.56 | F16: 0 | G16: 90 | H16: 225 | I16: 4264 | J16: 51300 | K16: 0 | L16: 0.2 | M16: 3124 | N16: 1080 | O16: 0 | P16: 0 | Q16: 5489 | R16: =D16-Q16 -> 181797 | S16: 190000 | T16: =U16+V16+W16 -> 2763.58 | U16: =F34 -> 344.12 | V16: =E34 -> 2141.46 | W16: =G34 -> 278 | AB16: =E16+F16+G16 -> 162.56 | AD16: =$W$9*K16/1000/R16 -> 0 | AE16: =$W$5*H16/1000/R16 -> 0.034654037 | AF16: =$W$6*L16/1000/R16 -> 1.1441333e-05 | AG16: =$W$7*M16/1000/R16 -> 0.0080421129 | AH16: =$W$8*N16/1000/R16 -> 0.035905543 | AI16: =AD16+AE16+AF16+AG16+AH16 -> 0.078613134 | AK16: =AB16*(100-进出水!T18)/100 -> 34.78784 | AL16: =H16/AK16 -> 6.4677772
A17: 13 | B17: 15.1 | C17: 雨 | D17: 185915 | E17: 32.44 | F17: 0 | G17: 0 | H17: 150 | I17: 5112 | J17: 50800 | K17: 0 | L17: 0 | M17: 3266 | N17: 1128 | O17: 0 | P17: 0 | Q17: 5468 | R17: =D17-Q17 -> 180447 | S17: 190000 | T17: 江边费用 | U17: 9.8 | V17: 9.8 | AB17: =E17+F17+G17 -> 32.44 | AD17: =$W$9*K17/1000/R17 -> 0 | AE17: =$W$5*H17/1000/R17 -> 0.023275532 | AF17: =$W$6*L17/1000/R17 -> 0 | AG17: =$W$7*M17/1000/R17 -> 0.0084705648 | AH17: =$W$8*N17/1000/R17 -> 0.037781908 | AI17: =AD17+AE17+AF17+AG17+AH17 -> 0.069528005 | AK17: =AB17*(100-进出水!T19)/100 -> 7.00704 | AL17: =H17/AK17 -> 21.407042
A18: 14 | B18: 14.7 | C18: 晴 | D18: 183062 | E18: 71.1 | F18: 0 | G18: 0 | H18: 125 | I18: 4328 | J18: 47700 | K18: 1560 | L18: 0.2 | M18: 3337 | N18: 1176 | O18: 0 | P18: 0 | Q18: 5484 | R18: =D18-Q18 -> 177578 | S18: 190000 | T18: =U18+V18 -> 24358.69 | U18: =ROUND(U16*U17,2) -> 3372.38 | V18: =ROUND(V16*V17,2) -> 20986.31 | AB18: =E18+F18+G18 -> 71.1 | AD18: =$W$9*K18/1000/R18 -> 0.0036545068 | AE18: =$W$5*H18/1000/R18 -> 0.019709649 | AF18: =$W$6*L18/1000/R18 -> 1.1713163e-05 | AG18: =$W$7*M18/1000/R18 -> 0.0087945354 | AH18: =$W$8*N18/1000/R18 -> 0.040026039 | AI18: =AD18+AE18+AF18+AG18+AH18 -> 0.072196443 | AK18: =AB18*(100-进出水!T20)/100 -> 15.1443 | AL18: =H18/AK18 -> 8.2539305
A19: 15 | B19: 15.2 | C19: 晴 | D19: 181934 | E19: 72.52 | F19: 0 | G19: 8 | H19: 125 | I19: 4372 | J19: 49800 | K19: 0 | L19: 0 | M19: 3479 | N19: 1200 | O19: 0 | P19: 0 | Q19: 5470 | R19: =D19-Q19 -> 176464 | S19: 190000 | T19: 排水承担 | V19: 0 | AB19: =E19+F19+G19 -> 80.52 | AD19: =$W$9*K19/1000/R19 -> 0 | AE19: =$W$5*H19/1000/R19 -> 0.019834074 | AF19: =$W$6*L19/1000/R19 -> 0 | AG19: =$W$7*M19/1000/R19 -> 0.0092266525 | AH19: =$W$8*N19/1000/R19 -> 0.041100734 | AI19: =AD19+AE19+AF19+AG19+AH19 -> 0.070161461 | AK19: =AB19*(100-进出水!T21)/100 -> 17.3118 | AL19: =H19/AK19 -> 7.2205086
A20: 16 | B20: 15.5 | C20: 晴 | D20: 204424 | E20: 85.14 | F20: 17.04 | G20: 30 | H20: 125 | I20: 4632 | J20: 55600 | K20: 0 | L20: 0 | M20: 3266 | N20: 1128 | O20: 0 | P20: 0 | Q20: 5487 | R20: =D20-Q20 -> 198937 | S20: 198936 | T20: =U20+V20 -> 0 | V20: =ROUND(V16*V19,2) -> 0 | AB20: =E20+F20+G20 -> 132.18 | AD20: =$W$9*K20/1000/R20 -> 0 | AE20: =$W$5*H20/1000/R20 -> 0.01759351 | AF20: =$W$6*L20/1000/R20 -> 0 | AG20: =$W$7*M20/1000/R20 -> 0.0076832766 | AH20: =$W$8*N20/1000/R20 -> 0.034270307 | AI20: =AD20+AE20+AF20+AG20+AH20 -> 0.059547093 | AK20: =AB20*(100-进出水!T22)/100 -> 28.81524 | AL20: =H20/AK20 -> 4.3379823
A21: 17 | B21: 15.8 | C21: 阴 | D21: 201762 | E21: 91.22 | F21: 0 | G21: 0 | H21: 125 | I21: 4544 | J21: 56900 | K21: 0 | L21: 0.2 | M21: 2840 | N21: 1008 | O21: 0 | P21: 0 | Q21: 5188 | R21: =D21-Q21 -> 196574 | S21: 196570 | T21: 总运费 | U21: 总单价 | V21: 9.8 | W21: 核对 | AB21: =E21+F21+G21 -> 91.22 | AD21: =$W$9*K21/1000/R21 -> 0 | AE21: =$W$5*H21/1000/R21 -> 0.017805 | AF21: =$W$6*L21/1000/R21 -> 1.0581257e-05 | AG21: =$W$7*M21/1000/R21 -> 0.0067614232 | AH21: =$W$8*N21/1000/R21 -> 0.030992664 | AI21: =AD21+AE21+AF21+AG21+AH21 -> 0.055569668 | AK21: =AB21*(100-进出水!T23)/100 -> 19.79474 | AL21: =H21/AK21 -> 6.3148089
A22: 18 | B22: 15.5 | C22: 阴 | D22: 192924 | E22: 106.26 | F22: 0 | G22: 30 | H22: 200 | I22: 4366 | J22: 58200 | K22: 0 | L22: 0 | M22: 852 | N22: 360 | O22: 0 | P22: 0 | Q22: 4765 | R22: =D22-Q22 -> 188159 | S22: 190000 | T22: =T18+T20 -> 24358.69 | W22: =T16-E34-F34-G34 -> 0 | AB22: =E22+F22+G22 -> 136.26 | AD22: =$W$9*K22/1000/R22 -> 0 | AE22: =$W$5*H22/1000/R22 -> 0.029762063 | AF22: =$W$6*L22/1000/R22 -> 0 | AG22: =$W$7*M22/1000/R22 -> 0.0021191439 | AH22: =$W$8*N22/1000/R22 -> 0.011563837 | AI22: =AD22+AE22+AF22+AG22+AH22 -> 0.043445044 | AK22: =AB22*(100-进出水!T24)/100 -> 29.15964 | AL22: =H22/AK22 -> 6.8587952
A23: 19 | B23: 15.2 | C23: 晴 | D23: 188315 | E23: 0 | F23: 33.42 | G23: 0 | H23: 125 | I23: 3888 | J23: 56700 | K23: 0 | L23: 0.2 | M23: 1775 | N23: 720 | O23: 0 | P23: 0 | Q23: 5488 | R23: =D23-Q23 -> 182827 | S23: 190000 | AB23: =E23+F23+G23 -> 33.42 | AD23: =$W$9*K23/1000/R23 -> 0 | AE23: =$W$5*H23/1000/R23 -> 0.019143781 | AF23: =$W$6*L23/1000/R23 -> 1.1376875e-05 | AG23: =$W$7*M23/1000/R23 -> 0.0045436396 | AH23: =$W$8*N23/1000/R23 -> 0.023802174 | AI23: =AD23+AE23+AF23+AG23+AH23 -> 0.047500971 | AK23: =AB23*(100-进出水!T25)/100 -> 7.08504 | AL23: =H23/AK23 -> 17.642808
A24: 20 | B24: 16.3 | C24: 晴 | D24: 177606 | E24: 85.94 | F24: 36.56 | G24: 0 | H24: 125 | I24: 4100 | J24: 52000 | K24: 0 | L24: 0 | M24: 2840 | N24: 1032 | O24: 0 | P24: 0 | Q24: 5475 | R24: =D24-Q24 -> 172131 | S24: 190000 | T24: 絮凝剂 | U24: 用量（kg） | V24: =H34 -> 4425 | W24: =L34 -> 2.2 | AB24: =E24+F24+G24 -> 122.5 | AD24: =$W$9*K24/1000/R24 -> 0 | AE24: =$W$5*H24/1000/R24 -> 0.020333351 | AF24: =$W$6*L24/1000/R24 -> 0 | AG24: =$W$7*M24/1000/R24 -> 0.0077215609 | AH24: =$W$8*N24/1000/R24 -> 0.036236401 | AI24: =AD24+AE24+AF24+AG24+AH24 -> 0.064291313 | AK24: =AB24*(100-进出水!T26)/100 -> 26.3375 | AL24: =H24/AK24 -> 4.7460845
A25: 21 | B25: 16.5 | C25: 晴 | D25: 169823 | E25: 83.34 | F25: 0 | G25: 15 | H25: 125 | I25: 4442 | J25: 51400 | K25: 0 | L25: 0 | M25: 4615 | N25: 1536 | O25: 0 | P25: 0 | Q25: 5485 | R25: =D25-Q25 -> 164338 | S25: 190000 | U25: 单耗（kg/T） | V25: =汇总!F6 -> 7.4751819 | W25: =W24/R34*1000 -> 0.00047475675 | AB25: =E25+F25+G25 -> 98.34 | AD25: =$W$9*K25/1000/R25 -> 0 | AE25: =$W$5*H25/1000/R25 -> 0.02129757 | AF25: =$W$6*L25/1000/R25 -> 0 | AG25: =$W$7*M25/1000/R25 -> 0.013142548 | AH25: =$W$8*N25/1000/R25 -> 0.056490793 | AI25: =AD25+AE25+AF25+AG25+AH25 -> 0.090930911 | AK25: =AB25*(100-进出水!T27)/100 -> 20.84808 | AL25: =H25/AK25 -> 5.995756
A26: 22 | B26: 16.1 | C26: 阴 | D26: 164823 | E26: 104.84 | F26: 0 | G26: 0 | H26: 125 | I26: 4416 | J26: 50200 | K26: 0 | L26: 0.2 | M26: 4828 | N26: 1656 | O26: 0 | P26: 0 | Q26: 5482 | R26: =D26-Q26 -> 159341 | S26: 190000 | T26: 混凝剂 | U26: 用量（kg） | V26: =K34 -> 33720 | AB26: =E26+F26+G26 -> 104.84 | AD26: =$W$9*K26/1000/R26 -> 0 | AE26: =$W$5*H26/1000/R26 -> 0.02196547 | AF26: =$W$6*L26/1000/R26 -> 1.3053765e-05 | AG26: =$W$7*M26/1000/R26 -> 0.014180305 | AH26: =$W$8*N26/1000/R26 -> 0.062814116 | AI26: =AD26+AE26+AF26+AG26+AH26 -> 0.098972945 | AK26: =AB26*(100-进出水!T28)/100 -> 22.33092 | AL26: =H26/AK26 -> 5.5976198
A27: 23 | B27: 16.8 | C27: 阴 | D27: 165919 | E27: 120.48 | F27: 16.78 | G27: 0 | H27: 125 | I27: 4714 | J27: 50200 | K27: 720 | L27: 0 | M27: 3408 | N27: 1200 | O27: 1.3 | P27: 0 | Q27: 5468 | R27: =D27-Q27 -> 160451 | S27: 190000 | U27: 单耗（g/m3） | V27: =ROUND(K34/R34*1000,1) -> 7.3 | AB27: =E27+F27+G27 -> 137.26 | AD27: =$W$9*K27/1000/R27 -> 0.0018667381 | AE27: =$W$5*H27/1000/R27 -> 0.021813513 | AF27: =$W$6*L27/1000/R27 -> 0 | AG27: =$W$7*M27/1000/R27 -> 0.0099403806 | AH27: =$W$8*N27/1000/R27 -> 0.045202585 | AI27: =AD27+AE27+AF27+AG27+AH27 -> 0.078823217 | AK27: =AB27*(100-进出水!T29)/100 -> 29.64816 | AL27: =H27/AK27 -> 4.2161132
A28: 24 | B28: 16.5 | C28: 阴 | D28: 172893 | E28: 102.8 | F28: 0 | G28: 0 | H28: 250 | I28: 4988 | J28: 49000 | K28: 9480 | L28: 0.2 | M28: 2556 | N28: 912 | O28: 1.95 | P28: 0 | Q28: 5451 | R28: =D28-Q28 -> 167442 | S28: 190000 | T28: 盐酸 | U28: 用量（kg） | V28: =M34 -> 82644 | AB28: =E28+F28+G28 -> 102.8 | AD28: =$W$9*K28/1000/R28 -> 0.023552514 | AE28: =$W$5*H28/1000/R28 -> 0.041805521 | AF28: =$W$6*L28/1000/R28 -> 1.2422212e-05 | AG28: =$W$7*M28/1000/R28 -> 0.007144014 | AH28: =$W$8*N28/1000/R28 -> 0.032919626 | AI28: =AD28+AE28+AF28+AG28+AH28 -> 0.1054341 | AK28: =AB28*(100-进出水!T30)/100 -> 22.3076 | AL28: =H28/AK28 -> 11.206943
A29: 25 | B29: 16.5 | C29: 晴 | D29: 179001 | E29: 138.16 | F29: 0 | G29: 0 | H29: 300 | I29: 5384 | J29: 51700 | K29: 8880 | L29: 0 | M29: 1775 | N29: 648 | O29: 2 | P29: 0 | Q29: 5481 | R29: =D29-Q29 -> 173520 | S29: 190000 | U29: 单耗（g/m3） | V29: =ROUND(M34/R34*1000,1) -> 17.8 | AB29: =E29+F29+G29 -> 138.16 | AD29: =$W$9*K29/1000/R29 -> 0.021289073 | AE29: =$W$5*H29/1000/R29 -> 0.048409405 | AF29: =$W$6*L29/1000/R29 -> 0 | AG29: =$W$7*M29/1000/R29 -> 0.0047873444 | AH29: =$W$8*N29/1000/R29 -> 0.022570954 | AI29: =AD29+AE29+AF29+AG29+AH29 -> 0.097056777 | AK29: =AB29*(100-进出水!T31)/100 -> 29.7044 | AL29: =H29/AK29 -> 10.099514
A30: 26 | B30: 16.7 | C30: 晴 | D30: 176902 | E30: 98.32 | F30: 34.86 | G30: 0 | H30: 250 | I30: 5420 | J30: 53100 | K30: 0 | L30: 0 | M30: 3408 | N30: 1176 | O30: 0.1 | P30: 0 | Q30: 5430 | R30: =D30-Q30 -> 171472 | S30: 190000 | T30: 氯酸钠 | U30: 用量（kg） | V30: =处理量!N34 -> 28896 | AB30: =E30+F30+G30 -> 133.18 | AD30: =$W$9*K30/1000/R30 -> 0 | AE30: =$W$5*H30/1000/R30 -> 0.040822992 | AF30: =$W$6*L30/1000/R30 -> 0 | AG30: =$W$7*M30/1000/R30 -> 0.0093014836 | AH30: =$W$8*N30/1000/R30 -> 0.041451339 | AI30: =AD30+AE30+AF30+AG30+AH30 -> 0.091575814 | AK30: =AB30*(100-进出水!T32)/100 -> 28.50052 | AL30: =H30/AK30 -> 8.7717698
A31: 27 | B31: 16.6 | C31: 晴 | D31: 176903 | E31: 150.38 | F31: 16.58 | G31: 0 | H31: 300 | I31: 4500 | J31: 52200 | K31: 0 | L31: 0.2 | M31: 3621 | N31: 1272 | O31: 0 | P31: 0 | Q31: 5463 | R31: =D31-Q31 -> 171440 | S31: 190000 | U31: 单耗（g/m3） | V31: =ROUND(N34/R34*1000,2) -> 6.24 | AB31: =E31+F31+G31 -> 166.96 | AD31: =$W$9*K31/1000/R31 -> 0 | AE31: =$W$5*H31/1000/R31 -> 0.048996734 | AF31: =$W$6*L31/1000/R31 -> 1.2132524e-05 | AG31: =$W$7*M31/1000/R31 -> 0.009884671 | AH31: =$W$8*N31/1000/R31 -> 0.04484349 | AI31: =AD31+AE31+AF31+AG31+AH31 -> 0.10373703 | AK31: =AB31*(100-进出水!T33)/100 -> 35.39552 | AL31: =H31/AK31 -> 8.4756489
A32: 28 | B32: 16.8 | C32: 晴 | D32: 173582 | E32: 139.78 | F32: 0 | G32: 0 | H32: 300 | I32: 4224 | J32: 54900 | K32: 13080 | L32: 0 | M32: 4970 | N32: 1632 | O32: 0 | P32: 0 | Q32: 5447 | R32: =D32-Q32 -> 168135 | S32: 190000 | T32: 乙酸 | U32: 用量（T） | V32: =O34 -> 31.95 | AB32: =E32+F32+G32 -> 139.78 | AD32: =$W$9*K32/1000/R32 -> 0.032362566 | AE32: =$W$5*H32/1000/R32 -> 0.049959854 | AF32: =$W$6*L32/1000/R32 -> 0 | AG32: =$W$7*M32/1000/R32 -> 0.013833883 | AH32: =$W$8*N32/1000/R32 -> 0.058666001 | AI32: =AD32+AE32+AF32+AG32+AH32 -> 0.1548223 | AK32: =AB32*(100-进出水!T34)/100 -> 29.91292 | AL32: =H32/AK32 -> 10.029111
A33: 平均 | B33: =AVERAGE(B5:B32) -> 15.410714 | C33: / | D33: =AVERAGE(D5:D32) -> 170930.07 | E33: =AVERAGE(E5:E32) -> 76.480714 | F33: =AVERAGE(F5:F32) -> 12.29 | G33: 0 | H33: =AVERAGE(H5:H32) -> 158.03571 | I33: =AVERAGE(I5:I32) -> 4789.5714 | J33: =AVERAGE(J5:J32) -> 50850 | K33: =AVERAGE(K5:K32) -> 1204.2857 | L33: =AVERAGE(L5:L32) -> 0.078571429 | M33: =AVERAGE(M5:M32) -> 2951.5714 | N33: =AVERAGE(N5:N32) -> 1032 | O33: =AVERAGE(O5:O32) -> 1.1410714 | ... Q33: =AVERAGE(Q5:Q32) -> 5431.7857 | R33: =D33-Q33 -> 165498.29
A34: 合计 | B34: / | C34: / | D34: =SUM(D5:D32) -> 4786042 | E34: =SUM(E5:E32) -> 2141.46 | F34: =SUM(F5:F32) -> 344.12 | G34: =SUM(G5:G32) -> 278 | H34: =SUM(H5:H32) -> 4425 | I34: / | J34: =SUM(J5:J32) -> 1423800 | K34: =SUM(K5:K32) -> 33720 | L34: =SUM(L5:L32) -> 2.2 | M34: =SUM(M5:M32) -> 82644 | N34: =SUM(N5:N32) -> 28896 | O34: =SUM(O5:O32) -> 31.95 | P34: =SUM(P5:P32) -> 0 | Q34: =SUM(Q5:Q32) -> 152090 | ... S34: =SUM(S5:S32) -> 5335506 | AB34: =SUM(AB5:AB33) -> 2763.58
A35: 审核： | I35: 制表： | Q35: 制表时间: | R35: 44991
M36: =M34*0.31 -> 25619.64
Q37: 最大 | R37: =MAX(R5:R32) -> 198937 | AB37: =(100-进出水!T35)*AB34/100 -> 591.95884
O38: =O34*1000 -> 31950 | Q38: 最小 | R38: =MIN(R5:R32) -> 136935
L39: =L34*1000/R34 -> 0.00047475675
R41: =L34/R34*1000 -> 0.00047475675

Sheet 汇总
A1: 常州市深水江边污水处理有限公司污水运行月报表
A2: 44958
A3: 污 水 处 理 | B3: 污水处理量（m3） | C3: =处理量!R34 -> 4633952 | D3: 污 泥 处 理 | E3: 脱水污泥量（T） | F3: =处理量!E34+处理量!F34+处理量!G34 -> 2763.58 | G3: 水 电 用 量 | H3: 用电量（度） | J3: =处理量!J34 -> 1423800 | K3: 污 水 电 单 耗 | L3: 污水（度/m3） | M3: =J3/C3 -> 0.30725394 | P3: 除臭用水量 | Q3: 1773.2 | R3: =J5-Q3 -> 1772.8 | V3: 188314
B4: 日均处理量（m3） | C4: =处理量!R33 -> 165498.29 | E4: 絮凝剂用量（kg） | F4: =处理量!H34 -> 4425 | H4: 日均用电量（度） | J4: =J3/M15 -> 50850 | L4: CODcr（度/kg） | M4: =J3/I12 -> 1.1876843 | P4: 除臭用电量 | Q4: 50536 | V4: 193894
E5: 含水率（%） | F5: =进出水!T35 -> 78.58 | H5: 用水量（T） | J5: 3546 | V5: =V4-V3 -> 5580
B6: 最高日处理量 | C6: =处理量!R37 -> 198937 | E6: 絮凝剂单耗（kg/T） | F6: =F4/(F3*(100-F5)/100) -> 7.4751819 | G6: 消 毒 剂 | H6: 工业合成盐酸（T） | J6: =处理量!M34/1000 -> 82.644 | L6: BOD5（度/kg） | M6: =J3/I13 -> 2.4288849
B7: 最低日处理量 | C7: =处理量!R38 -> 136935 | E7: 产泥率(g/m３) | F7: =F3*(100-F5)/100*1000/(C3/1000) -> 127.74384 | H7: 药单耗(g/m3) | J7: =J6*1000/(C3/1000) -> 17.834453 | L7: SS（度/kg） | M7: =J3/I14 -> 2.6592863
B8: 负荷率（%） | C8: =C4/200000*100 -> 82.749143 | D8: 混 凝 剂 | E8: 混凝剂用量（T） | F8: =处理量!K34/1000 -> 33.72 | H8: 氯酸钠（T） | J8: =处理量!N34/1000 -> 28.896 | K8: 乙酸-厌缺氧段 | L8: 投加量（吨） | M8: =处理量!O34 -> 31.95
B9: 进水水温(℃) | C9: =处理量!B33 -> 15.410714 | E9: 药单耗(g/m3) | F9: =F8*1000/(C3/1000) -> 7.2767262 | H9: 药单耗(g/m3) | J9: =J8*1000/(C3/1000) -> 6.2357141 | L9: 药单耗(g/m3) | M9: =M8*1000000/C3 -> 6.8947628
A10: 处 理 质 量 | B10: 项目 | C10: 进水 | E10: 出水 | G10: 去除率（%） | I10: 去除总量（kg) | K10: 乙酸-提标段 | L10: 投加量（吨） | M10: 0
L11: 药单耗(g/m3) | M11: 0
B12: CODcr | C12: =进出水!B35 -> 283 | E12: =进出水!N35 -> 24.3 | G12: =(C12-E12)/C12*100 -> 91.413428 | I12: =$C$3*(C12-E12)/1000 -> 1198803.4 | K12: 污 泥 去 向 | L12: 国电 | M12: =处理量!V16 -> 2141.46 | P12: =ROUND(E12,1) -> 24.3 | Q12: =C3 -> 4633952 | R12: =P12*Q12/1000000 -> 112.60503 | S12: CODcr
B13: BOD5 | C13: =进出水!C35 -> 129 | E13: =进出水!O35 -> 2.5 | G13: =(C13-E13)/C13*100 -> 98.062016 | I13: =$C$3*(C13-E13)/1000 -> 586194.93 | L13: 英科环境 | M13: =处理量!U16 -> 344.12 | P13: =ROUND(E13,1) -> 2.5 | Q13: =Q12 -> 4633952 | R13: =P13*Q13/1000000 -> 11.58488 | S13: BOD5
B14: SS | C14: =进出水!D35 -> 121 | E14: =进出水!P35 -> 5.46 | G14: =(C14-E14)/C14*100 -> 95.487603 | I14: =$C$3*(C14-E14)/1000 -> 535406.81 | L14: 其它 | M14: =处理量!W16 -> 278 | P14: =ROUND(E14,1) -> 5.5 | Q14: =Q13 -> 4633952 | R14: =P14*Q14/1000000 -> 25.486736 | S14: SS
B15: TP | C15: =进出水!E35 -> 2.6 | E15: =进出水!Q35 -> 0.16 | G15: =(C15-E15)/C15*100 -> 93.846154 | I15: =$C$3*(C15-E15)/1000 -> 11306.843 | K15: 运 行 情 况 | L15: 应运行天数 | M15: 28 | P15: =ROUND(E15,1) -> 0.2 | Q15: =Q14 -> 4633952 | R15: =P15*Q15/1000000 -> 0.9267904 | S15: TP
B16: TN | C16: =进出水!G35 -> 31.5 | E16: =进出水!S35 -> 6.87 | G16: =(C16-E16)/C16*100 -> 78.190476 | I16: =$C$3*(C16-E16)/1000 -> 114134.24 | L16: 实际运行天数 | M16: 28 | P16: =ROUND(E16,1) -> 6.9 | Q16: =Q15 -> 4633952 | R16: =P16*Q16/1000000 -> 31.974269 | S16: TN
B17: NH3-N | C17: =进出水!F35 -> 25 | E17: =进出水!R35 -> 0.39 | G17: =(C17-E17)/C17*100 -> 98.44 | I17: =$C$3*(C17-E17)/1000 -> 114041.56 | L17: 达标排放天数 | M17: 28 | P17: =ROUND(E17,1) -> 0.4 | Q17: =Q16 -> 4633952 | R17: =P17*Q17/1000000 -> 1.8535808 | S17: NH3-N
B18: 粪大肠菌群数 (个/L) | E18: <20 | L18: 运转率 | M18: 100
A19: 备注 | B19: 本月产生泥饼2763.58吨，其中运往常州市英科环境科技有限公司344.12吨，国电常州发电有限公司2141.46吨，外运接种278.00吨：常州市百丈污水处理有限公司120.00吨、常州东方诺亚印染有限公司105.00吨、常州市华艺植绒材料有限公司8.00吨、常州西源污水处理有限公司30.00吨、常州千红生化制药股份有限公司15.00吨。 | P19: =F3*(100-F5)/100 -> 591.95884
A21: 审核： 制表： 制表日期：2023/3/6
C22: 287 | D22: 24.2 | E22: =(C22-D22)/C22*100 -> 91.567944
C23: 136 | D23: 2.3 | E23: =(C23-D23)/C23*100 -> 98.308824
C24: 122 | D24: 5.18 | E24: =(C24-D24)/C24*100 -> 95.754098
C25: 2.6 | D25: 0.16 | E25: =(C25-D25)/C25*100 -> 93.846154
C26: 25 | D26: 0.39 | E26: =(C26-D26)/C26*100 -> 98.44
C27: 31.5 | D27: 6.87 | E27: =(C27-D27)/C27*100 -> 78.190476

Sheet 进出水
A1: 常州市深水江边污水处理有限公司进出水水质、污泥含水率月报表
J3: 44958
A4: 日期 | B4: 进水 | H4: 二沉池出水 | N4: 总出水 | T4: 污泥含水率 | U4: 粪大肠菌群
B5: CODCr | C5: BOD5 | D5: SS | E5: TP | F5: NH3-N | G5: TN | H5: CODCr | I5: BOD5 | J5: SS | K5: TP | L5: NH3-N | M5: TN | N5: CODCr | O5: BOD5 | P5: SS | Q5: TP | R5: NH3-N | S5: TN
B6: （mg/L） | C6: （mg/L） | D6: （mg/L） | E6: （mg/L） | F6: （mg/L） | G6: （mg/L） | H6: （mg/L） | I6: （mg/L） | J6: （mg/L） | K6: （mg/L） | L6: （mg/L） | M6: （mg/L） | N6: （mg/L） | O6: （mg/L） | P6: （mg/L） | Q6: （mg/L） | R6: （mg/L） | S6: （mg/L） | T6: （%） | U6: (个/L)
A7: 1 | B7: 253 | C7: 113 | D7: 118 | E7: 2.66 | F7: 30.6 | G7: 36.8 | H7: 18 | I7: 2.55 | J7: 12 | K7: 0.56 | L7: 0.2 | M7: 8.24 | N7: <16 | O7: 2.33 | P7: 5 | Q7: 0.11 | R7: 0.14 | S7: 8.16 | T7: 78.7 | U7: <20 | V7: =T7-0.5 -> 78.2 | W7: =1-S7/G7 -> 0.77826087
A8: 2 | B8: 338 | C8: 152 | D8: 158 | E8: 3.6 | F8: 32.2 | G8: 38.1 | H8: 23 | I8: 2.74 | J8: 13 | K8: 0.53 | L8: 0.28 | M8: 6.77 | N8: 20 | O8: 2.23 | P8: 6 | Q8: 0.1 | R8: 0.2 | S8: 6.48 | T8: 78.5 | U8: <20 | V8: =T8-0.5 -> 78 | W8: =1-S8/G8 -> 0.82992126
A9: 3 | B9: 192 | C9: 87.5 | D9: 92 | E9: 5.15 | F9: 32.3 | G9: 38.8 | H9: 23 | I9: 2.44 | J9: 12 | K9: 0.55 | L9: 0.69 | M9: 8.94 | N9: 18 | O9: 2.2 | P9: 6 | Q9: 0.12 | R9: 0.36 | S9: 8.72 | T9: 78.8 | U9: 60 | V9: =T9-0.5 -> 78.3 | W9: =1-S9/G9 -> 0.77525773
A10: 4 | B10: 200 | C10: 91.4 | D10: 106 | E10: 2.21 | F10: 24.5 | G10: 30.7 | H10: 25 | I10: 2.61 | J10: 13 | K10: 0.51 | L10: 0.59 | M10: 7.37 | N10: 22 | O10: 2.39 | P10: 5 | Q10: 0.13 | R10: 0.32 | S10: 6.94 | T10: 78.3 | U10: <20 | V10: =T10-0.5 -> 77.8 | W10: =1-S10/G10 -> 0.77394137
A11: 5 | B11: 318 | C11: 144 | D11: 166 | E11: 3.87 | F11: 33 | G11: 42.6 | H11: 32 | I11: 3.1 | J11: 12 | K11: 0.51 | L11: 0.46 | M11: 9.6 | N11: 25 | O11: 2.67 | P11: 5 | Q11: 0.13 | R11: 0.43 | S11: 8.34 | T11: 78.8 | U11: <20 | V11: =T11-0.5 -> 78.3 | W11: =1-S11/G11 -> 0.80422535
A12: 6 | B12: 328 | C12: 148 | D12: 152 | E12: 3.28 | F12: 28.7 | G12: 35.2 | H12: 25 | I12: 2.43 | J12: 13 | K12: 0.5 | L12: 0.42 | M12: 7.63 | N12: 19 | O12: 2.36 | P12: 6 | Q12: 0.13 | R12: 0.31 | S12: 6.68 | T12: 78.9 | U12: <20 | V12: =T12-0.5 -> 78.4 | W12: =1-S12/G12 -> 0.81022727
A13: 7 | B13: 306 | C13: 136 | D13: 150 | E13: 2.52 | F13: 40 | G13: 46.5 | H13: 26 | I13: 2.25 | J13: 14 | K13: 0.52 | L13: 0.52 | M13: 7.98 | N13: 19 | O13: 2.16 | P13: 5 | Q13: 0.2 | R13: 0.4 | S13: 6.9 | T13: 78.3 | U13: 90 | V13: =T13-0.5 -> 77.8 | W13: =1-S13/G13 -> 0.8516129
A14: 8 | B14: 446 | C14: 201 | D14: 116 | E14: 2.21 | F14: 26.5 | G14: 32 | H14: 26 | I14: 2.77 | J14: 14 | K14: 0.54 | L14: 0.49 | M14: 8.08 | N14: 19 | O14: 2.44 | P14: 5 | Q14: 0.15 | R14: 0.33 | S14: 6.58 | T14: 78.3 | U14: <20 | V14: =T14-0.5 -> 77.8 | W14: =1-S14/G14 -> 0.794375
A15: 9 | B15: 274 | C15: 126 | D15: 124 | E15: 3.45 | F15: 23.5 | G15: 34.6 | H15: 43 | I15: 3.69 | J15: 16 | K15: 0.54 | L15: 0.42 | M15: 8.08 | N15: 30 | O15: 2.94 | P15: 6 | Q15: 0.09 | R15: 0.4 | S15: 7.86 | T15: 78.7 | U15: <20 | V15: =T15-0.5 -> 78.2 | W15: =1-S15/G15 -> 0.77283237
A16: 10 | B16: 447 | C16: 203 | D16: 122 | E16: 1.97 | F16: 23.1 | G16: 30.4 | H16: 40 | I16: 3.05 | J16: 15 | K16: 0.56 | L16: 0.53 | M16: 7.32 | N16: 30 | O16: 3 | P16: 6 | Q16: 0.16 | R16: 0.4 | S16: 6.74 | T16: 78.7 | U16: <20 | V16: =T16-0.5 -> 78.2 | W16: =1-S16/G16 -> 0.77828947
A17: 11 | B17: 180 | C17: 82.4 | D17: 98 | E17: 1.96 | F17: 20.3 | G17: 24.6 | H17: 35 | I17: 2.88 | J17: 13 | K17: 0.52 | L17: 0.43 | M17: 6.74 | N17: 25 | O17: 2.76 | P17: 5 | Q17: 0.15 | R17: 0.34 | S17: 5.9 | T17: 78.8 | U17: <20 | V17: =T17-0.5 -> 78.3 | W17: =1-S17/G17 -> 0.7601626
A18: 12 | B18: 360 | C18: 166 | D18: 102 | E18: 1.52 | F18: 20 | G18: 26.9 | H18: 29 | I18: 2.74 | J18: 14 | K18: 0.53 | L18: 0.54 | M18: 8.06 | N18: 24 | O18: 2.51 | P18: 6 | Q18: 0.16 | R18: 0.51 | S18: 7.68 | T18: 78.6 | U18: 20 | V18: =T18-0.5 -> 78.1 | W18: =1-S18/G18 -> 0.71449814
A19: 13 | B19: 290 | C19: 133 | D19: 128 | E19: 2.63 | F19: 21.9 | G19: 27.2 | H19: 28 | I19: 2.65 | J19: 16 | K19: 0.5 | L19: 0.58 | M19: 6.48 | N19: 22 | O19: 2.4 | P19: 6 | Q19: 0.09 | R19: 0.43 | S19: 6.01 | T19: 78.4 | U19: <20 | V19: =T19-0.5 -> 77.9 | W19: =1-S19/G19 -> 0.77904412
A20: 14 | B20: 257 | C20: 117 | D20: 78 | E20: 2.02 | F20: 15.9 | G20: 22.3 | H20: 28 | I20: 2.47 | J20: 12 | K20: 0.52 | L20: 0.86 | M20: 5.99 | N20: 19 | O20: 2.3 | P20: 5 | Q20: 0.15 | R20: 0.31 | S20: 5.85 | T20: 78.7 | U20: <20 | V20: =T20-0.5 -> 78.2 | W20: =1-S20/G20 -> 0.73766816
A21: 15 | B21: 162 | C21: 74.6 | D21: 90 | E21: 1.97 | F21: 18.7 | G21: 25.7 | H21: 41 | I21: 3.77 | J21: 11 | K21: 0.51 | L21: 0.5 | M21: 7.37 | N21: 18 | O21: 2.26 | P21: 5 | Q21: 0.13 | R21: 0.39 | S21: 6.87 | T21: 78.5 | U21: <20 | V21: =T21-0.5 -> 78 | W21: =1-S21/G21 -> 0.73268482
A22: 16 | B22: 252 | C22: 115 | D22: 104 | E22: 2.17 | F22: 18.6 | G22: 25.2 | H22: 30 | I22: 2.44 | J22: 12 | K22: 0.53 | L22: 0.67 | M22: 7.4 | N22: 20 | O22: 2.21 | P22: 5 | Q22: 0.18 | R22: 0.47 | S22: 6.72 | T22: 78.2 | U22: <20 | V22: =T22-0.5 -> 77.7 | W22: =1-S22/G22 -> 0.73333333
A23: 17 | B23: 222 | C23: 101 | D23: 128 | E23: 2.03 | F23: 22 | G23: 29.7 | H23: 30 | I23: 2.38 | J23: 14 | K23: 0.55 | L23: 0.53 | M23: 7.5 | N23: 23 | O23: 2.2 | P23: 5 | Q23: 0.17 | R23: 0.4 | S23: 6.62 | T23: 78.3 | U23: <20 | V23: =T23-0.5 -> 77.8 | W23: =1-S23/G23 -> 0.77710438
A24: 18 | B24: 230 | C24: 105 | D24: 156 | E24: 2.83 | F24: 22.8 | G24: 29.1 | H24: 37 | I24: 3.14 | J24: 15 | K24: 0.56 | L24: 0.43 | M24: 7.2 | N24: 27 | O24: 2.29 | P24: 6 | Q24: 0.22 | R24: 0.31 | S24: 6.13 | T24: 78.6 | U24: <20 | V24: =T24-0.5 -> 78.1 | W24: =1-S24/G24 -> 0.78934708
A25: 19 | B25: 232 | C25: 109 | D25: 136 | E25: 2.72 | F25: 24.2 | G25: 30 | H25: 26 | I25: 2.82 | J25: 12 | K25: 0.51 | L25: 0.53 | M25: 8.68 | N25: 22 | O25: 2.65 | P25: 6 | Q25: 0.17 | R25: 0.43 | S25: 8.31 | T25: 78.8 | U25: 100 | V25: =T25-0.5 -> 78.3 | W25: =1-S25/G25 -> 0.723
A26: 20 | B26: 305 | C26: 138 | D26: 106 | E26: 2.46 | F26: 27.4 | G26: 33.3 | H26: 40 | I26: 3.34 | J26: 13 | K26: 0.55 | L26: 0.75 | M26: 7.04 | N26: 26 | O26: 2.71 | P26: 5 | Q26: 0.16 | R26: 0.51 | S26: 6.87 | T26: 78.5 | U26: <20 | V26: =T26-0.5 -> 78 | W26: =1-S26/G26 -> 0.79369369
A27: 21 | B27: 330 | C27: 150 | D27: 100 | E27: 2.46 | F27: 24.9 | G27: 30.3 | H27: 40 | I27: 3.6 | J27: 13 | K27: 0.53 | L27: 0.54 | M27: 8.41 | N27: 24 | O27: 2.31 | P27: 5 | Q27: 0.19 | R27: 0.37 | S27: 7.1 | T27: 78.8 | U27: <20 | V27: =T27-0.5 -> 78.3 | W27: =1-S27/G27 -> 0.76567657
A28: 22 | B28: 336 | C28: 152 | D28: 144 | E28: 2.47 | F28: 26.3 | G28: 32.4 | H28: 31 | I28: 3.02 | J28: 14 | K28: 0.54 | L28: 0.5 | M28: 7.02 | N28: 25 | O28: 2.7 | P28: 6 | Q28: 0.17 | R28: 0.3 | S28: 6.74 | T28: 78.7 | U28: 40 | V28: =T28-0.5 -> 78.2 | W28: =1-S28/G28 -> 0.79197531
A29: 23 | B29: 181 | C29: 83.2 | D29: 88 | E29: 1.95 | F29: 24.9 | G29: 30.1 | H29: 37 | I29: 3.33 | J29: 11 | K29: 0.51 | L29: 0.7 | M29: 6.87 | N29: 27 | O29: 2.41 | P29: 5 | Q29: 0.2 | R29: 0.42 | S29: 5.06 | T29: 78.4 | U29: <20 | V29: =T29-0.5 -> 77.9 | W29: =1-S29/G29 -> 0.83189369
A30: 24 | B30: 354 | C30: 161 | D30: 112 | E30: 1.79 | F30: 19.5 | G30: 25.3 | H30: 33 | I30: 3.01 | J30: 12 | K30: 0.53 | L30: 0.64 | M30: 6.57 | N30: 31 | O30: 2.8 | P30: 6 | Q30: 0.26 | R30: 0.39 | S30: 6.1 | T30: 78.3 | U30: <20 | V30: =T30-0.5 -> 77.8 | W30: =1-S30/G30 -> 0.75889328
A31: 25 | B31: 219 | C31: 99.8 | D31: 112 | E31: 2.02 | F31: 19.2 | G31: 26.2 | H31: 41 | I31: 3.15 | J31: 16 | K31: 0.54 | L31: 0.43 | M31: 7.32 | N31: 37 | O31: 2.94 | P31: 6 | Q31: 0.21 | R31: 0.32 | S31: 6.97 | T31: 78.5 | U31: <20 | V31: =T31-0.5 -> 78 | W31: =1-S31/G31 -> 0.73396947
A32: 26 | B32: 354 | C32: 162 | D32: 148 | E32: 3.16 | F32: 28.4 | G32: 34.2 | H32: 36 | I32: 3.11 | J32: 13 | K32: 0.52 | L32: 0.76 | M32: 6.57 | N32: 29 | O32: 2.6 | P32: 5 | Q32: 0.15 | R32: 0.65 | S32: 6.06 | T32: 78.6 | U32: 20 | V32: =T32-0.5 -> 78.1 | W32: =1-S32/G32 -> 0.82280702
A33: 27 | B33: 190 | C33: 86.4 | D33: 116 | E33: 2.16 | F33: 20.4 | G33: 26.3 | H33: 41 | I33: 3.73 | J33: 12 | K33: 0.56 | L33: 0.75 | M33: 6.57 | N33: 28 | O33: 2.61 | P33: 5 | Q33: 0.16 | R33: 0.51 | S33: 6.1 | T33: 78.8 | U33: <20 | V33: =T33-0.5 -> 78.3 | W33: =1-S33/G33 -> 0.76806084
A34: 28 | B34: 356 | C34: 162 | D34: 142 | E34: 3.53 | F34: 31.2 | G34: 37.3 | H34: 40 | I34: 3.13 | J34: 17 | K34: 0.51 | L34: 0.66 | M34: 8.01 | N34: 26 | O34: 2.51 | P34: 6 | Q34: 0.21 | R34: 0.57 | S34: 7.74 | T34: 78.6 | U34: <20 | V34: =T34-0.5 -> 78.1 | W34: =1-S34/G34 -> 0.7924933
A35: 平均 | B35: =ROUND(AVERAGE(B7:B34),0) -> 283 | C35: =ROUND(AVERAGE(C7:C34),0) -> 129 | D35: =ROUND(AVERAGE(D7:D34),0) -> 121 | E35: =ROUND(AVERAGE(E7:E34),2) -> 2.6 | F35: =ROUND(AVERAGE(F7:F34),1) -> 25 | G35: =ROUND(AVERAGE(G7:G34),1) -> 31.5 | H35: =ROUND(AVERAGE(H7:H34),1) -> 32.3 | I35: =ROUND(AVERAGE(I7:I34),2) -> 2.94 | J35: =ROUND(AVERAGE(J7:J34),2) -> 13.36 | K35: =ROUND(AVERAGE(K7:K34),2) -> 0.53 | L35: =ROUND(AVERAGE(L7:L34),2) -> 0.55 | M35: =ROUND(AVERAGE(M7:M34),1) -> 7.5 | N35: =ROUND(AVERAGE(N7:N34),1) -> 24.3 | O35: =ROUND(AVERAGE(O7:O34),2) -> 2.5 | P35: =ROUND(AVERAGE(P7:P34),2) -> 5.46 | Q35: =ROUND(AVERAGE(Q7:Q34),2) -> 0.16 | R35: =ROUND(AVERAGE(R7:R34),2) -> 0.39 | S35: =ROUND(AVERAGE(S7:S34),2) -> 6.87 | T35: =ROUND(AVERAGE(T7:T34),2) -> 78.58 | U35: <20
A36: 审核： | J36: 制表： | Q36: 制表时间：2023/3/6
B38: 项目 | C38: 进水（mg/L) | D38: 最大值 | E38: 最小值（mg/L) | F38: 出水（mg/L) | G38: 最大值 | H38: 最小值（mg/L) | I38: 去除率
D39: （mg/L) | G39: （mg/L) | I39: （%）
B40: CODCr | C40: =B35 -> 283 | D40: =MAX(B7:B34) -> 447 | E40: =MIN(B7:B34) -> 162 | F40: =N35 -> 24.3 | G40: =MAX(N7:N34) -> 37 | H40: =MIN(N7:N34) -> 18 | I40: =1-F40/C40 -> 0.91413428 | K40: B/C | L40: =C41/C40 -> 0.45583039
B41: BOD5 | C41: =C35 -> 129 | D41: =MAX(C7:C34) -> 203 | E41: =MIN(C7:C34) -> 74.6 | F41: <2 | G41: <2 | H41: <2 | I41: =1-2/C41 -> 0.98449612 | K41: B/TN | L41: =C41/C45 -> 4.0952381
B42: SS | C42: =D35 -> 121 | D42: =MAX(D7:D34) -> 166 | E42: =MIN(D7:D34) -> 78 | F42: =P35 -> 5.46 | G42: =MAX(P7:P34) -> 6 | H42: =MIN(P7:P34) -> 5 | I42: =1-F42/C42 -> 0.95487603 | K42: B/TP | L42: =C41/C43 -> 49.615385
...

Sheet 设备
A1: 常州市深水江边污水处理有限公司设备运行月报表
A2: 44958
A3: 运行 工段 | B3: 设备名称 | C3: 编号 | D3: 运行 天数 | E3: 定时 | F3: 额定运行时间 | G3: 实际运行时间 | H3: 利用率 | I3: 完好率 | J3: 维修、保养情况
D5: （d） | E5: （h/d） | F5: （h） | G5: （h） | H5: % | I5: %
A6: 预 处 理 | B6: 粗格栅机 | C6: 1# | D6: 28 | E6: 2 | F6: 56 | G6: 56 | H6: 1 | I6: 1
C7: 2# | D7: 28 | E7: 2 | F7: 56 | G7: 56 | H7: 1 | I7: 1
B8: 螺旋输送机 | C8: / | D8: 28 | E8: 2 | F8: 56 | G8: 56 | H8: 1 | I8: 1
B9: 螺旋压榨机 | C9: / | D9: 28 | E9: 2 | F9: 56 | G9: 56 | H9: 1 | I9: 1
B10: 进水泵 | C10: 1# | D10: 28 | E10: 24 | F10: 672 | G10: 0 | H10: 0 | I10: 1
C11: 2# | D11: 28 | E11: 24 | F11: 672 | G11: 390 | H11: 0.58035714 | I11: 1
C12: 3# | D12: 28 | E12: 24 | F12: 672 | G12: 672 | H12: 1 | I12: 1
C13: 4# | D13: 28 | E13: 24 | F13: 672 | G13: 60 | H13: 0.089285714 | I13: 1
C14: 5# | D14: 28 | E14: 24 | F14: 672 | G14: 672 | H14: 1 | I14: 1
B15: 细格栅机 | C15: 1# | D15: 28 | E15: 2.4 | F15: 67.2 | G15: 67.2 | H15: 1 | I15: 1
C16: 2# | D16: 28 | E16: 2.4 | F16: 67.2 | G16: 67.2 | H16: 1 | I16: 1
C17: 3# | D17: 28 | E17: 2.4 | F17: 67.2 | G17: 67.2 | H17: 1 | I17: 1
C18: 4# | D18: 28 | E18: 2.4 | F18: 67.2 | G18: 0 | H18: 0 | I18: 0
C19: 5# | D19: 28 | E19: 2.4 | F19: 67.2 | G19: 67.2 | H19: 1 | I19: 1
C20: 6# | D20: 28 | E20: 2.4 | F20: 67.2 | G20: 67.2 | H20: 1 | I20: 1
B21: 螺旋输送机 | C21: 1# | D21: 28 | E21: 2 | F21: 56 | G21: 56 | H21: 1 | I21: 1
C22: 2# | D22: 28 | E22: 2 | F22: 56 | G22: 56 | H22: 1 | I22: 1
B23: 螺旋压榨机 | C23: 1# | D23: 28 | E23: 2 | F23: 56 | G23: 56 | H23: 1 | I23: 1
C24: 2# | D24: 28 | E24: 2 | F24: 56 | G24: 56 | H24: 1 | I24: 1
B25: 搅拌机 | C25: 1# | D25: 28 | E25: 24 | F25: 672 | G25: 0 | H25: 0 | I25: 0
B26: 砂水分离机 | C26: 1# | D26: 28 | E26: 0.5 | F26: 14 | G26: 14 | H26: 1 | I26: 1
B27: 搅拌机 | C27: 2# | D27: 28 | E27: 24 | F27: 672 | G27: 0 | H27: 0 | I27: 0
B28: 砂水分离机 | C28: 2# | D28: 28 | E28: 0.5 | F28: 14 | G28: 14 | H28: 1 | I28: 1
B29: 搅拌机 | C29: 3# | D29: 28 | E29: 24 | F29: 672 | G29: 672 | H29: 1 | I29: 1
B30: 砂水分离机 | C30: 3# | D30: 28 | E30: 0.5 | F30: 14 | G30: 14 | H30: 1 | I30: 1
B31: 搅拌机 | C31: 4# | D31: 28 | E31: 24 | F31: 672 | G31: 672 | H31: 1 | I31: 1
B32: 砂水分离机 | C32: 4# | D32: 28 | E32: 0.5 | F32: 14 | G32: 14 | H32: 1 | I32: 1
B33: 高压鼓风机 | C33: 1# | D33: 28 | E33: 24 | F33: 672 | G33: 163 | H33: 0.24255952 | I33: 1
C34: 2# | D34: 28 | E34: 24 | F34: 672 | G34: 68 | H34: 0.10119048 | I34: 1
C35: 3# | D35: 28 | E35: 24 | F35: 672 | G35: 540 | H35: 0.80357143 | I35: 1
C36: 4# | D36: 28 | E36: 24 | F36: 672 | G36: 613 | H36: 0.91220238 | I36: 1
C37: 5# | D37: 28 | E37: 24 | F37: 672 | G37: 8 | H37: 0.011904762 | I37: 1
A38: 审核： | E38: 制表： | H38: 制表时间：2023/3/6
A46: 常州市深水江边污水处理有限公司设备运行月报表
A47: =A2 -> 44958
A48: 运行 工段 | B48: 设备名称 | C48: 编号 | D48: 运行 天数 | E48: 定时 | F48: 额定运行时间 | G48: 实际运行时间 | H48: 利用率 | I48: 完好率 | J48: 维修、保养情况
...

Sheet 仪表
A1: 常州市深水江边污水处理有限公司污水运行月报表
D2: 44958
A3: 仪表名称 | B3: 编号 | C3: 规格型号 | D3: 安装位置 | E3: 运行情况 | F3: 标定、校准情况 | G3: 备注
A4: 一期溶氧仪 | B4: 1#（南） | C4: 美商生化T-10 | D4: 一期生反池 | E4: 正常 | F4: 校准 | G4: 2022-02-07 2022-02-14 2022-02-21 2022-02-28
B5: 2#（南） | C5: 美商生化T-10 | D5: 一期生反池 | E5: 正常 | F5: 校准 | G5: =G4 -> 2022-02-07 2022-02-14 2022-02-21 2022-02-28
B6: 1#（北） | C6: 美商生化T-10 | D6: 一期生反池 | E6: 正常 | F6: 校准 | G6: =G5 -> 2022-02-07 2022-02-14 2022-02-21 2022-02-28
B7: 2#（北） | C7: 美商生化T-10 | D7: 一期生反池 | E7: 正常 | F7: 校准 | G7: =G6 -> 2022-02-07 2022-02-14 2022-02-21 2022-02-28
A8: 一期污泥浓度计 | B8: 1#（南） | C8: E+H | D8: 一期生反池 | E8: 正常 | F8: 校准 | G8: =G7 -> 2022-02-07 2022-02-14 2022-02-21 2022-02-28
B9: 2#（南） | C9: E+H | D9: 一期生反池 | E9: 正常 | F9: 校准 | G9: =G8 -> 2022-02-07 2022-02-14 2022-02-21 2022-02-28
B10: 1#（北） | C10: E+H | D10: 一期生反池 | E10: 正常 | F10: 校准 | G10: =G9 -> 2022-02-07 2022-02-14 2022-02-21 2022-02-28
B11: 2#（北） | C11: E+H | D11: 一期生反池 | E11: 正常 | F11: 校准 | G11: =G10 -> 2022-02-07 2022-02-14 2022-02-21 2022-02-28
A12: 进水PH计 | B12: 1# | C12: 哈希 | D12: 一期旋流沉砂池 | E12: 正常 | F12: 标定 | G12: =G11 -> 2022-02-07 2022-02-14 2022-02-21 2022-02-28
A13: 二期溶氧仪 | B13: 1#（南） | C13: 哈希LDO | D13: 二期生反池 | E13: 正常 | F13: 校准 | G13: =G12 -> 2022-02-07 2022-02-14 2022-02-21 2022-02-28
B14: 2#（南） | C14: 哈希LDO | D14: 二期生反池 | E14: 正常 | F14: 校准 | G14: =G13 -> 2022-02-07 2022-02-14 2022-02-21 2022-02-28
B15: 1#（北） | C15: 哈希LDO | D15: 二期生反池 | E15: 正常 | F15: 校准 | G15: =G14 -> 2022-02-07 2022-02-14 2022-02-21 2022-02-28
B16: 2#（北） | C16: 哈希LDO | D16: 二期生反池 | E16: 正常 | F16: 校准 | G16: =G15 -> 2022-02-07 2022-02-14 2022-02-21 2022-02-28
A17: 二期污泥浓度计 | B17: 1#（南） | C17: 哈希TXPRO-2 | D17: 二期生反池 | E17: 正常 | F17: 校准 | G17: =G16 -> 2022-02-07 2022-02-14 2022-02-21 2022-02-28
B18: 2#（南） | C18: E+H | D18: 二期生反池 | E18: 正常 | F18: 校准 | G18: =G17 -> 2022-02-07 2022-02-14 2022-02-21 2022-02-28
B19: 1#（北） | C19: 哈希TXPRO-2 | D19: 二期生反池 | E19: 正常 | F19: 校准 | G19: =G18 -> 2022-02-07 2022-02-14 2022-02-21 2022-02-28
B20: 2#（北） | C20: E+H | D20: 二期生反池 | E20: 正常 | F20: 校准 | G20: =G19 -> 2022-02-07 2022-02-14 2022-02-21 2022-02-28
A21: 审核： | D21: 制表： | F21: 制表日期：2023/3/6
A25: 常州市深水江边污水处理有限公司污水运行月报表
D26: =D2 -> 44958
A27: 仪表名称 | B27: 编号 | C27: 规格型号 | D27: 安装位置 | E27: 运行情况 | F27: 标定、校准情况 | G27: 备注
A28: 一期ORP | B28: 1#（南） | C28: E+H | D28: 一期生反池 | E28: 正常 | F28: 标定 | G28: 44609
B29: 2#（北） | C29: E+H | D29: 一期生反池 | E29: 正常 | F29: 标定 | G29: =G28 -> 44609
A30: 二期ORP | B30: 1#（南） | C30: 哈希 | D30: 二期生反池 | E30: 正常 | F30: 标定 | G30: =G29 -> 44609
B31: 2#（北） | C31: 哈希 | D31: 二期生反池 | E31: 正常 | F31: 标定 | G31: =G30 -> 44609
A32: 审核： | D32: 制表： | F32: =F21 -> 制表日期：2023/3/6

Sheet 实验数据
A1: 常州市深水江边污水处理有限公司实验数据汇总表
A3: 采样地点：一期南 | E3: 采样时间：2023-2-2
A4: 硝化实验 | E4: 反硝化实验 | G4: 释磷实验
A5: 时间节点 | B5: NO3-N(mg/l) | C5: NH3-N(mg/l) | D5: PO43-(mg/l) | E5: 时间节点 | F5: NO3-N(mg/l) | G5: 时间节点 | H5: PO43-(mg/l)
A6: 0分钟 | B6: 2.19 | C6: 7.67 | D6: 0.91 | E6: 0分钟 | F6: 6.02 | G6: 0分钟 | H6: 0.57
A7: 15分钟 | B7: 2.79 | C7: 6.91 | D7: 0.8 | E7: 15分钟 | F7: 5.71 | G7: 30分钟 | H7: 0.81
A8: 30分钟 | B8: 4.08 | C8: 4.01 | D8: 0.38 | E8: 30分钟 | F8: 4.32 | G8: 60分钟 | H8: 0.91
A9: 60分钟 | B9: 6.16 | C9: 3.29 | D9: 0.2 | E9: 45分钟 | F9: 3.58 | G9: 90分钟 | H9: 1.53
A10: MLSS(mg/l) | B10: 4654 | E10: 60分钟 | F10: 2.92 | G10: MLSS(mg/l) | H10: 4252
E11: 90分钟 | F11: 2.03
E12: MLSS(mg/l) | F12: 4680
A13: 审核： | D13: 制表： | G13: 制表日期：2022/3/3
