Workbook

Sheet 处理量
A1: 常州市深水江边污水处理有限公司污水处理运行月报表
A2: 2021年 12月
A3: 日 期 | B3: 水温 | C3: 天气 | D3: 日处理 水量 （m3） | E3: 污泥量（T） | H3: 药剂量 | I3: MLSS | J3: 电耗 | K3: 混凝剂 | L3: 絮凝剂 阴离子 （kg） | M3: 盐酸 | N3: 氯酸钠 | O3: 乙酸（吨） | Q3: 回用水 （m3） | R3: 实际水量（m3） | T3: 费用统计 | U3: 成本分析用 | W3: 单价 | X3: 单耗 | Y3: 之前价 | Z3: 最新时间 | AD3: PAC | AE3: PAM阳 | AF3: PAM阴 | AG3: HCL | AH3: NACLO3 | AI3: 合计 | AK3: 干泥量 | AL3: 单耗
B4: 度 | C4: 状况 | E4: 国电 | F4: 英科环境 | G4: 其他 | H4: （Kg） | I4: （mg/l） | J4: ( 度 ) | K4: （Kg） | M4: （Kg） | N4: （Kg） | O4: 缺氧段 | P4: 提标段 | T4: 电量 | U4: =ROUND(J37*W4,2) -> 1018666.1 | W4: 0.67645 | X4: =J36/R36 -> 0.314066 | Y4: 0.608 | Z4: 44565 | AB4: 污泥量合计
A5: 1 | B5: 22.6 | C5: 晴 | D5: 187715 | E5: 91.24 | F5: 0 | G5: 0 | H5: 175 | I5: 4916 | J5: 54000 | K5: 6948 | L5: 36 | M5: 3621 | N5: 1248 | O5: 4.02 | P5: 0 | Q5: 5611 | R5: =D5-Q5 -> 182104 | T5: 聚丙烯酰阳离子 | U5: =H37*W5/1000 -> 126180 | W5: 28040 | X5: =H36/R36*1000 -> 0.93850655 | Y5: 28150 | Z5: 44287 | AB5: =E5+F5+G5 -> 91.24 | AD5: =$W$9*K5/1000/R5 -> 0.0132776 | AE5: =$W$5*H5/1000/R5 -> 0.026946141 | AF5: =$W$6*L5/1000/R5 -> 0.002055968 | AG5: =$W$7*M5/1000/R5 -> 0.008550224 | AH5: =$W$8*N5/1000/R5 -> 0.06152827 | AI5: =AD5+AE5+AF5+AG5+AH5 -> 0.1123582 | AK5: =AB5*(100-进出水!T7)/100 -> 20.0728 | AL5: =H5/AK5 -> 8.7182655
A6: 2 | B6: 22.4 | C6: 晴 | D6: 188715 | E6: 156.62 | F6: 0 | G6: 0 | H6: 175 | I6: 5288 | J6: 53800 | K6: 6780 | L6: 41 | M6: 3550 | N6: 1152 | O6: 3.6 | P6: 0 | Q6: 5564 | R6: =D6-Q6 -> 183151 | T6: 聚丙烯酰阴离子 | U6: =L37*W6/1000 -> 7238.4 | V6: =U5+U6 -> 133418.4 | W6: 10400 | X6: =L36/R36*1000 -> 0.14515568 | Y6: 5784.76 | Z6: 44256 | AB6: =E6+F6+G6 -> 156.62 | AD6: =$W$9*K6/1000/R6 -> 0.012882485 | AE6: =$W$5*H6/1000/R6 -> 0.026792101 | AF6: =$W$6*L6/1000/R6 -> 0.0023281336 | AG6: =$W$7*M6/1000/R6 -> 0.0083346528 | AH6: =$W$8*N6/1000/R6 -> 0.05647065 | AI6: =AD6+AE6+AF6+AG6+AH6 -> 0.10680802 | AK6: =AB6*(100-进出水!T8)/100 -> 35.2395 | AL6: =H6/AK6 -> 4.9660182
A7: 3 | B7: 23 | C7: 晴 | D7: 125466 | E7: 194.16 | F7: 19.4 | G7: 0 | H7: 200 | I7: 5100 | J7: 44400 | K7: 6204 | L7: 37 | M7: 2982 | N7: 1008 | O7: 3.5 | P7: 0 | Q7: 5508 | R7: =D7-Q7 -> 119958 | T7: 工业盐酸 | U7: =M37*W7/1000 -> 43749.49 | W7: 430 | X7: =M36/R36*1000 -> 21.219216 | Y7: 182 | Z7: 44228 | AB7: =E7+F7+G7 -> 213.56 | AD7: =$W$9*K7/1000/R7 -> 0.017997899 | AE7: =$W$5*H7/1000/R7 -> 0.046749696 | AF7: =$W$6*L7/1000/R7 -> 0.0032077894 | AG7: =$W$7*M7/1000/R7 -> 0.010689241 | AH7: =$W$8*N7/1000/R7 -> 0.075441605 | AI7: =AD7+AE7+AF7+AG7+AH7 -> 0.15408623 | AK7: =AB7*(100-进出水!T9)/100 -> 47.41032 | AL7: =H7/AK7 -> 4.2184908
A8: 4 | B8: 23.2 | C8: 晴 | D8: 189096 | E8: 178.48 | F8: 0 | G8: 0 | H8: 150 | I8: 5522 | J8: 54200 | K8: 6096 | L8: 37 | M8: 4970 | N8: 1728 | O8: 2.59 | P8: 0 | Q8: 5677 | R8: =D8-Q8 -> 183419 | T8: 工业氯酸钠 | U8: =N37*W8/1000 -> 317605.73 | V8: =U7+U8 -> 361355.22 | W8: 8978 | X8: =N36/R36*1000 -> 7.3779128 | Y8: 6443 | Z8: 44565 | AB8: =E8+F8+G8 -> 178.48 | AD8: =$W$9*K8/1000/R8 -> 0.011565912 | AE8: =$W$5*H8/1000/R8 -> 0.022931103 | AF8: =$W$6*L8/1000/R8 -> 0.0020979288 | AG8: =$W$7*M8/1000/R8 -> 0.011651465 | AH8: =$W$8*N8/1000/R8 -> 0.084582208 | AI8: =AD8+AE8+AF8+AG8+AH8 -> 0.13282862 | AK8: =AB8*(100-进出水!T10)/100 -> 40.33648 | AL8: =H8/AK8 -> 3.7187181
A9: 5 | B9: 21.6 | C9: 晴 | D9: 185698 | E9: 145.5 | F9: 0 | G9: 0 | H9: 100 | I9: 5172 | J9: 55200 | K9: 10812 | L9: 34 | M9: 3408 | N9: 1128 | O9: 2.92 | P9: 0 | Q9: 5549 | R9: =D9-Q9 -> 180149 | T9: 混凝药剂 | U9: =K37*W9/1000 -> 51778.224 | W9: 348 | X9: =K36/R36*1000 -> 31.030781 | Y9: 370 | Z9: 44228 | AB9: =E9+F9+G9 -> 145.5 | AD9: =$W$9*K9/1000/R9 -> 0.020885911 | AE9: =$W$5*H9/1000/R9 -> 0.015564894 | AF9: =$W$6*L9/1000/R9 -> 0.0019628197 | AG9: =$W$7*M9/1000/R9 -> 0.0081345997 | AH9: =$W$8*N9/1000/R9 -> 0.056215599 | AI9: =AD9+AE9+AF9+AG9+AH9 -> 0.10276382 | AK9: =AB9*(100-进出水!T11)/100 -> 32.301 | AL9: =H9/AK9 -> 3.0958794
A10: 6 | B10: 22.4 | C10: 晴 | D10: 189333 | E10: 106.58 | F10: 0 | G10: 0 | H10: 150 | I10: 5118 | J10: 53400 | K10: 0 | L10: 0 | M10: 4331 | N10: 1440 | O10: 2.89 | P10: 0 | Q10: 5613 | R10: =D10-Q10 -> 183720 | T10: 污泥外运 | U10: =T18 -> 93141.19 | V10: 计算见下表 | AB10: =E10+F10+G10 -> 106.58 | AD10: =$W$9*K10/1000/R10 -> 0 | AE10: =$W$5*H10/1000/R10 -> 0.022893534 | AF10: =$W$6*L10/1000/R10 -> 0 | AG10: =$W$7*M10/1000/R10 -> 0.010136784 | AH10: =$W$8*N10/1000/R10 -> 0.070369693 | AI10: =AD10+AE10+AF10+AG10+AH10 -> 0.10340001 | AK10: =AB10*(100-进出水!T12)/100 -> 23.55418 | AL10: =H10/AK10 -> 6.3682964
A11: 7 | B11: 21.1 | C11: 晴 | D11: 188970 | E11: 143.56 | F11: 0 | G11: 0 | H11: 225 | I11: 4996 | J11: 52500 | K11: 0 | L11: 0 | M11: 4260 | N11: 1488 | O11: 3.24 | P11: 0 | Q11: 5581 | R11: =D11-Q11 -> 183389 | T11: 自来水 | U11: =汇总!J5*4.21 -> 21668.87 | W11: 4.21 | AB11: =E11+F11+G11 -> 143.56 | AD11: =$W$9*K11/1000/R11 -> 0 | AE11: =$W$5*H11/1000/R11 -> 0.034402281 | AF11: =$W$6*L11/1000/R11 -> 0 | AG11: =$W$7*M11/1000/R11 -> 0.0099886035 | AH11: =$W$8*N11/1000/R11 -> 0.072846594 | AI11: =AD11+AE11+AF11+AG11+AH11 -> 0.11723748 | AK11: =AB11*(100-进出水!T13)/100 -> 32.01388 | AL11: =H11/AK11 -> 7.0282015
A12: 8 | B12: 21.5 | C12: 晴 | D12: 174610 | E12: 217.74 | F12: 0 | G12: 0 | H12: 200 | I12: 3924 | J12: 51500 | K12: 0 | L12: 0 | M12: 3905 | N12: 1344 | O12: 3.34 | P12: 0 | Q12: 5577 | R12: =D12-Q12 -> 169033 | AB12: =E12+F12+G12 -> 217.74 | AD12: =$W$9*K12/1000/R12 -> 0 | AE12: =$W$5*H12/1000/R12 -> 0.033176954 | AF12: =$W$6*L12/1000/R12 -> 0 | AG12: =$W$7*M12/1000/R12 -> 0.0099338591 | AH12: =$W$8*N12/1000/R12 -> 0.071385067 | AI12: =AD12+AE12+AF12+AG12+AH12 -> 0.11449588 | AK12: =AB12*(100-进出水!T14)/100 -> 48.55602 | AL12: =H12/AK12 -> 4.1189537
A13: 9 | B13: 20.5 | C13: 阴 | D13: 192036 | E13: 176.98 | F13: 0 | G13: 37.92 | H13: 200 | I13: 4656 | J13: 53100 | K13: 4332 | L13: 29 | M13: 3905 | N13: 1344 | O13: 3.21 | P13: 0 | Q13: 5588 | R13: =D13-Q13 -> 186448 | U13: =U14/R37 -> 0.11398722 | AB13: =E13+F13+G13 -> 214.9 | AD13: =$W$9*K13/1000/R13 -> 0.0080855574 | AE13: =$W$5*H13/1000/R13 -> 0.030078091 | AF13: =$W$6*L13/1000/R13 -> 0.0016176092 | AG13: =$W$7*M13/1000/R13 -> 0.0090059963 | AH13: =$W$8*N13/1000/R13 -> 0.064717412 | AI13: =AD13+AE13+AF13+AG13+AH13 -> 0.11350467 | AK13: =AB13*(100-进出水!T15)/100 -> 47.9227 | AL13: =H13/AK13 -> 4.1733876
A14: 10 | B14: 21.2 | C14: 晴 | D14: 172989 | E14: 122.62 | F14: 0 | G14: 56.88 | H14: 175 | I14: 4962 | J14: 50600 | K14: 6264 | L14: 43 | M14: 2343 | N14: 840 | O14: 3.15 | P14: 0 | Q14: 5545 | R14: =D14-Q14 -> 167444 | T14: 总药剂 | U14: =U5+U6+U7+U8+U9 -> 546551.84 | V14: 除磷药剂 | W14: =U6+U9 -> 59016.624 | AB14: =E14+F14+G14 -> 179.5 | AD14: =$W$9*K14/1000/R14 -> 0.013018514 | AE14: =$W$5*H14/1000/R14 -> 0.02930532 | AF14: =$W$6*L14/1000/R14 -> 0.0026707437 | AG14: =$W$7*M14/1000/R14 -> 0.0060168773 | AH14: =$W$8*N14/1000/R14 -> 0.045039058 | AI14: =AD14+AE14+AF14+AG14+AH14 -> 0.096050512 | AK14: =AB14*(100-进出水!T16)/100 -> 40.567 | AL14: =H14/AK14 -> 4.3138512
A15: 11 | B15: 21 | C15: 晴 | D15: 161629 | E15: 199.36 | F15: 0 | G15: 18.34 | H15: 175 | I15: 4276 | J15: 49800 | K15: 5004 | L15: 38 | M15: 2272 | N15: 816 | O15: 3.22 | P15: 0 | Q15: 5477 | R15: =D15-Q15 -> 156152 | T15: 总泥量 | U15: 英科（吨） | V15: 国电（吨） | W15: 外运（吨） | AB15: =E15+F15+G15 -> 217.7 | AD15: =$W$9*K15/1000/R15 -> 0.011151903 | AE15: =$W$5*H15/1000/R15 -> 0.031424509 | AF15: =$W$6*L15/1000/R15 -> 0.0025308674 | AG15: =$W$7*M15/1000/R15 -> 0.0062564681 | AH15: =$W$8*N15/1000/R15 -> 0.046916133 | AI15: =AD15+AE15+AF15+AG15+AH15 -> 0.098279881 | AK15: =AB15*(100-进出水!T17)/100 -> 49.6356 | AL15: =H15/AK15 -> 3.5256953
A16: 12 | B16: 20.5 | C16: 雨 | D16: 164341 | E16: 0 | F16: 140.08 | G16: 18.4 | H16: 175 | I16: 4512 | J16: 49200 | K16: 6336 | L16: 54 | M16: 3053 | N16: 1056 | O16: 3.12 | P16: 0 | Q16: 5718 | R16: =D16-Q16 -> 158623 | T16: =U16+V16+W16 -> 4306.68 | U16: =F37 -> 831.58 | V16: =E37 -> 3253.56 | W16: =G37 -> 221.54 | AB16: =E16+F16+G16 -> 158.48 | AD16: =$W$9*K16/1000/R16 -> 0.013900431 | AE16: =$W$5*H16/1000/R16 -> 0.030934984 | AF16: =$W$6*L16/1000/R16 -> 0.0035404702 | AG16: =$W$7*M16/1000/R16 -> 0.0082761642 | AH16: =$W$8*N16/1000/R16 -> 0.059769189 | AI16: =AD16+AE16+AF16+AG16+AH16 -> 0.11642124 | AK16: =AB16*(100-进出水!T18)/100 -> 35.658 | AL16: =H16/AK16 -> 4.9077346
A17: 13 | B17: 23.2 | C17: 晴 | D17: 156527 | E17: 174.26 | F17: 0 | G17: 0 | H17: 200 | I17: 4954 | J17: 47800 | K17: 6420 | L17: 55 | M17: 4615 | N17: 1584 | O17: 2.98 | P17: 0 | Q17: 5596 | R17: =D17-Q17 -> 150931 | T17: 江边费用 | U17: 22.8 | V17: 22.8 | AB17: =E17+F17+G17 -> 174.26 | AD17: =$W$9*K17/1000/R17 -> 0.014802526 | AE17: =$W$5*H17/1000/R17 -> 0.037156051 | AF17: =$W$6*L17/1000/R17 -> 0.0037898112 | AG17: =$W$7*M17/1000/R17 -> 0.013148061 | AH17: =$W$8*N17/1000/R17 -> 0.09422287 | AI17: =AD17+AE17+AF17+AG17+AH17 -> 0.16311932 | AK17: =AB17*(100-进出水!T19)/100 -> 38.3372 | AL17: =H17/AK17 -> 5.2168651
A18: 14 | B18: 21.2 | C18: 晴 | D18: 144161 | E18: 209.78 | F18: 0 | G18: 0 | H18: 175 | I18: 4326 | J18: 44400 | K18: 1092 | L18: 8 | M18: 3195 | N18: 1104 | O18: 3.35 | P18: 0 | Q18: 5547 | R18: =D18-Q18 -> 138614 | T18: =U18+V18 -> 93141.19 | U18: =ROUND(U16*U17,2) -> 18960.02 | V18: =ROUND(V16*V17,2) -> 74181.17 | AB18: =E18+F18+G18 -> 209.78 | AD18: =$W$9*K18/1000/R18 -> 0.0027415413 | AE18: =$W$5*H18/1000/R18 -> 0.035400465 | AF18: =$W$6*L18/1000/R18 -> 0.00060022797 | AG18: =$W$7*M18/1000/R18 -> 0.0099113365 | AH18: =$W$8*N18/1000/R18 -> 0.071505851 | AI18: =AD18+AE18+AF18+AG18+AH18 -> 0.12015942 | AK18: =AB18*(100-进出水!T20)/100 -> 46.99072 | AL18: =H18/AK18 -> 3.7241396
A19: 15 | B19: 20.5 | C19: 阴 | D19: 158758 | E19: 161.72 | F19: 0 | G19: 0 | H19: 200 | I19: 4720 | J19: 47600 | K19: 3048 | L19: 25 | M19: 3053 | N19: 1080 | O19: 3.45 | P19: 0 | Q19: 5579 | R19: =D19-Q19 -> 153179 | T19: 排水承担 | V19: 0 | AB19: =E19+F19+G19 -> 161.72 | AD19: =$W$9*K19/1000/R19 -> 0.0069246045 | AE19: =$W$5*H19/1000/R19 -> 0.036610763 | AF19: =$W$6*L19/1000/R19 -> 0.0016973606 | AG19: =$W$7*M19/1000/R19 -> 0.0085703001 | AH19: =$W$8*N19/1000/R19 -> 0.063300061 | AI19: =AD19+AE19+AF19+AG19+AH19 -> 0.11710309 | AK19: =AB19*(100-进出水!T21)/100 -> 35.74012 | AL19: =H19/AK19 -> 5.5959521
A20: 16 | B20: 20.8 | C20: 阴 | D20: 140286 | E20: 85.72 | F20: 105.4 | G20: 0 | H20: 175 | I20: 4418 | J20: 45500 | K20: 6048 | L20: 55 | M20: 3479 | N20: 1200 | O20: 3.54 | P20: 0 | Q20: 5562 | R20: =D20-Q20 -> 134724 | T20: =U20+V20 -> 0 | V20: =ROUND(V16*V19,2) -> 0 | AB20: =E20+F20+G20 -> 191.12 | AD20: =$W$9*K20/1000/R20 -> 0.015622339 | AE20: =$W$5*H20/1000/R20 -> 0.036422612 | AF20: =$W$6*L20/1000/R20 -> 0.0042457172 | AG20: =$W$7*M20/1000/R20 -> 0.011103961 | AH20: =$W$8*N20/1000/R20 -> 0.079967934 | AI20: =AD20+AE20+AF20+AG20+AH20 -> 0.14736256 | AK20: =AB20*(100-进出水!T22)/100 -> 43.38424 | AL20: =H20/AK20 -> 4.0337228
A21: 17 | B21: 22.1 | C21: 晴 | D21: 161859 | E21: 192.4 | F21: 0 | G21: 0 | H21: 175 | I21: 4596 | J21: 49400 | K21: 5784 | L21: 10 | M21: 2698 | N21: 960 | O21: 3.62 | P21: 0 | Q21: 5562 | R21: =D21-Q21 -> 156297 | T21: 总运费 | U21: 总单价 | V21: =V17+V19 -> 22.8 | W21: 核对 | AB21: =E21+F21+G21 -> 192.4 | AD21: =$W$9*K21/1000/R21 -> 0.012878251 | AE21: =$W$5*H21/1000/R21 -> 0.031395356 | AF21: =$W$6*L21/1000/R21 -> 0.00066539985 | AG21: =$W$7*M21/1000/R21 -> 0.0074226633 | AH21: =$W$8*N21/1000/R21 -> 0.055144245 | AI21: =AD21+AE21+AF21+AG21+AH21 -> 0.10750592 | AK21: =AB21*(100-进出水!T23)/100 -> 43.0976 | AL21: =H21/AK21 -> 4.0605509
A22: 18 | B22: 22.1 | C22: 晴 | D22: 147016 | E22: 153.88 | F22: 0 | G22: 0 | H22: 175 | I22: 4112 | J22: 46500 | K22: 8712 | L22: 77 | M22: 1846 | N22: 672 | O22: 3.68 | P22: 0 | Q22: 5575 | R22: =D22-Q22 -> 141441 | T22: =T18+T20 -> 93141.19 | W22: =T16-E37-F37-G37 -> 0 | AB22: =E22+F22+G22 -> 153.88 | AD22: =$W$9*K22/1000/R22 -> 0.021434916 | AE22: =$W$5*H22/1000/R22 -> 0.034692911 | AF22: =$W$6*L22/1000/R22 -> 0.0056617247 | AG22: =$W$7*M22/1000/R22 -> 0.0056120927 | AH22: =$W$8*N22/1000/R22 -> 0.042655355 | AI22: =AD22+AE22+AF22+AG22+AH22 -> 0.110057 | AK22: =AB22*(100-进出水!T24)/100 -> 33.69972 | AL22: =H22/AK22 -> 5.1929215
A23: 19 | B23: 21.9 | C23: 晴 | D23: 151275 | E23: 211.64 | F23: 0 | G23: 0 | H23: 175 | I23: 4542 | J23: 46600 | K23: 7788 | L23: 25 | M23: 2840 | N23: 1032 | O23: 3.71 | P23: 0 | Q23: 5577 | R23: =D23-Q23 -> 145698 | AB23: =E23+F23+G23 -> 211.64 | AD23: =$W$9*K23/1000/R23 -> 0.018601655 | AE23: =$W$5*H23/1000/R23 -> 0.033679254 | AF23: =$W$6*L23/1000/R23 -> 0.0017845132 | AG23: =$W$7*M23/1000/R23 -> 0.0083817211 | AH23: =$W$8*N23/1000/R23 -> 0.063592472 | AI23: =AD23+AE23+AF23+AG23+AH23 -> 0.12603962 | AK23: =AB23*(100-进出水!T25)/100 -> 45.71424 | AL23: =H23/AK23 -> 3.8281288
A24: 20 | B24: 22 | C24: 晴 | D24: 139042 | E24: 175.6 | F24: 0 | G24: 0 | H24: 175 | I24: 4410 | J24: 47300 | K24: 12600 | L24: 42 | M24: 4189 | N24: 1440 | O24: 3.85 | P24: 0 | Q24: 5561 | R24: =D24-Q24 -> 133481 | T24: 絮凝剂 | U24: 用量（kg） | V24: =H37 -> 4500 | W24: =L37 -> 696 | AB24: =E24+F24+G24 -> 175.6 | AD24: =$W$9*K24/1000/R24 -> 0.032849619 | AE24: =$W$5*H24/1000/R24 -> 0.036761786 | AF24: =$W$6*L24/1000/R24 -> 0.0032723758 | AG24: =$W$7*M24/1000/R24 -> 0.01349458 | AH24: =$W$8*N24/1000/R24 -> 0.096855133 | AI24: =AD24+AE24+AF24+AG24+AH24 -> 0.18323349 | AK24: =AB24*(100-进出水!T26)/100 -> 38.9832 | AL24: =H24/AK24 -> 4.4891133
A25: 21 | B25: 21.8 | C25: 晴 | D25: 131241 | E25: 86.7 | F25: 69.08 | G25: 0 | H25: 125 | I25: 4506 | J25: 40900 | K25: 2796 | L25: 9 | M25: 3905 | N25: 1392 | O25: 3.88 | P25: 0 | Q25: 5583 | R25: =D25-Q25 -> 125658 | U25: 单耗（kg/T） | V25: =汇总!F6 -> 4.6919102 | W25: =W24/R37*1000 -> 0.14515568 | AB25: =E25+F25+G25 -> 155.78 | AD25: =$W$9*K25/1000/R25 -> 0.0077433033 | AE25: =$W$5*H25/1000/R25 -> 0.02789317 | AF25: =$W$6*L25/1000/R25 -> 0.00074487896 | AG25: =$W$7*M25/1000/R25 -> 0.013362858 | AH25: =$W$8*N25/1000/R25 -> 0.099455474 | AI25: =AD25+AE25+AF25+AG25+AH25 -> 0.14919968 | AK25: =AB25*(100-进出水!T27)/100 -> 34.89472 | AL25: =H25/AK25 -> 3.5822038
A26: 22 | B26: 21.6 | C26: 晴 | D26: 136991 | E26: 0 | F26: 86.58 | G26: 0 | H26: 0 | I26: 4816 | J26: 42800 | K26: 15324 | L26: 41 | M26: 3053 | N26: 1080 | O26: 4.12 | P26: 0 | Q26: 5546 | R26: =D26-Q26 -> 131445 | T26: 混凝剂 | U26: 用量（kg） | V26: =K37 -> 148788 | AB26: =E26+F26+G26 -> 86.58 | AD26: =$W$9*K26/1000/R26 -> 0.040570216 | AE26: =$W$5*H26/1000/R26 -> 0 | AF26: =$W$6*L26/1000/R26 -> 0.0032439423 | AG26: =$W$7*M26/1000/R26 -> 0.0099873711 | AH26: =$W$8*N26/1000/R26 -> 0.073766518 | AI26: =AD26+AE26+AF26+AG26+AH26 -> 0.12756805 | AK26: =AB26*(100-进出水!T28)/100 -> 19.56708 | AL26: =H26/AK26 -> 0
A27: 23 | B27: 21 | C27: 晴 | D27: 155044 | E27: 0 | F27: 0 | G27: 0 | H27: 0 | I27: 4594 | J27: 44900 | K27: 6228 | L27: 0 | M27: 2982 | N27: 1032 | O27: 4.31 | P27: 0 | Q27: 5460 | R27: =D27-Q27 -> 149584 | U27: 单耗（g/m3） | V27: =ROUND(K37/R37*1000,1) -> 31 | AB27: =E27+F27+G27 -> 0 | AD27: =$W$9*K27/1000/R27 -> 0.014489143 | AE27: =$W$5*H27/1000/R27 -> 0 | AF27: =$W$6*L27/1000/R27 -> 0 | AG27: =$W$7*M27/1000/R27 -> 0.0085721735 | AH27: =$W$8*N27/1000/R27 -> 0.061940421 | AI27: =AD27+AE27+AF27+AG27+AH27 -> 0.085001738 | AK27: =AB27*(100-进出水!T29)/100 -> 0 | AL27: =H27/AK27 -> #DIV/0!
A28: 24 | B28: 21.3 | C28: 阴 | D28: 153726 | E28: 0 | F28: 0 | G28: 0 | H28: 100 | I28: 4734 | J28: 47900 | K28: 6036 | L28: 0 | M28: 1988 | N28: 720 | O28: 4.35 | P28: 0 | Q28: 5552 | R28: =D28-Q28 -> 148174 | T28: 盐酸 | U28: 用量（kg） | V28: =M37 -> 101743 | AB28: =E28+F28+G28 -> 0 | AD28: =$W$9*K28/1000/R28 -> 0.01417609 | AE28: =$W$5*H28/1000/R28 -> 0.018923698 | AF28: =$W$6*L28/1000/R28 -> 0 | AG28: =$W$7*M28/1000/R28 -> 0.0057691633 | AH28: =$W$8*N28/1000/R28 -> 0.043625467 | AI28: =AD28+AE28+AF28+AG28+AH28 -> 0.082494419 | AK28: =AB28*(100-进出水!T30)/100 -> 0 | AL28: =H28/AK28 -> #DIV/0!
A29: 25 | B29: 20.6 | C29: 阴 | D29: 151047 | E29: 69.02 | F29: 0 | G29: 0 | H29: 100 | I29: 4118 | J29: 46900 | K29: 6036 | L29: 0 | M29: 2059 | N29: 744 | O29: 4.43 | P29: 0 | Q29: 5487 | R29: =D29-Q29 -> 145560 | U29: 单耗（g/m3） | V29: =ROUND(M37/R37*1000,1) -> 21.2 | AB29: =E29+F29+G29 -> 69.02 | AD29: =$W$9*K29/1000/R29 -> 0.014430668 | AE29: =$W$5*H29/1000/R29 -> 0.019263534 | AF29: =$W$6*L29/1000/R29 -> 0 | AG29: =$W$7*M29/1000/R29 -> 0.0060825089 | AH29: =$W$8*N29/1000/R29 -> 0.0458892 | AI29: =AD29+AE29+AF29+AG29+AH29 -> 0.085665911 | AK29: =AB29*(100-进出水!T31)/100 -> 14.97734 | AL29: =H29/AK29 -> 6.676753
A30: 26 | B30: 19.9 | C30: 晴 | D30: 144920 | E30: 0 | F30: 71.84 | G30: 0 | H30: 100 | I30: 4268 | J30: 48700 | K30: 2100 | L30: 0 | M30: 2769 | N30: 984 | O30: 4.51 | P30: 0 | Q30: 5645 | R30: =D30-Q30 -> 139275 | T30: 氯酸钠 | U30: 用量（kg） | V30: =处理量!N37 -> 35376 | AB30: =E30+F30+G30 -> 71.84 | AD30: =$W$9*K30/1000/R30 -> 0.0052471729 | AE30: =$W$5*H30/1000/R30 -> 0.020132831 | AF30: =$W$6*L30/1000/R30 -> 0 | AG30: =$W$7*M30/1000/R30 -> 0.0085490576 | AH30: =$W$8*N30/1000/R30 -> 0.063430996 | AI30: =AD30+AE30+AF30+AG30+AH30 -> 0.097360057 | AK30: =AB30*(100-进出水!T32)/100 -> 16.02032 | AL30: =H30/AK30 -> 6.2420726
A31: 27 | B31: 19.2 | C31: 晴 | D31: 154083 | E31: 0 | F31: 106.72 | G31: 0 | H31: 125 | I31: 4526 | J31: 46200 | K31: 0 | L31: 0 | M31: 3621 | N31: 1272 | O31: 4.55 | P31: 0 | Q31: 5586 | R31: =D31-Q31 -> 148497 | U31: 单耗（g/m3） | V31: =ROUND(N37/R37*1000,2) -> 7.38 | AB31: =E31+F31+G31 -> 106.72 | AD31: =$W$9*K31/1000/R31 -> 0 | AE31: =$W$5*H31/1000/R31 -> 0.02360317 | AF31: =$W$6*L31/1000/R31 -> 0 | AG31: =$W$7*M31/1000/R31 -> 0.010485262 | AH31: =$W$8*N31/1000/R31 -> 0.076904018 | AI31: =AD31+AE31+AF31+AG31+AH31 -> 0.11099245 | AK31: =AB31*(100-进出水!T33)/100 -> 23.69184 | AL31: =H31/AK31 -> 5.2760782
A32: 28 | B32: 19.5 | C32: 晴 | D32: 148275 | E32: 0 | F32: 99.92 | G32: 0 | H32: 100 | I32: 4152 | J32: 45600 | K32: 0 | L32: 0 | M32: 3550 | N32: 1248 | O32: 4.45 | P32: 0 | Q32: 5574 | R32: =D32-Q32 -> 142701 | T32: 乙酸 | U32: 用量（T） | V32: =O37 -> 115.21 | AB32: =E32+F32+G32 -> 99.92 | AD32: =$W$9*K32/1000/R32 -> 0 | AE32: =$W$5*H32/1000/R32 -> 0.019649477 | AF32: =$W$6*L32/1000/R32 -> 0 | AG32: =$W$7*M32/1000/R32 -> 0.010697192 | AH32: =$W$8*N32/1000/R32 -> 0.078517628 | AI32: =AD32+AE32+AF32+AG32+AH32 -> 0.1088643 | AK32: =AB32*(100-进出水!T34)/100 -> 22.68184 | AL32: =H32/AK32 -> 4.4088134
A33: 29 | B33: 19.3 | C33: 晴 | D33: 167621 | E33: 0 | F33: 80.8 | G33: 0 | H33: 100 | I33: 4330 | J33: 50900 | K33: 0 | L33: 0 | M33: 3195 | N33: 1104 | O33: 4.56 | P33: 0 | Q33: 5525 | R33: =D33-Q33 -> 162096 | U33: 单耗（g/m3） | V33: =ROUND(V32/R37*1000000,2) -> 24.03 | AB33: =E33+F33+G33 -> 80.8 | AD33: =$W$9*K33/1000/R33 -> 0 | AE33: =$W$5*H33/1000/R33 -> 0.017298391 | AF33: =$W$6*L33/1000/R33 -> 0 | AG33: =$W$7*M33/1000/R33 -> 0.008475533 | AH33: =$W$8*N33/1000/R33 -> 0.061147172 | AI33: =AD33+AE33+AF33+AG33+AH33 -> 0.086921096 | AK33: =AB33*(100-进出水!T35)/100 -> 17.6144 | AL33: =H33/AK33 -> 5.6771732
A34: 30 | B34: 19.5 | C34: 晴 | D34: 153109 | E34: 0 | F34: 33.48 | G34: 30 | H34: 100 | I34: 4792 | J34: 47600 | K34: 0 | L34: 0 | M34: 3408 | N34: 1176 | O34: 4.57 | P34: 0 | Q34: 5655 | R34: =D34-Q34 -> 147454 | AB34: =E34+F34+G34 -> 63.48 | AD34: =$W$9*K34/1000/R34 -> 0 | AE34: =$W$5*H34/1000/R34 -> 0.0190161 | AF34: =$W$6*L34/1000/R34 -> 0 | AG34: =$W$7*M34/1000/R34 -> 0.0099382858 | AH34: =$W$8*N34/1000/R34 -> 0.071602859 | AI34: =AD34+AE34+AF34+AG34+AH34 -> 0.10055724 | AK34: =AB34*(100-进出水!T36)/100 -> 13.9656 | AL34: =H34/AK34 -> 7.1604514
A35: 31 | B35: 18.8 | C35: 晴 | D35: 151950 | E35: 0 | F35: 18.28 | G35: 60 | H35: 100 | I35: 4610 | J35: 46700 | K35: 0 | L35: 0 | M35: 2698 | N35: 960 | O35: 4.5 | P35: 0 | Q35: 5497 | R35: =D35-Q35 -> 146453 | AB35: =E35+F35+G35 -> 78.28 | AD35: =$W$9*K35/1000/R35 -> 0 | AE35: =$W$5*H35/1000/R35 -> 0.019146074 | AF35: =$W$6*L35/1000/R35 -> 0 | AG35: =$W$7*M35/1000/R35 -> 0.0079215858 | AH35: =$W$8*N35/1000/R35 -> 0.058850826 | AI35: =AD35+AE35+AF35+AG35+AH35 -> 0.085918486 | AK35: =AB35*(100-进出水!T37)/100 -> 17.69128 | AL35: =H35/AK35 -> 5.6525022
A36: 平均 | B36: =AVERAGE(B5:B35) -> 21.203226 | C36: / | D36: =AVERAGE(D5:D35) -> 160242.87 | E36: =AVERAGE(E5:E35) -> 104.95355 | F36: =AVERAGE(F5:F35) -> 26.825161 | G36: =AVERAGE(G5:G35) -> 7.1464516 | H36: =AVERAGE(H5:H35) -> 145.16129 | I36: =AVERAGE(I5:I35) -> 4644.0645 | J36: =AVERAGE(J5:J35) -> 48577.419 | K36: =AVERAGE(K5:K35) -> 4799.6129 | ... Q36: =AVERAGE(Q5:Q35) -> 5570.2258 | R36: =D36-Q36 -> 154672.65
A37: 合计 | B37: / | C37: / | D37: =SUM(D5:D35) -> 4967529 | E37: =SUM(E5:E35) -> 3253.56 | F37: =SUM(F5:F35) -> 831.58 | G37: =SUM(G5:G35) -> 221.54 | H37: =SUM(H5:H35) -> 4500 | I37: / | J37: =SUM(J5:J35) -> 1505900 | K37: =SUM(K5:K35) -> 148788 | L37: =SUM(L5:L35) -> 696 | M37: =SUM(M5:M35) -> 101743 | N37: =SUM(N5:N35) -> 35376 | O37: =SUM(O5:O35) -> 115.21 | P37: =SUM(P5:P35) -> 0 | Q37: =SUM(Q5:Q35) -> 172677 | R37: =SUM(R5:R35) -> 4794852 | AB37: =SUM(AB5:AB36) -> 4306.68
A38: 审核： | I38: 制表： | Q38: 制表时间: | R38: 44565
M39: =M37*0.31 -> 31540.33
Q40: 最大 | R40: =MAX(R5:R35) -> 186448 | AB40: =(100-进出水!T38)*AB37/100 -> 959.09764
...

Sheet 汇总
A1: 常州市深水江边污水处理有限公司污水运行月报表
A2: 44531
A3: 污 水 处 理 | B3: 污水处理量（m3） | C3: =处理量!R37 -> 4794852 | D3: 污 泥 处 理 | E3: 脱水污泥量（T） | F3: =处理量!E37+处理量!F37+处理量!G37 -> 4306.68 | G3: 水 电 用 量 | H3: 用电量（度） | J3: =处理量!J37 -> 1505900 | K3: 污 水 电 单 耗 | L3: 污水（度/m3） | M3: =J3/C3 -> 0.314066 | P3: 除臭用水量 | Q3: 1773.2 | R3: =J5-Q3 -> 3373.8 | V3: 188314
B4: 日均处理量（m3） | C4: =处理量!R36 -> 154672.65 | E4: 絮凝剂用量（kg） | F4: =处理量!H37 -> 4500 | H4: 日均用电量（度） | J4: =J3/M15 -> 48577.419 | L4: CODcr（度/kg） | M4: =J3/I12 -> 1.4580594 | P4: 除臭用电量 | Q4: 50536 | V4: 193894
E5: 含水率（%） | F5: =进出水!T38 -> 77.73 | H5: 用水量（T） | J5: 5147 | V5: =V4-V3 -> 5580
B6: 最高日处理量 | C6: =处理量!R40 -> 186448 | E6: 絮凝剂单耗（kg/T） | F6: =F4/(F3*(100-F5)/100) -> 4.6919102 | G6: 消 毒 剂 | H6: 工业合成盐酸（T） | J6: =处理量!M37/1000 -> 101.743 | L6: BOD5（度/kg） | M6: =J3/I13 -> 2.4536406
B7: 最低日处理量 | C7: =处理量!R41 -> 119958 | E7: 产泥率(g/m３) | F7: =F3*(100-F5)/100*1000/(C3/1000) -> 200.02654 | H7: 药单耗(g/m3) | J7: =J6*1000/(C3/1000) -> 21.219216 | L7: SS（度/kg） | M7: =J3/I14 -> 2.3132209
B8: 负荷率（%） | C8: =C4/200000*100 -> 77.336323 | D8: 混 凝 剂 | E8: 混凝剂用量（T） | F8: =处理量!K37/1000 -> 148.788 | H8: 氯酸钠（T） | J8: =处理量!N37/1000 -> 35.376 | K8: 乙酸-厌缺氧段 | L8: 投加量（吨） | M8: =处理量!O37 -> 115.21
B9: 进水水温(℃) | C9: =处理量!B36 -> 21.203226 | E9: 药单耗(g/m3) | F9: =F8*1000/(C3/1000) -> 31.030781 | H9: 药单耗(g/m3) | J9: =J8*1000/(C3/1000) -> 7.3779128 | L9: 药单耗(g/m3) | M9: =M8*1000000/C3 -> 24.027853
A10: 处 理 质 量 | B10: 项目 | C10: 进水 | E10: 出水 | G10: 去除率（%） | I10: 去除总量（kg) | K10: 乙酸-提标段 | L10: 投加量（吨） | M10: 0
L11: 药单耗(g/m3) | M11: 0
B12: CODcr | C12: =进出水!B38 -> 245 | E12: =进出水!N38 -> 29.6 | G12: =(C12-E12)/C12*100 -> 87.918367 | I12: =$C$3*(C12-E12)/1000 -> 1032811.1 | K12: 污 泥 去 向 | L12: 国电 | M12: =处理量!V16 -> 3253.56 | P12: =ROUND(E12,1) -> 29.6 | Q12: =C3 -> 4794852 | R12: =P12*Q12/1000000 -> 141.92762 | S12: CODcr
B13: BOD5 | C13: =进出水!C38 -> 129 | E13: =[1]进出水!O38 -> <2 | G13: =(C13-1)/C13*100 -> 99.224806 | I13: =$C$3*(C13-1)/1000 -> 613741.06 | L13: 英科环境 | M13: =处理量!U16 -> 831.58 | P13: 1 | Q13: =Q12 -> 4794852 | R13: =P13*Q13/1000000 -> 4.794852 | S13: BOD5
B14: SS | C14: =进出水!D38 -> 141 | E14: =进出水!P38 -> 5.23 | G14: =(C14-E14)/C14*100 -> 96.29078 | I14: =$C$3*(C14-E14)/1000 -> 650997.06 | L14: 其它 | M14: =处理量!W16 -> 221.54 | P14: =ROUND(E14,1) -> 5.2 | Q14: =Q13 -> 4794852 | R14: =P14*Q14/1000000 -> 24.93323 | S14: SS
B15: TP | C15: =进出水!E38 -> 2.88 | E15: =进出水!Q38 -> 0.14 | G15: =(C15-E15)/C15*100 -> 95.138889 | I15: =$C$3*(C15-E15)/1000 -> 13137.894 | K15: 运 行 情 况 | L15: 应运行天数 | M15: 31 | P15: =ROUND(E15,1) -> 0.1 | Q15: =Q14 -> 4794852 | R15: =P15*Q15/1000000 -> 0.4794852 | S15: TP
B16: TN | C16: =进出水!G38 -> 30.9 | E16: =进出水!S38 -> 7.95 | G16: =(C16-E16)/C16*100 -> 74.271845 | I16: =$C$3*(C16-E16)/1000 -> 110041.85 | L16: 实际运行天数 | M16: 31 | P16: =ROUND(E16,1) -> 8 | Q16: =Q15 -> 4794852 | R16: =P16*Q16/1000000 -> 38.358816 | S16: TN
B17: NH3-N | C17: =进出水!F38 -> 24.5 | E17: =进出水!R38 -> 0.47 | G17: =(C17-E17)/C17*100 -> 98.081633 | I17: =$C$3*(C17-E17)/1000 -> 115220.29 | L17: 达标排放天数 | M17: 31 | P17: =ROUND(E17,1) -> 0.5 | Q17: =Q16 -> 4794852 | R17: =P17*Q17/1000000 -> 2.397426 | S17: NH3-N
B18: 粪大肠菌群数 (个/L) | E18: <20 | L18: 运转率 | M18: 100
A19: 备注 | B19: 本月产生泥饼4306.68吨，其中运往常州市英科环境科技有限公司831.58吨，国电常州发电有限公司3253.56吨，外运接种221.54吨：天合光能股份有限公司硅片分公司15.00吨、江苏盈天化学有限公司15.00吨、富德（常州）能源化工发展有限公司111.54吨、常州天马集团有限公司(原建材二五三厂)20.00吨、常州东方诺亚印染有限公司60.00吨。 | P19: =F3*(100-F5)/100 -> 959.09764
A21: 审核： 制表： 制表日期：2022/1/4

Sheet 进出水
A1: 常州市深水江边污水处理有限公司进出水水质、污泥含水率月报表
J3: 44531
A4: 日期 | B4: 进水 | H4: 二沉池出水 | N4: 总出水 | T4: 污泥含水率 | U4: 粪大肠菌群
B5: CODCr | C5: BOD5 | D5: SS | E5: TP | F5: NH3-N | G5: TN | H5: CODCr | I5: BOD5 | J5: SS | K5: TP | L5: NH3-N | M5: TN | N5: CODCr | O5: BOD5 | P5: SS | Q5: TP | R5: NH3-N | S5: TN
B6: （mg/L） | C6: （mg/L） | D6: （mg/L） | E6: （mg/L） | F6: （mg/L） | G6: （mg/L） | H6: （mg/L） | I6: （mg/L） | J6: （mg/L） | K6: （mg/L） | L6: （mg/L） | M6: （mg/L） | N6: （mg/L） | O6: （mg/L） | P6: （mg/L） | Q6: （mg/L） | R6: （mg/L） | S6: （mg/L） | T6: （%） | U6: (个/L)
A7: 1 | B7: 243 | C7: 127 | D7: 150 | E7: 2.93 | F7: 26.3 | G7: 31.4 | H7: 32 | I7: <2 | J7: 20 | K7: 0.53 | L7: 0.51 | M7: 8.82 | N7: 28 | O7: <2 | P7: 7 | Q7: 0.1 | R7: 0.38 | S7: 8.22 | T7: 78 | U7: <20 | W7: =1-S7/G7 -> 0.73821656
A8: 2 | B8: 288 | C8: 151 | D8: 180 | E8: 2.39 | F8: 22.9 | G8: 28.6 | H8: 38 | I8: <2 | J8: 20 | K8: 0.49 | L8: 0.54 | M8: 8.22 | N8: 31 | O8: <2 | P8: 5 | Q8: 0.13 | R8: 0.39 | S8: 7.7 | T8: 77.5 | U8: <20 | W8: =1-S8/G8 -> 0.73076923
A9: 3 | B9: 234 | C9: 124 | D9: 144 | E9: 2.63 | F9: 23.9 | G9: 28.8 | H9: 34 | I9: <2 | J9: 18 | K9: 0.51 | L9: 0.52 | M9: 7.83 | N9: 29 | O9: <2 | P9: 5 | Q9: 0.08 | R9: 0.46 | S9: 6.98 | T9: 77.8 | U9: <20 | W9: =1-S9/G9 -> 0.75763889
A10: 4 | B10: 260 | C10: 138 | D10: 152 | E10: 2.44 | F10: 24.5 | G10: 30.8 | H10: 38 | I10: <2 | J10: 17 | K10: 0.52 | L10: 0.54 | M10: 6.93 | N10: 29 | O10: <2 | P10: 5 | Q10: 0.09 | R10: 0.28 | S10: 6.58 | T10: 77.4 | W10: =1-S10/G10 -> 0.78636364
A11: 5 | B11: 230 | C11: 120 | D11: 122 | E11: 3.01 | F11: 28 | G11: 34.7 | H11: 36 | I11: <2 | J11: 17 | K11: 0.52 | L11: 0.6 | M11: 10.5 | N11: 27 | O11: <2 | P11: 5 | Q11: 0.13 | R11: 0.52 | S11: 8.47 | T11: 77.8 | W11: =1-S11/G11 -> 0.75590778
A12: 6 | B12: 213 | C12: 113 | D12: 130 | E12: 2.44 | F12: 24.5 | G12: 31.7 | H12: 32 | I12: <2 | J12: 15 | K12: 0.5 | L12: 0.68 | M12: 8.17 | N12: 26 | O12: <2 | P12: 5 | Q12: 0.1 | R12: 0.55 | S12: 7.88 | T12: 77.9 | U12: 70 | W12: =1-S12/G12 -> 0.75141956
A13: 7 | B13: 268 | C13: 141 | D13: 198 | E13: 3.06 | F13: 22.8 | G13: 28.2 | H13: 30 | I13: <2 | J13: 13 | K13: 0.51 | L13: 0.46 | M13: 8.22 | N13: 27 | O13: <2 | P13: 5 | Q13: 0.09 | R13: 0.36 | S13: 7.7 | T13: 77.7 | U13: <20 | W13: =1-S13/G13 -> 0.72695035
A14: 8 | B14: 332 | C14: 177 | D14: 244 | E14: 3.06 | F14: 20.6 | G14: 29.4 | H14: 33 | I14: <2 | J14: 17 | K14: 0.51 | L14: 0.48 | M14: 7.73 | N14: 26 | O14: <2 | P14: 5 | Q14: 0.1 | R14: 0.38 | S14: 7.36 | T14: 77.7 | U14: <20 | W14: =1-S14/G14 -> 0.74965986
A15: 9 | B15: 250 | C15: 133 | D15: 160 | E15: 3.24 | F15: 26.9 | G15: 33.9 | H15: 43 | I15: <2 | J15: 20 | K15: 0.54 | L15: 0.54 | M15: 8.42 | N15: 34 | O15: <2 | P15: 6 | Q15: 0.12 | R15: 0.43 | S15: 8.22 | T15: 77.7 | U15: <20 | W15: =1-S15/G15 -> 0.75752212
A16: 10 | B16: 160 | C16: 86.3 | D16: 76 | E16: 2.48 | F16: 23.8 | G16: 29.8 | H16: 39 | I16: <2 | J16: 18 | K16: 0.51 | L16: 0.5 | M16: 8.92 | N16: 31 | O16: <2 | P16: 6 | Q16: 0.12 | R16: 0.36 | S16: 8.22 | T16: 77.4 | U16: <20 | W16: =1-S16/G16 -> 0.72416107
A17: 11 | B17: 272 | C17: 141 | D17: 128 | E17: 3.62 | F17: 24.4 | G17: 30.8 | H17: 39 | I17: <2 | J17: 18 | K17: 0.49 | L17: 0.56 | M17: 8.32 | N17: 30 | O17: <2 | P17: 5 | Q17: 0.09 | R17: 0.43 | S17: 8.08 | T17: 77.2 | W17: =1-S17/G17 -> 0.73766234
A18: 12 | B18: 296 | C18: 160 | D18: 168 | E18: 3.11 | F18: 29 | G18: 38.5 | H18: 34 | I18: <2 | J18: 18 | K18: 0.53 | L18: 0.72 | M18: 9.87 | N18: 30 | O18: <2 | P18: 6 | Q18: 0.13 | R18: 0.65 | S18: 8.37 | T18: 77.5 | W18: =1-S18/G18 -> 0.7825974
A19: 13 | B19: 318 | C19: 168 | D19: 154 | E19: 3.52 | F19: 27.1 | G19: 35.1 | H19: 44 | I19: 2.16 | J19: 20 | K19: 0.57 | L19: 0.74 | M19: 9.8 | N19: 28 | O19: <2 | P19: 5 | Q19: 0.13 | R19: 0.34 | S19: 8.03 | T19: 78 | U19: <20 | W19: =1-S19/G19 -> 0.77122507
A20: 14 | B20: 252 | C20: 131 | D20: 122 | E20: 2.62 | F20: 31.9 | G20: 37.4 | H20: 39 | I20: <2 | J20: 18 | K20: 0.51 | L20: 0.53 | M20: 10.5 | N20: 28 | O20: <2 | P20: 5 | Q20: 0.14 | R20: 0.44 | S20: 8.97 | T20: 77.6 | U20: <20 | W20: =1-S20/G20 -> 0.76016043
A21: 15 | B21: 170 | C21: 90.6 | D21: 98 | E21: 2.41 | F21: 23.1 | G21: 27.9 | H21: 29 | I21: <2 | J21: 12 | K21: 0.51 | L21: 0.51 | M21: 8.17 | N21: 26 | O21: <2 | P21: 5 | Q21: 0.15 | R21: 0.36 | S21: 7.18 | T21: 77.9 | U21: <20 | W21: =1-S21/G21 -> 0.74265233
A22: 16 | B22: 250 | C22: 135 | D22: 222 | E22: 2.93 | F22: 22.3 | G22: 27.4 | H22: 32 | I22: <2 | J22: 18 | K22: 0.48 | L22: 0.6 | M22: 8.02 | N22: 25 | O22: <2 | P22: 6 | Q22: 0.19 | R22: 0.48 | S22: 7.27 | T22: 77.3 | U22: <20 | W22: =1-S22/G22 -> 0.73467153
A23: 17 | B23: 184 | C23: 99.2 | D23: 102 | E23: 2 | F23: 16.5 | G23: 21.8 | H23: 36 | I23: <2 | J23: 18 | K23: 0.52 | L23: 0.51 | M23: 8.22 | N23: 28 | O23: <2 | P23: 5 | Q23: 0.19 | R23: 0.41 | S23: 6.87 | T23: 77.6 | U23: <20 | W23: =1-S23/G23 -> 0.68486239
A24: 18 | B24: 191 | C24: 103 | D24: 106 | E24: 2.67 | F24: 17.3 | G24: 24.2 | H24: 41 | I24: 2.24 | J24: 19 | K24: 0.54 | L24: 0.53 | M24: 7.62 | N24: 32 | O24: <2 | P24: 5 | Q24: 0.19 | R24: 0.44 | S24: 7.17 | T24: 78.1 | W24: =1-S24/G24 -> 0.70371901
A25: 19 | B25: 210 | C25: 111 | D25: 96 | E25: 2.78 | F25: 32.1 | G25: 37.1 | H25: 41 | I25: <2 | J25: 19 | K25: 0.53 | L25: 0.73 | M25: 10.3 | N25: 31 | O25: <2 | P25: 5 | Q25: 0.18 | R25: 0.62 | S25: 9.07 | T25: 78.4 | W25: =1-S25/G25 -> 0.75552561
A26: 20 | B26: 225 | C26: 122 | D26: 118 | E26: 2.45 | F26: 24.2 | G26: 29.3 | H26: 34 | I26: <2 | J26: 11 | K26: 0.56 | L26: 0.73 | M26: 9.3 | N26: 30 | O26: <2 | P26: 5 | Q26: 0.19 | R26: 0.68 | S26: 8.67 | T26: 77.8 | U26: <20 | W26: =1-S26/G26 -> 0.70409556
A27: 21 | B27: 237 | C27: 125 | D27: 122 | E27: 1.87 | F27: 20 | G27: 25.2 | H27: 39 | I27: <2 | J27: 16 | K27: 0.51 | L27: 0.72 | M27: 9.92 | N27: 26 | O27: <2 | P27: 5 | Q27: 0.15 | R27: 0.53 | S27: 8.84 | T27: 77.6 | U27: <20 | W27: =1-S27/G27 -> 0.64920635
A28: 22 | B28: 244 | C28: 129 | D28: 136 | E28: 2.27 | F28: 23.8 | G28: 29.9 | H28: 39 | I28: <2 | J28: 12 | K28: 0.5 | L28: 0.66 | M28: 8.27 | N28: 32 | O28: <2 | P28: 5 | Q28: 0.19 | R28: 0.5 | S28: 7.97 | T28: 77.4 | U28: <20 | W28: =1-S28/G28 -> 0.73344482
A29: 23 | B29: 188 | C29: 102 | D29: 96 | E29: 1.97 | F29: 20.6 | G29: 26.7 | H29: 34 | I29: <2 | J29: 17 | K29: 0.53 | L29: 0.56 | M29: 8.22 | N29: 30 | O29: <2 | P29: 5 | Q29: 0.17 | R29: 0.4 | S29: 7.4 | T29: 77.8 | U29: <20 | W29: =1-S29/G29 -> 0.72284644
A30: 24 | B30: 228 | C30: 123 | D30: 132 | E30: 2.59 | F30: 23 | G30: 32.3 | H30: 41 | I30: 2.06 | J30: 18 | K30: 0.51 | L30: 0.92 | M30: 8.42 | N30: 34 | O30: <2 | P30: 6 | Q30: 0.12 | R30: 0.49 | S30: 7.82 | T30: 77.9 | U30: <20 | W30: =1-S30/G30 -> 0.75789474
A31: 25 | B31: 230 | C31: 120 | D31: 122 | E31: 2.91 | F31: 21.1 | G31: 28.8 | H31: 41 | I31: <2 | J31: 16 | K31: 0.56 | L31: 0.7 | M31: 9.77 | N31: 33 | O31: <2 | P31: 5 | Q31: 0.12 | R31: 0.55 | S31: 8.22 | T31: 78.3 | W31: =1-S31/G31 -> 0.71458333
A32: 26 | B32: 198 | C32: 105 | D32: 102 | E32: 3.17 | F32: 27.8 | G32: 33.8 | H32: 40 | I32: <2 | J32: 17 | K32: 0.53 | L32: 0.77 | M32: 9.52 | N32: 30 | O32: <2 | P32: 5 | Q32: 0.11 | R32: 0.76 | S32: 8.82 | T32: 77.7 | W32: =1-S32/G32 -> 0.73905325
A33: 27 | B33: 304 | C33: 160 | D33: 198 | E33: 3.49 | F33: 29.8 | G33: 35.1 | H33: 44 | I33: <2 | J33: 19 | K33: 0.56 | L33: 0.73 | M33: 10.1 | N33: 32 | O33: <2 | P33: 5 | Q33: 0.13 | R33: 0.56 | S33: 8.42 | T33: 77.8 | U33: <20 | W33: =1-S33/G33 -> 0.76011396
A34: 28 | B34: 325 | C34: 169 | D34: 132 | E34: 4.18 | F34: 31.2 | G34: 38 | H34: 42 | I34: <2 | J34: 12 | K34: 0.52 | L34: 0.8 | M34: 9.77 | N34: 35 | O34: <2 | P34: 5 | Q34: 0.15 | R34: 0.5 | S34: 8.52 | T34: 77.3 | U34: <20 | W34: =1-S34/G34 -> 0.77578947
A35: 29 | B35: 246 | C35: 130 | D35: 134 | E35: 3.79 | F35: 24.3 | G35: 29.7 | H35: 44 | I35: 2.06 | J35: 16 | K35: 0.52 | L35: 0.54 | M35: 9.02 | N35: 26 | O35: <2 | P35: 5 | Q35: 0.16 | R35: 0.46 | S35: 8.44 | T35: 78.2 | U35: <20 | W35: =1-S35/G35 -> 0.71582492
A36: 30 | B36: 258 | C36: 136 | D36: 168 | E36: 3.88 | F36: 25.3 | G36: 30.7 | H36: 41 | I36: <2 | J36: 18 | K36: 0.51 | L36: 0.71 | M36: 11.3 | N36: 31 | O36: <2 | P36: 5 | Q36: 0.18 | R36: 0.44 | S36: 8.22 | T36: 78 | U36: <20 | W36: =1-S36/G36 -> 0.73224756
A37: 31 | B37: 277 | C37: 144 | D37: 162 | E37: 3.22 | F37: 19.7 | G37: 29.8 | H37: 44 | I37: 2.18 | J37: 16 | K37: 0.5 | L37: 0.74 | M37: 8.72 | N37: 32 | O37: <2 | P37: 5 | Q37: 0.17 | R37: 0.55 | S37: 6.9 | T37: 77.4 | U37: <20 | W37: =1-S37/G37 -> 0.76845638
A38: 平均 | B38: =ROUND(AVERAGE(B7:B37),0) -> 245 | C38: =ROUND(AVERAGE(C7:C37),0) -> 129 | D38: =ROUND(AVERAGE(D7:D37),0) -> 141 | E38: =ROUND(AVERAGE(E7:E37),2) -> 2.88 | F38: =ROUND(AVERAGE(F7:F37),1) -> 24.5 | G38: =ROUND(AVERAGE(G7:G37),1) -> 30.9 | H38: =ROUND(AVERAGE(H7:H37),1) -> 37.8 | I38: =ROUND(AVERAGE(I7:I37),2) -> 2.14 | J38: =ROUND(AVERAGE(J7:J37),2) -> 16.87 | K38: =ROUND(AVERAGE(K7:K37),2) -> 0.52 | L38: =ROUND(AVERAGE(L7:L37),2) -> 0.63 | M38: =ROUND(AVERAGE(M7:M37),1) -> 8.9 | N38: =ROUND(AVERAGE(N7:N37),1) -> 29.6 | O38: <2 | P38: =ROUND(AVERAGE(P7:P37),2) -> 5.23 | Q38: =ROUND(AVERAGE(Q7:Q37),2) -> 0.14 | R38: =ROUND(AVERAGE(R7:R37),2) -> 0.47 | S38: =ROUND(AVERAGE(S7:S37),2) -> 7.95 | T38: =ROUND(AVERAGE(T7:T37),2) -> 77.73 | U38: <20
A39: 审核： | J39: 制表： | Q39: 制表时间：2022/1/4
B41: 项目 | C41: 进水（mg/L) | D41: 最大值 | E41: 最小值（mg/L) | F41: 出水（mg/L) | G41: 最大值 | H41: 最小值（mg/L) | I41: 去除率
D42: （mg/L) | G42: （mg/L) | I42: （%）
...

Sheet 设备
A1: 常州市深水江边污水处理有限公司设备运行月报表
A2: 44531
A3: 运行 工段 | B3: 设备名称 | C3: 编号 | D3: 运行 天数 | E3: 定时 | F3: 额定运行时间 | G3: 实际运行时间 | H3: 利用率 | I3: 完好率 | J3: 维修、保养情况
D5: （d） | E5: （h/d） | F5: （h） | G5: （h） | H5: % | I5: %
A6: 预 处 理 | B6: 粗格栅机 | C6: 1# | D6: 31 | E6: 2 | F6: 62 | G6: 62 | H6: 1 | I6: 1 | J6: 17日保养
C7: 2# | D7: 31 | E7: 2 | F7: 62 | G7: 62 | H7: 1 | I7: 1 | J7: 17日保养
B8: 螺旋输送机 | C8: / | D8: 31 | E8: 2 | F8: 62 | G8: 62 | H8: 1 | I8: 1 | J8: 17日保养
B9: 螺旋压榨机 | C9: / | D9: 31 | E9: 2 | F9: 62 | G9: 62 | H9: 1 | I9: 1 | J9: 17日保养
B10: 进水泵 | C10: 1# | D10: 31 | E10: 24 | F10: 744 | G10: 598 | H10: 0.80376344 | I10: 1
C11: 2# | D11: 31 | E11: 24 | F11: 744 | G11: 496 | H11: 0.66666667 | I11: 1
C12: 3# | D12: 31 | E12: 24 | F12: 744 | G12: 72 | H12: 0.096774194 | I12: 1
C13: 4# | D13: 31 | E13: 24 | F13: 744 | G13: 6 | H13: 0.0080645161 | I13: 1
C14: 5# | D14: 31 | E14: 24 | F14: 744 | G14: 740 | H14: 0.99462366 | I14: 1
B15: 细格栅机 | C15: 1# | D15: 31 | E15: 2.4 | F15: 74.4 | G15: 74.4 | H15: 1 | I15: 1
C16: 2# | D16: 31 | E16: 2.4 | F16: 74.4 | G16: 74.4 | H16: 1 | I16: 1
C17: 3# | D17: 31 | E17: 2.4 | F17: 74.4 | G17: 74.4 | H17: 1 | I17: 1
C18: 4# | D18: 31 | E18: 2.4 | F18: 74.4 | G18: 74.4 | H18: 1 | I18: 1
C19: 5# | D19: 31 | E19: 2.4 | F19: 74.4 | G19: 74.4 | H19: 1 | I19: 1
C20: 6# | D20: 31 | E20: 2.4 | F20: 74.4 | G20: 74.4 | H20: 1 | I20: 1
B21: 螺旋输送机 | C21: 1# | D21: 31 | E21: 2 | F21: 62 | G21: 15.5 | H21: 0.25 | I21: 1
C22: 2# | D22: 31 | E22: 2 | F22: 62 | G22: 15.5 | H22: 0.25 | I22: 1
B23: 螺旋压榨机 | C23: 1# | D23: 31 | E23: 2 | F23: 62 | G23: 15.5 | H23: 0.25 | I23: 1
C24: 2# | D24: 31 | E24: 2 | F24: 62 | G24: 15.5 | H24: 0.25 | I24: 1
B25: 搅拌机 | C25: 1# | D25: 31 | E25: 24 | F25: 744 | G25: 0 | H25: 0 | I25: 1
B26: 砂水分离机 | C26: 1# | D26: 31 | E26: 0.5 | F26: 15.5 | G26: 15.5 | H26: 1 | I26: 1
B27: 搅拌机 | C27: 2# | D27: 31 | E27: 24 | F27: 744 | G27: 0 | H27: 0 | I27: 1
B28: 砂水分离机 | C28: 2# | D28: 31 | E28: 0.5 | F28: 15.5 | G28: 15.5 | H28: 1 | I28: 1
B29: 搅拌机 | C29: 3# | D29: 31 | E29: 24 | F29: 744 | G29: 744 | H29: 1 | I29: 1
B30: 砂水分离机 | C30: 3# | D30: 31 | E30: 0.5 | F30: 15.5 | G30: 15.5 | H30: 1 | I30: 1
B31: 搅拌机 | C31: 4# | D31: 31 | E31: 24 | F31: 744 | G31: 0 | H31: 0 | I31: 1
B32: 砂水分离机 | C32: 4# | D32: 31 | E32: 0.5 | F32: 15.5 | G32: 15.5 | H32: 1 | I32: 1
B33: 高压鼓风机 | C33: 1# | D33: 31 | E33: 24 | F33: 744 | G33: 455 | H33: 0.61155914 | I33: 1 | J33: 28日加油保养
C34: 2# | D34: 31 | E34: 24 | F34: 744 | G34: 218 | H34: 0.29301075 | I34: 1 | J34: 23日滤网更换、28日加油保养
C35: 3# | D35: 31 | E35: 24 | F35: 744 | G35: 6 | H35: 0.0080645161 | I35: 1 | J35: 28日加油保养
C36: 4# | D36: 31 | E36: 24 | F36: 744 | G36: 405 | H36: 0.54435484 | I36: 1 | J36: 28日加油保养
C37: 5# | D37: 31 | E37: 24 | F37: 744 | G37: 448 | H37: 0.60215054 | I37: 1 | J37: 28日加油保养
A38: 审核： | E38: 制表： | H38: 制表时间：2022/1/4
A46: 常州市深水江边污水处理有限公司设备运行月报表
A47: =A2 -> 44531
A48: 运行 工段 | B48: 设备名称 | C48: 编号 | D48: 运行 天数 | E48: 定时 | F48: 额定运行时间 | G48: 实际运行时间 | H48: 利用率 | I48: 完好率 | J48: 维修、保养情况
...

Sheet 仪表
A1: 常州市深水江边污水处理有限公司污水运行月报表
D2: 44531
A3: 仪表名称 | B3: 编号 | C3: 规格型号 | D3: 安装位置 | E3: 运行情况 | F3: 标定、校准情况 | G3: 备注
A4: 一期溶氧仪 | B4: 1#（南） | C4: 美商生化T-10 | D4: 一期生反池 | E4: 正常 | F4: 校准 | G4: 2021-12-01 2021-12-08 2021-12-15 2021-12-22
B5: 2#（南） | C5: 美商生化T-10 | D5: 一期生反池 | E5: 正常 | F5: 校准 | G5: =G4 -> 2021-12-01 2021-12-08 2021-12-15 2021-12-22
B6: 1#（北） | C6: 美商生化T-10 | D6: 一期生反池 | E6: 正常 | F6: 校准 | G6: =G5 -> 2021-12-01 2021-12-08 2021-12-15 2021-12-22
B7: 2#（北） | C7: 美商生化T-10 | D7: 一期生反池 | E7: 正常 | F7: 校准 | G7: =G6 -> 2021-12-01 2021-12-08 2021-12-15 2021-12-22
A8: 一期污泥浓度计 | B8: 1#（南） | C8: E+H | D8: 一期生反池 | E8: 正常 | F8: 校准 | G8: =G7 -> 2021-12-01 2021-12-08 2021-12-15 2021-12-22
B9: 2#（南） | C9: E+H | D9: 一期生反池 | E9: 正常 | F9: 校准 | G9: =G8 -> 2021-12-01 2021-12-08 2021-12-15 2021-12-22
B10: 1#（北） | C10: E+H | D10: 一期生反池 | E10: 正常 | F10: 校准 | G10: =G9 -> 2021-12-01 2021-12-08 2021-12-15 2021-12-22
B11: 2#（北） | C11: E+H | D11: 一期生反池 | E11: 正常 | F11: 校准 | G11: =G10 -> 2021-12-01 2021-12-08 2021-12-15 2021-12-22
A12: 进水PH计 | B12: 1# | C12: 哈希 | D12: 一期旋流沉砂池 | E12: 正常 | F12: 标定 | G12: =G11 -> 2021-12-01 2021-12-08 2021-12-15 2021-12-22
A13: 二期溶氧仪 | B13: 1#（南） | C13: 哈希LDO | D13: 二期生反池 | E13: 正常 | F13: 校准 | G13: =G12 -> 2021-12-01 2021-12-08 2021-12-15 2021-12-22
B14: 2#（南） | C14: 哈希LDO | D14: 二期生反池 | E14: 正常 | F14: 校准 | G14: =G13 -> 2021-12-01 2021-12-08 2021-12-15 2021-12-22
B15: 1#（北） | C15: 哈希LDO | D15: 二期生反池 | E15: 正常 | F15: 校准 | G15: =G14 -> 2021-12-01 2021-12-08 2021-12-15 2021-12-22
B16: 2#（北） | C16: 哈希LDO | D16: 二期生反池 | E16: 正常 | F16: 校准 | G16: =G15 -> 2021-12-01 2021-12-08 2021-12-15 2021-12-22
A17: 二期污泥浓度计 | B17: 1#（南） | C17: 哈希TXPRO-2 | D17: 二期生反池 | E17: 正常 | F17: 校准 | G17: =G16 -> 2021-12-01 2021-12-08 2021-12-15 2021-12-22
B18: 2#（南） | C18: E+H | D18: 二期生反池 | E18: 正常 | F18: 校准 | G18: =G17 -> 2021-12-01 2021-12-08 2021-12-15 2021-12-22
B19: 1#（北） | C19: 哈希TXPRO-2 | D19: 二期生反池 | E19: 正常 | F19: 校准 | G19: =G18 -> 2021-12-01 2021-12-08 2021-12-15 2021-12-22
B20: 2#（北） | C20: E+H | D20: 二期生反池 | E20: 正常 | F20: 校准 | G20: =G19 -> 2021-12-01 2021-12-08 2021-12-15 2021-12-22
A21: 审核： | D21: 制表： | F21: 制表日期：2022/1/4
A25: 常州市深水江边污水处理有限公司污水运行月报表
D26: =D2 -> 44531
A27: 仪表名称 | B27: 编号 | C27: 规格型号 | D27: 安装位置 | E27: 运行情况 | F27: 标定、校准情况 | G27: 备注
A28: 一期ORP | B28: 1#（南） | C28: E+H | D28: 一期生反池 | E28: 正常 | F28: 标定 | G28: 44546
B29: 2#（北） | C29: E+H | D29: 一期生反池 | E29: 正常 | F29: 标定 | G29: =G28 -> 44546
A30: 二期ORP | B30: 1#（南） | C30: 哈希 | D30: 二期生反池 | E30: 正常 | F30: 标定 | G30: =G29 -> 44546
B31: 2#（北） | C31: 哈希 | D31: 二期生反池 | E31: 正常 | F31: 标定 | G31: =G30 -> 44546
A32: 审核： | D32: 制表： | F32: =F21 -> 制表日期：2022/1/4

Sheet 实验数据
A1: 常州市深水江边污水处理有限公司实验数据汇总表
A3: 采样地点：一期北 | E3: 采样时间：2021-12-20
A4: 硝化实验 | E4: 反硝化实验 | G4: 释磷实验
A5: 时间节点 | B5: NO3-N(mg/l) | C5: NH3-N(mg/l) | D5: PO43-(mg/l) | E5: 时间节点 | F5: NO3-N(mg/l) | G5: 时间节点 | H5: PO43-(mg/l)
A6: 0分钟 | B6: 4.18 | C6: 10.3 | D6: 3.79 | E6: 0分钟 | F6: 7.61 | G6: 0分钟 | H6: 1.25
A7: 15分钟 | B7: 5.68 | C7: 9.8 | D7: 2.32 | E7: 15分钟 | F7: 6.58 | G7: 30分钟 | H7: 1.65
A8: 30分钟 | B8: 8.88 | C8: 7.68 | D8: 2.15 | E8: 30分钟 | F8: 4.71 | G8: 60分钟 | H8: 1.98
A9: 60分钟 | B9: 9.96 | C9: 4.68 | D9: 1.29 | E9: 45分钟 | F9: 3.88 | G9: 90分钟 | H9: 3.68
A10: MLSS(mg/l) | B10: 5652 | E10: 60分钟 | F10: 2.88 | G10: MLSS(mg/l) | H10: 5216
E11: 90分钟 | F11: 1.68
E12: MLSS(mg/l) | F12: 6578
A13: 审核： | D13: 制表： | G13: 制表日期：2022/1/4
