Workbook

Sheet 处理量
A1: 常州市深水江边污水处理有限公司污水处理运行月报表
A2: 2021年 3月
A3: 日 期 | B3: 水温 | C3: 天气 | D3: 日处理水量 （m3） | E3: 污泥量 | F3: 药剂量 | G3: MLSS | H3: 电耗 | I3: 混凝剂 | J3: 絮凝剂 阴离子 （kg） | K3: 盐酸 | L3: 氯酸钠 | M3: 乙酸 | N3: 回用水 （m3） | O3: 实际水量（m3） | Q3: 费用统计 | R3: 成本分析用 | T3: 单价 | U3: 单耗 | V3: 之前价 | W3: 最新时间
B4: 度 | C4: 状况 | E4: （T） | F4: （Kg） | G4: （mg/l） | H4: ( 度 ) | I4: （Kg） | K4: （Kg） | L4: （Kg） | M4: （吨） | Q4: 电量 | R4: =ROUND(H37*T4,2) -> 914452.5 | T4: 0.565 | U4: =H36/O36 -> 0.29970502 | V4: 0.608 | W4: 44197
A5: 1 | B5: 17.3 | C5: 雨 | D5: 207629 | E5: 157.08 | F5: 125 | G5: 4560 | H5: 56000 | I5: 4740 | J5: 22 | K5: 4047 | L5: 1440 | M5: 3.12 | N5: 5573 | O5: =D5-N5 -> 202056 | Q5: 聚丙烯酰阳离子 | R5: =F37*T5/1000 -> 167492.5 | T5: 28150 | U5: =F36/O36*1000 -> 1.1017886 | V5: 28250 | W5: 43952
A6: 2 | B6: 16.9 | C6: 晴 | D6: 207632 | E6: 265.06 | F6: 225 | G6: 5066 | H6: 55100 | I6: 10020 | J6: 32 | K6: 3976 | L6: 1392 | M6: 3.12 | N6: 5367 | O6: =D6-N6 -> 202265 | Q6: 聚丙烯酰阴离子 | R6: =J37*T6/1000 -> 8444.8 | S6: =R5+R6 -> 175937.3 | T6: 10400 | U6: =J36/O36*1000 -> 0.15036174 | V6: 5784.76 | W6: 44256
A7: 3 | B7: 17 | C7: 晴 | D7: 205717 | E7: 173.88 | F7: 200 | G7: 4722 | H7: 59400 | I7: 9864 | J7: 34 | K7: 3834 | L7: 1368 | M7: 3.24 | N7: 5452 | O7: =D7-N7 -> 200265 | Q7: 工业盐酸 | R7: =K37*T7/1000 -> 38559.39 | T7: 430 | U7: =K36/O36*1000 -> 16.605158 | V7: 182 | W7: 44228
A8: 4 | B8: 18.7 | C8: 晴 | D8: 206136 | E8: 177.18 | F8: 200 | G8: 4956 | H8: 55000 | I8: 9768 | J8: 33 | K8: 2911 | L8: 1056 | M8: 3.26 | N8: 5441 | O8: =D8-N8 -> 200695 | Q8: 工业氯酸钠 | R8: =L37*T8/1000 -> 168551.96 | S8: =R7+R8 -> 207111.35 | T8: 5280.45 | U8: =L36/O36*1000 -> 5.9107718 | V8: 5462.35 | W8: 44256
A9: 5 | B9: 17.8 | C9: 阴 | D9: 120591 | E9: 210.98 | F9: 175 | G9: 4282 | H9: 40700 | I9: 7248 | J9: 23 | K9: 1633 | L9: 600 | M9: 2.92 | N9: 3050 | O9: =D9-N9 -> 117541 | Q9: 混凝药剂 | R9: =I37*T9/1000 -> 77978.448 | T9: 348 | U9: =I36/O36*1000 -> 41.493174 | V9: 370 | W9: 44228
A10: 6 | B10: 16.9 | C10: 雨 | D10: 180960 | E10: 211.54 | F10: 225 | G10: 4542 | H10: 50200 | I10: 9468 | J10: 33 | K10: 1704 | L10: 624 | M10: 2.97 | N10: 5277 | O10: =D10-N10 -> 175683 | Q10: 污泥外运 | R10: =Q18 -> 101391.14 | S10: 计算见下表
A11: 7 | B11: 15.8 | C11: 雨 | D11: 172168 | E11: 225.36 | F11: 200 | G11: 4550 | H11: 51900 | I11: 9516 | J11: 35 | K11: 2840 | L11: 1032 | M11: 3.18 | N11: 5523 | O11: =D11-N11 -> 166645 | Q11: 自来水 | R11: =汇总!J5*4.21 -> 24830.58 | T11: 4.21
A12: 8 | B12: 17.7 | C12: 阴 | D12: 147787 | E12: 207.24 | F12: 200 | G12: 4474 | H12: 48000 | I12: 11316 | J12: 33 | K12: 3053 | L12: 1080 | M12: 3.32 | N12: 5420 | O12: =D12-N12 -> 142367
A13: 9 | B13: 17.3 | C13: 雨 | D13: 202083 | E13: 193.76 | F13: 200 | G13: 5194 | H13: 53700 | I13: 12384 | J13: 31 | K13: 3195 | L13: 1104 | M13: 3.5 | N13: 5448 | O13: =D13-N13 -> 196635 | R13: =R14/O37 -> 0.085370488
A14: 10 | B14: 18.3 | C14: 晴 | D14: 161004 | E14: 232.64 | F14: 225 | G14: 5072 | H14: 47700 | I14: 12444 | J14: 31 | K14: 2982 | L14: 1056 | M14: 3.57 | N14: 5412 | O14: =D14-N14 -> 155592 | Q14: 总药剂 | R14: =R5+R6+R7+R8+R9 -> 461027.1 | S14: 除磷药剂 | T14: =R6+R9 -> 86423.248
A15: 11 | B15: 17.6 | C15: 雨 | D15: 178511 | E15: 230.48 | F15: 200 | G15: 5298 | H15: 50200 | I15: 12456 | J15: 29 | K15: 3266 | L15: 1176 | M15: 2.73 | N15: 5500 | O15: =D15-N15 -> 173011 | Q15: 总泥量 | R15: 英科（吨） | S15: 国电（吨） | T15: 外运（吨）
A16: 12 | B16: 17.5 | C16: 阴 | D16: 176264 | E16: 255.14 | F16: 225 | G16: 5346 | H16: 50400 | I16: 9936 | J16: 29 | K16: 1775 | L16: 552 | M16: 2.16 | N16: 5398 | O16: =D16-N16 -> 170866 | Q16: =R16+S16+T16 -> 5908.04 | R16: 1610.48 | S16: 2836.5 | T16: 1461.06
A17: 13 | B17: 18.1 | C17: 晴 | D17: 176634 | E17: 155.56 | F17: 200 | G17: 4534 | H17: 49100 | I17: 9720 | J17: 29 | K17: 1775 | L17: 576 | M17: 3.45 | N17: 5421.93 | O17: =D17-N17 -> 171212.07 | Q17: 江边费用 | R17: 22.8 | S17: 22.8
A18: 14 | B18: 18.5 | C18: 晴 | D18: 153905 | E18: 220.36 | F18: 250 | G18: 5022 | H18: 47500 | I18: 8820 | J18: 29 | K18: 2840 | L18: 1008 | M18: 2.91 | N18: 5498.07 | O18: =D18-N18 -> 148406.93 | Q18: =R18+S18 -> 101391.14 | R18: =ROUND(R16*R17,2) -> 36718.94 | S18: =ROUND(S16*S17,2) -> 64672.2
A19: 15 | B19: 19.2 | C19: 晴 | D19: 163744 | E19: 226.4 | F19: 250 | G19: 5170 | H19: 54800 | I19: 8724 | J19: 28 | K19: 3479 | L19: 1200 | M19: 2.81 | N19: 5451 | O19: =D19-N19 -> 158293 | Q19: 排水承担 | S19: 0
A20: 16 | B20: 18.2 | C20: 阴 | D20: 195385 | E20: 171.74 | F20: 225 | G20: 5170 | H20: 55200 | I20: 7464 | J20: 20 | K20: 3550 | L20: 1272 | M20: 2.65 | N20: 5437 | O20: =D20-N20 -> 189948 | Q20: =R20+S20 -> 0 | S20: =ROUND(S16*S19,2) -> 0
A21: 17 | B21: 17.8 | C21: 阴 | D21: 167940 | E21: 136 | F21: 225 | G21: 4194 | H21: 51900 | I21: 10392 | J21: 36 | K21: 3053 | L21: 1080 | M21: 3.49 | N21: 5433 | O21: =D21-N21 -> 162507 | Q21: 总运费 | R21: 总单价 | S21: =S17+S19 -> 22.8 | T21: 核对
A22: 18 | B22: 19.5 | C22: 阴 | D22: 174164 | E22: 214.8 | F22: 200 | G22: 5168 | H22: 52200 | I22: 7596 | J22: 40 | K22: 2840 | L22: 1032 | M22: 2.86 | N22: 5443 | O22: =D22-N22 -> 168721 | Q22: =Q18+Q20 -> 101391.14 | T22: =Q16-E37 -> 0
A23: 19 | B23: 19.8 | C23: 雨 | D23: 212669 | E23: 230.14 | F23: 200 | G23: 5440 | H23: 51900 | I23: 408 | J23: 3 | K23: 2130 | L23: 768 | M23: 3 | N23: 5440 | O23: =D23-N23 -> 207229
A24: 20 | B24: 18.5 | C24: 阴 | D24: 211683 | E24: 259.42 | F24: 200 | G24: 4676 | H24: 50000 | I24: 312 | J24: 2 | K24: 2272 | L24: 840 | M24: 3.16 | N24: 5424 | O24: =D24-N24 -> 206259 | Q24: 絮凝剂 | R24: 用量（kg） | S24: =F37 -> 5950 | T24: =J37 -> 812
A25: 21 | B25: 18.7 | C25: 阴 | D25: 206551 | E25: 232.94 | F25: 125 | G25: 4070 | H25: 60600 | I25: 7056 | J25: 39 | K25: 2840 | L25: 1080 | M25: 3.03 | N25: 5488 | O25: =D25-N25 -> 201063 | R25: 单耗（kg/T） | S25: =汇总!F6 -> 4.542635 | T25: =T24/O37*1000 -> 0.15036174
A26: 22 | B26: 18.6 | C26: 晴 | D26: 206092 | E26: 90.52 | F26: 100 | G26: 4242 | H26: 57100 | I26: 6372 | J26: 37 | K26: 3763 | L26: 1320 | M26: 3.2 | N26: 5462 | O26: =D26-N26 -> 200630 | Q26: 混凝剂 | R26: 用量（kg） | S26: =I37 -> 224076
A27: 23 | B27: 18.9 | C27: 晴 | D27: 168192 | E27: 120 | F27: 200 | G27: 4384 | H27: 53200 | I27: 5964 | J27: 37 | K27: 3834 | L27: 1344 | M27: 1.99 | N27: 5362 | O27: =D27-N27 -> 162830 | R27: 单耗（g/m3） | S27: =ROUND(I37/O37*1000,1) -> 41.5
A28: 24 | B28: 18.8 | C28: 晴 | D28: 176211 | E28: 178.86 | F28: 200 | G28: 4826 | H28: 53500 | I28: 2268 | J28: 14 | K28: 2982 | L28: 1080 | M28: 3.07 | N28: 5425 | O28: =D28-N28 -> 170786 | Q28: 盐酸 | R28: 用量（kg） | S28: =K37 -> 89673
A29: 25 | B29: 21.6 | C29: 晴 | D29: 161566 | E29: 220 | F29: 125 | G29: 4542 | H29: 51800 | I29: 0 | J29: 0 | K29: 2698 | L29: 960 | M29: 3.06 | N29: 5541 | O29: =D29-N29 -> 156025 | R29: 单耗（g/m3） | S29: =ROUND(K37/O37*1000,1) -> 16.6
A30: 26 | B30: 20.6 | C30: 晴 | D30: 166478 | E30: 111.64 | F30: 225 | G30: 4852 | H30: 49300 | I30: 0 | J30: 0 | K30: 2130 | L30: 768 | M30: 2.7 | N30: 5389 | O30: =D30-N30 -> 161089 | Q30: 氯酸钠 | R30: 用量（kg） | S30: =处理量!L37 -> 31920
A31: 27 | B31: 19.7 | C31: 雨 | D31: 164693 | E31: 228.22 | F31: 225 | G31: 4790 | H31: 52200 | I31: 0 | J31: 0 | K31: 1846 | L31: 672 | M31: 2.29 | N31: 5619 | O31: =D31-N31 -> 159074 | R31: 单耗（g/m3） | S31: =ROUND(L37/O37*1000,2) -> 5.91
A32: 28 | B32: 20.6 | C32: 晴 | D32: 169776 | E32: 203.62 | F32: 250 | G32: 4788 | H32: 53400 | I32: 5364 | J32: 26 | K32: 3195 | L32: 1128 | M32: 2.44 | N32: 5507 | O32: =D32-N32 -> 164269 | Q32: 乙酸 | R32: 用量（T） | S32: =M37 -> 91.62
A33: 29 | B33: 20.9 | C33: 晴 | D33: 170885 | E33: 121.6 | F33: 150 | G33: 4782 | H33: 52600 | I33: 7392 | J33: 35 | K33: 3053 | L33: 1104 | M33: 2.7 | N33: 5515 | O33: =D33-N33 -> 165370 | R33: 单耗（g/m3） | S33: =ROUND(S32/O37*1000000,2) -> 16.97
A34: 30 | B34: 21.6 | C34: 晴 | D34: 172293 | E34: 125.88 | F34: 100 | G34: 3712 | H34: 51400 | I34: 8640 | J34: 36 | K34: 4047 | L34: 1416 | M34: 2.61 | N34: 5495 | O34: =D34-N34 -> 166798
A35: 31 | B35: 19.6 | C35: 阴 | D35: 181679 | E35: 120 | F35: 100 | G35: 4710 | H35: 52500 | I35: 8424 | J35: 36 | K35: 2130 | L35: 792 | M35: 3.11 | N35: 5500 | O35: =D35-N35 -> 176179
A36: 平均 | B36: =AVERAGE(B5:B35) -> 18.645161 | C36: / | D36: =AVERAGE(D5:D35) -> 179581.35 | E36: =AVERAGE(E5:E35) -> 190.58194 | F36: =AVERAGE(F5:F35) -> 191.93548 | G36: =AVERAGE(G5:G35) -> 4746.2581 | H36: =AVERAGE(H5:H35) -> 52209.677 | I36: =AVERAGE(I5:I35) -> 7228.2581 | J36: =AVERAGE(J5:J35) -> 26.193548 | K36: =AVERAGE(K5:K35) -> 2892.6774 | ... N36: =AVERAGE(N5:N35) -> 5377.8065 | O36: =D36-N36 -> 174203.55
A37: 合计 | B37: / | C37: / | D37: =SUM(D5:D35) -> 5567022 | E37: =SUM(E5:E35) -> 5908.04 | F37: =SUM(F5:F35) -> 5950 | G37: / | H37: =SUM(H5:H35) -> 1618500 | I37: =SUM(I5:I35) -> 224076 | J37: =SUM(J5:J35) -> 812 | K37: =SUM(K5:K35) -> 89673 | L37: =SUM(L5:L35) -> 31920 | M37: =SUM(M5:M35) -> 91.62 | N37: =SUM(N5:N35) -> 166712 | O37: =SUM(O5:O35) -> 5400310
A38: 审核： | G38: 制表： | N38: 制表时间: | O38: 44291
K39: =K37*0.31 -> 27798.63
N40: 最大 | O40: =MAX(O5:O35) -> 207229
...

Sheet 汇总
A1: 常州市深水江边污水处理有限公司污水运行月报表
A2: 44256
A3: 污 水 处 理 | B3: 污水处理量 | C3: =处理量!O37 -> 5400310 | D3: 污 泥 处 理 | E3: 脱水污泥量（T） | F3: =处理量!E37 -> 5908.04 | G3: 水 电 用 量 | H3: 用电量（度） | J3: =处理量!H37 -> 1618500 | K3: 污 水 电 单 耗 | L3: 污水（度/m3） | M3: =J3/C3 -> 0.29970502 | P3: 除臭用水量 | Q3: 1862.3 | R3: =J5-Q3 -> 4035.7
B4: 日均处理量 | C4: =处理量!O36 -> 174203.55 | E4: 絮凝剂用量（kg） | F4: =处理量!F37 -> 5950 | H4: 日均用电量（度） | J4: =J3/M15 -> 52209.677 | L4: CODcr（度/kg） | M4: =J3/I12 -> 1.6431196 | P4: 除臭用电量 | Q4: 42248
E5: 含水率（%） | F5: =进出水!T38 -> 77.83 | H5: 用水量（T） | J5: 5898
B6: 最高日处理量 | C6: =处理量!O40 -> 207229 | E6: 絮凝剂单耗（kg/T） | F6: =F4/(F3*(100-F5)/100) -> 4.542635 | G6: 消 毒 剂 | H6: 工业合成盐酸（T） | J6: =处理量!K37/1000 -> 89.673 | L6: BOD5（度/kg） | M6: =J3/I13 -> 2.8274058
B7: 最低日处理量 | C7: =处理量!O41 -> 117541 | E7: 产泥率(g/m３) | F7: =F3*(100-F5)/100*1000/(C3/1000) -> 242.54394 | H7: 药单耗(g/m3) | J7: =J6*1000/(C3/1000) -> 16.605158 | L7: SS（度/kg） | M7: =J3/I14 -> 2.2900972
B8: 负荷率（%） | C8: =C4/200000*100 -> 87.101774 | D8: 混 凝 剂 | E8: 混凝剂用量（T） | F8: =处理量!I37/1000 -> 224.076 | H8: 氯酸钠（T） | J8: =处理量!L37/1000 -> 31.92 | K8: 乙酸-厌缺氧段 | L8: 投加量（吨） | M8: =处理量!M37 -> 91.62
B9: 进水水温(℃) | C9: =处理量!B36 -> 18.645161 | E9: 药单耗(g/m3) | F9: =F8*1000/(C3/1000) -> 41.493174 | H9: 药单耗(g/m3) | J9: =J8*1000/(C3/1000) -> 5.9107718 | L9: 药单耗(g/m3) | M9: =M8*1000000/C3 -> 16.965693
A10: 处 理 质 量 | B10: 项目 | C10: 进水 | E10: 出水 | G10: 去除率（%） | I10: 去除总量（kg) | K10: 乙酸-提标段 | L10: 投加量（吨） | M10: 0
L11: 药单耗(g/m3) | M11: 0
B12: CODcr | C12: =进出水!B38 -> 211 | E12: =进出水!N38 -> 28.6 | G12: =(C12-E12)/C12*100 -> 86.445498 | I12: =$C$3*(C12-E12)/1000 -> 985016.54 | K12: 污 泥 去 向 | L12: 国电 | M12: =处理量!S16 -> 2836.5 | P12: =ROUND(E12,1) -> 28.6 | Q12: =C3 -> 5400310 | R12: =P12*Q12/1000000 -> 154.44887 | S12: CODcr
B13: BOD5 | C13: =进出水!C38 -> 107 | E13: =[1]进出水!O38 -> <2 | G13: =(C13-1)/C13*100 -> 99.065421 | I13: =$C$3*(C13-1)/1000 -> 572432.86 | L13: 英科环境 | M13: =处理量!R16 -> 1610.48 | P13: 1 | Q13: =Q12 -> 5400310 | R13: =P13*Q13/1000000 -> 5.40031 | S13: BOD5
B14: SS | C14: =进出水!D38 -> 136 | E14: =进出水!P38 -> 5.13 | G14: =(C14-E14)/C14*100 -> 96.227941 | I14: =$C$3*(C14-E14)/1000 -> 706738.57 | L14: 其它 | M14: =处理量!T16 -> 1461.06 | P14: =ROUND(E14,1) -> 5.1 | Q14: =Q13 -> 5400310 | R14: =P14*Q14/1000000 -> 27.541581 | S14: SS
B15: TP | C15: =进出水!E38 -> 2.51 | E15: =进出水!Q38 -> 0.11 | G15: =(C15-E15)/C15*100 -> 95.61753 | I15: =$C$3*(C15-E15)/1000 -> 12960.744 | K15: 运 行 情 况 | L15: 应运行天数 | M15: 31 | P15: =ROUND(E15,1) -> 0.1 | Q15: =Q14 -> 5400310 | R15: =P15*Q15/1000000 -> 0.540031 | S15: TP
B16: TN | C16: =进出水!G38 -> 26.4 | E16: =进出水!S38 -> 7.42 | G16: =(C16-E16)/C16*100 -> 71.893939 | I16: =$C$3*(C16-E16)/1000 -> 102497.88 | L16: 实际运行天数 | M16: 31 | P16: =ROUND(E16,1) -> 7.4 | Q16: =Q15 -> 5400310 | R16: =P16*Q16/1000000 -> 39.962294 | S16: TN
B17: NH3-N | C17: =进出水!F38 -> 20.2 | E17: =进出水!R38 -> 0.52 | G17: =(C17-E17)/C17*100 -> 97.425743 | I17: =$C$3*(C17-E17)/1000 -> 106278.1 | L17: 达标排放天数 | M17: 31 | P17: =ROUND(E17,1) -> 0.5 | Q17: =Q16 -> 5400310 | R17: =P17*Q17/1000000 -> 2.700155 | S17: NH3-N
B18: 粪大肠菌群数 (个/L) | E18: <20 | L18: 运转率 | M18: 100
A19: 备注 | B19: 本月产生泥饼5908.04吨，其中运往常州市英科环境科技有限公司1610.48吨，国电常州发电有限公司2836.50吨，外运接种1461.06吨：常州市百丈污水处理有限公司105吨，常州龙宇颜料化学有限公司1140吨，江苏盈天化学有限公司75吨，富德（常州）能源化工发展有限公司111.06吨，天合光能股份有限公司硅片分公司30吨。
A21: 审核： 制表： 制表日期：2021/4/5

Sheet 进出水
A1: 常州市深水江边污水处理有限公司进出水水质、污泥含水率月报表
J3: 44256
A4: 日期 | B4: 进水 | H4: 二沉池出水 | N4: 总出水 | T4: 污泥含水率 | U4: 粪大肠菌群
B5: CODCr | C5: BOD5 | D5: SS | E5: TP | F5: NH3-N | G5: TN | H5: CODCr | I5: BOD5 | J5: SS | K5: TP | L5: NH3-N | M5: TN | N5: CODCr | O5: BOD5 | P5: SS | Q5: TP | R5: NH3-N | S5: TN
B6: （mg/L） | C6: （mg/L） | D6: （mg/L） | E6: （mg/L） | F6: （mg/L） | G6: （mg/L） | H6: （mg/L） | I6: （mg/L） | J6: （mg/L） | K6: （mg/L） | L6: （mg/L） | M6: （mg/L） | N6: （mg/L） | O6: （mg/L） | P6: （mg/L） | Q6: （mg/L） | R6: （mg/L） | S6: （mg/L） | T6: （%） | U6: (个/L)
A7: 1 | B7: 280 | C7: 137 | D7: 164 | E7: 2.39 | F7: 19.3 | G7: 25.4 | H7: 30 | I7: <2 | J7: 18 | K7: 0.51 | L7: 0.56 | M7: 7.21 | N7: 22 | O7: <2 | P7: 6 | Q7: 0.09 | R7: 0.4 | S7: 7.18 | T7: 77.8 | U7: <20 | W7: =1-S7/G7 -> 0.71732283
A8: 2 | B8: 146 | C8: 70.4 | D8: 80 | E8: 2.08 | F8: 19.2 | G8: 24.7 | H8: 33 | I8: 2.17 | J8: 16 | K8: 0.54 | L8: 0.97 | M8: 8.54 | N8: 24 | O8: <2 | P8: 5 | Q8: 0.12 | R8: 0.44 | S8: 8.28 | T8: 77.6 | U8: <20 | W8: =1-S8/G8 -> 0.66477733
A9: 3 | B9: 174 | C9: 90.4 | D9: 92 | E9: 2.08 | F9: 18.6 | G9: 23.6 | H9: 38 | I9: 2.08 | J9: 17 | K9: 0.55 | L9: 0.7 | M9: 7.61 | N9: 29 | O9: <2 | P9: 5 | Q9: 0.19 | R9: 0.56 | S9: 7.16 | T9: 78 | U9: <20 | W9: =1-S9/G9 -> 0.69661017
A10: 4 | B10: 176 | C10: 86.2 | D10: 88 | E10: 2.69 | F10: 23.4 | G10: 29 | H10: 46 | I10: 2.38 | J10: 18 | K10: 0.47 | L10: 0.89 | M10: 7.46 | N10: 27 | O10: <2 | P10: 5 | Q10: 0.17 | R10: 0.48 | S10: 7.44 | T10: 77.7 | U10: 20 | W10: =1-S10/G10 -> 0.74344828
A11: 5 | B11: 243 | C11: 126 | D11: 166 | E11: 2.2 | F11: 20.1 | G11: 26.1 | H11: 38 | I11: 2.17 | J11: 18 | K11: 0.56 | L11: 0.79 | M11: 6.92 | N11: 27 | O11: <2 | P11: 6 | Q11: 0.17 | R11: 0.48 | S11: 6 | T11: 78.2 | U11: 50 | W11: =1-S11/G11 -> 0.77011494
A12: 6 | B12: 155 | C12: 77.4 | D12: 96 | E12: 2.59 | F12: 23 | G12: 28.8 | H12: 38 | I12: 2.09 | J12: 17 | K12: 0.56 | L12: 0.77 | M12: 6.67 | N12: 26 | O12: <2 | P12: 5 | Q12: 0.12 | R12: 0.48 | S12: 6.44 | T12: 77.5 | W12: =1-S12/G12 -> 0.77638889
A13: 7 | B13: 238 | C13: 120 | D13: 196 | E13: 2.84 | F13: 19 | G13: 25.4 | H13: 44 | I13: 2.98 | J13: 18 | K13: 0.41 | L13: 0.79 | M13: 7.06 | N13: 29 | O13: <2 | P13: 5 | Q13: 0.12 | R13: 0.56 | S13: 6.3 | T13: 77.9 | W13: =1-S13/G13 -> 0.7519685
A14: 8 | B14: 238 | C14: 117 | D14: 190 | E14: 4.55 | F14: 22.1 | G14: 29.9 | H14: 45 | I14: 2.15 | J14: 19 | K14: 0.41 | L14: 0.87 | M14: 7.41 | N14: 31 | O14: <2 | P14: 5 | Q14: 0.12 | R14: 0.56 | S14: 7.31 | T14: 77.7 | U14: <20 | W14: =1-S14/G14 -> 0.75551839
A15: 9 | B15: 221 | C15: 113 | D15: 170 | E15: 2.15 | F15: 19 | G15: 25.3 | H15: 35 | I15: <2 | J15: 15 | K15: 0.58 | L15: 0.66 | M15: 8.1 | N15: 28 | O15: <2 | P15: 5 | Q15: 0.11 | R15: 0.52 | S15: 7.85 | T15: 78.4 | U15: 20 | W15: =1-S15/G15 -> 0.68972332
A16: 10 | B16: 166 | C16: 86.7 | D16: 98 | E16: 2.3 | F16: 25 | G16: 31.3 | H16: 41 | I16: 2.65 | J16: 17 | K16: 0.52 | L16: 0.73 | M16: 7.75 | N16: 29 | O16: <2 | P16: 5 | Q16: 0.12 | R16: 0.5 | S16: 7.56 | T16: 78.2 | U16: 50 | W16: =1-S16/G16 -> 0.75846645
A17: 11 | B17: 234 | C17: 115 | D17: 166 | E17: 2.45 | F17: 21.1 | G17: 26.2 | H17: 46 | I17: 2.78 | J17: 20 | K17: 0.44 | L17: 0.74 | M17: 7.8 | N17: 25 | O17: <2 | P17: 5 | Q17: 0.09 | R17: 0.53 | S17: 7.46 | T17: 77.8 | U17: <20 | W17: =1-S17/G17 -> 0.71526718
A18: 12 | B18: 260 | C18: 127 | D18: 132 | E18: 3.13 | F18: 20 | G18: 29.2 | H18: 44 | I18: 2.12 | J18: 16 | K18: 0.54 | L18: 0.76 | M18: 7.76 | N18: 27 | O18: <2 | P18: 5 | Q18: 0.09 | R18: 0.45 | S18: 7.26 | T18: 77.4 | U18: 20 | W18: =1-S18/G18 -> 0.75136986
A19: 13 | B19: 175 | C19: 89.2 | D19: 82 | E19: 2.45 | F19: 22.9 | G19: 28.4 | H19: 40 | I19: <2 | J19: 20 | K19: 0.56 | L19: 0.6 | M19: 8 | N19: 28 | O19: <2 | P19: 5 | Q19: 0.08 | R19: 0.42 | S19: 7.16 | T19: 77.6 | W19: =1-S19/G19 -> 0.74788732
A20: 14 | B20: 138 | C20: 72.4 | D20: 86 | E20: 2.5 | F20: 23 | G20: 27.8 | H20: 45 | I20: 2.66 | J20: 20 | K20: 0.48 | L20: 0.86 | M20: 11.9 | N20: 28 | O20: <2 | P20: 5 | Q20: 0.14 | R20: 0.5 | S20: 8.69 | T20: 78.2 | W20: =1-S20/G20 -> 0.68741007
A21: 15 | B21: 266 | C21: 135 | D21: 196 | E21: 2.92 | F21: 26.4 | G21: 32.7 | H21: 44 | I21: 2.56 | J21: 18 | K21: 0.57 | L21: 0.72 | M21: 7.61 | N21: 29 | O21: <2 | P21: 5 | Q21: 0.1 | R21: 0.55 | S21: 7.41 | T21: 77.9 | U21: <20 | W21: =1-S21/G21 -> 0.7733945
A22: 16 | B22: 212 | C22: 105 | D22: 148 | E22: 3.73 | F22: 25.8 | G22: 31.9 | H22: 42 | I22: 2.14 | J22: 19 | K22: 0.48 | L22: 1.62 | M22: 9.36 | N22: 31 | O22: <2 | P22: 5 | Q22: 0.16 | R22: 0.97 | S22: 8.27 | T22: 77.8 | U22: <20 | W22: =1-S22/G22 -> 0.74075235
A23: 17 | B23: 224 | C23: 116 | D23: 160 | E23: 3.16 | F23: 27.3 | G23: 33.6 | H23: 34 | I23: <2 | J23: 16 | K23: 0.52 | L23: 0.53 | M23: 7.74 | N23: 25 | O23: <2 | P23: 5 | Q23: 0.15 | R23: 0.38 | S23: 7.52 | T23: 77.5 | U23: <20 | W23: =1-S23/G23 -> 0.77619048
A24: 18 | B24: 146 | C24: 75.8 | D24: 98 | E24: 2.37 | F24: 16 | G24: 23.6 | H24: 40 | I24: <2 | J24: 14 | K24: 0.53 | L24: 0.72 | M24: 7.97 | N24: 27 | O24: <2 | P24: 5 | Q24: 0.11 | R24: 0.54 | S24: 7.62 | T24: 77.8 | U24: <20 | W24: =1-S24/G24 -> 0.67711864
A25: 19 | B25: 210 | C25: 111 | D25: 132 | E25: 2.32 | F25: 18.7 | G25: 23.8 | H25: 44 | I25: 2.14 | J25: 18 | K25: 0.51 | L25: 0.62 | M25: 7.72 | N25: 30 | O25: <2 | P25: 5 | Q25: 0.08 | R25: 0.45 | S25: 7.28 | T25: 77.9 | U25: <20 | W25: =1-S25/G25 -> 0.69411765
A26: 20 | B26: 242 | C26: 120 | D26: 106 | E26: 2.52 | F26: 17.4 | G26: 23.4 | H26: 46 | I26: 2.77 | J26: 20 | K26: 0.56 | L26: 0.7 | M26: 8.32 | N26: 33 | O26: <2 | P26: 5 | Q26: 0.08 | R26: 0.46 | S26: 7.82 | T26: 78.1 | W26: =1-S26/G26 -> 0.66581197
A27: 21 | B27: 224 | C27: 116 | D27: 168 | E27: 1.9 | F27: 18.2 | G27: 25.3 | H27: 37 | I27: <2 | J27: 16 | K27: 0.52 | L27: 0.6 | M27: 6.38 | N27: 28 | O27: <2 | P27: 5 | Q27: 0.09 | R27: 0.44 | S27: 6.24 | T27: 77.8 | W27: =1-S27/G27 -> 0.75335968
A28: 22 | B28: 130 | C28: 65.2 | D28: 80 | E28: 2.38 | F28: 23.9 | G28: 29.6 | H28: 36 | I28: <2 | J28: 16 | K28: 0.5 | L28: 0.69 | M28: 7.82 | N28: 26 | O28: <2 | P28: 5 | Q28: 0.08 | R28: 0.45 | S28: 7.38 | T28: 77.7 | U28: <20 | W28: =1-S28/G28 -> 0.75067568
A29: 23 | B29: 259 | C29: 137 | D29: 136 | E29: 3.11 | F29: 23.7 | G29: 29.2 | H29: 40 | I29: <2 | J29: 14 | K29: 0.51 | L29: 0.8 | M29: 8.47 | N29: 28 | O29: <2 | P29: 5 | Q29: 0.07 | R29: 0.73 | S29: 7.54 | T29: 78 | U29: <20 | W29: =1-S29/G29 -> 0.74178082
A30: 24 | B30: 226 | C30: 115 | D30: 118 | E30: 1.92 | F30: 17.1 | G30: 22.6 | H30: 39 | I30: <2 | J30: 13 | K30: 0.56 | L30: 0.66 | M30: 9.36 | N30: 26 | O30: <2 | P30: 5 | Q30: 0.08 | R30: 0.45 | S30: 8.47 | T30: 77.8 | U30: <20 | W30: =1-S30/G30 -> 0.62522124
A31: 25 | B31: 249 | C31: 125 | D31: 148 | E31: 1.8 | F31: 15 | G31: 21.2 | H31: 42 | I31: 2.14 | J31: 17 | K31: 0.56 | L31: 0.62 | M31: 7.87 | N31: 30 | O31: <2 | P31: 5 | Q31: 0.08 | R31: 0.6 | S31: 7.7 | T31: 77.5 | U31: <20 | W31: =1-S31/G31 -> 0.63679245
A32: 26 | B32: 152 | C32: 80.2 | D32: 60 | E32: 1.69 | F32: 15.3 | G32: 21.6 | H32: 49 | I32: <2 | J32: 19 | K32: 0.53 | L32: 0.6 | M32: 6.48 | N32: 30 | O32: <2 | P32: 5 | Q32: 0.09 | R32: 0.44 | S32: 6.38 | T32: 77.9 | U32: <20 | W32: =1-S32/G32 -> 0.70462963
A33: 27 | B33: 232 | C33: 118 | D33: 146 | E33: 2.32 | F33: 16.7 | G33: 22.9 | H33: 45 | I33: <2 | J33: 18 | K33: 0.52 | L33: 0.61 | M33: 8.22 | N33: 31 | O33: <2 | P33: 5 | Q33: 0.1 | R33: 0.54 | S33: 7.2 | T33: 77.5 | W33: =1-S33/G33 -> 0.68558952
A34: 28 | B34: 270 | C34: 140 | D34: 240 | E34: 3.56 | F34: 15.7 | G34: 22.6 | H34: 54 | I34: 2.33 | J34: 19 | K34: 0.41 | L34: 0.77 | M34: 7.67 | N34: 33 | O34: <2 | P34: 6 | Q34: 0.11 | R34: 0.54 | S34: 7.6 | T34: 77.9 | W34: =1-S34/G34 -> 0.66371681
A35: 29 | B35: 320 | C35: 170 | D35: 252 | E35: 2.08 | F35: 20.4 | G35: 26.9 | H35: 48 | I35: <2 | J35: 19 | K35: 0.45 | L35: 0.68 | M35: 8.22 | N35: 34 | O35: <2 | P35: 5 | Q35: 0.13 | R35: 0.6 | S35: 8.17 | T35: 78.2 | U35: <20 | W35: =1-S35/G35 -> 0.69628253
A36: 30 | B36: 190 | C36: 97.1 | D36: 110 | E36: 2 | F36: 17.7 | G36: 24.9 | H36: 54 | I36: 2.98 | J36: 20 | K36: 0.44 | L36: 0.77 | M36: 8.67 | N36: 31 | O36: <2 | P36: 5 | Q36: 0.11 | R36: 0.58 | S36: 7.98 | T36: 77.8 | U36: <20 | W36: =1-S36/G36 -> 0.67951807
A37: 31 | B37: 152 | C37: 77.4 | D37: 120 | E37: 1.55 | F37: 16.1 | G37: 21.8 | H37: 46 | I37: 2.03 | J37: 20 | K37: 0.55 | L37: 0.71 | M37: 7.87 | N37: 34 | O37: <2 | P37: 6 | Q37: 0.15 | R37: 0.54 | S37: 7.5 | T37: 77.7 | U37: <20 | W37: =1-S37/G37 -> 0.6559633
A38: 平均 | B38: =ROUND(AVERAGE(B7:B37),0) -> 211 | C38: =ROUND(AVERAGE(C7:C37),0) -> 107 | D38: =ROUND(AVERAGE(D7:D37),0) -> 136 | E38: =ROUND(AVERAGE(E7:E37),2) -> 2.51 | F38: =ROUND(AVERAGE(F7:F37),1) -> 20.2 | G38: =ROUND(AVERAGE(G7:G37),1) -> 26.4 | H38: =ROUND(AVERAGE(H7:H37),1) -> 42 | I38: =ROUND(AVERAGE(I7:I37),2) -> 2.39 | J38: =ROUND(AVERAGE(J7:J37),2) -> 17.58 | K38: =ROUND(AVERAGE(K7:K37),2) -> 0.51 | L38: =ROUND(AVERAGE(L7:L37),2) -> 0.75 | M38: =ROUND(AVERAGE(M7:M37),1) -> 7.9 | N38: =ROUND(AVERAGE(N7:N37),1) -> 28.6 | O38: <2 | P38: =ROUND(AVERAGE(P7:P37),2) -> 5.13 | Q38: =ROUND(AVERAGE(Q7:Q37),2) -> 0.11 | R38: =ROUND(AVERAGE(R7:R37),2) -> 0.52 | S38: =ROUND(AVERAGE(S7:S37),2) -> 7.42 | T38: =ROUND(AVERAGE(T7:T37),2) -> 77.83 | U38: <20
A39: 审核： | J39: 制表： | Q39: 制表时间：2021/4/5
B41: 项目 | C41: 进水（mg/L) | D41: 最大值 | E41: 最小值（mg/L) | F41: 出水（mg/L) | G41: 最大值 | H41: 最小值（mg/L) | I41: 去除率
D42: （mg/L) | G42: （mg/L) | I42: （%）
...

Sheet 设备
A1: 常州市深水江边污水处理有限公司设备运行月报表
A2: 44256
A3: 运行 工段 | B3: 设备名称 | C3: 编号 | D3: 运行 天数 | E3: 定时 | F3: 额定运行时间 | G3: 实际运行时间 | H3: 利用率 | I3: 完好率 | J3: 维修、保养情况
D5: （d） | E5: （h/d） | F5: （h） | G5: （h） | H5: % | I5: %
A6: 预 处 理 | B6: 粗格栅机 | C6: 1# | D6: 31 | E6: 2 | F6: 62 | G6: 62 | H6: 1 | I6: 1
C7: 2# | D7: 31 | E7: 2 | F7: 62 | G7: 62 | H7: 1 | I7: 1
B8: 螺旋输送机 | C8: / | D8: 31 | E8: 2 | F8: 62 | G8: 62 | H8: 1 | I8: 1
B9: 螺旋压榨机 | C9: / | D9: 31 | E9: 2 | F9: 62 | G9: 62 | H9: 1 | I9: 1
B10: 进水泵 | C10: 1# | D10: 31 | E10: 24 | F10: 744 | G10: 576 | H10: 0.77419355 | I10: 1
C11: 2# | D11: 31 | E11: 24 | F11: 744 | G11: 404 | H11: 0.54301075 | I11: 1
C12: 3# | D12: 31 | E12: 24 | F12: 744 | G12: 52 | H12: 0.069892473 | I12: 1
C13: 4# | D13: 31 | E13: 24 | F13: 744 | G13: 343 | H13: 0.46102151 | I13: 1
C14: 5# | D14: 31 | E14: 24 | F14: 744 | G14: 738 | H14: 0.99193548 | I14: 1
B15: 细格栅机 | C15: 1# | D15: 31 | E15: 2.4 | F15: 74.4 | G15: 74.4 | H15: 1 | I15: 1
C16: 2# | D16: 31 | E16: 2.4 | F16: 74.4 | G16: 74.4 | H16: 1 | I16: 1
C17: 3# | D17: 31 | E17: 2.4 | F17: 74.4 | G17: 74.4 | H17: 1 | I17: 1
C18: 4# | D18: 31 | E18: 2.4 | F18: 74.4 | G18: 74.4 | H18: 1 | I18: 1
C19: 5# | D19: 31 | E19: 2.4 | F19: 74.4 | G19: 74.4 | H19: 1 | I19: 1
C20: 6# | D20: 31 | E20: 2.4 | F20: 74.4 | G20: 74.4 | H20: 1 | I20: 1
B21: 螺旋输送机 | C21: 1# | D21: 31 | E21: 0.5 | F21: 15.5 | G21: 15.5 | H21: 1 | I21: 1
C22: 2# | D22: 31 | E22: 0.5 | F22: 15.5 | G22: 15.5 | H22: 1 | I22: 1
B23: 螺旋压榨机 | C23: 1# | D23: 31 | E23: 0.5 | F23: 15.5 | G23: 15.5 | H23: 1 | I23: 1
C24: 2# | D24: 31 | E24: 0.5 | F24: 15.5 | G24: 15.5 | H24: 1 | I24: 1
B25: 搅拌机 | C25: 1# | D25: 31 | E25: 24 | F25: 744 | G25: 0 | H25: 0 | I25: 0
B26: 砂水分离机 | C26: 1# | D26: 31 | E26: 0.5 | F26: 15.5 | G26: 15.5 | H26: 1 | I26: 1
B27: 搅拌机 | C27: 2# | D27: 31 | E27: 24 | F27: 744 | G27: 744 | H27: 1 | I27: 1
B28: 砂水分离机 | C28: 2# | D28: 31 | E28: 0.5 | F28: 15.5 | G28: 15.5 | H28: 1 | I28: 1
B29: 搅拌机 | C29: 3# | D29: 31 | E29: 24 | F29: 744 | G29: 744 | H29: 1 | I29: 1
B30: 砂水分离机 | C30: 3# | D30: 31 | E30: 0.5 | F30: 15.5 | G30: 15.5 | H30: 1 | I30: 1
B31: 搅拌机 | C31: 4# | D31: 31 | E31: 24 | F31: 744 | G31: 0 | H31: 0 | I31: 0
B32: 砂水分离机 | C32: 4# | D32: 31 | E32: 0.5 | F32: 15.5 | G32: 15.5 | H32: 1 | I32: 1
B33: 高压鼓风机 | C33: 1# | D33: 31 | E33: 24 | F33: 744 | G33: 268 | H33: 0.36021505 | I33: 1 | J33: 25日保养
C34: 2# | D34: 31 | E34: 24 | F34: 744 | G34: 78 | H34: 0.10483871 | I34: 1 | J34: 25日保养
C35: 3# | D35: 31 | E35: 24 | F35: 744 | G35: 486 | H35: 0.65322581 | I35: 1 | J35: 25日保养
C36: 4# | D36: 31 | E36: 24 | F36: 744 | G36: 282 | H36: 0.37903226 | I36: 1 | J36: 25日保养
C37: 5# | D37: 31 | E37: 24 | F37: 744 | G37: 406 | H37: 0.54569892 | I37: 1 | J37: 3-12日电机保养、25日保养
A38: 审核： | E38: 制表： | H38: 制表时间：2021/4/2
A46: 常州市深水江边污水处理有限公司设备运行月报表
A47: 44256
A48: 运行 工段 | B48: 设备名称 | C48: 编号 | D48: 运行 天数 | E48: 定时 | F48: 额定运行时间 | G48: 实际运行时间 | H48: 利用率 | I48: 完好率 | J48: 维修、保养情况
...

Sheet 仪表
A1: 常州市深水江边污水处理有限公司污水运行月报表
D2: 44256
A3: 仪表名称 | B3: 编号 | C3: 规格型号 | D3: 安装位置 | E3: 运行情况 | F3: 标定、校准情况 | G3: 备注
A4: 一期溶氧仪 | B4: 1#（南） | C4: 美商生化T-10 | D4: 一期生反池 | E4: 正常 | F4: 校准 | G4: 2021-03-05 2021-03-12 2021-03-19 2021-03-26
B5: 2#（南） | C5: 美商生化T-10 | D5: 一期生反池 | E5: 正常 | F5: 校准 | G5: =G4 -> 2021-03-05 2021-03-12 2021-03-19 2021-03-26
B6: 1#（北） | C6: 美商生化T-10 | D6: 一期生反池 | E6: 正常 | F6: 校准 | G6: =G5 -> 2021-03-05 2021-03-12 2021-03-19 2021-03-26
B7: 2#（北） | C7: 美商生化T-10 | D7: 一期生反池 | E7: 正常 | F7: 校准 | G7: =G6 -> 2021-03-05 2021-03-12 2021-03-19 2021-03-26
A8: 一期污泥浓度计 | B8: 1#（南） | C8: E+H | D8: 一期生反池 | E8: 正常 | F8: 校准 | G8: =G7 -> 2021-03-05 2021-03-12 2021-03-19 2021-03-26
B9: 2#（南） | C9: E+H | D9: 一期生反池 | E9: 正常 | F9: 校准 | G9: =G8 -> 2021-03-05 2021-03-12 2021-03-19 2021-03-26
B10: 1#（北） | C10: E+H | D10: 一期生反池 | E10: 正常 | F10: 校准 | G10: =G9 -> 2021-03-05 2021-03-12 2021-03-19 2021-03-26
B11: 2#（北） | C11: E+H | D11: 一期生反池 | E11: 正常 | F11: 校准 | G11: =G10 -> 2021-03-05 2021-03-12 2021-03-19 2021-03-26
A12: 进水PH计 | B12: 1# | C12: 哈希 | D12: 一期旋流沉砂池 | E12: 正常 | F12: 标定 | G12: =G11 -> 2021-03-05 2021-03-12 2021-03-19 2021-03-26
A13: 二期溶氧仪 | B13: 1#（南） | C13: 哈希LDO | D13: 二期生反池 | E13: 正常 | F13: 校准 | G13: =G12 -> 2021-03-05 2021-03-12 2021-03-19 2021-03-26
B14: 2#（南） | C14: 哈希LDO | D14: 二期生反池 | E14: 正常 | F14: 校准 | G14: =G13 -> 2021-03-05 2021-03-12 2021-03-19 2021-03-26
B15: 1#（北） | C15: 哈希LDO | D15: 二期生反池 | E15: 正常 | F15: 校准 | G15: =G14 -> 2021-03-05 2021-03-12 2021-03-19 2021-03-26
B16: 2#（北） | C16: 哈希LDO | D16: 二期生反池 | E16: 正常 | F16: 校准 | G16: =G15 -> 2021-03-05 2021-03-12 2021-03-19 2021-03-26
A17: 二期污泥浓度计 | B17: 1#（南） | C17: 哈希TXPRO-2 | D17: 二期生反池 | E17: 正常 | F17: 校准 | G17: =G16 -> 2021-03-05 2021-03-12 2021-03-19 2021-03-26
B18: 2#（南） | C18: E+H | D18: 二期生反池 | E18: 正常 | F18: 校准 | G18: =G17 -> 2021-03-05 2021-03-12 2021-03-19 2021-03-26
B19: 1#（北） | C19: 哈希TXPRO-2 | D19: 二期生反池 | E19: 正常 | F19: 校准 | G19: =G18 -> 2021-03-05 2021-03-12 2021-03-19 2021-03-26
B20: 2#（北） | C20: E+H | D20: 二期生反池 | E20: 正常 | F20: 校准 | G20: =G19 -> 2021-03-05 2021-03-12 2021-03-19 2021-03-26
A21: 审核： | D21: 制表： | F21: 制表日期：2021/4/5
A25: 常州市深水江边污水处理有限公司污水运行月报表
D26: =D2 -> 44256
A27: 仪表名称 | B27: 编号 | C27: 规格型号 | D27: 安装位置 | E27: 运行情况 | F27: 标定、校准情况 | G27: 备注
A28: 一期ORP | B28: 1#（南） | C28: E+H | D28: 一期生反池 | E28: 正常 | F28: 标定 | G28: 44258
B29: 2#（北） | C29: E+H | D29: 一期生反池 | E29: 正常 | F29: 标定 | G29: =G28 -> 44258
A30: 二期ORP | B30: 1#（南） | C30: 哈希 | D30: 二期生反池 | E30: 正常 | F30: 标定 | G30: =G29 -> 44258
B31: 2#（北） | C31: 哈希 | D31: 二期生反池 | E31: 正常 | F31: 标定 | G31: =G30 -> 44258
A32: 审核： | D32: 制表： | F32: =F21 -> 制表日期：2021/4/5

Sheet 实验数据
A1: 常州市深水江边污水处理有限公司实验数据汇总表
A3: 采样地点：一期北 | E3: 采样时间：2021-3-25
A4: 硝化实验 | E4: 反硝化实验 | G4: 释磷实验
A5: 时间节点 | B5: NO3-N(mg/l) | C5: NH3-N(mg/l) | D5: PO43-(mg/l) | E5: 时间节点 | F5: NO3-N(mg/l) | G5: 时间节点 | H5: PO43-(mg/l)
A6: 0分钟 | B6: 0.67671875 | C6: 5.4995346 | D6: 2.4375 | E6: 0分钟 | F6: 5.8354375 | G6: 0分钟 | H6: 1.605375
A7: 15分钟 | B7: 2.0970078 | C7: 3.4614824 | D7: 1.625 | E7: 15分钟 | F7: 4.0135995 | G7: 30分钟 | H7: 2.1666125
A8: 30分钟 | B8: 3.2265625 | C8: 1.6907919 | D8: 1.1779656 | E8: 30分钟 | F8: 2.85625 | G8: 60分钟 | H8: 2.4777188
A9: 60分钟 | B9: 5.2948794 | C9: 0.86384766 | D9: 0.78875 | E9: 45分钟 | F9: 2.0423047 | G9: 90分钟 | H9: 3.1131875
A10: MLSS(mg/l) | B10: 4564 | E10: 60分钟 | F10: 1.1936883 | G10: MLSS(mg/l) | H10: 4408
E11: 90分钟 | F11: 0.5729375
E12: MLSS(mg/l) | F12: 4616
A13: 审核： | D13: 制表： | G13: 制表日期：2021/4/5
