Workbook

Sheet 处理量
A1: 常州市深水江边污水处理有限公司污水处理运行月报表
A2: 2021年 5月
A3: 日 期 | B3: 水温 | C3: 天气 | D3: 日处理 水量 （m3） | E3: 污泥量（T） | H3: 药剂量 | I3: MLSS | J3: 电耗 | K3: 混凝剂 | L3: 絮凝剂 阴离子 （kg） | M3: 盐酸 | N3: 氯酸钠 | O3: 乙酸（吨） | Q3: 回用水 （m3） | R3: 实际水量（m3） | T3: 费用统计 | U3: 成本分析用 | W3: 单价 | X3: 单耗 | Y3: 之前价 | Z3: 最新时间
B4: 度 | C4: 状况 | E4: 国电 | F4: 英科环境 | G4: 其他 | H4: （Kg） | I4: （mg/l） | J4: ( 度 ) | K4: （Kg） | M4: （Kg） | N4: （Kg） | O4: 缺氧段 | P4: 提标段 | T4: 电量 | U4: =ROUND(J37*W4,2) -> 923549 | W4: 0.565 | X4: =J36/R36 -> 0.27055675 | Y4: 0.608 | Z4: 44197 | AB4: 污泥量合计
A5: 1 | B5: 23.5 | C5: 晴 | D5: 66552 | E5: 108.7 | F5: 0 | G5: 0 | H5: 100 | I5: 4396 | J5: 36600 | K5: 2760 | L5: 7 | M5: 2130 | N5: 792 | O5: 1.53 | P5: 0 | Q5: 5540 | R5: =D5-Q5 -> 61012 | T5: 聚丙烯酰阳离子 | U5: =H37*W5/1000 -> 133891 | W5: 28040 | X5: =H36/R36*1000 -> 0.79035146 | Y5: 28150 | Z5: 44287 | AB5: =E5+F5+G5 -> 108.7
A6: 2 | B6: 24.6 | C6: 晴 | D6: 143192 | E6: 106.6 | F6: 0 | G6: 0 | H6: 50 | I6: 4106 | J6: 50500 | K6: 20520 | L6: 34 | M6: 1278 | N6: 480 | O6: 2.49 | P6: 0 | Q6: 5529 | R6: =D6-Q6 -> 137663 | T6: 聚丙烯酰阴离子 | U6: =L37*W6/1000 -> 1965.6 | V6: =U5+U6 -> 135856.6 | W6: 10400 | X6: =L36/R36*1000 -> 0.031283021 | Y6: 5784.76 | Z6: 44256 | AB6: =E6+F6+G6 -> 106.6
A7: 3 | B7: 23.7 | C7: 晴 | D7: 162537 | E7: 36.8 | F7: 0 | G7: 0 | H7: 0 | I7: 4224 | J7: 47100 | K7: 4680 | L7: 10 | M7: 1136 | N7: 432 | O7: 2.44 | P7: 0 | Q7: 5437 | R7: =D7-Q7 -> 157100 | T7: 工业盐酸 | U7: =M37*W7/1000 -> 38193.03 | W7: 430 | X7: =M36/R36*1000 -> 14.70153 | Y7: 182 | Z7: 44228 | AB7: =E7+F7+G7 -> 36.8
A8: 4 | B8: 23.1 | C8: 阴 | D8: 213787 | E8: 0 | F8: 0 | G8: 0 | H8: 50 | I8: 4990 | J8: 53000 | K8: 0 | L8: 0 | M8: 1207 | N8: 456 | O8: 2.36 | P8: 0 | Q8: 5595 | R8: =D8-Q8 -> 208192 | T8: 工业氯酸钠 | U8: =N37*W8/1000 -> 185826.1 | V8: =U7+U8 -> 224019.13 | W8: 5826 | X8: =N36/R36*1000 -> 5.2793822 | Y8: 5507.8 | Z8: 44317 | AB8: =E8+F8+G8 -> 0
A9: 5 | B9: 23 | C9: 晴 | D9: 207994 | E9: 0 | F9: 0 | G9: 120 | H9: 200 | I9: 4986 | J9: 56200 | K9: 600 | L9: 3 | M9: 3053 | N9: 1080 | O9: 2.16 | P9: 0 | Q9: 5526 | R9: =D9-Q9 -> 202468 | T9: 混凝药剂 | U9: =K37*W9/1000 -> 23176.8 | W9: 348 | X9: =K36/R36*1000 -> 11.023541 | Y9: 370 | Z9: 44228 | AB9: =E9+F9+G9 -> 120
A10: 6 | B10: 22.8 | C10: 晴 | D10: 185971 | E10: 178.68 | F10: 0 | G10: 15 | H10: 200 | I10: 4428 | J10: 54300 | K10: 3120 | L10: 8 | M10: 4260 | N10: 1488 | O10: 2.15 | P10: 0 | Q10: 5528 | R10: =D10-Q10 -> 180443 | T10: 污泥外运 | U10: =T18 -> 88806.91 | V10: 计算见下表 | AB10: =E10+F10+G10 -> 193.68
A11: 7 | B11: 22.5 | C11: 晴 | D11: 184629 | E11: 165.36 | F11: 0 | G11: 0 | H11: 225 | I11: 4992 | J11: 53100 | K11: 1800 | L11: 2 | M11: 2840 | N11: 1080 | O11: 2.28 | P11: 0 | Q11: 5520 | R11: =D11-Q11 -> 179109 | T11: 自来水 | U11: =汇总!J5*4.21 -> 17383.09 | W11: 4.21 | AB11: =E11+F11+G11 -> 165.36
A12: 8 | B12: 22.6 | C12: 晴 | D12: 195393 | E12: 181.78 | F12: 0 | G12: 0 | H12: 200 | I12: 4726 | J12: 52400 | K12: 0 | L12: 0 | M12: 1562 | N12: 600 | O12: 2.16 | P12: 0 | Q12: 5528 | R12: =D12-Q12 -> 189865 | AB12: =E12+F12+G12 -> 181.78
A13: 9 | B13: 25.1 | C13: 晴 | D13: 192802 | E13: 184.44 | F13: 0 | G13: 0 | H13: 200 | I13: 5236 | J13: 56400 | K13: 3240 | L13: 2 | M13: 3053 | N13: 1080 | O13: 1.99 | P13: 0 | Q13: 5520 | R13: =D13-Q13 -> 187282 | U13: =U14/R37 -> 0.063402329 | AB13: =E13+F13+G13 -> 184.44
A14: 10 | B14: 25.5 | C14: 晴 | D14: 202452 | E14: 196.26 | F14: 0 | G14: 0 | H14: 225 | I14: 5064 | J14: 56800 | K14: 2040 | L14: 3 | M14: 4260 | N14: 1488 | O14: 1.74 | P14: 0 | Q14: 5520 | R14: =D14-Q14 -> 196932 | T14: 总药剂 | U14: =U5+U6+U7+U8+U9 -> 383052.53 | V14: 除磷药剂 | W14: =U6+U9 -> 25142.4 | AB14: =E14+F14+G14 -> 196.26
A15: 11 | B15: 23 | C15: 阴 | D15: 196494 | E15: 176.46 | F15: 0 | G15: 0 | H15: 200 | I15: 4802 | J15: 56900 | K15: 2280 | L15: 9 | M15: 4473 | N15: 1560 | O15: 2.78 | P15: 0 | Q15: 5512 | R15: =D15-Q15 -> 190982 | T15: 总泥量 | U15: 英科（吨） | V15: 国电（吨） | W15: 外运（吨） | AB15: =E15+F15+G15 -> 176.46
A16: 12 | B16: 22.5 | C16: 阴 | D16: 206094 | E16: 140.08 | F16: 0 | G16: 0 | H16: 200 | I16: 4582 | J16: 55800 | K16: 1200 | L16: 5 | M16: 2840 | N16: 1032 | O16: 2.75 | P16: 0 | Q16: 5520 | R16: =D16-Q16 -> 200574 | T16: =U16+V16+W16 -> 4075.04 | U16: =F37 -> 1023.04 | V16: =E37 -> 2872 | W16: =G37 -> 180 | AB16: =E16+F16+G16 -> 140.08
A17: 13 | B17: 22.3 | C17: 阴 | D17: 209679 | E17: 70.74 | F17: 88.9 | G17: 0 | H17: 125 | I17: 5580 | J17: 55900 | K17: 0 | L17: 0 | M17: 2627 | N17: 960 | O17: 2.36 | P17: 0 | Q17: 5584 | R17: =D17-Q17 -> 204095 | T17: 江边费用 | U17: 22.8 | V17: 22.8 | AB17: =E17+F17+G17 -> 159.64
A18: 14 | B18: 22.5 | C18: 阴 | D18: 213685 | E18: 91.58 | F18: 0 | G18: 0 | H18: 175 | I18: 4744 | J18: 56800 | K18: 0 | L18: 0 | M18: 2130 | N18: 768 | O18: 1.78 | P18: 0 | Q18: 5467 | R18: =D18-Q18 -> 208218 | T18: =U18+V18 -> 88806.91 | U18: =ROUND(U16*U17,2) -> 23325.31 | V18: =ROUND(V16*V17,2) -> 65481.6 | AB18: =E18+F18+G18 -> 91.58
A19: 15 | B19: 23.3 | C19: 晴 | D19: 212734 | E19: 179.3 | F19: 0 | G19: 0 | H19: 200 | I19: 4934 | J19: 57600 | K19: 0 | L19: 0 | M19: 1633 | N19: 600 | O19: 2.03 | P19: 0 | Q19: 5536 | R19: =D19-Q19 -> 207198 | T19: 排水承担 | V19: 0 | AB19: =E19+F19+G19 -> 179.3
A20: 16 | B20: 22.1 | C20: 晴 | D20: 214205 | E20: 180.42 | F20: 0 | G20: 0 | H20: 200 | I20: 4824 | J20: 53500 | K20: 600 | L20: 3 | M20: 3550 | N20: 1248 | O20: 2.25 | P20: 0 | Q20: 5515 | R20: =D20-Q20 -> 208690 | T20: =U20+V20 -> 0 | V20: =ROUND(V16*V19,2) -> 0 | AB20: =E20+F20+G20 -> 180.42
A21: 17 | B21: 23.5 | C21: 阴 | D21: 208911 | E21: 179.96 | F21: 17.44 | G21: 0 | H21: 225 | I21: 4966 | J21: 55600 | K21: 5640 | L21: 23 | M21: 4118 | N21: 1440 | O21: 2.78 | P21: 0 | Q21: 5538 | R21: =D21-Q21 -> 203373 | T21: 总运费 | U21: 总单价 | V21: =V17+V19 -> 22.8 | W21: 核对 | AB21: =E21+F21+G21 -> 197.4
A22: 18 | B22: 23 | C22: 阴 | D22: 209058 | E22: 172.06 | F22: 0 | G22: 0 | H22: 225 | I22: 4908 | J22: 53900 | K22: 3240 | L22: 11 | M22: 4189 | N22: 1488 | O22: 2.15 | P22: 0 | Q22: 5512 | R22: =D22-Q22 -> 203546 | T22: =T18+T20 -> 88806.91 | W22: =T16-E37-F37-G37 -> 2.2737368e-13 | AB22: =E22+F22+G22 -> 172.06
A23: 19 | B23: 22.8 | C23: 阴 | D23: 212964 | E23: 174.56 | F23: 0 | G23: 0 | H23: 125 | I23: 4478 | J23: 55000 | K23: 2280 | L23: 5 | M23: 3905 | N23: 1344 | O23: 2.12 | P23: 0 | Q23: 5528 | R23: =D23-Q23 -> 207436 | AB23: =E23+F23+G23 -> 174.56
A24: 20 | B24: 22.5 | C24: 阴 | D24: 214953 | E24: 83.44 | F24: 15.4 | G24: 0 | H24: 100 | I24: 4696 | J24: 50600 | K24: 1080 | L24: 3 | M24: 2840 | N24: 1008 | O24: 2.04 | P24: 0 | Q24: 5528 | R24: =D24-Q24 -> 209425 | T24: 絮凝剂 | U24: 用量（kg） | V24: =H37 -> 4775 | W24: =L37 -> 189 | AB24: =E24+F24+G24 -> 98.84
A25: 21 | B25: 23 | C25: 晴 | D25: 215073 | E25: 102.68 | F25: 0 | G25: 0 | H25: 100 | I25: 5024 | J25: 51600 | K25: 0 | L25: 0 | M25: 2272 | N25: 816 | O25: 2.12 | P25: 0 | Q25: 5536 | R25: =D25-Q25 -> 209537 | U25: 单耗（kg/T） | V25: =汇总!F6 -> 5.2640056 | W25: =W24/R37*1000 -> 0.031283021 | AB25: =E25+F25+G25 -> 102.68
A26: 22 | B26: 25.3 | C26: 晴 | D26: 216119 | E26: 72.94 | F26: 0 | G26: 15 | H26: 100 | I26: 4646 | J26: 53800 | K26: 0 | L26: 0 | M26: 1633 | N26: 600 | O26: 2.06 | P26: 0 | Q26: 5528 | R26: =D26-Q26 -> 210591 | T26: 混凝剂 | U26: 用量（kg） | V26: =K37 -> 66600 | AB26: =E26+F26+G26 -> 87.94
A27: 23 | B27: 21.8 | C27: 雨 | D27: 211660 | E27: 0 | F27: 85.08 | G27: 15 | H27: 75 | I27: 4422 | J27: 52100 | K27: 480 | L27: 2 | M27: 2982 | N27: 1080 | O27: 2.02 | P27: 0 | Q27: 5528 | R27: =D27-Q27 -> 206132 | U27: 单耗（g/m3） | V27: =ROUND(K37/R37*1000,1) -> 11 | AB27: =E27+F27+G27 -> 100.08
A28: 24 | B28: 23 | C28: 晴 | D28: 211857 | E28: 0 | F28: 86.32 | G28: 0 | H28: 150 | I28: 4716 | J28: 49700 | K28: 3120 | L28: 8 | M28: 3550 | N28: 1320 | O28: 2.17 | P28: 0 | Q28: 5528 | R28: =D28-Q28 -> 206329 | T28: 盐酸 | U28: 用量（kg） | V28: =M37 -> 88821 | AB28: =E28+F28+G28 -> 86.32
A29: 25 | B29: 25.2 | C29: 晴 | D29: 213010 | E29: 89.16 | F29: 0 | G29: 15 | H29: 125 | I29: 4494 | J29: 52700 | K29: 3240 | L29: 19 | M29: 3976 | N29: 1440 | O29: 2.23 | P29: 0 | Q29: 5544 | R29: =D29-Q29 -> 207466 | U29: 单耗（g/m3） | V29: =ROUND(M37/R37*1000,1) -> 14.7 | AB29: =E29+F29+G29 -> 104.16
A30: 26 | B30: 24 | C30: 雨 | D30: 213758 | E30: 0 | F30: 69.22 | G30: 0 | H30: 125 | I30: 4832 | J30: 49400 | K30: 2280 | L30: 12 | M30: 2982 | N30: 1080 | O30: 2.56 | P30: 0 | Q30: 5552 | R30: =D30-Q30 -> 208206 | T30: 氯酸钠 | U30: 用量（kg） | V30: =处理量!N37 -> 31896 | AB30: =E30+F30+G30 -> 69.22
A31: 27 | B31: 25 | C31: 晴 | D31: 211196 | E31: 0 | F31: 87.32 | G31: 0 | H31: 125 | I31: 4646 | J31: 49900 | K31: 1320 | L31: 10 | M31: 2627 | N31: 960 | O31: 2.14 | P31: 0 | Q31: 5536 | R31: =D31-Q31 -> 205660 | U31: 单耗（g/m3） | V31: =ROUND(N37/R37*1000,2) -> 5.28 | AB31: =E31+F31+G31 -> 87.32
A32: 28 | B32: 25 | C32: 晴 | D32: 216266 | E32: 0 | F32: 85 | G32: 0 | H32: 175 | I32: 4470 | J32: 49700 | K32: 0 | L32: 0 | M32: 2414 | N32: 888 | O32: 2.27 | P32: 0 | Q32: 5456 | R32: =D32-Q32 -> 210810 | T32: 乙酸 | U32: 用量（T） | V32: =O37 -> 68.7 | AB32: =E32+F32+G32 -> 85
A33: 29 | B33: 25.6 | C33: 晴 | D33: 217934 | E33: 0 | F33: 162.2 | G33: 0 | H33: 225 | I33: 4498 | J33: 51600 | K33: 720 | L33: 7 | M33: 1633 | N33: 600 | O33: 2.12 | P33: 0 | Q33: 5552 | R33: =D33-Q33 -> 212382 | U33: 单耗（g/m3） | V33: =ROUND(V32/R37*1000000,2) -> 11.37 | AB33: =E33+F33+G33 -> 162.2
A34: 30 | B34: 26.1 | C34: 晴 | D34: 217407 | E34: 0 | F34: 163.46 | G34: 0 | H34: 200 | I34: 4406 | J34: 53000 | K34: 0 | L34: 0 | M34: 3053 | N34: 1080 | O34: 2.61 | P34: 0 | Q34: 5552 | R34: =D34-Q34 -> 211855 | AB34: =E34+F34+G34 -> 163.46
A35: 31 | B35: 26 | C35: 阴 | D35: 214581 | E35: 0 | F35: 162.7 | G35: 0 | H35: 150 | I35: 4416 | J35: 53100 | K35: 360 | L35: 3 | M35: 4615 | N35: 1608 | O35: 2.06 | P35: 0 | Q35: 5536 | R35: =D35-Q35 -> 209045 | AB35: =E35+F35+G35 -> 162.7
A36: 平均 | B36: =AVERAGE(B5:B35) -> 23.674194 | C36: / | D36: =AVERAGE(D5:D35) -> 200417.65 | E36: =AVERAGE(E5:E35) -> 92.645161 | F36: =AVERAGE(F5:F35) -> 33.00129 | G36: =AVERAGE(G5:G35) -> 5.8064516 | H36: =AVERAGE(H5:H35) -> 154.03226 | I36: =AVERAGE(I5:I35) -> 4717.1613 | J36: =AVERAGE(J5:J35) -> 52729.032 | K36: =AVERAGE(K5:K35) -> 2148.3871 | ... Q36: =AVERAGE(Q5:Q35) -> 5526.8065 | R36: =D36-Q36 -> 194890.84
A37: 合计 | B37: / | C37: / | D37: =SUM(D5:D35) -> 6212947 | E37: =SUM(E5:E35) -> 2872 | F37: =SUM(F5:F35) -> 1023.04 | G37: =SUM(G5:G35) -> 180 | H37: =SUM(H5:H35) -> 4775 | I37: / | J37: =SUM(J5:J35) -> 1634600 | K37: =SUM(K5:K35) -> 66600 | L37: =SUM(L5:L35) -> 189 | M37: =SUM(M5:M35) -> 88821 | N37: =SUM(N5:N35) -> 31896 | O37: =SUM(O5:O35) -> 68.7 | P37: =SUM(P5:P35) -> 0 | Q37: =SUM(Q5:Q35) -> 171331 | R37: =SUM(R5:R35) -> 6041616 | AB37: =SUM(AB5:AB36) -> 4075.04
A38: 审核： | I38: 制表： | Q38: 制表时间: | R38: 44350
M39: =M37*0.31 -> 27534.51
Q40: 最大 | R40: =MAX(R5:R35) -> 212382
...

Sheet 汇总
A1: 常州市深水江边污水处理有限公司污水运行月报表
A2: 44317
A3: 污 水 处 理 | B3: 污水处理量 | C3: =处理量!R37 -> 6041616 | D3: 污 泥 处 理 | E3: 脱水污泥量（T） | F3: =处理量!E37+处理量!F37+处理量!G37 -> 4075.04 | G3: 水 电 用 量 | H3: 用电量（度） | J3: =处理量!J37 -> 1634600 | K3: 污 水 电 单 耗 | L3: 污水（度/m3） | M3: =J3/C3 -> 0.27055675 | P3: 除臭用水量 | Q3: 1684.1 | R3: =J5-Q3 -> 2444.9
B4: 日均处理量 | C4: =处理量!R36 -> 194890.84 | E4: 絮凝剂用量（kg） | F4: =处理量!H37 -> 4775 | H4: 日均用电量（度） | J4: =J3/M15 -> 52729.032 | L4: CODcr（度/kg） | M4: =J3/I12 -> 1.4360762 | P4: 除臭用电量 | Q4: 42300
E5: 含水率（%） | F5: =进出水!T38 -> 77.74 | H5: 用水量（T） | J5: 4129
B6: 最高日处理量 | C6: =处理量!R40 -> 212382 | E6: 絮凝剂单耗（kg/T） | F6: =F4/(F3*(100-F5)/100) -> 5.2640056 | G6: 消 毒 剂 | H6: 工业合成盐酸（T） | J6: =处理量!M37/1000 -> 88.821 | L6: BOD5（度/kg） | M6: =J3/I13 -> 2.4156853
B7: 最低日处理量 | C7: =处理量!R41 -> 61012 | E7: 产泥率(g/m３) | F7: =F3*(100-F5)/100*1000/(C3/1000) -> 150.14259 | H7: 药单耗(g/m3) | J7: =J6*1000/(C3/1000) -> 14.70153 | L7: SS（度/kg） | M7: =J3/I14 -> 2.5633041
B8: 负荷率（%） | C8: =C4/200000*100 -> 97.445419 | D8: 混 凝 剂 | E8: 混凝剂用量（T） | F8: =处理量!K37/1000 -> 66.6 | H8: 氯酸钠（T） | J8: =处理量!N37/1000 -> 31.896 | K8: 乙酸-厌缺氧段 | L8: 投加量（吨） | M8: =处理量!O37 -> 68.7
B9: 进水水温(℃) | C9: =处理量!B36 -> 23.674194 | E9: 药单耗(g/m3) | F9: =F8*1000/(C3/1000) -> 11.023541 | H9: 药单耗(g/m3) | J9: =J8*1000/(C3/1000) -> 5.2793822 | L9: 药单耗(g/m3) | M9: =M8*1000000/C3 -> 11.37113
A10: 处 理 质 量 | B10: 项目 | C10: 进水 | E10: 出水 | G10: 去除率（%） | I10: 去除总量（kg) | K10: 乙酸-提标段 | L10: 投加量（吨） | M10: 0
L11: 药单耗(g/m3) | M11: 0
B12: CODcr | C12: =进出水!B38 -> 214 | E12: =进出水!N38 -> 25.6 | G12: =(C12-E12)/C12*100 -> 88.037383 | I12: =$C$3*(C12-E12)/1000 -> 1138240.5 | K12: 污 泥 去 向 | L12: 国电 | M12: =处理量!V16 -> 2872 | P12: =ROUND(E12,1) -> 25.6 | Q12: =C3 -> 6041616 | R12: =P12*Q12/1000000 -> 154.66537 | S12: CODcr
B13: BOD5 | C13: =进出水!C38 -> 113 | E13: =[1]进出水!O38 -> <2 | G13: =(C13-1)/C13*100 -> 99.115044 | I13: =$C$3*(C13-1)/1000 -> 676660.99 | L13: 英科环境 | M13: =处理量!U16 -> 1023.04 | P13: 1 | Q13: =Q12 -> 6041616 | R13: =P13*Q13/1000000 -> 6.041616 | S13: BOD5
B14: SS | C14: =进出水!D38 -> 111 | E14: =进出水!P38 -> 5.45 | G14: =(C14-E14)/C14*100 -> 95.09009 | I14: =$C$3*(C14-E14)/1000 -> 637692.57 | L14: 其它 | M14: =处理量!W16 -> 180 | P14: =ROUND(E14,1) -> 5.5 | Q14: =Q13 -> 6041616 | R14: =P14*Q14/1000000 -> 33.228888 | S14: SS
B15: TP | C15: =进出水!E38 -> 3.95 | E15: =进出水!Q38 -> 0.1 | G15: =(C15-E15)/C15*100 -> 97.468354 | I15: =$C$3*(C15-E15)/1000 -> 23260.222 | K15: 运 行 情 况 | L15: 应运行天数 | M15: 31 | P15: =ROUND(E15,1) -> 0.1 | Q15: =Q14 -> 6041616 | R15: =P15*Q15/1000000 -> 0.6041616 | S15: TP
B16: TN | C16: =进出水!G38 -> 24.3 | E16: =进出水!S38 -> 6.88 | G16: =(C16-E16)/C16*100 -> 71.687243 | I16: =$C$3*(C16-E16)/1000 -> 105244.95 | L16: 实际运行天数 | M16: 31 | P16: =ROUND(E16,1) -> 6.9 | Q16: =Q15 -> 6041616 | R16: =P16*Q16/1000000 -> 41.68715 | S16: TN
B17: NH3-N | C17: =进出水!F38 -> 18.1 | E17: =进出水!R38 -> 0.44 | G17: =(C17-E17)/C17*100 -> 97.569061 | I17: =$C$3*(C17-E17)/1000 -> 106694.94 | L17: 达标排放天数 | M17: 31 | P17: =ROUND(E17,1) -> 0.4 | Q17: =Q16 -> 6041616 | R17: =P17*Q17/1000000 -> 2.4166464 | S17: NH3-N
B18: 粪大肠菌群数 (个/L) | E18: <20 | L18: 运转率 | M18: 100
A19: 备注 | B19: 本月产生泥饼4075.04吨，其中运往常州市英科环境科技有限公司1023.04吨，国电常州发电有限公司2872.00吨，外运接种180.00吨：常州龙宇颜料化学有限公司120吨，天合光能股份有限公司45吨，天合光能股份有限公司硅片分公司15吨。
A21: 审核： 制表： 制表日期：2021/6/3

Sheet 进出水
A1: 常州市深水江边污水处理有限公司进出水水质、污泥含水率月报表
J3: 44317
A4: 日期 | B4: 进水 | H4: 二沉池出水 | N4: 总出水 | T4: 污泥含水率 | U4: 粪大肠菌群
B5: CODCr | C5: BOD5 | D5: SS | E5: TP | F5: NH3-N | G5: TN | H5: CODCr | I5: BOD5 | J5: SS | K5: TP | L5: NH3-N | M5: TN | N5: CODCr | O5: BOD5 | P5: SS | Q5: TP | R5: NH3-N | S5: TN
B6: （mg/L） | C6: （mg/L） | D6: （mg/L） | E6: （mg/L） | F6: （mg/L） | G6: （mg/L） | H6: （mg/L） | I6: （mg/L） | J6: （mg/L） | K6: （mg/L） | L6: （mg/L） | M6: （mg/L） | N6: （mg/L） | O6: （mg/L） | P6: （mg/L） | Q6: （mg/L） | R6: （mg/L） | S6: （mg/L） | T6: （%） | U6: (个/L)
A7: 1 | B7: 164 | C7: 88.6 | D7: 120 | E7: 4.05 | F7: 20.3 | G7: 29.3 | H7: 41 | I7: 2.35 | J7: 16 | K7: 0.2 | L7: 0.47 | M7: 6.19 | N7: 28 | O7: <2 | P7: 5 | Q7: 0.11 | R7: 0.33 | S7: 6.04 | T7: 77.7 | W7: =1-S7/G7 -> 0.79385666
A8: 2 | B8: 338 | C8: 179 | D8: 164 | E8: 3.42 | F8: 16.7 | G8: 21.8 | H8: 44 | I8: 2.16 | J8: 17 | K8: 0.29 | L8: 1.24 | M8: 8.02 | N8: 29 | O8: <2 | P8: 5 | Q8: 0.1 | R8: 0.5 | S8: 6.06 | T8: 76.2 | W8: =1-S8/G8 -> 0.72201835
A9: 3 | B9: 234 | C9: 124 | D9: 198 | E9: 3.36 | F9: 24 | G9: 30 | H9: 45 | I9: 2.6 | J9: 18 | K9: 0.74 | L9: 2 | M9: 9.4 | N9: 29 | O9: <2 | P9: 5 | Q9: 0.12 | R9: 1.34 | S9: 7.2 | T9: 78.6 | U9: <20 | W9: =1-S9/G9 -> 0.76
A10: 4 | B10: 176 | C10: 95 | D10: 112 | E10: 3.02 | F10: 18.1 | G10: 24 | H10: 30 | I10: <2 | J10: 16 | K10: 0.25 | L10: 0.39 | M10: 7.13 | N10: 20 | O10: <2 | P10: 5 | Q10: 0.1 | R10: 0.26 | S10: 6.32 | T10: 77.1 | U10: <20 | W10: =1-S10/G10 -> 0.73666667
A11: 5 | B11: 120 | C11: 66 | D11: 72 | E11: 2.59 | F11: 21.7 | G11: 26.6 | H11: 32 | I11: <2 | J11: 19 | K11: 0.27 | L11: 0.44 | M11: 8.12 | N11: 24 | O11: <2 | P11: 5 | Q11: 0.09 | R11: 0.33 | S11: 7.18 | T11: 77.8 | U11: 140 | W11: =1-S11/G11 -> 0.73007519
A12: 6 | B12: 395 | C12: 213 | D12: 94 | E12: 5.74 | F12: 18.2 | G12: 23.6 | H12: 39 | I12: <2 | J12: 15 | K12: 0.43 | L12: 0.56 | M12: 7.57 | N12: 27 | O12: <2 | P12: 5 | Q12: 0.11 | R12: 0.46 | S12: 6.58 | T12: 77.7 | U12: <20 | W12: =1-S12/G12 -> 0.72118644
A13: 7 | B13: 240 | C13: 127 | D13: 90 | E13: 4.26 | F13: 20.1 | G13: 25.8 | H13: 36 | I13: <2 | J13: 17 | K13: 0.24 | L13: 0.63 | M13: 8.51 | N13: 24 | O13: <2 | P13: 5 | Q13: 0.1 | R13: 0.48 | S13: 8.12 | T13: 77.9 | U13: <20 | W13: =1-S13/G13 -> 0.68527132
A14: 8 | B14: 262 | C14: 138 | D14: 86 | E14: 4.57 | F14: 11.5 | G14: 16.3 | H14: 34 | I14: <2 | J14: 12 | K14: 0.21 | L14: 0.52 | M14: 8.02 | N14: 26 | O14: <2 | P14: 5 | Q14: 0.09 | R14: 0.44 | S14: 7.72 | T14: 76.6 | W14: =1-S14/G14 -> 0.52638037
A15: 9 | B15: 148 | C15: 79.9 | D15: 108 | E15: 3.07 | F15: 14.3 | G15: 20.4 | H15: 37 | I15: <2 | J15: 18 | K15: 0.22 | L15: 0.51 | M15: 7.03 | N15: 28 | O15: <2 | P15: 8 | Q15: 0.11 | R15: 0.44 | S15: 6.58 | T15: 78.8 | W15: =1-S15/G15 -> 0.67745098
A16: 10 | B16: 290 | C16: 154 | D16: 176 | E16: 4.85 | F16: 15 | G16: 23.8 | H16: 40 | I16: 2.04 | J16: 18 | K16: 0.44 | L16: 0.52 | M16: 6.93 | N16: 24 | O16: <2 | P16: 6 | Q16: 0.1 | R16: 0.42 | S16: 6.54 | T16: 78.3 | U16: 100 | W16: =1-S16/G16 -> 0.72521008
A17: 11 | B17: 276 | C17: 140 | D17: 134 | E17: 4.93 | F17: 18.3 | G17: 26.1 | H17: 35 | I17: <2 | J17: 16 | K17: 0.3 | L17: 0.53 | M17: 8.02 | N17: 25 | O17: <2 | P17: 7 | Q17: 0.1 | R17: 0.48 | S17: 6.49 | T17: 77.7 | U17: <20 | W17: =1-S17/G17 -> 0.751341
A18: 12 | B18: 140 | C18: 71.4 | D18: 104 | E18: 3.74 | F18: 18.1 | G18: 24.2 | H18: 37 | I18: <2 | J18: 10 | K18: 0.28 | L18: 0.53 | M18: 7.82 | N18: 28 | O18: <2 | P18: 5 | Q18: 0.1 | R18: 0.46 | S18: 7.62 | T18: 78.4 | U18: <20 | W18: =1-S18/G18 -> 0.68512397
A19: 13 | B19: 114 | C19: 58.2 | D19: 106 | E19: 3.59 | F19: 15.8 | G19: 23 | H19: 36 | I19: <2 | J19: 18 | K19: 0.19 | L19: 0.52 | M19: 7.3 | N19: 29 | O19: <2 | P19: 5 | Q19: 0.1 | R19: 0.47 | S19: 6.63 | T19: 76.6 | U19: <20 | W19: =1-S19/G19 -> 0.71173913
A20: 14 | B20: 340 | C20: 176 | D20: 106 | E20: 5.88 | F20: 21.8 | G20: 28.9 | H20: 34 | I20: <2 | J20: 19 | K20: 0.24 | L20: 0.55 | M20: 9.75 | N20: 26 | O20: <2 | P20: 5 | Q20: 0.1 | R20: 0.49 | S20: 8.26 | T20: 77.3 | U20: <20 | W20: =1-S20/G20 -> 0.71418685
A21: 15 | B21: 304 | C21: 161 | D21: 114 | E21: 5.55 | F21: 17 | G21: 23.4 | H21: 42 | I21: 2.14 | J21: 18 | K21: 0.26 | L21: 0.42 | M21: 8.54 | N21: 27 | O21: <2 | P21: 5 | Q21: 0.1 | R21: 0.37 | S21: 7.97 | T21: 78.3 | W21: =1-S21/G21 -> 0.65940171
A22: 16 | B22: 244 | C22: 131 | D22: 88 | E22: 5.34 | F22: 21.4 | G22: 25.7 | H22: 39 | I22: <2 | J22: 18 | K22: 0.32 | L22: 0.55 | M22: 7.41 | N22: 29 | O22: <2 | P22: 7 | Q22: 0.12 | R22: 0.44 | S22: 7.06 | T22: 77.7 | W22: =1-S22/G22 -> 0.72529183
A23: 17 | B23: 94 | C23: 49 | D23: 110 | E23: 3.09 | F23: 15.3 | G23: 21.6 | H23: 31 | I23: 2.16 | J23: 17 | K23: 0.21 | L23: 0.43 | M23: 7.46 | N23: 26 | O23: <2 | P23: 7 | Q23: 0.12 | R23: 0.34 | S23: 6.62 | T23: 78.9 | U23: 50 | W23: =1-S23/G23 -> 0.69351852
A24: 18 | B24: 344 | C24: 175 | D24: 150 | E24: 4.88 | F24: 22 | G24: 27.6 | H24: 41 | I24: 2.28 | J24: 18 | K24: 0.36 | L24: 0.48 | M24: 8.02 | N24: 25 | O24: <2 | P24: 5 | Q24: 0.12 | R24: 0.36 | S24: 7.51 | T24: 77.7 | U24: <20 | W24: =1-S24/G24 -> 0.72789855
A25: 19 | B25: 220 | C25: 115 | D25: 112 | E25: 4.42 | F25: 17.5 | G25: 23.8 | H25: 28 | I25: <2 | J25: 9 | K25: 0.2 | L25: 0.46 | M25: 7.95 | N25: 24 | O25: <2 | P25: 5 | Q25: 0.12 | R25: 0.44 | S25: 7.75 | T25: 77.3 | U25: <20 | W25: =1-S25/G25 -> 0.67436975
A26: 20 | B26: 225 | C26: 117 | D26: 96 | E26: 4.97 | F26: 24.4 | G26: 30.6 | H26: 43 | I26: 2.69 | J26: 18 | K26: 0.36 | L26: 0.6 | M26: 7.56 | N26: 29 | O26: <2 | P26: 5 | Q26: 0.12 | R26: 0.43 | S26: 7.36 | T26: 78.8 | U26: <20 | W26: =1-S26/G26 -> 0.75947712
A27: 21 | B27: 108 | C27: 57.3 | D27: 68 | E27: 2.99 | F27: 12 | G27: 18.6 | H27: 25 | I27: <2 | J27: 11 | K27: 0.15 | L27: 0.48 | M27: 7.9 | N27: 22 | O27: <2 | P27: 5 | Q27: 0.09 | R27: 0.42 | S27: 7.31 | T27: 76.6 | U27: 140 | W27: =1-S27/G27 -> 0.60698925
A28: 22 | B28: 238 | C28: 128 | D28: 116 | E28: 3.91 | F28: 18.1 | G28: 24.8 | H28: 36 | I28: <2 | J28: 14 | K28: 0.33 | L28: 0.44 | M28: 7.31 | N28: 26 | O28: <2 | P28: 5 | Q28: 0.09 | R28: 0.37 | S28: 6.42 | T28: 77.1 | W28: =1-S28/G28 -> 0.74112903
A29: 23 | B29: 247 | C29: 130 | D29: 174 | E29: 5.19 | F29: 22.9 | G29: 30.1 | H29: 39 | I29: <2 | J29: 18 | K29: 0.24 | L29: 0.55 | M29: 7.8 | N29: 32 | O29: <2 | P29: 5 | Q29: 0.1 | R29: 0.45 | S29: 7.51 | T29: 77.3 | W29: =1-S29/G29 -> 0.75049834
A30: 24 | B30: 297 | C30: 157 | D30: 120 | E30: 5.71 | F30: 18 | G30: 23.2 | H30: 32 | I30: <2 | J30: 11 | K30: 0.2 | L30: 0.57 | M30: 7.21 | N30: 26 | O30: <2 | P30: 5 | Q30: 0.09 | R30: 0.48 | S30: 6.57 | T30: 77.9 | U30: 100 | W30: =1-S30/G30 -> 0.71681034
A31: 25 | B31: 94 | C31: 48.8 | D31: 84 | E31: 3.43 | F31: 18.9 | G31: 25 | H31: 34 | I31: <2 | J31: 7 | K31: 0.3 | L31: 0.46 | M31: 6.91 | N31: 22 | O31: <2 | P31: 5 | Q31: 0.08 | R31: 0.43 | S31: 5.6 | T31: 78.1 | U31: <20 | W31: =1-S31/G31 -> 0.776
A32: 26 | B32: 206 | C32: 109 | D32: 98 | E32: 2.24 | F32: 21.9 | G32: 27.2 | H32: 32 | I32: <2 | J32: 18 | K32: 0.21 | L32: 0.46 | M32: 7.01 | N32: 24 | O32: <2 | P32: 6 | Q32: 0.09 | R32: 0.39 | S32: 6.84 | T32: 77.9 | U32: <20 | W32: =1-S32/G32 -> 0.74852941
A33: 27 | B33: 148 | C33: 78.4 | D33: 78 | E33: 1.98 | F33: 15.8 | G33: 21.9 | H33: 27 | I33: <2 | J33: 12 | K33: 0.22 | L33: 0.55 | M33: 6.42 | N33: 25 | O33: <2 | P33: 6 | Q33: 0.08 | R33: 0.46 | S33: 6.37 | T33: 78.8 | U33: <20 | W33: =1-S33/G33 -> 0.70913242
A34: 28 | B34: 122 | C34: 63.3 | D34: 50 | E34: 1.15 | F34: 12.3 | G34: 17.9 | H34: 23 | I34: <2 | J34: 11 | K34: 0.14 | L34: 0.35 | M34: 6.07 | N34: 21 | O34: <2 | P34: 5 | Q34: 0.08 | R34: 0.29 | S34: 5.13 | T34: 77.7 | U34: <20 | W34: =1-S34/G34 -> 0.71340782
A35: 29 | B35: 120 | C35: 62.4 | D35: 78 | E35: 1.69 | F35: 16.1 | G35: 21.8 | H35: 35 | I35: <2 | J35: 11 | K35: 0.17 | L35: 0.37 | M35: 6.57 | N35: 24 | O35: <2 | P35: 5 | Q35: 0.09 | R35: 0.35 | S35: 6.12 | T35: 78.9
A36: 30 | B36: 164 | C36: 86.9 | D36: 108 | E36: 4.34 | F36: 19.4 | G36: 25.5 | H36: 33 | I36: <2 | J36: 10 | K36: 0.26 | L36: 0.47 | M36: 7.6 | N36: 21 | O36: <2 | P36: 5 | Q36: 0.1 | R36: 0.42 | S36: 7.04 | T36: 76.6 | W36: =1-S36/G36 -> 0.72392157
A37: 31 | B37: 212 | C37: 112 | D37: 124 | E37: 4.42 | F37: 15.2 | G37: 21.7 | H37: 31 | I37: <2 | J37: 10 | K37: 0.24 | L37: 0.46 | M37: 7.11 | N37: 25 | O37: <2 | P37: 7 | Q37: 0.11 | R37: 0.37 | S37: 6.74 | T37: 77.6 | U37: <20 | W37: =1-S37/G37 -> 0.68940092
A38: 平均 | B38: =ROUND(AVERAGE(B7:B37),0) -> 214 | C38: =ROUND(AVERAGE(C7:C37),0) -> 113 | D38: =ROUND(AVERAGE(D7:D37),0) -> 111 | E38: =ROUND(AVERAGE(E7:E37),2) -> 3.95 | F38: =ROUND(AVERAGE(F7:F37),1) -> 18.1 | G38: =ROUND(AVERAGE(G7:G37),1) -> 24.3 | H38: =ROUND(AVERAGE(H7:H37),1) -> 35.2 | I38: =ROUND(AVERAGE(I7:I37),2) -> 2.3 | J38: =ROUND(AVERAGE(J7:J37),2) -> 14.84 | K38: =ROUND(AVERAGE(K7:K37),2) -> 0.27 | L38: =ROUND(AVERAGE(L7:L37),2) -> 0.56 | M38: =ROUND(AVERAGE(M7:M37),1) -> 7.6 | N38: =ROUND(AVERAGE(N7:N37),1) -> 25.6 | O38: <2 | P38: =ROUND(AVERAGE(P7:P37),2) -> 5.45 | Q38: =ROUND(AVERAGE(Q7:Q37),2) -> 0.1 | R38: =ROUND(AVERAGE(R7:R37),2) -> 0.44 | S38: =ROUND(AVERAGE(S7:S37),2) -> 6.88 | T38: =ROUND(AVERAGE(T7:T37),2) -> 77.74 | U38: <20
A39: 审核： | J39: 制表： | Q39: 制表时间：2021/6/3
B41: 项目 | C41: 进水（mg/L) | D41: 最大值 | E41: 最小值（mg/L) | F41: 出水（mg/L) | G41: 最大值 | H41: 最小值（mg/L) | I41: 去除率
D42: （mg/L) | G42: （mg/L) | I42: （%）
...

Sheet 设备
A1: 常州市深水江边污水处理有限公司设备运行月报表
A2: 43952
A3: 运行 工段 | B3: 设备名称 | C3: 编号 | D3: 运行 天数 | E3: 定时 | F3: 额定运行时间 | G3: 实际运行时间 | H3: 利用率 | I3: 完好率 | J3: 维修、保养情况
D5: （d） | E5: （h/d） | F5: （h） | G5: （h） | H5: % | I5: %
A6: 预 处 理 | B6: 粗格栅机 | C6: 1# | D6: 31 | E6: 2 | F6: 62 | G6: 62 | H6: 1 | I6: 1
C7: 2# | D7: 31 | E7: 2 | F7: 62 | G7: 56 | H7: 0.9 | I7: 0.9 | J7: 5-7日电机、减速机修理
B8: 螺旋输送机 | C8: / | D8: 31 | E8: 2 | F8: 62 | G8: 62 | H8: 1 | I8: 1
B9: 螺旋压榨机 | C9: / | D9: 31 | E9: 2 | F9: 62 | G9: 62 | H9: 1 | I9: 1
B10: 进水泵 | C10: 1# | D10: 31 | E10: 24 | F10: 744 | G10: 534 | H10: 0.71774194 | I10: 1
C11: 2# | D11: 31 | E11: 24 | F11: 744 | G11: 514 | H11: 0.69086022 | I11: 1
C12: 3# | D12: 31 | E12: 24 | F12: 744 | G12: 506 | H12: 0.68010753 | I12: 1
C13: 4# | D13: 31 | E13: 24 | F13: 744 | G13: 154 | H13: 0.20698925 | I13: 1
C14: 5# | D14: 31 | E14: 24 | F14: 744 | G14: 740 | H14: 0.99462366 | I14: 1
B15: 细格栅机 | C15: 1# | D15: 31 | E15: 2.4 | F15: 74.4 | G15: 74.4 | H15: 1 | I15: 1 | J15: 12日保养
C16: 2# | D16: 31 | E16: 2.4 | F16: 74.4 | G16: 74.4 | H16: 1 | I16: 1 | J16: 12日保养
C17: 3# | D17: 31 | E17: 2.4 | F17: 74.4 | G17: 74.4 | H17: 1 | I17: 1 | J17: 12日保养
C18: 4# | D18: 31 | E18: 2.4 | F18: 74.4 | G18: 74.4 | H18: 1 | I18: 1 | J18: 12日保养
C19: 5# | D19: 31 | E19: 2.4 | F19: 74.4 | G19: 74.4 | H19: 1 | I19: 1 | J19: 12日保养
C20: 6# | D20: 31 | E20: 2.4 | F20: 74.4 | G20: 74.4 | H20: 1 | I20: 1 | J20: 12日保养
B21: 螺旋输送机 | C21: 1# | D21: 31 | E21: 2 | F21: 62 | G21: 15.5 | H21: 0.25 | I21: 1 | J21: 12日保养
C22: 2# | D22: 31 | E22: 2 | F22: 62 | G22: 15.5 | H22: 0.25 | I22: 1 | J22: 12日保养
B23: 螺旋压榨机 | C23: 1# | D23: 31 | E23: 2 | F23: 62 | G23: 15.5 | H23: 0.25 | I23: 1 | J23: 12日保养
C24: 2# | D24: 31 | E24: 2 | F24: 62 | G24: 15.5 | H24: 0.25 | I24: 1 | J24: 12日保养
B25: 搅拌机 | C25: 1# | D25: 31 | E25: 24 | F25: 744 | G25: 0 | H25: 0 | I25: 0
B26: 砂水分离机 | C26: 1# | D26: 31 | E26: 0.5 | F26: 15.5 | G26: 15.5 | H26: 1 | I26: 1 | J26: 12日保养
B27: 搅拌机 | C27: 2# | D27: 31 | E27: 24 | F27: 744 | G27: 744 | H27: 1 | I27: 1 | J27: 12日保养
B28: 砂水分离机 | C28: 2# | D28: 31 | E28: 0.5 | F28: 15.5 | G28: 15.5 | H28: 1 | I28: 1 | J28: 12日保养
B29: 搅拌机 | C29: 3# | D29: 31 | E29: 24 | F29: 744 | G29: 744 | H29: 1 | I29: 1 | J29: 12日保养
B30: 砂水分离机 | C30: 3# | D30: 31 | E30: 0.5 | F30: 15.5 | G30: 15.5 | H30: 1 | I30: 1 | J30: 12日保养
B31: 搅拌机 | C31: 4# | D31: 31 | E31: 24 | F31: 744 | G31: 0 | H31: 0 | I31: 0
B32: 砂水分离机 | C32: 4# | D32: 31 | E32: 0.5 | F32: 15.5 | G32: 15.5 | H32: 1 | I32: 1 | J32: 12日保养
B33: 高压鼓风机 | C33: 1# | D33: 31 | E33: 24 | F33: 744 | G33: 366 | H33: 0.49193548 | I33: 1
C34: 2# | D34: 31 | E34: 24 | F34: 744 | G34: 36 | H34: 0.048387097 | I34: 1
C35: 3# | D35: 31 | E35: 24 | F35: 744 | G35: 342 | H35: 0.45967742 | I35: 1 | J35: 10日进风滤网更换
C36: 4# | D36: 31 | E36: 24 | F36: 744 | G36: 360 | H36: 0.48387097 | I36: 1
C37: 5# | D37: 31 | E37: 24 | F37: 744 | G37: 396 | H37: 0.53225806 | I37: 1
A38: 审核： | E38: 制表： | H38: 制表时间：2020/6/3
A46: 常州市深水江边污水处理有限公司设备运行月报表
A47: 43952
A48: 运行 工段 | B48: 设备名称 | C48: 编号 | D48: 运行 天数 | E48: 定时 | F48: 额定运行时间 | G48: 实际运行时间 | H48: 利用率 | I48: 完好率 | J48: 维修、保养情况
...

Sheet 仪表
A1: 常州市深水江边污水处理有限公司污水运行月报表
D2: 44317
A3: 仪表名称 | B3: 编号 | C3: 规格型号 | D3: 安装位置 | E3: 运行情况 | F3: 标定、校准情况 | G3: 备注
A4: 一期溶氧仪 | B4: 1#（南） | C4: 美商生化T-10 | D4: 一期生反池 | E4: 正常 | F4: 校准 | G4: 2021-05-10 2021-05-17 2021-05-24 2021-05-31
B5: 2#（南） | C5: 美商生化T-10 | D5: 一期生反池 | E5: 正常 | F5: 校准 | G5: =G4 -> 2021-05-10 2021-05-17 2021-05-24 2021-05-31
B6: 1#（北） | C6: 美商生化T-10 | D6: 一期生反池 | E6: 正常 | F6: 校准 | G6: =G5 -> 2021-05-10 2021-05-17 2021-05-24 2021-05-31
B7: 2#（北） | C7: 美商生化T-10 | D7: 一期生反池 | E7: 正常 | F7: 校准 | G7: =G6 -> 2021-05-10 2021-05-17 2021-05-24 2021-05-31
A8: 一期污泥浓度计 | B8: 1#（南） | C8: E+H | D8: 一期生反池 | E8: 正常 | F8: 校准 | G8: =G7 -> 2021-05-10 2021-05-17 2021-05-24 2021-05-31
B9: 2#（南） | C9: E+H | D9: 一期生反池 | E9: 正常 | F9: 校准 | G9: =G8 -> 2021-05-10 2021-05-17 2021-05-24 2021-05-31
B10: 1#（北） | C10: E+H | D10: 一期生反池 | E10: 正常 | F10: 校准 | G10: =G9 -> 2021-05-10 2021-05-17 2021-05-24 2021-05-31
B11: 2#（北） | C11: E+H | D11: 一期生反池 | E11: 正常 | F11: 校准 | G11: =G10 -> 2021-05-10 2021-05-17 2021-05-24 2021-05-31
A12: 进水PH计 | B12: 1# | C12: 哈希 | D12: 一期旋流沉砂池 | E12: 正常 | F12: 标定 | G12: =G11 -> 2021-05-10 2021-05-17 2021-05-24 2021-05-31
A13: 二期溶氧仪 | B13: 1#（南） | C13: 哈希LDO | D13: 二期生反池 | E13: 正常 | F13: 校准 | G13: =G12 -> 2021-05-10 2021-05-17 2021-05-24 2021-05-31
B14: 2#（南） | C14: 哈希LDO | D14: 二期生反池 | E14: 正常 | F14: 校准 | G14: =G13 -> 2021-05-10 2021-05-17 2021-05-24 2021-05-31
B15: 1#（北） | C15: 哈希LDO | D15: 二期生反池 | E15: 正常 | F15: 校准 | G15: =G14 -> 2021-05-10 2021-05-17 2021-05-24 2021-05-31
B16: 2#（北） | C16: 哈希LDO | D16: 二期生反池 | E16: 正常 | F16: 校准 | G16: =G15 -> 2021-05-10 2021-05-17 2021-05-24 2021-05-31
A17: 二期污泥浓度计 | B17: 1#（南） | C17: 哈希TXPRO-2 | D17: 二期生反池 | E17: 正常 | F17: 校准 | G17: =G16 -> 2021-05-10 2021-05-17 2021-05-24 2021-05-31
B18: 2#（南） | C18: E+H | D18: 二期生反池 | E18: 正常 | F18: 校准 | G18: =G17 -> 2021-05-10 2021-05-17 2021-05-24 2021-05-31
B19: 1#（北） | C19: 哈希TXPRO-2 | D19: 二期生反池 | E19: 正常 | F19: 校准 | G19: =G18 -> 2021-05-10 2021-05-17 2021-05-24 2021-05-31
B20: 2#（北） | C20: E+H | D20: 二期生反池 | E20: 正常 | F20: 校准 | G20: =G19 -> 2021-05-10 2021-05-17 2021-05-24 2021-05-31
A21: 审核： | D21: 制表： | F21: 制表日期：2021/6/3
A25: 常州市深水江边污水处理有限公司污水运行月报表
D26: =D2 -> 44317
A27: 仪表名称 | B27: 编号 | C27: 规格型号 | D27: 安装位置 | E27: 运行情况 | F27: 标定、校准情况 | G27: 备注
A28: 一期ORP | B28: 1#（南） | C28: E+H | D28: 一期生反池 | E28: 正常 | F28: 标定 | G28: 44326
B29: 2#（北） | C29: E+H | D29: 一期生反池 | E29: 正常 | F29: 标定 | G29: =G28 -> 44326
A30: 二期ORP | B30: 1#（南） | C30: 哈希 | D30: 二期生反池 | E30: 正常 | F30: 标定 | G30: =G29 -> 44326
B31: 2#（北） | C31: 哈希 | D31: 二期生反池 | E31: 正常 | F31: 标定 | G31: =G30 -> 44326
A32: 审核： | D32: 制表： | F32: =F21 -> 制表日期：2021/6/3

Sheet 实验数据
A1: 常州市深水江边污水处理有限公司实验数据汇总表
A3: 采样地点：二期北 | E3: 采样时间：2021-5-27
A4: 硝化实验 | E4: 反硝化实验 | G4: 释磷实验
A5: 时间节点 | B5: NO3-N(mg/l) | C5: NH3-N(mg/l) | D5: PO43-(mg/l) | E5: 时间节点 | F5: NO3-N(mg/l) | G5: 时间节点 | H5: PO43-(mg/l)
A6: 0分钟 | B6: 1.3773672 | C6: 6.4303711 | D6: 2.6316055 | E6: 0分钟 | F6: 6.615118 | G6: 0分钟 | H6: 1.795625
A7: 15分钟 | B7: 2.9695313 | C7: 4.6130503 | D7: 2.0534297 | E7: 15分钟 | F7: 4.8104851 | G7: 30分钟 | H7: 2.1605625
A8: 30分钟 | B8: 4.2671484 | C8: 3.071448 | D8: 1.575343 | E8: 30分钟 | F8: 3.3890625 | G8: 60分钟 | H8: 2.6359375
A9: 60分钟 | B9: 6.5441126 | C9: 1.1814854 | D9: 0.89765625 | E9: 45分钟 | F9: 2.3582559 | G9: 90分钟 | H9: 3.059375
A10: MLSS(mg/l) | B10: 4564 | E10: 60分钟 | F10: 1.3967603 | G10: MLSS(mg/l) | H10: 4348
E11: 90分钟 | F11: 0.75130469
E12: MLSS(mg/l) | F12: 4244
A13: 审核： | D13: 制表： | G13: 制表日期：2021/6/3
