Workbook

Sheet 汇总
A1: 常州市深水城北污水处理有限公司污水运行月报表
A2: 44866
A3: 污 水 处 理 | B3: 污水处理量（m3） | C3: =处理量!D36 -> 4365504 | D3: 污 泥 处 理 | E3: 脱水污泥量（T） | F3: =处理量!G40 -> 3417.68 | G3: 水 电 用 量 | H3: 用电量（度） | J3: 1364000 | K3: 污 水 电 单 耗 | L3: 污水（度/m3） | M3: =J3/C3 -> 0.3124496
B4: 日均处理量（m3） | C4: =处理量!D35 -> 145516.8 | E4: 絮凝剂用量（kg） | F4: =处理量!H36 -> 4700 | H4: 日均用电量（度） | J4: =J3/M16 -> 45466.667 | L4: CODcr（度/kg） | M4: =J3/I12 -> 1.0348298
E5: 含水率（%） | F5: =进出水!AB37 -> 78.643333 | H5: 用水量（T） | J5: 2460
B6: 最高日处理量（m3） | C6: =处理量!D40 -> 157632 | E6: 絮凝剂单耗（kg/T） | F6: =F4/处理量!G41 -> 6.439216 | G6: 消 毒 剂 | H6: 次氯酸钠（T） | J6: =处理量!O36 -> 283.112 | L6: BOD5（度/kg） | M6: =J3/I13 -> 1.8232102
B7: 最低日处理量（m3） | C7: =处理量!D41 -> 128128 | E7: 产泥率(g/m３) | F7: =处理量!G41/C3*1000000 -> 167.19777 | L7: SS（度/kg） | M7: =J3/I14 -> 1.6846672
B8: 负荷率（%） | C8: =C4/150000*100 -> 97.0112 | D8: 混 凝 剂 | E8: 混凝剂用量（T） | F8: =处理量!M36 -> 267.24 | H8: 药单耗(g/m3) | J8: =J6/C3*1000*1000 -> 64.852077 | K8: 乙酸-厌缺氧段 | L8: 投加量（吨） | M8: =处理量!P36 -> 58.99368
B9: 进水水温(℃) | C9: =处理量!B35 -> 22.593333 | E9: 药单耗(g/m3) | F9: =F8/C3*1000*1000 -> 61.216299 | L9: 药单耗(g/m3) | M9: =M8/C3*1000*1000 -> 13.513601
A10: 处 理 质 量 | B10: 项目 | C10: 进水（mg/l） | E10: 出水（mg/l） | G10: 去除率（%） | I10: 去除总量（kg) | K10: 乙酸-提标段 | L10: 投加量（吨） | M10: =处理量!Q36 -> 40.9788
L11: 药单耗(g/m3) | M11: =M10/C3*1000*1000 -> 9.3869574
B12: CODcr | C12: =进出水!B37 -> 309.93333 | E12: =进出水!V37 -> 12.133333 | G12: =(C12-8)/C12 -> 0.974188 | I12: =(C12-8)*C3/1000 -> 1318091.2 | K12: 污 泥 去 向 | L12: 国电(吨） | M12: =处理量!E36 -> 1765.34
B13: BOD5 | C13: =进出水!C37 -> 172.37333 | E13: =进出水!W37 -> 2.2273333 | G13: =(C13-1)/C13 -> 0.99419864 | I13: =(C13-1)*C3/1000 -> 748130.97 | L13: 英科环境(吨) | M13: =处理量!F36 -> 1652.34
B14: SS | C14: =进出水!D37 -> 190.46667 | E14: =进出水!X37 -> 5 | G14: =(C14-E14)/C14 -> 0.97374869 | I14: =(C14-5)*C3/1000 -> 809655.48 | L14: 其它 | M14: =处理量!G36 -> 0
B15: TP | C15: =进出水!E37 -> 5.3563333 | E15: =进出水!Y37 -> 0.19333333 | G15: =(C15-E15)/C15 -> 0.96390566 | I15: =(C15-E15)*C3/1000 -> 22539.097 | K15: 运 行 情 况 | L15: 应运行天数 | M15: 30
B16: TN | C16: =进出水!G37 -> 40.973333 | E16: =进出水!AA37 -> 7.871 | G16: =(C16-E16)/C16 -> 0.80789945 | I16: =(C16-E16)*C3/1000 -> 144508.37 | L16: 实际运行天数 | M16: 30
B17: NH3-N | C17: =进出水!F37 -> 30.23 | E17: =进出水!Z37 -> 0.209 | G17: =(C17-E17)/C17 -> 0.99308634 | I17: =(C17-E17)*C3/1000 -> 131056.8 | L17: 达标排放天数 | M17: 30
B18: 粪大肠菌群数 (个/L) | C18: / | E18: <20 | G18: / | I18: / | L18: 运转率 | M18: 100 | P18: =1424589-51986-8603 -> 1364000 | Q18: =3046-586 -> 2460
A19: 备注 | B19: 本月总用电量为1424589度，其中排水处电量为8603度，除臭工程用电51986度，城北实际用电为1364000度。本月自来水用量为3046吨，其中除臭工程自来水用量为586吨，城北实际用自来水用量为2460吨。 本月产生泥饼3417.68吨，运往英科焚烧中心1652.34吨；运往国电1765.34吨；无外运。
A21: 审核： 制表： 制表日期：2022-12-2

Sheet 处理量
A1: 常州市深水城北污水处理有限公司污水处理运行月报表
A2: 44866
A3: 日 期 | B3: 水温 | C3: 天气 | D3: 日处理水量 （m3） | E3: 污泥量（T） | H3: 药剂量 | I3: MLSS（mg/l） | L3: 电耗 | M3: 混凝剂 | N3: 絮凝剂 阴离子 （kg） | O3: 次氯酸钠 | P3: 乙酸(T） | R3: 回用水 （m3） | S3: 实际水量（m3） | T3: 消泡剂 | X3: 盐酸单价430 | Z3: 氯酸钠单价 | AA3: 4900 | AB3: PAM单价28000 | AD3: 消泡剂 | AE3: 14800
B4: 度 | C4: 状况 | E4: 国电 | F4: 英科环境 | G4: 其他 | H4: （Kg） | I4: 一期 | J4: 二期 | K4: 三期 | L4: ( 度 ) | M4: （T） | O4: （T） | P4: 厌缺氧 | Q4: 提标段
A5: 1 | B5: 24.4 | C5: 晴 | D5: 141888 | E5: 88.78 | F5: 56.58 | G5: 0 | H5: 175 | I5: 3278 | J5: 3848 | K5: 3640 | L5: 47502.96 | M5: 8.4 | N5: 0 | O5: 6.09525 | P5: 1.41546 | Q5: 0 | R5: 0 | S5: 141888 | T5: 35 | U5: =S5-115000 -> 26888
A6: 2 | B6: 24.3 | C6: 晴 | D6: 140160 | E6: 105.92 | F6: 0 | G6: 0 | H6: 150 | I6: 3542 | J6: 3940 | K6: 3676 | L6: 47802.97 | M6: 7.32 | N6: 0 | O6: 5.6115 | P6: 1.4013 | Q6: 0 | R6: 0 | S6: 140160 | T6: 35 | U6: =S6-115000 -> 25160
A7: 3 | B7: 24.5 | C7: 晴 | D7: 139872 | E7: 34.82 | F7: 106.18 | G7: 0 | H7: 150 | I7: 3828 | J7: 3878 | K7: 3704 | L7: 48103 | M7: 6.24 | N7: 0 | O7: 5.70825 | P7: 1.38912 | Q7: 0 | R7: 0 | S7: 139872 | T7: 35 | U7: =S7-135000 -> 4872 | Y7: 单价 | Z7: 当月用量 | AA7: 合计
A8: 4 | B8: 24.8 | C8: 晴 | D8: 140960 | E8: 107.8 | F8: 0 | G8: 0 | H8: 150 | I8: 4574 | J8: 4360 | K8: 4118 | L8: 47202.94 | M8: 6.48 | N8: 0 | O8: 5.62225 | P8: 1.35924 | Q8: 0 | R8: 0 | S8: 140960 | T8: 35 | U8: =S8-135000 -> 5960 | X8: 电费 | Y8: 0.667 | Z8: =L36 -> 1424588.8 | AA8: =Z8*Y8 -> 950200.7
A9: 5 | B9: 24.8 | C9: 晴 | D9: 139616 | E9: 107.16 | F9: 0 | G9: 0 | H9: 150 | I9: 4300 | J9: 3852 | K9: 4026 | L9: 45602.84 | M9: 6.48 | N9: 0 | O9: 6.7295 | P9: 1.40142 | Q9: 2.9436 | R9: 0 | S9: 139616 | T9: 35 | U9: =S9-135000 -> 4616 | X9: 絮凝剂 | Y9: 28000 | Z9: =H36/1000 -> 4.7 | AA9: =Z9*Y9 -> 131600
A10: 6 | B10: 24.2 | C10: 晴 | D10: 137440 | E10: 125.18 | F10: 0 | G10: 0 | H10: 150 | I10: 4036 | J10: 3944 | K10: 3872 | L10: 47202.94 | M10: 4.92 | N10: 0 | O10: 5.19225 | P10: 1.35282 | Q10: 1.62762 | R10: 0 | S10: 137440 | T10: 35 | U10: =S10-135000 -> 2440 | X10: 盐酸 | Y10: 430 | AA10: =Z10*Y10 -> 0
A11: 7 | B11: 23.9 | C11: 晴 | D11: 141408 | E11: 0 | F11: 140.04 | G11: 0 | H11: 150 | I11: 3862 | J11: 3738 | K11: 3610 | L11: 48603.04 | M11: 4.8 | N11: 0 | O11: 7.12725 | P11: 1.41426 | Q11: 1.70316 | R11: 0 | S11: 141408 | T11: 35 | U11: =S11-135000 -> 6408 | X11: 氯酸钠 | Y11: 4900 | AA11: =Z11*Y11 -> 0
A12: 8 | B12: 24.5 | C12: 晴 | D12: 128128 | E12: 121.32 | F12: 17.54 | G12: 0 | H12: 175 | I12: 4204 | J12: 3810 | K12: 3982 | L12: 47702.96 | M12: 12 | N12: 0 | O12: 4.71925 | P12: 1.72986 | Q12: 1.5147 | R12: 0 | S12: 128128 | T12: 35 | X12: 混凝剂 | Y12: 526 | Z12: =M36 -> 267.24 | AA12: =Z12*Y12 -> 140568.24
A13: 9 | B13: 24.1 | C13: 晴 | D13: 140384 | E13: 53.46 | F13: 51.7 | G13: 0 | H13: 150 | I13: 4224 | J13: 3978 | K13: 4006 | L13: 46302.89 | M13: 15.6 | N13: 0 | O13: 10.707 | P13: 2.15766 | Q13: 1.72932 | R13: 0 | S13: 140384 | T13: 35 | X13: 消泡剂 | Y13: 14800 | Z13: =T36/1000 -> 1.05 | AA13: =Z13*Y13 -> 15540
A14: 10 | B14: 24.1 | C14: 晴 | D14: 140672 | E14: 72.48 | F14: 51.92 | G14: 0 | H14: 150 | I14: 4392 | J14: 4330 | K14: 4114 | L14: 49103.06 | M14: 10.44 | N14: 0 | O14: 11.739 | P14: 1.66992 | Q14: 1.64022 | R14: 0 | S14: 140672 | T14: 35 | X14: 污泥外运 | Y14: 22.18 | Z14: =G40 -> 3417.68 | AA14: =Z14*Y14 -> 75804.142 | AB14: 运费总单价 | AC14: 46.36 | AD14: =Z14*AC14 -> 158443.64
A15: 11 | B15: 23.7 | C15: 阴 | D15: 140768 | E15: 70.44 | F15: 51.24 | G15: 0 | H15: 175 | I15: 4188 | J15: 4044 | K15: 3992 | L15: 48603.02 | M15: 9.12 | N15: 0 | O15: 7.51425 | P15: 2.07606 | Q15: 1.46628 | R15: 0 | S15: 140768 | T15: 35 | X15: 总药剂费 | AA15: =AA9+AA10+AA11+AA12+AA13 -> 287708.24
A16: 12 | B16: 21.5 | C16: 阴 | D16: 140768 | E16: 123.72 | F16: 0 | G16: 0 | H16: 150 | I16: 4376 | J16: 4116 | K16: 4228 | L16: 47802.98 | M16: 14.4 | N16: 0 | O16: 8.901 | P16: 2.04918 | Q16: 1.37034 | R16: 0 | S16: 140768 | T16: 35
A17: 13 | B17: 21.7 | C17: 阴 | D17: 132288 | E17: 85.92 | F17: 69.2 | G17: 0 | H17: 0 | I17: 4032 | J17: 3830 | K17: 4104 | L17: 43502.71 | M17: 16.8 | N17: 0 | O17: 9.36325 | P17: 1.65756 | Q17: 1.32498 | R17: 0 | S17: 132288 | T17: 35
A18: 14 | B18: 22 | C18: 阴 | D18: 138432 | E18: 0 | F18: 14.4 | G18: 0 | H18: 125 | I18: 4032 | J18: 3882 | K18: 3900 | L18: 46202.88 | M18: 3.72 | N18: 0 | O18: 10.0405 | P18: 1.95618 | Q18: 1.30788 | R18: 0 | S18: 138432 | T18: 35 | X18: 水费 | Y18: 4.2 | AA18: =Z18*Y18 -> 0
A19: 15 | B19: 20.7 | C19: 晴 | D19: 137856 | E19: 0 | F19: 34.22 | G19: 0 | H19: 175 | I19: 4088 | J19: 4028 | K19: 3914 | L19: 47202.94 | M19: 4.8 | N19: 0 | O19: 12.65275 | P19: 2.06232 | Q19: 1.37898 | R19: 0 | S19: 137856 | T19: 35 | AA19: =Z19*Y18 -> 0
A20: 16 | B20: 19.4 | C20: 雨 | D20: 138400 | E20: 68.08 | F20: 50.78 | G20: 0 | H20: 175 | I20: 4012 | J20: 4032 | K20: 3806 | L20: 47102.94 | M20: 9.6 | N20: 0 | O20: 9.44925 | P20: 2.0178 | Q20: 1.34946 | R20: 0 | S20: 138400 | T20: 35
A21: 17 | B21: 22.8 | C21: 雨 | D21: 145728 | E21: 51.32 | F21: 47.82 | G21: 0 | H21: 175 | I21: 4228 | J21: 4042 | K21: 4114 | L21: 46802.92 | M21: 11.64 | N21: 0 | O21: 11.34125 | P21: 2.21724 | Q21: 1.48236 | R21: 0 | S21: 145728 | T21: 35
A22: 18 | B22: 21.2 | C22: 雨 | D22: 152224 | E22: 50.4 | F22: 48.2 | G22: 0 | H22: 150 | I22: 3918 | J22: 3788 | K22: 3806 | L22: 49103.05 | M22: 9.96 | N22: 0 | O22: 9.245 | P22: 2.2569 | Q22: 1.50888 | R22: 0 | S22: 152224 | T22: 35
A23: 19 | B23: 20.8 | C23: 雨 | D23: 154080 | E23: 67.78 | F23: 65.94 | G23: 0 | H23: 200 | I23: 3934 | J23: 4196 | K23: 3882 | L23: 46202.88 | M23: 9.48 | N23: 0 | O23: 14.663 | P23: 2.25246 | Q23: 1.50576 | R23: 0 | S23: 154080 | T23: 35 | X23: 实际电费 | Z23: =Y23*Y8 -> 0 | AB23: =AA9+AA12+AA13 -> 287708.24
A24: 20 | B24: 21.8 | C24: 晴 | D24: 145056 | E24: 70.1 | F24: 67.18 | G24: 0 | H24: 150 | I24: 4056 | J24: 3836 | K24: 4012 | L24: 48303.01 | M24: 10.08 | N24: 0 | O24: 10.61025 | P24: 2.13702 | Q24: 1.4289 | R24: 0 | S24: 145056 | T24: 35
A25: 21 | B25: 23.8 | C25: 晴 | D25: 144576 | E25: 0 | F25: 101.56 | G25: 0 | H25: 175 | I25: 4180 | J25: 2724 | K25: 2892 | L25: 48703.04 | M25: 8.88 | N25: 0 | O25: 10.7285 | P25: 2.18046 | Q25: 1.45776 | R25: 0 | S25: 144576 | T25: 35 | Z25: =Y25*0.658 -> 0
A26: 22 | B26: 22.8 | C26: 雨 | D26: 156544 | E26: 50.74 | F26: 47.94 | G26: 0 | H26: 175 | I26: 4140 | J26: 3822 | K26: 4006 | L26: 47502.95 | M26: 7.32 | N26: 0 | O26: 9.16975 | P26: 2.31498 | Q26: 1.54812 | R26: 0 | S26: 156544 | T26: 35
A27: 23 | B27: 21.8 | C27: 晴 | D27: 156448 | E27: 68.1 | F27: 65.74 | G27: 0 | H27: 175 | I27: 3762 | J27: 4364 | K27: 3998 | L27: 47602.97 | M27: 7.68 | N27: 0 | O27: 9.32025 | P27: 2.31846 | Q27: 1.55046 | R27: 0 | S27: 156448 | T27: 35
A28: 24 | B28: 22.6 | C28: 晴 | D28: 153952 | E28: 69.22 | F28: 64.8 | G28: 0 | H28: 175 | I28: 4112 | J28: 3664 | K28: 3808 | L28: 48503.03 | M28: 7.32 | N28: 0 | O28: 12.52375 | P28: 2.25972 | Q28: 1.51062 | R28: 0 | S28: 153952 | T28: 35
A29: 25 | B29: 22.1 | C29: 晴 | D29: 157632 | E29: 85.52 | F29: 33.62 | G29: 0 | H29: 175 | I29: 3874 | J29: 3896 | K29: 3772 | L29: 48803.04 | M29: 1.68 | N29: 0 | O29: 6.923 | P29: 2.39832 | Q29: 1.63518 | R29: 0 | S29: 157632 | T29: 35
A30: 26 | B30: 22.1 | C30: 晴 | D30: 156224 | E30: 0 | F30: 104.78 | G30: 0 | H30: 175 | I30: 3890 | J30: 4124 | K30: 3912 | L30: 48102.99 | M30: 5.76 | N30: 0 | O30: 15.738 | P30: 2.27778 | Q30: 1.5711 | R30: 0 | S30: 156224 | T30: 35
A31: 27 | B31: 22.4 | C31: 晴 | D31: 155872 | E31: 87.08 | F31: 51.4 | G31: 0 | H31: 150 | I31: 4184 | J31: 3928 | K31: 4002 | L31: 49003.06 | M31: 5.16 | N31: 0 | O31: 5.64375 | P31: 2.32986 | Q31: 1.6146 | R31: 0 | S31: 155872 | T31: 35
A32: 28 | B32: 21.4 | C32: 雨 | D32: 156416 | E32: 0 | F32: 104.64 | G32: 0 | H32: 175 | I32: 3842 | J32: 3966 | K32: 3714 | L32: 48603.03 | M32: 7.44 | N32: 0 | O32: 17.25375 | P32: 2.31078 | Q32: 1.59072 | R32: 0 | S32: 156416 | T32: 35
A33: 29 | B33: 21.4 | C33: 雨 | D33: 154912 | E33: 0 | F33: 102.54 | G33: 0 | H33: 150 | I33: 4016 | J33: 4410 | K33: 4238 | L33: 46402.88 | M33: 17.88 | N33: 0 | O33: 4.95575 | P33: 2.39808 | Q33: 1.67592 | R33: 0 | S33: 154912 | T33: 35
A34: 30 | B34: 18.2 | C34: 阴 | D34: 156800 | E34: 0 | F34: 102.38 | G34: 0 | H34: 150 | I34: 3884 | J34: 3962 | K34: 3670 | L34: 45402.84 | M34: 15.84 | N34: 0 | O34: 17.8235 | P34: 2.23146 | Q34: 1.54188 | R34: 0 | S34: 156800 | T34: 35
A35: 平均 | B35: =AVERAGE(B5:B34) -> 22.593333 | C35: / | D35: =AVERAGE(D5:D34) -> 145516.8 | E35: =AVERAGE(E5:E34) -> 58.844667 | F35: =AVERAGE(F5:F34) -> 55.078 | G35: =AVERAGE(G5:G34) -> 0 | H35: =AVERAGE(H5:H34) -> 156.66667 | I35: =AVERAGE(I5:I34) -> 4032.9333 | J35: =AVERAGE(J5:J34) -> 3944.4 | K35: =AVERAGE(K5:K34) -> 3883.9333 | ... M35: =AVERAGE(M5:M34) -> 8.908 | N35: 0 | O35: =AVERAGE(O5:O34) -> 9.4370667 | P35: =AVERAGE(P5:P34) -> 1.966456 | Q35: =AVERAGE(Q5:Q34) -> 1.36596 | R35: =AVERAGE(R5:R34) -> 0 | S35: =D35-R35 -> 145516.8 | T35: =AVERAGE(T5:T34) -> 35
A36: 合计 | B36: / | C36: / | D36: =SUM(D5:D34) -> 4365504 | E36: =SUM(E5:E34) -> 1765.34 | F36: =SUM(F5:F34) -> 1652.34 | G36: =SUM(G5:G34) -> 0 | H36: =SUM(H5:H34) -> 4700 | I36: / | J36: / | K36: / | L36: =SUM(L5:L34) -> 1424588.8 | M36: =SUM(M5:M34) -> 267.24 | N36: 0 | O36: =SUM(O5:O34) -> 283.112 | P36: =SUM(P5:P34) -> 58.99368 | Q36: =SUM(Q5:Q34) -> 40.9788 | R36: =SUM(R5:R34) -> 0 | S36: =SUM(S5:S34) -> 4365504 | T36: =SUM(T5:T34) -> 1050
A37: 审核： | I37: 制表： | Q37: 制表时间:2022-12-2
B40: 最大值 | D40: =MAX(D5:D34) -> 157632 | E40: 脱水污泥量 | G40: =E36+F36+G36 -> 3417.68 | K40: 除臭
B41: 最小值 | D41: =MIN(D5:D34) -> 128128 | E41: 干污泥量 | G41: =G40*(100-进出水!AB37)/100 -> 729.90253 | K41: 排水借用 | P41: =P36+Q36 -> 99.97248 | Q41: =P36+Q36 -> 99.97248
L42: =L36-L40-L41 -> 1424588.8 | P42: =P41*1000 -> 99972.48 | Q42: =Q41*1000 -> 99972.48
...

Sheet 进出水
A1: 常州市深水城北污水处理有限公司出水水质、污泥含水率月报表
A3: 44866
A4: 日期 | B4: 进水 | H4: 一期出水 | N4: 二、三期出水 | T4: 高沉池 | V4: 总出水 | AB4: 污泥含水率（%） | AC4: 粪大肠杆菌
B5: CODCr | C5: BOD5 | D5: SS | E5: TP | F5: NH3-N | G5: TN | H5: CODCr | I5: BOD5 | J5: SS | K5: TP | L5: NH3-N | M5: TN | N5: CODCr | O5: BOD5 | P5: SS | Q5: TP | R5: NH3-N | S5: TN | T5: CODCr | U5: TP | V5: CODCr | W5: BOD5 | X5: SS | Y5: TP | Z5: NH3-N | AA5: TN
B6: （mg/l） | C6: （mg/l） | D6: （mg/l） | E6: （mg/l） | F6: （mg/l） | G6: （mg/l） | H6: （mg/l） | I6: （mg/l） | J6: （mg/l） | K6: （mg/l） | L6: （mg/l） | M6: （mg/l） | N6: （mg/l） | O6: （mg/l） | P6: （mg/l） | Q6: （mg/l） | R6: （mg/l） | S6: （mg/l） | T6: （mg/l） | U6: （mg/l） | V6: （mg/l） | W6: （mg/l） | X6: （mg/l） | Y6: （mg/l） | Z6: （mg/l） | AA6: （mg/l）
A7: 1 | B7: 226 | C7: 126 | D7: 144 | E7: 4.34 | F7: 35.2 | G7: 42.4 | H7: 18 | I7: 2.38 | J7: 6 | K7: 0.59 | L7: 0.55 | M7: 8.78 | N7: 17 | O7: 2.3 | P7: 5 | Q7: 0.98 | R7: 0.4 | S7: 7.96 | T7: 18.5 | U7: 0.95 | V7: 13 | W7: 2.17 | X7: 5 | Y7: 0.27 | Z7: 0.25 | AA7: 7.58 | AB7: 78.4 | AC7: <20
A8: 2 | B8: 209 | C8: 115 | D8: 138 | E8: 5.49 | F8: 32.8 | G8: 39.7 | H8: 21 | I8: 2.74 | J8: 6 | K8: 0.64 | L8: 0.28 | M8: 7.96 | N8: 16 | O8: 2.36 | P8: 5 | Q8: 0.99 | R8: 0.27 | S8: 5.46 | T8: 16.4 | U8: 0.65 | V8: 11 | W8: 2.3 | X8: 5 | Y8: 0.27 | Z8: 0.23 | AA8: 4.3 | AB8: 78 | AC8: <20
A9: 3 | B9: 331 | C9: 187 | D9: 246 | E9: 5.96 | F9: 29.8 | G9: 44.9 | H9: 17 | I9: 2.65 | J9: 6 | K9: 0.47 | L9: 0.24 | M9: 10.5 | N9: 13 | O9: 2.57 | P9: 6 | Q9: 0.92 | R9: 0.28 | S9: 9.96 | T9: 15.8 | U9: 0.82 | V9: 11 | W9: 2.41 | X9: 5 | Y9: 0.16 | Z9: 0.1 | AA9: 9.78 | AB9: 78.6 | AC9: 20
A10: 4 | B10: 168 | C10: 93.2 | D10: 102 | E10: 2.88 | F10: 21.6 | G10: 28.4 | H10: 20 | I10: 2.78 | J10: 5 | K10: 0.71 | L10: 0.15 | M10: 7.96 | N10: 15 | O10: 2.42 | P10: 5 | Q10: 0.97 | R10: 0.17 | S10: 7.4 | T10: 15.7 | U10: 0.91 | V10: 12 | W10: 2.2 | X10: 5 | Y10: 0.32 | Z10: 0.1 | AA10: 7.06 | AB10: 78.1 | AC10: 160
A11: 5 | B11: 316 | C11: 177 | D11: 200 | E11: 5.76 | F11: 30.2 | G11: 37.8 | H11: 21 | I11: 2.81 | J11: 5 | K11: 0.48 | L11: 0.14 | M11: 8.99 | N11: 19 | O11: 2.61 | P11: 5 | Q11: 0.94 | R11: 0.15 | S11: 6.58 | T11: 20.2 | U11: 0.83 | V11: 15 | W11: 2.55 | X11: 5 | Y11: 0.31 | Z11: 0.1 | AA11: 6.5 | AB11: 78.7 | AC11: <20
A12: 6 | B12: 289 | C12: 159 | D12: 172 | E12: 5.09 | F12: 33.6 | G12: 40.6 | H12: 18 | I12: 2.71 | J12: 5 | K12: 0.42 | L12: 0.26 | M12: 9.19 | N12: 17 | O12: 2.62 | P12: 5 | Q12: 0.99 | R12: 0.31 | S12: 8.37 | T12: 18.4 | U12: 0.59 | V12: 13 | W12: 2.33 | X12: 5 | Y12: 0.27 | Z12: 0.2 | AA12: 7.56 | AB12: 78.8 | AC12: <20
A13: 7 | B13: 390 | C13: 216 | D13: 198 | E13: 5.72 | F13: 35.4 | G13: 50.9 | H13: 17 | I13: 2.25 | J13: 5 | K13: 0.51 | L13: 0.28 | M13: 11.5 | N13: 16 | O13: 2.3 | P13: 5 | Q13: 0.81 | R13: 0.31 | S13: 9.75 | T13: 18.3 | U13: 0.75 | V13: 12 | W13: 2.09 | X13: 5 | Y13: 0.29 | Z13: 0.17 | AA13: 8.44 | AB13: 78.1 | AC13: <20
A14: 8 | B14: 398 | C14: 223 | D14: 222 | E14: 5.98 | F14: 27.5 | G14: 40.7 | H14: 20 | I14: 2.46 | J14: 5 | K14: 0.35 | L14: 0.35 | M14: 12.8 | N14: 17 | O14: 2.27 | P14: 5 | Q14: 0.86 | R14: 0.37 | S14: 10.7 | T14: 21.3 | U14: 0.7 | V14: 13 | W14: 2.21 | X14: 5 | Y14: 0.27 | Z14: 0.32 | AA14: 10.4 | AB14: 78.3 | AC14: <20
A15: 9 | B15: 396 | C15: 224 | D15: 238 | E15: 5.39 | F15: 34.8 | G15: 48.3 | H15: 18 | I15: 2.69 | J15: 6 | K15: 0.21 | L15: 0.39 | M15: 10.7 | N15: 18 | O15: 2.33 | P15: 5 | Q15: 0.81 | R15: 0.38 | S15: 9.04 | T15: 20.6 | U15: 0.65 | V15: 14 | W15: 2.18 | X15: 5 | Y15: 0.21 | Z15: 0.36 | AA15: 9.02 | AB15: 78.5 | AC15: 40
A16: 10 | B16: 254 | C16: 141 | D16: 126 | E16: 5.98 | F16: 30.4 | G16: 38 | H16: 18 | I16: 2.47 | J16: 5 | K16: 0.32 | L16: 0.41 | M16: 9.4 | N16: 16 | O16: 2.42 | P16: 5 | Q16: 0.96 | R16: 0.96 | S16: 10.5 | T16: 18.9 | U16: 0.75 | V16: 13 | W16: 2.28 | X16: 5 | Y16: 0.21 | Z16: 0.33 | AA16: 7.58 | AB16: 78.6 | AC16: <20
A17: 11 | B17: 304 | C17: 169 | D17: 198 | E17: 5.94 | F17: 35.4 | G17: 41.8 | H17: 20 | I17: 2.9 | J17: 6 | K17: 0.27 | L17: 0.33 | M17: 9.62 | N17: 18 | O17: 2.58 | P17: 5 | Q17: 0.97 | R17: 1.34 | S17: 10.4 | T17: 21.2 | U17: 0.81 | V17: 13 | W17: 2.52 | X17: 5 | Y17: 0.17 | Z17: 0.3 | AA17: 8.07 | AB17: 78.9 | AC17: <20
A18: 12 | B18: 297 | C18: 162 | D18: 186 | E18: 5.09 | F18: 30.2 | G18: 38.5 | H18: 15 | I18: 2.38 | J18: 5 | K18: 0.91 | L18: 1.24 | M18: 9.48 | N18: 14 | O18: 2.31 | P18: 5 | Q18: 0.67 | R18: 0.28 | S18: 9.55 | T18: 16 | U18: 0.45 | V18: 12 | W18: 2.15 | X18: 5 | Y18: 0.17 | Z18: 0.22 | AA18: 8.83 | AB18: 78.7 | AC18: 60
A19: 13 | B19: 301 | C19: 163 | D19: 192 | E19: 5.56 | F19: 33.3 | G19: 42.6 | H19: 20 | I19: 2.86 | J19: 6 | K19: 0.26 | L19: 0.3 | M19: 9.98 | N19: 18 | O19: 2.61 | P19: 6 | Q19: 0.77 | R19: 0.29 | S19: 8.99 | T19: 19.2 | U19: 0.6 | V19: 13 | W19: 2.47 | X19: 5 | Y19: 0.16 | Z19: 0.29 | AA19: 8.63 | AB19: 78.5 | AC19: <20
A20: 14 | B20: 376 | C20: 212 | D20: 202 | E20: 5.57 | F20: 37.3 | G20: 47.9 | H20: 18 | I20: 2.69 | J20: 6 | K20: 0.92 | L20: 3.1 | M20: 13.7 | N20: 16 | O20: 2.52 | P20: 5 | Q20: 0.81 | R20: 0.37 | S20: 10.4 | T20: 22.7 | U20: 0.45 | V20: 12 | W20: 2.26 | X20: 5 | Y20: 0.08 | Z20: 0.23 | AA20: 10.1 | AB20: 78.3 | AC20: <20
A21: 15 | B21: 337 | C21: 186 | D21: 194 | E21: 5.61 | F21: 35 | G21: 46.8 | H21: 18 | I21: 2.44 | J21: 6 | K21: 0.21 | L21: 0.39 | M21: 10 | N21: 16 | O21: 2.25 | P21: 5 | Q21: 0.44 | R21: 0.36 | S21: 9.96 | T21: 19.3 | U21: 0.42 | V21: 12 | W21: 2.11 | X21: 5 | Y21: 0.08 | Z21: 0.12 | AA21: 9.86 | AB21: 78.7 | AC21: <20
A22: 16 | B22: 256 | C22: 142 | D22: 144 | E22: 3.85 | F22: 30.4 | G22: 40.6 | H22: 21 | I22: 2.81 | J22: 7 | K22: 0.35 | L22: 0.36 | M22: 11 | N22: 17 | O22: 2.4 | P22: 5 | Q22: 0.78 | R22: 0.26 | S22: 10.4 | T22: 16 | U22: 0.54 | V22: 11 | W22: 2.21 | X22: 5 | Y22: 0.25 | Z22: 0.21 | AA22: 9.07 | AB22: 79 | AC22: <20
A23: 17 | B23: 250 | C23: 140 | D23: 118 | E23: 5.98 | F23: 30.9 | G23: 39.9 | H23: 20 | I23: 2.5 | J23: 5 | K23: 0.2 | L23: 0.37 | M23: 10 | N23: 18 | O23: 2.31 | P23: 5 | Q23: 0.9 | R23: 0.22 | S23: 8.91 | T23: 14.9 | U23: 0.7 | V23: 13 | W23: 2.27 | X23: 5 | Y23: 0.2 | Z23: 0.17 | AA23: 8.86 | AB23: 79.2 | AC23: <20
A24: 18 | B24: 354 | C24: 196 | D24: 200 | E24: 5.44 | F24: 20.8 | G24: 34.6 | H24: 17 | I24: 2.71 | J24: 6 | K24: 0.21 | L24: 0.3 | M24: 8.22 | N24: 16 | O24: 2.63 | P24: 5 | Q24: 0.83 | R24: 0.33 | S24: 8.19 | T24: 18 | U24: 0.77 | V24: 12 | W24: 2.33 | X24: 5 | Y24: 0.2 | Z24: 0.27 | AA24: 7.36 | AB24: 78.8 | AC24: 20
A25: 19 | B25: 275 | C25: 155 | D25: 188 | E25: 5.71 | F25: 36.6 | G25: 51.2 | H25: 14 | I25: 2.37 | J25: 5 | K25: 0.31 | L25: 0.17 | M25: 8.22 | N25: 12 | O25: 2.28 | P25: 5 | Q25: 0.92 | R25: 0.14 | S25: 7.47 | T25: 14.6 | U25: 0.84 | V25: 10 | W25: 2.14 | X25: 5 | Y25: 0.19 | Z25: 0.1 | AA25: 6.49 | AB25: 78.4 | AC25: <20
A26: 20 | B26: 444 | C26: 244 | D26: 314 | E26: 5.86 | F26: 23.3 | G26: 47.7 | H26: 14 | I26: 2.61 | J26: 5 | K26: 0.2 | L26: 0.26 | M26: 9.2 | N26: 13 | O26: 2.3 | P26: 5 | Q26: 0.65 | R26: 0.2 | S26: 7.36 | T26: 15.3 | U26: 0.49 | V26: 11 | W26: 2.08 | X26: 5 | Y26: 0.18 | Z26: 0.16 | AA26: 6.49 | AB26: 78.8 | AC26: <20
A27: 21 | B27: 435 | C27: 240 | D27: 324 | E27: 5.94 | F27: 33.4 | G27: 42.4 | H27: 14 | I27: 2.51 | J27: 6 | K27: 0.19 | L27: 0.26 | M27: 8.86 | N27: 15 | O27: 2.47 | P27: 5 | Q27: 0.91 | R27: 0.24 | S27: 7.08 | T27: 13 | U27: 0.7 | V27: 10 | W27: 2.16 | X27: 5 | Y27: 0.18 | Z27: 0.11 | AA27: 6.59 | AB27: 78.7 | AC27: 80
A28: 22 | B28: 399 | C28: 225 | D28: 214 | E28: 5.42 | F28: 31.2 | G28: 37.9 | H28: 13 | I28: 2.33 | J28: 5 | K28: 0.18 | L28: 0.42 | M28: 8.6 | N28: 14 | O28: 2.26 | P28: 5 | Q28: 0.64 | R28: 0.51 | S28: 6.1 | T28: 15.3 | U28: 0.38 | V28: 11 | W28: 2.2 | X28: 5 | Y28: 0.13 | Z28: 0.33 | AA28: 5.92 | AB28: 78.4 | AC28: <20
A29: 23 | B29: 188 | C29: 102 | D29: 110 | E29: 3.85 | F29: 18.3 | G29: 30 | H29: 15 | I29: 2.41 | J29: 5 | K29: 0.2 | L29: 0.5 | M29: 7.62 | N29: 14 | O29: 2.37 | P29: 5 | Q29: 0.78 | R29: 0.56 | S29: 6.88 | T29: 17.1 | U29: 0.48 | V29: 10 | W29: 2.11 | X29: 5 | Y29: 0.13 | Z29: 0.23 | AA29: 5.81 | AB29: 78.8 | AC29: <20
A30: 24 | B30: 351 | C30: 198 | D30: 224 | E30: 5.88 | F30: 27.2 | G30: 35.9 | H30: 16 | I30: 2.74 | J30: 6 | K30: 0.2 | L30: 0.36 | M30: 7.57 | N30: 14 | O30: 2.66 | P30: 6 | Q30: 0.71 | R30: 0.43 | S30: 7.74 | T30: 15.5 | U30: 0.57 | V30: 11 | W30: 2.31 | X30: 5 | Y30: 0.15 | Z30: 0.22 | AA30: 7.21 | AB30: 78.7 | AC30: <20
A31: 25 | B31: 433 | C31: 240 | D31: 288 | E31: 5.56 | F31: 29 | G31: 48.2 | H31: 17 | I31: 2.45 | J31: 7 | K31: 0.15 | L31: 0.28 | M31: 7.57 | N31: 15 | O31: 2.29 | P31: 6 | Q31: 0.49 | R31: 0.34 | S31: 8.22 | T31: 16.8 | U31: 0.38 | V31: 12 | W31: 2.08 | X31: 5 | Y31: 0.14 | Z31: 0.22 | AA31: 7.52 | AB31: 78.9 | AC31: <20
A32: 26 | B32: 217 | C32: 123 | D32: 124 | E32: 5.79 | F32: 30.3 | G32: 41.2 | H32: 18 | I32: 2.37 | J32: 5 | K32: 0.22 | L32: 0.19 | M32: 8.55 | N32: 20 | O32: 2.43 | P32: 5 | Q32: 0.69 | R32: 0.21 | S32: 7.05 | T32: 19.1 | U32: 0.49 | V32: 13 | W32: 2.14 | X32: 5 | Y32: 0.2 | Z32: 0.12 | AA32: 6.64 | AB32: 78.8 | AC32: 140
A33: 27 | B33: 289 | C33: 157 | D33: 154 | E33: 5.69 | F33: 31.3 | G33: 40.2 | H33: 17 | I33: 2.39 | J33: 5 | K33: 0.19 | L33: 0.32 | M33: 9.48 | N33: 16 | O33: 2.22 | P33: 5 | Q33: 0.55 | R33: 0.3 | S33: 10.4 | T33: 18.8 | U33: 0.42 | V33: 12 | W33: 2.04 | X33: 5 | Y33: 0.19 | Z33: 0.17 | AA33: 9.27 | AB33: 78.6 | AC33: <20
A34: 28 | B34: 256 | C34: 144 | D34: 218 | E34: 4.31 | F34: 31.8 | G34: 43.5 | H34: 18 | I34: 2.78 | J34: 5 | K34: 0.19 | L34: 0.28 | M34: 10.6 | N34: 17 | O34: 2.63 | P34: 5 | Q34: 0.91 | R34: 0.25 | S34: 9.7 | T34: 20 | U34: 0.49 | V34: 14 | W34: 2.36 | X34: 5 | Y34: 0.18 | Z34: 0.15 | AA34: 9.63 | AB34: 78.9 | AC34: <20
A35: 29 | B35: 306 | C35: 170 | D35: 192 | E35: 5.73 | F35: 28.2 | G35: 37.7 | H35: 20 | I35: 2.66 | J35: 5 | K35: 0.18 | L35: 0.31 | M35: 10.3 | N35: 19 | O35: 2.31 | P35: 5 | Q35: 0.59 | R35: 0.35 | S35: 9.92 | T35: 20.3 | U35: 0.48 | V35: 12 | W35: 2.11 | X35: 5 | Y35: 0.17 | Z35: 0.27 | AA35: 9.38 | AB35: 79.2 | AC35: <20
A36: 30 | B36: 253 | C36: 142 | D36: 144 | E36: 5.32 | F36: 21.7 | G36: 28.9 | H36: 18 | I36: 2.39 | J36: 5 | K36: 0.13 | L36: 0.22 | M36: 7.1 | N36: 17 | O36: 2.2 | P36: 5 | Q36: 0.41 | R36: 0.24 | S36: 6.2 | T36: 17.7 | U36: 0.53 | V36: 13 | W36: 2.05 | X36: 5 | Y36: 0.07 | Z36: 0.22 | AA36: 6.18 | AB36: 78.9 | AC36: <20
A37: 平均 | B37: =AVERAGE(B7:B36) -> 309.93333 | C37: =AVERAGE(C7:C36) -> 172.37333 | D37: =AVERAGE(D7:D36) -> 190.46667 | E37: =AVERAGE(E7:E36) -> 5.3563333 | F37: =AVERAGE(F7:F36) -> 30.23 | G37: =AVERAGE(G7:G36) -> 40.973333 | H37: =AVERAGE(H7:H36) -> 17.7 | I37: =AVERAGE(I7:I36) -> 2.5746667 | ... AB37: =AVERAGE(AB7:AB36) -> 78.643333 | AC37: <20
A38: 审核： 制表： 制表日期：2022-12-2
B41: =MIN(B7:B36) -> 168 | C41: =MIN(C7:C36) -> 93.2 | D41: =MIN(D7:D36) -> 102 | E41: =MIN(E7:E36) -> 2.88 | F41: =MIN(F7:F36) -> 18.3 | G41: =MIN(G7:G36) -> 28.4 | H41: =MIN(H7:H36) -> 13 | I41: =MIN(I7:I36) -> 2.25 | ... AB41: =MIN(AB7:AB36) -> 78
B42: =MAX(B7:B36) -> 444 | C42: =MAX(C7:C36) -> 244 | D42: =MAX(D7:D36) -> 324 | E42: =MAX(E7:E36) -> 5.98 | F42: =MAX(F7:F36) -> 37.3 | G42: =MAX(G7:G36) -> 51.2 | H42: =MAX(H7:H36) -> 21 | I42: =MAX(I7:I36) -> 2.9 | ... AB42: =MAX(AB7:AB36) -> 79.2
B43: 进水 | H43: 一期出水 | N43: 二、三期出水 | T43: 高沉池 | V43: 总出水 | AB43: 污泥含水率（%） | AC43: 粪大肠杆菌
...

Sheet 仪表
A1: 常州市深水城北污水处理有限公司设备运行月报表
A2: 44866
A3: 编号 | B3: 仪表名称 | C3: 规格型号 | D3: 安装位置 | E3: 运行情况 | F3: 标定校 准情况 | G3: 备注
A4: 1 | B4: pH计 | C4: 哈希PHD差分探头 | D4: 一期细格栅井 | E4: 正常 | F4: 标定 | G4: （2、9、16）日
A5: 2 | B5: pH计 | C5: 哈希PHD差分探头 | D5: 出水口 | E5: 正常 | F5: 标定 | G5: （2、9、16）日
A6: 3 | B6: MLSS测量仪 | C6: 哈希SC200-solitax | D6: 一期缺好氧池 | E6: 正常 | F6: 标定 | G6: （3、10、17）日
A7: 4 | B7: 溶解氧检测仪 | C7: 哈希SC200-LDO | D7: 一期缺好氧池 | E7: 正常 | F7: 标定 | G7: （4、11、18）日
A8: 5 | B8: 溶解氧检测仪 | C8: 哈希SC200-LDO | D8: 一期好氧池 | E8: 正常 | F8: 标定 | G8: （2、9、16）日
A9: 6 | B9: MLSS测量仪 | C9: 哈希SC200-solitax | D9: 一期好氧池 | E9: 正常 | F9: 标定 | G9: （3、10、17）日
A10: 7 | B10: 溶解氧检测仪 | C10: 哈希SC200-LDO | D10: 二期好氧池 | E10: 正常 | F10: 标定 | G10: （4、11、18）日
A11: 8 | B11: MLSS测量仪 | C11: 哈希SC200-solitax | D11: 二期好氧池 | E11: 正常 | F11: 标定 | G11: （2、9、16）日
A12: 9 | B12: 溶解氧检测仪 | C12: 哈希SC200-LDO | D12: 三期好氧池 | E12: 正常 | F12: 标定 | G12: （3、10、17）日
A13: 10 | B13: MLSS测量仪 | C13: 哈希SC200-solitax | D13: 三期好氧池 | E13: 正常 | F13: 标定 | G13: （4、11、18）日
A14: 11 | B14: COD在线检测仪 | C14: JHC-ⅢA | D14: 总排放口 | E14: 正常 | F14: 标定 | G14: 15日
A15: 12 | B15: TP在线检测仪 | C15: JHP | D15: 总排放口 | E15: 正常 | F15: 标定 | G15: 15日
... A23: 20 | B23: ORP在线仪表 | C23: PC-3100 | D23: 二三期厌缺氧池 | E23: 正常 | F23: 标定 | G23: （3、10、17）日
A24: 审核： 制表： 制表日期：2022-12-2

Sheet 设备
A1: 常州市深水城北污水处理有限公司设备运行汇总报表（一） 2022年11月
A2: 编号 | B2: 设备名称 | C2: 运行天数 （d） | D2: 定时 （h/d） | E2: 额定运行 时间（h） | F2: 实际运行 时间（h） | G2: 故障 （h） | H2: 利用率 （%） | I2: 完好率 （%） | J2: 检修保养情况 | K2: 备 注
A3: 一期
A4: 1 | B4: 刮泥机1# | C4: 30 | D4: 24 | E4: 720 | F4: 0 | H4: =F4/E4 -> 0 | I4: =1-G4/E4 -> 1
A5: 2 | B5: 污水二次提升泵1# | C5: 30 | D5: 24 | E5: 720 | F5: 715 | H5: =F5/E5 -> 0.99305556 | I5: =1-G5/E5 -> 1
A6: 3 | B6: 污水二次提升泵2# | C6: 30 | D6: 24 | E6: 720 | F6: 715 | H6: =F6/E6 -> 0.99305556 | I6: =1-G6/E6 -> 1
A7: 4 | B7: 污水二次提升泵3# | C7: 30 | D7: 24 | E7: 720 | F7: 0 | H7: =F7/E7 -> 0 | I7: =1-G7/E7 -> 1
A8: 5 | B8: 污水二次提升泵4# | C8: 30 | D8: 24 | E8: 720 | F8: 719 | H8: =F8/E8 -> 0.99861111 | I8: =1-G8/E8 -> 1
A9: 6 | B9: 污水二次提升泵5# | C9: 30 | D9: 24 | E9: 720 | F9: 719 | H9: =F9/E9 -> 0.99861111 | I9: =1-G9/E9 -> 1
A10: 7 | B10: 污水二次提升泵6# | C10: 30 | D10: 24 | E10: 720 | F10: 0 | H10: =F10/E10 -> 0 | I10: =1-G10/E10 -> 1
A11: 8 | B11: 水下搅拌器1# | C11: 30 | D11: 24 | E11: 720 | F11: 715 | H11: =F11/E11 -> 0.99305556 | I11: =1-G11/E11 -> 1
A12: 9 | B12: 水下搅拌器2# | C12: 30 | D12: 24 | E12: 720 | F12: 715 | H12: =F12/E12 -> 0.99305556 | I12: =1-G12/E12 -> 1
A13: 10 | B13: 水下搅拌器3# | C13: 30 | D13: 24 | E13: 720 | F13: 715 | H13: =F13/E13 -> 0.99305556 | I13: =1-G13/E13 -> 1
A14: 11 | B14: 水下搅拌器4# | C14: 30 | D14: 24 | E14: 720 | F14: 715 | H14: =F14/E14 -> 0.99305556 | I14: =1-G14/E14 -> 1
A15: 12 | B15: 水下搅拌器5# | C15: 30 | D15: 24 | E15: 720 | F15: 715 | H15: =F15/E15 -> 0.99305556 | I15: =1-G15/E15 -> 1
... A28: 25 | B28: 水下搅拌器18# | C28: 30 | D28: 24 | E28: 720 | F28: 719 | H28: =F28/E28 -> 0.99861111 | I28: =1-G28/E28 -> 1
A29: 26 | B29: 内回流泵1# | C29: 30 | D29: 24 | E29: 720 | F29: 714 | H29: =F29/E29 -> 0.99166667 | I29: =1-G29/E29 -> 1 | J29: 11月30日维修保养
A30: 27 | B30: 内回流泵2# | C30: 30 | D30: 24 | E30: 720 | F30: 714 | G30: 2 | H30: =F30/E30 -> 0.99166667 | I30: =1-G30/E30 -> 0.99722222 | J30: 11月2日水泵轴承故障检修
A31: 审核： | E31: 制表： | I31: 制表时间：2022-12-2
A32: 常州市深水城北污水处理有限公司设备运行汇总报表（二） 2022年11月
A33: 编号 | B33: 设备名称 | C33: 运行天数 （d） | D33: 定时 （h/d） | E33: 额定运行 时间（h） | F33: 实际运行 时间（h） | G33: 故障 （h） | H33: 利用率 （%） | I33: 完好率 （%） | J33: 检修保养情况 | K33: 备 注
A34: 30 | B34: 内回流泵3# | C34: 30 | D34: 24 | E34: 720 | F34: 715 | H34: =F34/E34 -> 0.99305556 | I34: =1-G34/E34 -> 1 | J34: 11月30日维修保养
A35: 29 | B35: 内回流泵4# | C35: 30 | D35: 24 | E35: 720 | F35: 715 | H35: =F35/E35 -> 0.99305556 | I35: =1-G35/E35 -> 1 | J35: 11月30日维修保养
A36: 30 | B36: 内回流泵5# | C36: 30 | D36: 24 | E36: 720 | F36: 719 | H36: =F36/E36 -> 0.99861111 | I36: =1-G36/E36 -> 1 | J36: 11月30日维修保养
A37: 30 | B37: 内回流泵6# | C37: 30 | D37: 24 | E37: 720 | F37: 719 | H37: =F37/E37 -> 0.99861111 | I37: =1-G37/E37 -> 1 | J37: 11月30日维修保养
A38: 32 | B38: 内回流泵7# | C38: 30 | D38: 24 | E38: 720 | F38: 719 | H38: =F38/E38 -> 0.99861111 | I38: =1-G38/E38 -> 1 | J38: 11月30日维修保养
A39: 33 | B39: 内回流泵8# | C39: 30 | D39: 24 | E39: 720 | F39: 719 | H39: =F39/E39 -> 0.99861111 | I39: =1-G39/E39 -> 1 | J39: 11月30日维修保养
A40: 34 | B40: 回流泵1# | C40: 30 | D40: 24 | E40: 720 | F40: 715 | H40: =F40/E40 -> 0.99305556 | I40: =1-G40/E40 -> 1 | J40: 11月30日维修保养
A41: 35 | B41: 回流泵2# | C41: 30 | D41: 24 | E41: 720 | F41: 715 | H41: =F41/E41 -> 0.99305556 | I41: =1-G41/E41 -> 1 | J41: 11月30日维修保养
A42: 36 | B42: 回流泵3# | C42: 30 | D42: 24 | E42: 720 | F42: 0 | H42: =F42/E42 -> 0 | I42: =1-G42/E42 -> 1 | J42: 11月30日维修保养
A43: 37 | B43: 回流泵4# | C43: 30 | D43: 24 | E43: 720 | F43: 719 | H43: =F43/E43 -> 0.99861111 | I43: =1-G43/E43 -> 1 | J43: 11月30日维修保养
A44: 38 | B44: 回流泵5# | C44: 30 | D44: 24 | E44: 720 | F44: 719 | H44: =F44/E44 -> 0.99861111 | I44: =1-G44/E44 -> 1 | J44: 11月30日维修保养
A45: 39 | B45: 回流泵6# | C45: 30 | D45: 24 | E45: 720 | F45: 0 | H45: =F45/E45 -> 0 | I45: =1-G45/E45 -> 1 | J45: 11月30日维修保养
A46: 40 | B46: 吸泥机1# | C46: 30 | D46: 24 | E46: 720 | F46: 692 | H46: =F46/E46 -> 0.96111111 | I46: =1-G46/E46 -> 1
A47: 41 | B47: 吸泥机2# | C47: 30 | D47: 24 | E47: 720 | F47: 715 | H47: =F47/E47 -> 0.99305556 | I47: =1-G47/E47 -> 1
A48: 42 | B48: 吸泥机3# | C48: 30 | D48: 24 | E48: 720 | F48: 715 | H48: =F48/E48 -> 0.99305556 | I48: =1-G48/E48 -> 1
A49: 43 | B49: 吸泥机4# | C49: 30 | D49: 24 | E49: 720 | F49: 715 | H49: =F49/E49 -> 0.99305556 | I49: =1-G49/E49 -> 1
A50: 44 | B50: 浓缩机1# | C50: 30 | D50: 24 | E50: 720 | F50: 720 | H50: =F50/E50 -> 1 | I50: =1-G50/E50 -> 1 | J50: 11月2日设备拆除重置
A51: 45 | B51: 浓缩机2# | C51: 30 | D51: 24 | E51: 720 | F51: 720 | H51: =F51/E51 -> 1 | I51: =1-G51/E51 -> 1
A52: 46 | B52: 浓缩机3# | C52: 30 | D52: 24 | E52: 720 | F52: 720 | H52: =F52/E52 -> 1 | I52: =1-G52/E52 -> 1
...

Sheet 实验
A1: 常州市深水城北污水处理有限公司硝化、反硝化、厌氧释磷实验
A2: 硝化实验
A3: 日期 | B3: 地点 | C3: 化验指标 | D3: 0 | E3: 15 | F3: 30 | G3: 60 | J3: MLSS | L3: 速率
A4: 44887 | B4: 一期南 | C4: NO2-N | J4: 3.268
C5: NO3-N | D5: 3.52 | E5: 4.58 | F5: 6.89 | G5: 7.92 | K5: =SLOPE(D5:G5,D$3:G$3) -> 0.075790476 | L5: =K5*60/J4 -> 1.391502
C6: NH3-N | D6: 8.15 | E6: 6.9 | F6: 5.14 | G6: 3.82 | K6: =SLOPE(D6:G6,D$3:G$3) -> -0.072819048 | L6: =K6*60/J4 -> -1.336947
C7: PO43- | D7: 5.66 | E7: 2.37 | F7: 1.95 | G7: 1.88 | K7: =SLOPE(D7:G7,D$3:G$3) -> -0.053066667 | L7: =K7*60/J4 -> -0.97429621
A8: 反硝化实验
A9: 日期 | B9: 地点 | C9: 化验指标 | D9: 0 | E9: 10 | F9: 20 | G9: 30 | H9: 60 | I9: 90 | J9: MLSS | L9: 速率
A10: 44887 | B10: 一期南 | C10: NO3-N | D10: 7.15 | E10: 6.72 | F10: 5.88 | G10: 4.37 | H10: 2.84 | I10: 2.36 | J10: 3.162 | K10: =SLOPE(D10:I10,D$9:I$9) -> -0.056956522 | L10: =K10*60/J10 -> -1.0807689
A11: 厌氧释磷实验
A12: 日期 | B12: 地点 | C12: 化验指标 | D12: 0 | E12: 15 | F12: 30 | G12: 60 | J12: MLSS | L12: 速率
A13: 44887 | B13: 一期南 | C13: PO43- | D13: 2.88 | E13: 5.34 | F13: 5.91 | G13: 8.84 | J13: 3.518 | K13: =SLOPE(D13:G13,D$12:G$12) -> 0.093885714 | L13: =K13*60/J13 -> 1.6012345
