Workbook

Sheet 1
B2: 记录人 | C2: 一期左进水 流量计读数 | D2: 一期右进水 流量计读数 | E2: 二期左进水 流量计读数 | F2: 二期右进水 流量计读数 | G2: 现场出水 流量计读数 | H2: 现场回用水 读数 | I2: 出水流量计 读数（网站） | J2: 回用水流量 （网站） | K2: 污泥流量 计读数 | L2: PAC2#流量计读数 | M2: PAC3#流量计读数 | N2: PAM流量 计读数 | O2: 盐酸流量 计读数 | P2: 氯酸钠流 量计读数 | Q2: 生反池 水温 | R2: 天气 (阴晴雨) | S2: 盐酸液位 差（CM） | T2: 氯酸钠液位差 差（CM） | U2: 最高流量 m3/h | V2: 最低流量 m3/h | W2: 最高液位 m | X2: 最低液位 m | Y2: 超液位时 间（分） | Z2: 备注 | AA2: 一期左 进水流量 | AB2: 一期右 进水流量 | AC2: 二期左 进水流量 | AD2: 二期右 进水流量 | AE2: 现场出水 流量 | AF2: 现场回用水 流量 | AG2: 进出水 流量差 | AH2: 出水流量（网站） | AI2: 回用水流量（网站） | AJ2: 实际处理量（网站） | AK2: 排泥量 m3 | AL2: PAC量 kg | AM2: PAM量 kg | AN2: 盐酸量 kg | AO2: 氯酸钠量 kg | AP2: 碳源用量kg | AQ2: PAC单耗 ppm | AR2: PAM单耗 ppm | AS2: 盐酸单耗 ppm | AT2: 氯酸钠单耗 ppm
A3: 43831 | B3: 胡叶青 | C3: 28605308 | D3: 14388475 | E3: 10105811 | F3: 9857958 | G3: 273459899 | H3: 105851533 | I3: 273459899 | J3: 105851533 | L3: 4299.8 | M3: 4261.28 | N3: 73752.65 | Q3: 18.5 | R3: 晴 | S3: 350 | T3: 370 | U3: 8301 | V3: 6253 | W3: 4.51 | X3: 3.66 | Y3: 1440 | AA3: =IF(OR(C4=""),"",C4-C3) -> 38624 | AB3: =IF(OR(D4=""),"",D4-D3) -> 46116 | AC3: =IF(OR(E4=""),"",E4-E3) -> 49383 | AD3: =IF(OR(F4=""),"",F4-F3) -> 42968 | AE3: =IF(OR(G4=""),"",G4-G3) -> 181830 | AF3: =IF(OR(H4=""),"",H4-H3) -> 4012 | AG3: =IF(OR(AA3="",AB3="",AC3=""),"",AA3+AB3+AC3+AD3-AE3) -> -4739 | AH3: =IF(OR(I4=""),"",I4-I3) -> 181830 | AI3: =IF(OR(J4=""),"",J4-J3) -> 4012 | AJ3: =IF(OR(AH3="",AI3=""),"",AH3-AI3) -> 177818 | AK3: 3000 | AL3: =IF(OR(L4="",M4=""),"",ROUND((L4-L3+M4-M3)*1200,0)) -> 0 | AM3: =IF(OR(N4=""),"",(ROUND((N4-N3)*2,0))) -> 0 | AN3: =IF(OR(S3=""),"",ROUND(S3*7.1,0)) -> 2485 | AO3: =IF(OR(T3=""),"",ROUND(T3*2.4,0)) -> 888 | AP3: 3395 | AQ3: =IF(OR($AJ3=""),"",ROUND(AL3/$AJ3*1000,1)) -> 0 | AR3: =IF(OR($AJ3=""),"",ROUND(AM3/$AJ3*1000,2)) -> 0 | AS3: =IF(OR($AJ3=""),"",ROUND(AN3/$AJ3*1000,1)) -> 14 | AT3: =IF(OR($AJ3=""),"",ROUND(AO3/$AJ3*1000,2)) -> 4.99
A4: =A3+1 -> 43832 | B4: 潘汝鑫 | C4: 28643932 | D4: 14434591 | E4: 10155194 | F4: 9900926 | G4: 273641729 | H4: 105855545 | I4: 273641729 | J4: 105855545 | L4: 4299.8 | M4: 4261.28 | N4: 73752.65 | Q4: 18.7 | R4: 晴 | S4: 360 | T4: 380 | U4: 8851 | V4: 5412 | W4: 4.8 | X4: 3.42 | Y4: 1440 | AA4: =IF(OR(C5=""),"",C5-C4) -> 37577 | AB4: =IF(OR(D5=""),"",D5-D4) -> 43036 | AC4: =IF(OR(E5=""),"",E5-E4) -> 46117 | AD4: =IF(OR(F5=""),"",F5-F4) -> 40930 | AE4: =IF(OR(G5=""),"",G5-G4) -> 152361 | AF4: =IF(OR(H5=""),"",H5-H4) -> 5169 | AG4: =IF(OR(AA4="",AB4="",AC4=""),"",AA4+AB4+AC4+AD4-AE4) -> 15299 | AH4: =IF(OR(I5=""),"",I5-I4) -> 152361 | AI4: =IF(OR(J5=""),"",J5-J4) -> 5169 | AJ4: =IF(OR(AH4="",AI4=""),"",AH4-AI4) -> 147192 | AK4: 3600 | AL4: =IF(OR(L5="",M5=""),"",ROUND((L5-L4+M5-M4)*1200,0)) -> 0 | AM4: =IF(OR(N5=""),"",(ROUND((N5-N4)*2,0))) -> 0 | AN4: =IF(OR(S4=""),"",ROUND(S4*7.1,0)) -> 2556 | AO4: =IF(OR(T4=""),"",ROUND(T4*2.4,0)) -> 912 | AP4: 3208 | AQ4: =IF(OR($AJ4=""),"",ROUND(AL4/$AJ4*1000,1)) -> 0 | AR4: =IF(OR($AJ4=""),"",ROUND(AM4/$AJ4*1000,2)) -> 0 | AS4: =IF(OR($AJ4=""),"",ROUND(AN4/$AJ4*1000,1)) -> 17.4 | AT4: =IF(OR($AJ4=""),"",ROUND(AO4/$AJ4*1000,2)) -> 6.2
A5: =A4+1 -> 43833 | B5: 陈智娇 | C5: 28681509 | D5: 14477627 | E5: 10201311 | F5: 9941856 | G5: 273794090 | H5: 105860714 | I5: 273794090 | J5: 105860714 | L5: 4299.8 | M5: 4261.28 | N5: 73752.65 | Q5: 18.5 | R5: 晴 | S5: 470 | T5: 490 | U5: 8261 | V5: 5425 | W5: 6.3 | X5: 2.69 | Y5: 1440 | Z5: 3：:0开水解池15圈， | AA5: =IF(OR(C6=""),"",C6-C5) -> 35397 | AB5: =IF(OR(D6=""),"",D6-D5) -> 40571 | AC5: =IF(OR(E6=""),"",E6-E5) -> 44403 | AD5: =IF(OR(F6=""),"",F6-F5) -> 39675 | AE5: =IF(OR(G6=""),"",G6-G5) -> 147857 | AF5: =IF(OR(H6=""),"",H6-H5) -> 5311 | AG5: =IF(OR(AA5="",AB5="",AC5=""),"",AA5+AB5+AC5+AD5-AE5) -> 12189 | AH5: =IF(OR(I6=""),"",I6-I5) -> 147857 | AI5: =IF(OR(J6=""),"",J6-J5) -> 5311 | AJ5: =IF(OR(AH5="",AI5=""),"",AH5-AI5) -> 142546 | AK5: 3500 | AL5: =IF(OR(L6="",M6=""),"",ROUND((L6-L5+M6-M5)*1200,0)) -> 0 | AM5: =IF(OR(N6=""),"",(ROUND((N6-N5)*2,0))) -> 0 | AN5: =IF(OR(S5=""),"",ROUND(S5*7.1,0)) -> 3337 | AO5: =IF(OR(T5=""),"",ROUND(T5*2.4,0)) -> 1176 | AP5: 3286 | AQ5: =IF(OR($AJ5=""),"",ROUND(AL5/$AJ5*1000,1)) -> 0 | AR5: =IF(OR($AJ5=""),"",ROUND(AM5/$AJ5*1000,2)) -> 0 | AS5: =IF(OR($AJ5=""),"",ROUND(AN5/$AJ5*1000,1)) -> 23.4 | AT5: =IF(OR($AJ5=""),"",ROUND(AO5/$AJ5*1000,2)) -> 8.25
A6: =A5+1 -> 43834 | B6: 易萍 | C6: 28716906 | D6: 14518198 | E6: 10245714 | F6: 9981531 | G6: 273941947 | H6: 105866025 | I6: 273941947 | J6: 105866025 | L6: 4299.8 | M6: 4261.28 | N6: 73752.65 | Q6: 18.3 | R6: 晴 | S6: 700 | T6: 720 | U6: 9112 | V6: 7500 | W6: 7.3 | X6: 4.05 | Y6: 1440 | Z6: 11：00关水解池。5：00进水解池 | AA6: =IF(OR(C7=""),"",C7-C6) -> 43202 | AB6: =IF(OR(D7=""),"",D7-D6) -> 51040 | AC6: =IF(OR(E7=""),"",E7-E6) -> 55572 | AD6: =IF(OR(F7=""),"",F7-F6) -> 48868 | AE6: =IF(OR(G7=""),"",G7-G6) -> 174996 | AF6: =IF(OR(H7=""),"",H7-H6) -> 5363 | AG6: =IF(OR(AA6="",AB6="",AC6=""),"",AA6+AB6+AC6+AD6-AE6) -> 23686 | AH6: =IF(OR(I7=""),"",I7-I6) -> 174996 | AI6: =IF(OR(J7=""),"",J7-J6) -> 5363 | AJ6: =IF(OR(AH6="",AI6=""),"",AH6-AI6) -> 169633 | AK6: 3600 | AL6: =IF(OR(L7="",M7=""),"",ROUND((L7-L6+M7-M6)*1200,0)) -> 0 | AM6: =IF(OR(N7=""),"",(ROUND((N7-N6)*2,0))) -> 0 | AN6: =IF(OR(S6=""),"",ROUND(S6*7.1,0)) -> 4970 | AO6: =IF(OR(T6=""),"",ROUND(T6*2.4,0)) -> 1728 | AP6: 3385 | AQ6: =IF(OR($AJ6=""),"",ROUND(AL6/$AJ6*1000,1)) -> 0 | AR6: =IF(OR($AJ6=""),"",ROUND(AM6/$AJ6*1000,2)) -> 0 | AS6: =IF(OR($AJ6=""),"",ROUND(AN6/$AJ6*1000,1)) -> 29.3 | AT6: =IF(OR($AJ6=""),"",ROUND(AO6/$AJ6*1000,2)) -> 10.19
A7: =A6+1 -> 43835 | B7: 易萍 | C7: 28760108 | D7: 14569238 | E7: 10301286 | F7: 10030399 | G7: 274116943 | H7: 105871388 | I7: 274116943 | J7: 105871388 | L7: 4299.8 | M7: 4261.28 | N7: 73752.65 | Q7: 18.2 | R7: 雨 | S7: 590 | T7: 600 | U7: 10211 | V7: 8641 | W7: 7.24 | X7: 6.5 | Y7: 1440 | Z7: 6:30关水解进水 | AA7: =IF(OR(C8=""),"",C8-C7) -> 49225 | AB7: =IF(OR(D8=""),"",D8-D7) -> 61637 | AC7: =IF(OR(E8=""),"",E8-E7) -> 63992 | AD7: =IF(OR(F8=""),"",F8-F7) -> 60740 | AE7: =IF(OR(G8=""),"",G8-G7) -> 209826 | AF7: =IF(OR(H8=""),"",H8-H7) -> 5321 | AG7: =IF(OR(AA7="",AB7="",AC7=""),"",AA7+AB7+AC7+AD7-AE7) -> 25768 | AH7: =IF(OR(I8=""),"",I8-I7) -> 209826 | AI7: =IF(OR(J8=""),"",J8-J7) -> 5321 | AJ7: =IF(OR(AH7="",AI7=""),"",AH7-AI7) -> 204505 | AK7: 3500 | AL7: =IF(OR(L8="",M8=""),"",ROUND((L8-L7+M8-M7)*1200,0)) -> 0 | AM7: =IF(OR(N8=""),"",(ROUND((N8-N7)*2,0))) -> 0 | AN7: =IF(OR(S7=""),"",ROUND(S7*7.1,0)) -> 4189 | AO7: =IF(OR(T7=""),"",ROUND(T7*2.4,0)) -> 1440 | AP7: 2985 | AQ7: =IF(OR($AJ7=""),"",ROUND(AL7/$AJ7*1000,1)) -> 0 | AR7: =IF(OR($AJ7=""),"",ROUND(AM7/$AJ7*1000,2)) -> 0 | AS7: =IF(OR($AJ7=""),"",ROUND(AN7/$AJ7*1000,1)) -> 20.5 | AT7: =IF(OR($AJ7=""),"",ROUND(AO7/$AJ7*1000,2)) -> 7.04
A8: =A7+1 -> 43836 | B8: 易萍 | C8: 28809333 | D8: 14630875 | E8: 10365278 | F8: 10091139 | G8: 274326769 | H8: 105876709 | I8: 274326769 | J8: 105876709 | L8: 4299.8 | M8: 4261.28 | N8: 73752.65 | Q8: 18.5 | R8: 晴 | S8: 640 | T8: 660 | U8: 9152 | V8: 8612 | W8: 7.2 | X8: 5.08 | Y8: 1440 | AA8: =IF(OR(C9=""),"",C9-C8) -> 46890 | AB8: =IF(OR(D9=""),"",D9-D8) -> 58061 | AC8: =IF(OR(E9=""),"",E9-E8) -> 58440 | AD8: =IF(OR(F9=""),"",F9-F8) -> 55614 | AE8: =IF(OR(G9=""),"",G9-G8) -> 205416 | AF8: =IF(OR(H9=""),"",H9-H8) -> 5303 | AG8: =IF(OR(AA8="",AB8="",AC8=""),"",AA8+AB8+AC8+AD8-AE8) -> 13589 | AH8: =IF(OR(I9=""),"",I9-I8) -> 205416 | AI8: =IF(OR(J9=""),"",J9-J8) -> 5303 | AJ8: =IF(OR(AH8="",AI8=""),"",AH8-AI8) -> 200113 | AK8: 3200 | AL8: =IF(OR(L9="",M9=""),"",ROUND((L9-L8+M9-M8)*1200,0)) -> 0 | AM8: =IF(OR(N9=""),"",(ROUND((N9-N8)*2,0))) -> 0 | AN8: =IF(OR(S8=""),"",ROUND(S8*7.1,0)) -> 4544 | AO8: =IF(OR(T8=""),"",ROUND(T8*2.4,0)) -> 1584 | AP8: 2711 | AQ8: =IF(OR($AJ8=""),"",ROUND(AL8/$AJ8*1000,1)) -> 0 | AR8: =IF(OR($AJ8=""),"",ROUND(AM8/$AJ8*1000,2)) -> 0 | AS8: =IF(OR($AJ8=""),"",ROUND(AN8/$AJ8*1000,1)) -> 22.7 | AT8: =IF(OR($AJ8=""),"",ROUND(AO8/$AJ8*1000,2)) -> 7.92
A9: =A8+1 -> 43837 | B9: 易萍 | C9: 28856223 | D9: 14688936 | E9: 10423718 | F9: 10146753 | G9: 274532185 | H9: 105882012 | I9: 274532185 | J9: 105882012 | L9: 4299.8 | M9: 4261.28 | N9: 73752.65 | Q9: 18.5 | R9: 阴 | S9: 520 | T9: 530 | U9: 9253 | V9: 6870 | W9: 5.13 | X9: 2.81 | Y9: 1380 | AA9: =IF(OR(C10=""),"",C10-C9) -> 44596 | AB9: =IF(OR(D10=""),"",D10-D9) -> 56194 | AC9: =IF(OR(E10=""),"",E10-E9) -> 56191 | AD9: =IF(OR(F10=""),"",F10-F9) -> 52942 | AE9: =IF(OR(G10=""),"",G10-G9) -> 211110 | AF9: =IF(OR(H10=""),"",H10-H9) -> 5213 | AG9: =IF(OR(AA9="",AB9="",AC9=""),"",AA9+AB9+AC9+AD9-AE9) -> -1187 | AH9: =IF(OR(I10=""),"",I10-I9) -> 211110 | AI9: =IF(OR(J10=""),"",J10-J9) -> 5213 | AJ9: =IF(OR(AH9="",AI9=""),"",AH9-AI9) -> 205897 | AK9: 3600 | AL9: =IF(OR(L10="",M10=""),"",ROUND((L10-L9+M10-M9)*1200,0)) -> 0 | AM9: =IF(OR(N10=""),"",(ROUND((N10-N9)*2,0))) -> 0 | AN9: =IF(OR(S9=""),"",ROUND(S9*7.1,0)) -> 3692 | AO9: =IF(OR(T9=""),"",ROUND(T9*2.4,0)) -> 1272 | AP9: 2889 | AQ9: =IF(OR($AJ9=""),"",ROUND(AL9/$AJ9*1000,1)) -> 0 | AR9: =IF(OR($AJ9=""),"",ROUND(AM9/$AJ9*1000,2)) -> 0 | AS9: =IF(OR($AJ9=""),"",ROUND(AN9/$AJ9*1000,1)) -> 17.9 | AT9: =IF(OR($AJ9=""),"",ROUND(AO9/$AJ9*1000,2)) -> 6.18
A10: =A9+1 -> 43838 | B10: 仇昊 | C10: 28900819 | D10: 14745130 | E10: 10479909 | F10: 10199695 | G10: 274743295 | H10: 105887225 | I10: 274743295 | J10: 105887225 | L10: 4299.8 | M10: 4261.28 | N10: 73752.65 | Q10: 18.3 | R10: 阴 | S10: 500 | T10: 510 | U10: 9125 | V10: 6875 | W10: 2.18 | X10: 5.41 | Y10: 1400 | AA10: =IF(OR(C11=""),"",C11-C10) -> 41721 | AB10: =IF(OR(D11=""),"",D11-D10) -> 51331 | AC10: =IF(OR(E11=""),"",E11-E10) -> 54420 | AD10: =IF(OR(F11=""),"",F11-F10) -> 47536 | AE10: =IF(OR(G11=""),"",G11-G10) -> 176214 | AF10: =IF(OR(H11=""),"",H11-H10) -> 5319 | AG10: =IF(OR(AA10="",AB10="",AC10=""),"",AA10+AB10+AC10+AD10-AE10) -> 18794 | AH10: =IF(OR(I11=""),"",I11-I10) -> 185881 | AI10: =IF(OR(J11=""),"",J11-J10) -> 5319 | AJ10: =IF(OR(AH10="",AI10=""),"",AH10-AI10) -> 180562 | AK10: 3500 | AL10: =IF(OR(L11="",M11=""),"",ROUND((L11-L10+M11-M10)*1200,0)) -> 0 | AM10: =IF(OR(N11=""),"",(ROUND((N11-N10)*2,0))) -> 0 | AN10: =IF(OR(S10=""),"",ROUND(S10*7.1,0)) -> 3550 | AO10: =IF(OR(T10=""),"",ROUND(T10*2.4,0)) -> 1224 | AP10: 2768 | AQ10: =IF(OR($AJ10=""),"",ROUND(AL10/$AJ10*1000,1)) -> 0 | AR10: =IF(OR($AJ10=""),"",ROUND(AM10/$AJ10*1000,2)) -> 0 | AS10: =IF(OR($AJ10=""),"",ROUND(AN10/$AJ10*1000,1)) -> 19.7 | AT10: =IF(OR($AJ10=""),"",ROUND(AO10/$AJ10*1000,2)) -> 6.78
A11: =A10+1 -> 43839 | B11: 胡叶青 | C11: 28942540 | D11: 14796461 | E11: 10534329 | F11: 10247231 | G11: 274919509 | H11: 105892544 | I11: 274929176 | J11: 105892544 | L11: 4299.8 | M11: 4261.28 | N11: 73752.65 | Q11: 18 | R11: 阴 | S11: 630 | T11: 650 | U11: 8511 | V11: 5920 | W11: 5.06 | X11: 3.8 | Y11: 1440 | AA11: =IF(OR(C12=""),"",C12-C11) -> 41561 | AB11: =IF(OR(D12=""),"",D12-D11) -> 50983 | AC11: =IF(OR(E12=""),"",E12-E11) -> 54413 | AD11: =IF(OR(F12=""),"",F12-F11) -> 46817 | AE11: =IF(OR(G12=""),"",G12-G11) -> 208619 | AF11: =IF(OR(H12=""),"",H12-H11) -> 5654 | AG11: =IF(OR(AA11="",AB11="",AC11=""),"",AA11+AB11+AC11+AD11-AE11) -> -14845 | AH11: =IF(OR(I12=""),"",I12-I11) -> 198952 | AI11: =IF(OR(J12=""),"",J12-J11) -> 5654 | AJ11: =IF(OR(AH11="",AI11=""),"",AH11-AI11) -> 193298 | AK11: 3800 | AL11: =IF(OR(L12="",M12=""),"",ROUND((L12-L11+M12-M11)*1200,0)) -> 0 | AM11: =IF(OR(N12=""),"",(ROUND((N12-N11)*2,0))) -> 0 | AN11: =IF(OR(S11=""),"",ROUND(S11*7.1,0)) -> 4473 | AO11: =IF(OR(T11=""),"",ROUND(T11*2.4,0)) -> 1560 | AP11: 2799 | AQ11: =IF(OR($AJ11=""),"",ROUND(AL11/$AJ11*1000,1)) -> 0 | AR11: =IF(OR($AJ11=""),"",ROUND(AM11/$AJ11*1000,2)) -> 0 | AS11: =IF(OR($AJ11=""),"",ROUND(AN11/$AJ11*1000,1)) -> 23.1 | AT11: =IF(OR($AJ11=""),"",ROUND(AO11/$AJ11*1000,2)) -> 8.07
A12: =A11+1 -> 43840 | B12: 易萍 | C12: 28984101 | D12: 14847444 | E12: 10588742 | F12: 10294048 | G12: 275128128 | H12: 105898198 | I12: 275128128 | J12: 105898198 | L12: 4299.8 | M12: 4261.28 | N12: 73752.65 | Q12: 18.2 | R12: 阴 | S12: 700 | T12: 710 | U12: 10213 | V12: 6021 | W12: 3.55 | X12: 2.41 | Y12: 420 | Z12: 9:00开水解池，6:00停 | AA12: =IF(OR(C13=""),"",C13-C12) -> 50312 | AB12: =IF(OR(D13=""),"",D13-D12) -> 64142 | AC12: =IF(OR(E13=""),"",E13-E12) -> 64013 | AD12: =IF(OR(F13=""),"",F13-F12) -> 57729 | AE12: =IF(OR(G13=""),"",G13-G12) -> 197672 | AF12: =IF(OR(H13=""),"",H13-H12) -> 5514 | AG12: =IF(OR(AA12="",AB12="",AC12=""),"",AA12+AB12+AC12+AD12-AE12) -> 38524 | AH12: =IF(OR(I13=""),"",I13-I12) -> 197672 | AI12: =IF(OR(J13=""),"",J13-J12) -> 5514 | AJ12: =IF(OR(AH12="",AI12=""),"",AH12-AI12) -> 192158 | AK12: 3600 | AL12: =IF(OR(L13="",M13=""),"",ROUND((L13-L12+M13-M12)*1200,0)) -> 0 | AM12: =IF(OR(N13=""),"",(ROUND((N13-N12)*2,0))) -> 0 | AN12: =IF(OR(S12=""),"",ROUND(S12*7.1,0)) -> 4970 | AO12: =IF(OR(T12=""),"",ROUND(T12*2.4,0)) -> 1704 | AP12: 2806 | AQ12: =IF(OR($AJ12=""),"",ROUND(AL12/$AJ12*1000,1)) -> 0 | AR12: =IF(OR($AJ12=""),"",ROUND(AM12/$AJ12*1000,2)) -> 0 | AS12: =IF(OR($AJ12=""),"",ROUND(AN12/$AJ12*1000,1)) -> 25.9 | AT12: =IF(OR($AJ12=""),"",ROUND(AO12/$AJ12*1000,2)) -> 8.87
A13: =A12+1 -> 43841 | B13: 易萍 | C13: 29034413 | D13: 14911586 | E13: 10652755 | F13: 10351777 | G13: 275325800 | H13: 105903712 | I13: 275325800 | J13: 105903712 | L13: 4299.8 | M13: 4261.28 | N13: 73752.65 | Q13: 18.5 | R13: 晴 | S13: 720 | T13: 740 | U13: 9056 | V13: 7412 | W13: 5.12 | X13: 3.78 | Y13: 1320 | AA13: =IF(OR(C14=""),"",C14-C13) -> 44757 | AB13: =IF(OR(D14=""),"",D14-D13) -> 58873 | AC13: =IF(OR(E14=""),"",E14-E13) -> 52150 | AD13: =IF(OR(F14=""),"",F14-F13) -> 47187 | AE13: =IF(OR(G14=""),"",G14-G13) -> 197445 | AF13: =IF(OR(H14=""),"",H14-H13) -> 5587 | AG13: =IF(OR(AA13="",AB13="",AC13=""),"",AA13+AB13+AC13+AD13-AE13) -> 5522 | AH13: =IF(OR(I14=""),"",I14-I13) -> 197445 | AI13: =IF(OR(J14=""),"",J14-J13) -> 5587 | AJ13: =IF(OR(AH13="",AI13=""),"",AH13-AI13) -> 191858 | AK13: 3300 | AL13: =IF(OR(L14="",M14=""),"",ROUND((L14-L13+M14-M13)*1200,0)) -> 1488 | AM13: =IF(OR(N14=""),"",(ROUND((N14-N13)*2,0))) -> 10 | AN13: =IF(OR(S13=""),"",ROUND(S13*7.1,0)) -> 5112 | AO13: =IF(OR(T13=""),"",ROUND(T13*2.4,0)) -> 1776 | AP13: 2836 | AQ13: =IF(OR($AJ13=""),"",ROUND(AL13/$AJ13*1000,1)) -> 7.8 | AR13: =IF(OR($AJ13=""),"",ROUND(AM13/$AJ13*1000,2)) -> 0.05 | AS13: =IF(OR($AJ13=""),"",ROUND(AN13/$AJ13*1000,1)) -> 26.6 | AT13: =IF(OR($AJ13=""),"",ROUND(AO13/$AJ13*1000,2)) -> 9.26
A14: =A13+1 -> 43842 | B14: 陈智娇 | C14: 29079170 | D14: 14970459 | E14: 10704905 | F14: 10398964 | G14: 275523245 | H14: 105909299 | I14: 275523245 | J14: 105909299 | L14: 4299.8 | M14: 4262.52 | N14: 73757.46 | Q14: 18.7 | R14: 晴 | S14: 520 | T14: 550 | U14: 9021 | V14: 5596 | W14: 5.6 | X14: 3.5 | Y14: 1440 | AA14: =IF(OR(C15=""),"",C15-C14) -> 42974 | AB14: =IF(OR(D15=""),"",D15-D14) -> 56457 | AC14: =IF(OR(E15=""),"",E15-E14) -> 51034 | AD14: =IF(OR(F15=""),"",F15-F14) -> 45917 | AE14: =IF(OR(G15=""),"",G15-G14) -> 192360 | AF14: =IF(OR(H15=""),"",H15-H14) -> 5534 | AG14: =IF(OR(AA14="",AB14="",AC14=""),"",AA14+AB14+AC14+AD14-AE14) -> 4022 | AH14: =IF(OR(I15=""),"",I15-I14) -> 192360 | AI14: =IF(OR(J15=""),"",J15-J14) -> 5534 | AJ14: =IF(OR(AH14="",AI14=""),"",AH14-AI14) -> 186826 | AK14: 3500 | AL14: =IF(OR(L15="",M15=""),"",ROUND((L15-L14+M15-M14)*1200,0)) -> 3912 | AM14: =IF(OR(N15=""),"",(ROUND((N15-N14)*2,0))) -> 51 | AN14: =IF(OR(S14=""),"",ROUND(S14*7.1,0)) -> 3692 | AO14: =IF(OR(T14=""),"",ROUND(T14*2.4,0)) -> 1320 | AP14: 3152 | AQ14: =IF(OR($AJ14=""),"",ROUND(AL14/$AJ14*1000,1)) -> 20.9 | AR14: =IF(OR($AJ14=""),"",ROUND(AM14/$AJ14*1000,2)) -> 0.27 | AS14: =IF(OR($AJ14=""),"",ROUND(AN14/$AJ14*1000,1)) -> 19.8 | AT14: =IF(OR($AJ14=""),"",ROUND(AO14/$AJ14*1000,2)) -> 7.07
A15: =A14+1 -> 43843 | B15: 易萍 | C15: 29122144 | D15: 15026916 | E15: 10755939 | F15: 10444881 | G15: 275715605 | H15: 105914833 | I15: 275715605 | J15: 105914833 | L15: 4299.8 | M15: 4265.78 | N15: 73782.82 | Q15: 18.2 | R15: 晴 | S15: 470 | T15: 500 | U15: 7990 | V15: 7211 | W15: 4.72 | X15: 3.32 | Y15: 1440 | AA15: =IF(OR(C16=""),"",C16-C15) -> 40004 | AB15: =IF(OR(D16=""),"",D16-D15) -> 52409 | AC15: =IF(OR(E16=""),"",E16-E15) -> 47379 | AD15: =IF(OR(F16=""),"",F16-F15) -> 42668 | AE15: =IF(OR(G16=""),"",G16-G15) -> 181716 | AF15: =IF(OR(H16=""),"",H16-H15) -> 5545 | AG15: =IF(OR(AA15="",AB15="",AC15=""),"",AA15+AB15+AC15+AD15-AE15) -> 744 | AH15: =IF(OR(I16=""),"",I16-I15) -> 181716 | AI15: =IF(OR(J16=""),"",J16-J15) -> 5545 | AJ15: =IF(OR(AH15="",AI15=""),"",AH15-AI15) -> 176171 | AK15: 3200 | AL15: =IF(OR(L16="",M16=""),"",ROUND((L16-L15+M16-M15)*1200,0)) -> 1296 | AM15: =IF(OR(N16=""),"",(ROUND((N16-N15)*2,0))) -> 19 | AN15: =IF(OR(S15=""),"",ROUND(S15*7.1,0)) -> 3337 | AO15: =IF(OR(T15=""),"",ROUND(T15*2.4,0)) -> 1200 | AP15: 3099 | AQ15: =IF(OR($AJ15=""),"",ROUND(AL15/$AJ15*1000,1)) -> 7.4 | AR15: =IF(OR($AJ15=""),"",ROUND(AM15/$AJ15*1000,2)) -> 0.11 | AS15: =IF(OR($AJ15=""),"",ROUND(AN15/$AJ15*1000,1)) -> 18.9 | AT15: =IF(OR($AJ15=""),"",ROUND(AO15/$AJ15*1000,2)) -> 6.81
A16: =A15+1 -> 43844 | B16: 易萍 | C16: 29162148 | D16: 15079325 | E16: 10803318 | F16: 10487549 | G16: 275897321 | H16: 105920378 | I16: 275897321 | J16: 105920378 | L16: 4299.8 | M16: 4266.86 | N16: 73792.24 | Q16: 18.4 | R16: 晴 | S16: 350 | T16: 370 | U16: 7845 | V16: 5412 | W16: 4.6 | X16: 2.56 | Y16: 1320 | AA16: =IF(OR(C17=""),"",C17-C16) -> 39540 | AB16: =IF(OR(D17=""),"",D17-D16) -> 48318 | AC16: =IF(OR(E17=""),"",E17-E16) -> 45986 | AD16: =IF(OR(F17=""),"",F17-F16) -> 41162 | AE16: =IF(OR(G17=""),"",G17-G16) -> 178124 | AF16: =IF(OR(H17=""),"",H17-H16) -> 5534 | AG16: =IF(OR(AA16="",AB16="",AC16=""),"",AA16+AB16+AC16+AD16-AE16) -> -3118 | AH16: =IF(OR(I17=""),"",I17-I16) -> 178124 | AI16: =IF(OR(J17=""),"",J17-J16) -> 5534 | AJ16: =IF(OR(AH16="",AI16=""),"",AH16-AI16) -> 172590 | AK16: 3500 | AL16: =IF(OR(L17="",M17=""),"",ROUND((L17-L16+M17-M16)*1200,0)) -> 0 | AM16: =IF(OR(N17=""),"",(ROUND((N17-N16)*2,0))) -> 0 | AN16: =IF(OR(S16=""),"",ROUND(S16*7.1,0)) -> 2485 | AO16: =IF(OR(T16=""),"",ROUND(T16*2.4,0)) -> 888 | AP16: 3205 | AQ16: =IF(OR($AJ16=""),"",ROUND(AL16/$AJ16*1000,1)) -> 0 | AR16: =IF(OR($AJ16=""),"",ROUND(AM16/$AJ16*1000,2)) -> 0 | AS16: =IF(OR($AJ16=""),"",ROUND(AN16/$AJ16*1000,1)) -> 14.4 | AT16: =IF(OR($AJ16=""),"",ROUND(AO16/$AJ16*1000,2)) -> 5.15
A17: =A16+1 -> 43845 | B17: 陈智娇 | C17: 29201688 | D17: 15127643 | E17: 10849304 | F17: 10528711 | G17: 276075445 | H17: 105925912 | I17: 276075445 | J17: 105925912 | L17: 4299.8 | M17: 4266.86 | N17: 73792.24 | Q17: 17.8 | R17: 晴 | S17: 380 | T17: 300 | U17: 7600 | V17: 4300 | W17: 4.6 | X17: 2.5 | Y17: 978 | AA17: =IF(OR(C18=""),"",C18-C17) -> 38575 | AB17: =IF(OR(D18=""),"",D18-D17) -> 45918 | AC17: =IF(OR(E18=""),"",E18-E17) -> 44477 | AD17: =IF(OR(F18=""),"",F18-F17) -> 40027 | AE17: =IF(OR(G18=""),"",G18-G17) -> 167153 | AF17: =IF(OR(H18=""),"",H18-H17) -> 5470 | AG17: =IF(OR(AA17="",AB17="",AC17=""),"",AA17+AB17+AC17+AD17-AE17) -> 1844 | AH17: =IF(OR(I18=""),"",I18-I17) -> 167153 | AI17: =IF(OR(J18=""),"",J18-J17) -> 5470 | AJ17: =IF(OR(AH17="",AI17=""),"",AH17-AI17) -> 161683 | AK17: 5000 | AL17: =IF(OR(L18="",M18=""),"",ROUND((L18-L17+M18-M17)*1200,0)) -> 0 | AM17: =IF(OR(N18=""),"",(ROUND((N18-N17)*2,0))) -> 0 | AN17: =IF(OR(S17=""),"",ROUND(S17*7.1,0)) -> 2698 | AO17: =IF(OR(T17=""),"",ROUND(T17*2.4,0)) -> 720 | AP17: 3155 | AQ17: =IF(OR($AJ17=""),"",ROUND(AL17/$AJ17*1000,1)) -> 0 | AR17: =IF(OR($AJ17=""),"",ROUND(AM17/$AJ17*1000,2)) -> 0 | AS17: =IF(OR($AJ17=""),"",ROUND(AN17/$AJ17*1000,1)) -> 16.7 | AT17: =IF(OR($AJ17=""),"",ROUND(AO17/$AJ17*1000,2)) -> 4.45
A18: =A17+1 -> 43846 | B18: 仇昊 | C18: 29240263 | D18: 15173561 | E18: 10893781 | F18: 10568738 | G18: 276242598 | H18: 105931382 | I18: 276242598 | J18: 105931382 | L18: 4299.8 | M18: 4266.86 | N18: 73792.24 | Q18: 17.6 | R18: 晴 | S18: 450 | T18: 470 | U18: 7512 | V18: 3146 | W18: 5.24 | X18: 2.35 | Y18: 1260 | AA18: =IF(OR(C19=""),"",C19-C18) -> 36218 | AB18: =IF(OR(D19=""),"",D19-D18) -> 42559 | AC18: =IF(OR(E19=""),"",E19-E18) -> 40995 | AD18: =IF(OR(F19=""),"",F19-F18) -> 37138 | AE18: =IF(OR(G19=""),"",G19-G18) -> 154241 | AF18: =IF(OR(H19=""),"",H19-H18) -> 5596 | AG18: =IF(OR(AA18="",AB18="",AC18=""),"",AA18+AB18+AC18+AD18-AE18) -> 2669 | AH18: =IF(OR(I19=""),"",I19-I18) -> 154241 | AI18: =IF(OR(J19=""),"",J19-J18) -> 5596 | AJ18: =IF(OR(AH18="",AI18=""),"",AH18-AI18) -> 148645 | AK18: 5200 | AL18: =IF(OR(L19="",M19=""),"",ROUND((L19-L18+M19-M18)*1200,0)) -> 0 | AM18: =IF(OR(N19=""),"",(ROUND((N19-N18)*2,0))) -> 0 | AN18: =IF(OR(S18=""),"",ROUND(S18*7.1,0)) -> 3195 | AO18: =IF(OR(T18=""),"",ROUND(T18*2.4,0)) -> 1128 | AP18: 2825 | AQ18: =IF(OR($AJ18=""),"",ROUND(AL18/$AJ18*1000,1)) -> 0 | AR18: =IF(OR($AJ18=""),"",ROUND(AM18/$AJ18*1000,2)) -> 0 | AS18: =IF(OR($AJ18=""),"",ROUND(AN18/$AJ18*1000,1)) -> 21.5 | AT18: =IF(OR($AJ18=""),"",ROUND(AO18/$AJ18*1000,2)) -> 7.59
A19: =A18+1 -> 43847 | B19: 易萍 | C19: 29276481 | D19: 15216120 | E19: 10934776 | F19: 10605876 | G19: 276396839 | H19: 105936978 | I19: 276396839 | J19: 105936978 | L19: 4299.8 | M19: 4266.86 | N19: 73792.24 | Q19: 20.8 | R19: 晴 | S19: 750 | T19: 760 | U19: 7994 | V19: 3139 | W19: 4.52 | X19: 2.8 | Y19: 1230 | AA19: =IF(OR(C20=""),"",C20-C19) -> 37871 | AB19: =IF(OR(D20=""),"",D20-D19) -> 45017 | AC19: =IF(OR(E20=""),"",E20-E19) -> 43390 | AD19: =IF(OR(F20=""),"",F20-F19) -> 38996 | AE19: =IF(OR(G20=""),"",G20-G19) -> 164922 | AF19: =IF(OR(H20=""),"",H20-H19) -> 5560 | AG19: =IF(OR(AA19="",AB19="",AC19=""),"",AA19+AB19+AC19+AD19-AE19) -> 352 | AH19: =IF(OR(I20=""),"",I20-I19) -> 164922 | AI19: =IF(OR(J20=""),"",J20-J19) -> 5560 | AJ19: =IF(OR(AH19="",AI19=""),"",AH19-AI19) -> 159362 | AK19: 5000 | AL19: =IF(OR(L20="",M20=""),"",ROUND((L20-L19+M20-M19)*1200,0)) -> 1644 | AM19: =IF(OR(N20=""),"",(ROUND((N20-N19)*2,0))) -> 3 | AN19: =IF(OR(S19=""),"",ROUND(S19*7.1,0)) -> 5325 | AO19: =IF(OR(T19=""),"",ROUND(T19*2.4,0)) -> 1824 | AP19: 2453 | AQ19: =IF(OR($AJ19=""),"",ROUND(AL19/$AJ19*1000,1)) -> 10.3 | AR19: =IF(OR($AJ19=""),"",ROUND(AM19/$AJ19*1000,2)) -> 0.02 | AS19: =IF(OR($AJ19=""),"",ROUND(AN19/$AJ19*1000,1)) -> 33.4 | AT19: =IF(OR($AJ19=""),"",ROUND(AO19/$AJ19*1000,2)) -> 11.45
A20: =A19+1 -> 43848 | B20: 易萍 | C20: 29314352 | D20: 15261137 | E20: 10978166 | F20: 10644872 | G20: 276561761 | H20: 105942538 | I20: 276561761 | J20: 105942538 | L20: 4299.8 | M20: 4268.23 | N20: 73793.77 | Q20: 22.5 | R20: 晴 | S20: 700 | T20: 710 | U20: 7237 | V20: 5104 | W20: 5.53 | X20: 2.67 | Y20: 1260 | AA20: =IF(OR(C21=""),"",C21-C20) -> 37113 | AB20: =IF(OR(D21=""),"",D21-D20) -> 42974 | AC20: =IF(OR(E21=""),"",E21-E20) -> 41949 | AD20: =IF(OR(F21=""),"",F21-F20) -> 37849 | AE20: =IF(OR(G21=""),"",G21-G20) -> 151904 | AF20: =IF(OR(H21=""),"",H21-H20) -> 5528 | AG20: =IF(OR(AA20="",AB20="",AC20=""),"",AA20+AB20+AC20+AD20-AE20) -> 7981 | AH20: =IF(OR(I21=""),"",I21-I20) -> 151904 | AI20: =IF(OR(J21=""),"",J21-J20) -> 5528 | AJ20: =IF(OR(AH20="",AI20=""),"",AH20-AI20) -> 146376 | AK20: 5100 | AL20: =IF(OR(L21="",M21=""),"",ROUND((L21-L20+M21-M20)*1200,0)) -> 9060 | AM20: =IF(OR(N21=""),"",(ROUND((N21-N20)*2,0))) -> 51 | AN20: =IF(OR(S20=""),"",ROUND(S20*7.1,0)) -> 4970 | AO20: =IF(OR(T20=""),"",ROUND(T20*2.4,0)) -> 1704 | AP20: 3191 | AQ20: =IF(OR($AJ20=""),"",ROUND(AL20/$AJ20*1000,1)) -> 61.9 | AR20: =IF(OR($AJ20=""),"",ROUND(AM20/$AJ20*1000,2)) -> 0.35 | AS20: =IF(OR($AJ20=""),"",ROUND(AN20/$AJ20*1000,1)) -> 34 | AT20: =IF(OR($AJ20=""),"",ROUND(AO20/$AJ20*1000,2)) -> 11.64
A21: =A20+1 -> 43849 | B21: 易萍 | C21: 29351465 | D21: 15304111 | E21: 11020115 | F21: 10682721 | G21: 276713665 | H21: 105948066 | I21: 276713665 | J21: 105948066 | L21: 4299.8 | M21: 4275.78 | N21: 73819.17 | Q21: 25 | R21: 晴 | S21: 480 | T21: 500 | U21: 8039 | V21: 4979 | W21: 5.42 | X21: 2.9 | Y21: 1140 | AA21: =IF(OR(C22=""),"",C22-C21) -> 39498 | AB21: =IF(OR(D22=""),"",D22-D21) -> 47209 | AC21: =IF(OR(E22=""),"",E22-E21) -> 45751 | AD21: =IF(OR(F22=""),"",F22-F21) -> 40772 | AE21: =IF(OR(G22=""),"",G22-G21) -> 171566 | AF21: =IF(OR(H22=""),"",H22-H21) -> 5514 | AG21: =IF(OR(AA21="",AB21="",AC21=""),"",AA21+AB21+AC21+AD21-AE21) -> 1664 | AH21: =IF(OR(I22=""),"",I22-I21) -> 171566 | AI21: =IF(OR(J22=""),"",J22-J21) -> 5514 | AJ21: =IF(OR(AH21="",AI21=""),"",AH21-AI21) -> 166052 | AK21: 4000 | AL21: =IF(OR(L22="",M22=""),"",ROUND((L22-L21+M22-M21)*1200,0)) -> 0 | AM21: =IF(OR(N22=""),"",(ROUND((N22-N21)*2,0))) -> 0 | AN21: =IF(OR(S21=""),"",ROUND(S21*7.1,0)) -> 3408 | AO21: =IF(OR(T21=""),"",ROUND(T21*2.4,0)) -> 1200 | AP21: 3140 | AQ21: =IF(OR($AJ21=""),"",ROUND(AL21/$AJ21*1000,1)) -> 0 | AR21: =IF(OR($AJ21=""),"",ROUND(AM21/$AJ21*1000,2)) -> 0 | AS21: =IF(OR($AJ21=""),"",ROUND(AN21/$AJ21*1000,1)) -> 20.5 | AT21: =IF(OR($AJ21=""),"",ROUND(AO21/$AJ21*1000,2)) -> 7.23
A22: =A21+1 -> 43850 | B22: 易萍 | C22: 29390963 | D22: 15351320 | E22: 11065866 | F22: 10723493 | G22: 276885231 | H22: 105953580 | I22: 276885231 | J22: 105953580 | L22: 4299.8 | M22: 4275.78 | N22: 73819.17 | Q22: 17.8 | R22: 阴 | S22: 650 | T22: 640 | U22: 6582 | V22: 1825 | W22: 4.61 | X22: 2.23 | Y22: 1080 | Z22: 泵站检修，水量低 | AA22: =IF(OR(C23=""),"",C23-C22) -> 33159 | AB22: =IF(OR(D23=""),"",D23-D22) -> 38044 | AC22: =IF(OR(E23=""),"",E23-E22) -> 36835 | AD22: =IF(OR(F23=""),"",F23-F22) -> 33406 | AE22: =IF(OR(G23=""),"",G23-G22) -> 138915 | AF22: =IF(OR(H23=""),"",H23-H22) -> 5535 | AG22: =IF(OR(AA22="",AB22="",AC22=""),"",AA22+AB22+AC22+AD22-AE22) -> 2529 | AH22: =IF(OR(I23=""),"",I23-I22) -> 138915 | AI22: =IF(OR(J23=""),"",J23-J22) -> 5535 | AJ22: =IF(OR(AH22="",AI22=""),"",AH22-AI22) -> 133380 | AK22: 4200 | AL22: =IF(OR(L23="",M23=""),"",ROUND((L23-L22+M23-M22)*1200,0)) -> 0 | AM22: =IF(OR(N23=""),"",(ROUND((N23-N22)*2,0))) -> 0 | AN22: =IF(OR(S22=""),"",ROUND(S22*7.1,0)) -> 4615 | AO22: =IF(OR(T22=""),"",ROUND(T22*2.4,0)) -> 1536 | AP22: 3235 | AQ22: =IF(OR($AJ22=""),"",ROUND(AL22/$AJ22*1000,1)) -> 0 | AR22: =IF(OR($AJ22=""),"",ROUND(AM22/$AJ22*1000,2)) -> 0 | AS22: =IF(OR($AJ22=""),"",ROUND(AN22/$AJ22*1000,1)) -> 34.6 | AT22: =IF(OR($AJ22=""),"",ROUND(AO22/$AJ22*1000,2)) -> 11.52
A23: =A22+1 -> 43851 | B23: 易萍 | C23: 29424122 | D23: 15389364 | E23: 11102701 | F23: 10756899 | G23: 277024146 | H23: 105959115 | I23: 277024146 | J23: 105959115 | L23: 4299.8 | M23: 4275.78 | N23: 73819.17 | Q23: 18 | R23: 阴 | S23: 450 | T23: 460 | U23: 7302 | V23: 6391 | W23: 4.78 | X23: 3.79 | Y23: 1440 | AA23: =IF(OR(C24=""),"",C24-C23) -> 37197 | AB23: =IF(OR(D24=""),"",D24-D23) -> 43214 | AC23: =IF(OR(E24=""),"",E24-E23) -> 42697 | AD23: =IF(OR(F24=""),"",F24-F23) -> 38683 | AE23: =IF(OR(G24=""),"",G24-G23) -> 159735 | AF23: =IF(OR(H24=""),"",H24-H23) -> 5540 | AG23: =IF(OR(AA23="",AB23="",AC23=""),"",AA23+AB23+AC23+AD23-AE23) -> 2056 | AH23: =IF(OR(I24=""),"",I24-I23) -> 159735 | AI23: =IF(OR(J24=""),"",J24-J23) -> 5540 | AJ23: =IF(OR(AH23="",AI23=""),"",AH23-AI23) -> 154195 | AK23: 4000 | AL23: =IF(OR(L24="",M24=""),"",ROUND((L24-L23+M24-M23)*1200,0)) -> 0 | AM23: =IF(OR(N24=""),"",(ROUND((N24-N23)*2,0))) -> 0 | AN23: =IF(OR(S23=""),"",ROUND(S23*7.1,0)) -> 3195 | AO23: =IF(OR(T23=""),"",ROUND(T23*2.4,0)) -> 1104 | AP23: 2954 | AQ23: =IF(OR($AJ23=""),"",ROUND(AL23/$AJ23*1000,1)) -> 0 | AR23: =IF(OR($AJ23=""),"",ROUND(AM23/$AJ23*1000,2)) -> 0 | AS23: =IF(OR($AJ23=""),"",ROUND(AN23/$AJ23*1000,1)) -> 20.7 | AT23: =IF(OR($AJ23=""),"",ROUND(AO23/$AJ23*1000,2)) -> 7.16
A24: =A23+1 -> 43852 | B24: 潘汝鑫 | C24: 29461319 | D24: 15432578 | E24: 11145398 | F24: 10795582 | G24: 277183881 | H24: 105964655 | I24: 277183881 | J24: 105964655 | L24: 4299.8 | M24: 4275.78 | N24: 73819.17 | Q24: 17.3 | R24: 阴 | S24: 440 | T24: 450 | U24: 8336 | V24: 5236 | W24: 4.12 | X24: 2.43 | Y24: 960 | AA24: =IF(OR(C25=""),"",C25-C24) -> 41629 | AB24: =IF(OR(D25=""),"",D25-D24) -> 50004 | AC24: =IF(OR(E25=""),"",E25-E24) -> 48241 | AD24: =IF(OR(F25=""),"",F25-F24) -> 42720 | AE24: =IF(OR(G25=""),"",G25-G24) -> 170875 | AF24: =IF(OR(H25=""),"",H25-H24) -> 5554 | AG24: =IF(OR(AA24="",AB24="",AC24=""),"",AA24+AB24+AC24+AD24-AE24) -> 11719 | AH24: =IF(OR(I25=""),"",I25-I24) -> 170875 | AI24: =IF(OR(J25=""),"",J25-J24) -> 5554 | AJ24: =IF(OR(AH24="",AI24=""),"",AH24-AI24) -> 165321 | AK24: 4690 | AL24: =IF(OR(L25="",M25=""),"",ROUND((L25-L24+M25-M24)*1200,0)) -> 0 | AM24: =IF(OR(N25=""),"",(ROUND((N25-N24)*2,0))) -> 0 | AN24: =IF(OR(S24=""),"",ROUND(S24*7.1,0)) -> 3124 | AO24: =IF(OR(T24=""),"",ROUND(T24*2.4,0)) -> 1080 | AP24: 3011 | AQ24: =IF(OR($AJ24=""),"",ROUND(AL24/$AJ24*1000,1)) -> 0 | AR24: =IF(OR($AJ24=""),"",ROUND(AM24/$AJ24*1000,2)) -> 0 | AS24: =IF(OR($AJ24=""),"",ROUND(AN24/$AJ24*1000,1)) -> 18.9 | AT24: =IF(OR($AJ24=""),"",ROUND(AO24/$AJ24*1000,2)) -> 6.53
A25: =A24+1 -> 43853 | B25: 陈智娇 | C25: 29502948 | D25: 15482582 | E25: 11193639 | F25: 10838302 | G25: 277354756 | H25: 105970209 | I25: 277354756 | J25: 105970209 | L25: 4299.8 | M25: 4275.78 | N25: 73819.17 | Q25: 17.1 | R25: 雨 | S25: 650 | T25: 660 | U25: 10378 | V25: 8264 | W25: 6.21 | X25: 3.58 | Y25: 1440 | AA25: =IF(OR(C26=""),"",C26-C25) -> 50908 | AB25: =IF(OR(D26=""),"",D26-D25) -> 60143 | AC25: =IF(OR(E26=""),"",E26-E25) -> 60952 | AD25: =IF(OR(F26=""),"",F26-F25) -> 57581 | AE25: =IF(OR(G26=""),"",G26-G25) -> 207300 | AF25: =IF(OR(H26=""),"",H26-H25) -> 5513 | AG25: =IF(OR(AA25="",AB25="",AC25=""),"",AA25+AB25+AC25+AD25-AE25) -> 22284 | AH25: =IF(OR(I26=""),"",I26-I25) -> 207300 | AI25: =IF(OR(J26=""),"",J26-J25) -> 5513 | AJ25: =IF(OR(AH25="",AI25=""),"",AH25-AI25) -> 201787 | AK25: 4300 | AL25: =IF(OR(L26="",M26=""),"",ROUND((L26-L25+M26-M25)*1200,0)) -> 0 | AM25: =IF(OR(N26=""),"",(ROUND((N26-N25)*2,0))) -> 0 | AN25: =IF(OR(S25=""),"",ROUND(S25*7.1,0)) -> 4615 | AO25: =IF(OR(T25=""),"",ROUND(T25*2.4,0)) -> 1584 | AP25: 3165 | AQ25: =IF(OR($AJ25=""),"",ROUND(AL25/$AJ25*1000,1)) -> 0 | AR25: =IF(OR($AJ25=""),"",ROUND(AM25/$AJ25*1000,2)) -> 0 | AS25: =IF(OR($AJ25=""),"",ROUND(AN25/$AJ25*1000,1)) -> 22.9 | AT25: =IF(OR($AJ25=""),"",ROUND(AO25/$AJ25*1000,2)) -> 7.85
A26: =A25+1 -> 43854 | B26: 易萍 | C26: 29553856 | D26: 15542725 | E26: 11254591 | F26: 10895883 | G26: 277562056 | H26: 105975722 | I26: 277562056 | J26: 105975722 | L26: 4299.8 | M26: 4275.78 | N26: 73819.17 | Q26: 16.4 | R26: 雨 | S26: 700 | T26: 690 | U26: 9129 | V26: 7884 | W26: 6.5 | X26: 5.11 | Y26: 1440 | AA26: =IF(OR(C27=""),"",C27-C26) -> 47352 | AB26: =IF(OR(D27=""),"",D27-D26) -> 60273 | AC26: =IF(OR(E27=""),"",E27-E26) -> 56050 | AD26: =IF(OR(F27=""),"",F27-F26) -> 52687 | AE26: =IF(OR(G27=""),"",G27-G26) -> 206729 | AF26: =IF(OR(H27=""),"",H27-H26) -> 5522 | AG26: =IF(OR(AA26="",AB26="",AC26=""),"",AA26+AB26+AC26+AD26-AE26) -> 9633 | AH26: =IF(OR(I27=""),"",I27-I26) -> 206729 | AI26: =IF(OR(J27=""),"",J27-J26) -> 5522 | AJ26: =IF(OR(AH26="",AI26=""),"",AH26-AI26) -> 201207 | AK26: 4200 | AL26: =IF(OR(L27="",M27=""),"",ROUND((L27-L26+M27-M26)*1200,0)) -> 0 | AM26: =IF(OR(N27=""),"",(ROUND((N27-N26)*2,0))) -> 0 | AN26: =IF(OR(S26=""),"",ROUND(S26*7.1,0)) -> 4970 | AO26: =IF(OR(T26=""),"",ROUND(T26*2.4,0)) -> 1656 | AP26: 2850 | AQ26: =IF(OR($AJ26=""),"",ROUND(AL26/$AJ26*1000,1)) -> 0 | AR26: =IF(OR($AJ26=""),"",ROUND(AM26/$AJ26*1000,2)) -> 0 | AS26: =IF(OR($AJ26=""),"",ROUND(AN26/$AJ26*1000,1)) -> 24.7 | AT26: =IF(OR($AJ26=""),"",ROUND(AO26/$AJ26*1000,2)) -> 8.23
A27: =A26+1 -> 43855 | B27: 易萍 | C27: 29601208 | D27: 15602998 | E27: 11310641 | F27: 10948570 | G27: 277768785 | H27: 105981244 | I27: 277768785 | J27: 105981244 | L27: 4299.8 | M27: 4275.78 | N27: 73819.17 | Q27: 16.7 | R27: 阴 | S27: 500 | T27: 520 | U27: 9206 | V27: 7791 | W27: 5.25 | X27: 3.07 | Y27: 1290 | AA27: =IF(OR(C28=""),"",C28-C27) -> 46824 | AB27: =IF(OR(D28=""),"",D28-D27) -> 58594 | AC27: =IF(OR(E28=""),"",E28-E27) -> 55650 | AD27: =IF(OR(F28=""),"",F28-F27) -> 51206 | AE27: =IF(OR(G28=""),"",G28-G27) -> 206166 | AF27: =IF(OR(H28=""),"",H28-H27) -> 5536 | AG27: =IF(OR(AA27="",AB27="",AC27=""),"",AA27+AB27+AC27+AD27-AE27) -> 6108 | AH27: =IF(OR(I28=""),"",I28-I27) -> 206166 | AI27: =IF(OR(J28=""),"",J28-J27) -> 5536 | AJ27: =IF(OR(AH27="",AI27=""),"",AH27-AI27) -> 200630 | AK27: 4000 | AL27: =IF(OR(L28="",M28=""),"",ROUND((L28-L27+M28-M27)*1200,0)) -> 0 | AM27: =IF(OR(N28=""),"",(ROUND((N28-N27)*2,0))) -> 0 | AN27: =IF(OR(S27=""),"",ROUND(S27*7.1,0)) -> 3550 | AO27: =IF(OR(T27=""),"",ROUND(T27*2.4,0)) -> 1248 | AP27: 3011 | AQ27: =IF(OR($AJ27=""),"",ROUND(AL27/$AJ27*1000,1)) -> 0 | AR27: =IF(OR($AJ27=""),"",ROUND(AM27/$AJ27*1000,2)) -> 0 | AS27: =IF(OR($AJ27=""),"",ROUND(AN27/$AJ27*1000,1)) -> 17.7 | AT27: =IF(OR($AJ27=""),"",ROUND(AO27/$AJ27*1000,2)) -> 6.22
A28: =A27+1 -> 43856 | B28: 易萍 | C28: 29648032 | D28: 15661592 | E28: 11366291 | F28: 10999776 | G28: 277974951 | H28: 105986780 | I28: 277974951 | J28: 105986780 | L28: 4299.8 | M28: 4275.78 | N28: 73819.17 | Q28: 16.5 | R28: 阴 | S28: 650 | T28: 640 | U28: 9696 | V28: 7994 | W28: 7.56 | X28: 2.75 | Y28: 1230 | AA28: =IF(OR(C29=""),"",C29-C28) -> 48677 | AB28: =IF(OR(D29=""),"",D29-D28) -> 61068 | AC28: =IF(OR(E29=""),"",E29-E28) -> 56857 | AD28: =IF(OR(F29=""),"",F29-F28) -> 53993 | AE28: =IF(OR(G29=""),"",G29-G28) -> 206199 | AF28: =IF(OR(H29=""),"",H29-H28) -> 5512 | AG28: =IF(OR(AA28="",AB28="",AC28=""),"",AA28+AB28+AC28+AD28-AE28) -> 14396 | AH28: =IF(OR(I29=""),"",I29-I28) -> 206199 | AI28: =IF(OR(J29=""),"",J29-J28) -> 5512 | AJ28: =IF(OR(AH28="",AI28=""),"",AH28-AI28) -> 200687 | AK28: 4200 | AL28: =IF(OR(L29="",M29=""),"",ROUND((L29-L28+M29-M28)*1200,0)) -> 0 | AM28: =IF(OR(N29=""),"",(ROUND((N29-N28)*2,0))) -> 0 | AN28: =IF(OR(S28=""),"",ROUND(S28*7.1,0)) -> 4615 | AO28: =IF(OR(T28=""),"",ROUND(T28*2.4,0)) -> 1536 | AP28: 3356 | AQ28: =IF(OR($AJ28=""),"",ROUND(AL28/$AJ28*1000,1)) -> 0 | AR28: =IF(OR($AJ28=""),"",ROUND(AM28/$AJ28*1000,2)) -> 0 | AS28: =IF(OR($AJ28=""),"",ROUND(AN28/$AJ28*1000,1)) -> 23 | AT28: =IF(OR($AJ28=""),"",ROUND(AO28/$AJ28*1000,2)) -> 7.65
A29: =A28+1 -> 43857 | B29: 易萍 | C29: 29696709 | D29: 15722660 | E29: 11423148 | F29: 11053769 | G29: 278181150 | H29: 105992292 | I29: 278181150 | J29: 105992292 | L29: 4299.8 | M29: 4275.78 | N29: 73819.17 | Q29: 16 | R29: 雨 | S29: 550 | T29: 560 | U29: 10352 | V29: 7998 | W29: 7.46 | X29: 4.78 | Y29: 1440 | AA29: =IF(OR(C30=""),"",C30-C29) -> 51273 | AB29: =IF(OR(D30=""),"",D30-D29) -> 63323 | AC29: =IF(OR(E30=""),"",E30-E29) -> 57678 | AD29: =IF(OR(F30=""),"",F30-F29) -> 55976 | AE29: =IF(OR(G30=""),"",G30-G29) -> 209908 | AF29: =IF(OR(H30=""),"",H30-H29) -> 5508 | AG29: =IF(OR(AA29="",AB29="",AC29=""),"",AA29+AB29+AC29+AD29-AE29) -> 18342 | AH29: =IF(OR(I30=""),"",I30-I29) -> 209908 | AI29: =IF(OR(J30=""),"",J30-J29) -> 5508 | AJ29: =IF(OR(AH29="",AI29=""),"",AH29-AI29) -> 204400 | AK29: 4300 | AL29: =IF(OR(L30="",M30=""),"",ROUND((L30-L29+M30-M29)*1200,0)) -> 0 | AM29: =IF(OR(N30=""),"",(ROUND((N30-N29)*2,0))) -> 0 | AN29: =IF(OR(S29=""),"",ROUND(S29*7.1,0)) -> 3905 | AO29: =IF(OR(T29=""),"",ROUND(T29*2.4,0)) -> 1344 | AP29: 3484 | AQ29: =IF(OR($AJ29=""),"",ROUND(AL29/$AJ29*1000,1)) -> 0 | AR29: =IF(OR($AJ29=""),"",ROUND(AM29/$AJ29*1000,2)) -> 0 | AS29: =IF(OR($AJ29=""),"",ROUND(AN29/$AJ29*1000,1)) -> 19.1 | AT29: =IF(OR($AJ29=""),"",ROUND(AO29/$AJ29*1000,2)) -> 6.58
A30: =A29+1 -> 43858 | B30: 易萍 | C30: 29747982 | D30: 15785983 | E30: 11480826 | F30: 11109745 | G30: 278391058 | H30: 105997800 | I30: 278391058 | J30: 105997800 | L30: 4299.8 | M30: 4275.78 | N30: 73819.17 | Q30: 16.4 | R30: 阴 | S30: 480 | T30: 500 | U30: 9352 | V30: 8119 | W30: 7.39 | X30: 5.12 | Y30: 1440 | AA30: =IF(OR(C31=""),"",C31-C30) -> 48718 | AB30: =IF(OR(D31=""),"",D31-D30) -> 61279 | AC30: =IF(OR(E31=""),"",E31-E30) -> 56394 | AD30: =IF(OR(F31=""),"",F31-F30) -> 53948 | AE30: =IF(OR(G31=""),"",G31-G30) -> 213414 | AF30: =IF(OR(H31=""),"",H31-H30) -> 5520 | AG30: =IF(OR(AA30="",AB30="",AC30=""),"",AA30+AB30+AC30+AD30-AE30) -> 6925 | AH30: =IF(OR(I31=""),"",I31-I30) -> 213414 | AI30: =IF(OR(J31=""),"",J31-J30) -> 5520 | AJ30: =IF(OR(AH30="",AI30=""),"",AH30-AI30) -> 207894 | AK30: 4500 | AL30: =IF(OR(L31="",M31=""),"",ROUND((L31-L30+M31-M30)*1200,0)) -> 0 | AM30: =IF(OR(N31=""),"",(ROUND((N31-N30)*2,0))) -> 0 | AN30: =IF(OR(S30=""),"",ROUND(S30*7.1,0)) -> 3408 | AO30: =IF(OR(T30=""),"",ROUND(T30*2.4,0)) -> 1200 | AP30: 3059 | AQ30: =IF(OR($AJ30=""),"",ROUND(AL30/$AJ30*1000,1)) -> 0 | AR30: =IF(OR($AJ30=""),"",ROUND(AM30/$AJ30*1000,2)) -> 0 | AS30: =IF(OR($AJ30=""),"",ROUND(AN30/$AJ30*1000,1)) -> 16.4 | AT30: =IF(OR($AJ30=""),"",ROUND(AO30/$AJ30*1000,2)) -> 5.77
A31: =A30+1 -> 43859 | B31: 易萍 | C31: 29796700 | D31: 15847262 | E31: 11537220 | F31: 11163693 | G31: 278604472 | H31: 106003320 | I31: 278604472 | J31: 106003320 | L31: 4299.8 | M31: 4275.78 | N31: 73819.17 | Q31: 16.6 | R31: 阴 | S31: 520 | T31: 510 | U31: 9674 | V31: 6992 | W31: 7.06 | X31: 4.82 | Y31: 1440 | AA31: =IF(OR(C32=""),"",C32-C31) -> 46596 | AB31: =IF(OR(D32=""),"",D32-D31) -> 58333 | AC31: =IF(OR(E32=""),"",E32-E31) -> 56689 | AD31: =IF(OR(F32=""),"",F32-F31) -> 51803 | AE31: =IF(OR(G32=""),"",G32-G31) -> 206573 | AF31: =IF(OR(H32=""),"",H32-H31) -> 5544 | AG31: =IF(OR(AA31="",AB31="",AC31=""),"",AA31+AB31+AC31+AD31-AE31) -> 6848 | AH31: =IF(OR(I32=""),"",I32-I31) -> 206573 | AI31: =IF(OR(J32=""),"",J32-J31) -> 5544 | AJ31: =IF(OR(AH31="",AI31=""),"",AH31-AI31) -> 201029 | AK31: 4300 | AL31: =IF(OR(L32="",M32=""),"",ROUND((L32-L31+M32-M31)*1200,0)) -> 0 | AM31: =IF(OR(N32=""),"",(ROUND((N32-N31)*2,0))) -> 0 | AN31: =IF(OR(S31=""),"",ROUND(S31*7.1,0)) -> 3692 | AO31: =IF(OR(T31=""),"",ROUND(T31*2.4,0)) -> 1224 | AP31: 2803 | AQ31: =IF(OR($AJ31=""),"",ROUND(AL31/$AJ31*1000,1)) -> 0 | AR31: =IF(OR($AJ31=""),"",ROUND(AM31/$AJ31*1000,2)) -> 0 | AS31: =IF(OR($AJ31=""),"",ROUND(AN31/$AJ31*1000,1)) -> 18.4 | AT31: =IF(OR($AJ31=""),"",ROUND(AO31/$AJ31*1000,2)) -> 6.09
A32: =A31+1 -> 43860 | B32: 易萍 | C32: 29843296 | D32: 15905595 | E32: 11593909 | F32: 11215496 | G32: 278811045 | H32: 106008864 | I32: 278811045 | J32: 106008864 | L32: 4299.8 | M32: 4275.78 | N32: 73819.17 | Q32: 16.5 | R32: 阴 | S32: 300 | T32: 280 | U32: 9215 | V32: 8451 | W32: 6.1 | X32: 4.2 | Y32: 1440 | AA32: =IF(OR(C33=""),"",C33-C32) -> 49037 | AB32: =IF(OR(D33=""),"",D33-D32) -> 61511 | AC32: =IF(OR(E33=""),"",E33-E32) -> 57845 | AD32: =IF(OR(F33=""),"",F33-F32) -> 54536 | AE32: =IF(OR(G33=""),"",G33-G32) -> 212465 | AF32: =IF(OR(H33=""),"",H33-H32) -> 5493 | AG32: =IF(OR(AA32="",AB32="",AC32=""),"",AA32+AB32+AC32+AD32-AE32) -> 10464 | AH32: =IF(OR(I33=""),"",I33-I32) -> 212465 | AI32: =IF(OR(J33=""),"",J33-J32) -> 5493 | AJ32: =IF(OR(AH32="",AI32=""),"",AH32-AI32) -> 206972 | AK32: 4500 | AL32: =IF(OR(L33="",M33=""),"",ROUND((L33-L32+M33-M32)*1200,0)) -> 0 | AM32: =IF(OR(N33=""),"",(ROUND((N33-N32)*2,0))) -> 0 | AN32: =IF(OR(S32=""),"",ROUND(S32*7.1,0)) -> 2130 | AO32: =IF(OR(T32=""),"",ROUND(T32*2.4,0)) -> 672 | AP32: 2911 | AQ32: =IF(OR($AJ32=""),"",ROUND(AL32/$AJ32*1000,1)) -> 0 | AR32: =IF(OR($AJ32=""),"",ROUND(AM32/$AJ32*1000,2)) -> 0 | AS32: =IF(OR($AJ32=""),"",ROUND(AN32/$AJ32*1000,1)) -> 10.3 | AT32: =IF(OR($AJ32=""),"",ROUND(AO32/$AJ32*1000,2)) -> 3.25
A33: =A32+1 -> 43861 | B33: 陈智娇 | C33: 29892333 | D33: 15967106 | E33: 11651754 | F33: 11270032 | G33: 279023510 | H33: 106014357 | I33: 279023510 | J33: 106014357 | L33: 4299.8 | M33: 4275.78 | N33: 73819.17 | Q33: 16 | R33: 晴 | S33: 310 | T33: 330 | U33: 8656 | V33: 3041 | W33: 4.3 | X33: 2.46 | Y33: 1140 | AA33: =IF(OR(C34=""),"",C34-C33) -> 47300 | AB33: =IF(OR(D34=""),"",D34-D33) -> 50711 | AC33: =IF(OR(E34=""),"",E34-E33) -> 49795 | AD33: =IF(OR(F34=""),"",F34-F33) -> 43084 | AE33: =IF(OR(G34=""),"",G34-G33) -> 186488 | AF33: =IF(OR(H34=""),"",H34-H33) -> 5472 | AG33: =IF(OR(AA33="",AB33="",AC33=""),"",AA33+AB33+AC33+AD33-AE33) -> 4402 | AH33: =IF(OR(I34=""),"",I34-I33) -> 186488 | AI33: =IF(OR(J34=""),"",J34-J33) -> 5472 | AJ33: =IF(OR(AH33="",AI33=""),"",AH33-AI33) -> 181016 | AK33: 4800 | AL33: =IF(OR(L34="",M34=""),"",ROUND((L34-L33+M34-M33)*1200,0)) -> 0 | AM33: =IF(OR(N34=""),"",(ROUND((N34-N33)*2,0))) -> 0 | AN33: =IF(OR(S33=""),"",ROUND(S33*7.1,0)) -> 2201 | AO33: =IF(OR(T33=""),"",ROUND(T33*2.4,0)) -> 792 | AP33: 2985 | AQ33: =IF(OR($AJ33=""),"",ROUND(AL33/$AJ33*1000,1)) -> 0 | AR33: =IF(OR($AJ33=""),"",ROUND(AM33/$AJ33*1000,2)) -> 0 | AS33: =IF(OR($AJ33=""),"",ROUND(AN33/$AJ33*1000,1)) -> 12.2 | AT33: =IF(OR($AJ33=""),"",ROUND(AO33/$AJ33*1000,2)) -> 4.38
A34: =A33+1 -> 43862 | B34: 仇昊 | C34: 29939633 | D34: 16017817 | E34: 11701549 | F34: 11313116 | G34: 279209998 | H34: 106019829 | I34: 279209998 | J34: 106019829 | L34: 4299.8 | M34: 4275.78 | N34: 73819.17
AA36: =IF(OR(C37=""),"",C37-C36) | AB36: =IF(OR(D37=""),"",D37-D36) | AC36: =IF(OR(E37=""),"",E37-E36) | AD36: =IF(OR(F37=""),"",F37-F36) | AE36: =IF(OR(G37=""),"",G37-G36) | AF36: =IF(OR(H37=""),"",H37-H36) | AG36: =IF(OR(AA36="",AB36="",AC36=""),"",AA36+AB36+AC36+AD36-AE36) | AH36: =SUM(AH3:AH34) -> 5750099 | AI36: =SUM(AI3:AI34) -> 168296 | AJ36: =SUM(AJ3:AJ34) -> 5581803 | AK36: =SUM(AK3:AK34) -> 124690 | AL36: =SUM(AL3:AL34) -> 17400 | AM36: =SUM(AM3:AM34) -> 134 | AN36: =SUM(AN3:AN34) -> 117008 | AO36: =SUM(AO3:AO34) -> 40224 | AQ36: =IF(OR($AJ36=0),"",ROUND(AL36/$AJ36*1000,1)) -> 3.1 | AR36: =IF(OR($AJ36=0),"",ROUND(AM36/$AJ36*1000,2)) -> 0.02 | AS36: =IF(OR($AJ36=0),"",ROUND(AN36/$AJ36*1000,1)) -> 21 | AT36: =IF(OR($AJ36=0),"",ROUND(AO36/$AJ36*1000,2)) -> 7.21

Sheet 2
B2: 记录人 | C2: 一期左进水 流量计读数 | D2: 一期右进水 流量计读数 | E2: 二期左进水 流量计读数 | F2: 二期右进水 流量计读数 | G2: 现场出水 流量计读数 | H2: 现场回用水 读数 | I2: 出水流量计 读数（网站） | J2: 回用水流量 （网站） | K2: 污泥流量 计读数 | L2: PAC2#流量计读数 | M2: PAC3#流量计读数 | N2: PAM流量 计读数 | O2: 盐酸流量 计读数 | P2: 氯酸钠流 量计读数 | Q2: 生反池 水温 | R2: 天气 (阴晴雨) | S2: 盐酸液位 差（CM） | T2: 氯酸钠液位差 差（CM） | U2: 最高流量 m3/h | V2: 最低流量 m3/h | W2: 最高液位 m | X2: 最低液位 m | Y2: 超液位时 间（分） | Z2: 备注 | AA2: 一期左 进水流量 | AB2: 一期右 进水流量 | AC2: 二期左 进水流量 | AD2: 二期右 进水流量 | AE2: 现场出水 流量 | AF2: 现场回用水 流量 | AG2: 进出水 流量差 | AH2: 出水流量（网站） | AI2: 回用水流量（网站） | AJ2: 实际处理量（网站） | AK2: 排泥量 m3 | AL2: PAC量 kg | AM2: PAM量 kg | AN2: 盐酸量 kg | AO2: 氯酸钠量 kg | AP2: 碳源用量kg | AQ2: PAC单耗 ppm | AR2: PAM单耗 ppm | AS2: 盐酸单耗 ppm | AT2: 氯酸钠单耗 ppm
A3: 43862 | B3: ='1'!B34 -> 仇昊 | C3: ='1'!C34 -> 29939633 | D3: ='1'!D34 -> 16017817 | E3: ='1'!E34 -> 11701549 | F3: ='1'!F34 -> 11313116 | G3: ='1'!G34 -> 279209998 | H3: ='1'!H34 -> 106019829 | I3: ='1'!I34 -> 279209998 | ... R3: ='1'!R34 -> 0 | S3: 300 | T3: 280 | U3: 4856 | V3: 2635 | W3: 3.72 | X3: 2.95 | Y3: 960 | AA3: =IF(OR(C4=""),"",C4-C3) -> 19386 | AB3: =IF(OR(D4=""),"",D4-D3) -> 28129 | AC3: =IF(OR(E4=""),"",E4-E3) -> 26661 | AD3: =IF(OR(F4=""),"",F4-F3) -> 24867 | AE3: =IF(OR(G4=""),"",G4-G3) -> 98977 | AF3: =IF(OR(H4=""),"",H4-H3) -> 5331 | AG3: =IF(OR(AA3="",AB3="",AC3=""),"",AA3+AB3+AC3+AD3-AE3) -> 66 | AH3: =IF(OR(I4=""),"",I4-I3) -> 98977 | AI3: =IF(OR(J4=""),"",J4-J3) -> 5331 | AJ3: =IF(OR(AH3="",AI3=""),"",AH3-AI3) -> 93646 | AK3: 4800 | AL3: =IF(OR(L4="",M4=""),"",ROUND((L4-L3+M4-M3)*1200,0)) -> 0 | AM3: =IF(OR(N4=""),"",(ROUND((N4-N3)*2,0))) -> 0 | AN3: =IF(OR(S3=""),"",ROUND(S3*7.1,0)) -> 2130 | AO3: =IF(OR(T3=""),"",ROUND(T3*2.4,0)) -> 672 | AP3: 2920 | AQ3: =IF(OR($AJ3=""),"",ROUND(AL3/$AJ3*1000,1)) -> 0 | AR3: =IF(OR($AJ3=""),"",ROUND(AM3/$AJ3*1000,2)) -> 0 | AS3: =IF(OR($AJ3=""),"",ROUND(AN3/$AJ3*1000,1)) -> 22.7 | AT3: =IF(OR($AJ3=""),"",ROUND(AO3/$AJ3*1000,2)) -> 7.18
A4: =A3+1 -> 43863 | B4: 胡叶青 | C4: 29959019 | D4: 16045946 | E4: 11728210 | F4: 11337983 | G4: 279308975 | H4: 106025160 | I4: 279308975 | J4: 106025160 | L4: 4299.8 | M4: 4275.78 | N4: 73819.17 | Q4: 15 | R4: 阴 | S4: 320 | T4: 300 | U4: 4907 | V4: 2495 | W4: 3.81 | X4: 2.91 | Y4: 960 | AA4: =IF(OR(C5=""),"",C5-C4) -> 24280 | AB4: =IF(OR(D5=""),"",D5-D4) -> 27512 | AC4: =IF(OR(E5=""),"",E5-E4) -> 26346 | AD4: =IF(OR(F5=""),"",F5-F4) -> 24195 | AE4: =IF(OR(G5=""),"",G5-G4) -> 105340 | AF4: =IF(OR(H5=""),"",H5-H4) -> 5702 | AG4: =IF(OR(AA4="",AB4="",AC4=""),"",AA4+AB4+AC4+AD4-AE4) -> -3007 | AH4: =IF(OR(I5=""),"",I5-I4) -> 103794 | AI4: =IF(OR(J5=""),"",J5-J4) -> 5702 | AJ4: =IF(OR(AH4="",AI4=""),"",AH4-AI4) -> 98092 | AK4: 4800 | AL4: =IF(OR(L5="",M5=""),"",ROUND((L5-L4+M5-M4)*1200,0)) -> 0 | AM4: =IF(OR(N5=""),"",(ROUND((N5-N4)*2,0))) -> 0 | AN4: =IF(OR(S4=""),"",ROUND(S4*7.1,0)) -> 2272 | AO4: =IF(OR(T4=""),"",ROUND(T4*2.4,0)) -> 720 | AP4: 3052 | AQ4: =IF(OR($AJ4=""),"",ROUND(AL4/$AJ4*1000,1)) -> 0 | AR4: =IF(OR($AJ4=""),"",ROUND(AM4/$AJ4*1000,2)) -> 0 | AS4: =IF(OR($AJ4=""),"",ROUND(AN4/$AJ4*1000,1)) -> 23.2 | AT4: =IF(OR($AJ4=""),"",ROUND(AO4/$AJ4*1000,2)) -> 7.34
A5: =A4+1 -> 43864 | B5: 潘汝鑫 | C5: 29983299 | D5: 16073458 | E5: 11754556 | F5: 11362178 | G5: 279414315 | H5: 106030862 | I5: 279412769 | J5: 106030862 | L5: 4299.8 | M5: 4275.78 | N5: 73819.17 | Q5: 15.2 | R5: 阴 | S5: 100 | T5: 100 | U5: 5054 | V5: 4212 | W5: 4.63 | X5: 3.1 | Y5: 1380 | AA5: =IF(OR(C6=""),"",C6-C5) -> 24770 | AB5: =IF(OR(D6=""),"",D6-D5) -> 27520 | AC5: =IF(OR(E6=""),"",E6-E5) -> 26142 | AD5: =IF(OR(F6=""),"",F6-F5) -> 24629 | AE5: =IF(OR(G6=""),"",G6-G5) -> 98457 | AF5: =IF(OR(H6=""),"",H6-H5) -> 5440 | AG5: =IF(OR(AA5="",AB5="",AC5=""),"",AA5+AB5+AC5+AD5-AE5) -> 4604 | AH5: =IF(OR(I6=""),"",I6-I5) -> 100003 | AI5: =IF(OR(J6=""),"",J6-J5) -> 5440 | AJ5: =IF(OR(AH5="",AI5=""),"",AH5-AI5) -> 94563 | AK5: 4500 | AL5: =IF(OR(L6="",M6=""),"",ROUND((L6-L5+M6-M5)*1200,0)) -> 0 | AM5: =IF(OR(N6=""),"",(ROUND((N6-N5)*2,0))) -> 0 | AN5: =IF(OR(S5=""),"",ROUND(S5*7.1,0)) -> 710 | AO5: =IF(OR(T5=""),"",ROUND(T5*2.4,0)) -> 240 | AP5: 5460 | AQ5: =IF(OR($AJ5=""),"",ROUND(AL5/$AJ5*1000,1)) -> 0 | AR5: =IF(OR($AJ5=""),"",ROUND(AM5/$AJ5*1000,2)) -> 0 | AS5: =IF(OR($AJ5=""),"",ROUND(AN5/$AJ5*1000,1)) -> 7.5 | AT5: =IF(OR($AJ5=""),"",ROUND(AO5/$AJ5*1000,2)) -> 2.54
A6: =A5+1 -> 43865 | B6: 张亚光 | C6: 30008069 | D6: 16100978 | E6: 11780698 | F6: 11386807 | G6: 279512772 | H6: 106036302 | I6: 279512772 | J6: 106036302 | L6: 4299.8 | M6: 4275.78 | N6: 73819.17 | Q6: 16 | R6: 晴 | S6: 100 | T6: 100 | U6: 5040 | V6: 3592 | W6: 4.85 | X6: 2.75 | Y6: 1080 | AA6: =IF(OR(C7=""),"",C7-C6) -> 24975 | AB6: =IF(OR(D7=""),"",D7-D6) -> 27280 | AC6: =IF(OR(E7=""),"",E7-E6) -> 26028 | AD6: =IF(OR(F7=""),"",F7-F6) -> 24237 | AE6: =IF(OR(G7=""),"",G7-G6) -> 96217 | AF6: =IF(OR(H7=""),"",H7-H6) -> 5413 | AG6: =IF(OR(AA6="",AB6="",AC6=""),"",AA6+AB6+AC6+AD6-AE6) -> 6303 | AH6: =IF(OR(I7=""),"",I7-I6) -> 96217 | AI6: =IF(OR(J7=""),"",J7-J6) -> 5413 | AJ6: =IF(OR(AH6="",AI6=""),"",AH6-AI6) -> 90804 | AK6: 4000 | AL6: =IF(OR(L7="",M7=""),"",ROUND((L7-L6+M7-M6)*1200,0)) -> 0 | AM6: =IF(OR(N7=""),"",(ROUND((N7-N6)*2,0))) -> 0 | AN6: =IF(OR(S6=""),"",ROUND(S6*7.1,0)) -> 710 | AO6: =IF(OR(T6=""),"",ROUND(T6*2.4,0)) -> 240 | AP6: 3181 | AQ6: =IF(OR($AJ6=""),"",ROUND(AL6/$AJ6*1000,1)) -> 0 | AR6: =IF(OR($AJ6=""),"",ROUND(AM6/$AJ6*1000,2)) -> 0 | AS6: =IF(OR($AJ6=""),"",ROUND(AN6/$AJ6*1000,1)) -> 7.8 | AT6: =IF(OR($AJ6=""),"",ROUND(AO6/$AJ6*1000,2)) -> 2.64
A7: =A6+1 -> 43866 | B7: 易萍 | C7: 30033044 | D7: 16128258 | E7: 11806726 | F7: 11411044 | G7: 279608989 | H7: 106041715 | I7: 279608989 | J7: 106041715 | L7: 4299.8 | M7: 4275.78 | N7: 73819.17 | Q7: 14.5 | R7: 晴 | S7: 260 | T7: 250 | U7: 4528 | V7: 3752 | W7: 4.95 | X7: 3.25 | Y7: 1260 | AA7: =IF(OR(C8=""),"",C8-C7) -> 24175 | AB7: =IF(OR(D8=""),"",D8-D7) -> 26567 | AC7: =IF(OR(E8=""),"",E8-E7) -> 24971 | AD7: =IF(OR(F8=""),"",F8-F7) -> 23454 | AE7: =IF(OR(G8=""),"",G8-G7) -> 98239 | AF7: =IF(OR(H8=""),"",H8-H7) -> 5485 | AG7: =IF(OR(AA7="",AB7="",AC7=""),"",AA7+AB7+AC7+AD7-AE7) -> 928 | AH7: =IF(OR(I8=""),"",I8-I7) -> 98239 | AI7: =IF(OR(J8=""),"",J8-J7) -> 5485 | AJ7: =IF(OR(AH7="",AI7=""),"",AH7-AI7) -> 92754 | AK7: 4000 | AL7: =IF(OR(L8="",M8=""),"",ROUND((L8-L7+M8-M7)*1200,0)) -> 0 | AM7: =IF(OR(N8=""),"",(ROUND((N8-N7)*2,0))) -> 0 | AN7: =IF(OR(S7=""),"",ROUND(S7*7.1,0)) -> 1846 | AO7: =IF(OR(T7=""),"",ROUND(T7*2.4,0)) -> 600 | AP7: 3096 | AQ7: =IF(OR($AJ7=""),"",ROUND(AL7/$AJ7*1000,1)) -> 0 | AR7: =IF(OR($AJ7=""),"",ROUND(AM7/$AJ7*1000,2)) -> 0 | AS7: =IF(OR($AJ7=""),"",ROUND(AN7/$AJ7*1000,1)) -> 19.9 | AT7: =IF(OR($AJ7=""),"",ROUND(AO7/$AJ7*1000,2)) -> 6.47
A8: =A7+1 -> 43867 | B8: 胡叶青 | C8: 30057219 | D8: 16154825 | E8: 11831697 | F8: 11434498 | G8: 279707228 | H8: 106047200 | I8: 279707228 | J8: 106047200 | L8: 4299.8 | M8: 4275.78 | N8: 73819.17 | Q8: 15 | R8: 晴 | S8: 430 | T8: 420 | U8: 6083 | V8: 4011 | W8: 4.35 | X8: 2.55 | Y8: 1230 | AA8: =IF(OR(C9=""),"",C9-C8) -> 31167 | AB8: =IF(OR(D9=""),"",D9-D8) -> 35531 | AC8: =IF(OR(E9=""),"",E9-E8) -> 33523 | AD8: =IF(OR(F9=""),"",F9-F8) -> 30613 | AE8: =IF(OR(G9=""),"",G9-G8) -> 124592 | AF8: =IF(OR(H9=""),"",H9-H8) -> 5461 | AG8: =IF(OR(AA8="",AB8="",AC8=""),"",AA8+AB8+AC8+AD8-AE8) -> 6242 | AH8: =IF(OR(I9=""),"",I9-I8) -> 124592 | AI8: =IF(OR(J9=""),"",J9-J8) -> 5461 | AJ8: =IF(OR(AH8="",AI8=""),"",AH8-AI8) -> 119131 | AK8: 4200 | AL8: =IF(OR(L9="",M9=""),"",ROUND((L9-L8+M9-M8)*1200,0)) -> 0 | AM8: =IF(OR(N9=""),"",(ROUND((N9-N8)*2,0))) -> 0 | AN8: =IF(OR(S8=""),"",ROUND(S8*7.1,0)) -> 3053 | AO8: =IF(OR(T8=""),"",ROUND(T8*2.4,0)) -> 1008 | AP8: 2998 | AQ8: =IF(OR($AJ8=""),"",ROUND(AL8/$AJ8*1000,1)) -> 0 | AR8: =IF(OR($AJ8=""),"",ROUND(AM8/$AJ8*1000,2)) -> 0 | AS8: =IF(OR($AJ8=""),"",ROUND(AN8/$AJ8*1000,1)) -> 25.6 | AT8: =IF(OR($AJ8=""),"",ROUND(AO8/$AJ8*1000,2)) -> 8.46
A9: =A8+1 -> 43868 | B9: 易萍 | C9: 30088386 | D9: 16190356 | E9: 11865220 | F9: 11465111 | G9: 279831820 | H9: 106052661 | I9: 279831820 | J9: 106052661 | L9: 4299.8 | M9: 4275.78 | N9: 73819.17 | Q9: 13.8 | R9: 雪 | S9: 700 | T9: 680 | U9: 10249 | V9: 3212 | W9: 6.92 | X9: 2.54 | Y9: 1260 | AA9: =IF(OR(C10=""),"",C10-C9) -> 43789 | AB9: =IF(OR(D10=""),"",D10-D9) -> 54265 | AC9: =IF(OR(E10=""),"",E10-E9) -> 48935 | AD9: =IF(OR(F10=""),"",F10-F9) -> 46100 | AE9: =IF(OR(G10=""),"",G10-G9) -> 170080 | AF9: =IF(OR(H10=""),"",H10-H9) -> 5489 | AG9: =IF(OR(AA9="",AB9="",AC9=""),"",AA9+AB9+AC9+AD9-AE9) -> 23009 | AH9: =IF(OR(I10=""),"",I10-I9) -> 170080 | AI9: =IF(OR(J10=""),"",J10-J9) -> 5489 | AJ9: =IF(OR(AH9="",AI9=""),"",AH9-AI9) -> 164591 | AK9: 4000 | AL9: =IF(OR(L10="",M10=""),"",ROUND((L10-L9+M10-M9)*1200,0)) -> 0 | AM9: =IF(OR(N10=""),"",(ROUND((N10-N9)*2,0))) -> 0 | AN9: =IF(OR(S9=""),"",ROUND(S9*7.1,0)) -> 4970 | AO9: =IF(OR(T9=""),"",ROUND(T9*2.4,0)) -> 1632 | AP9: 3049 | AQ9: =IF(OR($AJ9=""),"",ROUND(AL9/$AJ9*1000,1)) -> 0 | AR9: =IF(OR($AJ9=""),"",ROUND(AM9/$AJ9*1000,2)) -> 0 | AS9: =IF(OR($AJ9=""),"",ROUND(AN9/$AJ9*1000,1)) -> 30.2 | AT9: =IF(OR($AJ9=""),"",ROUND(AO9/$AJ9*1000,2)) -> 9.92
A10: =A9+1 -> 43869 | B10: 易萍 | C10: 30132175 | D10: 16244621 | E10: 11914155 | F10: 11511211 | G10: 280001900 | H10: 106058150 | I10: 280001900 | J10: 106058150 | L10: 4299.8 | M10: 4275.78 | N10: 73819.17 | Q10: 13 | R10: 阴 | S10: 670 | T10: 650 | U10: 9470 | V10: 8108 | W10: 6.87 | X10: 6.07 | Y10: 1440 | AA10: =IF(OR(C11=""),"",C11-C10) -> 48278 | AB10: =IF(OR(D11=""),"",D11-D10) -> 59275 | AC10: =IF(OR(E11=""),"",E11-E10) -> 54164 | AD10: =IF(OR(F11=""),"",F11-F10) -> 53529 | AE10: =IF(OR(G11=""),"",G11-G10) -> 212811 | AF10: =IF(OR(H11=""),"",H11-H10) -> 5527 | AG10: =IF(OR(AA10="",AB10="",AC10=""),"",AA10+AB10+AC10+AD10-AE10) -> 2435 | AH10: =IF(OR(I11=""),"",I11-I10) -> 212811 | AI10: =IF(OR(J11=""),"",J11-J10) -> 5527 | AJ10: =IF(OR(AH10="",AI10=""),"",AH10-AI10) -> 207284 | AK10: 4000 | AL10: =IF(OR(L11="",M11=""),"",ROUND((L11-L10+M11-M10)*1200,0)) -> 0 | AM10: =IF(OR(N11=""),"",(ROUND((N11-N10)*2,0))) -> 0 | AN10: =IF(OR(S10=""),"",ROUND(S10*7.1,0)) -> 4757 | AO10: =IF(OR(T10=""),"",ROUND(T10*2.4,0)) -> 1560 | AP10: 3045 | AQ10: =IF(OR($AJ10=""),"",ROUND(AL10/$AJ10*1000,1)) -> 0 | AR10: =IF(OR($AJ10=""),"",ROUND(AM10/$AJ10*1000,2)) -> 0 | AS10: =IF(OR($AJ10=""),"",ROUND(AN10/$AJ10*1000,1)) -> 22.9 | AT10: =IF(OR($AJ10=""),"",ROUND(AO10/$AJ10*1000,2)) -> 7.53
A11: =A10+1 -> 43870 | B11: 易萍 | C11: 30180453 | D11: 16303896 | E11: 11968319 | F11: 11564740 | G11: 280214711 | H11: 106063677 | I11: 280214711 | J11: 106063677 | L11: 4299.8 | M11: 4275.78 | N11: 73819.17 | Q11: 13.5 | R11: 阴 | S11: 680 | T11: 670 | U11: 9409 | V11: 7645 | W11: 6.17 | X11: 4.28 | Y11: 1440 | AA11: =IF(OR(C12=""),"",C12-C11) -> 48599 | AB11: =IF(OR(D12=""),"",D12-D11) -> 60786 | AC11: =IF(OR(E12=""),"",E12-E11) -> 54880 | AD11: =IF(OR(F12=""),"",F12-F11) -> 53224 | AE11: =IF(OR(G12=""),"",G12-G11) -> 211672 | AF11: =IF(OR(H12=""),"",H12-H11) -> 5489 | AG11: =IF(OR(AA11="",AB11="",AC11=""),"",AA11+AB11+AC11+AD11-AE11) -> 5817 | AH11: =IF(OR(I12=""),"",I12-I11) -> 211672 | AI11: =IF(OR(J12=""),"",J12-J11) -> 5489 | AJ11: =IF(OR(AH11="",AI11=""),"",AH11-AI11) -> 206183 | AK11: 3800 | AL11: =IF(OR(L12="",M12=""),"",ROUND((L12-L11+M12-M11)*1200,0)) -> 0 | AM11: =IF(OR(N12=""),"",(ROUND((N12-N11)*2,0))) -> 0 | AN11: =IF(OR(S11=""),"",ROUND(S11*7.1,0)) -> 4828 | AO11: =IF(OR(T11=""),"",ROUND(T11*2.4,0)) -> 1608 | AP11: 2985 | AQ11: =IF(OR($AJ11=""),"",ROUND(AL11/$AJ11*1000,1)) -> 0 | AR11: =IF(OR($AJ11=""),"",ROUND(AM11/$AJ11*1000,2)) -> 0 | AS11: =IF(OR($AJ11=""),"",ROUND(AN11/$AJ11*1000,1)) -> 23.4 | AT11: =IF(OR($AJ11=""),"",ROUND(AO11/$AJ11*1000,2)) -> 7.8
A12: =A11+1 -> 43871 | B12: 易萍 | C12: 30229052 | D12: 16364682 | E12: 12023199 | F12: 11617964 | G12: 280426383 | H12: 106069166 | I12: 280426383 | J12: 106069166 | L12: 4299.8 | M12: 4275.78 | N12: 73819.17 | Q12: 15.6 | R12: 阴 | S12: 470 | T12: 480 | U12: 9266 | V12: 7778 | W12: 5.64 | X12: 3.95 | Y12: 1440 | AA12: =IF(OR(C13=""),"",C13-C12) -> 47262 | AB12: =IF(OR(D13=""),"",D13-D12) -> 59006 | AC12: =IF(OR(E13=""),"",E13-E12) -> 55055 | AD12: =IF(OR(F13=""),"",F13-F12) -> 52271 | AE12: =IF(OR(G13=""),"",G13-G12) -> 210714 | AF12: =IF(OR(H13=""),"",H13-H12) -> 5471 | AG12: =IF(OR(AA12="",AB12="",AC12=""),"",AA12+AB12+AC12+AD12-AE12) -> 2880 | AH12: =IF(OR(I13=""),"",I13-I12) -> 210714 | AI12: =IF(OR(J13=""),"",J13-J12) -> 5471 | AJ12: =IF(OR(AH12="",AI12=""),"",AH12-AI12) -> 205243 | AK12: 4000 | AL12: =IF(OR(L13="",M13=""),"",ROUND((L13-L12+M13-M12)*1200,0)) -> 0 | AM12: =IF(OR(N13=""),"",(ROUND((N13-N12)*2,0))) -> 0 | AN12: =IF(OR(S12=""),"",ROUND(S12*7.1,0)) -> 3337 | AO12: =IF(OR(T12=""),"",ROUND(T12*2.4,0)) -> 1152 | AP12: 3251 | AQ12: =IF(OR($AJ12=""),"",ROUND(AL12/$AJ12*1000,1)) -> 0 | AR12: =IF(OR($AJ12=""),"",ROUND(AM12/$AJ12*1000,2)) -> 0 | AS12: =IF(OR($AJ12=""),"",ROUND(AN12/$AJ12*1000,1)) -> 16.3 | AT12: =IF(OR($AJ12=""),"",ROUND(AO12/$AJ12*1000,2)) -> 5.61
A13: =A12+1 -> 43872 | B13: 易萍 | C13: 30276314 | D13: 16423688 | E13: 12078254 | F13: 11670235 | G13: 280637097 | H13: 106074637 | I13: 280637097 | J13: 106074637 | L13: 4299.8 | M13: 4275.78 | N13: 73819.17 | Q13: 15.8 | R13: 雨 | S13: 350 | T13: 360 | U13: 9275 | V13: 9001 | W13: 6.34 | X13: 4.3 | Y13: 1440 | AA13: =IF(OR(C14=""),"",C14-C13) -> 49097 | AB13: =IF(OR(D14=""),"",D14-D13) -> 60977 | AC13: =IF(OR(E14=""),"",E14-E13) -> 56470 | AD13: =IF(OR(F14=""),"",F14-F13) -> 55048 | AE13: =IF(OR(G14=""),"",G14-G13) -> 209747 | AF13: =IF(OR(H14=""),"",H14-H13) -> 5463 | AG13: =IF(OR(AA13="",AB13="",AC13=""),"",AA13+AB13+AC13+AD13-AE13) -> 11845 | AH13: =IF(OR(I14=""),"",I14-I13) -> 209747 | AI13: =IF(OR(J14=""),"",J14-J13) -> 5463 | AJ13: =IF(OR(AH13="",AI13=""),"",AH13-AI13) -> 204284 | AK13: 4320 | AL13: =IF(OR(L14="",M14=""),"",ROUND((L14-L13+M14-M13)*1200,0)) -> 0 | AM13: =IF(OR(N14=""),"",(ROUND((N14-N13)*2,0))) -> 0 | AN13: =IF(OR(S13=""),"",ROUND(S13*7.1,0)) -> 2485 | AO13: =IF(OR(T13=""),"",ROUND(T13*2.4,0)) -> 864 | AP13: 3185 | AQ13: =IF(OR($AJ13=""),"",ROUND(AL13/$AJ13*1000,1)) -> 0 | AR13: =IF(OR($AJ13=""),"",ROUND(AM13/$AJ13*1000,2)) -> 0 | AS13: =IF(OR($AJ13=""),"",ROUND(AN13/$AJ13*1000,1)) -> 12.2 | AT13: =IF(OR($AJ13=""),"",ROUND(AO13/$AJ13*1000,2)) -> 4.23
A14: =A13+1 -> 43873 | B14: 陈智娇 | C14: 30325411 | D14: 16484665 | E14: 12134724 | F14: 11725283 | G14: 280846844 | H14: 106080100 | I14: 280846844 | J14: 106080100 | L14: 4299.8 | M14: 4275.78 | N14: 73819.17 | Q14: 14 | R14: 雨 | S14: 340 | T14: 360 | U14: 9308 | V14: 9006 | W14: 6.06 | X14: 5.14 | Y14: 1440 | AA14: =IF(OR(C15=""),"",C15-C14) -> 48354 | AB14: =IF(OR(D15=""),"",D15-D14) -> 60811 | AC14: =IF(OR(E15=""),"",E15-E14) -> 56434 | AD14: =IF(OR(F15=""),"",F15-F14) -> 54632 | AE14: =IF(OR(G15=""),"",G15-G14) -> 209277 | AF14: =IF(OR(H15=""),"",H15-H14) -> 5447 | AG14: =IF(OR(AA14="",AB14="",AC14=""),"",AA14+AB14+AC14+AD14-AE14) -> 10954 | AH14: =IF(OR(I15=""),"",I15-I14) -> 209277 | AI14: =IF(OR(J15=""),"",J15-J14) -> 5447 | AJ14: =IF(OR(AH14="",AI14=""),"",AH14-AI14) -> 203830 | AK14: 4200 | AL14: =IF(OR(L15="",M15=""),"",ROUND((L15-L14+M15-M14)*1200,0)) -> 0 | AM14: =IF(OR(N15=""),"",(ROUND((N15-N14)*2,0))) -> 0 | AN14: =IF(OR(S14=""),"",ROUND(S14*7.1,0)) -> 2414 | AO14: =IF(OR(T14=""),"",ROUND(T14*2.4,0)) -> 864 | AP14: 3089 | AQ14: =IF(OR($AJ14=""),"",ROUND(AL14/$AJ14*1000,1)) -> 0 | AR14: =IF(OR($AJ14=""),"",ROUND(AM14/$AJ14*1000,2)) -> 0 | AS14: =IF(OR($AJ14=""),"",ROUND(AN14/$AJ14*1000,1)) -> 11.8 | AT14: =IF(OR($AJ14=""),"",ROUND(AO14/$AJ14*1000,2)) -> 4.24
A15: =A14+1 -> 43874 | B15: 仇昊 | C15: 30373765 | D15: 16545476 | E15: 12191158 | F15: 11779915 | G15: 281056121 | H15: 106085547 | I15: 281056121 | J15: 106085547 | L15: 4299.8 | M15: 4275.78 | N15: 73819.17 | Q15: 14.1 | R15: 阴 | S15: 480 | T15: 470 | U15: 9348 | V15: 7878 | W15: 5.87 | X15: 4.72 | Y15: 1440 | AA15: =IF(OR(C16=""),"",C16-C15) -> 47740 | AB15: =IF(OR(D16=""),"",D16-D15) -> 59593 | AC15: =IF(OR(E16=""),"",E16-E15) -> 55989 | AD15: =IF(OR(F16=""),"",F16-F15) -> 53297 | AE15: =IF(OR(G16=""),"",G16-G15) -> 210630 | AF15: =IF(OR(H16=""),"",H16-H15) -> 5511 | AG15: =IF(OR(AA15="",AB15="",AC15=""),"",AA15+AB15+AC15+AD15-AE15) -> 5989 | AH15: =IF(OR(I16=""),"",I16-I15) -> 210630 | AI15: =IF(OR(J16=""),"",J16-J15) -> 5511 | AJ15: =IF(OR(AH15="",AI15=""),"",AH15-AI15) -> 205119 | AK15: 4000 | AL15: =IF(OR(L16="",M16=""),"",ROUND((L16-L15+M16-M15)*1200,0)) -> 0 | AM15: =IF(OR(N16=""),"",(ROUND((N16-N15)*2,0))) -> 0 | AN15: =IF(OR(S15=""),"",ROUND(S15*7.1,0)) -> 3408 | AO15: =IF(OR(T15=""),"",ROUND(T15*2.4,0)) -> 1128 | AP15: 2994 | AQ15: =IF(OR($AJ15=""),"",ROUND(AL15/$AJ15*1000,1)) -> 0 | AR15: =IF(OR($AJ15=""),"",ROUND(AM15/$AJ15*1000,2)) -> 0 | AS15: =IF(OR($AJ15=""),"",ROUND(AN15/$AJ15*1000,1)) -> 16.6 | AT15: =IF(OR($AJ15=""),"",ROUND(AO15/$AJ15*1000,2)) -> 5.5
... A30: =A29+1 -> 43889 | B30: 易萍 | C30: 31074730 | D30: 17416199 | E30: 13008615 | F30: 12560593 | G30: 284082000 | H30: 106163885 | I30: 284082000 | J30: 106163885 | L30: 4299.8 | M30: 4316.84 | N30: 73853.91 | Q30: 16.7 | R30: 晴 | S30: 730 | T30: 750 | U30: 9052 | V30: 7125 | W30: 5.73 | X30: 3.49 | Y30: 1440 | AA30: =IF(OR(C31=""),"",C31-C30) -> 43784 | AB30: =IF(OR(D31=""),"",D31-D30) -> 53821 | AC30: =IF(OR(E31=""),"",E31-E30) -> 51439 | AD30: =IF(OR(F31=""),"",F31-F30) -> 45519 | AE30: =IF(OR(G31=""),"",G31-G30) -> 186894 | AF30: =IF(OR(H31=""),"",H31-H30) -> 5508 | AG30: =IF(OR(AA30="",AB30="",AC30=""),"",AA30+AB30+AC30+AD30-AE30) -> 7669 | AH30: =IF(OR(I31=""),"",I31-I30) -> 186894 | AI30: =IF(OR(J31=""),"",J31-J30) -> 5508 | AJ30: =IF(OR(AH30="",AI30=""),"",AH30-AI30) -> 181386 | AK30: 3900 | AL30: =IF(OR(L31="",M31=""),"",ROUND((L31-L30+M31-M30)*1200,0)) -> 11160 | AM30: =IF(OR(N31=""),"",(ROUND((N31-N30)*2,0))) -> 34 | AN30: =IF(OR(S30=""),"",ROUND(S30*7.1,0)) -> 5183 | AO30: =IF(OR(T30=""),"",ROUND(T30*2.4,0)) -> 1800 | AP30: 2167 | AQ30: =IF(OR($AJ30=""),"",ROUND(AL30/$AJ30*1000,1)) -> 61.5 | AR30: =IF(OR($AJ30=""),"",ROUND(AM30/$AJ30*1000,2)) -> 0.19 | AS30: =IF(OR($AJ30=""),"",ROUND(AN30/$AJ30*1000,1)) -> 28.6 | AT30: =IF(OR($AJ30=""),"",ROUND(AO30/$AJ30*1000,2)) -> 9.92
