Workbook

Sheet 1
B2: 记录人 | C2: 一期左进水 流量计读数 | D2: 一期右进水 流量计读数 | E2: 二期左进水 流量计读数 | F2: 二期右进水 流量计读数 | G2: 现场出水 流量计读数 | H2: 现场回用水 读数 | I2: 出水流量计 读数（网站） | J2: 回用水流量 （网站） | K2: 污泥流量 计读数 | L2: PAC2#流量计读数 | M2: PAC3#流量计读数 | N2: PAM流量 计读数 | O2: 盐酸流量 计读数 | P2: 氯酸钠流 量计读数 | Q2: 生反池 水温 | R2: 天气 (阴晴雨) | S2: 盐酸液位 差（CM） | T2: 氯酸钠液位差 差（CM） | U2: 最高流量 m3/h | V2: 最低流量 m3/h | W2: 最高液位 m | X2: 最低液位 m | Y2: 超液位时 间（分） | Z2: 备注 | AA2: 一期左 进水流量 | AB2: 一期右 进水流量 | AC2: 二期左 进水流量 | AD2: 二期右 进水流量 | AE2: 现场出水 流量 | AF2: 现场回用水 流量 | AG2: 进出水 流量差 | AH2: 出水流量（网站） | AI2: 回用水流量（网站） | AJ2: 实际处理量（网站） | AK2: 排泥量 m3 | AL2: PAC量 kg | AM2: PAM量 kg | AN2: 盐酸量 kg | AO2: 氯酸钠量 kg | AP2: 碳源量 kg | AQ2: PAC单耗 ppm | AR2: PAM单耗 ppm | AS2: 盐酸单耗 ppm | AT2: 氯酸钠单耗 ppm
A3: 43831 | B3: 仇昊 | C3: 12589440 | D3: 15183451 | E3: 14233000 | F3: 14231000 | G3: 205463623 | H3: 43037145 | I3: 205463698 | J3: 43037145 | L3: 4246.2 | M3: 3276.65 | N3: 71617.86 | Q3: 17.8 | R3: 晴 | S3: 330 | T3: 350 | U3: 6427 | V3: 5586 | W3: 6 | X3: 3 | Y3: 1044 | AA3: =IF(OR(C4=""),"",C4-C3) -> 32739 | AB3: =IF(OR(D4=""),"",D4-D3) -> 36286 | AC3: =IF(OR(E4=""),"",E4-E3) -> 33000 | AD3: =IF(OR(F4=""),"",F4-F3) -> 31000 | AE3: =IF(OR(G4=""),"",G4-G3) -> 134872 | AF3: =IF(OR(H4=""),"",H4-H3) -> 5094 | AG3: =IF(OR(AA3="",AB3="",AC3=""),"",AA3+AB3+AC3+AD3-AE3) -> -1847 | AH3: =IF(OR(I4=""),"",I4-I3) -> 136795 | AI3: =IF(OR(J4=""),"",J4-J3) -> 5094 | AJ3: =IF(OR(AH3="",AI3=""),"",AH3-AI3) -> 131701 | AK3: 1750 | AL3: =IF(OR(L4="",M4=""),"",ROUND((L4-L3+M4-M3)*1200,0)) -> 5760 | AM3: =IF(OR(N4=""),"",(ROUND((N4-N3)*2,0))) -> 28 | AN3: =IF(OR(S3=""),"",ROUND(S3*7.1,0)) -> 2343 | AO3: =IF(OR(T3=""),"",ROUND(T3*2.4,0)) -> 840 | AP3: 1900 | AQ3: =IF(OR($AJ3=""),"",ROUND(AL3/$AJ3*1000,1)) -> 43.7 | AR3: =IF(OR($AJ3=""),"",ROUND(AM3/$AJ3*1000,2)) -> 0.21 | AS3: =IF(OR($AJ3=""),"",ROUND(AN3/$AJ3*1000,1)) -> 17.8 | AT3: =IF(OR($AJ3=""),"",ROUND(AO3/$AJ3*1000,2)) -> 6.38
A4: =A3+1 -> 43832 | B4: 胡叶青 | C4: 12622179 | D4: 15219737 | E4: 14266000 | F4: 14262000 | G4: 205598495 | H4: 43042239 | I4: 205600493 | J4: 43042239 | L4: 4246.2 | M4: 3281.45 | N4: 71632.07 | Q4: 17.5 | R4: 晴 | S4: 300 | T4: 330 | U4: 6174 | V4: 5867 | W4: 5.4 | X4: 4.81 | Y4: 1320 | AA4: =IF(OR(C5=""),"",C5-C4) -> 35763 | AB4: =IF(OR(D5=""),"",D5-D4) -> 38999 | AC4: =IF(OR(E5=""),"",E5-E4) -> 34000 | AD4: =IF(OR(F5=""),"",F5-F4) -> 34000 | AE4: =IF(OR(G5=""),"",G5-G4) -> 150191 | AF4: =IF(OR(H5=""),"",H5-H4) -> 5282 | AG4: =IF(OR(AA4="",AB4="",AC4=""),"",AA4+AB4+AC4+AD4-AE4) -> -7429 | AH4: =IF(OR(I5=""),"",I5-I4) -> 147807 | AI4: =IF(OR(J5=""),"",J5-J4) -> 5282 | AJ4: =IF(OR(AH4="",AI4=""),"",AH4-AI4) -> 142525 | AK4: 1400 | AL4: =IF(OR(L5="",M5=""),"",ROUND((L5-L4+M5-M4)*1200,0)) -> 4800 | AM4: =IF(OR(N5=""),"",(ROUND((N5-N4)*2,0))) -> 29 | AN4: =IF(OR(S4=""),"",ROUND(S4*7.1,0)) -> 2130 | AO4: =IF(OR(T4=""),"",ROUND(T4*2.4,0)) -> 792 | AP4: 1900 | AQ4: =IF(OR($AJ4=""),"",ROUND(AL4/$AJ4*1000,1)) -> 33.7 | AR4: =IF(OR($AJ4=""),"",ROUND(AM4/$AJ4*1000,2)) -> 0.2 | AS4: =IF(OR($AJ4=""),"",ROUND(AN4/$AJ4*1000,1)) -> 14.9 | AT4: =IF(OR($AJ4=""),"",ROUND(AO4/$AJ4*1000,2)) -> 5.56
A5: =A4+1 -> 43833 | B5: 潘汝鑫 | C5: 12657942 | D5: 15258736 | E5: 14300000 | F5: 14296000 | G5: 205748686 | H5: 43047521 | I5: 205748300 | J5: 43047521 | L5: 4246.2 | M5: 3285.45 | N5: 71646.49 | Q5: 18.2 | R5: 晴 | S5: 470 | T5: 500 | U5: 8399 | V5: 5054 | W5: 5.96 | X5: 4.28 | Y5: 1431 | AA5: =IF(OR(C6=""),"",C6-C5) -> 39647 | AB5: =IF(OR(D6=""),"",D6-D5) -> 44353 | AC5: =IF(OR(E6=""),"",E6-E5) -> 40000 | AD5: =IF(OR(F6=""),"",F6-F5) -> 40000 | AE5: =IF(OR(G6=""),"",G6-G5) -> 137715 | AF5: =IF(OR(H6=""),"",H6-H5) -> 5200 | AG5: =IF(OR(AA5="",AB5="",AC5=""),"",AA5+AB5+AC5+AD5-AE5) -> 26285 | AH5: =IF(OR(I6=""),"",I6-I5) -> 138071 | AI5: =IF(OR(J6=""),"",J6-J5) -> 5200 | AJ5: =IF(OR(AH5="",AI5=""),"",AH5-AI5) -> 132871 | AK5: 1200 | AL5: =IF(OR(L6="",M6=""),"",ROUND((L6-L5+M6-M5)*1200,0)) -> 9996 | AM5: =IF(OR(N6=""),"",(ROUND((N6-N5)*2,0))) -> 32 | AN5: =IF(OR(S5=""),"",ROUND(S5*7.1,0)) -> 3337 | AO5: =IF(OR(T5=""),"",ROUND(T5*2.4,0)) -> 1200 | AP5: 1900 | AQ5: =IF(OR($AJ5=""),"",ROUND(AL5/$AJ5*1000,1)) -> 75.2 | AR5: =IF(OR($AJ5=""),"",ROUND(AM5/$AJ5*1000,2)) -> 0.24 | AS5: =IF(OR($AJ5=""),"",ROUND(AN5/$AJ5*1000,1)) -> 25.1 | AT5: =IF(OR($AJ5=""),"",ROUND(AO5/$AJ5*1000,2)) -> 9.03
A6: =A5+1 -> 43834 | B6: 陈智娇 | C6: 12697589 | D6: 15303089 | E6: 14340000 | F6: 14336000 | G6: 205886401 | H6: 43052721 | I6: 205886371 | J6: 43052721 | L6: 4246.2 | M6: 3293.78 | N6: 71662.25 | Q6: 18.3 | R6: 阴 | S6: 400 | T6: 450 | U6: 8012 | V6: 4993 | W6: 5.9 | X6: 4.25 | Y6: 1434 | AA6: =IF(OR(C7=""),"",C7-C6) -> 41663 | AB6: =IF(OR(D7=""),"",D7-D6) -> 47029 | AC6: =IF(OR(E7=""),"",E7-E6) -> 42000 | AD6: =IF(OR(F7=""),"",F7-F6) -> 42000 | AE6: =IF(OR(G7=""),"",G7-G6) -> 156130 | AF6: =IF(OR(H7=""),"",H7-H6) -> 5120 | AG6: =IF(OR(AA6="",AB6="",AC6=""),"",AA6+AB6+AC6+AD6-AE6) -> 16562 | AH6: =IF(OR(I7=""),"",I7-I6) -> 153730 | AI6: =IF(OR(J7=""),"",J7-J6) -> 5120 | AJ6: =IF(OR(AH6="",AI6=""),"",AH6-AI6) -> 148610 | AK6: 0 | AL6: =IF(OR(L7="",M7=""),"",ROUND((L7-L6+M7-M6)*1200,0)) -> 12528 | AM6: =IF(OR(N7=""),"",(ROUND((N7-N6)*2,0))) -> 14 | AN6: =IF(OR(S6=""),"",ROUND(S6*7.1,0)) -> 2840 | AO6: =IF(OR(T6=""),"",ROUND(T6*2.4,0)) -> 1080 | AP6: 2200 | AQ6: =IF(OR($AJ6=""),"",ROUND(AL6/$AJ6*1000,1)) -> 84.3 | AR6: =IF(OR($AJ6=""),"",ROUND(AM6/$AJ6*1000,2)) -> 0.09 | AS6: =IF(OR($AJ6=""),"",ROUND(AN6/$AJ6*1000,1)) -> 19.1 | AT6: =IF(OR($AJ6=""),"",ROUND(AO6/$AJ6*1000,2)) -> 7.27
A7: =A6+1 -> 43835 | B7: 陈智娇 | C7: 12739252 | D7: 15350118 | E7: 14382000 | F7: 14378000 | G7: 206042531 | H7: 43057841 | I7: 206040101 | J7: 43057841 | L7: 4246.2 | M7: 3304.22 | N7: 71669.17 | Q7: 16.9 | R7: 阴 | S7: 550 | T7: 600 | U7: 6975 | V7: 5012 | W7: 6.15 | X7: 4.45 | Y7: 1434 | AA7: =IF(OR(C8=""),"",C8-C7) -> 35125 | AB7: =IF(OR(D8=""),"",D8-D7) -> 38688 | AC7: =IF(OR(E8=""),"",E8-E7) -> 35000 | AD7: =IF(OR(F8=""),"",F8-F7) -> 33000 | AE7: =IF(OR(G8=""),"",G8-G7) -> 136953 | AF7: =IF(OR(H8=""),"",H8-H7) -> 5170 | AG7: =IF(OR(AA7="",AB7="",AC7=""),"",AA7+AB7+AC7+AD7-AE7) -> 4860 | AH7: =IF(OR(I8=""),"",I8-I7) -> 139358 | AI7: =IF(OR(J8=""),"",J8-J7) -> 5170 | AJ7: =IF(OR(AH7="",AI7=""),"",AH7-AI7) -> 134188 | AK7: 0 | AL7: =IF(OR(L8="",M8=""),"",ROUND((L8-L7+M8-M7)*1200,0)) -> 11424 | AM7: =IF(OR(N8=""),"",(ROUND((N8-N7)*2,0))) -> 18 | AN7: =IF(OR(S7=""),"",ROUND(S7*7.1,0)) -> 3905 | AO7: =IF(OR(T7=""),"",ROUND(T7*2.4,0)) -> 1440 | AP7: 2200 | AQ7: =IF(OR($AJ7=""),"",ROUND(AL7/$AJ7*1000,1)) -> 85.1 | AR7: =IF(OR($AJ7=""),"",ROUND(AM7/$AJ7*1000,2)) -> 0.13 | AS7: =IF(OR($AJ7=""),"",ROUND(AN7/$AJ7*1000,1)) -> 29.1 | AT7: =IF(OR($AJ7=""),"",ROUND(AO7/$AJ7*1000,2)) -> 10.73
A8: =A7+1 -> 43836 | B8: 陈智娇 | C8: 12774377 | D8: 15388806 | E8: 14417000 | F8: 14411000 | G8: 206179484 | H8: 43063011 | I8: 206179459 | J8: 43063011 | L8: 4246.2 | M8: 3313.74 | N8: 71678.08 | Q8: 17.2 | R8: 阴 | S8: 500 | T8: 530 | U8: 7200 | V8: 4851 | W8: 5.93 | X8: 4.17 | Y8: 1434 | AA8: =IF(OR(C9=""),"",C9-C8) -> 37792 | AB8: =IF(OR(D9=""),"",D9-D8) -> 41406 | AC8: =IF(OR(E9=""),"",E9-E8) -> 38000 | AD8: =IF(OR(F9=""),"",F9-F8) -> 37000 | AE8: =IF(OR(G9=""),"",G9-G8) -> 151032 | AF8: 5157 | AG8: =IF(OR(AA8="",AB8="",AC8=""),"",AA8+AB8+AC8+AD8-AE8) -> 3166 | AH8: =IF(OR(I9=""),"",I9-I8) -> 150634 | AI8: 5157 | AJ8: =IF(OR(AH8="",AI8=""),"",AH8-AI8) -> 145477 | AK8: 0 | AL8: =IF(OR(L9="",M9=""),"",ROUND((L9-L8+M9-M8)*1200,0)) -> 7872 | AM8: =IF(OR(N9=""),"",(ROUND((N9-N8)*2,0))) -> 37 | AN8: =IF(OR(S8=""),"",ROUND(S8*7.1,0)) -> 3550 | AO8: =IF(OR(T8=""),"",ROUND(T8*2.4,0)) -> 1272 | AP8: 2100 | AQ8: =IF(OR($AJ8=""),"",ROUND(AL8/$AJ8*1000,1)) -> 54.1 | AR8: =IF(OR($AJ8=""),"",ROUND(AM8/$AJ8*1000,2)) -> 0.25 | AS8: =IF(OR($AJ8=""),"",ROUND(AN8/$AJ8*1000,1)) -> 24.4 | AT8: =IF(OR($AJ8=""),"",ROUND(AO8/$AJ8*1000,2)) -> 8.74
A9: =A8+1 -> 43837 | B9: 陈智娇 | C9: 12812169 | D9: 15430212 | E9: 14455000 | F9: 14448000 | G9: 206330516 | H9: 5157 | I9: 206330093 | J9: 5157 | L9: 4246.2 | M9: 3320.3 | N9: 71696.51 | Q9: 17.7 | R9: 阴 | S9: 670 | T9: 680 | U9: 7648 | V9: 5033 | W9: 5.92 | X9: 3.67 | Y9: 1434 | AA9: =IF(OR(C10=""),"",C10-C9) -> 40820 | AB9: =IF(OR(D10=""),"",D10-D9) -> 44932 | AC9: =IF(OR(E10=""),"",E10-E9) -> 31000 | AD9: =IF(OR(F10=""),"",F10-F9) -> 30000 | AE9: =IF(OR(G10=""),"",G10-G9) -> 145864 | AF9: =IF(OR(H10=""),"",H10-H9) -> 4816 | AG9: =IF(OR(AA9="",AB9="",AC9=""),"",AA9+AB9+AC9+AD9-AE9) -> 888 | AH9: =IF(OR(I10=""),"",I10-I9) -> 147271 | AI9: =IF(OR(J10=""),"",J10-J9) -> 4816 | AJ9: =IF(OR(AH9="",AI9=""),"",AH9-AI9) -> 142455 | AK9: 0 | AL9: =IF(OR(L10="",M10=""),"",ROUND((L10-L9+M10-M9)*1200,0)) -> 12 | AM9: =IF(OR(N10=""),"",(ROUND((N10-N9)*2,0))) -> 0 | AN9: =IF(OR(S9=""),"",ROUND(S9*7.1,0)) -> 4757 | AO9: =IF(OR(T9=""),"",ROUND(T9*2.4,0)) -> 1632 | AP9: 2100 | AQ9: =IF(OR($AJ9=""),"",ROUND(AL9/$AJ9*1000,1)) -> 0.1 | AR9: =IF(OR($AJ9=""),"",ROUND(AM9/$AJ9*1000,2)) -> 0 | AS9: =IF(OR($AJ9=""),"",ROUND(AN9/$AJ9*1000,1)) -> 33.4 | AT9: =IF(OR($AJ9=""),"",ROUND(AO9/$AJ9*1000,2)) -> 11.46
A10: =A9+1 -> 43838 | B10: 陈智娇 | C10: 12852989 | D10: 15475144 | E10: 14486000 | F10: 14478000 | G10: 206476380 | H10: 9973 | I10: 206477364 | J10: 9973 | L10: 4246.2 | M10: 3320.31 | N10: 71696.6 | Q10: 17 | R10: 晴 | S10: 480 | T10: 500 | U10: 6188 | V10: 5600 | W10: 5.5 | X10: 2.72 | Y10: 1285 | AA10: =IF(OR(C11=""),"",C11-C10) -> 41386 | AB10: =IF(OR(D11=""),"",D11-D10) -> 44798 | AC10: =IF(OR(E11=""),"",E11-E10) -> 27000 | AD10: =IF(OR(F11=""),"",F11-F10) -> 27000 | AE10: =IF(OR(G11=""),"",G11-G10) -> 143988 | AF10: =IF(OR(H11=""),"",H11-H10) -> 5195 | AG10: =IF(OR(AA10="",AB10="",AC10=""),"",AA10+AB10+AC10+AD10-AE10) -> -3804 | AH10: =IF(OR(I11=""),"",I11-I10) -> 142737 | AI10: =IF(OR(J11=""),"",J11-J10) -> 5195 | AJ10: =IF(OR(AH10="",AI10=""),"",AH10-AI10) -> 137542 | AK10: 0 | AL10: =IF(OR(L11="",M11=""),"",ROUND((L11-L10+M11-M10)*1200,0)) -> 0 | AM10: =IF(OR(N11=""),"",(ROUND((N11-N10)*2,0))) -> 0 | AN10: =IF(OR(S10=""),"",ROUND(S10*7.1,0)) -> 3408 | AO10: =IF(OR(T10=""),"",ROUND(T10*2.4,0)) -> 1200 | AP10: 2100 | AQ10: =IF(OR($AJ10=""),"",ROUND(AL10/$AJ10*1000,1)) -> 0 | AR10: =IF(OR($AJ10=""),"",ROUND(AM10/$AJ10*1000,2)) -> 0 | AS10: =IF(OR($AJ10=""),"",ROUND(AN10/$AJ10*1000,1)) -> 24.8 | AT10: =IF(OR($AJ10=""),"",ROUND(AO10/$AJ10*1000,2)) -> 8.72
A11: =A10+1 -> 43839 | B11: 张亚光 | C11: 12894375 | D11: 15519942 | E11: 14513000 | F11: 14505000 | G11: 206620368 | H11: 15168 | I11: 206620101 | J11: 15168 | L11: 4246.2 | M11: 3320.31 | N11: 71696.6 | Q11: 17.4 | R11: 晴 | S11: 290 | T11: 310 | U11: 6654 | V11: 6128 | W11: 5.52 | X11: 2.83 | Y11: 1035 | AA11: =IF(OR(C12=""),"",C12-C11) -> 43818 | AB11: =IF(OR(D12=""),"",D12-D11) -> 47543 | AC11: =IF(OR(E12=""),"",E12-E11) -> 29000 | AD11: =IF(OR(F12=""),"",F12-F11) -> 27000 | AE11: =IF(OR(G12=""),"",G12-G11) -> 146445 | AF11: =IF(OR(H12=""),"",H12-H11) -> 4711 | AG11: =IF(OR(AA11="",AB11="",AC11=""),"",AA11+AB11+AC11+AD11-AE11) -> 916 | AH11: =IF(OR(I12=""),"",I12-I11) -> 148982 | AI11: =IF(OR(J12=""),"",J12-J11) -> 4711 | AJ11: =IF(OR(AH11="",AI11=""),"",AH11-AI11) -> 144271 | AK11: 0 | AL11: =IF(OR(L12="",M12=""),"",ROUND((L12-L11+M12-M11)*1200,0)) -> 0 | AM11: =IF(OR(N12=""),"",(ROUND((N12-N11)*2,0))) -> 0 | AN11: =IF(OR(S11=""),"",ROUND(S11*7.1,0)) -> 2059 | AO11: =IF(OR(T11=""),"",ROUND(T11*2.4,0)) -> 744 | AP11: 1900 | AQ11: =IF(OR($AJ11=""),"",ROUND(AL11/$AJ11*1000,1)) -> 0 | AR11: =IF(OR($AJ11=""),"",ROUND(AM11/$AJ11*1000,2)) -> 0 | AS11: =IF(OR($AJ11=""),"",ROUND(AN11/$AJ11*1000,1)) -> 14.3 | AT11: =IF(OR($AJ11=""),"",ROUND(AO11/$AJ11*1000,2)) -> 5.16
A12: =A11+1 -> 43840 | B12: 胡叶青 | C12: 12938193 | D12: 15567485 | E12: 14542000 | F12: 14532000 | G12: 206766813 | H12: 19879 | I12: 206769083 | J12: 19879 | L12: 4246.2 | M12: 3320.31 | N12: 71696.6 | Q12: 17.6 | R12: 晴 | S12: 500 | T12: 530 | U12: 6641 | V12: 4950 | W12: 6.53 | X12: 4.23 | Y12: 1432 | AA12: =IF(OR(C13=""),"",C13-C12) -> 44805 | AB12: =IF(OR(D13=""),"",D13-D12) -> 48733 | AC12: =IF(OR(E13=""),"",E13-E12) -> 29000 | AD12: =IF(OR(F13=""),"",F13-F12) -> 29000 | AE12: =IF(OR(G13=""),"",G13-G12) -> 154057 | AF12: =IF(OR(H13=""),"",H13-H12) -> 5517 | AG12: =IF(OR(AA12="",AB12="",AC12=""),"",AA12+AB12+AC12+AD12-AE12) -> -2519 | AH12: =IF(OR(I13=""),"",I13-I12) -> 150904 | AI12: =IF(OR(J13=""),"",J13-J12) -> 5517 | AJ12: =IF(OR(AH12="",AI12=""),"",AH12-AI12) -> 145387 | AK12: 495 | AL12: =IF(OR(L13="",M13=""),"",ROUND((L13-L12+M13-M12)*1200,0)) -> 7872 | AM12: =IF(OR(N13=""),"",(ROUND((N13-N12)*2,0))) -> 36 | AN12: =IF(OR(S12=""),"",ROUND(S12*7.1,0)) -> 3550 | AO12: =IF(OR(T12=""),"",ROUND(T12*2.4,0)) -> 1272 | AP12: 2700 | AQ12: =IF(OR($AJ12=""),"",ROUND(AL12/$AJ12*1000,1)) -> 54.1 | AR12: =IF(OR($AJ12=""),"",ROUND(AM12/$AJ12*1000,2)) -> 0.25 | AS12: =IF(OR($AJ12=""),"",ROUND(AN12/$AJ12*1000,1)) -> 24.4 | AT12: =IF(OR($AJ12=""),"",ROUND(AO12/$AJ12*1000,2)) -> 8.75
A13: =A12+1 -> 43841 | B13: 陈智娇 | C13: 12982998 | D13: 15616218 | E13: 14571000 | F13: 14561000 | G13: 206920870 | H13: 25396 | I13: 206919987 | J13: 25396 | L13: 4246.2 | M13: 3326.87 | N13: 71714.46 | Q13: 17.2 | R13: 晴 | S13: 700 | T13: 730 | U13: 7878 | V13: 5012 | W13: 5.8 | X13: 4.23 | Y13: 1439 | AA13: =IF(OR(C14=""),"",C14-C13) -> 46421 | AB13: =IF(OR(D14=""),"",D14-D13) -> 51837 | AC13: =IF(OR(E14=""),"",E14-E13) -> 31000 | AD13: =IF(OR(F14=""),"",F14-F13) -> 30000 | AE13: =IF(OR(G14=""),"",G14-G13) -> 145150 | AF13: =IF(OR(H14=""),"",H14-H13) -> 5440 | AG13: =IF(OR(AA13="",AB13="",AC13=""),"",AA13+AB13+AC13+AD13-AE13) -> 14108 | AH13: =IF(OR(I14=""),"",I14-I13) -> 145766 | AI13: =IF(OR(J14=""),"",J14-J13) -> 5440 | AJ13: =IF(OR(AH13="",AI13=""),"",AH13-AI13) -> 140326 | AK13: 0 | AL13: =IF(OR(L14="",M14=""),"",ROUND((L14-L13+M14-M13)*1200,0)) -> 7356 | AM13: =IF(OR(N14=""),"",(ROUND((N14-N13)*2,0))) -> 26 | AN13: =IF(OR(S13=""),"",ROUND(S13*7.1,0)) -> 4970 | AO13: =IF(OR(T13=""),"",ROUND(T13*2.4,0)) -> 1752 | AP13: 2900 | AQ13: =IF(OR($AJ13=""),"",ROUND(AL13/$AJ13*1000,1)) -> 52.4 | AR13: =IF(OR($AJ13=""),"",ROUND(AM13/$AJ13*1000,2)) -> 0.19 | AS13: =IF(OR($AJ13=""),"",ROUND(AN13/$AJ13*1000,1)) -> 35.4 | AT13: =IF(OR($AJ13=""),"",ROUND(AO13/$AJ13*1000,2)) -> 12.49
A14: =A13+1 -> 43842 | B14: 陈智娇 | C14: 13029419 | D14: 15668055 | E14: 14602000 | F14: 14591000 | G14: 207066020 | H14: 30836 | I14: 207065753 | J14: 30836 | L14: 4246.2 | M14: 3333 | N14: 71727.36 | Q14: 17 | R14: 晴 | S14: 750 | T14: 740 | U14: 7156 | V14: 5525 | W14: 6.07 | X14: 3.51 | Y14: 1427 | AA14: =IF(OR(C15=""),"",C15-C14) -> 46510 | AB14: =IF(OR(D15=""),"",D15-D14) -> 51728 | AC14: =IF(OR(E15=""),"",E15-E14) -> 31000 | AD14: =IF(OR(F15=""),"",F15-F14) -> 29000 | AE14: =IF(OR(G15=""),"",G15-G14) -> 147223 | AF14: =IF(OR(H15=""),"",H15-H14) -> 5503 | AG14: =IF(OR(AA14="",AB14="",AC14=""),"",AA14+AB14+AC14+AD14-AE14) -> 11015 | AH14: =IF(OR(I15=""),"",I15-I14) -> 146689 | AI14: =IF(OR(J15=""),"",J15-J14) -> 5503 | AJ14: =IF(OR(AH14="",AI14=""),"",AH14-AI14) -> 141186 | AK14: 1320 | AL14: =IF(OR(L15="",M15=""),"",ROUND((L15-L14+M15-M14)*1200,0)) -> 7080 | AM14: =IF(OR(N15=""),"",(ROUND((N15-N14)*2,0))) -> 25 | AN14: =IF(OR(S14=""),"",ROUND(S14*7.1,0)) -> 5325 | AO14: =IF(OR(T14=""),"",ROUND(T14*2.4,0)) -> 1776 | AP14: 2400 | AQ14: =IF(OR($AJ14=""),"",ROUND(AL14/$AJ14*1000,1)) -> 50.1 | AR14: =IF(OR($AJ14=""),"",ROUND(AM14/$AJ14*1000,2)) -> 0.18 | AS14: =IF(OR($AJ14=""),"",ROUND(AN14/$AJ14*1000,1)) -> 37.7 | AT14: =IF(OR($AJ14=""),"",ROUND(AO14/$AJ14*1000,2)) -> 12.58
A15: =A14+1 -> 43843 | B15: 陈智娇 | C15: 13075929 | D15: 15719783 | E15: 14633000 | F15: 14620000 | G15: 207213243 | H15: 36339 | I15: 207212442 | J15: 36339 | L15: 4246.2 | M15: 3338.9 | N15: 71740 | Q15: 17.2 | R15: 晴 | S15: 710 | T15: 700 | U15: 8245 | V15: 5421 | W15: 5.77 | X15: 3.65 | Y15: 1432 | AA15: =IF(OR(C16=""),"",C16-C15) -> 47308 | AB15: =IF(OR(D16=""),"",D16-D15) -> 53371 | AC15: =IF(OR(E16=""),"",E16-E15) -> 31000 | AD15: =IF(OR(F16=""),"",F16-F15) -> 31000 | AE15: =IF(OR(G16=""),"",G16-G15) -> 148712 | AF15: =IF(OR(H16=""),"",H16-H15) -> 5476 | AG15: =IF(OR(AA15="",AB15="",AC15=""),"",AA15+AB15+AC15+AD15-AE15) -> 13967 | AH15: =IF(OR(I16=""),"",I16-I15) -> 148845 | AI15: =IF(OR(J16=""),"",J16-J15) -> 5476 | AJ15: =IF(OR(AH15="",AI15=""),"",AH15-AI15) -> 143369 | AK15: 1485 | AL15: =IF(OR(L16="",M16=""),"",ROUND((L16-L15+M16-M15)*1200,0)) -> 6948 | AM15: =IF(OR(N16=""),"",(ROUND((N16-N15)*2,0))) -> 26 | AN15: =IF(OR(S15=""),"",ROUND(S15*7.1,0)) -> 5041 | AO15: =IF(OR(T15=""),"",ROUND(T15*2.4,0)) -> 1680 | AP15: 2300 | AQ15: =IF(OR($AJ15=""),"",ROUND(AL15/$AJ15*1000,1)) -> 48.5 | AR15: =IF(OR($AJ15=""),"",ROUND(AM15/$AJ15*1000,2)) -> 0.18 | AS15: =IF(OR($AJ15=""),"",ROUND(AN15/$AJ15*1000,1)) -> 35.2 | AT15: =IF(OR($AJ15=""),"",ROUND(AO15/$AJ15*1000,2)) -> 11.72
A16: =A15+1 -> 43844 | B16: 陈智娇 | C16: 13123237 | D16: 15773154 | E16: 14664000 | F16: 14651000 | G16: 207361955 | H16: 41815 | I16: 207361287 | J16: 41815 | L16: 4246.2 | M16: 3344.69 | N16: 71752.83 | Q16: 16.4 | R16: 晴 | S16: 660 | T16: 650 | U16: 7012 | V16: 5689 | W16: 5.9 | X16: 3.82 | Y16: 1435 | AA16: =IF(OR(C17=""),"",C17-C16) -> 44971 | AB16: =IF(OR(D17=""),"",D17-D16) -> 49587 | AC16: =IF(OR(E17=""),"",E17-E16) -> 29000 | AD16: =IF(OR(F17=""),"",F17-F16) -> 28000 | AE16: =IF(OR(G17=""),"",G17-G16) -> 150086 | AF16: =IF(OR(H17=""),"",H17-H16) -> 5481 | AG16: =IF(OR(AA16="",AB16="",AC16=""),"",AA16+AB16+AC16+AD16-AE16) -> 1472 | AH16: =IF(OR(I17=""),"",I17-I16) -> 150106 | AI16: =IF(OR(J17=""),"",J17-J16) -> 5481 | AJ16: =IF(OR(AH16="",AI16=""),"",AH16-AI16) -> 144625 | AK16: 1320 | AL16: =IF(OR(L17="",M17=""),"",ROUND((L17-L16+M17-M16)*1200,0)) -> 7164 | AM16: =IF(OR(N17=""),"",(ROUND((N17-N16)*2,0))) -> 16 | AN16: =IF(OR(S16=""),"",ROUND(S16*7.1,0)) -> 4686 | AO16: =IF(OR(T16=""),"",ROUND(T16*2.4,0)) -> 1560 | AP16: 2300 | AQ16: =IF(OR($AJ16=""),"",ROUND(AL16/$AJ16*1000,1)) -> 49.5 | AR16: =IF(OR($AJ16=""),"",ROUND(AM16/$AJ16*1000,2)) -> 0.11 | AS16: =IF(OR($AJ16=""),"",ROUND(AN16/$AJ16*1000,1)) -> 32.4 | AT16: =IF(OR($AJ16=""),"",ROUND(AO16/$AJ16*1000,2)) -> 10.79
A17: =A16+1 -> 43845 | B17: 陈智娇 | C17: 13168208 | D17: 15822741 | E17: 14693000 | F17: 14679000 | G17: 207512041 | H17: 47296 | I17: 207511393 | J17: 47296 | L17: 4246.2 | M17: 3350.66 | N17: 71760.75 | Q17: 17.8 | R17: 晴 | S17: 500 | T17: 550 | U17: 7000 | V17: 5852 | W17: 3.94 | X17: 3.23 | Y17: 19 | AA17: =IF(OR(C18=""),"",C18-C17) -> 46687 | AB17: =IF(OR(D18=""),"",D18-D17) -> 51789 | AC17: =IF(OR(E18=""),"",E18-E17) -> 29000 | AD17: =IF(OR(F18=""),"",F18-F17) -> 28000 | AE17: =IF(OR(G18=""),"",G18-G17) -> 149402 | AF17: =IF(OR(H18=""),"",H18-H17) -> 5436 | AG17: =IF(OR(AA17="",AB17="",AC17=""),"",AA17+AB17+AC17+AD17-AE17) -> 6074 | AH17: =IF(OR(I18=""),"",I18-I17) -> 151220 | AI17: =IF(OR(J18=""),"",J18-J17) -> 5436 | AJ17: =IF(OR(AH17="",AI17=""),"",AH17-AI17) -> 145784 | AK17: 700 | AL17: =IF(OR(L18="",M18=""),"",ROUND((L18-L17+M18-M17)*1200,0)) -> 6636 | AM17: =IF(OR(N18=""),"",(ROUND((N18-N17)*2,0))) -> 24 | AN17: =IF(OR(S17=""),"",ROUND(S17*7.1,0)) -> 3550 | AO17: =IF(OR(T17=""),"",ROUND(T17*2.4,0)) -> 1320 | AP17: 2300 | AQ17: =IF(OR($AJ17=""),"",ROUND(AL17/$AJ17*1000,1)) -> 45.5 | AR17: =IF(OR($AJ17=""),"",ROUND(AM17/$AJ17*1000,2)) -> 0.16 | AS17: =IF(OR($AJ17=""),"",ROUND(AN17/$AJ17*1000,1)) -> 24.4 | AT17: =IF(OR($AJ17=""),"",ROUND(AO17/$AJ17*1000,2)) -> 9.05
A18: =A17+1 -> 43846 | B18: 易萍 | C18: 13214895 | D18: 15874530 | E18: 14722000 | F18: 14707000 | G18: 207661443 | H18: 52732 | I18: 207662613 | J18: 52732 | L18: 4246.2 | M18: 3356.19 | N18: 71772.69 | Q18: 17 | R18: 晴 | S18: 330 | T18: 350 | U18: 6217 | V18: 5319 | W18: 5.4 | X18: 2.96 | Y18: 1346 | AA18: =IF(OR(C19=""),"",C19-C18) -> 43802 | AB18: =IF(OR(D19=""),"",D19-D18) -> 46457 | AC18: =IF(OR(E19=""),"",E19-E18) -> 26000 | AD18: =IF(OR(F19=""),"",F19-F18) -> 26000 | AE18: =IF(OR(G19=""),"",G19-G18) -> 141865 | AF18: =IF(OR(H19=""),"",H19-H18) -> 5516 | AG18: =IF(OR(AA18="",AB18="",AC18=""),"",AA18+AB18+AC18+AD18-AE18) -> 394 | AH18: =IF(OR(I19=""),"",I19-I18) -> 141549 | AI18: =IF(OR(J19=""),"",J19-J18) -> 5516 | AJ18: =IF(OR(AH18="",AI18=""),"",AH18-AI18) -> 136033 | AK18: 1500 | AL18: =IF(OR(L19="",M19=""),"",ROUND((L19-L18+M19-M18)*1200,0)) -> 3132 | AM18: =IF(OR(N19=""),"",(ROUND((N19-N18)*2,0))) -> 14 | AN18: =IF(OR(S18=""),"",ROUND(S18*7.1,0)) -> 2343 | AO18: =IF(OR(T18=""),"",ROUND(T18*2.4,0)) -> 840 | AP18: 2000 | AQ18: =IF(OR($AJ18=""),"",ROUND(AL18/$AJ18*1000,1)) -> 23 | AR18: =IF(OR($AJ18=""),"",ROUND(AM18/$AJ18*1000,2)) -> 0.1 | AS18: =IF(OR($AJ18=""),"",ROUND(AN18/$AJ18*1000,1)) -> 17.2 | AT18: =IF(OR($AJ18=""),"",ROUND(AO18/$AJ18*1000,2)) -> 6.17
A19: =A18+1 -> 43847 | B19: 仇昊 | C19: 13258697 | D19: 15920987 | E19: 14748000 | F19: 14733000 | G19: 207803308 | H19: 58248 | I19: 207804162 | J19: 58248 | L19: 4246.2 | M19: 3358.8 | N19: 71779.788 | Q19: 16.8 | R19: 晴 | S19: 400 | T19: 450 | U19: 7312 | V19: 5341 | W19: 5.01 | X19: 3.2 | Y19: 955 | AA19: =IF(OR(C20=""),"",C20-C19) -> 45767 | AB19: =IF(OR(D20=""),"",D20-D19) -> 49497 | AC19: =IF(OR(E20=""),"",E20-E19) -> 29000 | AD19: =IF(OR(F20=""),"",F20-F19) -> 27000 | AE19: =IF(OR(G20=""),"",G20-G19) -> 148993 | AF19: =IF(OR(H20=""),"",H20-H19) -> 5528 | AG19: =IF(OR(AA19="",AB19="",AC19=""),"",AA19+AB19+AC19+AD19-AE19) -> 2271 | AH19: =IF(OR(I20=""),"",I20-I19) -> 147881 | AI19: =IF(OR(J20=""),"",J20-J19) -> 5528 | AJ19: =IF(OR(AH19="",AI19=""),"",AH19-AI19) -> 142353 | AK19: 1980 | AL19: =IF(OR(L20="",M20=""),"",ROUND((L20-L19+M20-M19)*1200,0)) -> 3024 | AM19: =IF(OR(N20=""),"",(ROUND((N20-N19)*2,0))) -> 20 | AN19: =IF(OR(S19=""),"",ROUND(S19*7.1,0)) -> 2840 | AO19: =IF(OR(T19=""),"",ROUND(T19*2.4,0)) -> 1080 | AP19: 1900 | AQ19: =IF(OR($AJ19=""),"",ROUND(AL19/$AJ19*1000,1)) -> 21.2 | AR19: =IF(OR($AJ19=""),"",ROUND(AM19/$AJ19*1000,2)) -> 0.14 | AS19: =IF(OR($AJ19=""),"",ROUND(AN19/$AJ19*1000,1)) -> 20 | AT19: =IF(OR($AJ19=""),"",ROUND(AO19/$AJ19*1000,2)) -> 7.59
A20: =A19+1 -> 43848 | B20: 陈智娇 | C20: 13304464 | D20: 15970484 | E20: 14777000 | F20: 14760000 | G20: 207952301 | H20: 63776 | I20: 207952043 | J20: 63776 | L20: 4246.2 | M20: 3361.32 | N20: 71789.56 | Q20: 16.7 | R20: 晴 | S20: 660 | T20: 680 | U20: 6400 | V20: 4100 | W20: 4.76 | X20: 2.71 | Y20: 838 | AA20: =IF(OR(C21=""),"",C21-C20) -> 34455 | AB20: =IF(OR(D21=""),"",D21-D20) -> 36371 | AC20: =IF(OR(E21=""),"",E21-E20) -> 34000 | AD20: =IF(OR(F21=""),"",F21-F20) -> 33000 | AE20: =IF(OR(G21=""),"",G21-G20) -> 137091 | AF20: =IF(OR(H21=""),"",H21-H20) -> 5477 | AG20: =IF(OR(AA20="",AB20="",AC20=""),"",AA20+AB20+AC20+AD20-AE20) -> 735 | AH20: =IF(OR(I21=""),"",I21-I20) -> 137151 | AI20: =IF(OR(J21=""),"",J21-J20) -> 5477 | AJ20: =IF(OR(AH20="",AI20=""),"",AH20-AI20) -> 131674 | AK20: 1980 | AL20: =IF(OR(L21="",M21=""),"",ROUND((L21-L20+M21-M20)*1200,0)) -> 2808 | AM20: =IF(OR(N21=""),"",(ROUND((N21-N20)*2,0))) -> 24 | AN20: =IF(OR(S20=""),"",ROUND(S20*7.1,0)) -> 4686 | AO20: =IF(OR(T20=""),"",ROUND(T20*2.4,0)) -> 1632 | AP20: 2800 | AQ20: =IF(OR($AJ20=""),"",ROUND(AL20/$AJ20*1000,1)) -> 21.3 | AR20: =IF(OR($AJ20=""),"",ROUND(AM20/$AJ20*1000,2)) -> 0.18 | AS20: =IF(OR($AJ20=""),"",ROUND(AN20/$AJ20*1000,1)) -> 35.6 | AT20: =IF(OR($AJ20=""),"",ROUND(AO20/$AJ20*1000,2)) -> 12.39
... A33: =A32+1 -> 43861 | B33: 潘汝鑫 | C33: 13803288 | D33: 16510954 | E33: 15305000 | F33: 15279000 | G33: 209961839 | H33: 134305 | I33: 209961839 | J33: 134305 | L33: 4246.2 | M33: 3428.34 | N33: 71938.33 | Q33: 16 | R33: 雨 | S33: 520 | T33: 500 | U33: 7375 | V33: 4230 | W33: 4.9 | X33: 2.74 | Y33: 780 | AA33: =IF(OR(C34=""),"",C34-C33) -> 36028 | AB33: =IF(OR(D34=""),"",D34-D33) -> 39098 | AC33: =IF(OR(E34=""),"",E34-E33) -> 39000 | AD33: =IF(OR(F34=""),"",F34-F33) -> 39000 | AE33: =IF(OR(G34=""),"",G34-G33) -> 143636 | AF33: =IF(OR(H34=""),"",H34-H33) -> 5405 | AG33: =IF(OR(AA33="",AB33="",AC33=""),"",AA33+AB33+AC33+AD33-AE33) -> 9490 | AH33: =IF(OR(I34=""),"",I34-I33) -> 143636 | AI33: =IF(OR(J34=""),"",J34-J33) -> 5405 | AJ33: =IF(OR(AH33="",AI33=""),"",AH33-AI33) -> 138231 | AK33: 2970 | AL33: =IF(OR(L34="",M34=""),"",ROUND((L34-L33+M34-M33)*1200,0)) -> 14124 | AM33: =IF(OR(N34=""),"",(ROUND((N34-N33)*2,0))) -> 22 | AN33: =IF(OR(S33=""),"",ROUND(S33*7.1,0)) -> 3692 | AO33: =IF(OR(T33=""),"",ROUND(T33*2.4,0)) -> 1200 | AP33: 1700 | AQ33: =IF(OR($AJ33=""),"",ROUND(AL33/$AJ33*1000,1)) -> 102.2 | AR33: =IF(OR($AJ33=""),"",ROUND(AM33/$AJ33*1000,2)) -> 0.16 | AS33: =IF(OR($AJ33=""),"",ROUND(AN33/$AJ33*1000,1)) -> 26.7 | AT33: =IF(OR($AJ33=""),"",ROUND(AO33/$AJ33*1000,2)) -> 8.68
A34: =A33+1 -> 43862 | B34: 陈智娇 | C34: 13839316 | D34: 16550052 | E34: 15344000 | F34: 15318000 | G34: 210105475 | H34: 139710 | I34: 210105475 | J34: 139710 | L34: 4246.2 | M34: 3440.11 | N34: 71949.47
AA36: =IF(OR(C37=""),"",C37-C36) | AB36: =IF(OR(D37=""),"",D37-D36) | AC36: =IF(OR(E37=""),"",E37-E36) | AD36: =IF(OR(F37=""),"",F37-F36) | AE36: =IF(OR(G37=""),"",G37-G36) | AF36: =IF(OR(H37=""),"",H37-H36) | AG36: =IF(OR(AA36="",AB36="",AC36=""),"",AA36+AB36+AC36+AD36-AE36) | AH36: =SUM(AH3:AH34) -> 4641777 | AI36: =SUM(AI3:AI34) -> 165576 | AJ36: =SUM(AJ3:AJ34) -> 4476201 | AK36: =SUM(AK3:AK34) -> 51755 | AL36: =SUM(AL3:AL34) -> 196152 | AM36: =SUM(AM3:AM34) -> 664 | AN36: =SUM(AN3:AN34) -> 116085 | AO36: =SUM(AO3:AO34) -> 40968 | AQ36: =IF(OR($AJ36=0),"",ROUND(AL36/$AJ36*1000,1)) -> 43.8 | AR36: =IF(OR($AJ36=0),"",ROUND(AM36/$AJ36*1000,2)) -> 0.15 | AS36: =IF(OR($AJ36=0),"",ROUND(AN36/$AJ36*1000,1)) -> 25.9 | AT36: =IF(OR($AJ36=0),"",ROUND(AO36/$AJ36*1000,2)) -> 9.15

Sheet 2
B2: 记录人 | C2: 一期左进水 流量计读数 | D2: 一期右进水 流量计读数 | E2: 二期左进水 流量计读数 | F2: 二期右进水 流量计读数 | G2: 现场出水 流量计读数 | H2: 现场回用水 读数 | I2: 出水流量计 读数（网站） | J2: 回用水流量 （网站） | K2: 污泥流量 计读数 | L2: PAC2#流量计读数 | M2: PAC3#流量计读数 | N2: PAM流量 计读数 | O2: 盐酸流量 计读数 | P2: 氯酸钠流 量计读数 | Q2: 生反池 水温 | R2: 天气 (阴晴雨) | S2: 盐酸液位 差（CM） | T2: 氯酸钠液位差 差（CM） | U2: 最高流量 m3/h | V2: 最低流量 m3/h | W2: 最高液位 m | X2: 最低液位 m | Y2: 超液位时 间（分） | Z2: 备注 | AA2: 一期左 进水流量 | AB2: 一期右 进水流量 | AC2: 二期左 进水流量 | AD2: 二期右 进水流量 | AE2: 现场出水 流量 | AF2: 现场回用水 流量 | AG2: 进出水 流量差 | AH2: 出水流量（网站） | AI2: 回用水流量（网站） | AJ2: 实际处理量（网站） | AK2: 排泥量 m3 | AL2: PAC量 kg | AM2: PAM量 kg | AN2: 盐酸量 kg | AO2: 氯酸钠量 kg | AP2: 碳源量 kg | AQ2: PAC单耗 ppm | AR2: PAM单耗 ppm | AS2: 盐酸单耗 ppm | AT2: 氯酸钠单耗 ppm
A3: 43862 | B3: ='1'!B34 -> 陈智娇 | C3: ='1'!C34 -> 13839316 | D3: ='1'!D34 -> 16550052 | E3: ='1'!E34 -> 15344000 | F3: ='1'!F34 -> 15318000 | G3: ='1'!G34 -> 210105475 | H3: ='1'!H34 -> 139710 | I3: ='1'!I34 -> 210105475 | ... P3: ='1'!P34 -> 0 | Q3: 17 | R3: 阴 | S3: 640 | T3: 620 | U3: 7012 | V3: 5741 | W3: 6.15 | X3: 4.56 | Y3: 1440 | AA3: =IF(OR(C4=""),"",C4-C3) -> 37428 | AB3: =IF(OR(D4=""),"",D4-D3) -> 40200 | AC3: =IF(OR(E4=""),"",E4-E3) -> 42000 | AD3: =IF(OR(F4=""),"",F4-F3) -> 41000 | AE3: =IF(OR(G4=""),"",G4-G3) -> 160492 | AF3: =IF(OR(H4=""),"",H4-H3) -> 5524 | AG3: =IF(OR(AA3="",AB3="",AC3=""),"",AA3+AB3+AC3+AD3-AE3) -> 136 | AH3: =IF(OR(I4=""),"",I4-I3) -> 160492 | AI3: =IF(OR(J4=""),"",J4-J3) -> 5524 | AJ3: =IF(OR(AH3="",AI3=""),"",AH3-AI3) -> 154968 | AK3: 2875 | AL3: =IF(OR(L4="",M4=""),"",ROUND((L4-L3+M4-M3)*1200,0)) -> 11868 | AM3: =IF(OR(N4=""),"",(ROUND((N4-N3)*2,0))) -> 37 | AN3: =IF(OR(S3=""),"",ROUND(S3*7.1,0)) -> 4544 | AO3: =IF(OR(T3=""),"",ROUND(T3*2.4,0)) -> 1488 | AP3: 3250 | AQ3: =IF(OR($AJ3=""),"",ROUND(AL3/$AJ3*1000,1)) -> 76.6 | AR3: =IF(OR($AJ3=""),"",ROUND(AM3/$AJ3*1000,2)) -> 0.24 | AS3: =IF(OR($AJ3=""),"",ROUND(AN3/$AJ3*1000,1)) -> 29.3 | AT3: =IF(OR($AJ3=""),"",ROUND(AO3/$AJ3*1000,2)) -> 9.6
A4: =A3+1 -> 43863 | B4: 陈智娇 | C4: 13876744 | D4: 16590252 | E4: 15386000 | F4: 15359000 | G4: 210265967 | H4: 145234 | I4: 210265967 | J4: 145234 | L4: 4246.2 | M4: 3450 | N4: 71967.81 | Q4: 17.1 | R4: 晴 | S4: 660 | T4: 650 | U4: 6834 | V4: 5412 | W4: 4.6 | X4: 3.56 | Y4: 1440 | AA4: =IF(OR(C5=""),"",C5-C4) -> 36733 | AB4: =IF(OR(D5=""),"",D5-D4) -> 39255 | AC4: =IF(OR(E5=""),"",E5-E4) -> 42000 | AD4: =IF(OR(F5=""),"",F5-F4) -> 41000 | AE4: =IF(OR(G5=""),"",G5-G4) -> 151879 | AF4: =IF(OR(H5=""),"",H5-H4) -> 5408 | AG4: =IF(OR(AA4="",AB4="",AC4=""),"",AA4+AB4+AC4+AD4-AE4) -> 7109 | AH4: =IF(OR(I5=""),"",I5-I4) -> 151879 | AI4: =IF(OR(J5=""),"",J5-J4) -> 5408 | AJ4: =IF(OR(AH4="",AI4=""),"",AH4-AI4) -> 146471 | AK4: 3110 | AL4: =IF(OR(L5="",M5=""),"",ROUND((L5-L4+M5-M4)*1200,0)) -> 12228 | AM4: =IF(OR(N5=""),"",(ROUND((N5-N4)*2,0))) -> 36 | AN4: =IF(OR(S4=""),"",ROUND(S4*7.1,0)) -> 4686 | AO4: =IF(OR(T4=""),"",ROUND(T4*2.4,0)) -> 1560 | AP4: 2980 | AQ4: =IF(OR($AJ4=""),"",ROUND(AL4/$AJ4*1000,1)) -> 83.5 | AR4: =IF(OR($AJ4=""),"",ROUND(AM4/$AJ4*1000,2)) -> 0.25 | AS4: =IF(OR($AJ4=""),"",ROUND(AN4/$AJ4*1000,1)) -> 32 | AT4: =IF(OR($AJ4=""),"",ROUND(AO4/$AJ4*1000,2)) -> 10.65
A5: =A4+1 -> 43864 | B5: 陈智娇 | C5: 13913477 | D5: 16629507 | E5: 15428000 | F5: 15400000 | G5: 210417846 | H5: 150642 | I5: 210417846 | J5: 150642 | L5: 4246.2 | M5: 3460.19 | N5: 71985.73 | Q5: 16.5 | R5: 晴 | S5: 590 | T5: 570 | U5: 6678 | V5: 5514 | W5: 4.8 | X5: 3.31 | Y5: 1440 | AA5: =IF(OR(C6=""),"",C6-C5) -> 33634 | AB5: =IF(OR(D6=""),"",D6-D5) -> 36139 | AC5: =IF(OR(E6=""),"",E6-E5) -> 38000 | AD5: =IF(OR(F6=""),"",F6-F5) -> 38000 | AE5: =IF(OR(G6=""),"",G6-G5) -> 143023 | AF5: =IF(OR(H6=""),"",H6-H5) -> 5477 | AG5: =IF(OR(AA5="",AB5="",AC5=""),"",AA5+AB5+AC5+AD5-AE5) -> 2750 | AH5: =IF(OR(I6=""),"",I6-I5) -> 143023 | AI5: =IF(OR(J6=""),"",J6-J5) -> 5477 | AJ5: =IF(OR(AH5="",AI5=""),"",AH5-AI5) -> 137546 | AK5: 2805 | AL5: =IF(OR(L6="",M6=""),"",ROUND((L6-L5+M6-M5)*1200,0)) -> 12504 | AM5: =IF(OR(N6=""),"",(ROUND((N6-N5)*2,0))) -> 49 | AN5: =IF(OR(S5=""),"",ROUND(S5*7.1,0)) -> 4189 | AO5: =IF(OR(T5=""),"",ROUND(T5*2.4,0)) -> 1368 | AP5: 3030 | AQ5: =IF(OR($AJ5=""),"",ROUND(AL5/$AJ5*1000,1)) -> 90.9 | AR5: =IF(OR($AJ5=""),"",ROUND(AM5/$AJ5*1000,2)) -> 0.36 | AS5: =IF(OR($AJ5=""),"",ROUND(AN5/$AJ5*1000,1)) -> 30.5 | AT5: =IF(OR($AJ5=""),"",ROUND(AO5/$AJ5*1000,2)) -> 9.95
A6: =A5+1 -> 43865 | B6: 陈智娇 | C6: 13947111 | D6: 16665646 | E6: 15466000 | F6: 15438000 | G6: 210560869 | H6: 156119 | I6: 210560869 | J6: 156119 | L6: 4246.2 | M6: 3470.61 | N6: 72010.09 | Q6: 18.6 | R6: 晴 | S6: 470 | T6: 460 | U6: 6801 | V6: 3456 | W6: 4.5 | X6: 2.96 | Y6: 1320 | AA6: =IF(OR(C7=""),"",C7-C6) -> 31673 | AB6: =IF(OR(D7=""),"",D7-D6) -> 33883 | AC6: =IF(OR(E7=""),"",E7-E6) -> 40000 | AD6: =IF(OR(F7=""),"",F7-F6) -> 40000 | AE6: =IF(OR(G7=""),"",G7-G6) -> 143235 | AF6: =IF(OR(H7=""),"",H7-H6) -> 5377 | AG6: =IF(OR(AA6="",AB6="",AC6=""),"",AA6+AB6+AC6+AD6-AE6) -> 2321 | AH6: =IF(OR(I7=""),"",I7-I6) -> 143235 | AI6: =IF(OR(J7=""),"",J7-J6) -> 5377 | AJ6: =IF(OR(AH6="",AI6=""),"",AH6-AI6) -> 137858 | AK6: 3300 | AL6: =IF(OR(L7="",M7=""),"",ROUND((L7-L6+M7-M6)*1200,0)) -> 12900 | AM6: =IF(OR(N7=""),"",(ROUND((N7-N6)*2,0))) -> 48 | AN6: =IF(OR(S6=""),"",ROUND(S6*7.1,0)) -> 3337 | AO6: =IF(OR(T6=""),"",ROUND(T6*2.4,0)) -> 1104 | AP6: 2560 | AQ6: =IF(OR($AJ6=""),"",ROUND(AL6/$AJ6*1000,1)) -> 93.6 | AR6: =IF(OR($AJ6=""),"",ROUND(AM6/$AJ6*1000,2)) -> 0.35 | AS6: =IF(OR($AJ6=""),"",ROUND(AN6/$AJ6*1000,1)) -> 24.2 | AT6: =IF(OR($AJ6=""),"",ROUND(AO6/$AJ6*1000,2)) -> 8.01
A7: =A6+1 -> 43866 | B7: 陈智娇 | C7: 13978784 | D7: 16699529 | E7: 15506000 | F7: 15478000 | G7: 210704104 | H7: 161496 | I7: 210704104 | J7: 161496 | L7: 4246.2 | M7: 3481.36 | N7: 72034.19 | Q7: 16 | R7: 雨 | S7: 340 | T7: 320 | U7: 6506 | V7: 3435 | W7: 4.12 | X7: 2.69 | Y7: 1320 | AA7: =IF(OR(C8=""),"",C8-C7) -> 27921 | AB7: =IF(OR(D8=""),"",D8-D7) -> 30199 | AC7: =IF(OR(E8=""),"",E8-E7) -> 36000 | AD7: =IF(OR(F8=""),"",F8-F7) -> 37000 | AE7: =IF(OR(G8=""),"",G8-G7) -> 128783 | AF7: =IF(OR(H8=""),"",H8-H7) -> 5455 | AG7: =IF(OR(AA7="",AB7="",AC7=""),"",AA7+AB7+AC7+AD7-AE7) -> 2337 | AH7: =IF(OR(I8=""),"",I8-I7) -> 128783 | AI7: =IF(OR(J8=""),"",J8-J7) -> 5455 | AJ7: =IF(OR(AH7="",AI7=""),"",AH7-AI7) -> 123328 | AK7: 3820 | AL7: =IF(OR(L8="",M8=""),"",ROUND((L8-L7+M8-M7)*1200,0)) -> 13104 | AM7: =IF(OR(N8=""),"",(ROUND((N8-N7)*2,0))) -> 50 | AN7: =IF(OR(S7=""),"",ROUND(S7*7.1,0)) -> 2414 | AO7: =IF(OR(T7=""),"",ROUND(T7*2.4,0)) -> 768 | AP7: 2980 | AQ7: =IF(OR($AJ7=""),"",ROUND(AL7/$AJ7*1000,1)) -> 106.3 | AR7: =IF(OR($AJ7=""),"",ROUND(AM7/$AJ7*1000,2)) -> 0.41 | AS7: =IF(OR($AJ7=""),"",ROUND(AN7/$AJ7*1000,1)) -> 19.6 | AT7: =IF(OR($AJ7=""),"",ROUND(AO7/$AJ7*1000,2)) -> 6.23
A8: =A7+1 -> 43867 | B8: 张亚光 | C8: 14006705 | D8: 16729728 | E8: 15542000 | F8: 15515000 | G8: 210832887 | H8: 166951 | I8: 210832887 | J8: 166951 | L8: 4246.2 | M8: 3492.28 | N8: 72059.13 | Q8: 16.7 | R8: 晴 | S8: 480 | T8: 460 | U8: 6342 | V8: 271 | W8: 4.58 | X8: 2.23 | Y8: 1320 | AA8: =IF(OR(C9=""),"",C9-C8) -> 27276 | AB8: =IF(OR(D9=""),"",D9-D8) -> 29658 | AC8: =IF(OR(E9=""),"",E9-E8) -> 34000 | AD8: =IF(OR(F9=""),"",F9-F8) -> 33000 | AE8: =IF(OR(G9=""),"",G9-G8) -> 95690 | AF8: =IF(OR(H9=""),"",H9-H8) -> 3934 | AG8: =IF(OR(AA8="",AB8="",AC8=""),"",AA8+AB8+AC8+AD8-AE8) -> 28244 | AH8: =IF(OR(I9=""),"",I9-I8) -> 95690 | AI8: =IF(OR(J9=""),"",J9-J8) -> 3934 | AJ8: =IF(OR(AH8="",AI8=""),"",AH8-AI8) -> 91756 | AK8: 3960 | AL8: =IF(OR(L9="",M9=""),"",ROUND((L9-L8+M9-M8)*1200,0)) -> 11196 | AM8: =IF(OR(N9=""),"",(ROUND((N9-N8)*2,0))) -> 40 | AN8: =IF(OR(S8=""),"",ROUND(S8*7.1,0)) -> 3408 | AO8: =IF(OR(T8=""),"",ROUND(T8*2.4,0)) -> 1104 | AP8: 2520 | AQ8: =IF(OR($AJ8=""),"",ROUND(AL8/$AJ8*1000,1)) -> 122 | AR8: =IF(OR($AJ8=""),"",ROUND(AM8/$AJ8*1000,2)) -> 0.44 | AS8: =IF(OR($AJ8=""),"",ROUND(AN8/$AJ8*1000,1)) -> 37.1 | AT8: =IF(OR($AJ8=""),"",ROUND(AO8/$AJ8*1000,2)) -> 12.03
A9: =A8+1 -> 43868 | B9: 陈智娇 | C9: 14033981 | D9: 16759386 | E9: 15576000 | F9: 15548000 | G9: 210928577 | H9: 170885 | I9: 210928577 | J9: 170885 | L9: 4246.2 | M9: 3501.61 | N9: 72079.37 | Q9: 16.8 | R9: 晴 | S9: 550 | T9: 560 | U9: 5689 | V9: 2860 | W9: 4.78 | X9: 2.4 | Y9: 954 | AA9: =IF(OR(C10=""),"",C10-C9) -> 27772 | AB9: =IF(OR(D10=""),"",D10-D9) -> 31164 | AC9: =IF(OR(E10=""),"",E10-E9) -> 29000 | AD9: =IF(OR(F10=""),"",F10-F9) -> 30000 | AE9: =IF(OR(G10=""),"",G10-G9) -> 116348 | AF9: =IF(OR(H10=""),"",H10-H9) -> 5448 | AG9: =IF(OR(AA9="",AB9="",AC9=""),"",AA9+AB9+AC9+AD9-AE9) -> 1588 | AH9: =IF(OR(I10=""),"",I10-I9) -> 116435 | AI9: =IF(OR(J10=""),"",J10-J9) -> 5448 | AJ9: =IF(OR(AH9="",AI9=""),"",AH9-AI9) -> 110987 | AK9: 2970 | AL9: =IF(OR(L10="",M10=""),"",ROUND((L10-L9+M10-M9)*1200,0)) -> 15108 | AM9: =IF(OR(N10=""),"",(ROUND((N10-N9)*2,0))) -> 50 | AN9: =IF(OR(S9=""),"",ROUND(S9*7.1,0)) -> 3905 | AO9: =IF(OR(T9=""),"",ROUND(T9*2.4,0)) -> 1344 | AP9: 2680 | AQ9: =IF(OR($AJ9=""),"",ROUND(AL9/$AJ9*1000,1)) -> 136.1 | AR9: =IF(OR($AJ9=""),"",ROUND(AM9/$AJ9*1000,2)) -> 0.45 | AS9: =IF(OR($AJ9=""),"",ROUND(AN9/$AJ9*1000,1)) -> 35.2 | AT9: =IF(OR($AJ9=""),"",ROUND(AO9/$AJ9*1000,2)) -> 12.11
A10: =A9+1 -> 43869 | B10: 陈智娇 | C10: 14061753 | D10: 16790550 | E10: 15605000 | F10: 15578000 | G10: 211044925 | H10: 176333 | I10: 211045012 | J10: 176333 | L10: 4246.2 | M10: 3514.2 | N10: 72104.4 | Q10: 17.7 | R10: 阴 | S10: 480 | T10: 500 | U10: 5615 | V10: 1845 | W10: 3.4 | X10: 2.12 | Y10: 101 | AA10: =IF(OR(C11=""),"",C11-C10) -> 24808 | AB10: =IF(OR(D11=""),"",D11-D10) -> 28213 | AC10: =IF(OR(E11=""),"",E11-E10) -> 27000 | AD10: =IF(OR(F11=""),"",F11-F10) -> 26000 | AE10: =IF(OR(G11=""),"",G11-G10) -> 102418 | AF10: =IF(OR(H11=""),"",H11-H10) -> 5413 | AG10: =IF(OR(AA10="",AB10="",AC10=""),"",AA10+AB10+AC10+AD10-AE10) -> 3603 | AH10: =IF(OR(I11=""),"",I11-I10) -> 102616 | AI10: =IF(OR(J11=""),"",J11-J10) -> 5413 | AJ10: =IF(OR(AH10="",AI10=""),"",AH10-AI10) -> 97203 | AK10: 2640 | AL10: =IF(OR(L11="",M11=""),"",ROUND((L11-L10+M11-M10)*1200,0)) -> 15024 | AM10: =IF(OR(N11=""),"",(ROUND((N11-N10)*2,0))) -> 50 | AN10: =IF(OR(S10=""),"",ROUND(S10*7.1,0)) -> 3408 | AO10: =IF(OR(T10=""),"",ROUND(T10*2.4,0)) -> 1200 | AP10: 2120 | AQ10: =IF(OR($AJ10=""),"",ROUND(AL10/$AJ10*1000,1)) -> 154.6 | AR10: =IF(OR($AJ10=""),"",ROUND(AM10/$AJ10*1000,2)) -> 0.51 | AS10: =IF(OR($AJ10=""),"",ROUND(AN10/$AJ10*1000,1)) -> 35.1 | AT10: =IF(OR($AJ10=""),"",ROUND(AO10/$AJ10*1000,2)) -> 12.35
A11: =A10+1 -> 43870 | B11: 陈智娇 | C11: 14086561 | D11: 16818763 | E11: 15632000 | F11: 15604000 | G11: 211147343 | H11: 181746 | I11: 211147628 | J11: 181746 | L11: 4246.2 | M11: 3526.72 | N11: 72129.43 | Q11: 16.3 | R11: 晴 | S11: 230 | T11: 250 | U11: 5789 | V11: 612 | W11: 3.6 | X11: 2.1 | Y11: 356 | AA11: =IF(OR(C12=""),"",C12-C11) -> 23451 | AB11: =IF(OR(D12=""),"",D12-D11) -> 26347 | AC11: =IF(OR(E12=""),"",E12-E11) -> 24000 | AD11: =IF(OR(F12=""),"",F12-F11) -> 24000 | AE11: =IF(OR(G12=""),"",G12-G11) -> 96713 | AF11: =IF(OR(H12=""),"",H12-H11) -> 5496 | AG11: =IF(OR(AA11="",AB11="",AC11=""),"",AA11+AB11+AC11+AD11-AE11) -> 1085 | AH11: =IF(OR(I12=""),"",I12-I11) -> 96415 | AI11: =IF(OR(J12=""),"",J12-J11) -> 5496 | AJ11: =IF(OR(AH11="",AI11=""),"",AH11-AI11) -> 90919 | AK11: 2400 | AL11: =IF(OR(L12="",M12=""),"",ROUND((L12-L11+M12-M11)*1200,0)) -> 816 | AM11: =IF(OR(N12=""),"",(ROUND((N12-N11)*2,0))) -> 3 | AN11: =IF(OR(S11=""),"",ROUND(S11*7.1,0)) -> 1633 | AO11: =IF(OR(T11=""),"",ROUND(T11*2.4,0)) -> 600 | AP11: 2010 | AQ11: =IF(OR($AJ11=""),"",ROUND(AL11/$AJ11*1000,1)) -> 9 | AR11: =IF(OR($AJ11=""),"",ROUND(AM11/$AJ11*1000,2)) -> 0.03 | AS11: =IF(OR($AJ11=""),"",ROUND(AN11/$AJ11*1000,1)) -> 18 | AT11: =IF(OR($AJ11=""),"",ROUND(AO11/$AJ11*1000,2)) -> 6.6
A12: =A11+1 -> 43871 | B12: 陈智娇 | C12: 14110012 | D12: 16845110 | E12: 15656000 | F12: 15628000 | G12: 211244056 | H12: 187242 | I12: 211244043 | J12: 187242 | L12: 4246.2 | M12: 3527.4 | N12: 72130.8 | Q12: 18.4 | R12: 晴 | S12: 230 | T12: 250 | U12: 5524 | V12: 4368 | W12: 4.68 | X12: 2.63 | Y12: 1119 | AA12: =IF(OR(C13=""),"",C13-C12) -> 24818 | AB12: =IF(OR(D13=""),"",D13-D12) -> 27827 | AC12: =IF(OR(E13=""),"",E13-E12) -> 27000 | AD12: =IF(OR(F13=""),"",F13-F12) -> 26000 | AE12: =IF(OR(G13=""),"",G13-G12) -> 97827 | AF12: =IF(OR(H13=""),"",H13-H12) -> 5290 | AG12: =IF(OR(AA12="",AB12="",AC12=""),"",AA12+AB12+AC12+AD12-AE12) -> 7818 | AH12: =IF(OR(I13=""),"",I13-I12) -> 101470 | AI12: =IF(OR(J13=""),"",J13-J12) -> 5290 | AJ12: =IF(OR(AH12="",AI12=""),"",AH12-AI12) -> 96180 | AK12: 2500 | AL12: =IF(OR(L13="",M13=""),"",ROUND((L13-L12+M13-M12)*1200,0)) -> 0 | AM12: =IF(OR(N13=""),"",(ROUND((N13-N12)*2,0))) -> 0 | AN12: =IF(OR(S12=""),"",ROUND(S12*7.1,0)) -> 1633 | AO12: =IF(OR(T12=""),"",ROUND(T12*2.4,0)) -> 600 | AP12: 1970 | AQ12: =IF(OR($AJ12=""),"",ROUND(AL12/$AJ12*1000,1)) -> 0 | AR12: =IF(OR($AJ12=""),"",ROUND(AM12/$AJ12*1000,2)) -> 0 | AS12: =IF(OR($AJ12=""),"",ROUND(AN12/$AJ12*1000,1)) -> 17 | AT12: =IF(OR($AJ12=""),"",ROUND(AO12/$AJ12*1000,2)) -> 6.24
A13: =A12+1 -> 43872 | B13: 胡叶青 | C13: 14134830 | D13: 16872937 | E13: 15683000 | F13: 15654000 | G13: 211341883 | H13: 192532 | I13: 211345513 | J13: 192532 | L13: 4246.2 | M13: 3527.4 | N13: 72130.8 | Q13: 16.8 | R13: 阴 | S13: 160 | T13: 180 | U13: 5301 | V13: 2567 | W13: 4.25 | X13: 2.47 | Y13: 804 | AA13: =IF(OR(C14=""),"",C14-C13) -> 25656 | AB13: =IF(OR(D14=""),"",D14-D13) -> 28796 | AC13: =IF(OR(E14=""),"",E14-E13) -> 27000 | AD13: =IF(OR(F14=""),"",F14-F13) -> 28000 | AE13: =IF(OR(G14=""),"",G14-G13) -> 110314 | AF13: =IF(OR(H14=""),"",H14-H13) -> 5631 | AG13: =IF(OR(AA13="",AB13="",AC13=""),"",AA13+AB13+AC13+AD13-AE13) -> -862 | AH13: =IF(OR(I14=""),"",I14-I13) -> 106605 | AI13: =IF(OR(J14=""),"",J14-J13) -> 5631 | AJ13: =IF(OR(AH13="",AI13=""),"",AH13-AI13) -> 100974 | AK13: 2500 | AL13: =IF(OR(L14="",M14=""),"",ROUND((L14-L13+M14-M13)*1200,0)) -> 0 | AM13: =IF(OR(N14=""),"",(ROUND((N14-N13)*2,0))) -> 0 | AN13: =IF(OR(S13=""),"",ROUND(S13*7.1,0)) -> 1136 | AO13: =IF(OR(T13=""),"",ROUND(T13*2.4,0)) -> 432 | AP13: 2070 | AQ13: =IF(OR($AJ13=""),"",ROUND(AL13/$AJ13*1000,1)) -> 0 | AR13: =IF(OR($AJ13=""),"",ROUND(AM13/$AJ13*1000,2)) -> 0 | AS13: =IF(OR($AJ13=""),"",ROUND(AN13/$AJ13*1000,1)) -> 11.3 | AT13: =IF(OR($AJ13=""),"",ROUND(AO13/$AJ13*1000,2)) -> 4.28
A14: =A13+1 -> 43873 | B14: 潘汝鑫 | C14: 14160486 | D14: 16901733 | E14: 15710000 | F14: 15682000 | G14: 211452197 | H14: 198163 | I14: 211452118 | J14: 198163 | L14: 4246.2 | M14: 3527.4 | N14: 72130.8 | Q14: 16.5 | R14: 阴 | S14: 200 | T14: 210 | U14: 3255 | V14: 2226 | W14: 2.44 | X14: 2.39 | Y14: 182 | AA14: =IF(OR(C15=""),"",C15-C14) -> 15050 | AB14: =IF(OR(D15=""),"",D15-D14) -> 16710 | AC14: =IF(OR(E15=""),"",E15-E14) -> 14000 | AD14: =IF(OR(F15=""),"",F15-F14) -> 13000 | AE14: =IF(OR(G15=""),"",G15-G14) -> 56256 | AF14: =IF(OR(H15=""),"",H15-H14) -> 5440 | AG14: =IF(OR(AA14="",AB14="",AC14=""),"",AA14+AB14+AC14+AD14-AE14) -> 2504 | AH14: =IF(OR(I15=""),"",I15-I14) -> 56330 | AI14: =IF(OR(J15=""),"",J15-J14) -> 5440 | AJ14: =IF(OR(AH14="",AI14=""),"",AH14-AI14) -> 50890 | AK14: 4200 | AL14: =IF(OR(L15="",M15=""),"",ROUND((L15-L14+M15-M14)*1200,0)) -> 0 | AM14: =IF(OR(N15=""),"",(ROUND((N15-N14)*2,0))) -> 0 | AN14: =IF(OR(S14=""),"",ROUND(S14*7.1,0)) -> 1420 | AO14: =IF(OR(T14=""),"",ROUND(T14*2.4,0)) -> 504 | AP14: 2290 | AQ14: =IF(OR($AJ14=""),"",ROUND(AL14/$AJ14*1000,1)) -> 0 | AR14: =IF(OR($AJ14=""),"",ROUND(AM14/$AJ14*1000,2)) -> 0 | AS14: =IF(OR($AJ14=""),"",ROUND(AN14/$AJ14*1000,1)) -> 27.9 | AT14: =IF(OR($AJ14=""),"",ROUND(AO14/$AJ14*1000,2)) -> 9.9
A15: =A14+1 -> 43874 | B15: 易萍 | C15: 14175536 | D15: 16918443 | E15: 15724000 | F15: 15695000 | G15: 211508453 | H15: 203603 | I15: 211508448 | J15: 203603 | L15: 4246.2 | M15: 3527.4 | N15: 72130.8 | Q15: 16.9 | R15: 阴 | S15: 150 | T15: 170 | U15: 3458 | V15: 517 | W15: 4.21 | X15: 2.2 | Y15: 1156 | AA15: =IF(OR(C16=""),"",C16-C15) -> 18893 | AB15: =IF(OR(D16=""),"",D16-D15) -> 20908 | AC15: =IF(OR(E16=""),"",E16-E15) -> 19000 | AD15: =IF(OR(F16=""),"",F16-F15) -> 19000 | AE15: =IF(OR(G16=""),"",G16-G15) -> 74095 | AF15: =IF(OR(H16=""),"",H16-H15) -> 5389 | AG15: =IF(OR(AA15="",AB15="",AC15=""),"",AA15+AB15+AC15+AD15-AE15) -> 3706 | AH15: =IF(OR(I16=""),"",I16-I15) -> 75145 | AI15: =IF(OR(J16=""),"",J16-J15) -> 5389 | AJ15: =IF(OR(AH15="",AI15=""),"",AH15-AI15) -> 69756 | AK15: 3500 | AL15: =IF(OR(L16="",M16=""),"",ROUND((L16-L15+M16-M15)*1200,0)) -> 0 | AM15: =IF(OR(N16=""),"",(ROUND((N16-N15)*2,0))) -> 0 | AN15: =IF(OR(S15=""),"",ROUND(S15*7.1,0)) -> 1065 | AO15: =IF(OR(T15=""),"",ROUND(T15*2.4,0)) -> 408 | AP15: 3250 | AQ15: =IF(OR($AJ15=""),"",ROUND(AL15/$AJ15*1000,1)) -> 0 | AR15: =IF(OR($AJ15=""),"",ROUND(AM15/$AJ15*1000,2)) -> 0 | AS15: =IF(OR($AJ15=""),"",ROUND(AN15/$AJ15*1000,1)) -> 15.3 | AT15: =IF(OR($AJ15=""),"",ROUND(AO15/$AJ15*1000,2)) -> 5.85
... A30: =A29+1 -> 43889 | B30: 潘汝鑫 | C30: 14629830 | D30: 17436753 | E30: 16190000 | F30: 16163000 | G30: 213204232 | H30: 285476 | I30: 213203941 | J30: 285476 | L30: 4246.2 | M30: 3584.22 | N30: 72303.7 | Q30: 18.2 | R30: 阴 | S30: 410 | T30: 430 | U30: 9102 | V30: 7012 | W30: 5.77 | X30: 4.75 | Y30: 1437 | AA30: =IF(OR(C31=""),"",C31-C30) -> 49376 | AB30: =IF(OR(D31=""),"",D31-D30) -> 58035 | AC30: =IF(OR(E31=""),"",E31-E30) -> 54000 | AD30: =IF(OR(F31=""),"",F31-F30) -> 54000 | AE30: =IF(OR(G31=""),"",G31-G30) -> 209964 | AF30: =IF(OR(H31=""),"",H31-H30) -> 5429 | AG30: =IF(OR(AA30="",AB30="",AC30=""),"",AA30+AB30+AC30+AD30-AE30) -> 5447 | AH30: =IF(OR(I31=""),"",I31-I30) -> 211120 | AI30: =IF(OR(J31=""),"",J31-J30) -> 5429 | AJ30: =IF(OR(AH30="",AI30=""),"",AH30-AI30) -> 205691 | AK30: 4400 | AL30: =IF(OR(L31="",M31=""),"",ROUND((L31-L30+M31-M30)*1200,0)) -> 2856 | AM30: =IF(OR(N31=""),"",(ROUND((N31-N30)*2,0))) -> 15 | AN30: =IF(OR(S30=""),"",ROUND(S30*7.1,0)) -> 2911 | AO30: =IF(OR(T30=""),"",ROUND(T30*2.4,0)) -> 1032 | AP30: 2600 | AQ30: =IF(OR($AJ30=""),"",ROUND(AL30/$AJ30*1000,1)) -> 13.9 | AR30: =IF(OR($AJ30=""),"",ROUND(AM30/$AJ30*1000,2)) -> 0.07 | AS30: =IF(OR($AJ30=""),"",ROUND(AN30/$AJ30*1000,1)) -> 14.2 | AT30: =IF(OR($AJ30=""),"",ROUND(AO30/$AJ30*1000,2)) -> 5.02
A31: 44256 | B31: 陈智娇 | C31: 14679206 | D31: 17494788 | E31: 16244000 | F31: 16217000 | G31: 213414196 | H31: 290905 | I31: 213415061 | J31: 290905 | L31: 4246.2 | M31: 3586.6 | N31: 72311.36 | Q31: 17.3 | R31: 雨 | AA31: =IF(OR(C32=""),"",C32-C31) | AB31: =IF(OR(D32=""),"",D32-D31) | AC31: =IF(OR(E32=""),"",E32-E31) | AD31: =IF(OR(F32=""),"",F32-F31) | AE31: =IF(OR(G32=""),"",G32-G31) | AF31: =IF(OR(H32=""),"",H32-H31) | AG31: =IF(OR(AA31="",AB31="",AC31=""),"",AA31+AB31+AC31+AD31-AE31) | AH31: =IF(OR(I32=""),"",I32-I31) | AI31: =IF(OR(J32=""),"",J32-J31) | AJ31: =IF(OR(AH31="",AI31=""),"",AH31-AI31) | AK31: =IF(K31="","",K32-K31) | AL31: =IF(OR(L32="",M32=""),"",ROUND((L32-L31+M32-M31)*1200,0)) | AM31: =IF(OR(N32=""),"",(ROUND((N32-N31)*2,0))) | AN31: =IF(OR(S31=""),"",ROUND(S31*7.1,0)) | AO31: =IF(OR(T31=""),"",ROUND(T31*2.4,0)) | AQ31: =IF(OR($AJ31=""),"",ROUND(AL31/$AJ31*1000,1)) | AR31: =IF(OR($AJ31=""),"",ROUND(AM31/$AJ31*1000,2)) | AS31: =IF(OR($AJ31=""),"",ROUND(AN31/$AJ31*1000,1)) | AT31: =IF(OR($AJ31=""),"",ROUND(AO31/$AJ31*1000,2))
AA32: =IF(OR(C33=""),"",C33-C32) | AB32: =IF(OR(D33=""),"",D33-D32) | AC32: =IF(OR(E33=""),"",E33-E32) | AD32: =IF(OR(F33=""),"",F33-F32) | AE32: =IF(OR(G33=""),"",G33-G32) | AF32: =IF(OR(H33=""),"",H33-H32) | AG32: =IF(OR(AA32="",AB32="",AC32=""),"",AA32+AB32+AC32+AD32-AE32) | AH32: =IF(OR(I33=""),"",I33-I32) | AI32: =IF(OR(J33=""),"",J33-J32) | AJ32: =IF(OR(AH32="",AI32=""),"",AH32-AI32) | AK32: =IF(K32="","",K33-K32) | AL32: =IF(OR(L33="",M33=""),"",ROUND((L33-L32+M33-M32)*1200,0)) | AM32: =IF(OR(N33=""),"",(ROUND((N33-N32)*2,0))) | AN32: =IF(OR(S32=""),"",ROUND(S32*7.1,0)) | AO32: =IF(OR(T32=""),"",ROUND(T32*2.4,0)) | AQ32: =IF(OR($AJ32=""),"",ROUND(AL32/$AJ32*1000,1)) | AR32: =IF(OR($AJ32=""),"",ROUND(AM32/$AJ32*1000,2)) | AS32: =IF(OR($AJ32=""),"",ROUND(AN32/$AJ32*1000,1)) | AT32: =IF(OR($AJ32=""),"",ROUND(AO32/$AJ32*1000,2))
AA35: =IF(OR(C36=""),"",C36-C35) | AB35: =IF(OR(D36=""),"",D36-D35) | AC35: =IF(OR(E36=""),"",E36-E35) | AD35: =IF(OR(F36=""),"",F36-F35) | AE35: =IF(OR(G36=""),"",G36-G35) | AF35: =IF(OR(H36=""),"",H36-H35) | AG35: =IF(OR(AA35="",AB35="",AC35=""),"",AA35+AB35+AC35+AD35-AE35) | AH35: =SUM(AH3:AH33) -> 3309586 | AI35: =SUM(AI3:AI33) -> 151195 | AJ35: =SUM(AJ3:AJ33) -> 3158391 | AK35: =SUM(AK3:AK33) -> 76240 | AL35: =SUM(AL3:AL33) -> 175788 | AM35: =SUM(AM3:AM33) -> 724 | AN35: =SUM(AN3:AN33) -> 66243 | AO35: =SUM(AO3:AO33) -> 23160 | AQ35: =IF(OR($AJ35=0),"",ROUND(AL35/$AJ35*1000,1)) -> 55.7 | AR35: =IF(OR($AJ35=0),"",ROUND(AM35/$AJ35*1000,2)) -> 0.23 | AS35: =IF(OR($AJ35=0),"",ROUND(AN35/$AJ35*1000,1)) -> 21 | AT35: =IF(OR($AJ35=0),"",ROUND(AO35/$AJ35*1000,2)) -> 7.33

Sheet 3
B2: 记录人 | C2: 一期左进水 流量计读数 | D2: 一期右进水 流量计读数 | E2: 二期左进水 流量计读数 | F2: 二期右进水 流量计读数 | G2: 现场出水 流量计读数 | H2: 现场回用水 读数 | I2: 出水流量计 读数（网站） | J2: 回用水流量 （网站） | K2: 污泥流量 计读数 | L2: PAC2#流量计读数 | M2: PAC3#流量计读数 | N2: PAM流量 计读数 | O2: 盐酸流量 计读数 | P2: 氯酸钠流 量计读数 | Q2: 生反池 水温 | R2: 天气 (阴晴雨) | S2: 盐酸液位 差（CM） | T2: 氯酸钠液位差 差（CM） | U2: 最高流量 m3/h | V2: 最低流量 m3/h | W2: 最高液位 m | X2: 最低液位 m | Y2: 超液位时 间（分） | Z2: 备注 | AA2: 一期左 进水流量 | AB2: 一期右 进水流量 | AC2: 二期左 进水流量 | AD2: 二期右 进水流量 | AE2: 现场出水 流量 | AF2: 现场回用水 流量 | AG2: 进出水 流量差 | AH2: 出水流量（网站） | AI2: 回用水流量（网站） | AJ2: 实际处理量（网站） | AK2: 排泥量 m3 | AL2: PAC量 kg | AM2: PAM量 kg | AN2: 盐酸量 kg | AO2: 氯酸钠量 kg | AP2: 碳源用量 kg | AQ2: PAC单耗 ppm | AR2: PAM单耗 ppm | AS2: 盐酸单耗 ppm | AT2: 氯酸钠单耗 ppm
A3: 43891 | B3: ='2'!B31 -> 陈智娇 | C3: ='2'!C31 -> 14679206 | D3: ='2'!D31 -> 17494788 | E3: ='2'!E31 -> 16244000 | F3: ='2'!F31 -> 16217000 | G3: ='2'!G31 -> 213414196 | H3: ='2'!H31 -> 290905 | I3: ='2'!I31 -> 213415061 | ... R3: ='2'!R31 -> 雨 | S3: 570 | T3: 600 | U3: 9256 | V3: 7120 | W3: 6.55 | X3: 5.25 | Y3: 1435 | AA3: =IF(OR(C4=""),"",C4-C3) -> 48024 | AB3: =IF(OR(D4=""),"",D4-D3) -> 57062 | AC3: =IF(OR(E4=""),"",E4-E3) -> 52000 | AD3: =IF(OR(F4=""),"",F4-F3) -> 52000 | AE3: =IF(OR(G4=""),"",G4-G3) -> 211585 | AF3: =IF(OR(H4=""),"",H4-H3) -> 5573 | AG3: =IF(OR(AA3="",AB3="",AC3=""),"",AA3+AB3+AC3+AD3-AE3) -> -2499 | AH3: =IF(OR(I4=""),"",I4-I3) -> 207629 | AI3: =IF(OR(J4=""),"",J4-J3) -> 5573 | AJ3: =IF(OR(AH3="",AI3=""),"",AH3-AI3) -> 202056 | AK3: 3440 | AL3: =IF(OR(L4="",M4=""),"",ROUND((L4-L3+M4-M3)*1200,0)) -> 4740 | AM3: =IF(OR(N4=""),"",(ROUND((N4-N3)*2,0))) -> 22 | AN3: =IF(OR(S3=""),"",ROUND(S3*7.1,0)) -> 4047 | AO3: =IF(OR(T3=""),"",ROUND(T3*2.4,0)) -> 1440 | AP3: 2600 | AQ3: =IF(OR($AJ3=""),"",ROUND(AL3/$AJ3*1000,1)) -> 23.5 | AR3: =IF(OR($AJ3=""),"",ROUND(AM3/$AJ3*1000,2)) -> 0.11 | AS3: =IF(OR($AJ3=""),"",ROUND(AN3/$AJ3*1000,1)) -> 20 | AT3: =IF(OR($AJ3=""),"",ROUND(AO3/$AJ3*1000,2)) -> 7.13
A4: 43526 | B4: 陈智娇 | C4: 14727230 | D4: 17551850 | E4: 16296000 | F4: 16269000 | G4: 213625781 | H4: 296478 | I4: 213622690 | J4: 296478 | L4: 4246.2 | M4: 3590.55 | N4: 72322.46 | Q4: 16.9 | R4: 晴 | S4: 560 | T4: 580 | U4: 9310 | V4: 7354 | W4: 6.58 | X4: 6.01 | Y4: 1432 | AA4: =IF(OR(C5=""),"",C5-C4) -> 48801 | AB4: =IF(OR(D5=""),"",D5-D4) -> 58335 | AC4: =IF(OR(E5=""),"",E5-E4) -> 53000 | AD4: =IF(OR(F5=""),"",F5-F4) -> 53000 | AE4: =IF(OR(G5=""),"",G5-G4) -> 204784 | AF4: =IF(OR(H5=""),"",H5-H4) -> 5367 | AG4: =IF(OR(AA4="",AB4="",AC4=""),"",AA4+AB4+AC4+AD4-AE4) -> 8352 | AH4: =IF(OR(I5=""),"",I5-I4) -> 207632 | AI4: =IF(OR(J5=""),"",J5-J4) -> 5367 | AJ4: =IF(OR(AH4="",AI4=""),"",AH4-AI4) -> 202265 | AK4: 2800 | AL4: =IF(OR(L5="",M5=""),"",ROUND((L5-L4+M5-M4)*1200,0)) -> 10020 | AM4: =IF(OR(N5=""),"",(ROUND((N5-N4)*2,0))) -> 32 | AN4: =IF(OR(S4=""),"",ROUND(S4*7.1,0)) -> 3976 | AO4: =IF(OR(T4=""),"",ROUND(T4*2.4,0)) -> 1392 | AP4: 2600 | AQ4: =IF(OR($AJ4=""),"",ROUND(AL4/$AJ4*1000,1)) -> 49.5 | AR4: =IF(OR($AJ4=""),"",ROUND(AM4/$AJ4*1000,2)) -> 0.16 | AS4: =IF(OR($AJ4=""),"",ROUND(AN4/$AJ4*1000,1)) -> 19.7 | AT4: =IF(OR($AJ4=""),"",ROUND(AO4/$AJ4*1000,2)) -> 6.88
A5: 43527 | B5: 陈智娇 | C5: 14776031 | D5: 17610185 | E5: 16349000 | F5: 16322000 | G5: 213830565 | H5: 301845 | I5: 213830322 | J5: 301845 | L5: 4246.2 | M5: 3598.9 | N5: 72338.3 | Q5: 17 | R5: 晴 | S5: 540 | T5: 570 | U5: 9456 | V5: 6512 | W5: 6.66 | X5: 4.85 | Y5: 1435 | AA5: =IF(OR(C6=""),"",C6-C5) -> 47779 | AB5: =IF(OR(D6=""),"",D6-D5) -> 56922 | AC5: =IF(OR(E6=""),"",E6-E5) -> 53000 | AD5: =IF(OR(F6=""),"",F6-F5) -> 53000 | AE5: =IF(OR(G6=""),"",G6-G5) -> 205744 | AF5: =IF(OR(H6=""),"",H6-H5) -> 5452 | AG5: =IF(OR(AA5="",AB5="",AC5=""),"",AA5+AB5+AC5+AD5-AE5) -> 4957 | AH5: =IF(OR(I6=""),"",I6-I5) -> 205717 | AI5: =IF(OR(J6=""),"",J6-J5) -> 5452 | AJ5: =IF(OR(AH5="",AI5=""),"",AH5-AI5) -> 200265 | AK5: 2640 | AL5: =IF(OR(L6="",M6=""),"",ROUND((L6-L5+M6-M5)*1200,0)) -> 9864 | AM5: =IF(OR(N6=""),"",(ROUND((N6-N5)*2,0))) -> 34 | AN5: =IF(OR(S5=""),"",ROUND(S5*7.1,0)) -> 3834 | AO5: =IF(OR(T5=""),"",ROUND(T5*2.4,0)) -> 1368 | AP5: 2700 | AQ5: =IF(OR($AJ5=""),"",ROUND(AL5/$AJ5*1000,1)) -> 49.3 | AR5: =IF(OR($AJ5=""),"",ROUND(AM5/$AJ5*1000,2)) -> 0.17 | AS5: =IF(OR($AJ5=""),"",ROUND(AN5/$AJ5*1000,1)) -> 19.1 | AT5: =IF(OR($AJ5=""),"",ROUND(AO5/$AJ5*1000,2)) -> 6.83
A6: 43528 | B6: 陈智娇 | C6: 14823810 | D6: 17667107 | E6: 16402000 | F6: 16375000 | G6: 214036309 | H6: 307297 | I6: 214036039 | J6: 307297 | L6: 4246.2 | M6: 3607.12 | N6: 72355.19 | Q6: 18.7 | R6: 晴 | S6: 410 | T6: 440 | U6: 9255 | V6: 7210 | W6: 6.26 | X6: 3.76 | Y6: 1436 | AA6: =IF(OR(C7=""),"",C7-C6) -> 49429 | AB6: =IF(OR(D7=""),"",D7-D6) -> 58046 | AC6: =IF(OR(E7=""),"",E7-E6) -> 54000 | AD6: =IF(OR(F7=""),"",F7-F6) -> 54000 | AE6: =IF(OR(G7=""),"",G7-G6) -> 206347 | AF6: =IF(OR(H7=""),"",H7-H6) -> 5441 | AG6: =IF(OR(AA6="",AB6="",AC6=""),"",AA6+AB6+AC6+AD6-AE6) -> 9128 | AH6: =IF(OR(I7=""),"",I7-I6) -> 206136 | AI6: =IF(OR(J7=""),"",J7-J6) -> 5441 | AJ6: =IF(OR(AH6="",AI6=""),"",AH6-AI6) -> 200695 | AK6: 2220 | AL6: =IF(OR(L7="",M7=""),"",ROUND((L7-L6+M7-M6)*1200,0)) -> 9768 | AM6: =IF(OR(N7=""),"",(ROUND((N7-N6)*2,0))) -> 33 | AN6: =IF(OR(S6=""),"",ROUND(S6*7.1,0)) -> 2911 | AO6: =IF(OR(T6=""),"",ROUND(T6*2.4,0)) -> 1056 | AP6: 2280 | AQ6: =IF(OR($AJ6=""),"",ROUND(AL6/$AJ6*1000,1)) -> 48.7 | AR6: =IF(OR($AJ6=""),"",ROUND(AM6/$AJ6*1000,2)) -> 0.16 | AS6: =IF(OR($AJ6=""),"",ROUND(AN6/$AJ6*1000,1)) -> 14.5 | AT6: =IF(OR($AJ6=""),"",ROUND(AO6/$AJ6*1000,2)) -> 5.26
A7: 43529 | B7: 陈智娇 | C7: 14873239 | D7: 17725153 | E7: 16456000 | F7: 16429000 | G7: 214242656 | H7: 312738 | I7: 214242175 | J7: 312738 | L7: 4246.2 | M7: 3615.26 | N7: 72371.7 | Q7: 17.8 | R7: 阴 | S7: 230 | T7: 250 | U7: 9268 | V7: 5319 | W7: 4.67 | X7: 3.05 | Y7: 1082 | AA7: =IF(OR(C8=""),"",C8-C7) -> 39126 | AB7: =IF(OR(D8=""),"",D8-D7) -> 43438 | AC7: =IF(OR(E8=""),"",E8-E7) -> 42000 | AD7: =IF(OR(F8=""),"",F8-F7) -> 42000 | AE7: =IF(OR(G8=""),"",G8-G7) -> 120100 | AF7: =IF(OR(H8=""),"",H8-H7) -> 3050 | AG7: =IF(OR(AA7="",AB7="",AC7=""),"",AA7+AB7+AC7+AD7-AE7) -> 46464 | AH7: =IF(OR(I8=""),"",I8-I7) -> 120591 | AI7: =IF(OR(J8=""),"",J8-J7) -> 3050 | AJ7: =IF(OR(AH7="",AI7=""),"",AH7-AI7) -> 117541 | AK7: 3450 | AL7: =IF(OR(L8="",M8=""),"",ROUND((L8-L7+M8-M7)*1200,0)) -> 7248 | AM7: =IF(OR(N8=""),"",(ROUND((N8-N7)*2,0))) -> 23 | AN7: =IF(OR(S7=""),"",ROUND(S7*7.1,0)) -> 1633 | AO7: =IF(OR(T7=""),"",ROUND(T7*2.4,0)) -> 600 | AP7: 2440 | AQ7: =IF(OR($AJ7=""),"",ROUND(AL7/$AJ7*1000,1)) -> 61.7 | AR7: =IF(OR($AJ7=""),"",ROUND(AM7/$AJ7*1000,2)) -> 0.2 | AS7: =IF(OR($AJ7=""),"",ROUND(AN7/$AJ7*1000,1)) -> 13.9 | AT7: =IF(OR($AJ7=""),"",ROUND(AO7/$AJ7*1000,2)) -> 5.1
A8: 43530 | B8: 仇昊 | C8: 14912365 | D8: 17768591 | E8: 16498000 | F8: 16471000 | G8: 214362756 | H8: 315788 | I8: 214362766 | J8: 315788 | L8: 4246.2 | M8: 3621.3 | N8: 72383.22 | Q8: 16.9 | R8: 雨 | S8: 240 | T8: 260 | U8: 9028 | V8: 3752 | W8: 7 | X8: 3.29 | Y8: 1433 | AA8: =IF(OR(C9=""),"",C9-C8) -> 42454 | AB8: =IF(OR(D9=""),"",D9-D8) -> 49839 | AC8: =IF(OR(E9=""),"",E9-E8) -> 46000 | AD8: =IF(OR(F9=""),"",F9-F8) -> 47000 | AE8: =IF(OR(G9=""),"",G9-G8) -> 180237 | AF8: =IF(OR(H9=""),"",H9-H8) -> 5277 | AG8: =IF(OR(AA8="",AB8="",AC8=""),"",AA8+AB8+AC8+AD8-AE8) -> 5056 | AH8: =IF(OR(I9=""),"",I9-I8) -> 180960 | AI8: =IF(OR(J9=""),"",J9-J8) -> 5277 | AJ8: =IF(OR(AH8="",AI8=""),"",AH8-AI8) -> 175683 | AK8: 3000 | AL8: =IF(OR(L9="",M9=""),"",ROUND((L9-L8+M9-M8)*1200,0)) -> 9468 | AM8: =IF(OR(N9=""),"",(ROUND((N9-N8)*2,0))) -> 33 | AN8: =IF(OR(S8=""),"",ROUND(S8*7.1,0)) -> 1704 | AO8: =IF(OR(T8=""),"",ROUND(T8*2.4,0)) -> 624 | AP8: 2480 | AQ8: =IF(OR($AJ8=""),"",ROUND(AL8/$AJ8*1000,1)) -> 53.9 | AR8: =IF(OR($AJ8=""),"",ROUND(AM8/$AJ8*1000,2)) -> 0.19 | AS8: =IF(OR($AJ8=""),"",ROUND(AN8/$AJ8*1000,1)) -> 9.7 | AT8: =IF(OR($AJ8=""),"",ROUND(AO8/$AJ8*1000,2)) -> 3.55
A9: 43531 | B9: 胡叶青 | C9: 14954819 | D9: 17818430 | E9: 16544000 | F9: 16518000 | G9: 214542993 | H9: 321065 | I9: 214543726 | J9: 321065 | L9: 4246.2 | M9: 3629.19 | N9: 72399.9 | Q9: 15.8 | R9: 雨 | S9: 400 | T9: 430 | U9: 8230 | V9: 4152 | W9: 3.98 | X9: 2.56 | Y9: 1148 | AA9: =IF(OR(C10=""),"",C10-C9) -> 40076 | AB9: =IF(OR(D10=""),"",D10-D9) -> 47280 | AC9: =IF(OR(E10=""),"",E10-E9) -> 44000 | AD9: =IF(OR(F10=""),"",F10-F9) -> 42000 | AE9: =IF(OR(G10=""),"",G10-G9) -> 173280 | AF9: =IF(OR(H10=""),"",H10-H9) -> 5523 | AG9: =IF(OR(AA9="",AB9="",AC9=""),"",AA9+AB9+AC9+AD9-AE9) -> 76 | AH9: =IF(OR(I10=""),"",I10-I9) -> 172168 | AI9: =IF(OR(J10=""),"",J10-J9) -> 5523 | AJ9: =IF(OR(AH9="",AI9=""),"",AH9-AI9) -> 166645 | AK9: 2400 | AL9: =IF(OR(L10="",M10=""),"",ROUND((L10-L9+M10-M9)*1200,0)) -> 9516 | AM9: =IF(OR(N10=""),"",(ROUND((N10-N9)*2,0))) -> 35 | AN9: =IF(OR(S9=""),"",ROUND(S9*7.1,0)) -> 2840 | AO9: =IF(OR(T9=""),"",ROUND(T9*2.4,0)) -> 1032 | AP9: 2650 | AQ9: =IF(OR($AJ9=""),"",ROUND(AL9/$AJ9*1000,1)) -> 57.1 | AR9: =IF(OR($AJ9=""),"",ROUND(AM9/$AJ9*1000,2)) -> 0.21 | AS9: =IF(OR($AJ9=""),"",ROUND(AN9/$AJ9*1000,1)) -> 17 | AT9: =IF(OR($AJ9=""),"",ROUND(AO9/$AJ9*1000,2)) -> 6.19
A10: 43532 | B10: 陈智娇 | C10: 14994895 | D10: 17865710 | E10: 16588000 | F10: 16560000 | G10: 214716273 | H10: 326588 | I10: 214715894 | J10: 326588 | L10: 4246.2 | M10: 3637.12 | N10: 72417.33 | Q10: 17.7 | R10: 阴 | S10: 430 | T10: 450 | U10: 7780 | V10: 3125 | W10: 5.2 | X10: 2.27 | Y10: 974 | AA10: =IF(OR(C11=""),"",C11-C10) -> 35551 | AB10: =IF(OR(D11=""),"",D11-D10) -> 41246 | AC10: =IF(OR(E11=""),"",E11-E10) -> 41000 | AD10: =IF(OR(F11=""),"",F11-F10) -> 41350 | AE10: =IF(OR(G11=""),"",G11-G10) -> 147175 | AF10: =IF(OR(H11=""),"",H11-H10) -> 5420 | AG10: =IF(OR(AA10="",AB10="",AC10=""),"",AA10+AB10+AC10+AD10-AE10) -> 11972 | AH10: =IF(OR(I11=""),"",I11-I10) -> 147787 | AI10: =IF(OR(J11=""),"",J11-J10) -> 5420 | AJ10: =IF(OR(AH10="",AI10=""),"",AH10-AI10) -> 142367 | AK10: 2760 | AL10: =IF(OR(L11="",M11=""),"",ROUND((L11-L10+M11-M10)*1200,0)) -> 11316 | AM10: =IF(OR(N11=""),"",(ROUND((N11-N10)*2,0))) -> 33 | AN10: =IF(OR(S10=""),"",ROUND(S10*7.1,0)) -> 3053 | AO10: =IF(OR(T10=""),"",ROUND(T10*2.4,0)) -> 1080 | AP10: 2770 | AQ10: =IF(OR($AJ10=""),"",ROUND(AL10/$AJ10*1000,1)) -> 79.5 | AR10: =IF(OR($AJ10=""),"",ROUND(AM10/$AJ10*1000,2)) -> 0.23 | AS10: =IF(OR($AJ10=""),"",ROUND(AN10/$AJ10*1000,1)) -> 21.4 | AT10: =IF(OR($AJ10=""),"",ROUND(AO10/$AJ10*1000,2)) -> 7.59
A11: 43533 | B11: 陈智娇 | C11: 15030446 | D11: 17906956 | E11: 16629000 | F11: 16601350 | G11: 214863448 | H11: 332008 | I11: 214863681 | J11: 332008 | L11: 4246.2 | M11: 3646.55 | N11: 72433.59 | Q11: 17.3 | R11: 雨 | S11: 450 | T11: 460 | U11: 9215 | V11: 3214 | W11: 6.45 | X11: 2.12 | Y11: 1271 | AA11: =IF(OR(C12=""),"",C12-C11) -> 44536 | AB11: =IF(OR(D12=""),"",D12-D11) -> 54086 | AC11: =IF(OR(E12=""),"",E12-E11) -> 52000 | AD11: =IF(OR(F12=""),"",F12-F11) -> 51650 | AE11: =IF(OR(G12=""),"",G12-G11) -> 202228 | AF11: =IF(OR(H12=""),"",H12-H11) -> 5448 | AG11: =IF(OR(AA11="",AB11="",AC11=""),"",AA11+AB11+AC11+AD11-AE11) -> 44 | AH11: =IF(OR(I12=""),"",I12-I11) -> 202083 | AI11: =IF(OR(J12=""),"",J12-J11) -> 5448 | AJ11: =IF(OR(AH11="",AI11=""),"",AH11-AI11) -> 196635 | AK11: 3150 | AL11: =IF(OR(L12="",M12=""),"",ROUND((L12-L11+M12-M11)*1200,0)) -> 12384 | AM11: =IF(OR(N12=""),"",(ROUND((N12-N11)*2,0))) -> 31 | AN11: =IF(OR(S11=""),"",ROUND(S11*7.1,0)) -> 3195 | AO11: =IF(OR(T11=""),"",ROUND(T11*2.4,0)) -> 1104 | AP11: 2090 | AQ11: =IF(OR($AJ11=""),"",ROUND(AL11/$AJ11*1000,1)) -> 63 | AR11: =IF(OR($AJ11=""),"",ROUND(AM11/$AJ11*1000,2)) -> 0.16 | AS11: =IF(OR($AJ11=""),"",ROUND(AN11/$AJ11*1000,1)) -> 16.2 | AT11: =IF(OR($AJ11=""),"",ROUND(AO11/$AJ11*1000,2)) -> 5.61
A12: 43534 | B12: 陈智娇 | C12: 15074982 | D12: 17961042 | E12: 16681000 | F12: 16653000 | G12: 215065676 | H12: 337456 | I12: 215065764 | J12: 337456 | L12: 4246.2 | M12: 3656.87 | N12: 72449.24 | Q12: 18.3 | R12: 晴 | S12: 420 | T12: 440 | U12: 8052 | V12: 2257 | W12: 6.12 | X12: 2.2 | Y12: 989 | AA12: =IF(OR(C13=""),"",C13-C12) -> 37381 | AB12: =IF(OR(D13=""),"",D13-D12) -> 44938 | AC12: =IF(OR(E13=""),"",E13-E12) -> 45000 | AD12: =IF(OR(F13=""),"",F13-F12) -> 43000 | AE12: =IF(OR(G13=""),"",G13-G12) -> 160003 | AF12: =IF(OR(H13=""),"",H13-H12) -> 5412 | AG12: =IF(OR(AA12="",AB12="",AC12=""),"",AA12+AB12+AC12+AD12-AE12) -> 10316 | AH12: =IF(OR(I13=""),"",I13-I12) -> 161004 | AI12: =IF(OR(J13=""),"",J13-J12) -> 5412 | AJ12: =IF(OR(AH12="",AI12=""),"",AH12-AI12) -> 155592 | AK12: 3465 | AL12: =IF(OR(L13="",M13=""),"",ROUND((L13-L12+M13-M12)*1200,0)) -> 12444 | AM12: =IF(OR(N13=""),"",(ROUND((N13-N12)*2,0))) -> 31 | AN12: =IF(OR(S12=""),"",ROUND(S12*7.1,0)) -> 2982 | AO12: =IF(OR(T12=""),"",ROUND(T12*2.4,0)) -> 1056 | AP12: 2290 | AQ12: =IF(OR($AJ12=""),"",ROUND(AL12/$AJ12*1000,1)) -> 80 | AR12: =IF(OR($AJ12=""),"",ROUND(AM12/$AJ12*1000,2)) -> 0.2 | AS12: =IF(OR($AJ12=""),"",ROUND(AN12/$AJ12*1000,1)) -> 19.2 | AT12: =IF(OR($AJ12=""),"",ROUND(AO12/$AJ12*1000,2)) -> 6.79
