Workbook

Sheet 1
B2: 高配电 表计数 | C2: 一次提升 | H2: 二次提升 | L2: 三次提升 | P2: 高压鼓风机 | U2: 提标 电表 | V2: 脱水 电表 | W2: 旧除臭 电表 | X2: 新除臭电表 | Z2: 除臭 总电表 | AA2: 旧除臭 水表 | AB2: 新除臭 水表 | AC2: 除臭 总水表 | AD2: 实际处 理水量 | AE2: 一次提升用电 | AK2: 二次提升 | AP2: 三次提升 | AU2: 高压鼓风机 | BA2: 提标电量 | BB2: 脱水电量 | BC2: 除臭电量 | BD2: 其他用电量 | BE2: 总电量 | BF2: 除臭水量 | BG2: 总单耗 | BH2: 一次提 升单耗 | BI2: 二次提 升单耗 | BJ2: 三次提 升单耗 | BK2: 风机 单耗 | BL2: 提标 总单耗 | BM2: 脱水 单耗 | BN2: 除臭 单耗 | BO2: 其他 单耗
C3: 1#泵 | D3: 2#泵 | E3: 3#泵 | F3: 4#泵 | G3: 5#泵 | H3: 1#泵 | I3: 2#泵 | J3: 3#泵 | K3: 4#泵 | L3: 1#泵 | M3: 2#泵 | N3: 3#泵 | O3: 4#泵 | P3: 1#风机 | Q3: 2#风机 | R3: 3#风机 | S3: 4#风机 | T3: 5#风机 | X3: 1# | Y3: 2# | AE3: 1#泵 | AF3: 2#泵 | AG3: 3#泵 | AH3: 4#泵 | AI3: 5#泵 | AJ3: 提升电量 | AK3: 1#泵 | AL3: 2#泵 | AM3: 3#泵 | AN3: 4#泵 | AO3: 提升电量 | AP3: 1#泵 | AQ3: 2#泵 | AR3: 3#泵 | AS3: 4#泵 | AT3: 提升电量 | AU3: 1#风机 | AV3: 2#风机 | AW3: 3#风机 | AX3: 4#风机 | AY3: 5#风机 | AZ3: 风机电量
A4: 44197 | B4: 15612.46 | C4: 85130.1 | D4: 54213.2 | E4: 55165.1 | F4: 3261.82 | G4: 107477.2 | H4: 5596.3 | I4: 2566.3 | J4: 967 | K4: 56 | L4: 86470.1 | M4: 61099.5 | N4: 68662.4 | O4: 98252.4 | P4: 5097.1 | Q4: 6873.9 | R4: 4172.8 | S4: 4857.2 | T4: 5879.8 | U4: 16509 | V4: 48750 | W4: 48754 | X4: 423 | Y4: 425.1 | Z4: =IF(OR(W4=""),"",(W4+X4+Y4)) -> 49602.1 | AA4: 54141.5 | AB4: 360 | AC4: =IF(OR(AA4=""),"",(AA4+AB4)) -> 54501.5 | AD4: 131701 | AE4: =IF(OR(C5=""),"",(C5-C4)*80) -> 0 | AF4: =IF(OR(D5=""),"",(D5-D4)*80) -> 0 | AG4: =IF(OR(E5=""),"",(E5-E4)*80) -> 2752 | AH4: =IF(OR(F5=""),"",(F5-F4)*80) -> -1.6 | AI4: =IF(OR(G5=""),"",(G5-G4)*80) -> 2296 | AJ4: =IF(OR(AE4="",AF4="",AG4=""),"",AE4+AF4+AG4+AH4+AI4) -> 5046.4 | AK4: =IF(OR(H5=""),"",(H5-H4)*80) -> 0 | AL4: =IF(OR(I5=""),"",(I5-I4)*80) -> 0 | AM4: =IF(OR(J5=""),"",(J5-J4)*80) -> 0 | AN4: =IF(OR(K5=""),"",(K5-K4)*80) -> 0 | AO4: =IF(OR(AK4="",AL4=""),"",AK4+AL4+AM4+AN4) -> 0 | AP4: =IF(OR(L5=""),"",(L5-L4)*100) -> 2230 | AQ4: =IF(OR(M5=""),"",(M5-M4)*100) -> 0 | AR4: =IF(OR(N5=""),"",(N5-N4)*100) -> 0 | AS4: =IF(OR(O5=""),"",(O5-O4)*100) -> 2270 | AT4: =IF(OR(AP4="",AQ4=""),"",AP4+AQ4+AR4+AS4) -> 4500 | AU4: =IF(OR(P5=""),"",(P5-P4)*1000) -> 0 | AV4: =IF(OR(Q5=""),"",(Q5-Q4)*1000) -> 0 | AW4: =IF(OR(R5=""),"",(R5-R4)*1000) -> 4900 | AX4: =IF(OR(S5=""),"",(S5-S4)*1000) -> 0 | AY4: =IF(OR(T5=""),"",(T5-T4)*1000) -> 0 | AZ4: =IF(OR(AU4="",AV4="",AW4=""),"",AU4+AV4+AW4+AX4+AY4) -> 4900 | BA4: =IF(OR(U5=""),"",(U5-U4)*2000) -> 5800 | BB4: =IF(OR(V5=""),"",(V5-V4)*80) -> 648 | BC4: =IF(OR(Z4=""),"",(Z5-Z4)*40) -> 1552 | BD4: =IF(OR(BE4="",BC4=""),"",BE4-BC4-BB4-BA4-AZ4-AT4-AO4-AJ4) -> 14253.6 | BE4: =IF(OR(B5=""),"",(B5-B4)*10000) -> 36700 | BF4: =IF(OR(AC5=""),"",AC5-AC4) -> 67.8 | BG4: =IF(OR($AD4=0),"",BE4/$AD4) -> 0.27866151 | BH4: =IF(OR($AD4=0),"",AJ4/$AD4) -> 0.038317097 | BI4: =IF(OR($AD4=0),"",AO4/$AD4) -> 0 | BJ4: =IF(OR($AD4=0),"",AT4/$AD4) -> 0.034168305 | BK4: =IF(OR($AD4=0),"",AZ4/$AD4) -> 0.037205488 | BL4: =IF(OR($AD4=0),"",BA4/$AD4) -> 0.044039149 | BM4: =IF(OR($AD4=0),"",BB4/$AD4) -> 0.004920236 | BN4: =IF(OR($AD4=0),"",BC4/$AD4) -> 0.011784269 | BO4: =IF(OR($AD4=0),"",BD4/$AD4) -> 0.10822697
A5: =A4+1 -> 44198 | B5: 15616.13 | C5: 85130.1 | D5: 54213.2 | E5: 55199.5 | F5: 3261.8 | G5: 107505.9 | H5: 5596.3 | I5: 2566.3 | J5: 967 | K5: 56 | L5: 86492.4 | M5: 61099.5 | N5: 68662.4 | O5: 98275.1 | P5: 5097.1 | Q5: 6873.9 | R5: 4177.7 | S5: 4857.2 | T5: 5879.8 | U5: 16511.9 | V5: 48758.1 | W5: 48771.7 | X5: 436.9 | Y5: 432.3 | Z5: =IF(OR(W5=""),"",(W5+X5+Y5)) -> 49640.9 | AA5: 54185.3 | AB5: 384 | AC5: =IF(OR(AA5=""),"",(AA5+AB5)) -> 54569.3 | AD5: 142525 | AE5: =IF(OR(C6=""),"",(C6-C5)*80) -> 0 | AF5: =IF(OR(D6=""),"",(D6-D5)*80) -> 0 | AG5: =IF(OR(E6=""),"",(E6-E5)*80) -> 3136 | AH5: =IF(OR(F6=""),"",(F6-F5)*80) -> 0 | AI5: =IF(OR(G6=""),"",(G6-G5)*80) -> 2264 | AJ5: =IF(OR(AE5="",AF5="",AG5=""),"",AE5+AF5+AG5+AH5+AI5) -> 5400 | AK5: =IF(OR(H6=""),"",(H6-H5)*80) -> 0 | AL5: =IF(OR(I6=""),"",(I6-I5)*80) -> 0 | AM5: =IF(OR(J6=""),"",(J6-J5)*80) -> 0 | AN5: =IF(OR(K6=""),"",(K6-K5)*80) -> 0 | AO5: =IF(OR(AK5="",AL5=""),"",AK5+AL5+AM5+AN5) -> 0 | AP5: =IF(OR(L6=""),"",(L6-L5)*100) -> 2760 | AQ5: =IF(OR(M6=""),"",(M6-M5)*100) -> 0 | AR5: =IF(OR(N6=""),"",(N6-N5)*100) -> 0 | AS5: =IF(OR(O6=""),"",(O6-O5)*100) -> 2500 | AT5: =IF(OR(AP5="",AQ5=""),"",AP5+AQ5+AR5+AS5) -> 5260 | AU5: =IF(OR(P6=""),"",(P6-P5)*1000) -> 3300 | AV5: =IF(OR(Q6=""),"",(Q6-Q5)*1000) -> 7500 | AW5: =IF(OR(R6=""),"",(R6-R5)*1000) -> 200 | AX5: =IF(OR(S6=""),"",(S6-S5)*1000) -> 0 | AY5: =IF(OR(T6=""),"",(T6-T5)*1000) -> 0 | AZ5: =IF(OR(AU5="",AV5="",AW5=""),"",AU5+AV5+AW5+AX5+AY5) -> 11000 | BA5: =IF(OR(U6=""),"",(U6-U5)*2000) -> 6200 | BB5: =IF(OR(V6=""),"",(V6-V5)*80) -> 200 | BC5: =IF(OR(Z5=""),"",(Z6-Z5)*40) -> 1644 | BD5: =IF(OR(BE5="",BC5=""),"",BE5-BC5-BB5-BA5-AZ5-AT5-AO5-AJ5) -> 9896 | BE5: =IF(OR(B6=""),"",(B6-B5)*10000) -> 39600 | BF5: =IF(OR(AC6=""),"",AC6-AC5) -> 77.3 | BG5: =IF(OR($AD5=0),"",BE5/$AD5) -> 0.27784599 | BH5: =IF(OR($AD5=0),"",AJ5/$AD5) -> 0.03788809 | BI5: =IF(OR($AD5=0),"",AO5/$AD5) -> 0 | BJ5: =IF(OR($AD5=0),"",AT5/$AD5) -> 0.036905806 | BK5: =IF(OR($AD5=0),"",AZ5/$AD5) -> 0.077179442 | BL5: =IF(OR($AD5=0),"",BA5/$AD5) -> 0.04350114 | BM5: =IF(OR($AD5=0),"",BB5/$AD5) -> 0.0014032626 | BN5: =IF(OR($AD5=0),"",BC5/$AD5) -> 0.011534818 | BO5: =IF(OR($AD5=0),"",BD5/$AD5) -> 0.069433433
A6: =A5+1 -> 44199 | B6: 15620.09 | C6: 85130.1 | D6: 54213.2 | E6: 55238.7 | F6: 3261.8 | G6: 107534.2 | H6: 5596.3 | I6: 2566.3 | J6: 967 | K6: 56 | L6: 86520 | M6: 61099.5 | N6: 68662.4 | O6: 98300.1 | P6: 5100.4 | Q6: 6881.4 | R6: 4177.9 | S6: 4857.2 | T6: 5879.8 | U6: 16515 | V6: 48760.6 | W6: 48789.1 | X6: 448.6 | Y6: 444.3 | Z6: =IF(OR(W6=""),"",(W6+X6+Y6)) -> 49682 | AA6: 54224.6 | AB6: 422 | AC6: =IF(OR(AA6=""),"",(AA6+AB6)) -> 54646.6 | AD6: 136835 | AE6: =IF(OR(C7=""),"",(C7-C6)*80) -> 0 | AF6: =IF(OR(D7=""),"",(D7-D6)*80) -> 1464 | AG6: =IF(OR(E7=""),"",(E7-E6)*80) -> 2480 | AH6: =IF(OR(F7=""),"",(F7-F6)*80) -> 19.2 | AI6: =IF(OR(G7=""),"",(G7-G6)*80) -> 2248 | AJ6: =IF(OR(AE6="",AF6="",AG6=""),"",AE6+AF6+AG6+AH6+AI6) -> 6211.2 | AK6: =IF(OR(H7=""),"",(H7-H6)*80) -> 0 | AL6: =IF(OR(I7=""),"",(I7-I6)*80) -> 0 | AM6: =IF(OR(J7=""),"",(J7-J6)*80) -> 0 | AN6: =IF(OR(K7=""),"",(K7-K6)*80) -> 0 | AO6: =IF(OR(AK6="",AL6=""),"",AK6+AL6+AM6+AN6) -> 0 | AP6: =IF(OR(L7=""),"",(L7-L6)*100) -> 2530 | AQ6: =IF(OR(M7=""),"",(M7-M6)*100) -> 0 | AR6: =IF(OR(N7=""),"",(N7-N6)*100) -> 0 | AS6: =IF(OR(O7=""),"",(O7-O6)*100) -> 2560 | AT6: =IF(OR(AP6="",AQ6=""),"",AP6+AQ6+AR6+AS6) -> 5090 | AU6: =IF(OR(P7=""),"",(P7-P6)*1000) -> 3100 | AV6: =IF(OR(Q7=""),"",(Q7-Q6)*1000) -> 5400 | AW6: =IF(OR(R7=""),"",(R7-R6)*1000) -> 800 | AX6: =IF(OR(S7=""),"",(S7-S6)*1000) -> 0 | AY6: =IF(OR(T7=""),"",(T7-T6)*1000) -> 400 | AZ6: =IF(OR(AU6="",AV6="",AW6=""),"",AU6+AV6+AW6+AX6+AY6) -> 9700 | BA6: =IF(OR(U7=""),"",(U7-U6)*2000) -> 6600 | BB6: =IF(OR(V7=""),"",(V7-V6)*80) -> 8 | BC6: =IF(OR(Z6=""),"",(Z7-Z6)*40) -> 1576 | BD6: =IF(OR(BE6="",BC6=""),"",BE6-BC6-BB6-BA6-AZ6-AT6-AO6-AJ6) -> 11614.8 | BE6: =IF(OR(B7=""),"",(B7-B6)*10000) -> 40800 | BF6: =IF(OR(AC7=""),"",AC7-AC6) -> 70.5 | BG6: =IF(OR($AD6=0),"",BE6/$AD6) -> 0.29816933 | BH6: =IF(OR($AD6=0),"",AJ6/$AD6) -> 0.045391895 | BI6: =IF(OR($AD6=0),"",AO6/$AD6) -> 0 | BJ6: =IF(OR($AD6=0),"",AT6/$AD6) -> 0.037198085 | BK6: =IF(OR($AD6=0),"",AZ6/$AD6) -> 0.070888296 | BL6: =IF(OR($AD6=0),"",BA6/$AD6) -> 0.048233274 | BM6: =IF(OR($AD6=0),"",BB6/$AD6) -> 5.8464574e-05 | BN6: =IF(OR($AD6=0),"",BC6/$AD6) -> 0.011517521 | BO6: =IF(OR($AD6=0),"",BD6/$AD6) -> 0.084881792
A7: =A6+1 -> 44200 | B7: 15624.17 | C7: 85130.1 | D7: 54231.5 | E7: 55269.7 | F7: 3262.04 | G7: 107562.3 | H7: 5596.3 | I7: 2566.3 | J7: 967 | K7: 56 | L7: 86545.3 | M7: 61099.5 | N7: 68662.4 | O7: 98325.7 | P7: 5103.5 | Q7: 6886.8 | R7: 4178.7 | S7: 4857.2 | T7: 5880.2 | U7: 16518.3 | V7: 48760.7 | W7: 48807.2 | X7: 460.6 | Y7: 453.6 | Z7: =IF(OR(W7=""),"",(W7+X7+Y7)) -> 49721.4 | AA7: 54269.1 | AB7: 448 | AC7: =IF(OR(AA7=""),"",(AA7+AB7)) -> 54717.1 | AD7: 153730 | AE7: =IF(OR(C8=""),"",(C8-C7)*80) -> 48 | AF7: =IF(OR(D8=""),"",(D8-D7)*80) -> 1464 | AG7: =IF(OR(E8=""),"",(E8-E7)*80) -> 1696 | AH7: =IF(OR(F8=""),"",(F8-F7)*80) -> 914.4 | AI7: =IF(OR(G8=""),"",(G8-G7)*80) -> 1952 | AJ7: =IF(OR(AE7="",AF7="",AG7=""),"",AE7+AF7+AG7+AH7+AI7) -> 6074.4 | AK7: =IF(OR(H8=""),"",(H8-H7)*80) -> 0 | AL7: =IF(OR(I8=""),"",(I8-I7)*80) -> 0 | AM7: =IF(OR(J8=""),"",(J8-J7)*80) -> 0 | AN7: =IF(OR(K8=""),"",(K8-K7)*80) -> 0 | AO7: =IF(OR(AK7="",AL7=""),"",AK7+AL7+AM7+AN7) -> 0 | AP7: =IF(OR(L8=""),"",(L8-L7)*100) -> 1470 | AQ7: =IF(OR(M8=""),"",(M8-M7)*100) -> 2330 | AR7: =IF(OR(N8=""),"",(N8-N7)*100) -> 50 | AS7: =IF(OR(O8=""),"",(O8-O7)*100) -> 2570 | AT7: =IF(OR(AP7="",AQ7=""),"",AP7+AQ7+AR7+AS7) -> 6420 | AU7: =IF(OR(P8=""),"",(P8-P7)*1000) -> 3600 | AV7: =IF(OR(Q8=""),"",(Q8-Q7)*1000) -> 7200 | AW7: =IF(OR(R8=""),"",(R8-R7)*1000) -> 100 | AX7: =IF(OR(S8=""),"",(S8-S7)*1000) -> 0 | AY7: =IF(OR(T8=""),"",(T8-T7)*1000) -> 700 | AZ7: =IF(OR(AU7="",AV7="",AW7=""),"",AU7+AV7+AW7+AX7+AY7) -> 11600 | BA7: =IF(OR(U8=""),"",(U8-U7)*2000) -> 8400 | BB7: =IF(OR(V8=""),"",(V8-V7)*80) -> 8 | BC7: =IF(OR(Z7=""),"",(Z8-Z7)*40) -> 1508 | BD7: =IF(OR(BE7="",BC7=""),"",BE7-BC7-BB7-BA7-AZ7-AT7-AO7-AJ7) -> 9189.6 | BE7: =IF(OR(B8=""),"",(B8-B7)*10000) -> 43200 | BF7: =IF(OR(AC8=""),"",AC8-AC7) -> 47.8 | BG7: =IF(OR($AD7=0),"",BE7/$AD7) -> 0.28101216 | BH7: =IF(OR($AD7=0),"",AJ7/$AD7) -> 0.039513433 | BI7: =IF(OR($AD7=0),"",AO7/$AD7) -> 0 | BJ7: =IF(OR($AD7=0),"",AT7/$AD7) -> 0.04176153 | BK7: =IF(OR($AD7=0),"",AZ7/$AD7) -> 0.07545697 | BL7: =IF(OR($AD7=0),"",BA7/$AD7) -> 0.054641254 | BM7: =IF(OR($AD7=0),"",BB7/$AD7) -> 5.203929e-05 | BN7: =IF(OR($AD7=0),"",BC7/$AD7) -> 0.0098094061 | BO7: =IF(OR($AD7=0),"",BD7/$AD7) -> 0.059777532
A8: =A7+1 -> 44201 | B8: 15628.49 | C8: 85130.7 | D8: 54249.8 | E8: 55290.9 | F8: 3273.47 | G8: 107586.7 | H8: 5596.3 | I8: 2566.3 | J8: 967 | K8: 56 | L8: 86560 | M8: 61122.8 | N8: 68662.9 | O8: 98351.4 | P8: 5107.1 | Q8: 6894 | R8: 4178.8 | S8: 4857.2 | T8: 5880.9 | U8: 16522.5 | V8: 48760.8 | W8: 48824.7 | X8: 472 | Y8: 462.4 | Z8: =IF(OR(W8=""),"",(W8+X8+Y8)) -> 49759.1 | AA8: 54311.5 | AB8: 453.4 | AC8: =IF(OR(AA8=""),"",(AA8+AB8)) -> 54764.9 | AD8: 139358 | AE8: =IF(OR(C9=""),"",(C9-C8)*80) -> 0 | AF8: =IF(OR(D9=""),"",(D9-D8)*80) -> 0 | AG8: =IF(OR(E9=""),"",(E9-E8)*80) -> 2920 | AH8: =IF(OR(F9=""),"",(F9-F8)*80) -> 4.8 | AI8: =IF(OR(G9=""),"",(G9-G8)*80) -> 2488 | AJ8: =IF(OR(AE8="",AF8="",AG8=""),"",AE8+AF8+AG8+AH8+AI8) -> 5412.8 | AK8: =IF(OR(H9=""),"",(H9-H8)*80) -> 0 | AL8: =IF(OR(I9=""),"",(I9-I8)*80) -> 0 | AM8: =IF(OR(J9=""),"",(J9-J8)*80) -> 0 | AN8: =IF(OR(K9=""),"",(K9-K8)*80) -> 0 | AO8: =IF(OR(AK8="",AL8=""),"",AK8+AL8+AM8+AN8) -> 0 | AP8: =IF(OR(L9=""),"",(L9-L8)*100) -> 2490 | AQ8: =IF(OR(M9=""),"",(M9-M8)*100) -> 0 | AR8: =IF(OR(N9=""),"",(N9-N8)*100) -> 80 | AS8: =IF(OR(O9=""),"",(O9-O8)*100) -> 2420 | AT8: =IF(OR(AP8="",AQ8=""),"",AP8+AQ8+AR8+AS8) -> 4990 | AU8: =IF(OR(P9=""),"",(P9-P8)*1000) -> 3600 | AV8: =IF(OR(Q9=""),"",(Q9-Q8)*1000) -> 7000 | AW8: =IF(OR(R9=""),"",(R9-R8)*1000) -> 0 | AX8: =IF(OR(S9=""),"",(S9-S8)*1000) -> 0 | AY8: =IF(OR(T9=""),"",(T9-T8)*1000) -> 0 | AZ8: =IF(OR(AU8="",AV8="",AW8=""),"",AU8+AV8+AW8+AX8+AY8) -> 10600 | BA8: =IF(OR(U9=""),"",(U9-U8)*2000) -> 7200 | BB8: =IF(OR(V9=""),"",(V9-V8)*80) -> 8 | BC8: =IF(OR(Z8=""),"",(Z9-Z8)*40) -> 1532 | BD8: =IF(OR(BE8="",BC8=""),"",BE8-BC8-BB8-BA8-AZ8-AT8-AO8-AJ8) -> 10757.2 | BE8: =IF(OR(B9=""),"",(B9-B8)*10000) -> 40500 | BF8: =IF(OR(AC9=""),"",AC9-AC8) -> 49 | BG8: =IF(OR($AD8=0),"",BE8/$AD8) -> 0.29061841 | BH8: =IF(OR($AD8=0),"",AJ8/$AD8) -> 0.038840971 | BI8: =IF(OR($AD8=0),"",AO8/$AD8) -> 0 | BJ8: =IF(OR($AD8=0),"",AT8/$AD8) -> 0.035807058 | BK8: =IF(OR($AD8=0),"",AZ8/$AD8) -> 0.076063089 | BL8: =IF(OR($AD8=0),"",BA8/$AD8) -> 0.051665495 | BM8: =IF(OR($AD8=0),"",BB8/$AD8) -> 5.7406105e-05 | BN8: =IF(OR($AD8=0),"",BC8/$AD8) -> 0.010993269 | BO8: =IF(OR($AD8=0),"",BD8/$AD8) -> 0.077191119
A9: =A8+1 -> 44202 | B9: 15632.54 | C9: 85130.7 | D9: 54249.8 | E9: 55327.4 | F9: 3273.53 | G9: 107617.8 | H9: 5596.3 | I9: 2566.3 | J9: 967 | K9: 56 | L9: 86584.9 | M9: 61122.8 | N9: 68663.7 | O9: 98375.6 | P9: 5110.7 | Q9: 6901 | R9: 4178.8 | S9: 4857.2 | T9: 5880.9 | U9: 16526.1 | V9: 48760.9 | W9: 48842.3 | X9: 483.7 | Y9: 471.4 | Z9: =IF(OR(W9=""),"",(W9+X9+Y9)) -> 49797.4 | AA9: 54354.8 | AB9: 459.1 | AC9: =IF(OR(AA9=""),"",(AA9+AB9)) -> 54813.9 | AD9: 145477 | AE9: =IF(OR(C10=""),"",(C10-C9)*80) -> 0 | AF9: =IF(OR(D10=""),"",(D10-D9)*80) -> 768 | AG9: =IF(OR(E10=""),"",(E10-E9)*80) -> 2856 | AH9: =IF(OR(F10=""),"",(F10-F9)*80) -> 4.8 | AI9: =IF(OR(G10=""),"",(G10-G9)*80) -> 2384 | AJ9: =IF(OR(AE9="",AF9="",AG9=""),"",AE9+AF9+AG9+AH9+AI9) -> 6012.8 | AK9: =IF(OR(H10=""),"",(H10-H9)*80) -> 0 | AL9: =IF(OR(I10=""),"",(I10-I9)*80) -> 0 | AM9: =IF(OR(J10=""),"",(J10-J9)*80) -> 0 | AN9: =IF(OR(K10=""),"",(K10-K9)*80) -> 0 | AO9: =IF(OR(AK9="",AL9=""),"",AK9+AL9+AM9+AN9) -> 0 | AP9: =IF(OR(L10=""),"",(L10-L9)*100) -> 2260 | AQ9: =IF(OR(M10=""),"",(M10-M9)*100) -> 0 | AR9: =IF(OR(N10=""),"",(N10-N9)*100) -> 800 | AS9: =IF(OR(O10=""),"",(O10-O9)*100) -> 2420 | AT9: =IF(OR(AP9="",AQ9=""),"",AP9+AQ9+AR9+AS9) -> 5480 | AU9: =IF(OR(P10=""),"",(P10-P9)*1000) -> 3700 | AV9: =IF(OR(Q10=""),"",(Q10-Q9)*1000) -> 6600 | AW9: =IF(OR(R10=""),"",(R10-R9)*1000) -> 300 | AX9: =IF(OR(S10=""),"",(S10-S9)*1000) -> 0 | AY9: =IF(OR(T10=""),"",(T10-T9)*1000) -> 0 | AZ9: =IF(OR(AU9="",AV9="",AW9=""),"",AU9+AV9+AW9+AX9+AY9) -> 10600 | BA9: =IF(OR(U10=""),"",(U10-U9)*2000) -> 7400 | BB9: =IF(OR(V10=""),"",(V10-V9)*80) -> 8 | BC9: =IF(OR(Z9=""),"",(Z10-Z9)*40) -> 1512 | BD9: =IF(OR(BE9="",BC9=""),"",BE9-BC9-BB9-BA9-AZ9-AT9-AO9-AJ9) -> 11287.2 | BE9: =IF(OR(B10=""),"",(B10-B9)*10000) -> 42300 | BF9: =IF(OR(AC10=""),"",AC10-AC9) -> 49.3 | BG9: =IF(OR($AD9=0),"",BE9/$AD9) -> 0.29076761 | BH9: =IF(OR($AD9=0),"",AJ9/$AD9) -> 0.041331619 | BI9: =IF(OR($AD9=0),"",AO9/$AD9) -> 0 | BJ9: =IF(OR($AD9=0),"",AT9/$AD9) -> 0.037669185 | BK9: =IF(OR($AD9=0),"",AZ9/$AD9) -> 0.072863752 | BL9: =IF(OR($AD9=0),"",BA9/$AD9) -> 0.050867147 | BM9: =IF(OR($AD9=0),"",BB9/$AD9) -> 5.4991511e-05 | BN9: =IF(OR($AD9=0),"",BC9/$AD9) -> 0.010393396 | BO9: =IF(OR($AD9=0),"",BD9/$AD9) -> 0.077587522
A10: =A9+1 -> 44203 | B10: 15636.77 | C10: 85130.7 | D10: 54259.4 | E10: 55363.1 | F10: 3273.59 | G10: 107647.6 | H10: 5596.3 | I10: 2566.3 | J10: 967 | K10: 56 | L10: 86607.5 | M10: 61122.8 | N10: 68671.7 | O10: 98399.8 | P10: 5114.4 | Q10: 6907.6 | R10: 4179.1 | S10: 4857.2 | T10: 5880.9 | U10: 16529.8 | V10: 48761 | W10: 48859.9 | X10: 495.4 | Y10: 479.9 | Z10: =IF(OR(W10=""),"",(W10+X10+Y10)) -> 49835.2 | AA10: 54398.4 | AB10: 464.8 | AC10: =IF(OR(AA10=""),"",(AA10+AB10)) -> 54863.2 | AD10: 142455 | AE10: =IF(OR(C11=""),"",(C11-C10)*80) -> 0 | AF10: =IF(OR(D11=""),"",(D11-D10)*80) -> 248 | AG10: =IF(OR(E11=""),"",(E11-E10)*80) -> 2928 | AH10: =IF(OR(F11=""),"",(F11-F10)*80) -> 4 | AI10: =IF(OR(G11=""),"",(G11-G10)*80) -> 2728 | AJ10: =IF(OR(AE10="",AF10="",AG10=""),"",AE10+AF10+AG10+AH10+AI10) -> 5908 | AK10: =IF(OR(H11=""),"",(H11-H10)*80) -> 0 | AL10: =IF(OR(I11=""),"",(I11-I10)*80) -> 0 | AM10: =IF(OR(J11=""),"",(J11-J10)*80) -> 0 | AN10: =IF(OR(K11=""),"",(K11-K10)*80) -> 0 | AO10: =IF(OR(AK10="",AL10=""),"",AK10+AL10+AM10+AN10) -> 0 | AP10: =IF(OR(L11=""),"",(L11-L10)*100) -> 1890 | AQ10: =IF(OR(M11=""),"",(M11-M10)*100) -> 10 | AR10: =IF(OR(N11=""),"",(N11-N10)*100) -> 860 | AS10: =IF(OR(O11=""),"",(O11-O10)*100) -> 2330 | AT10: =IF(OR(AP10="",AQ10=""),"",AP10+AQ10+AR10+AS10) -> 5090 | AU10: =IF(OR(P11=""),"",(P11-P10)*1000) -> 3800 | AV10: =IF(OR(Q11=""),"",(Q11-Q10)*1000) -> 6100 | AW10: =IF(OR(R11=""),"",(R11-R10)*1000) -> 1000 | AX10: =IF(OR(S11=""),"",(S11-S10)*1000) -> 0 | AY10: =IF(OR(T11=""),"",(T11-T10)*1000) -> 0 | AZ10: =IF(OR(AU10="",AV10="",AW10=""),"",AU10+AV10+AW10+AX10+AY10) -> 10900 | BA10: =IF(OR(U11=""),"",(U11-U10)*2000) -> 5800 | BB10: =IF(OR(V11=""),"",(V11-V10)*80) -> 8 | BC10: =IF(OR(Z10=""),"",(Z11-Z10)*40) -> 1836 | BD10: =IF(OR(BE10="",BC10=""),"",BE10-BC10-BB10-BA10-AZ10-AT10-AO10-AJ10) -> 13558 | BE10: =IF(OR(B11=""),"",(B11-B10)*10000) -> 43100 | BF10: =IF(OR(AC11=""),"",AC11-AC10) -> 51 | BG10: =IF(OR($AD10=0),"",BE10/$AD10) -> 0.30255168 | BH10: =IF(OR($AD10=0),"",AJ10/$AD10) -> 0.041472746 | BI10: =IF(OR($AD10=0),"",AO10/$AD10) -> 0 | BJ10: =IF(OR($AD10=0),"",AT10/$AD10) -> 0.035730582 | BK10: =IF(OR($AD10=0),"",AZ10/$AD10) -> 0.076515391 | BL10: =IF(OR($AD10=0),"",BA10/$AD10) -> 0.040714612 | BM10: =IF(OR($AD10=0),"",BB10/$AD10) -> 5.6158085e-05 | BN10: =IF(OR($AD10=0),"",BC10/$AD10) -> 0.012888281 | BO10: =IF(OR($AD10=0),"",BD10/$AD10) -> 0.095173915
A11: =A10+1 -> 44204 | B11: 15641.08 | C11: 85130.7 | D11: 54262.5 | E11: 55399.7 | F11: 3273.64 | G11: 107681.7 | H11: 5596.3 | I11: 2566.3 | J11: 967 | K11: 56 | L11: 86626.4 | M11: 61122.9 | N11: 68680.3 | O11: 98423.1 | P11: 5118.2 | Q11: 6913.7 | R11: 4180.1 | S11: 4857.2 | T11: 5880.9 | U11: 16532.7 | V11: 48761.1 | W11: 48878.3 | X11: 510.2 | Y11: 492.6 | Z11: =IF(OR(W11=""),"",(W11+X11+Y11)) -> 49881.1 | AA11: 54446 | AB11: 468.2 | AC11: =IF(OR(AA11=""),"",(AA11+AB11)) -> 54914.2 | AD11: 137542 | AE11: =IF(OR(C12=""),"",(C12-C11)*80) -> 0 | AF11: =IF(OR(D12=""),"",(D12-D11)*80) -> 0 | AG11: =IF(OR(E12=""),"",(E12-E11)*80) -> 2992 | AH11: =IF(OR(F12=""),"",(F12-F11)*80) -> 4.8 | AI11: =IF(OR(G12=""),"",(G12-G11)*80) -> 2624 | AJ11: =IF(OR(AE11="",AF11="",AG11=""),"",AE11+AF11+AG11+AH11+AI11) -> 5620.8 | AK11: =IF(OR(H12=""),"",(H12-H11)*80) -> 0 | AL11: =IF(OR(I12=""),"",(I12-I11)*80) -> 0 | AM11: =IF(OR(J12=""),"",(J12-J11)*80) -> 0 | AN11: =IF(OR(K12=""),"",(K12-K11)*80) -> 0 | AO11: =IF(OR(AK11="",AL11=""),"",AK11+AL11+AM11+AN11) -> 0 | AP11: =IF(OR(L12=""),"",(L12-L11)*100) -> 2560 | AQ11: =IF(OR(M12=""),"",(M12-M11)*100) -> 0 | AR11: =IF(OR(N12=""),"",(N12-N11)*100) -> 0 | AS11: =IF(OR(O12=""),"",(O12-O11)*100) -> 2340 | AT11: =IF(OR(AP11="",AQ11=""),"",AP11+AQ11+AR11+AS11) -> 4900 | AU11: =IF(OR(P12=""),"",(P12-P11)*1000) -> 2700 | AV11: =IF(OR(Q12=""),"",(Q12-Q11)*1000) -> 3100 | AW11: =IF(OR(R12=""),"",(R12-R11)*1000) -> 3400 | AX11: =IF(OR(S12=""),"",(S12-S11)*1000) -> 0 | AY11: =IF(OR(T12=""),"",(T12-T11)*1000) -> 0 | AZ11: =IF(OR(AU11="",AV11="",AW11=""),"",AU11+AV11+AW11+AX11+AY11) -> 9200 | BA11: =IF(OR(U12=""),"",(U12-U11)*2000) -> 5000 | BB11: =IF(OR(V12=""),"",(V12-V11)*80) -> 8 | BC11: =IF(OR(Z11=""),"",(Z12-Z11)*40) -> 1480 | BD11: =IF(OR(BE11="",BC11=""),"",BE11-BC11-BB11-BA11-AZ11-AT11-AO11-AJ11) -> 15991.2 | BE11: =IF(OR(B12=""),"",(B12-B11)*10000) -> 42200 | BF11: =IF(OR(AC12=""),"",AC12-AC11) -> 49.7 | BG11: =IF(OR($AD11=0),"",BE11/$AD11) -> 0.30681537 | BH11: =IF(OR($AD11=0),"",AJ11/$AD11) -> 0.040866063 | BI11: =IF(OR($AD11=0),"",AO11/$AD11) -> 0 | BJ11: =IF(OR($AD11=0),"",AT11/$AD11) -> 0.035625482 | BK11: =IF(OR($AD11=0),"",AZ11/$AD11) -> 0.066888659 | BL11: =IF(OR($AD11=0),"",BA11/$AD11) -> 0.036352532 | BM11: =IF(OR($AD11=0),"",BB11/$AD11) -> 5.8164052e-05 | BN11: =IF(OR($AD11=0),"",BC11/$AD11) -> 0.01076035 | BO11: =IF(OR($AD11=0),"",BD11/$AD11) -> 0.11626412
A12: =A11+1 -> 44205 | B12: 15645.3 | C12: 85130.7 | D12: 54262.5 | E12: 55437.1 | F12: 3273.7 | G12: 107714.5 | H12: 5596.3 | I12: 2566.3 | J12: 967 | K12: 56 | L12: 86652 | M12: 61122.9 | N12: 68680.3 | O12: 98446.5 | P12: 5120.9 | Q12: 6916.8 | R12: 4183.5 | S12: 4857.2 | T12: 5880.9 | U12: 16535.2 | V12: 48761.2 | W12: 48896 | X12: 521.1 | Y12: 501 | Z12: =IF(OR(W12=""),"",(W12+X12+Y12)) -> 49918.1 | AA12: 54493.7 | AB12: 470.2 | AC12: =IF(OR(AA12=""),"",(AA12+AB12)) -> 54963.9 | AD12: 144271 | AE12: =IF(OR(C13=""),"",(C13-C12)*80) -> 0 | AF12: =IF(OR(D13=""),"",(D13-D12)*80) -> 0 | AG12: =IF(OR(E13=""),"",(E13-E12)*80) -> 3760 | AH12: =IF(OR(F13=""),"",(F13-F12)*80) -> 4 | AI12: =IF(OR(G13=""),"",(G13-G12)*80) -> 2760 | AJ12: =IF(OR(AE12="",AF12="",AG12=""),"",AE12+AF12+AG12+AH12+AI12) -> 6524 | AK12: =IF(OR(H13=""),"",(H13-H12)*80) -> 0 | AL12: =IF(OR(I13=""),"",(I13-I12)*80) -> 0 | AM12: =IF(OR(J13=""),"",(J13-J12)*80) -> 0 | AN12: =IF(OR(K13=""),"",(K13-K12)*80) -> 0 | AO12: =IF(OR(AK12="",AL12=""),"",AK12+AL12+AM12+AN12) -> 0 | AP12: =IF(OR(L13=""),"",(L13-L12)*100) -> 2860 | AQ12: =IF(OR(M13=""),"",(M13-M12)*100) -> 10 | AR12: =IF(OR(N13=""),"",(N13-N12)*100) -> 0 | AS12: =IF(OR(O13=""),"",(O13-O12)*100) -> 2350 | AT12: =IF(OR(AP12="",AQ12=""),"",AP12+AQ12+AR12+AS12) -> 5220 | AU12: =IF(OR(P13=""),"",(P13-P12)*1000) -> 3700 | AV12: =IF(OR(Q13=""),"",(Q13-Q12)*1000) -> 0 | AW12: =IF(OR(R13=""),"",(R13-R12)*1000) -> 4500 | AX12: =IF(OR(S13=""),"",(S13-S12)*1000) -> 0 | AY12: =IF(OR(T13=""),"",(T13-T12)*1000) -> 0 | AZ12: =IF(OR(AU12="",AV12="",AW12=""),"",AU12+AV12+AW12+AX12+AY12) -> 8200 | BA12: =IF(OR(U13=""),"",(U13-U12)*2000) -> 5400 | BB12: =IF(OR(V13=""),"",(V13-V12)*80) -> 8 | BC12: =IF(OR(Z12=""),"",(Z13-Z12)*40) -> 1528 | BD12: =IF(OR(BE12="",BC12=""),"",BE12-BC12-BB12-BA12-AZ12-AT12-AO12-AJ12) -> 17720 | BE12: =IF(OR(B13=""),"",(B13-B12)*10000) -> 44600 | BF12: =IF(OR(AC13=""),"",AC13-AC12) -> 297.7 | BG12: =IF(OR($AD12=0),"",BE12/$AD12) -> 0.30914044 | BH12: =IF(OR($AD12=0),"",AJ12/$AD12) -> 0.045220453 | BI12: =IF(OR($AD12=0),"",AO12/$AD12) -> 0 | BJ12: =IF(OR($AD12=0),"",AT12/$AD12) -> 0.036181908 | BK12: =IF(OR($AD12=0),"",AZ12/$AD12) -> 0.056837479 | BL12: =IF(OR($AD12=0),"",BA12/$AD12) -> 0.03742956 | BM12: =IF(OR($AD12=0),"",BB12/$AD12) -> 5.5451199e-05 | BN12: =IF(OR($AD12=0),"",BC12/$AD12) -> 0.010591179 | BO12: =IF(OR($AD12=0),"",BD12/$AD12) -> 0.12282441
A13: =A12+1 -> 44206 | B13: 15649.76 | C13: 85130.7 | D13: 54262.5 | E13: 55484.1 | F13: 3273.75 | G13: 107749 | H13: 5596.3 | I13: 2566.3 | J13: 967 | K13: 56 | L13: 86680.6 | M13: 61123 | N13: 68680.3 | O13: 98470 | P13: 5124.6 | Q13: 6916.8 | R13: 4188 | S13: 4857.2 | T13: 5880.9 | U13: 16537.9 | V13: 48761.3 | W13: 48913.8 | X13: 532.9 | Y13: 509.6 | Z13: =IF(OR(W13=""),"",(W13+X13+Y13)) -> 49956.3 | AA13: 54540.6 | AB13: 721 | AC13: =IF(OR(AA13=""),"",(AA13+AB13)) -> 55261.6 | AD13: 145387 | AE13: =IF(OR(C14=""),"",(C14-C13)*80) -> 0 | AF13: =IF(OR(D14=""),"",(D14-D13)*80) -> 0 | AG13: =IF(OR(E14=""),"",(E14-E13)*80) -> 3360 | AH13: =IF(OR(F14=""),"",(F14-F13)*80) -> 4.8 | AI13: =IF(OR(G14=""),"",(G14-G13)*80) -> 2688 | AJ13: =IF(OR(AE13="",AF13="",AG13=""),"",AE13+AF13+AG13+AH13+AI13) -> 6052.8 | AK13: =IF(OR(H14=""),"",(H14-H13)*80) -> 0 | AL13: =IF(OR(I14=""),"",(I14-I13)*80) -> 0 | AM13: =IF(OR(J14=""),"",(J14-J13)*80) -> 0 | AN13: =IF(OR(K14=""),"",(K14-K13)*80) -> 0 | AO13: =IF(OR(AK13="",AL13=""),"",AK13+AL13+AM13+AN13) -> 0 | AP13: =IF(OR(L14=""),"",(L14-L13)*100) -> 3020 | AQ13: =IF(OR(M14=""),"",(M14-M13)*100) -> 10 | AR13: =IF(OR(N14=""),"",(N14-N13)*100) -> 140 | AS13: =IF(OR(O14=""),"",(O14-O13)*100) -> 2430 | AT13: =IF(OR(AP13="",AQ13=""),"",AP13+AQ13+AR13+AS13) -> 5600 | AU13: =IF(OR(P14=""),"",(P14-P13)*1000) -> 3500 | AV13: =IF(OR(Q14=""),"",(Q14-Q13)*1000) -> 0 | AW13: =IF(OR(R14=""),"",(R14-R13)*1000) -> 4400 | AX13: =IF(OR(S14=""),"",(S14-S13)*1000) -> 0 | AY13: =IF(OR(T14=""),"",(T14-T13)*1000) -> 0 | AZ13: =IF(OR(AU13="",AV13="",AW13=""),"",AU13+AV13+AW13+AX13+AY13) -> 7900 | BA13: =IF(OR(U14=""),"",(U14-U13)*2000) -> 6800 | BB13: =IF(OR(V14=""),"",(V14-V13)*80) -> 8 | BC13: =IF(OR(Z13=""),"",(Z14-Z13)*40) -> 1540 | BD13: =IF(OR(BE13="",BC13=""),"",BE13-BC13-BB13-BA13-AZ13-AT13-AO13-AJ13) -> 16699.2 | BE13: =IF(OR(B14=""),"",(B14-B13)*10000) -> 44600 | BF13: =IF(OR(AC14=""),"",AC14-AC13) -> 69.7 | BG13: =IF(OR($AD13=0),"",BE13/$AD13) -> 0.30676746 | BH13: =IF(OR($AD13=0),"",AJ13/$AD13) -> 0.041632333 | BI13: =IF(OR($AD13=0),"",AO13/$AD13) -> 0 | BJ13: =IF(OR($AD13=0),"",AT13/$AD13) -> 0.038517887 | BK13: =IF(OR($AD13=0),"",AZ13/$AD13) -> 0.054337733 | BL13: =IF(OR($AD13=0),"",BA13/$AD13) -> 0.04677172 | BM13: =IF(OR($AD13=0),"",BB13/$AD13) -> 5.5025552e-05 | BN13: =IF(OR($AD13=0),"",BC13/$AD13) -> 0.010592419 | BO13: =IF(OR($AD13=0),"",BD13/$AD13) -> 0.11486034
A14: =A13+1 -> 44207 | B14: 15654.22 | C14: 85130.7 | D14: 54262.5 | E14: 55526.1 | F14: 3273.81 | G14: 107782.6 | H14: 5596.3 | I14: 2566.3 | J14: 967 | K14: 56 | L14: 86710.8 | M14: 61123.1 | N14: 68681.7 | O14: 98494.3 | P14: 5128.1 | Q14: 6916.8 | R14: 4192.4 | S14: 4857.2 | T14: 5880.9 | U14: 16541.3 | V14: 48761.4 | W14: 48931.6 | X14: 544.7 | Y14: 518.5 | Z14: =IF(OR(W14=""),"",(W14+X14+Y14)) -> 49994.8 | AA14: 54590.3 | AB14: 741 | AC14: =IF(OR(AA14=""),"",(AA14+AB14)) -> 55331.3 | AD14: 140326 | AE14: =IF(OR(C15=""),"",(C15-C14)*80) -> 0 | AF14: =IF(OR(D15=""),"",(D15-D14)*80) -> 0 | AG14: =IF(OR(E15=""),"",(E15-E14)*80) -> 2496 | AH14: =IF(OR(F15=""),"",(F15-F14)*80) -> -0.8 | AI14: =IF(OR(G15=""),"",(G15-G14)*80) -> 2608 | AJ14: =IF(OR(AE14="",AF14="",AG14=""),"",AE14+AF14+AG14+AH14+AI14) -> 5103.2 | AK14: =IF(OR(H15=""),"",(H15-H14)*80) -> 0 | AL14: =IF(OR(I15=""),"",(I15-I14)*80) -> 0 | AM14: =IF(OR(J15=""),"",(J15-J14)*80) -> 0 | AN14: =IF(OR(K15=""),"",(K15-K14)*80) -> 0 | AO14: =IF(OR(AK14="",AL14=""),"",AK14+AL14+AM14+AN14) -> 0 | AP14: =IF(OR(L15=""),"",(L15-L14)*100) -> 2230 | AQ14: =IF(OR(M15=""),"",(M15-M14)*100) -> 0 | AR14: =IF(OR(N15=""),"",(N15-N14)*100) -> 570 | AS14: =IF(OR(O15=""),"",(O15-O14)*100) -> 2310 | AT14: =IF(OR(AP14="",AQ14=""),"",AP14+AQ14+AR14+AS14) -> 5110 | AU14: =IF(OR(P15=""),"",(P15-P14)*1000) -> 3600 | AV14: =IF(OR(Q15=""),"",(Q15-Q14)*1000) -> 0 | AW14: =IF(OR(R15=""),"",(R15-R14)*1000) -> 4400 | AX14: =IF(OR(S15=""),"",(S15-S14)*1000) -> 0 | AY14: =IF(OR(T15=""),"",(T15-T14)*1000) -> 0 | AZ14: =IF(OR(AU14="",AV14="",AW14=""),"",AU14+AV14+AW14+AX14+AY14) -> 8000 | BA14: =IF(OR(U15=""),"",(U15-U14)*2000) -> 6800 | BB14: =IF(OR(V15=""),"",(V15-V14)*80) -> 0 | BC14: =IF(OR(Z14=""),"",(Z15-Z14)*40) -> 1564 | BD14: =IF(OR(BE14="",BC14=""),"",BE14-BC14-BB14-BA14-AZ14-AT14-AO14-AJ14) -> 19322.8 | BE14: =IF(OR(B15=""),"",(B15-B14)*10000) -> 45900 | BF14: =IF(OR(AC15=""),"",AC15-AC14) -> 84.9 | BG14: =IF(OR($AD14=0),"",BE14/$AD14) -> 0.32709548 | BH14: =IF(OR($AD14=0),"",AJ14/$AD14) -> 0.036366746 | BI14: =IF(OR($AD14=0),"",AO14/$AD14) -> 0 | BJ14: =IF(OR($AD14=0),"",AT14/$AD14) -> 0.036415205 | BK14: =IF(OR($AD14=0),"",AZ14/$AD14) -> 0.057010105 | BL14: =IF(OR($AD14=0),"",BA14/$AD14) -> 0.048458589 | BM14: =IF(OR($AD14=0),"",BB14/$AD14) -> 0 | BN14: =IF(OR($AD14=0),"",BC14/$AD14) -> 0.011145476 | BO14: =IF(OR($AD14=0),"",BD14/$AD14) -> 0.13769936
A15: =A14+1 -> 44208 | B15: 15658.81 | C15: 85130.7 | D15: 54262.5 | E15: 55557.3 | F15: 3273.8 | G15: 107815.2 | H15: 5596.3 | I15: 2566.3 | J15: 967 | K15: 56 | L15: 86733.1 | M15: 61123.1 | N15: 68687.4 | O15: 98517.4 | P15: 5131.7 | Q15: 6916.8 | R15: 4196.8 | S15: 4857.2 | T15: 5880.9 | U15: 16544.7 | V15: 48761.4 | W15: 48949.6 | X15: 556.5 | Y15: 527.8 | Z15: =IF(OR(W15=""),"",(W15+X15+Y15)) -> 50033.9 | AA15: 54640 | AB15: 776.2 | AC15: =IF(OR(AA15=""),"",(AA15+AB15)) -> 55416.2 | AD15: 141186 | AE15: =IF(OR(C16=""),"",(C16-C15)*80) -> 0 | AF15: =IF(OR(D16=""),"",(D16-D15)*80) -> 2912 | AG15: =IF(OR(E16=""),"",(E16-E15)*80) -> 2144 | AH15: =IF(OR(F16=""),"",(F16-F15)*80) -> 9.6 | AI15: =IF(OR(G16=""),"",(G16-G15)*80) -> 2432 | AJ15: =IF(OR(AE15="",AF15="",AG15=""),"",AE15+AF15+AG15+AH15+AI15) -> 7497.6 | AK15: =IF(OR(H16=""),"",(H16-H15)*80) -> 0 | AL15: =IF(OR(I16=""),"",(I16-I15)*80) -> 0 | AM15: =IF(OR(J16=""),"",(J16-J15)*80) -> 0 | AN15: =IF(OR(K16=""),"",(K16-K15)*80) -> 0 | AO15: =IF(OR(AK15="",AL15=""),"",AK15+AL15+AM15+AN15) -> 0 | AP15: =IF(OR(L16=""),"",(L16-L15)*100) -> 2430 | AQ15: =IF(OR(M16=""),"",(M16-M15)*100) -> 0 | AR15: =IF(OR(N16=""),"",(N16-N15)*100) -> 2150 | AS15: =IF(OR(O16=""),"",(O16-O15)*100) -> 760 | AT15: =IF(OR(AP15="",AQ15=""),"",AP15+AQ15+AR15+AS15) -> 5340 | AU15: =IF(OR(P16=""),"",(P16-P15)*1000) -> 3900 | AV15: =IF(OR(Q16=""),"",(Q16-Q15)*1000) -> 0 | AW15: =IF(OR(R16=""),"",(R16-R15)*1000) -> 4300 | AX15: =IF(OR(S16=""),"",(S16-S15)*1000) -> 0 | AY15: =IF(OR(T16=""),"",(T16-T15)*1000) -> 300 | AZ15: =IF(OR(AU15="",AV15="",AW15=""),"",AU15+AV15+AW15+AX15+AY15) -> 8500 | BA15: =IF(OR(U16=""),"",(U16-U15)*2000) -> 7000 | BB15: =IF(OR(V16=""),"",(V16-V15)*80) -> 16 | BC15: =IF(OR(Z15=""),"",(Z16-Z15)*40) -> 1564 | BD15: =IF(OR(BE15="",BC15=""),"",BE15-BC15-BB15-BA15-AZ15-AT15-AO15-AJ15) -> 16982.4 | BE15: =IF(OR(B16=""),"",(B16-B15)*10000) -> 46900 | BF15: =IF(OR(AC16=""),"",AC16-AC15) -> 51.8 | BG15: =IF(OR($AD15=0),"",BE15/$AD15) -> 0.33218591 | BH15: =IF(OR($AD15=0),"",AJ15/$AD15) -> 0.053104415 | BI15: =IF(OR($AD15=0),"",AO15/$AD15) -> 0 | BJ15: =IF(OR($AD15=0),"",AT15/$AD15) -> 0.037822447 | BK15: =IF(OR($AD15=0),"",AZ15/$AD15) -> 0.06020427 | BL15: =IF(OR($AD15=0),"",BA15/$AD15) -> 0.049579987 | BM15: =IF(OR($AD15=0),"",BB15/$AD15) -> 0.00011332568 | BN15: =IF(OR($AD15=0),"",BC15/$AD15) -> 0.011077586 | BO15: =IF(OR($AD15=0),"",BD15/$AD15) -> 0.12028388
A16: =A15+1 -> 44209 | B16: 15663.5 | C16: 85130.7 | D16: 54298.9 | E16: 55584.1 | F16: 3273.92 | G16: 107845.6 | H16: 5596.3 | I16: 2566.3 | J16: 967 | K16: 56 | L16: 86757.4 | M16: 61123.1 | N16: 68708.9 | O16: 98525 | P16: 5135.6 | Q16: 6916.8 | R16: 4201.1 | S16: 4857.2 | T16: 5881.2 | U16: 16548.2 | V16: 48761.6 | W16: 48967.3 | X16: 568.3 | Y16: 537.4 | Z16: =IF(OR(W16=""),"",(W16+X16+Y16)) -> 50073 | AA16: 54689.7 | AB16: 778.3 | AC16: =IF(OR(AA16=""),"",(AA16+AB16)) -> 55468 | AD16: 143369 | AE16: =IF(OR(C17=""),"",(C17-C16)*80) -> 0 | AF16: =IF(OR(D17=""),"",(D17-D16)*80) -> 1448 | AG16: =IF(OR(E17=""),"",(E17-E16)*80) -> 2480 | AH16: =IF(OR(F17=""),"",(F17-F16)*80) -> 4.8 | AI16: =IF(OR(G17=""),"",(G17-G16)*80) -> 2704 | AJ16: =IF(OR(AE16="",AF16="",AG16=""),"",AE16+AF16+AG16+AH16+AI16) -> 6636.8 | AK16: =IF(OR(H17=""),"",(H17-H16)*80) -> 0 | AL16: =IF(OR(I17=""),"",(I17-I16)*80) -> 0 | AM16: =IF(OR(J17=""),"",(J17-J16)*80) -> 0 | AN16: =IF(OR(K17=""),"",(K17-K16)*80) -> 0 | AO16: =IF(OR(AK16="",AL16=""),"",AK16+AL16+AM16+AN16) -> 0 | AP16: =IF(OR(L17=""),"",(L17-L16)*100) -> 2010 | AQ16: =IF(OR(M17=""),"",(M17-M16)*100) -> 10 | AR16: =IF(OR(N17=""),"",(N17-N16)*100) -> 2910 | AS16: =IF(OR(O17=""),"",(O17-O16)*100) -> 870 | AT16: =IF(OR(AP16="",AQ16=""),"",AP16+AQ16+AR16+AS16) -> 5800 | AU16: =IF(OR(P17=""),"",(P17-P16)*1000) -> 3700 | AV16: =IF(OR(Q17=""),"",(Q17-Q16)*1000) -> 0 | AW16: =IF(OR(R17=""),"",(R17-R16)*1000) -> 200 | AX16: =IF(OR(S17=""),"",(S17-S16)*1000) -> 0 | AY16: =IF(OR(T17=""),"",(T17-T16)*1000) -> 8700 | AZ16: =IF(OR(AU16="",AV16="",AW16=""),"",AU16+AV16+AW16+AX16+AY16) -> 12600 | BA16: =IF(OR(U17=""),"",(U17-U16)*2000) -> 7000 | BB16: =IF(OR(V17=""),"",(V17-V16)*80) -> 392 | BC16: =IF(OR(Z16=""),"",(Z17-Z16)*40) -> 1524 | BD16: =IF(OR(BE16="",BC16=""),"",BE16-BC16-BB16-BA16-AZ16-AT16-AO16-AJ16) -> 11147.2 | BE16: =IF(OR(B17=""),"",(B17-B16)*10000) -> 45100 | BF16: =IF(OR(AC17=""),"",AC17-AC16) -> 67.9 | BG16: =IF(OR($AD16=0),"",BE16/$AD16) -> 0.31457289 | BH16: =IF(OR($AD16=0),"",AJ16/$AD16) -> 0.046291737 | BI16: =IF(OR($AD16=0),"",AO16/$AD16) -> 0 | BJ16: =IF(OR($AD16=0),"",AT16/$AD16) -> 0.04045505 | BK16: =IF(OR($AD16=0),"",AZ16/$AD16) -> 0.087885108 | BL16: =IF(OR($AD16=0),"",BA16/$AD16) -> 0.04882506 | BM16: =IF(OR($AD16=0),"",BB16/$AD16) -> 0.0027342033 | BN16: =IF(OR($AD16=0),"",BC16/$AD16) -> 0.010629913 | BO16: =IF(OR($AD16=0),"",BD16/$AD16) -> 0.077751815
... A34: =A33+1 -> 44227 | B34: 15748.63 | C34: 85691.6 | D34: 54553.8 | E34: 55782 | F34: 3276.9 | G34: 108316.8 | H34: 5596.3 | I34: 2566.3 | J34: 967 | K34: 56 | L34: 87075.2 | M34: 61126.4 | N34: 69122.2 | O34: 98792 | P34: 5158 | Q34: 6973.5 | R34: 4232.6 | S34: 4868 | T34: 6009 | U34: 16612.3 | V34: 48903.7 | W34: 49282.1 | X34: 780.3 | Y34: 698.6 | Z34: =IF(OR(W34=""),"",(W34+X34+Y34)) -> 50761 | AA34: 55530.2 | AB34: 1020.2 | AC34: =IF(OR(AA34=""),"",(AA34+AB34)) -> 56550.4 | AD34: 138231 | AE34: =IF(OR(C35=""),"",(C35-C34)*80) -> 3872 | AF34: =IF(OR(D35=""),"",(D35-D34)*80) -> 936 | AG34: =IF(OR(E35=""),"",(E35-E34)*80) -> 0 | AH34: =IF(OR(F35=""),"",(F35-F34)*80) -> 10.4 | AI34: =IF(OR(G35=""),"",(G35-G34)*80) -> 2120 | AJ34: =IF(OR(AE34="",AF34="",AG34=""),"",AE34+AF34+AG34+AH34+AI34) -> 6938.4 | AK34: =IF(OR(H35=""),"",(H35-H34)*80) -> 0 | AL34: =IF(OR(I35=""),"",(I35-I34)*80) -> 0 | AM34: =IF(OR(J35=""),"",(J35-J34)*80) -> 0 | AN34: =IF(OR(K35=""),"",(K35-K34)*80) -> 0 | AO34: =IF(OR(AK34="",AL34=""),"",AK34+AL34+AM34+AN34) -> 0 | AP34: =IF(OR(L35=""),"",(L35-L34)*100) -> 1950 | AQ34: =IF(OR(M35=""),"",(M35-M34)*100) -> 10 | AR34: =IF(OR(N35=""),"",(N35-N34)*100) -> 810 | AS34: =IF(OR(O35=""),"",(O35-O34)*100) -> 2650 | AT34: =IF(OR(AP34="",AQ34=""),"",AP34+AQ34+AR34+AS34) -> 5420 | AU34: =IF(OR(P35=""),"",(P35-P34)*1000) -> 0 | AV34: =IF(OR(Q35=""),"",(Q35-Q34)*1000) -> 0 | AW34: =IF(OR(R35=""),"",(R35-R34)*1000) -> 4300 | AX34: =IF(OR(S35=""),"",(S35-S34)*1000) -> 5100 | AY34: =IF(OR(T35=""),"",(T35-T34)*1000) -> 0 | AZ34: =IF(OR(AU34="",AV34="",AW34=""),"",AU34+AV34+AW34+AX34+AY34) -> 9400 | BA34: =IF(OR(U35=""),"",(U35-U34)*2000) -> 7400 | BB34: =IF(OR(V35=""),"",(V35-V34)*80) -> 640 | BC34: =IF(OR(Z34=""),"",(Z35-Z34)*40) -> 1604 | BD34: =IF(OR(BE34="",BC34=""),"",BE34-BC34-BB34-BA34-AZ34-AT34-AO34-AJ34) -> 18697.6 | BE34: =IF(OR(B35=""),"",(B35-B34)*10000) -> 50100 | BF34: =IF(OR(AC35=""),"",AC35-AC34) -> 57.8 | BG34: =IF(OR($AD34=0),"",BE34/$AD34) -> 0.36243679 | BH34: =IF(OR($AD34=0),"",AJ34/$AD34) -> 0.05019424 | BI34: =IF(OR($AD34=0),"",AO34/$AD34) -> 0 | BJ34: =IF(OR($AD34=0),"",AT34/$AD34) -> 0.039209729 | BK34: =IF(OR($AD34=0),"",AZ34/$AD34) -> 0.068002112 | BL34: =IF(OR($AD34=0),"",BA34/$AD34) -> 0.053533578 | BM34: =IF(OR($AD34=0),"",BB34/$AD34) -> 0.0046299311 | BN34: =IF(OR($AD34=0),"",BC34/$AD34) -> 0.011603765 | BO34: =IF(OR($AD34=0),"",BD34/$AD34) -> 0.13526344
A35: =A34+1 -> 44228 | B35: 15753.64 | C35: 85740 | D35: 54565.5 | E35: 55782 | F35: 3277.03 | G35: 108343.3 | H35: 5596.3 | I35: 2566.3 | J35: 967 | K35: 56 | L35: 87094.7 | M35: 61126.5 | N35: 69130.3 | O35: 98818.5 | P35: 5158 | Q35: 6973.5 | R35: 4236.9 | S35: 4873.1 | T35: 6009 | U35: 16616 | V35: 48911.7 | W35: 49299.8 | X35: 794.1 | Y35: 707.2 | Z35: =IF(OR(W35=""),"",(W35+X35+Y35)) -> 50801.1 | AA35: 55577.2 | AB35: 1031 | AC35: =IF(OR(AA35=""),"",(AA35+AB35)) -> 56608.2 | BE35: 总水量 | BF35: 总电量 | BG35: =SUM(BE4:BE34) -> 1411800 | BH35: =SUM(AJ4:AJ34) -> 196832.8 | BI35: =SUM(AO4:AO34) -> 0 | BJ35: =SUM(AT4:AT34) -> 168560 | BK35: =SUM(AZ4:AZ34) -> 369700 | BL35: =SUM(BA4:BA34) -> 214000 | BM35: =SUM(BB4:BB34) -> 12936 | BN35: =SUM(BC4:BC34) -> 47960 | BO35: =SUM(BD4:BD34) -> 401811.2
BE36: =SUM(AD4:AD34) -> 4490455 | BF36: 总单耗 | BG36: =IF(OR(BG35=0),"",ROUND(BG35/$BE$36,3)) -> 0.314 | BH36: =IF(OR(BH35=0),"",ROUND(BH35/$BE$36,4)) -> 0.0438 | BI36: =IF(OR(BI35=0),"",ROUND(BI35/$BE$36,4)) | BJ36: =IF(OR(BJ35=0),"",ROUND(BJ35/$BE$36,4)) -> 0.0375 | BK36: =IF(OR(BK35=0),"",ROUND(BK35/$BE$36,4)) -> 0.0823 | BL36: =IF(OR(BL35=0),"",ROUND(BL35/$BE$36,4)) -> 0.0477 | BM36: =IF(OR(BM35=0),"",ROUND(BM35/$BE$36,4)) -> 0.0029 | BN36: =IF(OR(BN35=0),"",ROUND(BN35/$BE$36,4)) -> 0.0107 | BO36: =IF(OR(BO35=0),"",ROUND(BO35/$BE$36,4)) -> 0.0895

Sheet 2
B2: 高配电 表计数 | C2: 一次提升 | H2: 二次提升 | L2: 三次提升 | P2: 高压鼓风机 | U2: 提标 电表 | V2: 脱水 电表 | W2: 旧除臭 电表 | X2: 新除臭电表 | Z2: 除臭 总电表 | AA2: 旧除臭 水表 | AB2: 新除臭 水表 | AC2: 除臭 总水表 | AD2: 实际处 理水量 | AE2: 一次提升用电 | AK2: 二次提升 | AP2: 三次提升 | AU2: 高压鼓风机 | BA2: 提标电量 | BB2: 脱水电量 | BC2: 除臭电量 | BD2: 其他用电量 | BE2: 总电量 | BF2: 除臭水量 | BG2: 总单耗 | BH2: 一次提 升单耗 | BI2: 二次提 升单耗 | BJ2: 三次提 升单耗 | BK2: 风机 单耗 | BL2: 提标 总单耗 | BM2: 脱水 单耗 | BN2: 除臭 单耗 | BO2: 其他 单耗
C3: 1#泵 | D3: 2#泵 | E3: 3#泵 | F3: 4#泵 | G3: 5#泵 | H3: 1#泵 | I3: 2#泵 | J3: 3#泵 | K3: 4#泵 | L3: 1#泵 | M3: 2#泵 | N3: 3#泵 | O3: 4#泵 | P3: 1#风机 | Q3: 2#风机 | R3: 3#风机 | S3: 4#风机 | T3: 5#风机 | X3: 1# | Y3: 2# | AE3: 1#泵 | AF3: 2#泵 | AG3: 3#泵 | AH3: 4#泵 | AI3: 5#泵 | AJ3: 提升电量 | AK3: 1#泵 | AL3: 2#泵 | AM3: 3#泵 | AN3: 4#泵 | AO3: 提升电量 | AP3: 1#泵 | AQ3: 2#泵 | AR3: 3#泵 | AS3: 4#泵 | AT3: 提升电量 | AU3: 1#风机 | AV3: 2#风机 | AW3: 3#风机 | AX3: 4#风机 | AY3: 5#风机 | AZ3: 风机电量
A4: ='1'!A35 -> 44228 | B4: 15753.64 | C4: 85740 | D4: 54565.5 | E4: 55782 | F4: 3277.03 | G4: 108343.3 | H4: 5596.3 | I4: 2566.3 | J4: 967 | K4: 56 | L4: 87094.7 | M4: 61126.5 | N4: 69130.3 | O4: 98818.5 | P4: 5158 | Q4: 6973.5 | R4: 4236.9 | S4: 4873.1 | T4: 6009 | U4: 16616 | V4: 48911.7 | W4: 49299.8 | X4: 794.1 | Y4: 707.2 | Z4: =IF(OR(W4=""),"",(W4+X4+Y4)) -> 50801.1 | AA4: 55577.2 | AB4: 1031 | AC4: =IF(OR(AA4=""),"",(AA4+AB4)) -> 56608.2 | AD4: 154968 | AE4: =IF(OR(C5=""),"",(C5-C4)*80) -> 328 | AF4: =IF(OR(D5=""),"",(D5-D4)*80) -> 1048 | AG4: =IF(OR(E5=""),"",(E5-E4)*80) -> 0 | AH4: =IF(OR(F5=""),"",(F5-F4)*80) -> 1385.6 | AI4: =IF(OR(G5=""),"",(G5-G4)*80) -> 2368 | AJ4: =IF(OR(AE4="",AF4="",AG4=""),"",AE4+AF4+AG4+AH4+AI4) -> 5129.6 | AK4: =IF(OR(H5=""),"",(H5-H4)*80) -> 0 | AL4: =IF(OR(I5=""),"",(I5-I4)*80) -> 0 | AM4: =IF(OR(J5=""),"",(J5-J4)*80) -> 0 | AN4: =IF(OR(K5=""),"",(K5-K4)*80) -> 0 | AO4: =IF(OR(AK4="",AL4=""),"",AK4+AL4+AM4+AN4) -> 0 | AP4: =IF(OR(L5=""),"",(L5-L4)*100) -> 1330 | AQ4: =IF(OR(M5=""),"",(M5-M4)*100) -> 0 | AR4: =IF(OR(N5=""),"",(N5-N4)*100) -> 1940 | AS4: =IF(OR(O5=""),"",(O5-O4)*100) -> 2550 | AT4: =IF(OR(AP4="",AQ4=""),"",AP4+AQ4+AR4+AS4) -> 5820 | AU4: =IF(OR(P5=""),"",(P5-P4)*1000) -> 100 | AV4: =IF(OR(Q5=""),"",(Q5-Q4)*1000) -> 100 | AW4: =IF(OR(R5=""),"",(R5-R4)*1000) -> 4500 | AX4: =IF(OR(S5=""),"",(S5-S4)*1000) -> 5300 | AY4: =IF(OR(T5=""),"",(T5-T4)*1000) -> 100 | AZ4: =IF(OR(AU4="",AV4="",AW4=""),"",AU4+AV4+AW4+AX4+AY4) -> 10100 | BA4: =IF(OR(U5=""),"",(U5-U4)*2000) -> 9600 | BB4: =IF(OR(V5=""),"",(V5-V4)*80) -> 520 | BC4: =IF(OR(Z4=""),"",(Z5-Z4)*40) -> 1928 | BD4: =IF(OR(BE4="",BC4=""),"",BE4-BC4-BB4-BA4-AZ4-AT4-AO4-AJ4) -> 13802.4 | BE4: =IF(OR(B5=""),"",(B5-B4)*10000) -> 46900 | BF4: =IF(OR(AC5=""),"",AC5-AC4) -> 53.7 | BG4: =IF(OR($AD4=0),"",BE4/$AD4) -> 0.30264313 | BH4: =IF(OR($AD4=0),"",AJ4/$AD4) -> 0.033101027 | BI4: =IF(OR($AD4=0),"",AO4/$AD4) -> 0 | BJ4: =IF(OR($AD4=0),"",AT4/$AD4) -> 0.037556141 | BK4: =IF(OR($AD4=0),"",AZ4/$AD4) -> 0.065174746 | BL4: =IF(OR($AD4=0),"",BA4/$AD4) -> 0.061948273 | BM4: =IF(OR($AD4=0),"",BB4/$AD4) -> 0.0033555315 | BN4: =IF(OR($AD4=0),"",BC4/$AD4) -> 0.012441278 | BO4: =IF(OR($AD4=0),"",BD4/$AD4) -> 0.08906613
A5: =A4+1 -> 44229 | B5: 15758.33 | C5: 85744.1 | D5: 54578.6 | E5: 55782 | F5: 3294.35 | G5: 108372.9 | H5: 5596.3 | I5: 2566.3 | J5: 967 | K5: 56 | L5: 87108 | M5: 61126.5 | N5: 69149.7 | O5: 98844 | P5: 5158.1 | Q5: 6973.6 | R5: 4241.4 | S5: 4878.4 | T5: 6009.1 | U5: 16620.8 | V5: 48918.2 | W5: 49317.3 | X5: 870.6 | Y5: 715.5 | Z5: 50849.3 | AA5: 55621.9 | AB5: 1040 | AC5: =IF(OR(AA5=""),"",(AA5+AB5)) -> 56661.9 | AD5: 146471 | AE5: =IF(OR(C6=""),"",(C6-C5)*80) -> 0 | AF5: =IF(OR(D6=""),"",(D6-D5)*80) -> 32 | AG5: =IF(OR(E6=""),"",(E6-E5)*80) -> 0 | AH5: =IF(OR(F6=""),"",(F6-F5)*80) -> 2465.6 | AI5: =IF(OR(G6=""),"",(G6-G5)*80) -> 2624 | AJ5: =IF(OR(AE5="",AF5="",AG5=""),"",AE5+AF5+AG5+AH5+AI5) -> 5121.6 | AK5: =IF(OR(H6=""),"",(H6-H5)*80) -> 0 | AL5: =IF(OR(I6=""),"",(I6-I5)*80) -> 0 | AM5: =IF(OR(J6=""),"",(J6-J5)*80) -> 0 | AN5: =IF(OR(K6=""),"",(K6-K5)*80) -> 0 | AO5: =IF(OR(AK5="",AL5=""),"",AK5+AL5+AM5+AN5) -> 0 | AP5: =IF(OR(L6=""),"",(L6-L5)*100) -> 1280 | AQ5: =IF(OR(M6=""),"",(M6-M5)*100) -> 0 | AR5: =IF(OR(N6=""),"",(N6-N5)*100) -> 1830 | AS5: =IF(OR(O6=""),"",(O6-O5)*100) -> 2450 | AT5: =IF(OR(AP5="",AQ5=""),"",AP5+AQ5+AR5+AS5) -> 5560 | AU5: =IF(OR(P6=""),"",(P6-P5)*1000) -> 0 | AV5: =IF(OR(Q6=""),"",(Q6-Q5)*1000) -> 7900 | AW5: =IF(OR(R6=""),"",(R6-R5)*1000) -> 0 | AX5: =IF(OR(S6=""),"",(S6-S5)*1000) -> 5200 | AY5: =IF(OR(T6=""),"",(T6-T5)*1000) -> 0 | AZ5: =IF(OR(AU5="",AV5="",AW5=""),"",AU5+AV5+AW5+AX5+AY5) -> 13100 | BA5: =IF(OR(U6=""),"",(U6-U5)*2000) -> 7000 | BB5: =IF(OR(V6=""),"",(V6-V5)*80) -> 608 | BC5: =IF(OR(Z5=""),"",(Z6-Z5)*40) -> 1236 | BD5: =IF(OR(BE5="",BC5=""),"",BE5-BC5-BB5-BA5-AZ5-AT5-AO5-AJ5) -> 14974.4 | BE5: =IF(OR(B6=""),"",(B6-B5)*10000) -> 47600 | BF5: =IF(OR(AC6=""),"",AC6-AC5) -> 54.4 | BG5: =IF(OR($AD5=0),"",BE5/$AD5) -> 0.32497901 | BH5: =IF(OR($AD5=0),"",AJ5/$AD5) -> 0.034966649 | BI5: =IF(OR($AD5=0),"",AO5/$AD5) -> 0 | BJ5: =IF(OR($AD5=0),"",AT5/$AD5) -> 0.037959733 | BK5: =IF(OR($AD5=0),"",AZ5/$AD5) -> 0.0894375 | BL5: =IF(OR($AD5=0),"",BA5/$AD5) -> 0.04779103 | BM5: =IF(OR($AD5=0),"",BB5/$AD5) -> 0.0041509923 | BN5: =IF(OR($AD5=0),"",BC5/$AD5) -> 0.0084385305 | BO5: =IF(OR($AD5=0),"",BD5/$AD5) -> 0.10223457
A6: =A5+1 -> 44230 | B6: 15763.09 | C6: 85744.1 | D6: 54579 | E6: 55782 | F6: 3325.17 | G6: 108405.7 | H6: 5596.3 | I6: 2566.3 | J6: 967 | K6: 56 | L6: 87120.8 | M6: 61126.5 | N6: 69168 | O6: 98868.5 | P6: 5158.1 | Q6: 6981.5 | R6: 4241.4 | S6: 4883.6 | T6: 6009.1 | U6: 16624.3 | V6: 48925.8 | W6: 49335 | X6: 821.2 | Y6: 724 | Z6: =IF(OR(W6=""),"",(W6+X6+Y6)) -> 50880.2 | AA6: 55667.3 | AB6: 1049 | AC6: =IF(OR(AA6=""),"",(AA6+AB6)) -> 56716.3 | AD6: 137546 | AE6: =IF(OR(C7=""),"",(C7-C6)*80) -> 0 | AF6: =IF(OR(D7=""),"",(D7-D6)*80) -> 856 | AG6: =IF(OR(E7=""),"",(E7-E6)*80) -> 0 | AH6: =IF(OR(F7=""),"",(F7-F6)*80) -> 1743.2 | AI6: =IF(OR(G7=""),"",(G7-G6)*80) -> 2104 | AJ6: =IF(OR(AE6="",AF6="",AG6=""),"",AE6+AF6+AG6+AH6+AI6) -> 4703.2 | AK6: =IF(OR(H7=""),"",(H7-H6)*80) -> 0 | AL6: =IF(OR(I7=""),"",(I7-I6)*80) -> 0 | AM6: =IF(OR(J7=""),"",(J7-J6)*80) -> 0 | AN6: =IF(OR(K7=""),"",(K7-K6)*80) -> 0 | AO6: =IF(OR(AK6="",AL6=""),"",AK6+AL6+AM6+AN6) -> 0 | AP6: =IF(OR(L7=""),"",(L7-L6)*100) -> 2690 | AQ6: =IF(OR(M7=""),"",(M7-M6)*100) -> 0 | AR6: =IF(OR(N7=""),"",(N7-N6)*100) -> 0 | AS6: =IF(OR(O7=""),"",(O7-O6)*100) -> 2510 | AT6: =IF(OR(AP6="",AQ6=""),"",AP6+AQ6+AR6+AS6) -> 5200 | AU6: =IF(OR(P7=""),"",(P7-P6)*1000) -> 0 | AV6: =IF(OR(Q7=""),"",(Q7-Q6)*1000) -> 7500 | AW6: =IF(OR(R7=""),"",(R7-R6)*1000) -> 300 | AX6: =IF(OR(S7=""),"",(S7-S6)*1000) -> 5000 | AY6: =IF(OR(T7=""),"",(T7-T6)*1000) -> 0 | AZ6: =IF(OR(AU6="",AV6="",AW6=""),"",AU6+AV6+AW6+AX6+AY6) -> 12800 | BA6: =IF(OR(U7=""),"",(U7-U6)*2000) -> 7400 | BB6: =IF(OR(V7=""),"",(V7-V6)*80) -> 608 | BC6: =IF(OR(Z6=""),"",(Z7-Z6)*40) -> 1544 | BD6: =IF(OR(BE6="",BC6=""),"",BE6-BC6-BB6-BA6-AZ6-AT6-AO6-AJ6) -> 13044.8 | BE6: =IF(OR(B7=""),"",(B7-B6)*10000) -> 45300 | BF6: =IF(OR(AC7=""),"",AC7-AC6) -> 57.3 | BG6: =IF(OR($AD6=0),"",BE6/$AD6) -> 0.32934436 | BH6: =IF(OR($AD6=0),"",AJ6/$AD6) -> 0.034193652 | BI6: =IF(OR($AD6=0),"",AO6/$AD6) -> 0 | BJ6: =IF(OR($AD6=0),"",AT6/$AD6) -> 0.037805534 | BK6: =IF(OR($AD6=0),"",AZ6/$AD6) -> 0.093059776 | BL6: =IF(OR($AD6=0),"",BA6/$AD6) -> 0.053800183 | BM6: =IF(OR($AD6=0),"",BB6/$AD6) -> 0.0044203394 | BN6: =IF(OR($AD6=0),"",BC6/$AD6) -> 0.011225336 | BO6: =IF(OR($AD6=0),"",BD6/$AD6) -> 0.094839545
A7: =A6+1 -> 44231 | B7: 15767.62 | C7: 85744.1 | D7: 54589.7 | E7: 55782 | F7: 3346.96 | G7: 108432 | H7: 5596.3 | I7: 2566.3 | J7: 967 | K7: 56 | L7: 87147.7 | M7: 61126.5 | N7: 69168 | O7: 98893.6 | P7: 5158.1 | Q7: 6989 | R7: 4241.7 | S7: 4888.6 | T7: 6009.1 | U7: 16628 | V7: 48933.4 | W7: 49352.6 | X7: 833.5 | Y7: 732.7 | Z7: =IF(OR(W7=""),"",(W7+X7+Y7)) -> 50918.8 | AA7: 55712.6 | AB7: 1061 | AC7: =IF(OR(AA7=""),"",(AA7+AB7)) -> 56773.6 | AD7: 137858 | AE7: =IF(OR(C8=""),"",(C8-C7)*80) -> 0 | AF7: =IF(OR(D8=""),"",(D8-D7)*80) -> 248 | AG7: =IF(OR(E8=""),"",(E8-E7)*80) -> 0 | AH7: =IF(OR(F8=""),"",(F8-F7)*80) -> 2228 | AI7: =IF(OR(G8=""),"",(G8-G7)*80) -> 2248 | AJ7: =IF(OR(AE7="",AF7="",AG7=""),"",AE7+AF7+AG7+AH7+AI7) -> 4724 | AK7: =IF(OR(H8=""),"",(H8-H7)*80) -> 0 | AL7: =IF(OR(I8=""),"",(I8-I7)*80) -> 0 | AM7: =IF(OR(J8=""),"",(J8-J7)*80) -> 0 | AN7: =IF(OR(K8=""),"",(K8-K7)*80) -> 0 | AO7: =IF(OR(AK7="",AL7=""),"",AK7+AL7+AM7+AN7) -> 0 | AP7: =IF(OR(L8=""),"",(L8-L7)*100) -> 2000 | AQ7: =IF(OR(M8=""),"",(M8-M7)*100) -> 0 | AR7: =IF(OR(N8=""),"",(N8-N7)*100) -> 710 | AS7: =IF(OR(O8=""),"",(O8-O7)*100) -> 2350 | AT7: =IF(OR(AP7="",AQ7=""),"",AP7+AQ7+AR7+AS7) -> 5060 | AU7: =IF(OR(P8=""),"",(P8-P7)*1000) -> 0 | AV7: =IF(OR(Q8=""),"",(Q8-Q7)*1000) -> 8100 | AW7: =IF(OR(R8=""),"",(R8-R7)*1000) -> 0 | AX7: =IF(OR(S8=""),"",(S8-S7)*1000) -> 5300 | AY7: =IF(OR(T8=""),"",(T8-T7)*1000) -> 0 | AZ7: =IF(OR(AU7="",AV7="",AW7=""),"",AU7+AV7+AW7+AX7+AY7) -> 13400 | BA7: =IF(OR(U8=""),"",(U8-U7)*2000) -> 7600 | BB7: =IF(OR(V8=""),"",(V8-V7)*80) -> 608 | BC7: =IF(OR(Z7=""),"",(Z8-Z7)*40) -> 1596 | BD7: =IF(OR(BE7="",BC7=""),"",BE7-BC7-BB7-BA7-AZ7-AT7-AO7-AJ7) -> 12412 | BE7: =IF(OR(B8=""),"",(B8-B7)*10000) -> 45400 | BF7: =IF(OR(AC8=""),"",AC8-AC7) -> 51.2 | BG7: =IF(OR($AD7=0),"",BE7/$AD7) -> 0.32932438 | BH7: =IF(OR($AD7=0),"",AJ7/$AD7) -> 0.034267144 | BI7: =IF(OR($AD7=0),"",AO7/$AD7) -> 0 | BJ7: =IF(OR($AD7=0),"",AT7/$AD7) -> 0.036704435 | BK7: =IF(OR($AD7=0),"",AZ7/$AD7) -> 0.097201468 | BL7: =IF(OR($AD7=0),"",BA7/$AD7) -> 0.055129191 | BM7: =IF(OR($AD7=0),"",BB7/$AD7) -> 0.0044103353 | BN7: =IF(OR($AD7=0),"",BC7/$AD7) -> 0.01157713 | BO7: =IF(OR($AD7=0),"",BD7/$AD7) -> 0.090034673
A8: =A7+1 -> 44232 | B8: 15772.16 | C8: 85744.1 | D8: 54592.8 | E8: 55782 | F8: 3374.81 | G8: 108460.1 | H8: 5596.3 | I8: 2566.3 | J8: 967 | K8: 56 | L8: 87167.7 | M8: 61126.5 | N8: 69175.1 | O8: 98917.1 | P8: 5158.1 | Q8: 6997.1 | R8: 4241.7 | S8: 4893.9 | T8: 6009.1 | U8: 16631.8 | V8: 48941 | W8: 49370.3 | X8: 847.1 | Y8: 741.3 | Z8: =IF(OR(W8=""),"",(W8+X8+Y8)) -> 50958.7 | AA8: 55755.8 | AB8: 1069 | AC8: =IF(OR(AA8=""),"",(AA8+AB8)) -> 56824.8 | AD8: 123328 | AE8: =IF(OR(C9=""),"",(C9-C8)*80) -> 0 | AF8: =IF(OR(D9=""),"",(D9-D8)*80) -> 424 | AG8: =IF(OR(E9=""),"",(E9-E8)*80) -> 0 | AH8: =IF(OR(F9=""),"",(F9-F8)*80) -> 1599.2 | AI8: =IF(OR(G9=""),"",(G9-G8)*80) -> 2248 | AJ8: =IF(OR(AE8="",AF8="",AG8=""),"",AE8+AF8+AG8+AH8+AI8) -> 4271.2 | AK8: =IF(OR(H9=""),"",(H9-H8)*80) -> 0 | AL8: =IF(OR(I9=""),"",(I9-I8)*80) -> 0 | AM8: =IF(OR(J9=""),"",(J9-J8)*80) -> 0 | AN8: =IF(OR(K9=""),"",(K9-K8)*80) -> 0 | AO8: =IF(OR(AK8="",AL8=""),"",AK8+AL8+AM8+AN8) -> 0 | AP8: =IF(OR(L9=""),"",(L9-L8)*100) -> 2220 | AQ8: =IF(OR(M9=""),"",(M9-M8)*100) -> 0 | AR8: =IF(OR(N9=""),"",(N9-N8)*100) -> 0 | AS8: =IF(OR(O9=""),"",(O9-O8)*100) -> 2520 | AT8: =IF(OR(AP8="",AQ8=""),"",AP8+AQ8+AR8+AS8) -> 4740 | AU8: =IF(OR(P9=""),"",(P9-P8)*1000) -> 1900 | AV8: =IF(OR(Q9=""),"",(Q9-Q8)*1000) -> 2500 | AW8: =IF(OR(R9=""),"",(R9-R8)*1000) -> 2700 | AX8: =IF(OR(S9=""),"",(S9-S8)*1000) -> 3500 | AY8: =IF(OR(T9=""),"",(T9-T8)*1000) -> 0 | AZ8: =IF(OR(AU8="",AV8="",AW8=""),"",AU8+AV8+AW8+AX8+AY8) -> 10600 | BA8: =IF(OR(U9=""),"",(U9-U8)*2000) -> 6400 | BB8: =IF(OR(V9=""),"",(V9-V8)*80) -> 904 | BC8: =IF(OR(Z8=""),"",(Z9-Z8)*40) -> 1556 | BD8: =IF(OR(BE8="",BC8=""),"",BE8-BC8-BB8-BA8-AZ8-AT8-AO8-AJ8) -> 16628.8 | BE8: =IF(OR(B9=""),"",(B9-B8)*10000) -> 45100 | BF8: =IF(OR(AC9=""),"",AC9-AC8) -> 52.3 | BG8: =IF(OR($AD8=0),"",BE8/$AD8) -> 0.36569149 | BH8: =IF(OR($AD8=0),"",AJ8/$AD8) -> 0.034632849 | BI8: =IF(OR($AD8=0),"",AO8/$AD8) -> 0 | BJ8: =IF(OR($AD8=0),"",AT8/$AD8) -> 0.038434094 | BK8: =IF(OR($AD8=0),"",AZ8/$AD8) -> 0.085949663 | BL8: =IF(OR($AD8=0),"",BA8/$AD8) -> 0.051894136 | BM8: =IF(OR($AD8=0),"",BB8/$AD8) -> 0.0073300467 | BN8: =IF(OR($AD8=0),"",BC8/$AD8) -> 0.012616762 | BO8: =IF(OR($AD8=0),"",BD8/$AD8) -> 0.13483394
A9: =A8+1 -> 44233 | B9: 15776.67 | C9: 85744.1 | D9: 54598.1 | E9: 55782 | F9: 3394.8 | G9: 108488.2 | H9: 5596.3 | I9: 2566.3 | J9: 967 | K9: 56 | L9: 87189.9 | M9: 61126.5 | N9: 69175.1 | O9: 98942.3 | P9: 5160 | Q9: 6999.6 | R9: 4244.4 | S9: 4897.4 | T9: 6009.1 | U9: 16635 | V9: 48952.3 | W9: 49387.8 | X9: 860.3 | Y9: 749.5 | Z9: =IF(OR(W9=""),"",(W9+X9+Y9)) -> 50997.6 | AA9: 55800.1 | AB9: 1077 | AC9: =IF(OR(AA9=""),"",(AA9+AB9)) -> 56877.1 | AD9: 91756 | AE9: =IF(OR(C10=""),"",(C10-C9)*80) -> 3520 | AF9: =IF(OR(D10=""),"",(D10-D9)*80) -> 0 | AG9: =IF(OR(E10=""),"",(E10-E9)*80) -> 0 | AH9: =IF(OR(F10=""),"",(F10-F9)*80) -> 3.2 | AI9: =IF(OR(G10=""),"",(G10-G9)*80) -> 1904 | AJ9: =IF(OR(AE9="",AF9="",AG9=""),"",AE9+AF9+AG9+AH9+AI9) -> 5427.2 | AK9: =IF(OR(H10=""),"",(H10-H9)*80) -> 0 | AL9: =IF(OR(I10=""),"",(I10-I9)*80) -> 0 | AM9: =IF(OR(J10=""),"",(J10-J9)*80) -> 0 | AN9: =IF(OR(K10=""),"",(K10-K9)*80) -> 0 | AO9: =IF(OR(AK9="",AL9=""),"",AK9+AL9+AM9+AN9) -> 0 | AP9: =IF(OR(L10=""),"",(L10-L9)*100) -> 1790 | AQ9: =IF(OR(M10=""),"",(M10-M9)*100) -> 0 | AR9: =IF(OR(N10=""),"",(N10-N9)*100) -> 110 | AS9: =IF(OR(O10=""),"",(O10-O9)*100) -> 1650 | AT9: =IF(OR(AP9="",AQ9=""),"",AP9+AQ9+AR9+AS9) -> 3550 | AU9: =IF(OR(P10=""),"",(P10-P9)*1000) -> 1100 | AV9: =IF(OR(Q10=""),"",(Q10-Q9)*1000) -> 100 | AW9: =IF(OR(R10=""),"",(R10-R9)*1000) -> 3000 | AX9: =IF(OR(S10=""),"",(S10-S9)*1000) -> 4300 | AY9: =IF(OR(T10=""),"",(T10-T9)*1000) -> 0 | AZ9: =IF(OR(AU9="",AV9="",AW9=""),"",AU9+AV9+AW9+AX9+AY9) -> 8500 | BA9: =IF(OR(U10=""),"",(U10-U9)*2000) -> 4800 | BB9: =IF(OR(V10=""),"",(V10-V9)*80) -> 1112 | BC9: =IF(OR(Z9=""),"",(Z10-Z9)*40) -> 1336 | BD9: =IF(OR(BE9="",BC9=""),"",BE9-BC9-BB9-BA9-AZ9-AT9-AO9-AJ9) -> 15374.8 | BE9: =IF(OR(B10=""),"",(B10-B9)*10000) -> 40100 | BF9: =IF(OR(AC10=""),"",AC10-AC9) -> 53.1 | BG9: =IF(OR($AD9=0),"",BE9/$AD9) -> 0.43702864 | BH9: =IF(OR($AD9=0),"",AJ9/$AD9) -> 0.059148176 | BI9: =IF(OR($AD9=0),"",AO9/$AD9) -> 0 | BJ9: =IF(OR($AD9=0),"",AT9/$AD9) -> 0.038689568 | BK9: =IF(OR($AD9=0),"",AZ9/$AD9) -> 0.092636994 | BL9: =IF(OR($AD9=0),"",BA9/$AD9) -> 0.052312655 | BM9: =IF(OR($AD9=0),"",BB9/$AD9) -> 0.012119098 | BN9: =IF(OR($AD9=0),"",BC9/$AD9) -> 0.014560356 | BO9: =IF(OR($AD9=0),"",BD9/$AD9) -> 0.16756179
A10: =A9+1 -> 44234 | B10: 15780.68 | C10: 85788.1 | D10: 54598.1 | E10: 55782 | F10: 3394.84 | G10: 108512 | H10: 5596.3 | I10: 2566.3 | J10: 967 | K10: 56 | L10: 87207.8 | M10: 61126.5 | N10: 69176.2 | O10: 98958.8 | P10: 5161.1 | Q10: 6999.7 | R10: 4247.4 | S10: 4901.7 | T10: 6009.1 | U10: 16637.4 | V10: 48966.2 | W10: 49405.3 | X10: 873.6 | Y10: 752.1 | Z10: =IF(OR(W10=""),"",(W10+X10+Y10)) -> 51031 | AA10: 55844.2 | AB10: 1086 | AC10: =IF(OR(AA10=""),"",(AA10+AB10)) -> 56930.2 | AD10: 110987 | AE10: =IF(OR(C11=""),"",(C11-C10)*80) -> 40 | AF10: =IF(OR(D11=""),"",(D11-D10)*80) -> 2664 | AG10: =IF(OR(E11=""),"",(E11-E10)*80) -> 0 | AH10: =IF(OR(F11=""),"",(F11-F10)*80) -> 4.8 | AI10: =IF(OR(G11=""),"",(G11-G10)*80) -> 2008 | AJ10: =IF(OR(AE10="",AF10="",AG10=""),"",AE10+AF10+AG10+AH10+AI10) -> 4716.8 | AK10: =IF(OR(H11=""),"",(H11-H10)*80) -> 0 | AL10: =IF(OR(I11=""),"",(I11-I10)*80) -> 0 | AM10: =IF(OR(J11=""),"",(J11-J10)*80) -> 0 | AN10: =IF(OR(K11=""),"",(K11-K10)*80) -> 0 | AO10: =IF(OR(AK10="",AL10=""),"",AK10+AL10+AM10+AN10) -> 0 | AP10: =IF(OR(L11=""),"",(L11-L10)*100) -> 2000 | AQ10: =IF(OR(M11=""),"",(M11-M10)*100) -> 0 | AR10: =IF(OR(N11=""),"",(N11-N10)*100) -> 0 | AS10: =IF(OR(O11=""),"",(O11-O10)*100) -> 2130 | AT10: =IF(OR(AP10="",AQ10=""),"",AP10+AQ10+AR10+AS10) -> 4130 | AU10: =IF(OR(P11=""),"",(P11-P10)*1000) -> 3600 | AV10: =IF(OR(Q11=""),"",(Q11-Q10)*1000) -> 4600 | AW10: =IF(OR(R11=""),"",(R11-R10)*1000) -> 400 | AX10: =IF(OR(S11=""),"",(S11-S10)*1000) -> 2300 | AY10: =IF(OR(T11=""),"",(T11-T10)*1000) -> 0 | AZ10: =IF(OR(AU10="",AV10="",AW10=""),"",AU10+AV10+AW10+AX10+AY10) -> 10900 | BA10: =IF(OR(U11=""),"",(U11-U10)*2000) -> 5400 | BB10: =IF(OR(V11=""),"",(V11-V10)*80) -> 1088 | BC10: =IF(OR(Z10=""),"",(Z11-Z10)*40) -> 1504 | BD10: =IF(OR(BE10="",BC10=""),"",BE10-BC10-BB10-BA10-AZ10-AT10-AO10-AJ10) -> 14861.2 | BE10: =IF(OR(B11=""),"",(B11-B10)*10000) -> 42600 | BF10: =IF(OR(AC11=""),"",AC11-AC10) -> 68.6 | BG10: =IF(OR($AD10=0),"",BE10/$AD10) -> 0.38382874 | BH10: =IF(OR($AD10=0),"",AJ10/$AD10) -> 0.042498671 | BI10: =IF(OR($AD10=0),"",AO10/$AD10) -> 0 | BJ10: =IF(OR($AD10=0),"",AT10/$AD10) -> 0.037211565 | BK10: =IF(OR($AD10=0),"",AZ10/$AD10) -> 0.0982097 | BL10: =IF(OR($AD10=0),"",BA10/$AD10) -> 0.048654347 | BM10: =IF(OR($AD10=0),"",BB10/$AD10) -> 0.0098029499 | BN10: =IF(OR($AD10=0),"",BC10/$AD10) -> 0.013551137 | BO10: =IF(OR($AD10=0),"",BD10/$AD10) -> 0.13390037
A11: =A10+1 -> 44235 | B11: 15784.94 | C11: 85788.6 | D11: 54631.4 | E11: 55782 | F11: 3394.9 | G11: 108537.1 | H11: 5596.3 | I11: 2566.3 | J11: 967 | K11: 56 | L11: 87227.8 | M11: 61126.5 | N11: 69176.2 | O11: 98980.1 | P11: 5164.7 | Q11: 7004.3 | R11: 4247.8 | S11: 4904 | T11: 6009.1 | U11: 16640.1 | V11: 48979.8 | W11: 49422.6 | X11: 887.1 | Y11: 758.9 | Z11: =IF(OR(W11=""),"",(W11+X11+Y11)) -> 51068.6 | AA11: 55886.8 | AB11: 1112 | AC11: =IF(OR(AA11=""),"",(AA11+AB11)) -> 56998.8 | AD11: 97203 | AE11: =IF(OR(C12=""),"",(C12-C11)*80) -> 0 | AF11: =IF(OR(D12=""),"",(D12-D11)*80) -> 2528 | AG11: =IF(OR(E12=""),"",(E12-E11)*80) -> 0 | AH11: =IF(OR(F12=""),"",(F12-F11)*80) -> 4.8 | AI11: =IF(OR(G12=""),"",(G12-G11)*80) -> 1848 | AJ11: =IF(OR(AE11="",AF11="",AG11=""),"",AE11+AF11+AG11+AH11+AI11) -> 4380.8 | AK11: =IF(OR(H12=""),"",(H12-H11)*80) -> 0 | AL11: =IF(OR(I12=""),"",(I12-I11)*80) -> 0 | AM11: =IF(OR(J12=""),"",(J12-J11)*80) -> 0 | AN11: =IF(OR(K12=""),"",(K12-K11)*80) -> 0 | AO11: =IF(OR(AK11="",AL11=""),"",AK11+AL11+AM11+AN11) -> 0 | AP11: =IF(OR(L12=""),"",(L12-L11)*100) -> 1540 | AQ11: =IF(OR(M12=""),"",(M12-M11)*100) -> 0 | AR11: =IF(OR(N12=""),"",(N12-N11)*100) -> 0 | AS11: =IF(OR(O12=""),"",(O12-O11)*100) -> 2080 | AT11: =IF(OR(AP11="",AQ11=""),"",AP11+AQ11+AR11+AS11) -> 3620 | AU11: =IF(OR(P12=""),"",(P12-P11)*1000) -> 2200 | AV11: =IF(OR(Q12=""),"",(Q12-Q11)*1000) -> 5300 | AW11: =IF(OR(R12=""),"",(R12-R11)*1000) -> 2700 | AX11: =IF(OR(S12=""),"",(S12-S11)*1000) -> 1700 | AY11: =IF(OR(T12=""),"",(T12-T11)*1000) -> 0 | AZ11: =IF(OR(AU11="",AV11="",AW11=""),"",AU11+AV11+AW11+AX11+AY11) -> 11900 | BA11: =IF(OR(U12=""),"",(U12-U11)*2000) -> 5000 | BB11: =IF(OR(V12=""),"",(V12-V11)*80) -> 1120 | BC11: =IF(OR(Z11=""),"",(Z12-Z11)*40) -> 1604 | BD11: =IF(OR(BE11="",BC11=""),"",BE11-BC11-BB11-BA11-AZ11-AT11-AO11-AJ11) -> 16175.2 | BE11: =IF(OR(B12=""),"",(B12-B11)*10000) -> 43800 | BF11: =IF(OR(AC12=""),"",AC12-AC11) -> 75 | BG11: =IF(OR($AD11=0),"",BE11/$AD11) -> 0.45060338 | BH11: =IF(OR($AD11=0),"",AJ11/$AD11) -> 0.045068568 | BI11: =IF(OR($AD11=0),"",AO11/$AD11) -> 0 | BJ11: =IF(OR($AD11=0),"",AT11/$AD11) -> 0.037241649 | BK11: =IF(OR($AD11=0),"",AZ11/$AD11) -> 0.12242421 | BL11: =IF(OR($AD11=0),"",BA11/$AD11) -> 0.051438742 | BM11: =IF(OR($AD11=0),"",BB11/$AD11) -> 0.011522278 | BN11: =IF(OR($AD11=0),"",BC11/$AD11) -> 0.016501548 | BO11: =IF(OR($AD11=0),"",BD11/$AD11) -> 0.16640639
A12: =A11+1 -> 44236 | B12: 15789.32 | C12: 85788.6 | D12: 54663 | E12: 55782 | F12: 3394.96 | G12: 108560.2 | H12: 5596.3 | I12: 2566.3 | J12: 967 | K12: 56 | L12: 87243.2 | M12: 61126.5 | N12: 69176.2 | O12: 99000.9 | P12: 5166.9 | Q12: 7009.6 | R12: 4250.5 | S12: 4905.7 | T12: 6009.1 | U12: 16642.6 | V12: 48993.8 | W12: 49440.6 | X12: 900.7 | Y12: 767.4 | Z12: =IF(OR(W12=""),"",(W12+X12+Y12)) -> 51108.7 | AA12: 55929.8 | AB12: 1144 | AC12: =IF(OR(AA12=""),"",(AA12+AB12)) -> 57073.8 | AD12: 90919 | AE12: =IF(OR(C13=""),"",(C13-C12)*80) -> 0 | AF12: =IF(OR(D13=""),"",(D13-D12)*80) -> 2960 | AG12: =IF(OR(E13=""),"",(E13-E12)*80) -> 0 | AH12: =IF(OR(F13=""),"",(F13-F12)*80) -> 4.8 | AI12: =IF(OR(G13=""),"",(G13-G12)*80) -> 1728 | AJ12: =IF(OR(AE12="",AF12="",AG12=""),"",AE12+AF12+AG12+AH12+AI12) -> 4692.8 | AK12: =IF(OR(H13=""),"",(H13-H12)*80) -> 0 | AL12: =IF(OR(I13=""),"",(I13-I12)*80) -> 0 | AM12: =IF(OR(J13=""),"",(J13-J12)*80) -> 0 | AN12: =IF(OR(K13=""),"",(K13-K12)*80) -> 0 | AO12: =IF(OR(AK12="",AL12=""),"",AK12+AL12+AM12+AN12) -> 0 | AP12: =IF(OR(L13=""),"",(L13-L12)*100) -> 1690 | AQ12: =IF(OR(M13=""),"",(M13-M12)*100) -> 0 | AR12: =IF(OR(N13=""),"",(N13-N12)*100) -> 0 | AS12: =IF(OR(O13=""),"",(O13-O12)*100) -> 1730 | AT12: =IF(OR(AP12="",AQ12=""),"",AP12+AQ12+AR12+AS12) -> 3420 | AU12: =IF(OR(P13=""),"",(P13-P12)*1000) -> 2200 | AV12: =IF(OR(Q13=""),"",(Q13-Q12)*1000) -> 1200 | AW12: =IF(OR(R13=""),"",(R13-R12)*1000) -> 4200 | AX12: =IF(OR(S13=""),"",(S13-S12)*1000) -> 400 | AY12: =IF(OR(T13=""),"",(T13-T12)*1000) -> 0 | AZ12: =IF(OR(AU12="",AV12="",AW12=""),"",AU12+AV12+AW12+AX12+AY12) -> 8000 | BA12: =IF(OR(U13=""),"",(U13-U12)*2000) -> 3800 | BB12: =IF(OR(V13=""),"",(V13-V12)*80) -> 720 | BC12: =IF(OR(Z12=""),"",(Z13-Z12)*40) -> 1544 | BD12: =IF(OR(BE12="",BC12=""),"",BE12-BC12-BB12-BA12-AZ12-AT12-AO12-AJ12) -> 15423.2 | BE12: =IF(OR(B13=""),"",(B13-B12)*10000) -> 37600 | BF12: =IF(OR(AC13=""),"",AC13-AC12) -> 77.1 | BG12: =IF(OR($AD12=0),"",BE12/$AD12) -> 0.41355492 | BH12: =IF(OR($AD12=0),"",AJ12/$AD12) -> 0.051615174 | BI12: =IF(OR($AD12=0),"",AO12/$AD12) -> 0 | BJ12: =IF(OR($AD12=0),"",AT12/$AD12) -> 0.0376159 | BK12: =IF(OR($AD12=0),"",AZ12/$AD12) -> 0.087990409 | BL12: =IF(OR($AD12=0),"",BA12/$AD12) -> 0.041795444 | BM12: =IF(OR($AD12=0),"",BB12/$AD12) -> 0.0079191368 | BN12: =IF(OR($AD12=0),"",BC12/$AD12) -> 0.016982149 | BO12: =IF(OR($AD12=0),"",BD12/$AD12) -> 0.16963671
A13: =A12+1 -> 44237 | B13: 15793.08 | C13: 85788.6 | D13: 54700 | E13: 55782 | F13: 3395.02 | G13: 108581.8 | H13: 5596.3 | I13: 2566.3 | J13: 967 | K13: 56 | L13: 87260.1 | M13: 61126.5 | N13: 69176.2 | O13: 99018.2 | P13: 5169.1 | Q13: 7010.8 | R13: 4254.7 | S13: 4906.1 | T13: 6009.1 | U13: 16644.5 | V13: 49002.8 | W13: 49457.7 | X13: 913.9 | Y13: 775.7 | Z13: =IF(OR(W13=""),"",(W13+X13+Y13)) -> 51147.3 | AA13: 55973.9 | AB13: 1177 | AC13: =IF(OR(AA13=""),"",(AA13+AB13)) -> 57150.9 | AD13: 96180 | AE13: =IF(OR(C14=""),"",(C14-C13)*80) -> 0 | AF13: =IF(OR(D14=""),"",(D14-D13)*80) -> 2008 | AG13: =IF(OR(E14=""),"",(E14-E13)*80) -> 0 | AH13: =IF(OR(F14=""),"",(F14-F13)*80) -> 0 | AI13: =IF(OR(G14=""),"",(G14-G13)*80) -> 1464 | AJ13: =IF(OR(AE13="",AF13="",AG13=""),"",AE13+AF13+AG13+AH13+AI13) -> 3472 | AK13: =IF(OR(H14=""),"",(H14-H13)*80) -> 0 | AL13: =IF(OR(I14=""),"",(I14-I13)*80) -> 0 | AM13: =IF(OR(J14=""),"",(J14-J13)*80) -> 0 | AN13: =IF(OR(K14=""),"",(K14-K13)*80) -> 0 | AO13: =IF(OR(AK13="",AL13=""),"",AK13+AL13+AM13+AN13) -> 0 | AP13: =IF(OR(L14=""),"",(L14-L13)*100) -> 1740 | AQ13: =IF(OR(M14=""),"",(M14-M13)*100) -> 0 | AR13: =IF(OR(N14=""),"",(N14-N13)*100) -> 0 | AS13: =IF(OR(O14=""),"",(O14-O13)*100) -> 1670 | AT13: =IF(OR(AP13="",AQ13=""),"",AP13+AQ13+AR13+AS13) -> 3410 | AU13: =IF(OR(P14=""),"",(P14-P13)*1000) -> 300 | AV13: =IF(OR(Q14=""),"",(Q14-Q13)*1000) -> 0 | AW13: =IF(OR(R14=""),"",(R14-R13)*1000) -> 2000 | AX13: =IF(OR(S14=""),"",(S14-S13)*1000) -> 5500 | AY13: =IF(OR(T14=""),"",(T14-T13)*1000) -> 0 | AZ13: =IF(OR(AU13="",AV13="",AW13=""),"",AU13+AV13+AW13+AX13+AY13) -> 7800 | BA13: =IF(OR(U14=""),"",(U14-U13)*2000) -> 4000 | BB13: =IF(OR(V14=""),"",(V14-V13)*80) -> 608 | BC13: =IF(OR(Z13=""),"",(Z14-Z13)*40) -> 1564 | BD13: =IF(OR(BE13="",BC13=""),"",BE13-BC13-BB13-BA13-AZ13-AT13-AO13-AJ13) -> 17146 | BE13: =IF(OR(B14=""),"",(B14-B13)*10000) -> 38000 | BF13: =IF(OR(AC14=""),"",AC14-AC13) -> 78.3 | BG13: =IF(OR($AD13=0),"",BE13/$AD13) -> 0.39509253 | BH13: =IF(OR($AD13=0),"",AJ13/$AD13) -> 0.036098981 | BI13: =IF(OR($AD13=0),"",AO13/$AD13) -> 0 | BJ13: =IF(OR($AD13=0),"",AT13/$AD13) -> 0.035454356 | BK13: =IF(OR($AD13=0),"",AZ13/$AD13) -> 0.081097941 | BL13: =IF(OR($AD13=0),"",BA13/$AD13) -> 0.041588688 | BM13: =IF(OR($AD13=0),"",BB13/$AD13) -> 0.0063214806 | BN13: =IF(OR($AD13=0),"",BC13/$AD13) -> 0.016261177 | BO13: =IF(OR($AD13=0),"",BD13/$AD13) -> 0.17826991
