Workbook

Sheet 汇总
A1: 常州市深水城北污水处理有限公司污水运行月报表
A2: 44409
A3: 污 水 处 理 | B3: 污水处理量（m3） | C3: =处理量!D37 -> 4980928 | D3: 污 泥 处 理 | E3: 脱水污泥量（T） | F3: =处理量!G41 -> 2476.46 | G3: 水 电 用 量 | H3: 用电量（度） | J3: 1429347 | K3: 污 水 电 单 耗 | L3: 污水（度/m3） | M3: =J3/C3 -> 0.286964
B4: 日均处理量（m3） | C4: =处理量!D36 -> 160675.1 | E4: 絮凝剂用量（kg） | F4: =处理量!H37 -> 2675 | H4: 日均用电量（度） | J4: =J3/M15 -> 46107.968 | L4: CODcr（度/kg） | M4: =J3/I12 -> 1.5928172
E5: 含水率（%） | F5: =进出水!Z38 -> 78.212903 | H5: 用水量（T） | J5: 2017
B6: 最高日处理量（m3） | C6: =处理量!D41 -> 164480 | E6: 絮凝剂单耗（kg/T） | F6: =F4/处理量!G42 -> 4.9578468 | G6: 消 毒 剂 | H6: 工业合成盐酸（T） | J6: =处理量!O37/1000 -> 69.638 | L6: BOD5（度/kg） | M6: =J3/I13 -> 2.923777
B7: 最低日处理量（m3） | C7: =处理量!D42 -> 155296 | E7: 产泥率(g/m３) | F7: =处理量!G42/C3*1000000 -> 108.32293 | H7: 药单耗(g/m3) | J7: =J6/C3*1000*1000 -> 13.980929 | L7: SS（度/kg） | M7: =J3/I14 -> 2.58827
B8: 负荷率（%） | C8: =C4/150000*100 -> 107.11673 | D8: 混 凝 剂 | E8: 混凝剂用量（T） | F8: =处理量!M37 -> 414.48 | H8: 氯酸钠（T） | J8: =处理量!P37/1000 -> 17.4095 | K8: 乙酸-厌缺氧段 | L8: 投加量（吨） | M8: =处理量!Q37 -> 79.69785
B9: 进水水温(℃) | C9: =处理量!B36 -> 30.512903 | E9: 药单耗(g/m3) | F9: =F8/C3*1000*1000 -> 83.213409 | H9: 药单耗(g/m3) | J9: =J8/C3*1000*1000 -> 3.4952322 | L9: 药单耗(g/m3) | M9: =M8/C3*1000*1000 -> 16.000603
A10: 处 理 质 量 | B10: 项目 | C10: 进水（mg/l） | E10: 出水（mg/l） | G10: 去除率（%） | I10: 去除总量（kg) | K10: 乙酸-提标段 | L10: 投加量（吨） | M10: =处理量!R37 -> 26.9379
L11: 药单耗(g/m3) | M11: =M10/C3*1000*1000 -> 5.4082091
B12: CODcr | C12: =进出水!B38 -> 188.16129 | E12: =进出水!T38 -> <16 | G12: =(C12-8)/C12 -> 0.95748328 | I12: =(C12-8)*C3/1000 -> 897370.42 | K12: 污 泥 去 向 | L12: 国电(吨） | M12: =处理量!E37 -> 117.7 | O12: =ROUND(C$3*16/1000000,2) -> 79.69
B13: BOD5 | C13: =进出水!C38 -> 99.148387 | E13: =进出水!U38 -> <2 | G13: =(C13-1)/C13 -> 0.98991411 | I13: =(C13-1)*C3/1000 -> 488870.05 | L13: 英科环境(吨) | M13: =处理量!F37 -> 2358.76
B14: SS | C14: =进出水!D38 -> 115.87097 | E14: =进出水!V38 -> 5 | G14: =(C14-E14)/C14 -> 0.95684855 | I14: =(C14-5)*C3/1000 -> 552240.31 | L14: 其它 | M14: =处理量!G37 -> 0
B15: TP | C15: =进出水!E38 -> 3.3032258 | E15: =进出水!W38 -> 0.14322581 | G15: =(C15-E15)/C15 -> 0.95664063 | I15: =(C15-E15)*C3/1000 -> 15739.732 | K15: 运 行 情 况 | L15: 应运行天数 | M15: 31 | O15: =ROUND(C$3*E15/1000000,2) -> 0.71
B16: TN | C16: =进出水!G38 -> 28.703226 | E16: =进出水!Y38 -> 5.916129 | G16: =(C16-E16)/C16 -> 0.79388627 | I16: =(C16-E16)*C3/1000 -> 113500.89 | L16: 实际运行天数 | M16: 31 | O16: =ROUND(C$3*E16/1000000,2) -> 29.47
B17: NH3-N | C17: =进出水!F38 -> 22.089032 | E17: =进出水!X38 -> 0.13612903 | G17: =(C17-E17)/C17 -> 0.99383726 | I17: =(C17-E17)*C3/1000 -> 109345.83 | L17: 达标排放天数 | M17: 31 | O17: =ROUND(C$3*E17/1000000,2) -> 0.68
B18: 粪大肠菌群数 (个/L) | C18: / | E18: <20 | G18: / | I18: / | L18: 运转率 | M18: 100
A19: 备注 | B19: 本月总用电量为1505594度，其中排水处电量为13340度，除臭工程用电62907度，城北实际用电为1429347度。本月自来水用量为2897吨，其中除臭工程自来水用量为880吨，城北实际用自来水用量为2017吨。 本月产生泥饼2476.46吨，运往英科焚烧中心2358.76吨；运往国电117.7吨。
A21: 审核： 制表： 制表日期：2021-9-3

Sheet 处理量
A1: 常州市深水城北污水处理有限公司污水处理运行月报表
A2: 44409
A3: 日 期 | B3: 水温 | C3: 天气 | D3: 日处理水量 （m3） | E3: 污泥量（T） | H3: 药剂量 | I3: MLSS（mg/l） | L3: 电耗 | M3: 混凝剂 | N3: 絮凝剂 阴离子 （kg） | O3: 盐酸 | P3: 氯酸钠 | Q3: 乙酸(T） | S3: 回用水 （m3） | T3: 实际水量（m3） | U3: 消泡剂 | Y3: 盐酸单价430 | AA3: 氯酸钠单价 | AB3: 4900 | AC3: PAM单价28040 | AE3: 消泡剂 | AF3: 12800
B4: 度 | C4: 状况 | E4: 国电 | F4: 英科环境 | G4: 其他 | H4: （Kg） | I4: 一期 | J4: 二期 | K4: 三期 | L4: ( 度 ) | M4: （T） | O4: （Kg） | P4: （Kg） | Q4: 厌缺氧 | R4: 提标段
A5: 1 | B5: 30.5 | C5: 晴 | D5: 163808 | E5: 18.36 | F5: 123.68 | G5: 0 | H5: 125 | I5: 3128 | J5: 3602 | K5: 3266 | L5: 46502.96 | M5: 2.16 | N5: 0 | O5: 2288 | P5: 572 | Q5: 3.15835 | R5: 0.85655 | S5: 0 | T5: =D5-S5 -> 163808 | U5: 48 | V5: =E5+F5 -> 142.04
A6: 2 | B6: 30.3 | C6: 晴 | D6: 159840 | E6: 16.96 | F6: 87.22 | G6: 0 | H6: 100 | I6: 3352 | J6: 3252 | K6: 3148 | L6: 48903.04 | M6: 0 | N6: 0 | O6: 2245 | P6: 561.25 | Q6: 3.2039 | R6: 0.8685 | S6: 0 | T6: =D6-S6 -> 159840 | U6: 48 | V6: =E6+F6 -> 104.18
A7: 3 | B7: 30.1 | C7: 阴 | D7: 161120 | E7: 0 | F7: 71.32 | G7: 0 | H7: 0 | I7: 3424 | J7: 3020 | K7: 3280 | L7: 47802.99 | M7: 0 | N7: 0 | O7: 2233 | P7: 558.25 | Q7: 3.2734 | R7: 0.88585 | S7: 0 | T7: =D7-S7 -> 161120 | U7: 48 | V7: =E7+F7 -> 71.32 | Z7: 单价 | AA7: 当月用量 | AB7: 合计
A8: 4 | B8: 30.3 | C8: 晴 | D8: 163008 | E8: 0 | F8: 34.68 | G8: 0 | H8: 0 | I8: 3644 | J8: 3778 | K8: 3512 | L8: 48203 | M8: 0 | N8: 0 | O8: 2216 | P8: 554 | Q8: 2.4168 | R8: 0.8668 | S8: 0 | T8: =D8-S8 -> 163008 | U8: 48 | V8: =E8+F8 -> 34.68 | Y8: 电费 | Z8: 0.551 | AA8: =L37 -> 1505593.9 | AB8: =AA8*Z8 -> 829582.22
A9: 5 | B9: 31.7 | C9: 晴 | D9: 160832 | E9: 0 | F9: 35.26 | G9: 0 | H9: 0 | I9: 3542 | J9: 3100 | K9: 3230 | L9: 49003.05 | M9: 6.36 | N9: 0 | O9: 2262 | P9: 565.5 | Q9: 2.38195 | R9: 0.85565 | S9: 0 | T9: =D9-S9 -> 160832 | U9: 48 | V9: =E9+F9 -> 35.26 | Y9: 絮凝剂 | Z9: 28040 | AA9: =H37/1000 -> 2.675 | AB9: =AA9*Z9 -> 75007
A10: 6 | B10: 31.3 | C10: 阴 | D10: 160320 | E10: 17.48 | F10: 0 | G10: 0 | H10: 0 | I10: 3750 | J10: 3348 | K10: 3410 | L10: 49603.09 | M10: 10.08 | N10: 0 | O10: 2234 | P10: 558.5 | Q10: 2.4867 | R10: 0.8702 | S10: 0 | T10: =D10-S10 -> 160320 | U10: 48 | V10: =E10+F10 -> 17.48 | Y10: 盐酸 | Z10: 430 | AA10: =O37/1000 -> 69.638 | AB10: =AA10*Z10 -> 29944.34
A11: 7 | B11: 31.5 | C11: 阴 | D11: 160096 | E11: 0 | F11: 18.04 | G11: 0 | H11: 225 | I11: 3874 | J11: 3754 | K11: 3406 | L11: 51503.21 | M11: 13.08 | N11: 0 | O11: 2268 | P11: 567 | Q11: 2.5167 | R11: 0.87715 | S11: 0 | T11: =D11-S11 -> 160096 | U11: 48 | V11: =E11+F11 -> 18.04 | Y11: 氯酸钠 | Z11: 4900 | AA11: =P37/1000 -> 17.4095 | AB11: =AA11*Z11 -> 85306.55
A12: 8 | B12: 30.8 | C12: 晴 | D12: 158720 | E12: 16.48 | F12: 68.2 | G12: 0 | H12: 150 | I12: 3664 | J12: 3854 | K12: 3442 | L12: 50803.16 | M12: 11.4 | N12: 0 | O12: 2252 | P12: 563 | Q12: 2.47425 | R12: 0.86335 | S12: 0 | T12: =D12-S12 -> 158720 | U12: 48 | V12: =E12+F12 -> 84.68 | Y12: 混凝剂 | Z12: 348 | AA12: =M37 -> 414.48 | AB12: =AA12*Z12 -> 144239.04
A13: 9 | B13: 32.1 | C13: 晴 | D13: 159168 | E13: 0 | F13: 107.8 | G13: 0 | H13: 150 | I13: 3616 | J13: 3434 | K13: 3280 | L13: 52403.26 | M13: 15.36 | N13: 0 | O13: 2017 | P13: 504.25 | Q13: 2.88125 | R13: 0.84885 | S13: 0 | T13: =D13-S13 -> 159168 | U13: 48 | V13: =E13+F13 -> 107.8 | Y13: 消泡剂 | Z13: 12800 | AA13: =U37/1000 -> 1.488 | AB13: =AA13*Z13 -> 19046.4
A14: 10 | B14: 31.2 | C14: 雨 | D14: 159616 | E14: 34.1 | F14: 89.94 | G14: 0 | H14: 100 | I14: 3688 | J14: 3618 | K14: 3406 | L14: 51803.23 | M14: 15.96 | N14: 0 | O14: 2064 | P14: 516 | Q14: 2.5293 | R14: 0.88175 | S14: 0 | T14: =D14-S14 -> 159616 | U14: 48 | V14: =E14+F14 -> 124.04 | Y14: 污泥外运 | Z14: 22.18 | AA14: =G41 -> 2476.46 | AB14: =AA14*Z14 -> 54927.883
A15: 11 | B15: 30.8 | C15: 阴 | D15: 155296 | E15: 0 | F15: 125.44 | G15: 0 | H15: 50 | I15: 3700 | J15: 3554 | K15: 3600 | L15: 50603.16 | M15: 18.24 | N15: 0 | O15: 2000 | P15: 500 | Q15: 2.49955 | R15: 0.8798 | S15: 0 | T15: =D15-S15 -> 155296 | U15: 48 | V15: =E15+F15 -> 125.44
A16: 12 | B16: 30.8 | C16: 阴 | D16: 157056 | E16: 14.32 | F16: 17.34 | G16: 0 | H16: 0 | I16: 3556 | J16: 3588 | K16: 3346 | L16: 48803.03 | M16: 20.76 | N16: 0 | O16: 2044 | P16: 511 | Q16: 2.62835 | R16: 0.91555 | S16: 0 | T16: =D16-S16 -> 157056 | U16: 48 | V16: =E16+F16 -> 31.66
A17: 13 | B17: 31.2 | C17: 阴 | D17: 160736 | E17: 0 | F17: 18.54 | G17: 0 | H17: 125 | I17: 3722 | J17: 3642 | K17: 3510 | L17: 49203.08 | M17: 23.76 | N17: 0 | O17: 2016 | P17: 504 | Q17: 2.2855 | R17: 0.79705 | S17: 0 | T17: =D17-S17 -> 160736 | U17: 48 | V17: =E17+F17 -> 18.54
A18: 14 | B18: 30.6 | C18: 雨 | D18: 159840 | E18: 0 | F18: 99.48 | G18: 0 | H18: 150 | I18: 3950 | J18: 3654 | K18: 3712 | L18: 47702.97 | M18: 23.4 | N18: 0 | O18: 2201 | P18: 550.25 | Q18: 2.54245 | R18: 0.886 | S18: 0 | T18: =D18-S18 -> 159840 | U18: 48 | V18: =E18+F18 -> 99.48
A19: 15 | B19: 30.2 | C19: 雨 | D19: 157248 | E19: 0 | F19: 137.9 | G19: 0 | H19: 150 | I19: 3862 | J19: 3340 | K19: 3518 | L19: 45502.83 | M19: 14.4 | N19: 0 | O19: 2212 | P19: 553 | Q19: 2.52945 | R19: 0.8817 | S19: 0 | T19: =D19-S19 -> 157248 | U19: 48 | V19: =E19+F19 -> 137.9
A20: 16 | B20: 26.8 | C20: 阴 | D20: 160640 | E20: 0 | F20: 136.36 | G20: 0 | H20: 125 | I20: 3608 | J20: 3470 | K20: 3276 | L20: 46202.94 | M20: 11.88 | N20: 0 | O20: 2244 | P20: 561 | Q20: 2.4613 | R20: 0.85785 | S20: 0 | T20: =D20-S20 -> 160640 | U20: 48 | V20: =E20+F20 -> 136.36
A21: 17 | B21: 30.5 | C21: 晴 | D21: 163872 | E21: 0 | F21: 102.42 | G21: 0 | H21: 125 | I21: 3314 | J21: 3516 | K21: 3408 | L21: 46602.85 | M21: 15.48 | N21: 0 | O21: 2224 | P21: 556 | Q21: 2.45015 | R21: 0.854 | S21: 0 | T21: =D21-S21 -> 163872 | U21: 48 | V21: =E21+F21 -> 102.42
A22: 18 | B22: 30.7 | C22: 晴 | D22: 161856 | E22: 0 | F22: 103.74 | G22: 0 | H22: 50 | I22: 3162 | J22: 3466 | K22: 3300 | L22: 45802.85 | M22: 21.6 | N22: 0 | O22: 2456 | P22: 614 | Q22: 2.51525 | R22: 0.8765 | S22: 0 | T22: =D22-S22 -> 161856 | U22: 48 | V22: =E22+F22 -> 103.74
A23: 19 | B23: 30.5 | C23: 晴 | D23: 163968 | E23: 0 | F23: 17.52 | G23: 0 | H23: 0 | I23: 2894 | J23: 3372 | K23: 3014 | L23: 46802.91 | M23: 8.88 | N23: 0 | O23: 2462 | P23: 615.5 | Q23: 2.51805 | R23: 0.87755 | S23: 0 | T23: =D23-S23 -> 163968 | U23: 48 | V23: =E23+F23 -> 17.52
A24: 20 | B24: 27.6 | C24: 阴 | D24: 164480 | E24: 0 | F24: 17.88 | G24: 0 | H24: 0 | I24: 2784 | J24: 3480 | K24: 3218 | L24: 48503.03 | M24: 5.16 | N24: 0 | O24: 2416 | P24: 604 | Q24: 2.47385 | R24: 0.86235 | S24: 0 | T24: =D24-S24 -> 164480 | U24: 48 | V24: =E24+F24 -> 17.88
A25: 21 | B25: 30.5 | C25: 晴 | D25: 163968 | E25: 0 | F25: 17.76 | G25: 0 | H25: 0 | I25: 3156 | J25: 3940 | K25: 3452 | L25: 46402.89 | M25: 10.68 | N25: 0 | O25: 2421 | P25: 605.25 | Q25: 2.434 | R25: 0.84915 | S25: 0 | T25: =D25-S25 -> 163968 | U25: 48 | V25: =E25+F25 -> 17.76
A26: 22 | B26: 31.2 | C26: 阴 | D26: 160576 | E26: 0 | F26: 17.9 | G26: 0 | H26: 0 | I26: 2802 | J26: 4202 | K26: 3164 | L26: 49503.08 | M26: 16.8 | N26: 0 | O26: 2455 | P26: 613.75 | Q26: 2.5156 | R26: 0.8777 | S26: 0 | T26: =D26-S26 -> 160576 | U26: 48 | V26: =E26+F26 -> 17.9
... A35: 31 | B35: 31.5 | C35: 晴 | D35: 158528 | E35: 0 | F35: 105.6 | G35: 0 | H35: 75 | I35: 3580 | J35: 3056 | K35: 3370 | L35: 48102.99 | M35: 18.6 | N35: 0 | O35: 1844 | P35: 461 | Q35: 2.5838 | R35: 0.9006 | S35: 0 | T35: =D35-S35 -> 158528 | U35: 48 | V35: =E35+F35 -> 105.6
A36: 平均 | B36: =AVERAGE(B5:B35) -> 30.512903 | C36: / | D36: =AVERAGE(D5:D35) -> 160675.1 | E36: =AVERAGE(E5:E35) -> 3.7967742 | F36: =AVERAGE(F5:F35) -> 76.089032 | G36: =AVERAGE(G5:G35) -> 0 | H36: =AVERAGE(H5:H35) -> 86.290323 | I36: =AVERAGE(I5:I35) -> 3454.1935 | J36: =AVERAGE(J5:J35) -> 3532.6452 | K36: =AVERAGE(K5:K35) -> 3351.3548 | ... M36: =AVERAGE(M5:M35) -> 13.370323 | N36: 0 | O36: =AVERAGE(O5:O35) -> 2246.3871 | P36: =AVERAGE(P5:P35) -> 561.59677 | Q36: =AVERAGE(Q5:Q35) -> 2.5708984 | R36: =AVERAGE(R5:R35) -> 0.86896452 | S36: =AVERAGE(S5:S35) -> 0 | T36: =D36-S36 -> 160675.1
A37: 合计 | B37: / | C37: / | D37: =SUM(D5:D35) -> 4980928 | E37: =SUM(E5:E35) -> 117.7 | F37: =SUM(F5:F35) -> 2358.76 | G37: =SUM(G5:G35) -> 0 | H37: =SUM(H5:H35) -> 2675 | I37: / | J37: / | K37: / | L37: =SUM(L5:L35) -> 1505593.9 | M37: =SUM(M5:M35) -> 414.48 | N37: 0 | O37: =SUM(O5:O35) -> 69638 | P37: =SUM(P5:P35) -> 17409.5 | Q37: =SUM(Q5:Q35) -> 79.69785 | R37: =SUM(R5:R35) -> 26.9379 | S37: =SUM(S5:S35) -> 0 | T37: =SUM(T5:T35) -> 4980928 | U37: =SUM(U5:U36) -> 1488
A38: 审核： | I38: 制表： | R38: 制表时间:2021-9-3
B41: 最大值 | D41: =MAX(D5:D35) -> 164480 | E41: 脱水污泥量 | G41: =E37+F37+G37 -> 2476.46
B42: 最小值 | D42: =MIN(D5:D35) -> 155296 | E42: 干污泥量 | G42: =G41*(100-进出水!Z38)/100 -> 539.54874 | Q42: =Q37+R37 -> 106.63575 | R42: =Q37+R37 -> 106.63575
Q43: =Q42*1000 -> 106635.75 | R43: =R42*1000 -> 106635.75

Sheet 进出水
A1: 常州市深水城北污水处理有限公司出水水质、污泥含水率月报表
A3: 44409
A4: 日期 | B4: 进水 | H4: 一期出水 | N4: 二、三期出水 | T4: 总出水 | Z4: 污泥含水率（%） | AA4: 粪大肠杆菌
B5: CODCr | C5: BOD5 | D5: SS | E5: TP | F5: NH3-N | G5: TN | H5: CODCr | I5: BOD5 | J5: SS | K5: TP | L5: NH3-N | M5: TN | N5: CODCr | O5: BOD5 | P5: SS | Q5: TP | R5: NH3-N | S5: TN | T5: CODCr | U5: BOD5 | V5: SS | W5: TP | X5: NH3-N | Y5: TN
B6: （mg/l） | C6: （mg/l） | D6: （mg/l） | E6: （mg/l） | F6: （mg/l） | G6: （mg/l） | H6: （mg/l） | I6: （mg/l） | J6: （mg/l） | K6: （mg/l） | L6: （mg/l） | M6: （mg/l） | N6: （mg/l） | O6: （mg/l） | P6: （mg/l） | Q6: （mg/l） | R6: （mg/l） | S6: （mg/l） | T6: （mg/l） | U6: （mg/l） | V6: （mg/l） | W6: （mg/l） | X6: （mg/l） | Y6: （mg/l）
A7: 1 | B7: 311 | C7: 158 | D7: 212 | E7: 4.42 | F7: 27.5 | G7: 45.7 | H7: 21 | I7: <2 | J7: 5 | K7: 0.34 | L7: 0.2 | M7: 9.75 | N7: 19 | O7: <2 | P7: 5 | Q7: 0.26 | R7: 0.13 | S7: 7.3 | T7: <16 | U7: <2 | V7: 5 | W7: 0.12 | X7: 0.1 | Y7: 6.75 | Z7: 78.3
A8: 2 | B8: 154 | C8: 80.8 | D8: 88 | E8: 3.16 | F8: 21.2 | G8: 26.7 | H8: 18 | I8: <2 | J8: 5 | K8: 0.24 | L8: 0.17 | M8: 8 | N8: 19 | O8: <2 | P8: 5 | Q8: 0.43 | R8: 0.18 | S8: 7.6 | T8: <16 | U8: <2 | V8: 5 | W8: 0.13 | X8: 0.16 | Y8: 7.4 | Z8: 77.9 | AA8: <20
A9: 3 | B9: 192 | C9: 105 | D9: 102 | E9: 3.14 | F9: 16.4 | G9: 22.6 | H9: 19 | I9: <2 | J9: 5 | K9: 0.19 | L9: 0.21 | M9: 6.25 | N9: 18 | O9: <2 | P9: 5 | Q9: 0.39 | R9: 0.21 | S9: 6.05 | T9: <16 | U9: <2 | V9: 5 | W9: 0.18 | X9: 0.15 | Y9: 5.95 | Z9: 78.1 | AA9: <20
A10: 4 | B10: 203 | C10: 107 | D10: 140 | E10: 3.45 | F10: 25.7 | G10: 31.4 | H10: 17 | I10: <2 | J10: 5 | K10: 0.2 | L10: 0.16 | M10: 5.65 | N10: 18 | O10: <2 | P10: 5 | Q10: 0.2 | R10: 0.15 | S10: 5.15 | T10: <16 | U10: <2 | V10: 5 | W10: 0.18 | X10: 0.14 | Y10: 5 | Z10: 77.4 | AA10: <20
A11: 5 | B11: 177 | C11: 93.7 | D11: 88 | E11: 3.29 | F11: 24.7 | G11: 32.3 | H11: 19 | I11: <2 | J11: 5 | K11: 0.28 | L11: 0.13 | M11: 8.2 | N11: 16 | O11: <2 | P11: 5 | Q11: 0.26 | R11: 0.12 | S11: 7.5 | T11: <16 | U11: <2 | V11: 5 | W11: 0.17 | X11: 0.11 | Y11: 7.4 | Z11: 77.8 | AA11: <20
A12: 6 | B12: 103 | C12: 53.4 | D12: 76 | E12: 2.14 | F12: 17.4 | G12: 23.2 | H12: 21 | I12: <2 | J12: 5 | K12: 0.24 | L12: 0.12 | M12: 7 | N12: 19 | O12: <2 | P12: 5 | Q12: 0.44 | R12: 0.13 | S12: 7.2 | T12: <16 | U12: <2 | V12: 5 | W12: 0.2 | X12: 0.1 | Y12: 6.68 | Z12: 77.9 | AA12: 50
A13: 7 | B13: 159 | C13: 84.1 | D13: 90 | E13: 2.79 | F13: 26.2 | G13: 35.8 | H13: 19 | I13: <2 | J13: 5 | K13: 0.21 | L13: 0.16 | M13: 8 | N13: 19 | O13: <2 | P13: 5 | Q13: 0.7 | R13: 0.17 | S13: 7.1 | T13: <16 | U13: <2 | V13: 5 | W13: 0.13 | X13: 0.1 | Y13: 7.05 | Z13: 78.2
A14: 8 | B14: 252 | C14: 136 | D14: 122 | E14: 3.85 | F14: 28.8 | G14: 34.1 | H14: 19 | I14: <2 | J14: 5 | K14: 0.18 | L14: 0.24 | M14: 8 | N14: <16 | O14: <2 | P14: 5 | Q14: 0.6 | R14: 0.23 | S14: 8.3 | T14: <16 | U14: <2 | V14: 5 | W14: 0.1 | X14: 0.23 | Y14: 7.6 | Z14: 78
A15: 9 | B15: 218 | C15: 115 | D15: 102 | E15: 4.3 | F15: 29.4 | G15: 34.5 | H15: 18 | I15: <2 | J15: 5 | K15: 0.27 | L15: 0.16 | M15: 7.2 | N15: <16 | O15: <2 | P15: 5 | Q15: 0.23 | R15: 0.12 | S15: 6.9 | T15: <16 | U15: <2 | V15: 5 | W15: 0.15 | X15: 0.1 | Y15: 6.58 | Z15: 78.4 | AA15: 360
A16: 10 | B16: 195 | C16: 103 | D16: 116 | E16: 3.53 | F16: 23.3 | G16: 29.7 | H16: 19 | I16: <2 | J16: 5 | K16: 0.19 | L16: 0.2 | M16: 8.2 | N16: 20 | O16: <2 | P16: 7 | Q16: 0.29 | R16: 0.23 | S16: 7.2 | T16: <16 | U16: <2 | V16: 5 | W16: 0.18 | X16: 0.18 | Y16: 6.95 | Z16: 78.3 | AA16: <20
A17: 11 | B17: 220 | C17: 116 | D17: 146 | E17: 4.95 | F17: 25.9 | G17: 31.4 | H17: 16 | I17: <2 | J17: 5 | K17: 0.25 | L17: 0.17 | M17: 6.6 | N17: 17 | O17: <2 | P17: 5 | Q17: 0.6 | R17: 0.18 | S17: 6.68 | T17: <16 | U17: <2 | V17: 5 | W17: 0.19 | X17: 0.1 | Y17: 5.15 | Z17: 78.1 | AA17: <20
A18: 12 | B18: 323 | C18: 171 | D18: 228 | E18: 3.42 | F18: 30.4 | G18: 35.9 | H18: 16 | I18: <2 | J18: 5 | K18: 0.17 | L18: 0.17 | M18: 7.2 | N18: 24 | O18: <2 | P18: 8 | Q18: 0.26 | R18: 0.16 | S18: 6.18 | T18: <16 | U18: <2 | V18: 5 | W18: 0.15 | X18: 0.13 | Y18: 5.4 | Z18: 78.6 | AA18: <20
A19: 13 | B19: 243 | C19: 126 | D19: 166 | E19: 3.12 | F19: 16.8 | G19: 23.2 | H19: 16 | I19: <2 | J19: 5 | K19: 0.31 | L19: 0.21 | M19: 6.25 | N19: <16 | O19: <2 | P19: 5 | Q19: 0.55 | R19: 0.2 | S19: 5.85 | T19: <16 | U19: <2 | V19: 5 | W19: 0.13 | X19: 0.19 | Y19: 5.65 | Z19: 78 | AA19: <20
A20: 14 | B20: 113 | C20: 57.5 | D20: 84 | E20: 2.39 | F20: 10.4 | G20: 17.3 | H20: 18 | I20: <2 | J20: 6 | K20: 0.28 | L20: 0.14 | M20: 4.95 | N20: 17 | O20: <2 | P20: 7 | Q20: 0.67 | R20: 0.15 | S20: 5.4 | T20: <16 | U20: <2 | V20: 5 | W20: 0.15 | X20: 0.11 | Y20: 4.19 | Z20: 77.6
A21: 15 | B21: 167 | C21: 88.4 | D21: 100 | E21: 4.02 | F21: 43.5 | G21: 48.9 | H21: <16 | I21: <2 | J21: 5 | K21: 0.32 | L21: 0.4 | M21: 7.6 | N21: 17 | O21: <2 | P21: 6 | Q21: 0.76 | R21: 0.46 | S21: 6.75 | T21: <16 | U21: <2 | V21: 5 | W21: 0.13 | X21: 0.25 | Y21: 4.8 | Z21: 77.9
A22: 16 | B22: 96 | C22: 49.9 | D22: 62 | E22: 2.81 | F22: 8.86 | G22: 14.2 | H22: 18 | I22: <2 | J22: 5 | K22: 0.27 | L22: 0.12 | M22: 4.72 | N22: <16 | O22: <2 | P22: 5 | Q22: 0.3 | R22: 0.11 | S22: 4.62 | T22: <16 | U22: <2 | V22: 5 | W22: 0.09 | X22: 0.1 | Y22: 4.52 | Z22: 78.3 | AA22: <20
A23: 17 | B23: 169 | C23: 90.2 | D23: 102 | E23: 5.69 | F23: 17.7 | G23: 26.4 | H23: 18 | I23: <2 | J23: 5 | K23: 0.4 | L23: 0.26 | M23: 5.57 | N23: 16 | O23: <2 | P23: 5 | Q23: 0.67 | R23: 0.12 | S23: 4.52 | T23: <16 | U23: <2 | V23: 5 | W23: 0.12 | X23: 0.11 | Y23: 4.22 | Z23: 78.6 | AA23: <20
A24: 18 | B24: 155 | C24: 82.2 | D24: 78 | E24: 3.79 | F24: 16.2 | G24: 23.4 | H24: <16 | I24: <2 | J24: 5 | K24: 0.35 | L24: 0.14 | M24: 6.67 | N24: <16 | O24: <2 | P24: 5 | Q24: 0.74 | R24: 0.12 | S24: 5.44 | T24: <16 | U24: <2 | V24: 5 | W24: 0.18 | X24: 0.1 | Y24: 4.67 | Z24: 77.9 | AA24: <20
A25: 19 | B25: 179 | C25: 95.3 | D25: 64 | E25: 3.49 | F25: 20.3 | G25: 25.9 | H25: 20 | I25: <2 | J25: 7 | K25: 0.32 | L25: 0.22 | M25: 7.61 | N25: <16 | O25: <2 | P25: 5 | Q25: 0.55 | R25: 0.1 | S25: 6.37 | T25: <16 | U25: <2 | V25: 5 | W25: 0.13 | X25: 0.1 | Y25: 6.32 | Z25: 78.1 | AA25: <20
A26: 20 | B26: 188 | C26: 99.7 | D26: 92 | E26: 2.71 | F26: 19.4 | G26: 24.7 | H26: 16 | I26: <2 | J26: 5 | K26: 0.21 | L26: 0.14 | M26: 8.06 | N26: <16 | O26: <2 | P26: 5 | Q26: 0.25 | R26: 0.16 | S26: 7.71 | T26: <16 | U26: <2 | V26: 5 | W26: 0.1 | X26: 0.1 | Y26: 6.27 | Z26: 78.4 | AA26: <20
A27: 21 | B27: 198 | C27: 102 | D27: 102 | E27: 3.02 | F27: 21 | G27: 26.7 | H27: 21 | I27: <2 | J27: 7 | K27: 0.31 | L27: 0.15 | M27: 7.18 | N27: 20 | O27: <2 | P27: 8 | Q27: 0.52 | R27: 0.36 | S27: 5.97 | T27: <16 | U27: <2 | V27: 5 | W27: 0.13 | X27: 0.13 | Y27: 5.67 | Z27: 78.9
A28: 22 | B28: 190 | C28: 100 | D28: 122 | E28: 2.34 | F28: 23.2 | G28: 28.9 | H28: 22 | I28: <2 | J28: 7 | K28: 0.37 | L28: 0.42 | M28: 8.46 | N28: 23 | O28: <2 | P28: 5 | Q28: 0.81 | R28: 0.95 | S28: 9.51 | T28: <16 | U28: <2 | V28: 5 | W28: 0.13 | X28: 0.38 | Y28: 7.86 | Z28: 79.2
A29: 23 | B29: 213 | C29: 113 | D29: 142 | E29: 3.04 | F29: 29.2 | G29: 36.9 | H29: 19 | I29: <2 | J29: 6 | K29: 0.4 | L29: 0.26 | M29: 6.8 | N29: <16 | O29: <2 | P29: 5 | Q29: 0.82 | R29: 0.18 | S29: 6.67 | T29: <16 | U29: <2 | V29: 5 | W29: 0.14 | X29: 0.1 | Y29: 6.52 | Z29: 78.8 | AA29: <20
A30: 24 | B30: 170 | C30: 91.5 | D30: 146 | E30: 3.25 | F30: 20 | G30: 25.9 | H30: 16 | I30: <2 | J30: 5 | K30: 0.27 | L30: 0.11 | M30: 8.01 | N30: <16 | O30: <2 | P30: 5 | Q30: 0.77 | R30: 0.22 | S30: 7.41 | T30: <16 | U30: <2 | V30: 5 | W30: 0.12 | X30: 0.1 | Y30: 5.87 | Z30: 78.1 | AA30: <20
A31: 25 | B31: 246 | C31: 132 | D31: 164 | E31: 4.03 | F31: 23.4 | G31: 29 | H31: 19 | I31: <2 | J31: 6 | K31: 0.37 | L31: 0.29 | M31: 6.77 | N31: <16 | O31: <2 | P31: 5 | Q31: 0.82 | R31: 0.22 | S31: 6.57 | T31: <16 | U31: <2 | V31: 5 | W31: 0.2 | X31: 0.16 | Y31: 6.42 | Z31: 78.4 | AA31: 230
A32: 26 | B32: 129 | C32: 68.5 | D32: 78 | E32: 2.33 | F32: 10.1 | G32: 15.4 | H32: 19 | I32: <2 | J32: 5 | K32: 0.9 | L32: 0.12 | M32: 4.52 | N32: 16 | O32: <2 | P32: 5 | Q32: 0.77 | R32: 0.1 | S32: 4.12 | T32: <16 | U32: <2 | V32: 5 | W32: 0.19 | X32: 0.1 | Y32: 3.72 | Z32: 77.8 | AA32: <20
A33: 27 | B33: 134 | C33: 69.5 | D33: 76 | E33: 2.82 | F33: 17.1 | G33: 23.6 | H33: 16 | I33: <2 | J33: 5 | K33: 0.33 | L33: 0.11 | M33: 5.44 | N33: <16 | O33: <2 | P33: 5 | Q33: 0.48 | R33: 0.12 | S33: 5.02 | T33: <16 | U33: <2 | V33: 5 | W33: 0.21 | X33: 0.1 | Y33: 4.02 | Z33: 78.2 | AA33: 50
A34: 28 | B34: 182 | C34: 94.7 | D34: 114 | E34: 2.56 | F34: 18.2 | G34: 24.9 | H34: <16 | I34: <2 | J34: 5 | K34: 0.2 | L34: 0.13 | M34: 6.27 | N34: <16 | O34: <2 | P34: 5 | Q34: 0.37 | R34: 0.24 | S34: 4.82 | T34: <16 | U34: <2 | V34: 5 | W34: 0.12 | X34: 0.11 | Y34: 4.62 | Z34: 77.9
A35: 29 | B35: 212 | C35: 110 | D35: 146 | E35: 3.55 | F35: 31 | G35: 36.7 | H35: 19 | I35: <2 | J35: 5 | K35: 0.28 | L35: 0.29 | M35: 8.84 | N35: <16 | O35: <2 | P35: 5 | Q35: 0.29 | R35: 0.27 | S35: 7.81 | T35: <16 | U35: <2 | V35: 5 | W35: 0.12 | X35: 0.13 | Y35: 7.71 | Z35: 78.6
A36: 30 | B36: 171 | C36: 90.5 | D36: 126 | E36: 1.71 | F36: 19.7 | G36: 27.8 | H36: 17 | I36: <2 | J36: 5 | K36: 0.28 | L36: 0.52 | M36: 7.71 | N36: <16 | O36: <2 | P36: 5 | Q36: 0.23 | R36: 0.49 | S36: 7.66 | T36: <16 | U36: <2 | V36: 5 | W36: 0.11 | X36: 0.15 | Y36: 6.92 | Z36: 78.1 | AA36: <20
A37: 31 | B37: 171 | C37: 89.7 | D37: 118 | E37: 3.29 | F37: 21.8 | G37: 26.7 | H37: <16 | I37: <2 | J37: 5 | K37: 0.24 | L37: 0.16 | M37: 7.71 | N37: 16 | O37: <2 | P37: 5 | Q37: 0.56 | R37: 0.17 | S37: 6.67 | T37: <16 | U37: <2 | V37: 5 | W37: 0.06 | X37: 0.1 | Y37: 5.52 | Z37: 78.8 | AA37: <20
A38: 平均 | B38: =AVERAGE(B7:B37) -> 188.16129 | C38: =AVERAGE(C7:C37) -> 99.148387 | D38: =AVERAGE(D7:D37) -> 115.87097 | E38: =AVERAGE(E7:E37) -> 3.3032258 | F38: =AVERAGE(F7:F37) -> 22.089032 | G38: =AVERAGE(G7:G37) -> 28.703226 | H38: =AVERAGE(H7:H37) -> 18.37037 | I38: <2 | J38: =AVERAGE(J7:J37) -> 5.2903226 | K38: =AVERAGE(K7:K37) -> 0.29580645 | L38: =AVERAGE(L7:L37) -> 0.20258065 | M38: =AVERAGE(M7:M37) -> 7.0706452 | N38: =AVERAGE(N11:N37) -> 18.461538 | O38: <2 | P38: =AVERAGE(P7:P37) -> 5.3548387 | Q38: =AVERAGE(Q7:Q37) -> 0.50290323 | R38: =AVERAGE(R7:R37) -> 0.21774194 | S38: =AVERAGE(S7:S37) -> 6.5177419 | T38: <16 | U38: <2 | V38: =AVERAGE(V7:V37) -> 5 | W38: =AVERAGE(W7:W37) -> 0.14322581 | X38: =AVERAGE(X7:X37) -> 0.13612903 | Y38: =AVERAGE(Y7:Y37) -> 5.916129 | Z38: =AVERAGE(Z7:Z37) -> 78.212903 | AA38: <20
A39: 审核： 制表： 制表日期：2021-9-3
B42: =MIN(B7:B37) -> 96 | C42: =MIN(C7:C37) -> 49.9 | D42: =MIN(D7:D37) -> 62 | E42: =MIN(E7:E37) -> 1.71 | F42: =MIN(F7:F37) -> 8.86 | G42: =MIN(G7:G37) -> 14.2 | H42: =MIN(H7:H37) -> 16 | I42: =MIN(I7:I37) -> 0 | ... Z42: =MIN(Z7:Z37) -> 77.4
B43: =MAX(B7:B37) -> 323 | C43: =MAX(C7:C37) -> 171 | D43: =MAX(D7:D37) -> 228 | E43: =MAX(E7:E37) -> 5.69 | F43: =MAX(F7:F37) -> 43.5 | G43: =MAX(G7:G37) -> 48.9 | H43: =MAX(H7:H37) -> 22 | I43: =MAX(I7:I37) -> 0 | ... Z43: =MAX(Z7:Z37) -> 79.2
...

Sheet 设备
A1: 常州市深水城北污水处理有限公司设备运行汇总报表（一） 2021年8月
A2: 编号 | B2: 设备名称 | C2: 运行天数 （d） | D2: 定时 （h/d） | E2: 额定运行 时间（h） | F2: 实际运行 时间（h） | G2: 故障 （h） | H2: 利用率 （%） | I2: 完好率 （%） | J2: 检修保养情况 | K2: 备 注
A4: 一期
A5: 1 | B5: 刮泥机1# | C5: 31 | D5: 24 | E5: 744 | F5: 0 | H5: 0 | I5: 100
A6: 2 | B6: 污水二次提升泵1# | C6: 31 | D6: 24 | E6: 744 | F6: 0 | H6: 0 | I6: 100
A7: 3 | B7: 污水二次提升泵2# | C7: 31 | D7: 24 | E7: 744 | F7: 744 | H7: 1 | I7: 100
A8: 4 | B8: 污水二次提升泵3# | C8: 31 | D8: 24 | E8: 744 | F8: 744 | H8: 1 | I8: 100
A9: 5 | B9: 污水二次提升泵4# | C9: 31 | D9: 24 | E9: 744 | F9: 744 | H9: 1 | I9: 100
A10: 6 | B10: 污水二次提升泵5# | C10: 31 | D10: 24 | E10: 744 | F10: 744 | H10: 1 | I10: 100
A11: 7 | B11: 污水二次提升泵6# | C11: 31 | D11: 24 | E11: 744 | F11: 0 | H11: 0 | I11: 100
A12: 8 | B12: 水下搅拌器1# | C12: 31 | D12: 24 | E12: 744 | F12: 744 | H12: 1 | I12: 100
A13: 9 | B13: 水下搅拌器2# | C13: 31 | D13: 24 | E13: 744 | F13: 744 | H13: 1 | I13: 100
A14: 10 | B14: 水下搅拌器3# | C14: 31 | D14: 24 | E14: 744 | F14: 744 | H14: 1 | I14: 100
A15: 11 | B15: 水下搅拌器4# | C15: 31 | D15: 24 | E15: 744 | F15: 744 | H15: 1 | I15: 100
A16: 12 | B16: 水下搅拌器5# | C16: 31 | D16: 24 | E16: 744 | F16: 744 | H16: 1 | I16: 100
... A31: 27 | B31: 内回流泵2# | C31: 31 | D31: 24 | E31: 744 | F31: 744 | H31: 1 | I31: 100
A32: 审核： | E32: 制表： | I32: 制表时间：2021-9-3
A33: 常州市深水城北污水处理有限公司设备运行汇总报表（二） 2021年8月
A34: 编号 | B34: 设备名称 | C34: 运行天数 （d） | D34: 定时 （h/d） | E34: 额定运行 时间（h） | F34: 实际运行 时间（h） | G34: 故障 （h） | H34: 利用率 （%） | I34: 完好率 （%） | J34: 检修保养情况 | K34: 备 注
A36: 28 | B36: 内回流泵3# | C36: 31 | D36: 24 | E36: 744 | F36: 744 | H36: 1 | I36: 100
A37: 29 | B37: 内回流泵4# | C37: 31 | D37: 24 | E37: 744 | F37: 294.5 | H37: 0.39583333 | I37: 100
A38: 30 | B38: 内回流泵5# | C38: 31 | D38: 24 | E38: 744 | F38: 744 | H38: 1 | I38: 100
A39: 31 | B39: 内回流泵6# | C39: 31 | D39: 24 | E39: 744 | F39: 744 | H39: 1 | I39: 100
A40: 32 | B40: 内回流泵7# | C40: 31 | D40: 24 | E40: 744 | F40: 742 | G40: 2 | H40: 0.99731183 | I40: 99.7 | J40: 8月9日过热故障检修
A41: 33 | B41: 内回流泵8# | C41: 31 | D41: 24 | E41: 744 | F41: 295 | H41: 0.39650538 | I41: 100
A42: 34 | B42: 回流泵1# | C42: 31 | D42: 24 | E42: 744 | F42: 744 | H42: 1 | I42: 100
A43: 35 | B43: 回流泵2# | C43: 31 | D43: 24 | E43: 744 | F43: 744 | H43: 1 | I43: 100
A44: 36 | B44: 回流泵3# | C44: 31 | D44: 24 | E44: 744 | F44: 0 | H44: 0 | I44: 100
A45: 37 | B45: 回流泵4# | C45: 31 | D45: 24 | E45: 744 | F45: 744 | H45: 1 | I45: 100
A46: 38 | B46: 回流泵5# | C46: 31 | D46: 24 | E46: 744 | F46: 744 | H46: 1 | I46: 100
A47: 39 | B47: 回流泵6# | C47: 31 | D47: 24 | E47: 744 | F47: 0 | H47: 0 | I47: 100
A48: 40 | B48: 吸泥机1# | C48: 31 | D48: 24 | E48: 744 | F48: 744 | H48: 1 | I48: 100
A49: 41 | B49: 吸泥机2# | C49: 31 | D49: 24 | E49: 744 | F49: 744 | H49: 1 | I49: 100
A50: 42 | B50: 吸泥机3# | C50: 31 | D50: 24 | E50: 744 | F50: 744 | H50: 1 | I50: 100
A51: 43 | B51: 吸泥机4# | C51: 31 | D51: 24 | E51: 744 | F51: 744 | H51: 1 | I51: 100
A52: 44 | B52: 浓缩机1# | C52: 31 | D52: 24 | E52: 744 | F52: 0 | H52: 0 | I52: 100
... A54: 46 | B54: 浓缩机3# | C54: 31 | D54: 24 | E54: 744 | F54: 744 | H54: 1 | I54: 100
A55: 一期缺好氧池
A56: 47 | B56: 水下搅拌器1# | C56: 31 | D56: 24 | E56: 744 | F56: 744 | H56: 1 | I56: 100
A57: 48 | B57: 水下搅拌器2# | C57: 31 | D57: 24 | E57: 744 | F57: 744 | H57: 1 | I57: 100
...

Sheet 仪表
A1: 常州市深水城北污水处理有限公司设备运行月报表
A2: 44409
A3: 编号 | B3: 仪表名称 | C3: 规格型号 | D3: 安装位置 | E3: 运行情况 | F3: 标定校 准情况 | G3: 备注
A4: 1 | B4: pH计 | C4: 哈希PHD差分探头 | D4: 一期细格栅井 | E4: 正常 | F4: 标定 | G4: （2、9、16、23）日
A5: 2 | B5: pH计 | C5: 哈希PHD差分探头 | D5: 出水口 | E5: 正常 | F5: 标定 | G5: （3、10、17、24）日
A6: 3 | B6: MLSS测量仪 | C6: 哈希SC200-solitax | D6: 一期缺好氧池 | E6: 正常 | F6: 标定 | G6: （4、11、18、25）日
A7: 4 | B7: 溶解氧检测仪 | C7: 哈希SC200-LDO | D7: 一期缺好氧池 | E7: 正常 | F7: 标定 | G7: （3、10、17、24）日
A8: 5 | B8: 溶解氧检测仪 | C8: 哈希SC200-LDO | D8: 一期好氧池 | E8: 正常 | F8: 标定 | G8: （4、11、18、25）日
A9: 6 | B9: MLSS测量仪 | C9: 哈希SC200-solitax | D9: 一期好氧池 | E9: 正常 | F9: 标定 | G9: （5、12、19、26）日
A10: 7 | B10: 溶解氧检测仪 | C10: 哈希SC200-LDO | D10: 二期好氧池 | E10: 正常 | F10: 标定 | G10: （2、9、16、23）日
A11: 8 | B11: MLSS测量仪 | C11: 哈希SC200-solitax | D11: 二期好氧池 | E11: 正常 | F11: 标定 | G11: （3、10、17、24）日
A12: 9 | B12: 溶解氧检测仪 | C12: 哈希SC200-LDO | D12: 三期好氧池 | E12: 正常 | F12: 标定 | G12: （4、11、18、25）日
A13: 10 | B13: MLSS测量仪 | C13: 哈希SC200-solitax | D13: 三期好氧池 | E13: 正常 | F13: 标定 | G13: （5、12、19、26）日
A14: 11 | B14: COD在线检测仪 | C14: JHC-ⅢA | D14: 总排放口 | E14: 正常 | F14: 标定 | G14: 16日
A15: 12 | B15: TP在线检测仪 | C15: JHP | D15: 总排放口 | E15: 正常 | F15: 标定 | G15: 16日
... A23: 20 | B23: ORP在线仪表 | C23: PC-3100 | D23: 二三期厌缺氧池 | E23: 正常 | F23: 标定 | G23: （3、10、17、24）日
A24: 审核： 制表： 制表日期：2021-9-3

Sheet 实验
A1: 常州市深水城北污水处理有限公司硝化、反硝化、厌氧释磷实验
A2: 硝化实验
A3: 日期 | B3: 地点 | C3: 化验指标 | D3: 0 | E3: 15 | F3: 30 | G3: 60 | J3: MLSS | L3: 速率
A4: 44432 | B4: 一期南 | C4: NO2-N | J4: 3.225
C5: NO3-N | D5: 3.63 | E5: 4.57 | F5: 7.32 | G5: 8.89 | K5: =SLOPE(D5:G5,D$3:G$3) -> 0.091828571 | L5: =K5*60/J4 -> 1.7084385
C6: NH3-N | D6: 8.12 | E6: 6.7 | F6: 5.09 | G6: 3.51 | K6: =SLOPE(D6:G6,D$3:G$3) -> -0.076685714 | L6: =K6*60/J4 -> -1.426711
C7: PO43- | D7: 5.51 | E7: 2.25 | F7: 1.83 | G7: 1.67 | K7: =SLOPE(D7:G7,D$3:G$3) -> -0.054209524 | L7: =K7*60/J4 -> -1.0085493
A8: 反硝化实验
A9: 日期 | B9: 地点 | C9: 化验指标 | D9: 0 | E9: 10 | F9: 20 | G9: 30 | H9: 60 | I9: 90 | J9: MLSS | L9: 速率
A10: 44432 | B10: 一期南 | C10: NO3-N | D10: 7.29 | E10: 6.65 | F10: 5.91 | G10: 4.39 | H10: 2.91 | I10: 2.2 | J10: 3.054 | K10: =SLOPE(D10:I10,D$9:I$9) -> -0.058826087 | L10: =K10*60/J10 -> -1.1557188
A11: 厌氧释磷实验
A12: 日期 | B12: 地点 | C12: 化验指标 | D12: 0 | E12: 15 | F12: 30 | G12: 60 | J12: MLSS | L12: 速率
A13: 44432 | B13: 一期南 | C13: PO43- | D13: 2.71 | E13: 5.32 | F13: 6.51 | G13: 9.37 | J13: 3.482 | K13: =SLOPE(D13:G13,D$12:G$12) -> 0.10649524 | L13: =K13*60/J13 -> 1.8350702
